{
  "version": 8,
  "blockIdVersion": 11,
  "anchorX": 0,
  "anchorY": 3,
  "anchorZ": 0,
  "blocks": [
    {
      "x": -4,
      "y": 8,
      "z": 0,
      "name": "Plant_Leaves_Skylands"
    },
    {
      "x": -4,
      "y": 9,
      "z": 0,
      "name": "Plant_Leaves_Skylands"
    },
    {
      "x": -4,
      "y": 10,
      "z": 0,
      "name": "Plant_Leaves_Skylands"
    },
    {
      "x": -3,
      "y": 8,
      "z": -1,
      "name": "Plant_Leaves_Skylands"
    },
    {
      "x": -3,
      "y": 9,
      "z": -1,
      "name": "Plant_Leaves_Skylands"
    },
    {
      "x": -3,
      "y": 10,
      "z": -1,
      "name": "Plant_Leaves_Skylands"
    },
    {
      "x": -3,
      "y": 11,
      "z": -1,
      "name": "Plant_Leaves_Skylands"
    },
    {
      "x": -3,
      "y": 7,
      "z": 0,
      "name": "Plant_Leaves_Skylands"
    },
    {
      "x": -3,
      "y": 8,
      "z": 0,
      "name": "Plant_Leaves_Skylands"
    },
    {
      "x": -3,
      "y": 9,
      "z": 0,
      "name": "Plant_Leaves_Skylands"
    },
    {
      "x": -3,
      "y": 10,
      "z": 0,
      "name": "Plant_Leaves_Skylands"
    },
    {
      "x": -3,
      "y": 11,
      "z": 0,
      "name": "Plant_Leaves_Skylands"
    },
    {
      "x": -3,
      "y": 12,
      "z": 0,
      "name": "Plant_Leaves_Skylands"
    },
    {
      "x": -3,
      "y": 7,
      "z": 1,
      "name": "Plant_Leaves_Skylands"
    },
    {
      "x": -3,
      "y": 8,
      "z": 1,
      "name": "Plant_Leaves_Skylands"
    },
    {
      "x": -3,
      "y": 9,
      "z": 1,
      "name": "Plant_Leaves_Skylands"
    },
    {
      "x": -2,
      "y": 8,
      "z": -3,
      "name": "Plant_Leaves_Skylands"
    },
    {
      "x": -2,
      "y": 7,
      "z": -2,
      "name": "Plant_Leaves_Skylands"
    },
    {
      "x": -2,
      "y": 8,
      "z": -2,
      "name": "Plant_Leaves_Skylands"
    },
    {
      "x": -2,
      "y": 9,
      "z": -2,
      "name": "Plant_Leaves_Skylands"
    },
    {
      "x": -2,
      "y": 9,
      "z": -1,
      "name": "Plant_Leaves_Skylands"
    },
    {
      "x": -2,
      "y": 10,
      "z": -1,
      "name": "Plant_Leaves_Skylands"
    },
    {
      "x": -2,
      "y": 11,
      "z": -1,
      "name": "Plant_Leaves_Skylands"
    },
    {
      "x": -2,
      "y": 8,
      "z": 0,
      "name": "Wood_Ash_Branch_Long",
      "rotation": 5
    },
    {
      "x": -2,
      "y": 9,
      "z": 0,
      "name": "Plant_Leaves_Skylands"
    },
    {
      "x": -2,
      "y": 10,
      "z": 0,
      "name": "Plant_Leaves_Skylands"
    },
    {
      "x": -2,
      "y": 11,
      "z": 0,
      "name": "Plant_Leaves_Skylands"
    },
    {
      "x": -2,
      "y": 12,
      "z": 0,
      "name": "Plant_Leaves_Skylands"
    },
    {
      "x": -2,
      "y": 13,
      "z": 0,
      "name": "Plant_Leaves_Skylands"
    },
    {
      "x": -2,
      "y": 9,
      "z": 1,
      "name": "Plant_Leaves_Skylands"
    },
    {
      "x": -2,
      "y": 10,
      "z": 1,
      "name": "Plant_Leaves_Skylands"
    },
    {
      "x": -2,
      "y": 11,
      "z": 1,
      "name": "Plant_Leaves_Skylands"
    },
    {
      "x": -2,
      "y": 8,
      "z": 2,
      "name": "Plant_Leaves_Skylands"
    },
    {
      "x": -2,
      "y": 10,
      "z": 2,
      "name": "Plant_Leaves_Skylands"
    },
    {
      "x": -1,
      "y": 9,
      "z": -3,
      "name": "Plant_Leaves_Skylands"
    },
    {
      "x": -1,
      "y": 10,
      "z": -3,
      "name": "Plant_Leaves_Skylands"
    },
    {
      "x": -1,
      "y": 9,
      "z": -2,
      "name": "Plant_Leaves_Skylands"
    },
    {
      "x": -1,
      "y": 10,
      "z": -2,
      "name": "Plant_Leaves_Skylands"
    },
    {
      "x": -1,
      "y": 11,
      "z": -2,
      "name": "Plant_Leaves_Skylands"
    },
    {
      "x": -1,
      "y": 11,
      "z": -1,
      "name": "Plant_Leaves_Skylands"
    },
    {
      "x": -1,
      "y": 12,
      "z": -1,
      "name": "Plant_Leaves_Skylands"
    },
    {
      "x": -1,
      "y": 8,
      "z": 0,
      "name": "Wood_Ash_Branch_Long",
      "rotation": 5
    },
    {
      "x": -1,
      "y": 10,
      "z": 0,
      "name": "Wood_Ash_Branch_Long",
      "rotation": 5
    },
    {
      "x": -1,
      "y": 11,
      "z": 0,
      "name": "Plant_Leaves_Skylands"
    },
    {
      "x": -1,
      "y": 12,
      "z": 0,
      "name": "Plant_Leaves_Skylands"
    },
    {
      "x": -1,
      "y": 13,
      "z": 0,
      "name": "Plant_Leaves_Skylands"
    },
    {
      "x": -1,
      "y": 14,
      "z": 0,
      "name": "Plant_Leaves_Skylands"
    },
    {
      "x": -1,
      "y": 10,
      "z": 1,
      "name": "Plant_Leaves_Skylands"
    },
    {
      "x": -1,
      "y": 11,
      "z": 1,
      "name": "Plant_Leaves_Skylands"
    },
    {
      "x": -1,
      "y": 12,
      "z": 1,
      "name": "Plant_Leaves_Skylands"
    },
    {
      "x": -1,
      "y": 13,
      "z": 1,
      "name": "Plant_Leaves_Skylands"
    },
    {
      "x": -1,
      "y": 8,
      "z": 2,
      "name": "Plant_Leaves_Skylands"
    },
    {
      "x": -1,
      "y": 9,
      "z": 2,
      "name": "Plant_Leaves_Skylands"
    },
    {
      "x": -1,
      "y": 10,
      "z": 2,
      "name": "Plant_Leaves_Skylands"
    },
    {
      "x": -1,
      "y": 11,
      "z": 2,
      "name": "Plant_Leaves_Skylands"
    },
    {
      "x": -1,
      "y": 7,
      "z": 3,
      "name": "Plant_Leaves_Skylands"
    },
    {
      "x": -1,
      "y": 8,
      "z": 3,
      "name": "Plant_Leaves_Skylands"
    },
    {
      "x": 0,
      "y": 9,
      "z": -3,
      "name": "Plant_Leaves_Skylands"
    },
    {
      "x": 0,
      "y": 10,
      "z": -3,
      "name": "Plant_Leaves_Skylands"
    },
    {
      "x": 0,
      "y": 11,
      "z": -2,
      "name": "Plant_Leaves_Skylands"
    },
    {
      "x": 0,
      "y": 12,
      "z": -2,
      "name": "Plant_Leaves_Skylands"
    },
    {
      "x": 0,
      "y": 12,
      "z": -1,
      "name": "Plant_Leaves_Skylands"
    },
    {
      "x": 0,
      "y": 13,
      "z": -1,
      "name": "Plant_Leaves_Skylands"
    },
    {
      "x": 0,
      "y": 14,
      "z": -1,
      "name": "Plant_Leaves_Skylands"
    },
    {
      "x": 0,
      "y": 6,
      "z": 0,
      "name": "Wood_Ash_Branch_Long",
      "rotation": 5
    },
    {
      "x": 0,
      "y": 8,
      "z": 0,
      "name": "Wood_Ash_Branch_Long",
      "rotation": 5
    },
    {
      "x": 0,
      "y": 10,
      "z": 0,
      "name": "Wood_Ash_Branch_Long",
      "rotation": 5
    },
    {
      "x": 0,
      "y": 12,
      "z": 0,
      "name": "Wood_Ash_Branch_Long",
      "rotation": 5
    },
    {
      "x": 0,
      "y": 13,
      "z": 0,
      "name": "Plant_Leaves_Skylands"
    },
    {
      "x": 0,
      "y": 14,
      "z": 0,
      "name": "Plant_Leaves_Skylands"
    },
    {
      "x": 0,
      "y": 11,
      "z": 1,
      "name": "Plant_Leaves_Skylands"
    },
    {
      "x": 0,
      "y": 12,
      "z": 1,
      "name": "Plant_Leaves_Skylands"
    },
    {
      "x": 0,
      "y": 13,
      "z": 1,
      "name": "Plant_Leaves_Skylands"
    },
    {
      "x": 0,
      "y": 8,
      "z": 2,
      "name": "Plant_Leaves_Skylands"
    },
    {
      "x": 0,
      "y": 9,
      "z": 2,
      "name": "Plant_Leaves_Skylands"
    },
    {
      "x": 0,
      "y": 11,
      "z": 2,
      "name": "Plant_Leaves_Skylands"
    },
    {
      "x": 0,
      "y": 12,
      "z": 2,
      "name": "Plant_Leaves_Skylands"
    },
    {
      "x": 0,
      "y": 8,
      "z": 3,
      "name": "Plant_Leaves_Skylands"
    },
    {
      "x": 0,
      "y": 10,
      "z": 3,
      "name": "Plant_Leaves_Skylands"
    },
    {
      "x": 0,
      "y": 11,
      "z": 3,
      "name": "Plant_Leaves_Skylands"
    },
    {
      "x": 1,
      "y": 9,
      "z": -4,
      "name": "Plant_Leaves_Skylands"
    },
    {
      "x": 1,
      "y": 10,
      "z": -4,
      "name": "Plant_Leaves_Skylands"
    },
    {
      "x": 1,
      "y": 11,
      "z": -4,
      "name": "Plant_Leaves_Skylands"
    },
    {
      "x": 1,
      "y": 9,
      "z": -3,
      "name": "Wood_Ash_Branch_Long",
      "rotation": 4
    },
    {
      "x": 1,
      "y": 10,
      "z": -3,
      "name": "Plant_Leaves_Skylands"
    },
    {
      "x": 1,
      "y": 11,
      "z": -3,
      "name": "Plant_Leaves_Skylands"
    },
    {
      "x": 1,
      "y": 12,
      "z": -3,
      "name": "Plant_Leaves_Skylands"
    },
    {
      "x": 1,
      "y": 9,
      "z": -2,
      "name": "Wood_Ash_Branch_Long",
      "rotation": 4
    },
    {
      "x": 1,
      "y": 11,
      "z": -2,
      "name": "Plant_Leaves_Skylands"
    },
    {
      "x": 1,
      "y": 12,
      "z": -2,
      "name": "Plant_Leaves_Skylands"
    },
    {
      "x": 1,
      "y": 13,
      "z": -2,
      "name": "Plant_Leaves_Skylands"
    },
    {
      "x": 1,
      "y": 0,
      "z": -1,
      "name": "Wood_Ash_Trunk_Full"
    },
    {
      "x": 1,
      "y": 9,
      "z": -1,
      "name": "Wood_Ash_Branch_Long",
      "rotation": 4
    },
    {
      "x": 1,
      "y": 11,
      "z": -1,
      "name": "Wood_Ash_Branch_Long",
      "rotation": 4
    },
    {
      "x": 1,
      "y": 12,
      "z": -1,
      "name": "Plant_Leaves_Skylands"
    },
    {
      "x": 1,
      "y": 13,
      "z": -1,
      "name": "Plant_Leaves_Skylands"
    },
    {
      "x": 1,
      "y": 14,
      "z": -1,
      "name": "Plant_Leaves_Skylands"
    },
    {
      "x": 1,
      "y": 0,
      "z": 0,
      "name": "Wood_Ash_Trunk"
    },
    {
      "x": 1,
      "y": 1,
      "z": 0,
      "name": "Wood_Ash_Trunk_Full"
    },
    {
      "x": 1,
      "y": 5,
      "z": 0,
      "name": "Wood_Ash_Trunk_Full"
    },
    {
      "x": 1,
      "y": 6,
      "z": 0,
      "name": "Wood_Ash_Trunk"
    },
    {
      "x": 1,
      "y": 7,
      "z": 0,
      "name": "Wood_Ash_Trunk"
    },
    {
      "x": 1,
      "y": 8,
      "z": 0,
      "name": "Wood_Ash_Trunk"
    },
    {
      "x": 1,
      "y": 9,
      "z": 0,
      "name": "Wood_Ash_Trunk"
    },
    {
      "x": 1,
      "y": 10,
      "z": 0,
      "name": "Wood_Ash_Trunk"
    },
    {
      "x": 1,
      "y": 11,
      "z": 0,
      "name": "Wood_Ash_Trunk"
    },
    {
      "x": 1,
      "y": 12,
      "z": 0,
      "name": "Wood_Ash_Trunk"
    },
    {
      "x": 1,
      "y": 13,
      "z": 0,
      "name": "Wood_Ash_Branch_Long"
    },
    {
      "x": 1,
      "y": 14,
      "z": 0,
      "name": "Plant_Leaves_Skylands"
    },
    {
      "x": 1,
      "y": 7,
      "z": 1,
      "name": "Wood_Ash_Branch_Short"
    },
    {
      "x": 1,
      "y": 9,
      "z": 1,
      "name": "Wood_Ash_Branch_Long",
      "rotation": 4
    },
    {
      "x": 1,
      "y": 11,
      "z": 1,
      "name": "Wood_Ash_Branch_Long",
      "rotation": 4
    },
    {
      "x": 1,
      "y": 12,
      "z": 1,
      "name": "Plant_Leaves_Skylands"
    },
    {
      "x": 1,
      "y": 13,
      "z": 1,
      "name": "Plant_Leaves_Skylands"
    },
    {
      "x": 1,
      "y": 14,
      "z": 1,
      "name": "Plant_Leaves_Skylands"
    },
    {
      "x": 1,
      "y": 9,
      "z": 2,
      "name": "Wood_Ash_Branch_Long",
      "rotation": 4
    },
    {
      "x": 1,
      "y": 10,
      "z": 2,
      "name": "Plant_Leaves_Skylands"
    },
    {
      "x": 1,
      "y": 11,
      "z": 2,
      "name": "Plant_Leaves_Skylands"
    },
    {
      "x": 1,
      "y": 12,
      "z": 2,
      "name": "Plant_Leaves_Skylands"
    },
    {
      "x": 1,
      "y": 13,
      "z": 2,
      "name": "Plant_Leaves_Skylands"
    },
    {
      "x": 1,
      "y": 9,
      "z": 3,
      "name": "Plant_Leaves_Skylands"
    },
    {
      "x": 1,
      "y": 10,
      "z": 3,
      "name": "Plant_Leaves_Skylands"
    },
    {
      "x": 1,
      "y": 11,
      "z": 3,
      "name": "Plant_Leaves_Skylands"
    },
    {
      "x": 1,
      "y": 12,
      "z": 3,
      "name": "Plant_Leaves_Skylands"
    },
    {
      "x": 1,
      "y": 10,
      "z": 4,
      "name": "Plant_Leaves_Skylands"
    },
    {
      "x": 1,
      "y": 11,
      "z": 4,
      "name": "Plant_Leaves_Skylands"
    },
    {
      "x": 2,
      "y": 9,
      "z": -3,
      "name": "Plant_Leaves_Skylands"
    },
    {
      "x": 2,
      "y": 10,
      "z": -3,
      "name": "Plant_Leaves_Skylands"
    },
    {
      "x": 2,
      "y": 11,
      "z": -3,
      "name": "Plant_Leaves_Skylands"
    },
    {
      "x": 2,
      "y": 10,
      "z": -2,
      "name": "Plant_Leaves_Skylands"
    },
    {
      "x": 2,
      "y": 11,
      "z": -2,
      "name": "Plant_Leaves_Skylands"
    },
    {
      "x": 2,
      "y": 4,
      "z": -1,
      "name": "Wood_Ash_Branch_Short",
      "rotation": 2
    },
    {
      "x": 2,
      "y": 11,
      "z": -1,
      "name": "Plant_Leaves_Skylands"
    },
    {
      "x": 2,
      "y": 13,
      "z": -1,
      "name": "Plant_Leaves_Skylands"
    },
    {
      "x": 2,
      "y": 1,
      "z": 0,
      "name": "Wood_Ash_Trunk_Full"
    },
    {
      "x": 2,
      "y": 2,
      "z": 0,
      "name": "Wood_Ash_Trunk"
    },
    {
      "x": 2,
      "y": 3,
      "z": 0,
      "name": "Wood_Ash_Trunk"
    },
    {
      "x": 2,
      "y": 4,
      "z": 0,
      "name": "Wood_Ash_Trunk"
    },
    {
      "x": 2,
      "y": 5,
      "z": 0,
      "name": "Wood_Ash_Trunk_Full"
    },
    {
      "x": 2,
      "y": 6,
      "z": 0,
      "name": "Wood_Ash_Branch_Short",
      "rotation": 1
    },
    {
      "x": 2,
      "y": 8,
      "z": 0,
      "name": "Wood_Ash_Branch_Long",
      "rotation": 5
    },
    {
      "x": 2,
      "y": 11,
      "z": 0,
      "name": "Wood_Ash_Branch_Long",
      "rotation": 5
    },
    {
      "x": 2,
      "y": 12,
      "z": 0,
      "name": "Plant_Leaves_Skylands"
    },
    {
      "x": 2,
      "y": 13,
      "z": 0,
      "name": "Plant_Leaves_Skylands"
    },
    {
      "x": 2,
      "y": 14,
      "z": 0,
      "name": "Plant_Leaves_Skylands"
    },
    {
      "x": 2,
      "y": 1,
      "z": 1,
      "name": "Wood_Ash_Trunk_Full"
    },
    {
      "x": 2,
      "y": 2,
      "z": 1,
      "name": "Wood_Ash_Trunk"
    },
    {
      "x": 2,
      "y": 3,
      "z": 1,
      "name": "Wood_Ash_Trunk"
    },
    {
      "x": 2,
      "y": 4,
      "z": 1,
      "name": "Wood_Ash_Trunk_Full"
    },
    {
      "x": 2,
      "y": 12,
      "z": 1,
      "name": "Plant_Leaves_Skylands"
    },
    {
      "x": 2,
      "y": 13,
      "z": 1,
      "name": "Plant_Leaves_Skylands"
    },
    {
      "x": 2,
      "y": 9,
      "z": 2,
      "name": "Plant_Leaves_Skylands"
    },
    {
      "x": 2,
      "y": 10,
      "z": 2,
      "name": "Plant_Leaves_Skylands"
    },
    {
      "x": 2,
      "y": 11,
      "z": 2,
      "name": "Plant_Leaves_Skylands"
    },
    {
      "x": 2,
      "y": 12,
      "z": 2,
      "name": "Plant_Leaves_Skylands"
    },
    {
      "x": 2,
      "y": 10,
      "z": 3,
      "name": "Plant_Leaves_Skylands"
    },
    {
      "x": 3,
      "y": 9,
      "z": -3,
      "name": "Plant_Leaves_Skylands"
    },
    {
      "x": 3,
      "y": 10,
      "z": -3,
      "name": "Plant_Leaves_Skylands"
    },
    {
      "x": 3,
      "y": 9,
      "z": -2,
      "name": "Plant_Leaves_Skylands"
    },
    {
      "x": 3,
      "y": 10,
      "z": -2,
      "name": "Plant_Leaves_Skylands"
    },
    {
      "x": 3,
      "y": 11,
      "z": -2,
      "name": "Plant_Leaves_Skylands"
    },
    {
      "x": 3,
      "y": 8,
      "z": -1,
      "name": "Plant_Leaves_Skylands"
    },
    {
      "x": 3,
      "y": 9,
      "z": -1,
      "name": "Plant_Leaves_Skylands"
    },
    {
      "x": 3,
      "y": 10,
      "z": -1,
      "name": "Plant_Leaves_Skylands"
    },
    {
      "x": 3,
      "y": 11,
      "z": -1,
      "name": "Plant_Leaves_Skylands"
    },
    {
      "x": 3,
      "y": 12,
      "z": -1,
      "name": "Plant_Leaves_Skylands"
    },
    {
      "x": 3,
      "y": 0,
      "z": 0,
      "name": "Wood_Ash_Trunk_Full"
    },
    {
      "x": 3,
      "y": 1,
      "z": 0,
      "name": "Wood_Ash_Trunk"
    },
    {
      "x": 3,
      "y": 2,
      "z": 0,
      "name": "Wood_Ash_Trunk_Full"
    },
    {
      "x": 3,
      "y": 8,
      "z": 0,
      "name": "Wood_Ash_Branch_Long",
      "rotation": 5
    },
    {
      "x": 3,
      "y": 10,
      "z": 0,
      "name": "Plant_Leaves_Skylands"
    },
    {
      "x": 3,
      "y": 11,
      "z": 0,
      "name": "Plant_Leaves_Skylands"
    },
    {
      "x": 3,
      "y": 12,
      "z": 0,
      "name": "Plant_Leaves_Skylands"
    },
    {
      "x": 3,
      "y": 13,
      "z": 0,
      "name": "Plant_Leaves_Skylands"
    },
    {
      "x": 3,
      "y": 8,
      "z": 1,
      "name": "Plant_Leaves_Skylands"
    },
    {
      "x": 3,
      "y": 9,
      "z": 1,
      "name": "Plant_Leaves_Skylands"
    },
    {
      "x": 3,
      "y": 11,
      "z": 1,
      "name": "Plant_Leaves_Skylands"
    },
    {
      "x": 3,
      "y": 12,
      "z": 1,
      "name": "Plant_Leaves_Skylands"
    },
    {
      "x": 3,
      "y": 9,
      "z": 2,
      "name": "Plant_Leaves_Skylands"
    },
    {
      "x": 3,
      "y": 10,
      "z": 2,
      "name": "Plant_Leaves_Skylands"
    },
    {
      "x": 3,
      "y": 11,
      "z": 2,
      "name": "Plant_Leaves_Skylands"
    },
    {
      "x": 4,
      "y": 10,
      "z": -2,
      "name": "Plant_Leaves_Skylands"
    },
    {
      "x": 4,
      "y": 9,
      "z": -1,
      "name": "Plant_Leaves_Skylands"
    },
    {
      "x": 4,
      "y": 10,
      "z": -1,
      "name": "Plant_Leaves_Skylands"
    },
    {
      "x": 4,
      "y": 11,
      "z": -1,
      "name": "Plant_Leaves_Skylands"
    },
    {
      "x": 4,
      "y": 8,
      "z": 0,
      "name": "Plant_Leaves_Skylands"
    },
    {
      "x": 4,
      "y": 9,
      "z": 0,
      "name": "Plant_Leaves_Skylands"
    },
    {
      "x": 4,
      "y": 10,
      "z": 0,
      "name": "Plant_Leaves_Skylands"
    },
    {
      "x": 4,
      "y": 11,
      "z": 0,
      "name": "Plant_Leaves_Skylands"
    },
    {
      "x": 4,
      "y": 12,
      "z": 0,
      "name": "Plant_Leaves_Skylands"
    },
    {
      "x": 4,
      "y": 9,
      "z": 1,
      "name": "Plant_Leaves_Skylands"
    },
    {
      "x": 4,
      "y": 11,
      "z": 1,
      "name": "Plant_Leaves_Skylands"
    },
    {
      "x": 5,
      "y": 9,
      "z": 0,
      "name": "Plant_Leaves_Skylands"
    },
    {
      "x": 5,
      "y": 10,
      "z": 0,
      "name": "Plant_Leaves_Skylands"
    },
    {
      "x": 5,
      "y": 11,
      "z": 0,
      "name": "Plant_Leaves_Skylands"
    }
  ]
}