{
  "version": 8,
  "blockIdVersion": 11,
  "anchorX": 0,
  "anchorY": 0,
  "anchorZ": 0,
  "blocks": [
    {
      "x": -3,
      "y": 6,
      "z": -2,
      "name": "Rock_Aqua_Brick_Smooth_Half",
      "rotation": 8
    },
    {
      "x": -3,
      "y": 6,
      "z": -1,
      "name": "Rock_Aqua_Brick_Smooth_Half",
      "rotation": 8
    },
    {
      "x": -3,
      "y": 6,
      "z": 0,
      "name": "Rock_Aqua_Brick_Smooth_Half",
      "rotation": 8
    },
    {
      "x": -3,
      "y": 7,
      "z": 0,
      "name": "Rock_Aqua_Brick_Smooth_Half"
    },
    {
      "x": -3,
      "y": 6,
      "z": 1,
      "name": "Rock_Aqua_Brick_Smooth_Half",
      "rotation": 8
    },
    {
      "x": -3,
      "y": 6,
      "z": 2,
      "name": "Rock_Aqua_Brick_Smooth_Half",
      "rotation": 8
    },
    {
      "x": -2,
      "y": 6,
      "z": -3,
      "name": "Rock_Aqua_Brick_Smooth_Half",
      "rotation": 8
    },
    {
      "x": -2,
      "y": 0,
      "z": -2,
      "name": "Rock_Aqua_Brick"
    },
    {
      "x": -2,
      "y": 1,
      "z": -2,
      "name": "Rock_Aqua_Brick_Pillar_Base"
    },
    {
      "x": -2,
      "y": 2,
      "z": -2,
      "name": "Rock_Aqua_Brick_Pillar_Middle"
    },
    {
      "x": -2,
      "y": 3,
      "z": -2,
      "name": "Rock_Aqua_Brick_Beam"
    },
    {
      "x": -2,
      "y": 4,
      "z": -2,
      "name": "Rock_Aqua_Brick_Beam"
    },
    {
      "x": -2,
      "y": 5,
      "z": -2,
      "name": "Rock_Aqua_Brick_Pillar_Middle"
    },
    {
      "x": -2,
      "y": 6,
      "z": -2,
      "name": "Rock_Aqua_Brick_Pillar_Base",
      "rotation": 8
    },
    {
      "x": -2,
      "y": 7,
      "z": -2,
      "name": "Rock_Aqua_Brick_Smooth_Half"
    },
    {
      "x": -2,
      "y": 0,
      "z": -1,
      "name": "Rock_Aqua_Brick"
    },
    {
      "x": -2,
      "y": 7,
      "z": -1,
      "name": "Rock_Aqua_Brick_Smooth_Half"
    },
    {
      "x": -2,
      "y": 0,
      "z": 0,
      "name": "Rock_Aqua_Brick"
    },
    {
      "x": -2,
      "y": 7,
      "z": 0,
      "name": "Rock_Aqua_Brick_Smooth"
    },
    {
      "x": -2,
      "y": 0,
      "z": 1,
      "name": "Rock_Aqua_Brick"
    },
    {
      "x": -2,
      "y": 7,
      "z": 1,
      "name": "Rock_Aqua_Brick_Smooth_Half"
    },
    {
      "x": -2,
      "y": 0,
      "z": 2,
      "name": "Rock_Aqua_Brick"
    },
    {
      "x": -2,
      "y": 1,
      "z": 2,
      "name": "Rock_Aqua_Brick_Pillar_Base"
    },
    {
      "x": -2,
      "y": 2,
      "z": 2,
      "name": "Rock_Aqua_Brick_Pillar_Middle"
    },
    {
      "x": -2,
      "y": 3,
      "z": 2,
      "name": "Rock_Aqua_Brick_Beam"
    },
    {
      "x": -2,
      "y": 4,
      "z": 2,
      "name": "Rock_Aqua_Brick_Beam"
    },
    {
      "x": -2,
      "y": 5,
      "z": 2,
      "name": "Rock_Aqua_Brick_Pillar_Middle"
    },
    {
      "x": -2,
      "y": 6,
      "z": 2,
      "name": "Rock_Aqua_Brick_Pillar_Base",
      "rotation": 8
    },
    {
      "x": -2,
      "y": 7,
      "z": 2,
      "name": "Rock_Aqua_Brick_Smooth_Half"
    },
    {
      "x": -2,
      "y": 6,
      "z": 3,
      "name": "Rock_Aqua_Brick_Smooth_Half",
      "rotation": 8
    },
    {
      "x": -1,
      "y": 0,
      "z": -3,
      "name": "Rock_Aqua_Brick"
    },
    {
      "x": -1,
      "y": 6,
      "z": -3,
      "name": "Rock_Aqua_Brick_Smooth_Half",
      "rotation": 8
    },
    {
      "x": -1,
      "y": 0,
      "z": -2,
      "name": "Rock_Aqua_Brick"
    },
    {
      "x": -1,
      "y": 7,
      "z": -2,
      "name": "Rock_Aqua_Brick_Smooth_Half"
    },
    {
      "x": -1,
      "y": 0,
      "z": -1,
      "name": "Rock_Aqua_Brick"
    },
    {
      "x": -1,
      "y": 7,
      "z": -1,
      "name": "Rock_Aqua_Brick_Smooth_Half",
      "rotation": 8
    },
    {
      "x": -1,
      "y": 0,
      "z": 0,
      "name": "Rock_Aqua_Brick"
    },
    {
      "x": -1,
      "y": 7,
      "z": 0,
      "name": "Rock_Aqua_Brick_Smooth_Half",
      "rotation": 8
    },
    {
      "x": -1,
      "y": 8,
      "z": 0,
      "name": "Rock_Aqua_Brick_Smooth"
    },
    {
      "x": -1,
      "y": 0,
      "z": 1,
      "name": "Rock_Aqua_Brick"
    },
    {
      "x": -1,
      "y": 7,
      "z": 1,
      "name": "Rock_Aqua_Brick_Smooth_Half",
      "rotation": 8
    },
    {
      "x": -1,
      "y": 0,
      "z": 2,
      "name": "Rock_Aqua_Brick"
    },
    {
      "x": -1,
      "y": 7,
      "z": 2,
      "name": "Rock_Aqua_Brick_Smooth_Half"
    },
    {
      "x": -1,
      "y": 0,
      "z": 3,
      "name": "Rock_Aqua_Brick"
    },
    {
      "x": -1,
      "y": 6,
      "z": 3,
      "name": "Rock_Aqua_Brick_Smooth_Half",
      "rotation": 8
    },
    {
      "x": 0,
      "y": 0,
      "z": -3,
      "name": "Rock_Aqua_Brick"
    },
    {
      "x": 0,
      "y": 6,
      "z": -3,
      "name": "Rock_Aqua_Brick_Smooth_Half",
      "rotation": 8
    },
    {
      "x": 0,
      "y": 7,
      "z": -3,
      "name": "Rock_Aqua_Brick_Smooth_Half"
    },
    {
      "x": 0,
      "y": 0,
      "z": -2,
      "name": "Rock_Aqua_Brick"
    },
    {
      "x": 0,
      "y": 7,
      "z": -2,
      "name": "Rock_Aqua_Brick_Smooth"
    },
    {
      "x": 0,
      "y": 0,
      "z": -1,
      "name": "Rock_Aqua_Brick"
    },
    {
      "x": 0,
      "y": 7,
      "z": -1,
      "name": "Rock_Aqua_Brick_Smooth_Half",
      "rotation": 8
    },
    {
      "x": 0,
      "y": 8,
      "z": -1,
      "name": "Rock_Aqua_Brick_Smooth"
    },
    {
      "x": 0,
      "y": 0,
      "z": 0,
      "name": "Rock_Aqua_Brick"
    },
    {
      "x": 0,
      "y": 1,
      "z": 0,
      "name": "Rock_Aqua_Brick_Pillar_Base"
    },
    {
      "x": 0,
      "y": 2,
      "z": 0,
      "name": "Furniture_Temple_Dark_Statue_Gaia",
      "rotation": 1
    },
    {
      "x": 0,
      "y": 3,
      "z": 0,
      "name": "Furniture_Temple_Dark_Statue_Gaia",
      "filler": 1024,
      "rotation": 1
    },
    {
      "x": 0,
      "y": 4,
      "z": 0,
      "name": "Furniture_Temple_Dark_Statue_Gaia",
      "filler": 2048,
      "rotation": 1
    },
    {
      "x": 0,
      "y": 7,
      "z": 0,
      "name": "Rock_Aqua_Brick_Smooth_Half",
      "rotation": 8
    },
    {
      "x": 0,
      "y": 8,
      "z": 0,
      "name": "Rock_Aqua_Brick_Smooth"
    },
    {
      "x": 0,
      "y": 9,
      "z": 0,
      "name": "Rock_Aqua_Brick_Smooth"
    },
    {
      "x": 0,
      "y": 10,
      "z": 0,
      "name": "Rock_Aqua_Brick_Pillar_Middle"
    },
    {
      "x": 0,
      "y": 11,
      "z": 0,
      "name": "Rock_Aqua_Brick_Beam"
    },
    {
      "x": 0,
      "y": 12,
      "z": 0,
      "name": "Rock_Aqua_Brick_Beam"
    },
    {
      "x": 0,
      "y": 0,
      "z": 1,
      "name": "Rock_Aqua_Brick"
    },
    {
      "x": 0,
      "y": 7,
      "z": 1,
      "name": "Rock_Aqua_Brick_Smooth_Half",
      "rotation": 8
    },
    {
      "x": 0,
      "y": 8,
      "z": 1,
      "name": "Rock_Aqua_Brick_Smooth"
    },
    {
      "x": 0,
      "y": 0,
      "z": 2,
      "name": "Rock_Aqua_Brick"
    },
    {
      "x": 0,
      "y": 7,
      "z": 2,
      "name": "Rock_Aqua_Brick_Smooth"
    },
    {
      "x": 0,
      "y": 0,
      "z": 3,
      "name": "Rock_Aqua_Brick"
    },
    {
      "x": 0,
      "y": 6,
      "z": 3,
      "name": "Rock_Aqua_Brick_Smooth_Half",
      "rotation": 8
    },
    {
      "x": 0,
      "y": 7,
      "z": 3,
      "name": "Rock_Aqua_Brick_Smooth_Half"
    },
    {
      "x": 1,
      "y": 0,
      "z": -3,
      "name": "Rock_Aqua_Brick"
    },
    {
      "x": 1,
      "y": 6,
      "z": -3,
      "name": "Rock_Aqua_Brick_Smooth_Half",
      "rotation": 8
    },
    {
      "x": 1,
      "y": 0,
      "z": -2,
      "name": "Rock_Aqua_Brick"
    },
    {
      "x": 1,
      "y": 7,
      "z": -2,
      "name": "Rock_Aqua_Brick_Smooth_Half"
    },
    {
      "x": 1,
      "y": 0,
      "z": -1,
      "name": "Rock_Aqua_Brick"
    },
    {
      "x": 1,
      "y": 7,
      "z": -1,
      "name": "Rock_Aqua_Brick_Smooth_Half",
      "rotation": 8
    },
    {
      "x": 1,
      "y": 0,
      "z": 0,
      "name": "Rock_Aqua_Brick"
    },
    {
      "x": 1,
      "y": 7,
      "z": 0,
      "name": "Rock_Aqua_Brick_Smooth_Half",
      "rotation": 8
    },
    {
      "x": 1,
      "y": 8,
      "z": 0,
      "name": "Rock_Aqua_Brick_Smooth"
    },
    {
      "x": 1,
      "y": 0,
      "z": 1,
      "name": "Rock_Aqua_Brick"
    },
    {
      "x": 1,
      "y": 7,
      "z": 1,
      "name": "Rock_Aqua_Brick_Smooth_Half",
      "rotation": 8
    },
    {
      "x": 1,
      "y": 0,
      "z": 2,
      "name": "Rock_Aqua_Brick"
    },
    {
      "x": 1,
      "y": 7,
      "z": 2,
      "name": "Rock_Aqua_Brick_Smooth_Half"
    },
    {
      "x": 1,
      "y": 0,
      "z": 3,
      "name": "Rock_Aqua_Brick"
    },
    {
      "x": 1,
      "y": 6,
      "z": 3,
      "name": "Rock_Aqua_Brick_Smooth_Half",
      "rotation": 8
    },
    {
      "x": 2,
      "y": 6,
      "z": -3,
      "name": "Rock_Aqua_Brick_Smooth_Half",
      "rotation": 8
    },
    {
      "x": 2,
      "y": 0,
      "z": -2,
      "name": "Rock_Aqua_Brick"
    },
    {
      "x": 2,
      "y": 1,
      "z": -2,
      "name": "Rock_Aqua_Brick_Pillar_Base"
    },
    {
      "x": 2,
      "y": 2,
      "z": -2,
      "name": "Rock_Aqua_Brick_Pillar_Middle"
    },
    {
      "x": 2,
      "y": 3,
      "z": -2,
      "name": "Rock_Aqua_Brick_Beam"
    },
    {
      "x": 2,
      "y": 4,
      "z": -2,
      "name": "Rock_Aqua_Brick_Beam"
    },
    {
      "x": 2,
      "y": 5,
      "z": -2,
      "name": "Rock_Aqua_Brick_Pillar_Middle"
    },
    {
      "x": 2,
      "y": 6,
      "z": -2,
      "name": "Rock_Aqua_Brick_Pillar_Base",
      "rotation": 8
    },
    {
      "x": 2,
      "y": 7,
      "z": -2,
      "name": "Rock_Aqua_Brick_Smooth_Half"
    },
    {
      "x": 2,
      "y": 0,
      "z": -1,
      "name": "Rock_Aqua_Brick"
    },
    {
      "x": 2,
      "y": 7,
      "z": -1,
      "name": "Rock_Aqua_Brick_Smooth_Half"
    },
    {
      "x": 2,
      "y": 0,
      "z": 0,
      "name": "Rock_Aqua_Brick"
    },
    {
      "x": 2,
      "y": 7,
      "z": 0,
      "name": "Rock_Aqua_Brick_Smooth"
    },
    {
      "x": 2,
      "y": 0,
      "z": 1,
      "name": "Rock_Aqua_Brick"
    },
    {
      "x": 2,
      "y": 7,
      "z": 1,
      "name": "Rock_Aqua_Brick_Smooth_Half"
    },
    {
      "x": 2,
      "y": 0,
      "z": 2,
      "name": "Rock_Aqua_Brick"
    },
    {
      "x": 2,
      "y": 1,
      "z": 2,
      "name": "Rock_Aqua_Brick_Pillar_Base"
    },
    {
      "x": 2,
      "y": 2,
      "z": 2,
      "name": "Rock_Aqua_Brick_Pillar_Middle"
    },
    {
      "x": 2,
      "y": 3,
      "z": 2,
      "name": "Rock_Aqua_Brick_Beam"
    },
    {
      "x": 2,
      "y": 4,
      "z": 2,
      "name": "Rock_Aqua_Brick_Beam"
    },
    {
      "x": 2,
      "y": 5,
      "z": 2,
      "name": "Rock_Aqua_Brick_Pillar_Middle"
    },
    {
      "x": 2,
      "y": 6,
      "z": 2,
      "name": "Rock_Aqua_Brick_Pillar_Base",
      "rotation": 8
    },
    {
      "x": 2,
      "y": 7,
      "z": 2,
      "name": "Rock_Aqua_Brick_Smooth_Half"
    },
    {
      "x": 2,
      "y": 6,
      "z": 3,
      "name": "Rock_Aqua_Brick_Smooth_Half",
      "rotation": 8
    },
    {
      "x": 3,
      "y": 6,
      "z": -2,
      "name": "Rock_Aqua_Brick_Smooth_Half",
      "rotation": 8
    },
    {
      "x": 3,
      "y": 6,
      "z": -1,
      "name": "Rock_Aqua_Brick_Smooth_Half",
      "rotation": 8
    },
    {
      "x": 3,
      "y": 6,
      "z": 0,
      "name": "Rock_Aqua_Brick_Smooth_Half",
      "rotation": 8
    },
    {
      "x": 3,
      "y": 7,
      "z": 0,
      "name": "Rock_Aqua_Brick_Smooth_Half"
    },
    {
      "x": 3,
      "y": 6,
      "z": 1,
      "name": "Rock_Aqua_Brick_Smooth_Half",
      "rotation": 8
    },
    {
      "x": 3,
      "y": 6,
      "z": 2,
      "name": "Rock_Aqua_Brick_Smooth_Half",
      "rotation": 8
    }
  ],
  "fluids": [
    {
      "x": -3,
      "y": 6,
      "z": -2,
      "name": "Empty",
      "level": 0
    },
    {
      "x": -3,
      "y": 6,
      "z": -1,
      "name": "Empty",
      "level": 0
    },
    {
      "x": -3,
      "y": 6,
      "z": 0,
      "name": "Empty",
      "level": 0
    },
    {
      "x": -3,
      "y": 7,
      "z": 0,
      "name": "Empty",
      "level": 0
    },
    {
      "x": -3,
      "y": 6,
      "z": 1,
      "name": "Empty",
      "level": 0
    },
    {
      "x": -3,
      "y": 6,
      "z": 2,
      "name": "Empty",
      "level": 0
    },
    {
      "x": -2,
      "y": 6,
      "z": -3,
      "name": "Empty",
      "level": 0
    },
    {
      "x": -2,
      "y": 0,
      "z": -2,
      "name": "Empty",
      "level": 0
    },
    {
      "x": -2,
      "y": 1,
      "z": -2,
      "name": "Empty",
      "level": 0
    },
    {
      "x": -2,
      "y": 2,
      "z": -2,
      "name": "Empty",
      "level": 0
    },
    {
      "x": -2,
      "y": 3,
      "z": -2,
      "name": "Empty",
      "level": 0
    },
    {
      "x": -2,
      "y": 4,
      "z": -2,
      "name": "Empty",
      "level": 0
    },
    {
      "x": -2,
      "y": 5,
      "z": -2,
      "name": "Empty",
      "level": 0
    },
    {
      "x": -2,
      "y": 6,
      "z": -2,
      "name": "Empty",
      "level": 0
    },
    {
      "x": -2,
      "y": 7,
      "z": -2,
      "name": "Empty",
      "level": 0
    },
    {
      "x": -2,
      "y": 0,
      "z": -1,
      "name": "Empty",
      "level": 0
    },
    {
      "x": -2,
      "y": 7,
      "z": -1,
      "name": "Empty",
      "level": 0
    },
    {
      "x": -2,
      "y": 0,
      "z": 0,
      "name": "Empty",
      "level": 0
    },
    {
      "x": -2,
      "y": 7,
      "z": 0,
      "name": "Empty",
      "level": 0
    },
    {
      "x": -2,
      "y": 0,
      "z": 1,
      "name": "Empty",
      "level": 0
    },
    {
      "x": -2,
      "y": 7,
      "z": 1,
      "name": "Empty",
      "level": 0
    },
    {
      "x": -2,
      "y": 0,
      "z": 2,
      "name": "Empty",
      "level": 0
    },
    {
      "x": -2,
      "y": 1,
      "z": 2,
      "name": "Empty",
      "level": 0
    },
    {
      "x": -2,
      "y": 2,
      "z": 2,
      "name": "Empty",
      "level": 0
    },
    {
      "x": -2,
      "y": 3,
      "z": 2,
      "name": "Empty",
      "level": 0
    },
    {
      "x": -2,
      "y": 4,
      "z": 2,
      "name": "Empty",
      "level": 0
    },
    {
      "x": -2,
      "y": 5,
      "z": 2,
      "name": "Empty",
      "level": 0
    },
    {
      "x": -2,
      "y": 6,
      "z": 2,
      "name": "Empty",
      "level": 0
    },
    {
      "x": -2,
      "y": 7,
      "z": 2,
      "name": "Empty",
      "level": 0
    },
    {
      "x": -2,
      "y": 6,
      "z": 3,
      "name": "Empty",
      "level": 0
    },
    {
      "x": -1,
      "y": 0,
      "z": -3,
      "name": "Empty",
      "level": 0
    },
    {
      "x": -1,
      "y": 6,
      "z": -3,
      "name": "Empty",
      "level": 0
    },
    {
      "x": -1,
      "y": 0,
      "z": -2,
      "name": "Empty",
      "level": 0
    },
    {
      "x": -1,
      "y": 7,
      "z": -2,
      "name": "Empty",
      "level": 0
    },
    {
      "x": -1,
      "y": 0,
      "z": -1,
      "name": "Empty",
      "level": 0
    },
    {
      "x": -1,
      "y": 7,
      "z": -1,
      "name": "Empty",
      "level": 0
    },
    {
      "x": -1,
      "y": 0,
      "z": 0,
      "name": "Empty",
      "level": 0
    },
    {
      "x": -1,
      "y": 7,
      "z": 0,
      "name": "Empty",
      "level": 0
    },
    {
      "x": -1,
      "y": 8,
      "z": 0,
      "name": "Empty",
      "level": 0
    },
    {
      "x": -1,
      "y": 0,
      "z": 1,
      "name": "Empty",
      "level": 0
    },
    {
      "x": -1,
      "y": 7,
      "z": 1,
      "name": "Empty",
      "level": 0
    },
    {
      "x": -1,
      "y": 0,
      "z": 2,
      "name": "Empty",
      "level": 0
    },
    {
      "x": -1,
      "y": 7,
      "z": 2,
      "name": "Empty",
      "level": 0
    },
    {
      "x": -1,
      "y": 0,
      "z": 3,
      "name": "Empty",
      "level": 0
    },
    {
      "x": -1,
      "y": 6,
      "z": 3,
      "name": "Empty",
      "level": 0
    },
    {
      "x": 0,
      "y": 0,
      "z": -3,
      "name": "Empty",
      "level": 0
    },
    {
      "x": 0,
      "y": 6,
      "z": -3,
      "name": "Empty",
      "level": 0
    },
    {
      "x": 0,
      "y": 7,
      "z": -3,
      "name": "Empty",
      "level": 0
    },
    {
      "x": 0,
      "y": 0,
      "z": -2,
      "name": "Empty",
      "level": 0
    },
    {
      "x": 0,
      "y": 7,
      "z": -2,
      "name": "Empty",
      "level": 0
    },
    {
      "x": 0,
      "y": 0,
      "z": -1,
      "name": "Empty",
      "level": 0
    },
    {
      "x": 0,
      "y": 7,
      "z": -1,
      "name": "Empty",
      "level": 0
    },
    {
      "x": 0,
      "y": 8,
      "z": -1,
      "name": "Empty",
      "level": 0
    },
    {
      "x": 0,
      "y": 0,
      "z": 0,
      "name": "Empty",
      "level": 0
    },
    {
      "x": 0,
      "y": 1,
      "z": 0,
      "name": "Empty",
      "level": 0
    },
    {
      "x": 0,
      "y": 2,
      "z": 0,
      "name": "Empty",
      "level": 0
    },
    {
      "x": 0,
      "y": 3,
      "z": 0,
      "name": "Empty",
      "level": 0
    },
    {
      "x": 0,
      "y": 4,
      "z": 0,
      "name": "Empty",
      "level": 0
    },
    {
      "x": 0,
      "y": 7,
      "z": 0,
      "name": "Empty",
      "level": 0
    },
    {
      "x": 0,
      "y": 8,
      "z": 0,
      "name": "Empty",
      "level": 0
    },
    {
      "x": 0,
      "y": 9,
      "z": 0,
      "name": "Empty",
      "level": 0
    },
    {
      "x": 0,
      "y": 10,
      "z": 0,
      "name": "Empty",
      "level": 0
    },
    {
      "x": 0,
      "y": 11,
      "z": 0,
      "name": "Empty",
      "level": 0
    },
    {
      "x": 0,
      "y": 12,
      "z": 0,
      "name": "Empty",
      "level": 0
    },
    {
      "x": 0,
      "y": 0,
      "z": 1,
      "name": "Empty",
      "level": 0
    },
    {
      "x": 0,
      "y": 7,
      "z": 1,
      "name": "Empty",
      "level": 0
    },
    {
      "x": 0,
      "y": 8,
      "z": 1,
      "name": "Empty",
      "level": 0
    },
    {
      "x": 0,
      "y": 0,
      "z": 2,
      "name": "Empty",
      "level": 0
    },
    {
      "x": 0,
      "y": 7,
      "z": 2,
      "name": "Empty",
      "level": 0
    },
    {
      "x": 0,
      "y": 0,
      "z": 3,
      "name": "Empty",
      "level": 0
    },
    {
      "x": 0,
      "y": 6,
      "z": 3,
      "name": "Empty",
      "level": 0
    },
    {
      "x": 0,
      "y": 7,
      "z": 3,
      "name": "Empty",
      "level": 0
    },
    {
      "x": 1,
      "y": 0,
      "z": -3,
      "name": "Empty",
      "level": 0
    },
    {
      "x": 1,
      "y": 6,
      "z": -3,
      "name": "Empty",
      "level": 0
    },
    {
      "x": 1,
      "y": 0,
      "z": -2,
      "name": "Empty",
      "level": 0
    },
    {
      "x": 1,
      "y": 7,
      "z": -2,
      "name": "Empty",
      "level": 0
    },
    {
      "x": 1,
      "y": 0,
      "z": -1,
      "name": "Empty",
      "level": 0
    },
    {
      "x": 1,
      "y": 7,
      "z": -1,
      "name": "Empty",
      "level": 0
    },
    {
      "x": 1,
      "y": 0,
      "z": 0,
      "name": "Empty",
      "level": 0
    },
    {
      "x": 1,
      "y": 7,
      "z": 0,
      "name": "Empty",
      "level": 0
    },
    {
      "x": 1,
      "y": 8,
      "z": 0,
      "name": "Empty",
      "level": 0
    },
    {
      "x": 1,
      "y": 0,
      "z": 1,
      "name": "Empty",
      "level": 0
    },
    {
      "x": 1,
      "y": 7,
      "z": 1,
      "name": "Empty",
      "level": 0
    },
    {
      "x": 1,
      "y": 0,
      "z": 2,
      "name": "Empty",
      "level": 0
    },
    {
      "x": 1,
      "y": 7,
      "z": 2,
      "name": "Empty",
      "level": 0
    },
    {
      "x": 1,
      "y": 0,
      "z": 3,
      "name": "Empty",
      "level": 0
    },
    {
      "x": 1,
      "y": 6,
      "z": 3,
      "name": "Empty",
      "level": 0
    },
    {
      "x": 2,
      "y": 6,
      "z": -3,
      "name": "Empty",
      "level": 0
    },
    {
      "x": 2,
      "y": 0,
      "z": -2,
      "name": "Empty",
      "level": 0
    },
    {
      "x": 2,
      "y": 1,
      "z": -2,
      "name": "Empty",
      "level": 0
    },
    {
      "x": 2,
      "y": 2,
      "z": -2,
      "name": "Empty",
      "level": 0
    },
    {
      "x": 2,
      "y": 3,
      "z": -2,
      "name": "Empty",
      "level": 0
    },
    {
      "x": 2,
      "y": 4,
      "z": -2,
      "name": "Empty",
      "level": 0
    },
    {
      "x": 2,
      "y": 5,
      "z": -2,
      "name": "Empty",
      "level": 0
    },
    {
      "x": 2,
      "y": 6,
      "z": -2,
      "name": "Empty",
      "level": 0
    },
    {
      "x": 2,
      "y": 7,
      "z": -2,
      "name": "Empty",
      "level": 0
    },
    {
      "x": 2,
      "y": 0,
      "z": -1,
      "name": "Empty",
      "level": 0
    },
    {
      "x": 2,
      "y": 7,
      "z": -1,
      "name": "Empty",
      "level": 0
    },
    {
      "x": 2,
      "y": 0,
      "z": 0,
      "name": "Empty",
      "level": 0
    },
    {
      "x": 2,
      "y": 7,
      "z": 0,
      "name": "Empty",
      "level": 0
    },
    {
      "x": 2,
      "y": 0,
      "z": 1,
      "name": "Empty",
      "level": 0
    },
    {
      "x": 2,
      "y": 7,
      "z": 1,
      "name": "Empty",
      "level": 0
    },
    {
      "x": 2,
      "y": 0,
      "z": 2,
      "name": "Empty",
      "level": 0
    },
    {
      "x": 2,
      "y": 1,
      "z": 2,
      "name": "Empty",
      "level": 0
    },
    {
      "x": 2,
      "y": 2,
      "z": 2,
      "name": "Empty",
      "level": 0
    },
    {
      "x": 2,
      "y": 3,
      "z": 2,
      "name": "Empty",
      "level": 0
    },
    {
      "x": 2,
      "y": 4,
      "z": 2,
      "name": "Empty",
      "level": 0
    },
    {
      "x": 2,
      "y": 5,
      "z": 2,
      "name": "Empty",
      "level": 0
    },
    {
      "x": 2,
      "y": 6,
      "z": 2,
      "name": "Empty",
      "level": 0
    },
    {
      "x": 2,
      "y": 7,
      "z": 2,
      "name": "Empty",
      "level": 0
    },
    {
      "x": 2,
      "y": 6,
      "z": 3,
      "name": "Empty",
      "level": 0
    },
    {
      "x": 3,
      "y": 6,
      "z": -2,
      "name": "Empty",
      "level": 0
    },
    {
      "x": 3,
      "y": 6,
      "z": -1,
      "name": "Empty",
      "level": 0
    },
    {
      "x": 3,
      "y": 6,
      "z": 0,
      "name": "Empty",
      "level": 0
    },
    {
      "x": 3,
      "y": 7,
      "z": 0,
      "name": "Empty",
      "level": 0
    },
    {
      "x": 3,
      "y": 6,
      "z": 1,
      "name": "Empty",
      "level": 0
    },
    {
      "x": 3,
      "y": 6,
      "z": 2,
      "name": "Empty",
      "level": 0
    }
  ]
}