{
  "version": 8,
  "blockIdVersion": 11,
  "anchorX": 0,
  "anchorY": 0,
  "anchorZ": 0,
  "blocks": [
    {
      "x": -31,
      "y": 43,
      "z": -24,
      "name": "Rock_Stone"
    },
    {
      "x": -31,
      "y": 44,
      "z": -24,
      "name": "Rock_Stone"
    },
    {
      "x": -31,
      "y": 43,
      "z": -23,
      "name": "Rock_Stone"
    },
    {
      "x": -31,
      "y": 44,
      "z": -23,
      "name": "Rock_Stone"
    },
    {
      "x": -31,
      "y": 43,
      "z": -22,
      "name": "Rock_Stone"
    },
    {
      "x": -31,
      "y": 44,
      "z": -22,
      "name": "Rock_Stone"
    },
    {
      "x": -31,
      "y": 44,
      "z": -21,
      "name": "Rock_Stone"
    },
    {
      "x": -30,
      "y": 43,
      "z": -27,
      "name": "Rock_Stone"
    },
    {
      "x": -30,
      "y": 42,
      "z": -26,
      "name": "Rock_Stone"
    },
    {
      "x": -30,
      "y": 43,
      "z": -26,
      "name": "Rock_Stone"
    },
    {
      "x": -30,
      "y": 44,
      "z": -26,
      "name": "Soil_Gravel"
    },
    {
      "x": -30,
      "y": 41,
      "z": -25,
      "name": "Rock_Stone"
    },
    {
      "x": -30,
      "y": 42,
      "z": -25,
      "name": "Rock_Stone"
    },
    {
      "x": -30,
      "y": 43,
      "z": -25,
      "name": "Rock_Stone"
    },
    {
      "x": -30,
      "y": 44,
      "z": -25,
      "name": "Rock_Stone"
    },
    {
      "x": -30,
      "y": 45,
      "z": -25,
      "name": "Soil_Gravel"
    },
    {
      "x": -30,
      "y": 40,
      "z": -24,
      "name": "Rock_Stone"
    },
    {
      "x": -30,
      "y": 41,
      "z": -24,
      "name": "Rock_Stone"
    },
    {
      "x": -30,
      "y": 42,
      "z": -24,
      "name": "Rock_Stone"
    },
    {
      "x": -30,
      "y": 43,
      "z": -24,
      "name": "Rock_Stone"
    },
    {
      "x": -30,
      "y": 44,
      "z": -24,
      "name": "Rock_Stone"
    },
    {
      "x": -30,
      "y": 45,
      "z": -24,
      "name": "Rock_Stone"
    },
    {
      "x": -30,
      "y": 40,
      "z": -23,
      "name": "Rock_Stone"
    },
    {
      "x": -30,
      "y": 41,
      "z": -23,
      "name": "Rock_Stone"
    },
    {
      "x": -30,
      "y": 42,
      "z": -23,
      "name": "Rock_Stone"
    },
    {
      "x": -30,
      "y": 43,
      "z": -23,
      "name": "Rock_Stone"
    },
    {
      "x": -30,
      "y": 44,
      "z": -23,
      "name": "Rock_Stone"
    },
    {
      "x": -30,
      "y": 45,
      "z": -23,
      "name": "Rock_Stone"
    },
    {
      "x": -30,
      "y": 42,
      "z": -22,
      "name": "Rock_Stone"
    },
    {
      "x": -30,
      "y": 43,
      "z": -22,
      "name": "Rock_Stone"
    },
    {
      "x": -30,
      "y": 44,
      "z": -22,
      "name": "Rock_Stone"
    },
    {
      "x": -30,
      "y": 45,
      "z": -22,
      "name": "Rock_Stone"
    },
    {
      "x": -30,
      "y": 42,
      "z": -21,
      "name": "Rock_Stone"
    },
    {
      "x": -30,
      "y": 43,
      "z": -21,
      "name": "Rock_Stone"
    },
    {
      "x": -30,
      "y": 44,
      "z": -21,
      "name": "Rock_Stone"
    },
    {
      "x": -30,
      "y": 45,
      "z": -21,
      "name": "Rock_Stone"
    },
    {
      "x": -30,
      "y": 43,
      "z": -20,
      "name": "Rock_Stone"
    },
    {
      "x": -30,
      "y": 44,
      "z": -20,
      "name": "Rock_Stone"
    },
    {
      "x": -29,
      "y": 41,
      "z": -28,
      "name": "Rock_Stone"
    },
    {
      "x": -29,
      "y": 42,
      "z": -28,
      "name": "Rock_Stone"
    },
    {
      "x": -29,
      "y": 43,
      "z": -28,
      "name": "Rock_Stone"
    },
    {
      "x": -29,
      "y": 44,
      "z": -28,
      "name": "Rock_Stone"
    },
    {
      "x": -29,
      "y": 40,
      "z": -27,
      "name": "Rock_Stone"
    },
    {
      "x": -29,
      "y": 41,
      "z": -27,
      "name": "Rock_Stone"
    },
    {
      "x": -29,
      "y": 42,
      "z": -27,
      "name": "Rock_Stone"
    },
    {
      "x": -29,
      "y": 43,
      "z": -27,
      "name": "Rock_Stone"
    },
    {
      "x": -29,
      "y": 44,
      "z": -27,
      "name": "Soil_Gravel"
    },
    {
      "x": -29,
      "y": 45,
      "z": -27,
      "name": "Soil_Gravel"
    },
    {
      "x": -29,
      "y": 38,
      "z": -26,
      "name": "Rock_Stone"
    },
    {
      "x": -29,
      "y": 39,
      "z": -26,
      "name": "Rock_Stone"
    },
    {
      "x": -29,
      "y": 40,
      "z": -26,
      "name": "Rock_Stone"
    },
    {
      "x": -29,
      "y": 41,
      "z": -26,
      "name": "Rock_Stone"
    },
    {
      "x": -29,
      "y": 42,
      "z": -26,
      "name": "Rock_Stone"
    },
    {
      "x": -29,
      "y": 43,
      "z": -26,
      "name": "Soil_Gravel"
    },
    {
      "x": -29,
      "y": 44,
      "z": -26,
      "name": "Soil_Gravel"
    },
    {
      "x": -29,
      "y": 45,
      "z": -26,
      "name": "Soil_Gravel"
    },
    {
      "x": -29,
      "y": 38,
      "z": -25,
      "name": "Rock_Stone"
    },
    {
      "x": -29,
      "y": 39,
      "z": -25,
      "name": "Rock_Stone"
    },
    {
      "x": -29,
      "y": 40,
      "z": -25,
      "name": "Rock_Stone"
    },
    {
      "x": -29,
      "y": 41,
      "z": -25,
      "name": "Rock_Stone"
    },
    {
      "x": -29,
      "y": 42,
      "z": -25,
      "name": "Rock_Stone"
    },
    {
      "x": -29,
      "y": 43,
      "z": -25,
      "name": "Rock_Stone"
    },
    {
      "x": -29,
      "y": 44,
      "z": -25,
      "name": "Soil_Gravel"
    },
    {
      "x": -29,
      "y": 45,
      "z": -25,
      "name": "Soil_Gravel"
    },
    {
      "x": -29,
      "y": 38,
      "z": -24,
      "name": "Rock_Stone"
    },
    {
      "x": -29,
      "y": 39,
      "z": -24,
      "name": "Rock_Stone"
    },
    {
      "x": -29,
      "y": 40,
      "z": -24,
      "name": "Rock_Stone"
    },
    {
      "x": -29,
      "y": 41,
      "z": -24,
      "name": "Rock_Stone"
    },
    {
      "x": -29,
      "y": 42,
      "z": -24,
      "name": "Rock_Stone"
    },
    {
      "x": -29,
      "y": 43,
      "z": -24,
      "name": "Rock_Stone"
    },
    {
      "x": -29,
      "y": 44,
      "z": -24,
      "name": "Rock_Stone"
    },
    {
      "x": -29,
      "y": 45,
      "z": -24,
      "name": "Soil_Gravel"
    },
    {
      "x": -29,
      "y": 39,
      "z": -23,
      "name": "Rock_Stone"
    },
    {
      "x": -29,
      "y": 40,
      "z": -23,
      "name": "Rock_Stone"
    },
    {
      "x": -29,
      "y": 41,
      "z": -23,
      "name": "Rock_Stone"
    },
    {
      "x": -29,
      "y": 42,
      "z": -23,
      "name": "Rock_Stone"
    },
    {
      "x": -29,
      "y": 43,
      "z": -23,
      "name": "Rock_Stone"
    },
    {
      "x": -29,
      "y": 44,
      "z": -23,
      "name": "Rock_Stone"
    },
    {
      "x": -29,
      "y": 45,
      "z": -23,
      "name": "Rock_Stone"
    },
    {
      "x": -29,
      "y": 46,
      "z": -23,
      "name": "Rock_Stone"
    },
    {
      "x": -29,
      "y": 39,
      "z": -22,
      "name": "Rock_Stone"
    },
    {
      "x": -29,
      "y": 40,
      "z": -22,
      "name": "Rock_Stone"
    },
    {
      "x": -29,
      "y": 41,
      "z": -22,
      "name": "Rock_Stone"
    },
    {
      "x": -29,
      "y": 42,
      "z": -22,
      "name": "Rock_Stone"
    },
    {
      "x": -29,
      "y": 43,
      "z": -22,
      "name": "Rock_Stone"
    },
    {
      "x": -29,
      "y": 44,
      "z": -22,
      "name": "Rock_Stone"
    },
    {
      "x": -29,
      "y": 45,
      "z": -22,
      "name": "Rock_Stone"
    },
    {
      "x": -29,
      "y": 46,
      "z": -22,
      "name": "Rock_Stone"
    },
    {
      "x": -29,
      "y": 38,
      "z": -21,
      "name": "Rock_Stone"
    },
    {
      "x": -29,
      "y": 39,
      "z": -21,
      "name": "Rock_Stone"
    },
    {
      "x": -29,
      "y": 40,
      "z": -21,
      "name": "Rock_Stone"
    },
    {
      "x": -29,
      "y": 41,
      "z": -21,
      "name": "Rock_Stone"
    },
    {
      "x": -29,
      "y": 42,
      "z": -21,
      "name": "Rock_Stone"
    },
    {
      "x": -29,
      "y": 43,
      "z": -21,
      "name": "Rock_Stone"
    },
    {
      "x": -29,
      "y": 44,
      "z": -21,
      "name": "Rock_Stone"
    },
    {
      "x": -29,
      "y": 45,
      "z": -21,
      "name": "Rock_Stone"
    },
    {
      "x": -29,
      "y": 46,
      "z": -21,
      "name": "Rock_Stone"
    },
    {
      "x": -29,
      "y": 37,
      "z": -20,
      "name": "Rock_Stone"
    },
    {
      "x": -29,
      "y": 38,
      "z": -20,
      "name": "Rock_Stone"
    },
    {
      "x": -29,
      "y": 39,
      "z": -20,
      "name": "Rock_Stone"
    },
    {
      "x": -29,
      "y": 40,
      "z": -20,
      "name": "Rock_Stone"
    },
    {
      "x": -29,
      "y": 41,
      "z": -20,
      "name": "Rock_Stone"
    },
    {
      "x": -29,
      "y": 42,
      "z": -20,
      "name": "Rock_Stone"
    },
    {
      "x": -29,
      "y": 43,
      "z": -20,
      "name": "Rock_Stone"
    },
    {
      "x": -29,
      "y": 44,
      "z": -20,
      "name": "Rock_Stone"
    },
    {
      "x": -29,
      "y": 45,
      "z": -20,
      "name": "Rock_Stone"
    },
    {
      "x": -29,
      "y": 39,
      "z": -19,
      "name": "Rock_Stone"
    },
    {
      "x": -29,
      "y": 40,
      "z": -19,
      "name": "Rock_Stone"
    },
    {
      "x": -29,
      "y": 41,
      "z": -19,
      "name": "Rock_Stone"
    },
    {
      "x": -29,
      "y": 42,
      "z": -19,
      "name": "Rock_Stone"
    },
    {
      "x": -29,
      "y": 43,
      "z": -19,
      "name": "Rock_Stone"
    },
    {
      "x": -29,
      "y": 44,
      "z": -19,
      "name": "Rock_Stone"
    },
    {
      "x": -29,
      "y": 59,
      "z": -15,
      "name": "Rock_Quartzite_Brick_Smooth"
    },
    {
      "x": -29,
      "y": 60,
      "z": -15,
      "name": "Rock_Quartzite_Brick_Smooth"
    },
    {
      "x": -29,
      "y": 59,
      "z": -14,
      "name": "Rock_Quartzite_Brick_Smooth"
    },
    {
      "x": -29,
      "y": 60,
      "z": -14,
      "name": "Rock_Quartzite_Brick_Smooth"
    },
    {
      "x": -29,
      "y": 59,
      "z": -13,
      "name": "Rock_Quartzite_Brick_Smooth"
    },
    {
      "x": -29,
      "y": 60,
      "z": -13,
      "name": "Rock_Quartzite_Brick_Smooth"
    },
    {
      "x": -29,
      "y": 61,
      "z": -13,
      "name": "Rock_Stone_Brick_Wall",
      "rotation": 1
    },
    {
      "x": -29,
      "y": 59,
      "z": -12,
      "name": "Rock_Quartzite_Brick_Smooth"
    },
    {
      "x": -29,
      "y": 60,
      "z": -12,
      "name": "Rock_Quartzite_Brick_Smooth"
    },
    {
      "x": -29,
      "y": 61,
      "z": -12,
      "name": "Rock_Stone_Brick_Wall",
      "rotation": 1
    },
    {
      "x": -29,
      "y": 59,
      "z": -11,
      "name": "Rock_Quartzite_Brick_Smooth"
    },
    {
      "x": -29,
      "y": 60,
      "z": -11,
      "name": "Rock_Quartzite_Brick_Smooth"
    },
    {
      "x": -29,
      "y": 61,
      "z": -11,
      "name": "Rock_Stone_Brick_Wall",
      "rotation": 1
    },
    {
      "x": -28,
      "y": 39,
      "z": -28,
      "name": "Rock_Stone"
    },
    {
      "x": -28,
      "y": 40,
      "z": -28,
      "name": "Rock_Stone"
    },
    {
      "x": -28,
      "y": 41,
      "z": -28,
      "name": "Rock_Stone"
    },
    {
      "x": -28,
      "y": 42,
      "z": -28,
      "name": "Rock_Stone"
    },
    {
      "x": -28,
      "y": 43,
      "z": -28,
      "name": "Rock_Stone"
    },
    {
      "x": -28,
      "y": 44,
      "z": -28,
      "name": "Soil_Gravel"
    },
    {
      "x": -28,
      "y": 38,
      "z": -27,
      "name": "Rock_Stone"
    },
    {
      "x": -28,
      "y": 39,
      "z": -27,
      "name": "Rock_Stone"
    },
    {
      "x": -28,
      "y": 40,
      "z": -27,
      "name": "Rock_Stone"
    },
    {
      "x": -28,
      "y": 41,
      "z": -27,
      "name": "Rock_Stone"
    },
    {
      "x": -28,
      "y": 42,
      "z": -27,
      "name": "Rock_Stone"
    },
    {
      "x": -28,
      "y": 43,
      "z": -27,
      "name": "Soil_Gravel"
    },
    {
      "x": -28,
      "y": 44,
      "z": -27,
      "name": "Soil_Gravel"
    },
    {
      "x": -28,
      "y": 45,
      "z": -27,
      "name": "Soil_Gravel"
    },
    {
      "x": -28,
      "y": 57,
      "z": -27,
      "name": "Rock_Quartzite_Brick_Smooth"
    },
    {
      "x": -28,
      "y": 58,
      "z": -27,
      "name": "Rock_Quartzite_Brick_Smooth"
    },
    {
      "x": -28,
      "y": 37,
      "z": -26,
      "name": "Rock_Stone"
    },
    {
      "x": -28,
      "y": 38,
      "z": -26,
      "name": "Rock_Stone"
    },
    {
      "x": -28,
      "y": 39,
      "z": -26,
      "name": "Rock_Stone"
    },
    {
      "x": -28,
      "y": 40,
      "z": -26,
      "name": "Rock_Stone"
    },
    {
      "x": -28,
      "y": 41,
      "z": -26,
      "name": "Rock_Stone"
    },
    {
      "x": -28,
      "y": 42,
      "z": -26,
      "name": "Rock_Stone"
    },
    {
      "x": -28,
      "y": 43,
      "z": -26,
      "name": "Soil_Gravel"
    },
    {
      "x": -28,
      "y": 44,
      "z": -26,
      "name": "Soil_Gravel"
    },
    {
      "x": -28,
      "y": 45,
      "z": -26,
      "name": "Soil_Gravel"
    },
    {
      "x": -28,
      "y": 57,
      "z": -26,
      "name": "Rock_Quartzite_Brick_Smooth"
    },
    {
      "x": -28,
      "y": 58,
      "z": -26,
      "name": "Rock_Quartzite_Brick_Smooth"
    },
    {
      "x": -28,
      "y": 36,
      "z": -25,
      "name": "Rock_Stone"
    },
    {
      "x": -28,
      "y": 37,
      "z": -25,
      "name": "Rock_Stone"
    },
    {
      "x": -28,
      "y": 38,
      "z": -25,
      "name": "Rock_Stone"
    },
    {
      "x": -28,
      "y": 39,
      "z": -25,
      "name": "Rock_Stone"
    },
    {
      "x": -28,
      "y": 40,
      "z": -25,
      "name": "Rock_Stone"
    },
    {
      "x": -28,
      "y": 41,
      "z": -25,
      "name": "Rock_Stone"
    },
    {
      "x": -28,
      "y": 42,
      "z": -25,
      "name": "Rock_Stone"
    },
    {
      "x": -28,
      "y": 43,
      "z": -25,
      "name": "Soil_Gravel"
    },
    {
      "x": -28,
      "y": 44,
      "z": -25,
      "name": "Soil_Gravel"
    },
    {
      "x": -28,
      "y": 45,
      "z": -25,
      "name": "Rock_Stone"
    },
    {
      "x": -28,
      "y": 46,
      "z": -25,
      "name": "Rock_Stone"
    },
    {
      "x": -28,
      "y": 57,
      "z": -25,
      "name": "Rock_Quartzite_Brick_Smooth"
    },
    {
      "x": -28,
      "y": 58,
      "z": -25,
      "name": "Rock_Quartzite_Brick_Smooth"
    },
    {
      "x": -28,
      "y": 59,
      "z": -25,
      "name": "Rock_Stone_Brick_Wall",
      "rotation": 1
    },
    {
      "x": -28,
      "y": 36,
      "z": -24,
      "name": "Rock_Stone"
    },
    {
      "x": -28,
      "y": 37,
      "z": -24,
      "name": "Rock_Stone"
    },
    {
      "x": -28,
      "y": 38,
      "z": -24,
      "name": "Rock_Stone"
    },
    {
      "x": -28,
      "y": 39,
      "z": -24,
      "name": "Rock_Stone"
    },
    {
      "x": -28,
      "y": 40,
      "z": -24,
      "name": "Rock_Stone"
    },
    {
      "x": -28,
      "y": 41,
      "z": -24,
      "name": "Rock_Stone"
    },
    {
      "x": -28,
      "y": 42,
      "z": -24,
      "name": "Rock_Stone"
    },
    {
      "x": -28,
      "y": 43,
      "z": -24,
      "name": "Rock_Stone"
    },
    {
      "x": -28,
      "y": 44,
      "z": -24,
      "name": "Soil_Gravel"
    },
    {
      "x": -28,
      "y": 45,
      "z": -24,
      "name": "Soil_Gravel"
    },
    {
      "x": -28,
      "y": 46,
      "z": -24,
      "name": "Rock_Stone"
    },
    {
      "x": -28,
      "y": 57,
      "z": -24,
      "name": "Rock_Quartzite_Brick_Smooth"
    },
    {
      "x": -28,
      "y": 58,
      "z": -24,
      "name": "Rock_Quartzite_Brick_Smooth"
    },
    {
      "x": -28,
      "y": 59,
      "z": -24,
      "name": "Rock_Stone_Brick_Wall",
      "rotation": 1
    },
    {
      "x": -28,
      "y": 37,
      "z": -23,
      "name": "Rock_Stone"
    },
    {
      "x": -28,
      "y": 38,
      "z": -23,
      "name": "Rock_Stone"
    },
    {
      "x": -28,
      "y": 39,
      "z": -23,
      "name": "Rock_Stone"
    },
    {
      "x": -28,
      "y": 40,
      "z": -23,
      "name": "Rock_Stone"
    },
    {
      "x": -28,
      "y": 41,
      "z": -23,
      "name": "Rock_Stone"
    },
    {
      "x": -28,
      "y": 42,
      "z": -23,
      "name": "Rock_Stone"
    },
    {
      "x": -28,
      "y": 43,
      "z": -23,
      "name": "Rock_Stone"
    },
    {
      "x": -28,
      "y": 44,
      "z": -23,
      "name": "Rock_Stone"
    },
    {
      "x": -28,
      "y": 45,
      "z": -23,
      "name": "Rock_Stone"
    },
    {
      "x": -28,
      "y": 46,
      "z": -23,
      "name": "Rock_Stone"
    },
    {
      "x": -28,
      "y": 57,
      "z": -23,
      "name": "Rock_Quartzite_Brick_Smooth"
    },
    {
      "x": -28,
      "y": 58,
      "z": -23,
      "name": "Rock_Quartzite_Brick_Smooth"
    },
    {
      "x": -28,
      "y": 59,
      "z": -23,
      "name": "Rock_Stone_Brick_Wall",
      "rotation": 1
    },
    {
      "x": -28,
      "y": 37,
      "z": -22,
      "name": "Rock_Stone"
    },
    {
      "x": -28,
      "y": 38,
      "z": -22,
      "name": "Rock_Stone"
    },
    {
      "x": -28,
      "y": 39,
      "z": -22,
      "name": "Rock_Stone"
    },
    {
      "x": -28,
      "y": 40,
      "z": -22,
      "name": "Rock_Stone"
    },
    {
      "x": -28,
      "y": 41,
      "z": -22,
      "name": "Rock_Stone"
    },
    {
      "x": -28,
      "y": 42,
      "z": -22,
      "name": "Rock_Stone"
    },
    {
      "x": -28,
      "y": 43,
      "z": -22,
      "name": "Rock_Stone"
    },
    {
      "x": -28,
      "y": 44,
      "z": -22,
      "name": "Rock_Stone"
    },
    {
      "x": -28,
      "y": 45,
      "z": -22,
      "name": "Rock_Stone"
    },
    {
      "x": -28,
      "y": 46,
      "z": -22,
      "name": "Rock_Stone"
    },
    {
      "x": -28,
      "y": 57,
      "z": -22,
      "name": "Rock_Quartzite_Brick_Smooth"
    },
    {
      "x": -28,
      "y": 58,
      "z": -22,
      "name": "Rock_Quartzite_Brick_Smooth"
    },
    {
      "x": -28,
      "y": 59,
      "z": -22,
      "name": "Rock_Stone_Brick_Wall",
      "rotation": 1
    },
    {
      "x": -28,
      "y": 36,
      "z": -21,
      "name": "Rock_Stone"
    },
    {
      "x": -28,
      "y": 37,
      "z": -21,
      "name": "Rock_Stone"
    },
    {
      "x": -28,
      "y": 38,
      "z": -21,
      "name": "Rock_Stone"
    },
    {
      "x": -28,
      "y": 39,
      "z": -21,
      "name": "Rock_Stone"
    },
    {
      "x": -28,
      "y": 40,
      "z": -21,
      "name": "Rock_Stone"
    },
    {
      "x": -28,
      "y": 41,
      "z": -21,
      "name": "Rock_Stone"
    },
    {
      "x": -28,
      "y": 42,
      "z": -21,
      "name": "Rock_Stone"
    },
    {
      "x": -28,
      "y": 43,
      "z": -21,
      "name": "Rock_Stone"
    },
    {
      "x": -28,
      "y": 44,
      "z": -21,
      "name": "Rock_Stone"
    },
    {
      "x": -28,
      "y": 45,
      "z": -21,
      "name": "Rock_Stone"
    },
    {
      "x": -28,
      "y": 46,
      "z": -21,
      "name": "Rock_Stone"
    },
    {
      "x": -28,
      "y": 57,
      "z": -21,
      "name": "Rock_Quartzite_Brick_Smooth"
    },
    {
      "x": -28,
      "y": 58,
      "z": -21,
      "name": "Rock_Quartzite_Brick_Smooth"
    },
    {
      "x": -28,
      "y": 59,
      "z": -21,
      "name": "Rock_Stone_Brick_Wall",
      "rotation": 1
    },
    {
      "x": -28,
      "y": 36,
      "z": -20,
      "name": "Rock_Stone"
    },
    {
      "x": -28,
      "y": 37,
      "z": -20,
      "name": "Rock_Stone"
    },
    {
      "x": -28,
      "y": 38,
      "z": -20,
      "name": "Rock_Stone"
    },
    {
      "x": -28,
      "y": 39,
      "z": -20,
      "name": "Rock_Stone"
    },
    {
      "x": -28,
      "y": 40,
      "z": -20,
      "name": "Rock_Stone"
    },
    {
      "x": -28,
      "y": 41,
      "z": -20,
      "name": "Rock_Stone"
    },
    {
      "x": -28,
      "y": 42,
      "z": -20,
      "name": "Rock_Stone"
    },
    {
      "x": -28,
      "y": 43,
      "z": -20,
      "name": "Rock_Stone"
    },
    {
      "x": -28,
      "y": 44,
      "z": -20,
      "name": "Rock_Stone"
    },
    {
      "x": -28,
      "y": 45,
      "z": -20,
      "name": "Rock_Stone"
    },
    {
      "x": -28,
      "y": 46,
      "z": -20,
      "name": "Rock_Stone"
    },
    {
      "x": -28,
      "y": 57,
      "z": -20,
      "name": "Rock_Quartzite_Brick_Smooth"
    },
    {
      "x": -28,
      "y": 58,
      "z": -20,
      "name": "Rock_Quartzite_Brick_Smooth"
    },
    {
      "x": -28,
      "y": 59,
      "z": -20,
      "name": "Rock_Stone_Brick_Wall",
      "rotation": 1
    },
    {
      "x": -28,
      "y": 37,
      "z": -19,
      "name": "Rock_Stone"
    },
    {
      "x": -28,
      "y": 38,
      "z": -19,
      "name": "Rock_Stone"
    },
    {
      "x": -28,
      "y": 39,
      "z": -19,
      "name": "Rock_Stone"
    },
    {
      "x": -28,
      "y": 40,
      "z": -19,
      "name": "Rock_Stone"
    },
    {
      "x": -28,
      "y": 41,
      "z": -19,
      "name": "Rock_Stone"
    },
    {
      "x": -28,
      "y": 42,
      "z": -19,
      "name": "Rock_Stone"
    },
    {
      "x": -28,
      "y": 43,
      "z": -19,
      "name": "Rock_Stone"
    },
    {
      "x": -28,
      "y": 44,
      "z": -19,
      "name": "Rock_Stone"
    },
    {
      "x": -28,
      "y": 45,
      "z": -19,
      "name": "Rock_Stone"
    },
    {
      "x": -28,
      "y": 46,
      "z": -19,
      "name": "Rock_Stone"
    },
    {
      "x": -28,
      "y": 57,
      "z": -19,
      "name": "Rock_Quartzite_Brick_Smooth"
    },
    {
      "x": -28,
      "y": 58,
      "z": -19,
      "name": "Rock_Quartzite_Brick_Smooth"
    },
    {
      "x": -28,
      "y": 38,
      "z": -18,
      "name": "Rock_Stone"
    },
    {
      "x": -28,
      "y": 39,
      "z": -18,
      "name": "Rock_Stone"
    },
    {
      "x": -28,
      "y": 40,
      "z": -18,
      "name": "Rock_Stone"
    },
    {
      "x": -28,
      "y": 41,
      "z": -18,
      "name": "Rock_Stone"
    },
    {
      "x": -28,
      "y": 42,
      "z": -18,
      "name": "Rock_Stone"
    },
    {
      "x": -28,
      "y": 43,
      "z": -18,
      "name": "Rock_Stone"
    },
    {
      "x": -28,
      "y": 44,
      "z": -18,
      "name": "Rock_Stone"
    },
    {
      "x": -28,
      "y": 57,
      "z": -18,
      "name": "Rock_Quartzite_Brick_Smooth"
    },
    {
      "x": -28,
      "y": 59,
      "z": -16,
      "name": "Rock_Quartzite_Brick_Smooth"
    },
    {
      "x": -28,
      "y": 60,
      "z": -16,
      "name": "Rock_Quartzite_Brick_Smooth"
    },
    {
      "x": -28,
      "y": 59,
      "z": -15,
      "name": "Rock_Quartzite_Brick_Smooth"
    },
    {
      "x": -28,
      "y": 60,
      "z": -15,
      "name": "Rock_Quartzite_Brick_Smooth"
    },
    {
      "x": -28,
      "y": 57,
      "z": -14,
      "name": "Rock_Quartzite_Brick"
    },
    {
      "x": -28,
      "y": 58,
      "z": -14,
      "name": "Rock_Quartzite_Brick"
    },
    {
      "x": -28,
      "y": 59,
      "z": -14,
      "name": "Rock_Quartzite_Brick_Smooth"
    },
    {
      "x": -28,
      "y": 60,
      "z": -14,
      "name": "Rock_Quartzite_Brick_Smooth"
    },
    {
      "x": -28,
      "y": 57,
      "z": -13,
      "name": "Rock_Quartzite_Brick"
    },
    {
      "x": -28,
      "y": 58,
      "z": -13,
      "name": "Rock_Quartzite_Brick"
    },
    {
      "x": -28,
      "y": 59,
      "z": -13,
      "name": "Rock_Quartzite_Brick_Smooth"
    },
    {
      "x": -28,
      "y": 60,
      "z": -13,
      "name": "Rock_Quartzite_Brick_Smooth"
    },
    {
      "x": -28,
      "y": 58,
      "z": -12,
      "name": "Rock_Quartzite_Brick"
    },
    {
      "x": -28,
      "y": 59,
      "z": -12,
      "name": "Rock_Quartzite_Brick_Smooth"
    },
    {
      "x": -28,
      "y": 60,
      "z": -12,
      "name": "Rock_Quartzite_Brick_Smooth"
    },
    {
      "x": -28,
      "y": 59,
      "z": -11,
      "name": "Rock_Quartzite_Brick_Smooth"
    },
    {
      "x": -28,
      "y": 60,
      "z": -11,
      "name": "Rock_Quartzite_Brick_Smooth"
    },
    {
      "x": -28,
      "y": 59,
      "z": -10,
      "name": "Plant_Moss_Wall_Green"
    },
    {
      "x": -27,
      "y": 38,
      "z": -28,
      "name": "Rock_Stone"
    },
    {
      "x": -27,
      "y": 39,
      "z": -28,
      "name": "Rock_Stone"
    },
    {
      "x": -27,
      "y": 40,
      "z": -28,
      "name": "Rock_Stone"
    },
    {
      "x": -27,
      "y": 41,
      "z": -28,
      "name": "Rock_Stone"
    },
    {
      "x": -27,
      "y": 42,
      "z": -28,
      "name": "Rock_Stone"
    },
    {
      "x": -27,
      "y": 43,
      "z": -28,
      "name": "Rock_Stone"
    },
    {
      "x": -27,
      "y": 44,
      "z": -28,
      "name": "Soil_Gravel"
    },
    {
      "x": -27,
      "y": 57,
      "z": -28,
      "name": "Rock_Quartzite_Brick_Smooth"
    },
    {
      "x": -27,
      "y": 58,
      "z": -28,
      "name": "Rock_Quartzite_Brick_Smooth"
    },
    {
      "x": -27,
      "y": 35,
      "z": -27,
      "name": "Rock_Stone"
    },
    {
      "x": -27,
      "y": 36,
      "z": -27,
      "name": "Rock_Stone"
    },
    {
      "x": -27,
      "y": 37,
      "z": -27,
      "name": "Rock_Stone"
    },
    {
      "x": -27,
      "y": 38,
      "z": -27,
      "name": "Rock_Stone"
    },
    {
      "x": -27,
      "y": 39,
      "z": -27,
      "name": "Rock_Stone"
    },
    {
      "x": -27,
      "y": 40,
      "z": -27,
      "name": "Rock_Stone"
    },
    {
      "x": -27,
      "y": 41,
      "z": -27,
      "name": "Rock_Stone"
    },
    {
      "x": -27,
      "y": 42,
      "z": -27,
      "name": "Rock_Stone"
    },
    {
      "x": -27,
      "y": 43,
      "z": -27,
      "name": "Soil_Gravel"
    },
    {
      "x": -27,
      "y": 44,
      "z": -27,
      "name": "Soil_Gravel"
    },
    {
      "x": -27,
      "y": 45,
      "z": -27,
      "name": "Soil_Gravel"
    },
    {
      "x": -27,
      "y": 46,
      "z": -27,
      "name": "Rock_Stone_Brick"
    },
    {
      "x": -27,
      "y": 47,
      "z": -27,
      "name": "Rock_Stone_Brick"
    },
    {
      "x": -27,
      "y": 48,
      "z": -27,
      "name": "Rock_Stone_Brick"
    },
    {
      "x": -27,
      "y": 55,
      "z": -27,
      "name": "Rock_Quartzite_Brick"
    },
    {
      "x": -27,
      "y": 56,
      "z": -27,
      "name": "Rock_Quartzite_Brick"
    },
    {
      "x": -27,
      "y": 57,
      "z": -27,
      "name": "Rock_Quartzite_Brick_Smooth"
    },
    {
      "x": -27,
      "y": 58,
      "z": -27,
      "name": "Rock_Quartzite_Brick_Smooth"
    },
    {
      "x": -27,
      "y": 35,
      "z": -26,
      "name": "Rock_Stone"
    },
    {
      "x": -27,
      "y": 36,
      "z": -26,
      "name": "Rock_Stone"
    },
    {
      "x": -27,
      "y": 37,
      "z": -26,
      "name": "Rock_Stone"
    },
    {
      "x": -27,
      "y": 38,
      "z": -26,
      "name": "Rock_Stone"
    },
    {
      "x": -27,
      "y": 39,
      "z": -26,
      "name": "Rock_Stone"
    },
    {
      "x": -27,
      "y": 40,
      "z": -26,
      "name": "Rock_Stone"
    },
    {
      "x": -27,
      "y": 41,
      "z": -26,
      "name": "Rock_Stone"
    },
    {
      "x": -27,
      "y": 42,
      "z": -26,
      "name": "Rock_Stone"
    },
    {
      "x": -27,
      "y": 43,
      "z": -26,
      "name": "Soil_Gravel"
    },
    {
      "x": -27,
      "y": 44,
      "z": -26,
      "name": "Soil_Gravel"
    },
    {
      "x": -27,
      "y": 45,
      "z": -26,
      "name": "Rock_Stone"
    },
    {
      "x": -27,
      "y": 46,
      "z": -26,
      "name": "Rock_Stone_Brick"
    },
    {
      "x": -27,
      "y": 47,
      "z": -26,
      "name": "Rock_Stone_Brick"
    },
    {
      "x": -27,
      "y": 48,
      "z": -26,
      "name": "Rock_Stone_Brick"
    },
    {
      "x": -27,
      "y": 49,
      "z": -26,
      "name": "Rock_Quartzite_Brick"
    },
    {
      "x": -27,
      "y": 50,
      "z": -26,
      "name": "Rock_Quartzite_Brick"
    },
    {
      "x": -27,
      "y": 51,
      "z": -26,
      "name": "Rock_Quartzite_Brick"
    },
    {
      "x": -27,
      "y": 52,
      "z": -26,
      "name": "Rock_Quartzite_Brick"
    },
    {
      "x": -27,
      "y": 53,
      "z": -26,
      "name": "Rock_Quartzite_Brick"
    },
    {
      "x": -27,
      "y": 54,
      "z": -26,
      "name": "Rock_Quartzite_Brick"
    },
    {
      "x": -27,
      "y": 55,
      "z": -26,
      "name": "Rock_Quartzite_Brick"
    },
    {
      "x": -27,
      "y": 56,
      "z": -26,
      "name": "Rock_Quartzite_Brick"
    },
    {
      "x": -27,
      "y": 57,
      "z": -26,
      "name": "Rock_Quartzite_Brick_Smooth"
    },
    {
      "x": -27,
      "y": 58,
      "z": -26,
      "name": "Rock_Quartzite_Brick_Smooth"
    },
    {
      "x": -27,
      "y": 35,
      "z": -25,
      "name": "Rock_Stone"
    },
    {
      "x": -27,
      "y": 36,
      "z": -25,
      "name": "Rock_Stone"
    },
    {
      "x": -27,
      "y": 37,
      "z": -25,
      "name": "Rock_Stone"
    },
    {
      "x": -27,
      "y": 38,
      "z": -25,
      "name": "Rock_Stone"
    },
    {
      "x": -27,
      "y": 39,
      "z": -25,
      "name": "Rock_Stone"
    },
    {
      "x": -27,
      "y": 40,
      "z": -25,
      "name": "Rock_Stone"
    },
    {
      "x": -27,
      "y": 41,
      "z": -25,
      "name": "Rock_Stone"
    },
    {
      "x": -27,
      "y": 42,
      "z": -25,
      "name": "Rock_Stone"
    },
    {
      "x": -27,
      "y": 43,
      "z": -25,
      "name": "Rock_Stone"
    },
    {
      "x": -27,
      "y": 44,
      "z": -25,
      "name": "Rock_Stone"
    },
    {
      "x": -27,
      "y": 45,
      "z": -25,
      "name": "Rock_Stone"
    },
    {
      "x": -27,
      "y": 46,
      "z": -25,
      "name": "Rock_Stone"
    },
    {
      "x": -27,
      "y": 47,
      "z": -25,
      "name": "Rock_Stone_Brick"
    },
    {
      "x": -27,
      "y": 48,
      "z": -25,
      "name": "Rock_Stone_Brick"
    },
    {
      "x": -27,
      "y": 49,
      "z": -25,
      "name": "Rock_Quartzite_Brick"
    },
    {
      "x": -27,
      "y": 50,
      "z": -25,
      "name": "Rock_Quartzite_Brick"
    },
    {
      "x": -27,
      "y": 51,
      "z": -25,
      "name": "Rock_Quartzite_Brick"
    },
    {
      "x": -27,
      "y": 52,
      "z": -25,
      "name": "Rock_Quartzite_Brick"
    },
    {
      "x": -27,
      "y": 53,
      "z": -25,
      "name": "Rock_Quartzite_Brick"
    },
    {
      "x": -27,
      "y": 54,
      "z": -25,
      "name": "Rock_Quartzite_Brick"
    },
    {
      "x": -27,
      "y": 55,
      "z": -25,
      "name": "Rock_Quartzite_Brick"
    },
    {
      "x": -27,
      "y": 56,
      "z": -25,
      "name": "Rock_Quartzite_Brick"
    },
    {
      "x": -27,
      "y": 57,
      "z": -25,
      "name": "Rock_Quartzite_Brick_Smooth"
    },
    {
      "x": -27,
      "y": 58,
      "z": -25,
      "name": "Rock_Quartzite_Brick_Smooth"
    },
    {
      "x": -27,
      "y": 36,
      "z": -24,
      "name": "Rock_Stone"
    },
    {
      "x": -27,
      "y": 37,
      "z": -24,
      "name": "Rock_Stone"
    },
    {
      "x": -27,
      "y": 38,
      "z": -24,
      "name": "Rock_Stone"
    },
    {
      "x": -27,
      "y": 39,
      "z": -24,
      "name": "Rock_Stone"
    },
    {
      "x": -27,
      "y": 40,
      "z": -24,
      "name": "Rock_Stone"
    },
    {
      "x": -27,
      "y": 41,
      "z": -24,
      "name": "Rock_Stone"
    },
    {
      "x": -27,
      "y": 42,
      "z": -24,
      "name": "Rock_Stone"
    },
    {
      "x": -27,
      "y": 43,
      "z": -24,
      "name": "Rock_Stone"
    },
    {
      "x": -27,
      "y": 44,
      "z": -24,
      "name": "Soil_Gravel"
    },
    {
      "x": -27,
      "y": 45,
      "z": -24,
      "name": "Rock_Stone"
    },
    {
      "x": -27,
      "y": 46,
      "z": -24,
      "name": "Rock_Stone"
    },
    {
      "x": -27,
      "y": 47,
      "z": -24,
      "name": "Rock_Stone_Brick"
    },
    {
      "x": -27,
      "y": 55,
      "z": -24,
      "name": "Rock_Quartzite_Brick"
    },
    {
      "x": -27,
      "y": 56,
      "z": -24,
      "name": "Rock_Quartzite_Brick"
    },
    {
      "x": -27,
      "y": 57,
      "z": -24,
      "name": "Rock_Quartzite_Brick_Smooth"
    },
    {
      "x": -27,
      "y": 58,
      "z": -24,
      "name": "Rock_Quartzite_Brick_Smooth"
    },
    {
      "x": -27,
      "y": 36,
      "z": -23,
      "name": "Rock_Stone"
    },
    {
      "x": -27,
      "y": 37,
      "z": -23,
      "name": "Rock_Stone"
    },
    {
      "x": -27,
      "y": 38,
      "z": -23,
      "name": "Rock_Stone"
    },
    {
      "x": -27,
      "y": 39,
      "z": -23,
      "name": "Rock_Stone"
    },
    {
      "x": -27,
      "y": 40,
      "z": -23,
      "name": "Rock_Stone"
    },
    {
      "x": -27,
      "y": 41,
      "z": -23,
      "name": "Rock_Stone"
    },
    {
      "x": -27,
      "y": 42,
      "z": -23,
      "name": "Rock_Stone"
    },
    {
      "x": -27,
      "y": 43,
      "z": -23,
      "name": "Rock_Stone"
    },
    {
      "x": -27,
      "y": 44,
      "z": -23,
      "name": "Rock_Stone"
    },
    {
      "x": -27,
      "y": 45,
      "z": -23,
      "name": "Rock_Stone"
    },
    {
      "x": -27,
      "y": 46,
      "z": -23,
      "name": "Rock_Stone"
    },
    {
      "x": -27,
      "y": 47,
      "z": -23,
      "name": "Rock_Stone_Brick"
    },
    {
      "x": -27,
      "y": 56,
      "z": -23,
      "name": "Rock_Quartzite_Brick"
    },
    {
      "x": -27,
      "y": 57,
      "z": -23,
      "name": "Rock_Quartzite_Brick_Smooth"
    },
    {
      "x": -27,
      "y": 58,
      "z": -23,
      "name": "Rock_Quartzite_Brick_Smooth"
    },
    {
      "x": -27,
      "y": 35,
      "z": -22,
      "name": "Rock_Stone"
    },
    {
      "x": -27,
      "y": 36,
      "z": -22,
      "name": "Rock_Stone"
    },
    {
      "x": -27,
      "y": 37,
      "z": -22,
      "name": "Rock_Stone"
    },
    {
      "x": -27,
      "y": 38,
      "z": -22,
      "name": "Rock_Stone"
    },
    {
      "x": -27,
      "y": 39,
      "z": -22,
      "name": "Rock_Stone"
    },
    {
      "x": -27,
      "y": 40,
      "z": -22,
      "name": "Rock_Stone"
    },
    {
      "x": -27,
      "y": 41,
      "z": -22,
      "name": "Rock_Stone"
    },
    {
      "x": -27,
      "y": 42,
      "z": -22,
      "name": "Rock_Stone"
    },
    {
      "x": -27,
      "y": 43,
      "z": -22,
      "name": "Rock_Stone"
    },
    {
      "x": -27,
      "y": 44,
      "z": -22,
      "name": "Rock_Stone"
    },
    {
      "x": -27,
      "y": 45,
      "z": -22,
      "name": "Rock_Stone"
    },
    {
      "x": -27,
      "y": 46,
      "z": -22,
      "name": "Rock_Stone"
    },
    {
      "x": -27,
      "y": 47,
      "z": -22,
      "name": "Rock_Stone_Brick"
    },
    {
      "x": -27,
      "y": 57,
      "z": -22,
      "name": "Rock_Quartzite_Brick_Smooth"
    },
    {
      "x": -27,
      "y": 58,
      "z": -22,
      "name": "Rock_Quartzite_Brick_Smooth"
    },
    {
      "x": -27,
      "y": 34,
      "z": -21,
      "name": "Rock_Stone"
    },
    {
      "x": -27,
      "y": 35,
      "z": -21,
      "name": "Rock_Stone"
    },
    {
      "x": -27,
      "y": 36,
      "z": -21,
      "name": "Rock_Stone"
    },
    {
      "x": -27,
      "y": 37,
      "z": -21,
      "name": "Rock_Stone"
    },
    {
      "x": -27,
      "y": 38,
      "z": -21,
      "name": "Rock_Stone"
    },
    {
      "x": -27,
      "y": 39,
      "z": -21,
      "name": "Rock_Stone"
    },
    {
      "x": -27,
      "y": 40,
      "z": -21,
      "name": "Rock_Stone"
    },
    {
      "x": -27,
      "y": 41,
      "z": -21,
      "name": "Rock_Stone"
    },
    {
      "x": -27,
      "y": 42,
      "z": -21,
      "name": "Rock_Stone"
    },
    {
      "x": -27,
      "y": 43,
      "z": -21,
      "name": "Rock_Stone"
    },
    {
      "x": -27,
      "y": 44,
      "z": -21,
      "name": "Rock_Stone"
    },
    {
      "x": -27,
      "y": 45,
      "z": -21,
      "name": "Rock_Stone"
    },
    {
      "x": -27,
      "y": 46,
      "z": -21,
      "name": "Rock_Stone"
    },
    {
      "x": -27,
      "y": 47,
      "z": -21,
      "name": "Rock_Stone_Brick"
    },
    {
      "x": -27,
      "y": 48,
      "z": -21,
      "name": "Rock_Stone_Brick"
    },
    {
      "x": -27,
      "y": 56,
      "z": -21,
      "name": "Rock_Quartzite_Brick"
    },
    {
      "x": -27,
      "y": 57,
      "z": -21,
      "name": "Rock_Quartzite_Brick_Smooth"
    },
    {
      "x": -27,
      "y": 58,
      "z": -21,
      "name": "Rock_Quartzite_Brick_Smooth"
    },
    {
      "x": -27,
      "y": 35,
      "z": -20,
      "name": "Rock_Stone"
    },
    {
      "x": -27,
      "y": 36,
      "z": -20,
      "name": "Rock_Stone"
    },
    {
      "x": -27,
      "y": 37,
      "z": -20,
      "name": "Rock_Stone"
    },
    {
      "x": -27,
      "y": 38,
      "z": -20,
      "name": "Rock_Stone"
    },
    {
      "x": -27,
      "y": 39,
      "z": -20,
      "name": "Rock_Stone"
    },
    {
      "x": -27,
      "y": 40,
      "z": -20,
      "name": "Rock_Stone"
    },
    {
      "x": -27,
      "y": 41,
      "z": -20,
      "name": "Rock_Stone"
    },
    {
      "x": -27,
      "y": 42,
      "z": -20,
      "name": "Rock_Stone"
    },
    {
      "x": -27,
      "y": 43,
      "z": -20,
      "name": "Rock_Stone"
    },
    {
      "x": -27,
      "y": 44,
      "z": -20,
      "name": "Rock_Stone"
    },
    {
      "x": -27,
      "y": 45,
      "z": -20,
      "name": "Rock_Stone"
    },
    {
      "x": -27,
      "y": 46,
      "z": -20,
      "name": "Rock_Stone"
    },
    {
      "x": -27,
      "y": 47,
      "z": -20,
      "name": "Rock_Stone_Brick"
    },
    {
      "x": -27,
      "y": 48,
      "z": -20,
      "name": "Rock_Stone_Brick"
    },
    {
      "x": -27,
      "y": 49,
      "z": -20,
      "name": "Plant_Moss_Rug_Green"
    },
    {
      "x": -27,
      "y": 55,
      "z": -20,
      "name": "Rock_Quartzite_Brick"
    },
    {
      "x": -27,
      "y": 56,
      "z": -20,
      "name": "Rock_Quartzite_Brick"
    },
    {
      "x": -27,
      "y": 57,
      "z": -20,
      "name": "Rock_Quartzite_Brick_Smooth"
    },
    {
      "x": -27,
      "y": 58,
      "z": -20,
      "name": "Rock_Quartzite_Brick_Smooth"
    },
    {
      "x": -27,
      "y": 35,
      "z": -19,
      "name": "Rock_Stone"
    },
    {
      "x": -27,
      "y": 36,
      "z": -19,
      "name": "Rock_Stone"
    },
    {
      "x": -27,
      "y": 37,
      "z": -19,
      "name": "Rock_Stone"
    },
    {
      "x": -27,
      "y": 38,
      "z": -19,
      "name": "Rock_Stone"
    },
    {
      "x": -27,
      "y": 39,
      "z": -19,
      "name": "Rock_Stone"
    },
    {
      "x": -27,
      "y": 40,
      "z": -19,
      "name": "Rock_Stone"
    },
    {
      "x": -27,
      "y": 41,
      "z": -19,
      "name": "Rock_Stone"
    },
    {
      "x": -27,
      "y": 42,
      "z": -19,
      "name": "Rock_Stone"
    },
    {
      "x": -27,
      "y": 43,
      "z": -19,
      "name": "Rock_Stone"
    },
    {
      "x": -27,
      "y": 44,
      "z": -19,
      "name": "Rock_Stone"
    },
    {
      "x": -27,
      "y": 45,
      "z": -19,
      "name": "Rock_Stone"
    },
    {
      "x": -27,
      "y": 46,
      "z": -19,
      "name": "Rock_Stone"
    },
    {
      "x": -27,
      "y": 47,
      "z": -19,
      "name": "Rock_Stone_Brick"
    },
    {
      "x": -27,
      "y": 48,
      "z": -19,
      "name": "Rock_Stone_Brick"
    },
    {
      "x": -27,
      "y": 49,
      "z": -19,
      "name": "Rock_Stone_Brick"
    },
    {
      "x": -27,
      "y": 50,
      "z": -19,
      "name": "Rock_Quartzite_Brick"
    },
    {
      "x": -27,
      "y": 53,
      "z": -19,
      "name": "Rock_Quartzite_Brick"
    },
    {
      "x": -27,
      "y": 54,
      "z": -19,
      "name": "Rock_Quartzite_Brick"
    },
    {
      "x": -27,
      "y": 55,
      "z": -19,
      "name": "Rock_Quartzite_Brick"
    },
    {
      "x": -27,
      "y": 56,
      "z": -19,
      "name": "Rock_Quartzite_Brick"
    },
    {
      "x": -27,
      "y": 57,
      "z": -19,
      "name": "Rock_Quartzite_Brick_Smooth"
    },
    {
      "x": -27,
      "y": 58,
      "z": -19,
      "name": "Rock_Quartzite_Brick_Smooth"
    },
    {
      "x": -27,
      "y": 36,
      "z": -18,
      "name": "Rock_Stone"
    },
    {
      "x": -27,
      "y": 37,
      "z": -18,
      "name": "Rock_Stone"
    },
    {
      "x": -27,
      "y": 38,
      "z": -18,
      "name": "Rock_Stone"
    },
    {
      "x": -27,
      "y": 39,
      "z": -18,
      "name": "Rock_Stone"
    },
    {
      "x": -27,
      "y": 40,
      "z": -18,
      "name": "Rock_Stone"
    },
    {
      "x": -27,
      "y": 41,
      "z": -18,
      "name": "Rock_Stone"
    },
    {
      "x": -27,
      "y": 42,
      "z": -18,
      "name": "Rock_Stone"
    },
    {
      "x": -27,
      "y": 43,
      "z": -18,
      "name": "Rock_Stone"
    },
    {
      "x": -27,
      "y": 44,
      "z": -18,
      "name": "Rock_Stone"
    },
    {
      "x": -27,
      "y": 45,
      "z": -18,
      "name": "Rock_Stone"
    },
    {
      "x": -27,
      "y": 46,
      "z": -18,
      "name": "Rock_Stone"
    },
    {
      "x": -27,
      "y": 47,
      "z": -18,
      "name": "Rock_Stone_Brick"
    },
    {
      "x": -27,
      "y": 48,
      "z": -18,
      "name": "Rock_Stone_Brick"
    },
    {
      "x": -27,
      "y": 49,
      "z": -18,
      "name": "Rock_Stone_Brick"
    },
    {
      "x": -27,
      "y": 50,
      "z": -18,
      "name": "Rock_Quartzite_Brick"
    },
    {
      "x": -27,
      "y": 51,
      "z": -18,
      "name": "Rock_Quartzite_Brick"
    },
    {
      "x": -27,
      "y": 54,
      "z": -18,
      "name": "Rock_Quartzite_Brick"
    },
    {
      "x": -27,
      "y": 55,
      "z": -18,
      "name": "Rock_Quartzite_Brick"
    },
    {
      "x": -27,
      "y": 56,
      "z": -18,
      "name": "Rock_Quartzite_Brick"
    },
    {
      "x": -27,
      "y": 57,
      "z": -18,
      "name": "Rock_Quartzite_Brick_Smooth"
    },
    {
      "x": -27,
      "y": 58,
      "z": -18,
      "name": "Rock_Quartzite_Brick_Smooth"
    },
    {
      "x": -27,
      "y": 37,
      "z": -17,
      "name": "Rock_Stone"
    },
    {
      "x": -27,
      "y": 38,
      "z": -17,
      "name": "Rock_Stone"
    },
    {
      "x": -27,
      "y": 39,
      "z": -17,
      "name": "Rock_Stone"
    },
    {
      "x": -27,
      "y": 40,
      "z": -17,
      "name": "Rock_Stone"
    },
    {
      "x": -27,
      "y": 41,
      "z": -17,
      "name": "Rock_Stone"
    },
    {
      "x": -27,
      "y": 42,
      "z": -17,
      "name": "Rock_Stone"
    },
    {
      "x": -27,
      "y": 43,
      "z": -17,
      "name": "Rock_Stone"
    },
    {
      "x": -27,
      "y": 44,
      "z": -17,
      "name": "Rock_Stone"
    },
    {
      "x": -27,
      "y": 45,
      "z": -17,
      "name": "Rock_Stone"
    },
    {
      "x": -27,
      "y": 46,
      "z": -17,
      "name": "Rock_Stone"
    },
    {
      "x": -27,
      "y": 59,
      "z": -16,
      "name": "Rock_Quartzite_Brick_Smooth"
    },
    {
      "x": -27,
      "y": 60,
      "z": -16,
      "name": "Rock_Quartzite_Brick_Smooth"
    },
    {
      "x": -27,
      "y": 59,
      "z": -15,
      "name": "Rock_Quartzite_Brick_Smooth"
    },
    {
      "x": -27,
      "y": 60,
      "z": -15,
      "name": "Rock_Quartzite_Brick_Smooth"
    },
    {
      "x": -27,
      "y": 57,
      "z": -14,
      "name": "Rock_Quartzite_Brick"
    },
    {
      "x": -27,
      "y": 58,
      "z": -14,
      "name": "Rock_Quartzite_Brick"
    },
    {
      "x": -27,
      "y": 59,
      "z": -14,
      "name": "Rock_Quartzite_Brick_Smooth"
    },
    {
      "x": -27,
      "y": 60,
      "z": -14,
      "name": "Rock_Quartzite_Brick_Smooth"
    },
    {
      "x": -27,
      "y": 57,
      "z": -13,
      "name": "Rock_Quartzite_Brick"
    },
    {
      "x": -27,
      "y": 58,
      "z": -13,
      "name": "Rock_Quartzite_Brick"
    },
    {
      "x": -27,
      "y": 59,
      "z": -13,
      "name": "Rock_Quartzite_Brick_Smooth"
    },
    {
      "x": -27,
      "y": 60,
      "z": -13,
      "name": "Rock_Quartzite_Brick_Smooth"
    },
    {
      "x": -27,
      "y": 59,
      "z": -12,
      "name": "Rock_Quartzite_Brick_Smooth"
    },
    {
      "x": -27,
      "y": 60,
      "z": -12,
      "name": "Rock_Quartzite_Brick_Smooth"
    },
    {
      "x": -27,
      "y": 59,
      "z": -11,
      "name": "Plant_Moss_Wall_Green",
      "rotation": 1
    },
    {
      "x": -27,
      "y": 60,
      "z": -11,
      "name": "Plant_Moss_Wall_Green"
    },
    {
      "x": -26,
      "y": 38,
      "z": -28,
      "name": "Rock_Stone"
    },
    {
      "x": -26,
      "y": 39,
      "z": -28,
      "name": "Rock_Stone"
    },
    {
      "x": -26,
      "y": 40,
      "z": -28,
      "name": "Rock_Stone"
    },
    {
      "x": -26,
      "y": 41,
      "z": -28,
      "name": "Rock_Stone"
    },
    {
      "x": -26,
      "y": 42,
      "z": -28,
      "name": "Rock_Stone"
    },
    {
      "x": -26,
      "y": 43,
      "z": -28,
      "name": "Soil_Gravel"
    },
    {
      "x": -26,
      "y": 57,
      "z": -28,
      "name": "Rock_Quartzite_Brick_Smooth"
    },
    {
      "x": -26,
      "y": 58,
      "z": -28,
      "name": "Rock_Quartzite_Brick_Smooth"
    },
    {
      "x": -26,
      "y": 36,
      "z": -27,
      "name": "Rock_Stone"
    },
    {
      "x": -26,
      "y": 37,
      "z": -27,
      "name": "Rock_Stone"
    },
    {
      "x": -26,
      "y": 38,
      "z": -27,
      "name": "Rock_Stone"
    },
    {
      "x": -26,
      "y": 39,
      "z": -27,
      "name": "Rock_Stone"
    },
    {
      "x": -26,
      "y": 40,
      "z": -27,
      "name": "Rock_Stone"
    },
    {
      "x": -26,
      "y": 41,
      "z": -27,
      "name": "Rock_Stone"
    },
    {
      "x": -26,
      "y": 42,
      "z": -27,
      "name": "Rock_Stone"
    },
    {
      "x": -26,
      "y": 43,
      "z": -27,
      "name": "Soil_Gravel"
    },
    {
      "x": -26,
      "y": 44,
      "z": -27,
      "name": "Soil_Gravel"
    },
    {
      "x": -26,
      "y": 45,
      "z": -27,
      "name": "Rock_Stone_Brick"
    },
    {
      "x": -26,
      "y": 46,
      "z": -27,
      "name": "Rock_Stone_Brick"
    },
    {
      "x": -26,
      "y": 47,
      "z": -27,
      "name": "Rock_Stone_Brick"
    },
    {
      "x": -26,
      "y": 48,
      "z": -27,
      "name": "Rock_Stone_Brick"
    },
    {
      "x": -26,
      "y": 55,
      "z": -27,
      "name": "Rock_Quartzite_Brick"
    },
    {
      "x": -26,
      "y": 56,
      "z": -27,
      "name": "Rock_Quartzite_Brick"
    },
    {
      "x": -26,
      "y": 57,
      "z": -27,
      "name": "Rock_Quartzite_Brick_Smooth"
    },
    {
      "x": -26,
      "y": 58,
      "z": -27,
      "name": "Rock_Quartzite_Brick_Smooth"
    },
    {
      "x": -26,
      "y": 34,
      "z": -26,
      "name": "Rock_Stone"
    },
    {
      "x": -26,
      "y": 35,
      "z": -26,
      "name": "Rock_Stone"
    },
    {
      "x": -26,
      "y": 36,
      "z": -26,
      "name": "Rock_Stone"
    },
    {
      "x": -26,
      "y": 37,
      "z": -26,
      "name": "Rock_Stone"
    },
    {
      "x": -26,
      "y": 38,
      "z": -26,
      "name": "Rock_Stone"
    },
    {
      "x": -26,
      "y": 39,
      "z": -26,
      "name": "Rock_Stone"
    },
    {
      "x": -26,
      "y": 40,
      "z": -26,
      "name": "Rock_Stone"
    },
    {
      "x": -26,
      "y": 41,
      "z": -26,
      "name": "Rock_Stone"
    },
    {
      "x": -26,
      "y": 42,
      "z": -26,
      "name": "Rock_Stone"
    },
    {
      "x": -26,
      "y": 43,
      "z": -26,
      "name": "Soil_Gravel"
    },
    {
      "x": -26,
      "y": 44,
      "z": -26,
      "name": "Rock_Stone"
    },
    {
      "x": -26,
      "y": 45,
      "z": -26,
      "name": "Rock_Stone"
    },
    {
      "x": -26,
      "y": 46,
      "z": -26,
      "name": "Rock_Stone_Brick"
    },
    {
      "x": -26,
      "y": 47,
      "z": -26,
      "name": "Rock_Stone_Brick"
    },
    {
      "x": -26,
      "y": 48,
      "z": -26,
      "name": "Rock_Stone_Brick"
    },
    {
      "x": -26,
      "y": 49,
      "z": -26,
      "name": "Rock_Quartzite_Brick"
    },
    {
      "x": -26,
      "y": 50,
      "z": -26,
      "name": "Rock_Quartzite_Brick"
    },
    {
      "x": -26,
      "y": 51,
      "z": -26,
      "name": "Rock_Quartzite_Brick"
    },
    {
      "x": -26,
      "y": 52,
      "z": -26,
      "name": "Rock_Quartzite_Brick"
    },
    {
      "x": -26,
      "y": 53,
      "z": -26,
      "name": "Rock_Quartzite_Brick"
    },
    {
      "x": -26,
      "y": 54,
      "z": -26,
      "name": "Rock_Quartzite_Brick"
    },
    {
      "x": -26,
      "y": 55,
      "z": -26,
      "name": "Rock_Quartzite_Brick"
    },
    {
      "x": -26,
      "y": 56,
      "z": -26,
      "name": "Rock_Quartzite_Brick"
    },
    {
      "x": -26,
      "y": 57,
      "z": -26,
      "name": "Rock_Quartzite_Brick_Smooth"
    },
    {
      "x": -26,
      "y": 58,
      "z": -26,
      "name": "Rock_Quartzite_Brick_Smooth"
    },
    {
      "x": -26,
      "y": 35,
      "z": -25,
      "name": "Rock_Stone"
    },
    {
      "x": -26,
      "y": 36,
      "z": -25,
      "name": "Rock_Stone"
    },
    {
      "x": -26,
      "y": 37,
      "z": -25,
      "name": "Rock_Stone"
    },
    {
      "x": -26,
      "y": 38,
      "z": -25,
      "name": "Rock_Stone"
    },
    {
      "x": -26,
      "y": 39,
      "z": -25,
      "name": "Rock_Stone"
    },
    {
      "x": -26,
      "y": 40,
      "z": -25,
      "name": "Rock_Stone"
    },
    {
      "x": -26,
      "y": 41,
      "z": -25,
      "name": "Rock_Stone"
    },
    {
      "x": -26,
      "y": 42,
      "z": -25,
      "name": "Rock_Stone"
    },
    {
      "x": -26,
      "y": 43,
      "z": -25,
      "name": "Rock_Stone"
    },
    {
      "x": -26,
      "y": 44,
      "z": -25,
      "name": "Soil_Dirt"
    },
    {
      "x": -26,
      "y": 45,
      "z": -25,
      "name": "Soil_Dirt"
    },
    {
      "x": -26,
      "y": 46,
      "z": -25,
      "name": "Soil_Dirt"
    },
    {
      "x": -26,
      "y": 47,
      "z": -25,
      "name": "Rock_Stone_Brick"
    },
    {
      "x": -26,
      "y": 48,
      "z": -25,
      "name": "Rock_Stone_Brick"
    },
    {
      "x": -26,
      "y": 49,
      "z": -25,
      "name": "Rock_Quartzite_Brick"
    },
    {
      "x": -26,
      "y": 50,
      "z": -25,
      "name": "Rock_Quartzite_Brick"
    },
    {
      "x": -26,
      "y": 51,
      "z": -25,
      "name": "Rock_Quartzite_Brick"
    },
    {
      "x": -26,
      "y": 52,
      "z": -25,
      "name": "Rock_Quartzite_Brick"
    },
    {
      "x": -26,
      "y": 53,
      "z": -25,
      "name": "Rock_Quartzite_Brick"
    },
    {
      "x": -26,
      "y": 54,
      "z": -25,
      "name": "Rock_Quartzite_Brick"
    },
    {
      "x": -26,
      "y": 55,
      "z": -25,
      "name": "Rock_Quartzite_Brick"
    },
    {
      "x": -26,
      "y": 56,
      "z": -25,
      "name": "Rock_Quartzite_Brick"
    },
    {
      "x": -26,
      "y": 57,
      "z": -25,
      "name": "Rock_Quartzite_Brick_Smooth"
    },
    {
      "x": -26,
      "y": 58,
      "z": -25,
      "name": "Rock_Quartzite_Brick_Smooth"
    },
    {
      "x": -26,
      "y": 35,
      "z": -24,
      "name": "Rock_Stone"
    },
    {
      "x": -26,
      "y": 36,
      "z": -24,
      "name": "Rock_Stone"
    },
    {
      "x": -26,
      "y": 37,
      "z": -24,
      "name": "Rock_Stone"
    },
    {
      "x": -26,
      "y": 38,
      "z": -24,
      "name": "Rock_Stone"
    },
    {
      "x": -26,
      "y": 39,
      "z": -24,
      "name": "Rock_Stone"
    },
    {
      "x": -26,
      "y": 40,
      "z": -24,
      "name": "Rock_Stone"
    },
    {
      "x": -26,
      "y": 41,
      "z": -24,
      "name": "Rock_Stone"
    },
    {
      "x": -26,
      "y": 42,
      "z": -24,
      "name": "Rock_Stone"
    },
    {
      "x": -26,
      "y": 43,
      "z": -24,
      "name": "Rock_Stone"
    },
    {
      "x": -26,
      "y": 44,
      "z": -24,
      "name": "Soil_Dirt"
    },
    {
      "x": -26,
      "y": 45,
      "z": -24,
      "name": "Soil_Dirt"
    },
    {
      "x": -26,
      "y": 46,
      "z": -24,
      "name": "Soil_Dirt"
    },
    {
      "x": -26,
      "y": 47,
      "z": -24,
      "name": "Rock_Stone_Brick"
    },
    {
      "x": -26,
      "y": 55,
      "z": -24,
      "name": "Rock_Quartzite_Brick"
    },
    {
      "x": -26,
      "y": 57,
      "z": -24,
      "name": "Rock_Quartzite_Brick_Smooth"
    },
    {
      "x": -26,
      "y": 58,
      "z": -24,
      "name": "Rock_Quartzite_Brick_Smooth"
    },
    {
      "x": -26,
      "y": 35,
      "z": -23,
      "name": "Rock_Stone"
    },
    {
      "x": -26,
      "y": 36,
      "z": -23,
      "name": "Rock_Stone"
    },
    {
      "x": -26,
      "y": 37,
      "z": -23,
      "name": "Rock_Stone"
    },
    {
      "x": -26,
      "y": 38,
      "z": -23,
      "name": "Rock_Stone"
    },
    {
      "x": -26,
      "y": 39,
      "z": -23,
      "name": "Rock_Stone"
    },
    {
      "x": -26,
      "y": 40,
      "z": -23,
      "name": "Rock_Stone"
    },
    {
      "x": -26,
      "y": 41,
      "z": -23,
      "name": "Rock_Stone"
    },
    {
      "x": -26,
      "y": 42,
      "z": -23,
      "name": "Rock_Stone"
    },
    {
      "x": -26,
      "y": 43,
      "z": -23,
      "name": "Rock_Stone"
    },
    {
      "x": -26,
      "y": 44,
      "z": -23,
      "name": "Soil_Dirt"
    },
    {
      "x": -26,
      "y": 45,
      "z": -23,
      "name": "Soil_Dirt"
    },
    {
      "x": -26,
      "y": 46,
      "z": -23,
      "name": "Soil_Dirt"
    },
    {
      "x": -26,
      "y": 47,
      "z": -23,
      "name": "Rock_Stone_Brick"
    },
    {
      "x": -26,
      "y": 57,
      "z": -23,
      "name": "Rock_Quartzite_Brick_Smooth"
    },
    {
      "x": -26,
      "y": 58,
      "z": -23,
      "name": "Rock_Quartzite_Brick_Smooth"
    },
    {
      "x": -26,
      "y": 34,
      "z": -22,
      "name": "Rock_Stone"
    },
    {
      "x": -26,
      "y": 35,
      "z": -22,
      "name": "Rock_Stone"
    },
    {
      "x": -26,
      "y": 36,
      "z": -22,
      "name": "Rock_Stone"
    },
    {
      "x": -26,
      "y": 37,
      "z": -22,
      "name": "Rock_Stone"
    },
    {
      "x": -26,
      "y": 38,
      "z": -22,
      "name": "Rock_Stone"
    },
    {
      "x": -26,
      "y": 39,
      "z": -22,
      "name": "Rock_Stone"
    },
    {
      "x": -26,
      "y": 40,
      "z": -22,
      "name": "Rock_Stone"
    },
    {
      "x": -26,
      "y": 41,
      "z": -22,
      "name": "Rock_Stone"
    },
    {
      "x": -26,
      "y": 42,
      "z": -22,
      "name": "Rock_Stone"
    },
    {
      "x": -26,
      "y": 43,
      "z": -22,
      "name": "Rock_Stone"
    },
    {
      "x": -26,
      "y": 44,
      "z": -22,
      "name": "Rock_Stone"
    },
    {
      "x": -26,
      "y": 45,
      "z": -22,
      "name": "Rock_Stone"
    },
    {
      "x": -26,
      "y": 46,
      "z": -22,
      "name": "Rock_Stone"
    },
    {
      "x": -26,
      "y": 47,
      "z": -22,
      "name": "Rock_Stone_Brick"
    },
    {
      "x": -26,
      "y": 48,
      "z": -22,
      "name": "Plant_Moss_Rug_Green"
    },
    {
      "x": -26,
      "y": 57,
      "z": -22,
      "name": "Rock_Quartzite_Brick_Smooth"
    },
    {
      "x": -26,
      "y": 58,
      "z": -22,
      "name": "Rock_Quartzite_Brick_Smooth"
    },
    {
      "x": -26,
      "y": 34,
      "z": -21,
      "name": "Rock_Stone"
    },
    {
      "x": -26,
      "y": 35,
      "z": -21,
      "name": "Rock_Stone"
    },
    {
      "x": -26,
      "y": 36,
      "z": -21,
      "name": "Rock_Stone"
    },
    {
      "x": -26,
      "y": 37,
      "z": -21,
      "name": "Rock_Stone"
    },
    {
      "x": -26,
      "y": 38,
      "z": -21,
      "name": "Rock_Stone"
    },
    {
      "x": -26,
      "y": 39,
      "z": -21,
      "name": "Rock_Stone"
    },
    {
      "x": -26,
      "y": 40,
      "z": -21,
      "name": "Rock_Stone"
    },
    {
      "x": -26,
      "y": 41,
      "z": -21,
      "name": "Rock_Stone"
    },
    {
      "x": -26,
      "y": 42,
      "z": -21,
      "name": "Rock_Stone"
    },
    {
      "x": -26,
      "y": 43,
      "z": -21,
      "name": "Rock_Stone"
    },
    {
      "x": -26,
      "y": 44,
      "z": -21,
      "name": "Rock_Stone"
    },
    {
      "x": -26,
      "y": 45,
      "z": -21,
      "name": "Rock_Stone"
    },
    {
      "x": -26,
      "y": 46,
      "z": -21,
      "name": "Rock_Stone"
    },
    {
      "x": -26,
      "y": 47,
      "z": -21,
      "name": "Rock_Stone_Brick"
    },
    {
      "x": -26,
      "y": 48,
      "z": -21,
      "name": "Plant_Moss_Block_Green"
    },
    {
      "x": -26,
      "y": 49,
      "z": -21,
      "name": "Plant_Moss_Rug_Green"
    },
    {
      "x": -26,
      "y": 55,
      "z": -21,
      "name": "Plant_Moss_Cave_Green",
      "rotation": 8
    },
    {
      "x": -26,
      "y": 56,
      "z": -21,
      "name": "Rock_Quartzite_Brick"
    },
    {
      "x": -26,
      "y": 57,
      "z": -21,
      "name": "Rock_Quartzite_Brick_Smooth"
    },
    {
      "x": -26,
      "y": 58,
      "z": -21,
      "name": "Rock_Quartzite_Brick_Smooth"
    },
    {
      "x": -26,
      "y": 34,
      "z": -20,
      "name": "Rock_Stone"
    },
    {
      "x": -26,
      "y": 35,
      "z": -20,
      "name": "Rock_Stone"
    },
    {
      "x": -26,
      "y": 36,
      "z": -20,
      "name": "Rock_Stone"
    },
    {
      "x": -26,
      "y": 37,
      "z": -20,
      "name": "Rock_Stone"
    },
    {
      "x": -26,
      "y": 38,
      "z": -20,
      "name": "Rock_Stone"
    },
    {
      "x": -26,
      "y": 39,
      "z": -20,
      "name": "Rock_Stone"
    },
    {
      "x": -26,
      "y": 40,
      "z": -20,
      "name": "Rock_Stone"
    },
    {
      "x": -26,
      "y": 41,
      "z": -20,
      "name": "Rock_Stone"
    },
    {
      "x": -26,
      "y": 42,
      "z": -20,
      "name": "Rock_Stone"
    },
    {
      "x": -26,
      "y": 43,
      "z": -20,
      "name": "Rock_Stone"
    },
    {
      "x": -26,
      "y": 44,
      "z": -20,
      "name": "Rock_Stone"
    },
    {
      "x": -26,
      "y": 45,
      "z": -20,
      "name": "Rock_Stone"
    },
    {
      "x": -26,
      "y": 46,
      "z": -20,
      "name": "Rock_Stone"
    },
    {
      "x": -26,
      "y": 47,
      "z": -20,
      "name": "Rock_Stone_Brick"
    },
    {
      "x": -26,
      "y": 48,
      "z": -20,
      "name": "Plant_Moss_Block_Green"
    },
    {
      "x": -26,
      "y": 49,
      "z": -20,
      "name": "Plant_Moss_Rug_Green"
    },
    {
      "x": -26,
      "y": 54,
      "z": -20,
      "name": "Plant_Moss_Cave_Green",
      "rotation": 8
    },
    {
      "x": -26,
      "y": 55,
      "z": -20,
      "name": "Rock_Quartzite_Brick"
    },
    {
      "x": -26,
      "y": 56,
      "z": -20,
      "name": "Rock_Quartzite_Brick"
    },
    {
      "x": -26,
      "y": 57,
      "z": -20,
      "name": "Rock_Quartzite_Brick_Smooth"
    },
    {
      "x": -26,
      "y": 58,
      "z": -20,
      "name": "Rock_Quartzite_Brick_Smooth"
    },
    {
      "x": -26,
      "y": 33,
      "z": -19,
      "name": "Rock_Stone"
    },
    {
      "x": -26,
      "y": 34,
      "z": -19,
      "name": "Rock_Stone"
    },
    {
      "x": -26,
      "y": 35,
      "z": -19,
      "name": "Rock_Stone"
    },
    {
      "x": -26,
      "y": 36,
      "z": -19,
      "name": "Rock_Stone"
    },
    {
      "x": -26,
      "y": 37,
      "z": -19,
      "name": "Rock_Stone"
    },
    {
      "x": -26,
      "y": 38,
      "z": -19,
      "name": "Rock_Stone"
    },
    {
      "x": -26,
      "y": 39,
      "z": -19,
      "name": "Rock_Stone"
    },
    {
      "x": -26,
      "y": 40,
      "z": -19,
      "name": "Rock_Stone"
    },
    {
      "x": -26,
      "y": 41,
      "z": -19,
      "name": "Rock_Stone"
    },
    {
      "x": -26,
      "y": 42,
      "z": -19,
      "name": "Rock_Stone"
    },
    {
      "x": -26,
      "y": 43,
      "z": -19,
      "name": "Rock_Stone"
    },
    {
      "x": -26,
      "y": 44,
      "z": -19,
      "name": "Rock_Stone"
    },
    {
      "x": -26,
      "y": 45,
      "z": -19,
      "name": "Rock_Stone"
    },
    {
      "x": -26,
      "y": 46,
      "z": -19,
      "name": "Rock_Stone"
    },
    {
      "x": -26,
      "y": 47,
      "z": -19,
      "name": "Rock_Stone_Brick"
    },
    {
      "x": -26,
      "y": 48,
      "z": -19,
      "name": "Rock_Stone_Brick"
    },
    {
      "x": -26,
      "y": 49,
      "z": -19,
      "name": "Rock_Stone_Brick"
    },
    {
      "x": -26,
      "y": 50,
      "z": -19,
      "name": "Rock_Quartzite_Brick"
    },
    {
      "x": -26,
      "y": 53,
      "z": -19,
      "name": "Rock_Quartzite_Brick"
    },
    {
      "x": -26,
      "y": 54,
      "z": -19,
      "name": "Rock_Quartzite_Brick"
    },
    {
      "x": -26,
      "y": 55,
      "z": -19,
      "name": "Rock_Quartzite_Brick"
    },
    {
      "x": -26,
      "y": 56,
      "z": -19,
      "name": "Rock_Quartzite_Brick"
    },
    {
      "x": -26,
      "y": 57,
      "z": -19,
      "name": "Rock_Quartzite_Brick_Smooth"
    },
    {
      "x": -26,
      "y": 58,
      "z": -19,
      "name": "Rock_Quartzite_Brick_Smooth"
    },
    {
      "x": -26,
      "y": 35,
      "z": -18,
      "name": "Rock_Stone"
    },
    {
      "x": -26,
      "y": 36,
      "z": -18,
      "name": "Rock_Stone"
    },
    {
      "x": -26,
      "y": 37,
      "z": -18,
      "name": "Rock_Stone"
    },
    {
      "x": -26,
      "y": 38,
      "z": -18,
      "name": "Rock_Stone"
    },
    {
      "x": -26,
      "y": 39,
      "z": -18,
      "name": "Rock_Stone"
    },
    {
      "x": -26,
      "y": 40,
      "z": -18,
      "name": "Rock_Stone"
    },
    {
      "x": -26,
      "y": 41,
      "z": -18,
      "name": "Rock_Stone"
    },
    {
      "x": -26,
      "y": 42,
      "z": -18,
      "name": "Rock_Stone"
    },
    {
      "x": -26,
      "y": 43,
      "z": -18,
      "name": "Rock_Stone"
    },
    {
      "x": -26,
      "y": 44,
      "z": -18,
      "name": "Rock_Stone"
    },
    {
      "x": -26,
      "y": 45,
      "z": -18,
      "name": "Rock_Stone"
    },
    {
      "x": -26,
      "y": 46,
      "z": -18,
      "name": "Rock_Stone"
    },
    {
      "x": -26,
      "y": 47,
      "z": -18,
      "name": "Rock_Stone_Brick"
    },
    {
      "x": -26,
      "y": 48,
      "z": -18,
      "name": "Rock_Stone_Brick"
    },
    {
      "x": -26,
      "y": 49,
      "z": -18,
      "name": "Rock_Stone_Brick"
    },
    {
      "x": -26,
      "y": 50,
      "z": -18,
      "name": "Rock_Quartzite_Brick"
    },
    {
      "x": -26,
      "y": 51,
      "z": -18,
      "name": "Rock_Quartzite_Brick"
    },
    {
      "x": -26,
      "y": 54,
      "z": -18,
      "name": "Rock_Quartzite_Brick"
    },
    {
      "x": -26,
      "y": 55,
      "z": -18,
      "name": "Rock_Quartzite_Brick"
    },
    {
      "x": -26,
      "y": 56,
      "z": -18,
      "name": "Rock_Quartzite_Brick"
    },
    {
      "x": -26,
      "y": 57,
      "z": -18,
      "name": "Rock_Quartzite_Brick_Smooth"
    },
    {
      "x": -26,
      "y": 58,
      "z": -18,
      "name": "Rock_Quartzite_Brick_Smooth"
    },
    {
      "x": -26,
      "y": 59,
      "z": -18,
      "name": "Plant_Moss_Rug_Green"
    },
    {
      "x": -26,
      "y": 36,
      "z": -17,
      "name": "Rock_Stone"
    },
    {
      "x": -26,
      "y": 37,
      "z": -17,
      "name": "Rock_Stone"
    },
    {
      "x": -26,
      "y": 38,
      "z": -17,
      "name": "Rock_Stone"
    },
    {
      "x": -26,
      "y": 39,
      "z": -17,
      "name": "Rock_Stone"
    },
    {
      "x": -26,
      "y": 40,
      "z": -17,
      "name": "Rock_Stone"
    },
    {
      "x": -26,
      "y": 41,
      "z": -17,
      "name": "Rock_Stone"
    },
    {
      "x": -26,
      "y": 42,
      "z": -17,
      "name": "Rock_Stone"
    },
    {
      "x": -26,
      "y": 43,
      "z": -17,
      "name": "Rock_Stone"
    },
    {
      "x": -26,
      "y": 44,
      "z": -17,
      "name": "Rock_Stone"
    },
    {
      "x": -26,
      "y": 45,
      "z": -17,
      "name": "Rock_Stone"
    },
    {
      "x": -26,
      "y": 46,
      "z": -17,
      "name": "Rock_Stone"
    },
    {
      "x": -26,
      "y": 40,
      "z": -16,
      "name": "Rock_Stone"
    },
    {
      "x": -26,
      "y": 41,
      "z": -16,
      "name": "Rock_Stone"
    },
    {
      "x": -26,
      "y": 42,
      "z": -16,
      "name": "Rock_Stone"
    },
    {
      "x": -26,
      "y": 43,
      "z": -16,
      "name": "Rock_Stone"
    },
    {
      "x": -26,
      "y": 44,
      "z": -16,
      "name": "Rock_Stone"
    },
    {
      "x": -26,
      "y": 45,
      "z": -16,
      "name": "Rock_Stone"
    },
    {
      "x": -26,
      "y": 59,
      "z": -15,
      "name": "Rock_Quartzite_Brick_Smooth"
    },
    {
      "x": -26,
      "y": 60,
      "z": -15,
      "name": "Rock_Quartzite_Brick_Smooth"
    },
    {
      "x": -26,
      "y": 61,
      "z": -15,
      "name": "Rock_Stone_Brick_Wall",
      "rotation": 1
    },
    {
      "x": -26,
      "y": 59,
      "z": -14,
      "name": "Rock_Quartzite_Brick_Smooth"
    },
    {
      "x": -26,
      "y": 60,
      "z": -14,
      "name": "Rock_Quartzite_Brick_Smooth"
    },
    {
      "x": -26,
      "y": 61,
      "z": -14,
      "name": "Rock_Stone_Brick_Wall",
      "rotation": 1
    },
    {
      "x": -26,
      "y": 59,
      "z": -13,
      "name": "Rock_Quartzite_Brick_Smooth"
    },
    {
      "x": -26,
      "y": 60,
      "z": -13,
      "name": "Rock_Quartzite_Brick_Smooth"
    },
    {
      "x": -25,
      "y": 40,
      "z": -28,
      "name": "Rock_Stone"
    },
    {
      "x": -25,
      "y": 41,
      "z": -28,
      "name": "Rock_Stone"
    },
    {
      "x": -25,
      "y": 57,
      "z": -28,
      "name": "Rock_Quartzite_Brick_Smooth"
    },
    {
      "x": -25,
      "y": 58,
      "z": -28,
      "name": "Rock_Quartzite_Brick_Smooth"
    },
    {
      "x": -25,
      "y": 38,
      "z": -27,
      "name": "Rock_Stone"
    },
    {
      "x": -25,
      "y": 39,
      "z": -27,
      "name": "Rock_Stone"
    },
    {
      "x": -25,
      "y": 40,
      "z": -27,
      "name": "Rock_Stone"
    },
    {
      "x": -25,
      "y": 41,
      "z": -27,
      "name": "Rock_Stone"
    },
    {
      "x": -25,
      "y": 42,
      "z": -27,
      "name": "Rock_Stone"
    },
    {
      "x": -25,
      "y": 43,
      "z": -27,
      "name": "Soil_Gravel"
    },
    {
      "x": -25,
      "y": 44,
      "z": -27,
      "name": "Rock_Stone"
    },
    {
      "x": -25,
      "y": 57,
      "z": -27,
      "name": "Rock_Quartzite_Brick_Smooth"
    },
    {
      "x": -25,
      "y": 58,
      "z": -27,
      "name": "Rock_Quartzite_Brick_Smooth"
    },
    {
      "x": -25,
      "y": 35,
      "z": -26,
      "name": "Rock_Stone"
    },
    {
      "x": -25,
      "y": 36,
      "z": -26,
      "name": "Rock_Stone"
    },
    {
      "x": -25,
      "y": 37,
      "z": -26,
      "name": "Rock_Stone"
    },
    {
      "x": -25,
      "y": 38,
      "z": -26,
      "name": "Rock_Stone"
    },
    {
      "x": -25,
      "y": 39,
      "z": -26,
      "name": "Rock_Stone"
    },
    {
      "x": -25,
      "y": 40,
      "z": -26,
      "name": "Rock_Stone"
    },
    {
      "x": -25,
      "y": 41,
      "z": -26,
      "name": "Rock_Stone"
    },
    {
      "x": -25,
      "y": 42,
      "z": -26,
      "name": "Rock_Stone"
    },
    {
      "x": -25,
      "y": 43,
      "z": -26,
      "name": "Rock_Stone"
    },
    {
      "x": -25,
      "y": 44,
      "z": -26,
      "name": "Soil_Dirt"
    },
    {
      "x": -25,
      "y": 57,
      "z": -26,
      "name": "Rock_Quartzite_Brick_Smooth"
    },
    {
      "x": -25,
      "y": 58,
      "z": -26,
      "name": "Rock_Quartzite_Brick_Smooth"
    },
    {
      "x": -25,
      "y": 59,
      "z": -26,
      "name": "Rock_Stone_Brick_Wall",
      "rotation": 1
    },
    {
      "x": -25,
      "y": 34,
      "z": -25,
      "name": "Rock_Stone"
    },
    {
      "x": -25,
      "y": 35,
      "z": -25,
      "name": "Rock_Stone"
    },
    {
      "x": -25,
      "y": 36,
      "z": -25,
      "name": "Rock_Stone"
    },
    {
      "x": -25,
      "y": 37,
      "z": -25,
      "name": "Rock_Stone"
    },
    {
      "x": -25,
      "y": 38,
      "z": -25,
      "name": "Rock_Stone"
    },
    {
      "x": -25,
      "y": 39,
      "z": -25,
      "name": "Rock_Stone"
    },
    {
      "x": -25,
      "y": 40,
      "z": -25,
      "name": "Rock_Stone"
    },
    {
      "x": -25,
      "y": 41,
      "z": -25,
      "name": "Rock_Stone"
    },
    {
      "x": -25,
      "y": 42,
      "z": -25,
      "name": "Rock_Stone"
    },
    {
      "x": -25,
      "y": 43,
      "z": -25,
      "name": "Soil_Dirt"
    },
    {
      "x": -25,
      "y": 44,
      "z": -25,
      "name": "Soil_Dirt"
    },
    {
      "x": -25,
      "y": 45,
      "z": -25,
      "name": "Soil_Grass"
    },
    {
      "x": -25,
      "y": 57,
      "z": -25,
      "name": "Rock_Quartzite_Brick_Smooth"
    },
    {
      "x": -25,
      "y": 58,
      "z": -25,
      "name": "Rock_Quartzite_Brick_Smooth"
    },
    {
      "x": -25,
      "y": 59,
      "z": -25,
      "name": "Rock_Stone_Brick_Wall",
      "rotation": 1
    },
    {
      "x": -25,
      "y": 35,
      "z": -24,
      "name": "Rock_Stone"
    },
    {
      "x": -25,
      "y": 36,
      "z": -24,
      "name": "Rock_Stone"
    },
    {
      "x": -25,
      "y": 37,
      "z": -24,
      "name": "Rock_Stone"
    },
    {
      "x": -25,
      "y": 38,
      "z": -24,
      "name": "Rock_Stone"
    },
    {
      "x": -25,
      "y": 39,
      "z": -24,
      "name": "Rock_Stone"
    },
    {
      "x": -25,
      "y": 40,
      "z": -24,
      "name": "Rock_Stone"
    },
    {
      "x": -25,
      "y": 41,
      "z": -24,
      "name": "Rock_Stone"
    },
    {
      "x": -25,
      "y": 42,
      "z": -24,
      "name": "Soil_Dirt"
    },
    {
      "x": -25,
      "y": 43,
      "z": -24,
      "name": "Soil_Dirt"
    },
    {
      "x": -25,
      "y": 44,
      "z": -24,
      "name": "Soil_Dirt"
    },
    {
      "x": -25,
      "y": 45,
      "z": -24,
      "name": "Soil_Dirt"
    },
    {
      "x": -25,
      "y": 46,
      "z": -24,
      "name": "Soil_Grass"
    },
    {
      "x": -25,
      "y": 57,
      "z": -24,
      "name": "Rock_Quartzite_Brick_Smooth"
    },
    {
      "x": -25,
      "y": 58,
      "z": -24,
      "name": "Rock_Quartzite_Brick_Smooth"
    },
    {
      "x": -25,
      "y": 35,
      "z": -23,
      "name": "Rock_Stone"
    },
    {
      "x": -25,
      "y": 36,
      "z": -23,
      "name": "Rock_Stone"
    },
    {
      "x": -25,
      "y": 37,
      "z": -23,
      "name": "Rock_Stone"
    },
    {
      "x": -25,
      "y": 38,
      "z": -23,
      "name": "Rock_Stone"
    },
    {
      "x": -25,
      "y": 39,
      "z": -23,
      "name": "Rock_Stone"
    },
    {
      "x": -25,
      "y": 40,
      "z": -23,
      "name": "Rock_Stone"
    },
    {
      "x": -25,
      "y": 41,
      "z": -23,
      "name": "Rock_Stone"
    },
    {
      "x": -25,
      "y": 42,
      "z": -23,
      "name": "Rock_Stone"
    },
    {
      "x": -25,
      "y": 43,
      "z": -23,
      "name": "Soil_Dirt"
    },
    {
      "x": -25,
      "y": 44,
      "z": -23,
      "name": "Soil_Dirt"
    },
    {
      "x": -25,
      "y": 45,
      "z": -23,
      "name": "Soil_Dirt"
    },
    {
      "x": -25,
      "y": 46,
      "z": -23,
      "name": "Soil_Grass"
    },
    {
      "x": -25,
      "y": 59,
      "z": -23,
      "name": "Rock_Stone_Brick_Wall",
      "rotation": 1
    },
    {
      "x": -25,
      "y": 34,
      "z": -22,
      "name": "Rock_Stone"
    },
    {
      "x": -25,
      "y": 35,
      "z": -22,
      "name": "Rock_Stone"
    },
    {
      "x": -25,
      "y": 36,
      "z": -22,
      "name": "Rock_Stone"
    },
    {
      "x": -25,
      "y": 37,
      "z": -22,
      "name": "Rock_Stone"
    },
    {
      "x": -25,
      "y": 38,
      "z": -22,
      "name": "Rock_Stone"
    },
    {
      "x": -25,
      "y": 39,
      "z": -22,
      "name": "Rock_Stone"
    },
    {
      "x": -25,
      "y": 40,
      "z": -22,
      "name": "Rock_Stone"
    },
    {
      "x": -25,
      "y": 41,
      "z": -22,
      "name": "Rock_Stone"
    },
    {
      "x": -25,
      "y": 42,
      "z": -22,
      "name": "Rock_Stone"
    },
    {
      "x": -25,
      "y": 43,
      "z": -22,
      "name": "Rock_Stone"
    },
    {
      "x": -25,
      "y": 44,
      "z": -22,
      "name": "Soil_Dirt"
    },
    {
      "x": -25,
      "y": 45,
      "z": -22,
      "name": "Soil_Dirt"
    },
    {
      "x": -25,
      "y": 46,
      "z": -22,
      "name": "Soil_Dirt"
    },
    {
      "x": -25,
      "y": 47,
      "z": -22,
      "name": "Plant_Moss_Rug_Green"
    },
    {
      "x": -25,
      "y": 58,
      "z": -22,
      "name": "Rock_Quartzite_Brick_Smooth"
    },
    {
      "x": -25,
      "y": 59,
      "z": -22,
      "name": "Rock_Stone_Brick_Wall",
      "rotation": 1
    },
    {
      "x": -25,
      "y": 33,
      "z": -21,
      "name": "Rock_Stone"
    },
    {
      "x": -25,
      "y": 34,
      "z": -21,
      "name": "Rock_Stone"
    },
    {
      "x": -25,
      "y": 35,
      "z": -21,
      "name": "Rock_Stone"
    },
    {
      "x": -25,
      "y": 36,
      "z": -21,
      "name": "Rock_Stone"
    },
    {
      "x": -25,
      "y": 37,
      "z": -21,
      "name": "Rock_Stone"
    },
    {
      "x": -25,
      "y": 38,
      "z": -21,
      "name": "Rock_Stone"
    },
    {
      "x": -25,
      "y": 39,
      "z": -21,
      "name": "Rock_Stone"
    },
    {
      "x": -25,
      "y": 40,
      "z": -21,
      "name": "Rock_Stone"
    },
    {
      "x": -25,
      "y": 41,
      "z": -21,
      "name": "Rock_Stone"
    },
    {
      "x": -25,
      "y": 42,
      "z": -21,
      "name": "Rock_Stone"
    },
    {
      "x": -25,
      "y": 43,
      "z": -21,
      "name": "Rock_Stone"
    },
    {
      "x": -25,
      "y": 44,
      "z": -21,
      "name": "Soil_Dirt"
    },
    {
      "x": -25,
      "y": 45,
      "z": -21,
      "name": "Soil_Dirt"
    },
    {
      "x": -25,
      "y": 46,
      "z": -21,
      "name": "Soil_Dirt"
    },
    {
      "x": -25,
      "y": 47,
      "z": -21,
      "name": "Plant_Moss_Block_Green"
    },
    {
      "x": -25,
      "y": 48,
      "z": -21,
      "name": "Plant_Moss_Rug_Green"
    },
    {
      "x": -25,
      "y": 57,
      "z": -21,
      "name": "Rock_Quartzite_Brick_Smooth"
    },
    {
      "x": -25,
      "y": 58,
      "z": -21,
      "name": "Rock_Quartzite_Brick_Smooth"
    },
    {
      "x": -25,
      "y": 33,
      "z": -20,
      "name": "Rock_Stone"
    },
    {
      "x": -25,
      "y": 34,
      "z": -20,
      "name": "Rock_Stone"
    },
    {
      "x": -25,
      "y": 35,
      "z": -20,
      "name": "Rock_Stone"
    },
    {
      "x": -25,
      "y": 36,
      "z": -20,
      "name": "Rock_Stone"
    },
    {
      "x": -25,
      "y": 37,
      "z": -20,
      "name": "Rock_Stone"
    },
    {
      "x": -25,
      "y": 38,
      "z": -20,
      "name": "Rock_Stone"
    },
    {
      "x": -25,
      "y": 39,
      "z": -20,
      "name": "Rock_Stone"
    },
    {
      "x": -25,
      "y": 40,
      "z": -20,
      "name": "Rock_Stone"
    },
    {
      "x": -25,
      "y": 41,
      "z": -20,
      "name": "Rock_Stone"
    },
    {
      "x": -25,
      "y": 42,
      "z": -20,
      "name": "Rock_Stone"
    },
    {
      "x": -25,
      "y": 43,
      "z": -20,
      "name": "Rock_Stone"
    },
    {
      "x": -25,
      "y": 44,
      "z": -20,
      "name": "Rock_Stone"
    },
    {
      "x": -25,
      "y": 45,
      "z": -20,
      "name": "Rock_Stone"
    },
    {
      "x": -25,
      "y": 46,
      "z": -20,
      "name": "Rock_Stone"
    },
    {
      "x": -25,
      "y": 47,
      "z": -20,
      "name": "Plant_Moss_Block_Green"
    },
    {
      "x": -25,
      "y": 48,
      "z": -20,
      "name": "Plant_Moss_Rug_Green"
    },
    {
      "x": -25,
      "y": 57,
      "z": -20,
      "name": "Rock_Quartzite_Brick_Smooth"
    },
    {
      "x": -25,
      "y": 58,
      "z": -20,
      "name": "Rock_Quartzite_Brick_Smooth"
    },
    {
      "x": -25,
      "y": 59,
      "z": -20,
      "name": "Rock_Stone_Brick_Wall",
      "rotation": 1
    },
    {
      "x": -25,
      "y": 33,
      "z": -19,
      "name": "Rock_Stone"
    },
    {
      "x": -25,
      "y": 34,
      "z": -19,
      "name": "Rock_Stone"
    },
    {
      "x": -25,
      "y": 35,
      "z": -19,
      "name": "Rock_Stone"
    },
    {
      "x": -25,
      "y": 36,
      "z": -19,
      "name": "Rock_Stone"
    },
    {
      "x": -25,
      "y": 37,
      "z": -19,
      "name": "Rock_Stone"
    },
    {
      "x": -25,
      "y": 38,
      "z": -19,
      "name": "Rock_Stone"
    },
    {
      "x": -25,
      "y": 39,
      "z": -19,
      "name": "Rock_Stone"
    },
    {
      "x": -25,
      "y": 40,
      "z": -19,
      "name": "Rock_Stone"
    },
    {
      "x": -25,
      "y": 41,
      "z": -19,
      "name": "Rock_Stone"
    },
    {
      "x": -25,
      "y": 42,
      "z": -19,
      "name": "Rock_Stone"
    },
    {
      "x": -25,
      "y": 43,
      "z": -19,
      "name": "Rock_Stone"
    },
    {
      "x": -25,
      "y": 44,
      "z": -19,
      "name": "Rock_Stone"
    },
    {
      "x": -25,
      "y": 45,
      "z": -19,
      "name": "Rock_Stone"
    },
    {
      "x": -25,
      "y": 46,
      "z": -19,
      "name": "Rock_Stone"
    },
    {
      "x": -25,
      "y": 47,
      "z": -19,
      "name": "Plant_Moss_Block_Green"
    },
    {
      "x": -25,
      "y": 57,
      "z": -19,
      "name": "Rock_Quartzite_Brick_Smooth"
    },
    {
      "x": -25,
      "y": 58,
      "z": -19,
      "name": "Rock_Quartzite_Brick_Smooth"
    },
    {
      "x": -25,
      "y": 59,
      "z": -19,
      "name": "Rock_Stone_Brick_Wall",
      "rotation": 1
    },
    {
      "x": -25,
      "y": 33,
      "z": -18,
      "name": "Rock_Stone"
    },
    {
      "x": -25,
      "y": 34,
      "z": -18,
      "name": "Rock_Stone"
    },
    {
      "x": -25,
      "y": 35,
      "z": -18,
      "name": "Rock_Stone"
    },
    {
      "x": -25,
      "y": 36,
      "z": -18,
      "name": "Rock_Stone"
    },
    {
      "x": -25,
      "y": 37,
      "z": -18,
      "name": "Rock_Stone"
    },
    {
      "x": -25,
      "y": 38,
      "z": -18,
      "name": "Rock_Stone"
    },
    {
      "x": -25,
      "y": 39,
      "z": -18,
      "name": "Rock_Stone"
    },
    {
      "x": -25,
      "y": 40,
      "z": -18,
      "name": "Rock_Stone"
    },
    {
      "x": -25,
      "y": 41,
      "z": -18,
      "name": "Rock_Stone"
    },
    {
      "x": -25,
      "y": 42,
      "z": -18,
      "name": "Rock_Stone"
    },
    {
      "x": -25,
      "y": 43,
      "z": -18,
      "name": "Rock_Stone"
    },
    {
      "x": -25,
      "y": 44,
      "z": -18,
      "name": "Rock_Stone"
    },
    {
      "x": -25,
      "y": 45,
      "z": -18,
      "name": "Rock_Stone"
    },
    {
      "x": -25,
      "y": 46,
      "z": -18,
      "name": "Plant_Moss_Block_Green"
    },
    {
      "x": -25,
      "y": 57,
      "z": -18,
      "name": "Rock_Quartzite_Brick_Smooth"
    },
    {
      "x": -25,
      "y": 58,
      "z": -18,
      "name": "Rock_Quartzite_Brick_Smooth"
    },
    {
      "x": -25,
      "y": 59,
      "z": -18,
      "name": "Plant_Moss_Rug_Green"
    },
    {
      "x": -25,
      "y": 35,
      "z": -17,
      "name": "Rock_Stone"
    },
    {
      "x": -25,
      "y": 36,
      "z": -17,
      "name": "Rock_Stone"
    },
    {
      "x": -25,
      "y": 37,
      "z": -17,
      "name": "Rock_Stone"
    },
    {
      "x": -25,
      "y": 38,
      "z": -17,
      "name": "Rock_Stone"
    },
    {
      "x": -25,
      "y": 39,
      "z": -17,
      "name": "Rock_Stone"
    },
    {
      "x": -25,
      "y": 40,
      "z": -17,
      "name": "Rock_Stone"
    },
    {
      "x": -25,
      "y": 41,
      "z": -17,
      "name": "Rock_Stone"
    },
    {
      "x": -25,
      "y": 42,
      "z": -17,
      "name": "Rock_Stone"
    },
    {
      "x": -25,
      "y": 43,
      "z": -17,
      "name": "Rock_Stone"
    },
    {
      "x": -25,
      "y": 44,
      "z": -17,
      "name": "Rock_Stone"
    },
    {
      "x": -25,
      "y": 45,
      "z": -17,
      "name": "Rock_Stone"
    },
    {
      "x": -25,
      "y": 46,
      "z": -17,
      "name": "Plant_Moss_Block_Green"
    },
    {
      "x": -25,
      "y": 57,
      "z": -17,
      "name": "Rock_Quartzite_Brick_Smooth"
    },
    {
      "x": -25,
      "y": 58,
      "z": -17,
      "name": "Rock_Quartzite_Brick_Smooth"
    },
    {
      "x": -25,
      "y": 59,
      "z": -17,
      "name": "Plant_Moss_Rug_Green"
    },
    {
      "x": -25,
      "y": 37,
      "z": -16,
      "name": "Rock_Stone"
    },
    {
      "x": -25,
      "y": 38,
      "z": -16,
      "name": "Rock_Stone"
    },
    {
      "x": -25,
      "y": 39,
      "z": -16,
      "name": "Rock_Stone"
    },
    {
      "x": -25,
      "y": 40,
      "z": -16,
      "name": "Rock_Stone"
    },
    {
      "x": -25,
      "y": 41,
      "z": -16,
      "name": "Rock_Stone"
    },
    {
      "x": -25,
      "y": 42,
      "z": -16,
      "name": "Rock_Stone"
    },
    {
      "x": -25,
      "y": 43,
      "z": -16,
      "name": "Rock_Stone"
    },
    {
      "x": -25,
      "y": 44,
      "z": -16,
      "name": "Rock_Stone"
    },
    {
      "x": -25,
      "y": 45,
      "z": -16,
      "name": "Rock_Stone"
    },
    {
      "x": -25,
      "y": 42,
      "z": 1,
      "name": "Rock_Stone"
    },
    {
      "x": -25,
      "y": 43,
      "z": 1,
      "name": "Rock_Stone"
    },
    {
      "x": -25,
      "y": 44,
      "z": 1,
      "name": "Rock_Stone"
    },
    {
      "x": -25,
      "y": 41,
      "z": 2,
      "name": "Rock_Stone"
    },
    {
      "x": -25,
      "y": 42,
      "z": 2,
      "name": "Rock_Stone"
    },
    {
      "x": -25,
      "y": 43,
      "z": 2,
      "name": "Rock_Stone"
    },
    {
      "x": -25,
      "y": 44,
      "z": 2,
      "name": "Rock_Stone"
    },
    {
      "x": -25,
      "y": 45,
      "z": 2,
      "name": "Rock_Stone"
    },
    {
      "x": -25,
      "y": 40,
      "z": 3,
      "name": "Rock_Stone"
    },
    {
      "x": -25,
      "y": 41,
      "z": 3,
      "name": "Rock_Stone"
    },
    {
      "x": -25,
      "y": 42,
      "z": 3,
      "name": "Rock_Stone"
    },
    {
      "x": -25,
      "y": 43,
      "z": 3,
      "name": "Rock_Stone"
    },
    {
      "x": -25,
      "y": 44,
      "z": 3,
      "name": "Rock_Stone"
    },
    {
      "x": -25,
      "y": 45,
      "z": 3,
      "name": "Rock_Stone"
    },
    {
      "x": -24,
      "y": 39,
      "z": -27,
      "name": "Rock_Stone"
    },
    {
      "x": -24,
      "y": 40,
      "z": -27,
      "name": "Rock_Stone"
    },
    {
      "x": -24,
      "y": 41,
      "z": -27,
      "name": "Rock_Stone"
    },
    {
      "x": -24,
      "y": 42,
      "z": -27,
      "name": "Rock_Stone"
    },
    {
      "x": -24,
      "y": 37,
      "z": -26,
      "name": "Rock_Stone"
    },
    {
      "x": -24,
      "y": 38,
      "z": -26,
      "name": "Rock_Stone"
    },
    {
      "x": -24,
      "y": 39,
      "z": -26,
      "name": "Rock_Stone"
    },
    {
      "x": -24,
      "y": 40,
      "z": -26,
      "name": "Rock_Stone"
    },
    {
      "x": -24,
      "y": 41,
      "z": -26,
      "name": "Rock_Stone"
    },
    {
      "x": -24,
      "y": 42,
      "z": -26,
      "name": "Rock_Stone"
    },
    {
      "x": -24,
      "y": 43,
      "z": -26,
      "name": "Rock_Stone"
    },
    {
      "x": -24,
      "y": 35,
      "z": -25,
      "name": "Rock_Stone"
    },
    {
      "x": -24,
      "y": 36,
      "z": -25,
      "name": "Rock_Stone"
    },
    {
      "x": -24,
      "y": 37,
      "z": -25,
      "name": "Rock_Stone"
    },
    {
      "x": -24,
      "y": 38,
      "z": -25,
      "name": "Rock_Stone"
    },
    {
      "x": -24,
      "y": 39,
      "z": -25,
      "name": "Rock_Stone"
    },
    {
      "x": -24,
      "y": 40,
      "z": -25,
      "name": "Rock_Stone"
    },
    {
      "x": -24,
      "y": 41,
      "z": -25,
      "name": "Rock_Stone"
    },
    {
      "x": -24,
      "y": 42,
      "z": -25,
      "name": "Soil_Dirt"
    },
    {
      "x": -24,
      "y": 43,
      "z": -25,
      "name": "Soil_Dirt"
    },
    {
      "x": -24,
      "y": 44,
      "z": -25,
      "name": "Soil_Grass"
    },
    {
      "x": -24,
      "y": 34,
      "z": -24,
      "name": "Rock_Stone"
    },
    {
      "x": -24,
      "y": 35,
      "z": -24,
      "name": "Rock_Stone"
    },
    {
      "x": -24,
      "y": 36,
      "z": -24,
      "name": "Rock_Stone"
    },
    {
      "x": -24,
      "y": 37,
      "z": -24,
      "name": "Rock_Stone"
    },
    {
      "x": -24,
      "y": 38,
      "z": -24,
      "name": "Rock_Stone"
    },
    {
      "x": -24,
      "y": 39,
      "z": -24,
      "name": "Rock_Stone"
    },
    {
      "x": -24,
      "y": 40,
      "z": -24,
      "name": "Rock_Stone"
    },
    {
      "x": -24,
      "y": 41,
      "z": -24,
      "name": "Rock_Stone"
    },
    {
      "x": -24,
      "y": 42,
      "z": -24,
      "name": "Soil_Dirt"
    },
    {
      "x": -24,
      "y": 43,
      "z": -24,
      "name": "Soil_Dirt"
    },
    {
      "x": -24,
      "y": 44,
      "z": -24,
      "name": "Soil_Dirt"
    },
    {
      "x": -24,
      "y": 45,
      "z": -24,
      "name": "Soil_Grass"
    },
    {
      "x": -24,
      "y": 35,
      "z": -23,
      "name": "Rock_Stone"
    },
    {
      "x": -24,
      "y": 36,
      "z": -23,
      "name": "Rock_Stone"
    },
    {
      "x": -24,
      "y": 37,
      "z": -23,
      "name": "Rock_Stone"
    },
    {
      "x": -24,
      "y": 38,
      "z": -23,
      "name": "Rock_Stone"
    },
    {
      "x": -24,
      "y": 39,
      "z": -23,
      "name": "Rock_Stone"
    },
    {
      "x": -24,
      "y": 40,
      "z": -23,
      "name": "Rock_Stone"
    },
    {
      "x": -24,
      "y": 41,
      "z": -23,
      "name": "Rock_Stone"
    },
    {
      "x": -24,
      "y": 42,
      "z": -23,
      "name": "Soil_Dirt"
    },
    {
      "x": -24,
      "y": 43,
      "z": -23,
      "name": "Soil_Dirt"
    },
    {
      "x": -24,
      "y": 44,
      "z": -23,
      "name": "Soil_Dirt"
    },
    {
      "x": -24,
      "y": 45,
      "z": -23,
      "name": "Soil_Grass"
    },
    {
      "x": -24,
      "y": 34,
      "z": -22,
      "name": "Rock_Stone"
    },
    {
      "x": -24,
      "y": 35,
      "z": -22,
      "name": "Rock_Stone"
    },
    {
      "x": -24,
      "y": 36,
      "z": -22,
      "name": "Rock_Stone"
    },
    {
      "x": -24,
      "y": 37,
      "z": -22,
      "name": "Rock_Stone"
    },
    {
      "x": -24,
      "y": 38,
      "z": -22,
      "name": "Rock_Stone"
    },
    {
      "x": -24,
      "y": 39,
      "z": -22,
      "name": "Rock_Stone"
    },
    {
      "x": -24,
      "y": 40,
      "z": -22,
      "name": "Rock_Stone"
    },
    {
      "x": -24,
      "y": 41,
      "z": -22,
      "name": "Rock_Stone"
    },
    {
      "x": -24,
      "y": 42,
      "z": -22,
      "name": "Soil_Dirt"
    },
    {
      "x": -24,
      "y": 43,
      "z": -22,
      "name": "Soil_Dirt"
    },
    {
      "x": -24,
      "y": 44,
      "z": -22,
      "name": "Soil_Dirt"
    },
    {
      "x": -24,
      "y": 45,
      "z": -22,
      "name": "Soil_Dirt"
    },
    {
      "x": -24,
      "y": 46,
      "z": -22,
      "name": "Soil_Grass"
    },
    {
      "x": -24,
      "y": 33,
      "z": -21,
      "name": "Rock_Stone"
    },
    {
      "x": -24,
      "y": 34,
      "z": -21,
      "name": "Rock_Stone"
    },
    {
      "x": -24,
      "y": 35,
      "z": -21,
      "name": "Rock_Stone"
    },
    {
      "x": -24,
      "y": 36,
      "z": -21,
      "name": "Rock_Stone"
    },
    {
      "x": -24,
      "y": 37,
      "z": -21,
      "name": "Rock_Stone"
    },
    {
      "x": -24,
      "y": 38,
      "z": -21,
      "name": "Rock_Stone"
    },
    {
      "x": -24,
      "y": 39,
      "z": -21,
      "name": "Rock_Stone"
    },
    {
      "x": -24,
      "y": 40,
      "z": -21,
      "name": "Rock_Stone"
    },
    {
      "x": -24,
      "y": 41,
      "z": -21,
      "name": "Rock_Stone"
    },
    {
      "x": -24,
      "y": 42,
      "z": -21,
      "name": "Rock_Stone"
    },
    {
      "x": -24,
      "y": 43,
      "z": -21,
      "name": "Soil_Dirt"
    },
    {
      "x": -24,
      "y": 44,
      "z": -21,
      "name": "Soil_Dirt"
    },
    {
      "x": -24,
      "y": 45,
      "z": -21,
      "name": "Soil_Dirt"
    },
    {
      "x": -24,
      "y": 46,
      "z": -21,
      "name": "Plant_Moss_Block_Green"
    },
    {
      "x": -24,
      "y": 33,
      "z": -20,
      "name": "Rock_Stone"
    },
    {
      "x": -24,
      "y": 34,
      "z": -20,
      "name": "Rock_Stone"
    },
    {
      "x": -24,
      "y": 35,
      "z": -20,
      "name": "Rock_Stone"
    },
    {
      "x": -24,
      "y": 36,
      "z": -20,
      "name": "Rock_Stone"
    },
    {
      "x": -24,
      "y": 37,
      "z": -20,
      "name": "Rock_Stone"
    },
    {
      "x": -24,
      "y": 38,
      "z": -20,
      "name": "Rock_Stone"
    },
    {
      "x": -24,
      "y": 39,
      "z": -20,
      "name": "Rock_Stone"
    },
    {
      "x": -24,
      "y": 40,
      "z": -20,
      "name": "Rock_Stone"
    },
    {
      "x": -24,
      "y": 41,
      "z": -20,
      "name": "Rock_Stone"
    },
    {
      "x": -24,
      "y": 42,
      "z": -20,
      "name": "Rock_Stone"
    },
    {
      "x": -24,
      "y": 43,
      "z": -20,
      "name": "Rock_Stone"
    },
    {
      "x": -24,
      "y": 44,
      "z": -20,
      "name": "Soil_Dirt"
    },
    {
      "x": -24,
      "y": 45,
      "z": -20,
      "name": "Soil_Dirt"
    },
    {
      "x": -24,
      "y": 46,
      "z": -20,
      "name": "Plant_Moss_Block_Green"
    },
    {
      "x": -24,
      "y": 32,
      "z": -19,
      "name": "Rock_Stone"
    },
    {
      "x": -24,
      "y": 33,
      "z": -19,
      "name": "Rock_Stone"
    },
    {
      "x": -24,
      "y": 34,
      "z": -19,
      "name": "Rock_Stone"
    },
    {
      "x": -24,
      "y": 35,
      "z": -19,
      "name": "Rock_Stone"
    },
    {
      "x": -24,
      "y": 36,
      "z": -19,
      "name": "Rock_Stone"
    },
    {
      "x": -24,
      "y": 37,
      "z": -19,
      "name": "Rock_Stone"
    },
    {
      "x": -24,
      "y": 38,
      "z": -19,
      "name": "Rock_Stone"
    },
    {
      "x": -24,
      "y": 39,
      "z": -19,
      "name": "Rock_Stone"
    },
    {
      "x": -24,
      "y": 40,
      "z": -19,
      "name": "Rock_Stone"
    },
    {
      "x": -24,
      "y": 41,
      "z": -19,
      "name": "Rock_Stone"
    },
    {
      "x": -24,
      "y": 42,
      "z": -19,
      "name": "Rock_Stone"
    },
    {
      "x": -24,
      "y": 43,
      "z": -19,
      "name": "Rock_Stone"
    },
    {
      "x": -24,
      "y": 44,
      "z": -19,
      "name": "Soil_Dirt"
    },
    {
      "x": -24,
      "y": 45,
      "z": -19,
      "name": "Soil_Dirt"
    },
    {
      "x": -24,
      "y": 46,
      "z": -19,
      "name": "Plant_Moss_Block_Green"
    },
    {
      "x": -24,
      "y": 32,
      "z": -18,
      "name": "Rock_Stone"
    },
    {
      "x": -24,
      "y": 33,
      "z": -18,
      "name": "Rock_Stone"
    },
    {
      "x": -24,
      "y": 34,
      "z": -18,
      "name": "Rock_Stone"
    },
    {
      "x": -24,
      "y": 35,
      "z": -18,
      "name": "Rock_Stone"
    },
    {
      "x": -24,
      "y": 36,
      "z": -18,
      "name": "Rock_Stone"
    },
    {
      "x": -24,
      "y": 37,
      "z": -18,
      "name": "Rock_Stone"
    },
    {
      "x": -24,
      "y": 38,
      "z": -18,
      "name": "Rock_Stone"
    },
    {
      "x": -24,
      "y": 39,
      "z": -18,
      "name": "Rock_Stone"
    },
    {
      "x": -24,
      "y": 40,
      "z": -18,
      "name": "Rock_Stone"
    },
    {
      "x": -24,
      "y": 41,
      "z": -18,
      "name": "Rock_Stone"
    },
    {
      "x": -24,
      "y": 42,
      "z": -18,
      "name": "Rock_Stone"
    },
    {
      "x": -24,
      "y": 43,
      "z": -18,
      "name": "Rock_Stone"
    },
    {
      "x": -24,
      "y": 44,
      "z": -18,
      "name": "Soil_Pathway"
    },
    {
      "x": -24,
      "y": 45,
      "z": -18,
      "name": "Plant_Moss_Block_Green"
    },
    {
      "x": -24,
      "y": 35,
      "z": -17,
      "name": "Rock_Stone"
    },
    {
      "x": -24,
      "y": 36,
      "z": -17,
      "name": "Rock_Stone"
    },
    {
      "x": -24,
      "y": 37,
      "z": -17,
      "name": "Rock_Stone"
    },
    {
      "x": -24,
      "y": 38,
      "z": -17,
      "name": "Rock_Stone"
    },
    {
      "x": -24,
      "y": 39,
      "z": -17,
      "name": "Rock_Stone"
    },
    {
      "x": -24,
      "y": 40,
      "z": -17,
      "name": "Rock_Stone"
    },
    {
      "x": -24,
      "y": 41,
      "z": -17,
      "name": "Rock_Stone"
    },
    {
      "x": -24,
      "y": 42,
      "z": -17,
      "name": "Rock_Stone"
    },
    {
      "x": -24,
      "y": 43,
      "z": -17,
      "name": "Rock_Stone"
    },
    {
      "x": -24,
      "y": 44,
      "z": -17,
      "name": "Soil_Pathway"
    },
    {
      "x": -24,
      "y": 45,
      "z": -17,
      "name": "Soil_Grass"
    },
    {
      "x": -24,
      "y": 36,
      "z": -16,
      "name": "Rock_Stone"
    },
    {
      "x": -24,
      "y": 37,
      "z": -16,
      "name": "Rock_Stone"
    },
    {
      "x": -24,
      "y": 38,
      "z": -16,
      "name": "Rock_Stone"
    },
    {
      "x": -24,
      "y": 39,
      "z": -16,
      "name": "Rock_Stone"
    },
    {
      "x": -24,
      "y": 40,
      "z": -16,
      "name": "Rock_Stone"
    },
    {
      "x": -24,
      "y": 41,
      "z": -16,
      "name": "Rock_Stone"
    },
    {
      "x": -24,
      "y": 42,
      "z": -16,
      "name": "Rock_Stone"
    },
    {
      "x": -24,
      "y": 43,
      "z": -16,
      "name": "Rock_Stone"
    },
    {
      "x": -24,
      "y": 44,
      "z": -16,
      "name": "Rock_Stone"
    },
    {
      "x": -24,
      "y": 45,
      "z": -16,
      "name": "Rock_Stone"
    },
    {
      "x": -24,
      "y": 40,
      "z": 0,
      "name": "Rock_Stone"
    },
    {
      "x": -24,
      "y": 41,
      "z": 0,
      "name": "Rock_Stone"
    },
    {
      "x": -24,
      "y": 42,
      "z": 0,
      "name": "Rock_Stone"
    },
    {
      "x": -24,
      "y": 43,
      "z": 0,
      "name": "Rock_Stone"
    },
    {
      "x": -24,
      "y": 44,
      "z": 0,
      "name": "Rock_Stone"
    },
    {
      "x": -24,
      "y": 39,
      "z": 1,
      "name": "Rock_Stone"
    },
    {
      "x": -24,
      "y": 40,
      "z": 1,
      "name": "Rock_Stone"
    },
    {
      "x": -24,
      "y": 41,
      "z": 1,
      "name": "Rock_Stone"
    },
    {
      "x": -24,
      "y": 42,
      "z": 1,
      "name": "Rock_Stone"
    },
    {
      "x": -24,
      "y": 43,
      "z": 1,
      "name": "Rock_Stone"
    },
    {
      "x": -24,
      "y": 44,
      "z": 1,
      "name": "Rock_Stone"
    },
    {
      "x": -24,
      "y": 45,
      "z": 1,
      "name": "Rock_Stone"
    },
    {
      "x": -24,
      "y": 37,
      "z": 2,
      "name": "Rock_Stone"
    },
    {
      "x": -24,
      "y": 38,
      "z": 2,
      "name": "Rock_Stone"
    },
    {
      "x": -24,
      "y": 39,
      "z": 2,
      "name": "Rock_Stone"
    },
    {
      "x": -24,
      "y": 40,
      "z": 2,
      "name": "Rock_Stone"
    },
    {
      "x": -24,
      "y": 41,
      "z": 2,
      "name": "Rock_Stone"
    },
    {
      "x": -24,
      "y": 42,
      "z": 2,
      "name": "Rock_Stone"
    },
    {
      "x": -24,
      "y": 43,
      "z": 2,
      "name": "Rock_Stone"
    },
    {
      "x": -24,
      "y": 44,
      "z": 2,
      "name": "Rock_Stone"
    },
    {
      "x": -24,
      "y": 45,
      "z": 2,
      "name": "Rock_Stone"
    },
    {
      "x": -24,
      "y": 37,
      "z": 3,
      "name": "Rock_Stone"
    },
    {
      "x": -24,
      "y": 38,
      "z": 3,
      "name": "Rock_Stone"
    },
    {
      "x": -24,
      "y": 39,
      "z": 3,
      "name": "Rock_Stone"
    },
    {
      "x": -24,
      "y": 40,
      "z": 3,
      "name": "Rock_Stone"
    },
    {
      "x": -24,
      "y": 41,
      "z": 3,
      "name": "Rock_Stone"
    },
    {
      "x": -24,
      "y": 42,
      "z": 3,
      "name": "Rock_Stone"
    },
    {
      "x": -24,
      "y": 43,
      "z": 3,
      "name": "Rock_Stone"
    },
    {
      "x": -24,
      "y": 44,
      "z": 3,
      "name": "Rock_Stone"
    },
    {
      "x": -24,
      "y": 45,
      "z": 3,
      "name": "Rock_Stone"
    },
    {
      "x": -24,
      "y": 39,
      "z": 4,
      "name": "Rock_Stone"
    },
    {
      "x": -24,
      "y": 40,
      "z": 4,
      "name": "Rock_Stone"
    },
    {
      "x": -24,
      "y": 41,
      "z": 4,
      "name": "Rock_Stone"
    },
    {
      "x": -24,
      "y": 42,
      "z": 4,
      "name": "Rock_Stone"
    },
    {
      "x": -24,
      "y": 43,
      "z": 4,
      "name": "Rock_Stone"
    },
    {
      "x": -24,
      "y": 44,
      "z": 4,
      "name": "Rock_Stone"
    },
    {
      "x": -24,
      "y": 45,
      "z": 4,
      "name": "Rock_Stone"
    },
    {
      "x": -23,
      "y": 39,
      "z": -26,
      "name": "Rock_Stone"
    },
    {
      "x": -23,
      "y": 40,
      "z": -26,
      "name": "Rock_Stone"
    },
    {
      "x": -23,
      "y": 41,
      "z": -26,
      "name": "Rock_Stone"
    },
    {
      "x": -23,
      "y": 42,
      "z": -26,
      "name": "Rock_Stone"
