{
  "version": 8,
  "blockIdVersion": 11,
  "anchorX": 0,
  "anchorY": 0,
  "anchorZ": 0,
  "blocks": [
    {
      "x": -8,
      "y": 10,
      "z": -2,
      "name": "Soil_Grass_Full"
    },
    {
      "x": -8,
      "y": 11,
      "z": -2,
      "name": "Plant_Crop_Mushroom_Glowing_Blue"
    },
    {
      "x": -8,
      "y": 9,
      "z": -1,
      "name": "Soil_Dirt"
    },
    {
      "x": -8,
      "y": 10,
      "z": -1,
      "name": "Soil_Dirt"
    },
    {
      "x": -8,
      "y": 11,
      "z": -1,
      "name": "Soil_Grass_Full"
    },
    {
      "x": -8,
      "y": 9,
      "z": 0,
      "name": "Soil_Dirt"
    },
    {
      "x": -8,
      "y": 10,
      "z": 0,
      "name": "Soil_Dirt"
    },
    {
      "x": -8,
      "y": 11,
      "z": 0,
      "name": "Soil_Grass_Full"
    },
    {
      "x": -8,
      "y": 9,
      "z": 1,
      "name": "Soil_Dirt"
    },
    {
      "x": -8,
      "y": 10,
      "z": 1,
      "name": "Soil_Grass_Full"
    },
    {
      "x": -8,
      "y": 8,
      "z": 2,
      "name": "Soil_Grass_Full"
    },
    {
      "x": -7,
      "y": 12,
      "z": -5,
      "name": "Soil_Grass_Full"
    },
    {
      "x": -7,
      "y": 9,
      "z": -4,
      "name": "Soil_Dirt"
    },
    {
      "x": -7,
      "y": 10,
      "z": -4,
      "name": "Soil_Dirt"
    },
    {
      "x": -7,
      "y": 11,
      "z": -4,
      "name": "Soil_Dirt"
    },
    {
      "x": -7,
      "y": 12,
      "z": -4,
      "name": "Soil_Dirt"
    },
    {
      "x": -7,
      "y": 13,
      "z": -4,
      "name": "Soil_Grass_Full"
    },
    {
      "x": -7,
      "y": 9,
      "z": -3,
      "name": "Soil_Dirt"
    },
    {
      "x": -7,
      "y": 10,
      "z": -3,
      "name": "Soil_Dirt"
    },
    {
      "x": -7,
      "y": 11,
      "z": -3,
      "name": "Soil_Dirt"
    },
    {
      "x": -7,
      "y": 12,
      "z": -3,
      "name": "Soil_Dirt"
    },
    {
      "x": -7,
      "y": 13,
      "z": -3,
      "name": "Soil_Grass_Full"
    },
    {
      "x": -7,
      "y": 14,
      "z": -3,
      "name": "Plant_Grass_Sharp",
      "support": 15
    },
    {
      "x": -7,
      "y": 9,
      "z": -2,
      "name": "Soil_Dirt"
    },
    {
      "x": -7,
      "y": 10,
      "z": -2,
      "name": "Soil_Dirt"
    },
    {
      "x": -7,
      "y": 11,
      "z": -2,
      "name": "Soil_Dirt"
    },
    {
      "x": -7,
      "y": 12,
      "z": -2,
      "name": "Soil_Dirt"
    },
    {
      "x": -7,
      "y": 13,
      "z": -2,
      "name": "Soil_Grass_Full"
    },
    {
      "x": -7,
      "y": 8,
      "z": -1,
      "name": "Rock_Marble"
    },
    {
      "x": -7,
      "y": 9,
      "z": -1,
      "name": "Soil_Dirt"
    },
    {
      "x": -7,
      "y": 10,
      "z": -1,
      "name": "Soil_Dirt"
    },
    {
      "x": -7,
      "y": 11,
      "z": -1,
      "name": "Soil_Dirt"
    },
    {
      "x": -7,
      "y": 12,
      "z": -1,
      "name": "Soil_Dirt"
    },
    {
      "x": -7,
      "y": 13,
      "z": -1,
      "name": "Soil_Grass_Full"
    },
    {
      "x": -7,
      "y": 14,
      "z": -1,
      "name": "Plant_Grass_Sharp",
      "support": 15
    },
    {
      "x": -7,
      "y": 8,
      "z": 0,
      "name": "Rock_Marble"
    },
    {
      "x": -7,
      "y": 9,
      "z": 0,
      "name": "Soil_Dirt"
    },
    {
      "x": -7,
      "y": 10,
      "z": 0,
      "name": "Soil_Dirt"
    },
    {
      "x": -7,
      "y": 11,
      "z": 0,
      "name": "Soil_Dirt"
    },
    {
      "x": -7,
      "y": 12,
      "z": 0,
      "name": "Soil_Dirt"
    },
    {
      "x": -7,
      "y": 13,
      "z": 0,
      "name": "Soil_Grass_Full"
    },
    {
      "x": -7,
      "y": 8,
      "z": 1,
      "name": "Rock_Marble"
    },
    {
      "x": -7,
      "y": 9,
      "z": 1,
      "name": "Soil_Dirt"
    },
    {
      "x": -7,
      "y": 10,
      "z": 1,
      "name": "Soil_Dirt"
    },
    {
      "x": -7,
      "y": 11,
      "z": 1,
      "name": "Soil_Dirt"
    },
    {
      "x": -7,
      "y": 12,
      "z": 1,
      "name": "Soil_Dirt"
    },
    {
      "x": -7,
      "y": 13,
      "z": 1,
      "name": "Soil_Grass_Full"
    },
    {
      "x": -7,
      "y": 14,
      "z": 1,
      "name": "Plant_Crop_Mushroom_Glowing_Blue"
    },
    {
      "x": -7,
      "y": 7,
      "z": 2,
      "name": "Rock_Marble"
    },
    {
      "x": -7,
      "y": 8,
      "z": 2,
      "name": "Rock_Marble"
    },
    {
      "x": -7,
      "y": 9,
      "z": 2,
      "name": "Soil_Dirt"
    },
    {
      "x": -7,
      "y": 10,
      "z": 2,
      "name": "Soil_Dirt"
    },
    {
      "x": -7,
      "y": 11,
      "z": 2,
      "name": "Soil_Dirt"
    },
    {
      "x": -7,
      "y": 12,
      "z": 2,
      "name": "Soil_Dirt"
    },
    {
      "x": -7,
      "y": 13,
      "z": 2,
      "name": "Soil_Grass_Full"
    },
    {
      "x": -7,
      "y": 8,
      "z": 3,
      "name": "Soil_Dirt"
    },
    {
      "x": -7,
      "y": 9,
      "z": 3,
      "name": "Soil_Dirt"
    },
    {
      "x": -7,
      "y": 10,
      "z": 3,
      "name": "Soil_Dirt"
    },
    {
      "x": -7,
      "y": 11,
      "z": 3,
      "name": "Soil_Grass_Full"
    },
    {
      "x": -7,
      "y": 8,
      "z": 4,
      "name": "Soil_Dirt"
    },
    {
      "x": -7,
      "y": 9,
      "z": 4,
      "name": "Soil_Dirt"
    },
    {
      "x": -7,
      "y": 10,
      "z": 4,
      "name": "Soil_Grass_Full"
    },
    {
      "x": -7,
      "y": 11,
      "z": 4,
      "name": "Plant_Grass_Sharp",
      "support": 15
    },
    {
      "x": -7,
      "y": 8,
      "z": 5,
      "name": "Soil_Grass"
    },
    {
      "x": -6,
      "y": 12,
      "z": -7,
      "name": "Soil_Grass_Full"
    },
    {
      "x": -6,
      "y": 9,
      "z": -6,
      "name": "Soil_Dirt"
    },
    {
      "x": -6,
      "y": 10,
      "z": -6,
      "name": "Soil_Dirt"
    },
    {
      "x": -6,
      "y": 11,
      "z": -6,
      "name": "Soil_Dirt"
    },
    {
      "x": -6,
      "y": 12,
      "z": -6,
      "name": "Soil_Dirt"
    },
    {
      "x": -6,
      "y": 13,
      "z": -6,
      "name": "Soil_Grass_Full"
    },
    {
      "x": -6,
      "y": 9,
      "z": -5,
      "name": "Soil_Dirt"
    },
    {
      "x": -6,
      "y": 10,
      "z": -5,
      "name": "Soil_Dirt"
    },
    {
      "x": -6,
      "y": 11,
      "z": -5,
      "name": "Soil_Dirt"
    },
    {
      "x": -6,
      "y": 12,
      "z": -5,
      "name": "Soil_Dirt"
    },
    {
      "x": -6,
      "y": 13,
      "z": -5,
      "name": "Soil_Grass_Full"
    },
    {
      "x": -6,
      "y": 14,
      "z": -5,
      "name": "Plant_Grass_Sharp",
      "support": 15
    },
    {
      "x": -6,
      "y": 8,
      "z": -4,
      "name": "Rock_Marble"
    },
    {
      "x": -6,
      "y": 9,
      "z": -4,
      "name": "Rock_Marble"
    },
    {
      "x": -6,
      "y": 10,
      "z": -4,
      "name": "Soil_Dirt"
    },
    {
      "x": -6,
      "y": 11,
      "z": -4,
      "name": "Soil_Dirt"
    },
    {
      "x": -6,
      "y": 12,
      "z": -4,
      "name": "Soil_Dirt"
    },
    {
      "x": -6,
      "y": 13,
      "z": -4,
      "name": "Soil_Dirt"
    },
    {
      "x": -6,
      "y": 14,
      "z": -4,
      "name": "Soil_Grass_Full"
    },
    {
      "x": -6,
      "y": 15,
      "z": -4,
      "name": "Plant_Crop_Mushroom_Glowing_Blue"
    },
    {
      "x": -6,
      "y": 8,
      "z": -3,
      "name": "Rock_Marble"
    },
    {
      "x": -6,
      "y": 9,
      "z": -3,
      "name": "Rock_Marble"
    },
    {
      "x": -6,
      "y": 10,
      "z": -3,
      "name": "Soil_Dirt"
    },
    {
      "x": -6,
      "y": 11,
      "z": -3,
      "name": "Soil_Dirt"
    },
    {
      "x": -6,
      "y": 12,
      "z": -3,
      "name": "Soil_Dirt"
    },
    {
      "x": -6,
      "y": 13,
      "z": -3,
      "name": "Soil_Dirt"
    },
    {
      "x": -6,
      "y": 14,
      "z": -3,
      "name": "Soil_Grass_Full"
    },
    {
      "x": -6,
      "y": 8,
      "z": -2,
      "name": "Rock_Marble"
    },
    {
      "x": -6,
      "y": 9,
      "z": -2,
      "name": "Rock_Marble"
    },
    {
      "x": -6,
      "y": 10,
      "z": -2,
      "name": "Soil_Dirt"
    },
    {
      "x": -6,
      "y": 11,
      "z": -2,
      "name": "Soil_Dirt"
    },
    {
      "x": -6,
      "y": 12,
      "z": -2,
      "name": "Soil_Dirt"
    },
    {
      "x": -6,
      "y": 13,
      "z": -2,
      "name": "Soil_Dirt"
    },
    {
      "x": -6,
      "y": 14,
      "z": -2,
      "name": "Soil_Grass_Full"
    },
    {
      "x": -6,
      "y": 8,
      "z": -1,
      "name": "Rock_Marble"
    },
    {
      "x": -6,
      "y": 9,
      "z": -1,
      "name": "Rock_Marble"
    },
    {
      "x": -6,
      "y": 10,
      "z": -1,
      "name": "Soil_Dirt"
    },
    {
      "x": -6,
      "y": 11,
      "z": -1,
      "name": "Soil_Dirt"
    },
    {
      "x": -6,
      "y": 12,
      "z": -1,
      "name": "Soil_Dirt"
    },
    {
      "x": -6,
      "y": 13,
      "z": -1,
      "name": "Soil_Dirt"
    },
    {
      "x": -6,
      "y": 14,
      "z": -1,
      "name": "Soil_Grass_Full"
    },
    {
      "x": -6,
      "y": 15,
      "z": -1,
      "name": "Plant_Grass_Sharp",
      "support": 15
    },
    {
      "x": -6,
      "y": 8,
      "z": 0,
      "name": "Rock_Marble"
    },
    {
      "x": -6,
      "y": 9,
      "z": 0,
      "name": "Rock_Marble"
    },
    {
      "x": -6,
      "y": 10,
      "z": 0,
      "name": "Soil_Dirt"
    },
    {
      "x": -6,
      "y": 11,
      "z": 0,
      "name": "Soil_Dirt"
    },
    {
      "x": -6,
      "y": 12,
      "z": 0,
      "name": "Soil_Dirt"
    },
    {
      "x": -6,
      "y": 13,
      "z": 0,
      "name": "Soil_Dirt"
    },
    {
      "x": -6,
      "y": 14,
      "z": 0,
      "name": "Soil_Grass_Full"
    },
    {
      "x": -6,
      "y": 7,
      "z": 1,
      "name": "Rock_Marble"
    },
    {
      "x": -6,
      "y": 8,
      "z": 1,
      "name": "Rock_Marble"
    },
    {
      "x": -6,
      "y": 9,
      "z": 1,
      "name": "Rock_Marble"
    },
    {
      "x": -6,
      "y": 10,
      "z": 1,
      "name": "Soil_Dirt"
    },
    {
      "x": -6,
      "y": 11,
      "z": 1,
      "name": "Soil_Dirt"
    },
    {
      "x": -6,
      "y": 12,
      "z": 1,
      "name": "Soil_Dirt"
    },
    {
      "x": -6,
      "y": 13,
      "z": 1,
      "name": "Soil_Dirt"
    },
    {
      "x": -6,
      "y": 14,
      "z": 1,
      "name": "Soil_Grass_Full"
    },
    {
      "x": -6,
      "y": 15,
      "z": 1,
      "name": "Plant_Grass_Sharp",
      "support": 15
    },
    {
      "x": -6,
      "y": 7,
      "z": 2,
      "name": "Rock_Marble"
    },
    {
      "x": -6,
      "y": 8,
      "z": 2,
      "name": "Rock_Marble"
    },
    {
      "x": -6,
      "y": 9,
      "z": 2,
      "name": "Rock_Marble"
    },
    {
      "x": -6,
      "y": 10,
      "z": 2,
      "name": "Soil_Dirt"
    },
    {
      "x": -6,
      "y": 11,
      "z": 2,
      "name": "Soil_Dirt"
    },
    {
      "x": -6,
      "y": 12,
      "z": 2,
      "name": "Soil_Dirt"
    },
    {
      "x": -6,
      "y": 13,
      "z": 2,
      "name": "Soil_Dirt"
    },
    {
      "x": -6,
      "y": 14,
      "z": 2,
      "name": "Soil_Grass_Full"
    },
    {
      "x": -6,
      "y": 7,
      "z": 3,
      "name": "Rock_Marble"
    },
    {
      "x": -6,
      "y": 8,
      "z": 3,
      "name": "Rock_Marble"
    },
    {
      "x": -6,
      "y": 9,
      "z": 3,
      "name": "Rock_Marble"
    },
    {
      "x": -6,
      "y": 10,
      "z": 3,
      "name": "Soil_Dirt"
    },
    {
      "x": -6,
      "y": 11,
      "z": 3,
      "name": "Soil_Dirt"
    },
    {
      "x": -6,
      "y": 12,
      "z": 3,
      "name": "Soil_Dirt"
    },
    {
      "x": -6,
      "y": 13,
      "z": 3,
      "name": "Soil_Dirt"
    },
    {
      "x": -6,
      "y": 14,
      "z": 3,
      "name": "Soil_Grass_Full"
    },
    {
      "x": -6,
      "y": 7,
      "z": 4,
      "name": "Rock_Marble"
    },
    {
      "x": -6,
      "y": 8,
      "z": 4,
      "name": "Rock_Marble"
    },
    {
      "x": -6,
      "y": 9,
      "z": 4,
      "name": "Soil_Dirt"
    },
    {
      "x": -6,
      "y": 10,
      "z": 4,
      "name": "Soil_Dirt"
    },
    {
      "x": -6,
      "y": 11,
      "z": 4,
      "name": "Soil_Dirt"
    },
    {
      "x": -6,
      "y": 12,
      "z": 4,
      "name": "Soil_Dirt"
    },
    {
      "x": -6,
      "y": 13,
      "z": 4,
      "name": "Soil_Grass_Full"
    },
    {
      "x": -6,
      "y": 14,
      "z": 4,
      "name": "Plant_Crop_Mushroom_Glowing_Blue"
    },
    {
      "x": -6,
      "y": 7,
      "z": 5,
      "name": "Rock_Marble"
    },
    {
      "x": -6,
      "y": 8,
      "z": 5,
      "name": "Rock_Marble"
    },
    {
      "x": -6,
      "y": 9,
      "z": 5,
      "name": "Soil_Dirt"
    },
    {
      "x": -6,
      "y": 10,
      "z": 5,
      "name": "Soil_Dirt"
    },
    {
      "x": -6,
      "y": 11,
      "z": 5,
      "name": "Soil_Dirt"
    },
    {
      "x": -6,
      "y": 12,
      "z": 5,
      "name": "Soil_Dirt"
    },
    {
      "x": -6,
      "y": 13,
      "z": 5,
      "name": "Soil_Grass_Full"
    },
    {
      "x": -6,
      "y": 7,
      "z": 6,
      "name": "Soil_Dirt"
    },
    {
      "x": -6,
      "y": 8,
      "z": 6,
      "name": "Soil_Dirt"
    },
    {
      "x": -6,
      "y": 9,
      "z": 6,
      "name": "Soil_Dirt"
    },
    {
      "x": -6,
      "y": 10,
      "z": 6,
      "name": "Soil_Dirt"
    },
    {
      "x": -6,
      "y": 11,
      "z": 6,
      "name": "Soil_Grass_Full"
    },
    {
      "x": -6,
      "y": 9,
      "z": 7,
      "name": "Soil_Dirt"
    },
    {
      "x": -6,
      "y": 10,
      "z": 7,
      "name": "Soil_Grass_Full"
    },
    {
      "x": -6,
      "y": 11,
      "z": 7,
      "name": "Plant_Grass_Sharp",
      "support": 15
    },
    {
      "x": -5,
      "y": 9,
      "z": -7,
      "name": "Soil_Dirt"
    },
    {
      "x": -5,
      "y": 10,
      "z": -7,
      "name": "Soil_Dirt"
    },
    {
      "x": -5,
      "y": 11,
      "z": -7,
      "name": "Soil_Dirt"
    },
    {
      "x": -5,
      "y": 12,
      "z": -7,
      "name": "Soil_Grass_Full"
    },
    {
      "x": -5,
      "y": 8,
      "z": -6,
      "name": "Rock_Marble"
    },
    {
      "x": -5,
      "y": 9,
      "z": -6,
      "name": "Soil_Dirt"
    },
    {
      "x": -5,
      "y": 10,
      "z": -6,
      "name": "Soil_Dirt"
    },
    {
      "x": -5,
      "y": 11,
      "z": -6,
      "name": "Soil_Dirt"
    },
    {
      "x": -5,
      "y": 12,
      "z": -6,
      "name": "Soil_Dirt"
    },
    {
      "x": -5,
      "y": 13,
      "z": -6,
      "name": "Soil_Grass_Full"
    },
    {
      "x": -5,
      "y": 8,
      "z": -5,
      "name": "Rock_Marble"
    },
    {
      "x": -5,
      "y": 9,
      "z": -5,
      "name": "Rock_Marble"
    },
    {
      "x": -5,
      "y": 10,
      "z": -5,
      "name": "Soil_Dirt"
    },
    {
      "x": -5,
      "y": 11,
      "z": -5,
      "name": "Soil_Dirt"
    },
    {
      "x": -5,
      "y": 12,
      "z": -5,
      "name": "Soil_Dirt"
    },
    {
      "x": -5,
      "y": 13,
      "z": -5,
      "name": "Soil_Dirt"
    },
    {
      "x": -5,
      "y": 14,
      "z": -5,
      "name": "Soil_Grass_Full"
    },
    {
      "x": -5,
      "y": 7,
      "z": -4,
      "name": "Rock_Marble"
    },
    {
      "x": -5,
      "y": 8,
      "z": -4,
      "name": "Rock_Marble"
    },
    {
      "x": -5,
      "y": 9,
      "z": -4,
      "name": "Rock_Marble"
    },
    {
      "x": -5,
      "y": 10,
      "z": -4,
      "name": "Soil_Dirt"
    },
    {
      "x": -5,
      "y": 11,
      "z": -4,
      "name": "Soil_Dirt"
    },
    {
      "x": -5,
      "y": 12,
      "z": -4,
      "name": "Soil_Dirt"
    },
    {
      "x": -5,
      "y": 13,
      "z": -4,
      "name": "Soil_Dirt"
    },
    {
      "x": -5,
      "y": 14,
      "z": -4,
      "name": "Soil_Grass_Full"
    },
    {
      "x": -5,
      "y": 6,
      "z": -3,
      "name": "Rock_Marble"
    },
    {
      "x": -5,
      "y": 7,
      "z": -3,
      "name": "Rock_Marble"
    },
    {
      "x": -5,
      "y": 8,
      "z": -3,
      "name": "Rock_Marble"
    },
    {
      "x": -5,
      "y": 9,
      "z": -3,
      "name": "Rock_Marble"
    },
    {
      "x": -5,
      "y": 10,
      "z": -3,
      "name": "Rock_Marble"
    },
    {
      "x": -5,
      "y": 11,
      "z": -3,
      "name": "Soil_Dirt"
    },
    {
      "x": -5,
      "y": 12,
      "z": -3,
      "name": "Soil_Dirt"
    },
    {
      "x": -5,
      "y": 13,
      "z": -3,
      "name": "Soil_Dirt"
    },
    {
      "x": -5,
      "y": 14,
      "z": -3,
      "name": "Soil_Dirt"
    },
    {
      "x": -5,
      "y": 15,
      "z": -3,
      "name": "Soil_Grass_Full"
    },
    {
      "x": -5,
      "y": 5,
      "z": -2,
      "name": "Rock_Marble"
    },
    {
      "x": -5,
      "y": 6,
      "z": -2,
      "name": "Rock_Marble"
    },
    {
      "x": -5,
      "y": 7,
      "z": -2,
      "name": "Rock_Marble"
    },
    {
      "x": -5,
      "y": 8,
      "z": -2,
      "name": "Rock_Marble"
    },
    {
      "x": -5,
      "y": 9,
      "z": -2,
      "name": "Rock_Marble"
    },
    {
      "x": -5,
      "y": 10,
      "z": -2,
      "name": "Rock_Marble"
    },
    {
      "x": -5,
      "y": 11,
      "z": -2,
      "name": "Soil_Dirt"
    },
    {
      "x": -5,
      "y": 12,
      "z": -2,
      "name": "Soil_Dirt"
    },
    {
      "x": -5,
      "y": 13,
      "z": -2,
      "name": "Soil_Dirt"
    },
    {
      "x": -5,
      "y": 14,
      "z": -2,
      "name": "Soil_Dirt"
    },
    {
      "x": -5,
      "y": 15,
      "z": -2,
      "name": "Soil_Grass_Full"
    },
    {
      "x": -5,
      "y": 5,
      "z": -1,
      "name": "Rock_Marble"
    },
    {
      "x": -5,
      "y": 6,
      "z": -1,
      "name": "Rock_Marble"
    },
    {
      "x": -5,
      "y": 7,
      "z": -1,
      "name": "Rock_Marble"
    },
    {
      "x": -5,
      "y": 8,
      "z": -1,
      "name": "Rock_Marble"
    },
    {
      "x": -5,
      "y": 9,
      "z": -1,
      "name": "Rock_Marble"
    },
    {
      "x": -5,
      "y": 10,
      "z": -1,
      "name": "Rock_Marble"
    },
    {
      "x": -5,
      "y": 11,
      "z": -1,
      "name": "Soil_Dirt"
    },
    {
      "x": -5,
      "y": 12,
      "z": -1,
      "name": "Soil_Dirt"
    },
    {
      "x": -5,
      "y": 13,
      "z": -1,
      "name": "Soil_Dirt"
    },
    {
      "x": -5,
      "y": 14,
      "z": -1,
      "name": "Soil_Dirt"
    },
    {
      "x": -5,
      "y": 15,
      "z": -1,
      "name": "Soil_Grass_Full"
    },
    {
      "x": -5,
      "y": 5,
      "z": 0,
      "name": "Rock_Marble"
    },
    {
      "x": -5,
      "y": 6,
      "z": 0,
      "name": "Rock_Marble"
    },
    {
      "x": -5,
      "y": 7,
      "z": 0,
      "name": "Rock_Marble"
    },
    {
      "x": -5,
      "y": 8,
      "z": 0,
      "name": "Rock_Marble"
    },
    {
      "x": -5,
      "y": 9,
      "z": 0,
      "name": "Rock_Marble"
    },
    {
      "x": -5,
      "y": 10,
      "z": 0,
      "name": "Rock_Marble"
    },
    {
      "x": -5,
      "y": 11,
      "z": 0,
      "name": "Soil_Dirt"
    },
    {
      "x": -5,
      "y": 12,
      "z": 0,
      "name": "Soil_Dirt"
    },
    {
      "x": -5,
      "y": 13,
      "z": 0,
      "name": "Soil_Dirt"
    },
    {
      "x": -5,
      "y": 14,
      "z": 0,
      "name": "Soil_Dirt"
    },
    {
      "x": -5,
      "y": 15,
      "z": 0,
      "name": "Soil_Grass_Full"
    },
    {
      "x": -5,
      "y": 6,
      "z": 1,
      "name": "Rock_Marble"
    },
    {
      "x": -5,
      "y": 7,
      "z": 1,
      "name": "Rock_Marble"
    },
    {
      "x": -5,
      "y": 8,
      "z": 1,
      "name": "Rock_Marble"
    },
    {
      "x": -5,
      "y": 9,
      "z": 1,
      "name": "Rock_Marble"
    },
    {
      "x": -5,
      "y": 10,
      "z": 1,
      "name": "Rock_Marble"
    },
    {
      "x": -5,
      "y": 11,
      "z": 1,
      "name": "Soil_Dirt"
    },
    {
      "x": -5,
      "y": 12,
      "z": 1,
      "name": "Soil_Dirt"
    },
    {
      "x": -5,
      "y": 13,
      "z": 1,
      "name": "Soil_Dirt"
    },
    {
      "x": -5,
      "y": 14,
      "z": 1,
      "name": "Soil_Dirt"
    },
    {
      "x": -5,
      "y": 15,
      "z": 1,
      "name": "Soil_Grass_Full"
    },
    {
      "x": -5,
      "y": 7,
      "z": 2,
      "name": "Rock_Marble"
    },
    {
      "x": -5,
      "y": 8,
      "z": 2,
      "name": "Rock_Marble"
    },
    {
      "x": -5,
      "y": 9,
      "z": 2,
      "name": "Rock_Marble"
    },
    {
      "x": -5,
      "y": 10,
      "z": 2,
      "name": "Rock_Marble"
    },
    {
      "x": -5,
      "y": 11,
      "z": 2,
      "name": "Soil_Dirt"
    },
    {
      "x": -5,
      "y": 12,
      "z": 2,
      "name": "Soil_Dirt"
    },
    {
      "x": -5,
      "y": 13,
      "z": 2,
      "name": "Soil_Dirt"
    },
    {
      "x": -5,
      "y": 14,
      "z": 2,
      "name": "Soil_Dirt"
    },
    {
      "x": -5,
      "y": 15,
      "z": 2,
      "name": "Soil_Grass_Full"
    },
    {
      "x": -5,
      "y": 7,
      "z": 3,
      "name": "Rock_Marble"
    },
    {
      "x": -5,
      "y": 8,
      "z": 3,
      "name": "Rock_Marble"
    },
    {
      "x": -5,
      "y": 9,
      "z": 3,
      "name": "Rock_Marble"
    },
    {
      "x": -5,
      "y": 10,
      "z": 3,
      "name": "Soil_Dirt"
    },
    {
      "x": -5,
      "y": 11,
      "z": 3,
      "name": "Soil_Dirt"
    },
    {
      "x": -5,
      "y": 12,
      "z": 3,
      "name": "Soil_Dirt"
    },
    {
      "x": -5,
      "y": 13,
      "z": 3,
      "name": "Soil_Dirt"
    },
    {
      "x": -5,
      "y": 14,
      "z": 3,
      "name": "Soil_Grass_Full"
    },
    {
      "x": -5,
      "y": 15,
      "z": 3,
      "name": "Plant_Grass_Sharp",
      "support": 15
    },
    {
      "x": -5,
      "y": 6,
      "z": 4,
      "name": "Rock_Marble"
    },
    {
      "x": -5,
      "y": 7,
      "z": 4,
      "name": "Rock_Marble"
    },
    {
      "x": -5,
      "y": 8,
      "z": 4,
      "name": "Rock_Marble"
    },
    {
      "x": -5,
      "y": 9,
      "z": 4,
      "name": "Rock_Marble"
    },
    {
      "x": -5,
      "y": 10,
      "z": 4,
      "name": "Soil_Dirt"
    },
    {
      "x": -5,
      "y": 11,
      "z": 4,
      "name": "Soil_Dirt"
    },
    {
      "x": -5,
      "y": 12,
      "z": 4,
      "name": "Soil_Dirt"
    },
    {
      "x": -5,
      "y": 13,
      "z": 4,
      "name": "Soil_Dirt"
    },
    {
      "x": -5,
      "y": 14,
      "z": 4,
      "name": "Soil_Grass_Full"
    },
    {
      "x": -5,
      "y": 15,
      "z": 4,
      "name": "Plant_Grass_Sharp",
      "support": 15
    },
    {
      "x": -5,
      "y": 7,
      "z": 5,
      "name": "Rock_Marble"
    },
    {
      "x": -5,
      "y": 8,
      "z": 5,
      "name": "Rock_Marble"
    },
    {
      "x": -5,
      "y": 9,
      "z": 5,
      "name": "Soil_Dirt"
    },
    {
      "x": -5,
      "y": 10,
      "z": 5,
      "name": "Soil_Dirt"
    },
    {
      "x": -5,
      "y": 11,
      "z": 5,
      "name": "Soil_Dirt"
    },
    {
      "x": -5,
      "y": 12,
      "z": 5,
      "name": "Soil_Dirt"
    },
    {
      "x": -5,
      "y": 13,
      "z": 5,
      "name": "Soil_Grass_Full"
    },
    {
      "x": -5,
      "y": 7,
      "z": 6,
      "name": "Rock_Marble"
    },
    {
      "x": -5,
      "y": 8,
      "z": 6,
      "name": "Soil_Dirt"
    },
    {
      "x": -5,
      "y": 9,
      "z": 6,
      "name": "Soil_Dirt"
    },
    {
      "x": -5,
      "y": 10,
      "z": 6,
      "name": "Soil_Dirt"
    },
    {
      "x": -5,
      "y": 11,
      "z": 6,
      "name": "Soil_Dirt"
    },
    {
      "x": -5,
      "y": 12,
      "z": 6,
      "name": "Soil_Grass_Full"
    },
    {
      "x": -5,
      "y": 13,
      "z": 6,
      "name": "Plant_Crop_Mushroom_Glowing_Blue"
    },
    {
      "x": -5,
      "y": 8,
      "z": 7,
      "name": "Soil_Dirt"
    },
    {
      "x": -5,
      "y": 9,
      "z": 7,
      "name": "Soil_Dirt"
    },
    {
      "x": -5,
      "y": 10,
      "z": 7,
      "name": "Soil_Dirt"
    },
    {
      "x": -5,
      "y": 11,
      "z": 7,
      "name": "Soil_Grass_Full"
    },
    {
      "x": -4,
      "y": 10,
      "z": -9,
      "name": "Soil_Grass_Full"
    },
    {
      "x": -4,
      "y": 9,
      "z": -8,
      "name": "Soil_Dirt"
    },
    {
      "x": -4,
      "y": 10,
      "z": -8,
      "name": "Soil_Dirt"
    },
    {
      "x": -4,
      "y": 11,
      "z": -8,
      "name": "Soil_Dirt"
    },
    {
      "x": -4,
      "y": 12,
      "z": -8,
      "name": "Soil_Dirt"
    },
    {
      "x": -4,
      "y": 13,
      "z": -8,
      "name": "Soil_Grass_Full"
    },
    {
      "x": -4,
      "y": 14,
      "z": -8,
      "name": "Plant_Crop_Mushroom_Glowing_Blue"
    },
    {
      "x": -4,
      "y": 8,
      "z": -7,
      "name": "Rock_Marble"
    },
    {
      "x": -4,
      "y": 9,
      "z": -7,
      "name": "Soil_Dirt"
    },
    {
      "x": -4,
      "y": 10,
      "z": -7,
      "name": "Soil_Dirt"
    },
    {
      "x": -4,
      "y": 11,
      "z": -7,
      "name": "Soil_Dirt"
    },
    {
      "x": -4,
      "y": 12,
      "z": -7,
      "name": "Soil_Dirt"
    },
    {
      "x": -4,
      "y": 13,
      "z": -7,
      "name": "Soil_Grass_Full"
    },
    {
      "x": -4,
      "y": 7,
      "z": -6,
      "name": "Rock_Marble"
    },
    {
      "x": -4,
      "y": 8,
      "z": -6,
      "name": "Rock_Marble"
    },
    {
      "x": -4,
      "y": 9,
      "z": -6,
      "name": "Rock_Marble"
    },
    {
      "x": -4,
      "y": 10,
      "z": -6,
      "name": "Soil_Dirt"
    },
    {
      "x": -4,
      "y": 11,
      "z": -6,
      "name": "Soil_Dirt"
    },
    {
      "x": -4,
      "y": 12,
      "z": -6,
      "name": "Soil_Dirt"
    },
    {
      "x": -4,
      "y": 13,
      "z": -6,
      "name": "Soil_Dirt"
    },
    {
      "x": -4,
      "y": 14,
      "z": -6,
      "name": "Soil_Grass_Full"
    },
    {
      "x": -4,
      "y": 15,
      "z": -6,
      "name": "Plant_Grass_Sharp",
      "support": 15
    },
    {
      "x": -4,
      "y": 6,
      "z": -5,
      "name": "Rock_Marble"
    },
    {
      "x": -4,
      "y": 7,
      "z": -5,
      "name": "Rock_Marble"
    },
    {
      "x": -4,
      "y": 8,
      "z": -5,
      "name": "Rock_Marble"
    },
    {
      "x": -4,
      "y": 9,
      "z": -5,
      "name": "Rock_Marble"
    },
    {
      "x": -4,
      "y": 10,
      "z": -5,
      "name": "Soil_Dirt"
    },
    {
      "x": -4,
      "y": 11,
      "z": -5,
      "name": "Soil_Dirt"
    },
    {
      "x": -4,
      "y": 12,
      "z": -5,
      "name": "Soil_Dirt"
    },
    {
      "x": -4,
      "y": 13,
      "z": -5,
      "name": "Soil_Dirt"
    },
    {
      "x": -4,
      "y": 14,
      "z": -5,
      "name": "Soil_Grass_Full"
    },
    {
      "x": -4,
      "y": 5,
      "z": -4,
      "name": "Rock_Marble"
    },
    {
      "x": -4,
      "y": 6,
      "z": -4,
      "name": "Rock_Marble"
    },
    {
      "x": -4,
      "y": 7,
      "z": -4,
      "name": "Rock_Marble"
    },
    {
      "x": -4,
      "y": 8,
      "z": -4,
      "name": "Rock_Marble"
    },
    {
      "x": -4,
      "y": 9,
      "z": -4,
      "name": "Rock_Marble"
    },
    {
      "x": -4,
      "y": 10,
      "z": -4,
      "name": "Rock_Marble"
    },
    {
      "x": -4,
      "y": 11,
      "z": -4,
      "name": "Soil_Dirt"
    },
    {
      "x": -4,
      "y": 12,
      "z": -4,
      "name": "Soil_Dirt"
    },
    {
      "x": -4,
      "y": 13,
      "z": -4,
      "name": "Soil_Dirt"
    },
    {
      "x": -4,
      "y": 14,
      "z": -4,
      "name": "Soil_Dirt"
    },
    {
      "x": -4,
      "y": 15,
      "z": -4,
      "name": "Soil_Grass_Full"
    },
    {
      "x": -4,
      "y": 2,
      "z": -3,
      "name": "Rock_Marble"
    },
    {
      "x": -4,
      "y": 3,
      "z": -3,
      "name": "Rock_Marble"
    },
    {
      "x": -4,
      "y": 4,
      "z": -3,
      "name": "Rock_Marble"
    },
    {
      "x": -4,
      "y": 5,
      "z": -3,
      "name": "Rock_Marble"
    },
    {
      "x": -4,
      "y": 6,
      "z": -3,
      "name": "Rock_Marble"
    },
    {
      "x": -4,
      "y": 7,
      "z": -3,
      "name": "Rock_Marble"
    },
    {
      "x": -4,
      "y": 8,
      "z": -3,
      "name": "Rock_Marble"
    },
    {
      "x": -4,
      "y": 9,
      "z": -3,
      "name": "Rock_Marble"
    },
    {
      "x": -4,
      "y": 10,
      "z": -3,
      "name": "Rock_Marble"
    },
    {
      "x": -4,
      "y": 11,
      "z": -3,
      "name": "Soil_Dirt"
    },
    {
      "x": -4,
      "y": 12,
      "z": -3,
      "name": "Soil_Dirt"
    },
    {
      "x": -4,
      "y": 13,
      "z": -3,
      "name": "Soil_Dirt"
    },
    {
      "x": -4,
      "y": 14,
      "z": -3,
      "name": "Soil_Dirt"
    },
    {
      "x": -4,
      "y": 15,
      "z": -3,
      "name": "Soil_Grass_Full"
    },
    {
      "x": -4,
      "y": 16,
      "z": -3,
      "name": "Plant_Grass_Sharp",
      "support": 15
    },
    {
      "x": -4,
      "y": 3,
      "z": -2,
      "name": "Rock_Marble"
    },
    {
      "x": -4,
      "y": 4,
      "z": -2,
      "name": "Rock_Marble"
    },
    {
      "x": -4,
      "y": 5,
      "z": -2,
      "name": "Rock_Marble"
    },
    {
      "x": -4,
      "y": 6,
      "z": -2,
      "name": "Rock_Marble"
    },
    {
      "x": -4,
      "y": 7,
      "z": -2,
      "name": "Rock_Marble"
    },
    {
      "x": -4,
      "y": 8,
      "z": -2,
      "name": "Rock_Marble"
    },
    {
      "x": -4,
      "y": 9,
      "z": -2,
      "name": "Rock_Marble"
    },
    {
      "x": -4,
      "y": 10,
      "z": -2,
      "name": "Rock_Marble"
    },
    {
      "x": -4,
      "y": 11,
      "z": -2,
      "name": "Soil_Dirt"
    },
    {
      "x": -4,
      "y": 12,
      "z": -2,
      "name": "Soil_Dirt"
    },
    {
      "x": -4,
      "y": 13,
      "z": -2,
      "name": "Soil_Dirt"
    },
    {
      "x": -4,
      "y": 14,
      "z": -2,
      "name": "Soil_Dirt"
    },
    {
      "x": -4,
      "y": 15,
      "z": -2,
      "name": "Soil_Grass_Full"
    },
    {
      "x": -4,
      "y": 4,
      "z": -1,
      "name": "Rock_Marble"
    },
    {
      "x": -4,
      "y": 5,
      "z": -1,
      "name": "Rock_Marble"
    },
    {
      "x": -4,
      "y": 6,
      "z": -1,
      "name": "Rock_Marble"
    },
    {
      "x": -4,
      "y": 7,
      "z": -1,
      "name": "Rock_Marble"
    },
    {
      "x": -4,
      "y": 8,
      "z": -1,
      "name": "Rock_Marble"
    },
    {
      "x": -4,
      "y": 9,
      "z": -1,
      "name": "Rock_Marble"
    },
    {
      "x": -4,
      "y": 10,
      "z": -1,
      "name": "Rock_Marble"
    },
    {
      "x": -4,
      "y": 11,
      "z": -1,
      "name": "Soil_Dirt"
    },
    {
      "x": -4,
      "y": 12,
      "z": -1,
      "name": "Soil_Dirt"
    },
    {
      "x": -4,
      "y": 13,
      "z": -1,
      "name": "Soil_Dirt"
    },
    {
      "x": -4,
      "y": 14,
      "z": -1,
      "name": "Soil_Dirt"
    },
    {
      "x": -4,
      "y": 15,
      "z": -1,
      "name": "Soil_Grass_Full"
    },
    {
      "x": -4,
      "y": 4,
      "z": 0,
      "name": "Rock_Marble"
    },
    {
      "x": -4,
      "y": 5,
      "z": 0,
      "name": "Rock_Marble"
    },
    {
      "x": -4,
      "y": 6,
      "z": 0,
      "name": "Rock_Marble"
    },
    {
      "x": -4,
      "y": 7,
      "z": 0,
      "name": "Rock_Marble"
    },
    {
      "x": -4,
      "y": 8,
      "z": 0,
      "name": "Rock_Marble"
    },
    {
      "x": -4,
      "y": 9,
      "z": 0,
      "name": "Rock_Marble"
    },
    {
      "x": -4,
      "y": 10,
      "z": 0,
      "name": "Rock_Marble"
    },
    {
      "x": -4,
      "y": 11,
      "z": 0,
      "name": "Soil_Dirt"
    },
    {
      "x": -4,
      "y": 12,
      "z": 0,
      "name": "Soil_Dirt"
    },
    {
      "x": -4,
      "y": 13,
      "z": 0,
      "name": "Soil_Dirt"
    },
    {
      "x": -4,
      "y": 14,
      "z": 0,
      "name": "Soil_Dirt"
    },
    {
      "x": -4,
      "y": 15,
      "z": 0,
      "name": "Soil_Grass_Full"
    },
    {
      "x": -4,
      "y": 3,
      "z": 1,
      "name": "Rock_Marble"
    },
    {
      "x": -4,
      "y": 4,
      "z": 1,
      "name": "Rock_Marble"
    },
    {
      "x": -4,
      "y": 5,
      "z": 1,
      "name": "Rock_Marble"
    },
    {
      "x": -4,
      "y": 6,
      "z": 1,
      "name": "Rock_Marble"
    },
    {
      "x": -4,
      "y": 7,
      "z": 1,
      "name": "Rock_Marble"
    },
    {
      "x": -4,
      "y": 8,
      "z": 1,
      "name": "Rock_Marble"
    },
    {
      "x": -4,
      "y": 9,
      "z": 1,
      "name": "Rock_Marble"
    },
    {
      "x": -4,
      "y": 10,
      "z": 1,
      "name": "Rock_Marble"
    },
    {
      "x": -4,
      "y": 11,
      "z": 1,
      "name": "Soil_Dirt"
    },
    {
      "x": -4,
      "y": 12,
      "z": 1,
      "name": "Soil_Dirt"
    },
    {
      "x": -4,
      "y": 13,
      "z": 1,
      "name": "Soil_Dirt"
    },
    {
      "x": -4,
      "y": 14,
      "z": 1,
      "name": "Soil_Dirt"
    },
    {
      "x": -4,
      "y": 15,
      "z": 1,
      "name": "Soil_Grass_Full"
    },
    {
      "x": -4,
      "y": 4,
      "z": 2,
      "name": "Rock_Marble"
    },
    {
      "x": -4,
      "y": 5,
      "z": 2,
      "name": "Rock_Marble"
    },
    {
      "x": -4,
      "y": 6,
      "z": 2,
      "name": "Rock_Marble"
    },
    {
      "x": -4,
      "y": 7,
      "z": 2,
      "name": "Rock_Marble"
    },
    {
      "x": -4,
      "y": 8,
      "z": 2,
      "name": "Rock_Marble"
    },
    {
      "x": -4,
      "y": 9,
      "z": 2,
      "name": "Rock_Marble"
    },
    {
      "x": -4,
      "y": 10,
      "z": 2,
      "name": "Rock_Marble"
    },
    {
      "x": -4,
      "y": 11,
      "z": 2,
      "name": "Soil_Dirt"
    },
    {
      "x": -4,
      "y": 12,
      "z": 2,
      "name": "Soil_Dirt"
    },
    {
      "x": -4,
      "y": 13,
      "z": 2,
      "name": "Soil_Dirt"
    },
    {
      "x": -4,
      "y": 14,
      "z": 2,
      "name": "Soil_Dirt"
    },
    {
      "x": -4,
      "y": 15,
      "z": 2,
      "name": "Soil_Grass_Full"
    },
    {
      "x": -4,
      "y": 5,
      "z": 3,
      "name": "Rock_Marble"
    },
    {
      "x": -4,
      "y": 6,
      "z": 3,
      "name": "Rock_Marble"
    },
    {
      "x": -4,
      "y": 7,
      "z": 3,
      "name": "Rock_Marble"
    },
    {
      "x": -4,
      "y": 8,
      "z": 3,
      "name": "Rock_Marble"
    },
    {
      "x": -4,
      "y": 9,
      "z": 3,
      "name": "Rock_Marble"
    },
    {
      "x": -4,
      "y": 10,
      "z": 3,
      "name": "Rock_Marble"
    },
    {
      "x": -4,
      "y": 11,
      "z": 3,
      "name": "Soil_Dirt"
    },
    {
      "x": -4,
      "y": 12,
      "z": 3,
      "name": "Soil_Dirt"
    },
    {
      "x": -4,
      "y": 13,
      "z": 3,
      "name": "Soil_Dirt"
    },
    {
      "x": -4,
      "y": 14,
      "z": 3,
      "name": "Soil_Dirt"
    },
    {
      "x": -4,
      "y": 15,
      "z": 3,
      "name": "Soil_Grass_Full"
    },
    {
      "x": -4,
      "y": 7,
      "z": 4,
      "name": "Rock_Marble"
    },
    {
      "x": -4,
      "y": 8,
      "z": 4,
      "name": "Rock_Marble"
    },
    {
      "x": -4,
      "y": 9,
      "z": 4,
      "name": "Rock_Marble"
    },
    {
      "x": -4,
      "y": 10,
      "z": 4,
      "name": "Soil_Dirt"
    },
    {
      "x": -4,
      "y": 11,
      "z": 4,
      "name": "Soil_Dirt"
    },
    {
      "x": -4,
      "y": 12,
      "z": 4,
      "name": "Soil_Dirt"
    },
    {
      "x": -4,
      "y": 13,
      "z": 4,
      "name": "Soil_Dirt"
    },
    {
      "x": -4,
      "y": 14,
      "z": 4,
      "name": "Soil_Grass_Full"
    },
    {
      "x": -4,
      "y": 15,
      "z": 4,
      "name": "Plant_Grass_Sharp",
      "support": 15
    },
    {
      "x": -4,
      "y": 6,
      "z": 5,
      "name": "Rock_Marble"
    },
    {
      "x": -4,
      "y": 7,
      "z": 5,
      "name": "Rock_Marble"
    },
    {
      "x": -4,
      "y": 8,
      "z": 5,
      "name": "Rock_Marble"
    },
    {
      "x": -4,
      "y": 9,
      "z": 5,
      "name": "Rock_Marble"
    },
    {
      "x": -4,
      "y": 10,
      "z": 5,
      "name": "Soil_Dirt"
    },
    {
      "x": -4,
      "y": 11,
      "z": 5,
      "name": "Soil_Dirt"
    },
    {
      "x": -4,
      "y": 12,
      "z": 5,
      "name": "Soil_Dirt"
    },
    {
      "x": -4,
      "y": 13,
      "z": 5,
      "name": "Soil_Dirt"
    },
    {
      "x": -4,
      "y": 14,
      "z": 5,
      "name": "Soil_Grass_Full"
    },
    {
      "x": -4,
      "y": 7,
      "z": 6,
      "name": "Rock_Marble"
    },
    {
      "x": -4,
      "y": 8,
      "z": 6,
      "name": "Rock_Marble"
    },
    {
      "x": -4,
      "y": 9,
      "z": 6,
      "name": "Soil_Dirt"
    },
    {
      "x": -4,
      "y": 10,
      "z": 6,
      "name": "Soil_Dirt"
    },
    {
      "x": -4,
      "y": 11,
      "z": 6,
      "name": "Soil_Dirt"
    },
    {
      "x": -4,
      "y": 12,
      "z": 6,
      "name": "Soil_Dirt"
    },
    {
      "x": -4,
      "y": 13,
      "z": 6,
      "name": "Soil_Grass_Full"
    },
    {
      "x": -4,
      "y": 8,
      "z": 7,
      "name": "Rock_Marble"
    },
    {
      "x": -4,
      "y": 9,
      "z": 7,
      "name": "Soil_Dirt"
    },
    {
      "x": -4,
      "y": 10,
      "z": 7,
      "name": "Soil_Dirt"
    },
    {
      "x": -4,
      "y": 11,
      "z": 7,
      "name": "Soil_Dirt"
    },
    {
      "x": -4,
      "y": 12,
      "z": 7,
      "name": "Soil_Dirt"
    },
    {
      "x": -4,
      "y": 13,
      "z": 7,
      "name": "Soil_Grass_Full"
    },
    {
      "x": -4,
      "y": 9,
      "z": 8,
      "name": "Soil_Dirt"
    },
    {
      "x": -4,
      "y": 10,
      "z": 8,
      "name": "Soil_Dirt"
    },
    {
      "x": -4,
      "y": 11,
      "z": 8,
      "name": "Soil_Grass_Full"
    },
    {
      "x": -3,
      "y": 8,
      "z": -9,
      "name": "Soil_Dirt"
    },
    {
      "x": -3,
      "y": 9,
      "z": -9,
      "name": "Soil_Dirt"
    },
    {
      "x": -3,
      "y": 10,
      "z": -9,
      "name": "Soil_Dirt"
    },
    {
      "x": -3,
      "y": 11,
      "z": -9,
      "name": "Soil_Grass_Full"
    },
    {
      "x": -3,
      "y": 8,
      "z": -8,
      "name": "Rock_Marble"
    },
    {
      "x": -3,
      "y": 9,
      "z": -8,
      "name": "Rock_Marble"
    },
    {
      "x": -3,
      "y": 10,
      "z": -8,
      "name": "Soil_Dirt"
    },
    {
      "x": -3,
      "y": 11,
      "z": -8,
      "name": "Soil_Dirt"
    },
    {
      "x": -3,
      "y": 12,
      "z": -8,
      "name": "Soil_Dirt"
    },
    {
      "x": -3,
      "y": 13,
      "z": -8,
      "name": "Soil_Dirt"
    },
    {
      "x": -3,
      "y": 14,
      "z": -8,
      "name": "Soil_Grass_Full"
    },
    {
      "x": -3,
      "y": 7,
      "z": -7,
      "name": "Rock_Marble"
    },
    {
      "x": -3,
      "y": 8,
      "z": -7,
      "name": "Rock_Marble"
    },
    {
      "x": -3,
      "y": 9,
      "z": -7,
      "name": "Rock_Marble"
    },
    {
      "x": -3,
      "y": 10,
      "z": -7,
      "name": "Soil_Dirt"
    },
    {
      "x": -3,
      "y": 11,
      "z": -7,
      "name": "Soil_Dirt"
    },
    {
      "x": -3,
      "y": 12,
      "z": -7,
      "name": "Soil_Dirt"
    },
    {
      "x": -3,
      "y": 13,
      "z": -7,
      "name": "Soil_Dirt"
    },
    {
      "x": -3,
      "y": 14,
      "z": -7,
      "name": "Soil_Grass_Full"
    },
    {
      "x": -3,
      "y": 15,
      "z": -7,
      "name": "Plant_Grass_Sharp",
      "support": 15
    },
    {
      "x": -3,
      "y": 5,
      "z": -6,
      "name": "Rock_Marble"
    },
    {
      "x": -3,
      "y": 6,
      "z": -6,
      "name": "Rock_Marble"
    },
    {
      "x": -3,
      "y": 7,
      "z": -6,
      "name": "Rock_Marble"
    },
    {
      "x": -3,
      "y": 8,
      "z": -6,
      "name": "Rock_Marble"
    },
    {
      "x": -3,
      "y": 9,
      "z": -6,
      "name": "Rock_Marble"
    },
    {
      "x": -3,
      "y": 10,
      "z": -6,
      "name": "Soil_Dirt"
    },
    {
      "x": -3,
      "y": 11,
      "z": -6,
      "name": "Soil_Dirt"
    },
    {
      "x": -3,
      "y": 12,
      "z": -6,
      "name": "Soil_Dirt"
    },
    {
      "x": -3,
      "y": 13,
      "z": -6,
      "name": "Soil_Dirt"
    },
    {
      "x": -3,
      "y": 14,
      "z": -6,
      "name": "Soil_Grass_Full"
    },
    {
      "x": -3,
      "y": 5,
      "z": -5,
      "name": "Rock_Marble"
    },
    {
      "x": -3,
      "y": 6,
      "z": -5,
      "name": "Rock_Marble"
    },
    {
      "x": -3,
      "y": 7,
      "z": -5,
      "name": "Rock_Marble"
    },
    {
      "x": -3,
      "y": 8,
      "z": -5,
      "name": "Rock_Marble"
    },
    {
      "x": -3,
      "y": 9,
      "z": -5,
      "name": "Rock_Marble"
    },
    {
      "x": -3,
      "y": 10,
      "z": -5,
      "name": "Rock_Marble"
    },
    {
      "x": -3,
      "y": 11,
      "z": -5,
      "name": "Soil_Dirt"
    },
    {
      "x": -3,
      "y": 12,
      "z": -5,
      "name": "Soil_Dirt"
    },
    {
      "x": -3,
      "y": 13,
      "z": -5,
      "name": "Soil_Dirt"
    },
    {
      "x": -3,
      "y": 14,
      "z": -5,
      "name": "Soil_Dirt"
    },
    {
      "x": -3,
      "y": 15,
      "z": -5,
      "name": "Soil_Grass_Full"
    },
    {
      "x": -3,
      "y": 2,
      "z": -4,
      "name": "Rock_Marble"
    },
    {
      "x": -3,
      "y": 3,
      "z": -4,
      "name": "Rock_Marble"
    },
    {
      "x": -3,
      "y": 4,
      "z": -4,
      "name": "Rock_Marble"
    },
    {
      "x": -3,
      "y": 5,
      "z": -4,
      "name": "Rock_Marble"
    },
    {
      "x": -3,
      "y": 6,
      "z": -4,
      "name": "Rock_Marble"
    },
    {
      "x": -3,
      "y": 7,
      "z": -4,
      "name": "Rock_Marble"
    },
    {
      "x": -3,
      "y": 8,
      "z": -4,
      "name": "Rock_Marble"
    },
    {
      "x": -3,
      "y": 9,
      "z": -4,
      "name": "Rock_Marble"
    },
    {
      "x": -3,
      "y": 10,
      "z": -4,
      "name": "Rock_Marble"
    },
    {
      "x": -3,
      "y": 11,
      "z": -4,
      "name": "Soil_Dirt"
    },
    {
      "x": -3,
      "y": 12,
      "z": -4,
      "name": "Soil_Dirt"
    },
    {
      "x": -3,
      "y": 13,
      "z": -4,
      "name": "Soil_Dirt"
    },
    {
      "x": -3,
      "y": 14,
      "z": -4,
      "name": "Soil_Dirt"
    },
    {
      "x": -3,
      "y": 15,
      "z": -4,
      "name": "Soil_Grass_Full"
    },
    {
      "x": -3,
      "y": 16,
      "z": -4,
      "name": "Plant_Grass_Sharp",
      "support": 15
    },
    {
      "x": -3,
      "y": 1,
      "z": -3,
      "name": "Rock_Marble"
    },
    {
      "x": -3,
      "y": 2,
      "z": -3,
      "name": "Rock_Marble"
    },
    {
      "x": -3,
      "y": 3,
      "z": -3,
      "name": "Rock_Marble"
    },
    {
      "x": -3,
      "y": 4,
      "z": -3,
      "name": "Rock_Marble"
    },
    {
      "x": -3,
      "y": 5,
      "z": -3,
      "name": "Rock_Marble"
    },
    {
      "x": -3,
      "y": 6,
      "z": -3,
      "name": "Rock_Marble"
    },
    {
      "x": -3,
      "y": 7,
      "z": -3,
      "name": "Rock_Marble"
    },
    {
      "x": -3,
      "y": 8,
      "z": -3,
      "name": "Rock_Marble"
    },
    {
      "x": -3,
      "y": 9,
      "z": -3,
      "name": "Rock_Marble"
    },
    {
      "x": -3,
      "y": 10,
      "z": -3,
      "name": "Rock_Marble"
    },
    {
      "x": -3,
      "y": 11,
      "z": -3,
      "name": "Soil_Dirt"
    },
    {
      "x": -3,
      "y": 12,
      "z": -3,
      "name": "Soil_Dirt"
    },
    {
      "x": -3,
      "y": 13,
      "z": -3,
      "name": "Soil_Dirt"
    },
    {
      "x": -3,
      "y": 14,
      "z": -3,
      "name": "Soil_Dirt"
    },
    {
      "x": -3,
      "y": 15,
      "z": -3,
      "name": "Soil_Grass_Full"
    },
    {
      "x": -3,
      "y": 16,
      "z": -3,
      "name": "Plant_Grass_Sharp",
      "support": 15
    },
    {
      "x": -3,
      "y": 2,
      "z": -2,
      "name": "Rock_Marble"
    },
    {
      "x": -3,
      "y": 3,
      "z": -2,
      "name": "Rock_Marble"
    },
    {
      "x": -3,
      "y": 4,
      "z": -2,
      "name": "Rock_Marble"
    },
    {
      "x": -3,
      "y": 5,
      "z": -2,
      "name": "Rock_Marble"
    },
    {
      "x": -3,
      "y": 6,
      "z": -2,
      "name": "Rock_Marble"
    },
    {
      "x": -3,
      "y": 7,
      "z": -2,
      "name": "Rock_Marble"
    },
    {
      "x": -3,
      "y": 8,
      "z": -2,
      "name": "Rock_Marble"
    },
    {
      "x": -3,
      "y": 9,
      "z": -2,
      "name": "Rock_Marble"
    },
    {
      "x": -3,
      "y": 10,
      "z": -2,
      "name": "Rock_Marble"
    },
    {
      "x": -3,
      "y": 11,
      "z": -2,
      "name": "Soil_Dirt"
    },
    {
      "x": -3,
      "y": 12,
      "z": -2,
      "name": "Soil_Dirt"
    },
    {
      "x": -3,
      "y": 13,
      "z": -2,
      "name": "Soil_Dirt"
    },
    {
      "x": -3,
      "y": 14,
      "z": -2,
      "name": "Soil_Dirt"
    },
    {
      "x": -3,
      "y": 15,
      "z": -2,
      "name": "Soil_Grass_Full"
    },
    {
      "x": -3,
      "y": 16,
      "z": -2,
      "name": "Plant_Crop_Mushroom_Glowing_Blue"
    },
    {
      "x": -3,
      "y": 3,
      "z": -1,
      "name": "Rock_Marble"
    },
    {
      "x": -3,
      "y": 4,
      "z": -1,
      "name": "Rock_Marble"
    },
    {
      "x": -3,
      "y": 5,
      "z": -1,
      "name": "Rock_Marble"
    },
    {
      "x": -3,
      "y": 6,
      "z": -1,
      "name": "Rock_Marble"
    },
    {
      "x": -3,
      "y": 7,
      "z": -1,
      "name": "Rock_Marble"
    },
    {
      "x": -3,
      "y": 8,
      "z": -1,
      "name": "Rock_Marble"
    },
    {
      "x": -3,
      "y": 9,
      "z": -1,
      "name": "Rock_Marble"
    },
    {
      "x": -3,
      "y": 10,
      "z": -1,
      "name": "Rock_Marble"
    },
    {
      "x": -3,
      "y": 11,
      "z": -1,
      "name": "Soil_Dirt"
    },
    {
      "x": -3,
      "y": 12,
      "z": -1,
      "name": "Soil_Dirt"
    },
    {
      "x": -3,
      "y": 13,
      "z": -1,
      "name": "Soil_Dirt"
    },
    {
      "x": -3,
      "y": 14,
      "z": -1,
      "name": "Soil_Dirt"
    },
    {
      "x": -3,
      "y": 15,
      "z": -1,
      "name": "Soil_Grass_Full"
    },
    {
      "x": -3,
      "y": 3,
      "z": 0,
      "name": "Rock_Marble"
    },
    {
      "x": -3,
      "y": 4,
      "z": 0,
      "name": "Rock_Marble"
    },
    {
      "x": -3,
      "y": 5,
      "z": 0,
      "name": "Rock_Marble"
    },
    {
      "x": -3,
      "y": 6,
      "z": 0,
      "name": "Rock_Marble"
    },
    {
      "x": -3,
      "y": 7,
      "z": 0,
      "name": "Rock_Marble"
    },
    {
      "x": -3,
      "y": 8,
      "z": 0,
      "name": "Rock_Marble"
    },
    {
      "x": -3,
      "y": 9,
      "z": 0,
      "name": "Rock_Marble"
    },
    {
      "x": -3,
      "y": 10,
      "z": 0,
      "name": "Rock_Marble"
    },
    {
      "x": -3,
      "y": 11,
      "z": 0,
      "name": "Soil_Dirt"
    },
    {
      "x": -3,
      "y": 12,
      "z": 0,
      "name": "Soil_Dirt"
    },
    {
      "x": -3,
      "y": 13,
      "z": 0,
      "name": "Soil_Dirt"
    },
    {
      "x": -3,
      "y": 14,
      "z": 0,
      "name": "Soil_Dirt"
    },
    {
      "x": -3,
      "y": 15,
      "z": 0,
      "name": "Soil_Grass_Full"
    },
    {
      "x": -3,
      "y": 3,
      "z": 1,
      "name": "Rock_Marble"
    },
    {
      "x": -3,
      "y": 4,
      "z": 1,
      "name": "Rock_Marble"
    },
    {
      "x": -3,
      "y": 5,
      "z": 1,
      "name": "Rock_Marble"
    },
    {
      "x": -3,
      "y": 6,
      "z": 1,
      "name": "Rock_Marble"
    },
    {
      "x": -3,
      "y": 7,
      "z": 1,
      "name": "Rock_Marble"
    },
    {
      "x": -3,
      "y": 8,
      "z": 1,
      "name": "Rock_Marble"
    },
    {
      "x": -3,
      "y": 9,
      "z": 1,
      "name": "Rock_Marble"
    },
    {
      "x": -3,
      "y": 10,
      "z": 1,
      "name": "Rock_Marble"
    },
    {
      "x": -3,
      "y": 11,
      "z": 1,
      "name": "Soil_Dirt"
    },
    {
      "x": -3,
      "y": 12,
      "z": 1,
      "name": "Soil_Dirt"
    },
    {
      "x": -3,
      "y": 13,
      "z": 1,
      "name": "Soil_Dirt"
    },
    {
      "x": -3,
      "y": 14,
      "z": 1,
      "name": "Soil_Dirt"
    },
    {
      "x": -3,
      "y": 15,
      "z": 1,
      "name": "Soil_Grass"
    },
    {
      "x": -3,
      "y": 4,
      "z": 2,
      "name": "Rock_Marble"
    },
    {
      "x": -3,
      "y": 5,
      "z": 2,
      "name": "Rock_Marble"
    },
    {
      "x": -3,
      "y": 6,
      "z": 2,
      "name": "Rock_Marble"
    },
    {
      "x": -3,
      "y": 7,
      "z": 2,
      "name": "Rock_Marble"
    },
    {
      "x": -3,
      "y": 8,
      "z": 2,
      "name": "Rock_Marble"
    },
    {
      "x": -3,
      "y": 9,
      "z": 2,
      "name": "Rock_Marble"
    },
    {
      "x": -3,
      "y": 10,
      "z": 2,
      "name": "Rock_Marble"
    },
    {
      "x": -3,
      "y": 11,
      "z": 2,
      "name": "Soil_Dirt"
    },
    {
      "x": -3,
      "y": 12,
      "z": 2,
      "name": "Soil_Dirt"
    },
    {
      "x": -3,
      "y": 13,
      "z": 2,
      "name": "Soil_Dirt"
    },
    {
      "x": -3,
      "y": 14,
      "z": 2,
      "name": "Soil_Dirt"
    },
    {
      "x": -3,
      "y": 15,
      "z": 2,
      "name": "Soil_Grass"
    },
    {
      "x": -3,
      "y": 4,
      "z": 3,
      "name": "Rock_Marble"
    },
    {
      "x": -3,
      "y": 5,
      "z": 3,
      "name": "Rock_Marble"
    },
    {
      "x": -3,
      "y": 6,
      "z": 3,
      "name": "Rock_Marble"
    },
    {
      "x": -3,
      "y": 7,
      "z": 3,
      "name": "Rock_Marble"
    },
    {
      "x": -3,
      "y": 8,
      "z": 3,
      "name": "Rock_Marble"
    },
    {
      "x": -3,
      "y": 9,
      "z": 3,
      "name": "Rock_Marble"
    },
    {
      "x": -3,
      "y": 10,
      "z": 3,
      "name": "Rock_Marble"
    },
    {
      "x": -3,
      "y": 11,
      "z": 3,
      "name": "Soil_Dirt"
    },
    {
      "x": -3,
      "y": 12,
      "z": 3,
      "name": "Soil_Dirt"
    },
    {
      "x": -3,
      "y": 13,
      "z": 3,
      "name": "Soil_Dirt"
    },
    {
      "x": -3,
      "y": 14,
      "z": 3,
      "name": "Soil_Dirt"
    },
    {
      "x": -3,
      "y": 15,
      "z": 3,
      "name": "Soil_Grass"
    },
    {
      "x": -3,
      "y": 4,
      "z": 4,
      "name": "Rock_Marble"
    },
    {
      "x": -3,
      "y": 5,
      "z": 4,
      "name": "Rock_Marble"
    },
    {
      "x": -3,
      "y": 6,
      "z": 4,
      "name": "Rock_Marble"
    },
    {
      "x": -3,
      "y": 7,
      "z": 4,
      "name": "Rock_Marble"
    },
    {
      "x": -3,
      "y": 8,
      "z": 4,
      "name": "Rock_Marble"
    },
    {
      "x": -3,
      "y": 9,
      "z": 4,
      "name": "Rock_Marble"
    },
    {
      "x": -3,
      "y": 10,
      "z": 4,
      "name": "Rock_Marble"
    },
    {
      "x": -3,
      "y": 11,
      "z": 4,
      "name": "Soil_Dirt"
    },
    {
      "x": -3,
      "y": 12,
      "z": 4,
      "name": "Soil_Dirt"
    },
    {
      "x": -3,
      "y": 13,
      "z": 4,
      "name": "Soil_Dirt"
    },
    {
      "x": -3,
      "y": 14,
      "z": 4,
      "name": "Soil_Dirt"
    },
    {
      "x": -3,
      "y": 15,
      "z": 4,
      "name": "Soil_Grass_Full"
    },
    {
      "x": -3,
      "y": 6,
      "z": 5,
      "name": "Rock_Marble"
    },
    {
      "x": -3,
      "y": 7,
      "z": 5,
      "name": "Rock_Marble"
    },
    {
      "x": -3,
      "y": 8,
      "z": 5,
      "name": "Rock_Marble"
    },
    {
      "x": -3,
      "y": 9,
      "z": 5,
      "name": "Rock_Marble"
    },
    {
      "x": -3,
      "y": 10,
      "z": 5,
      "name": "Soil_Dirt"
    },
    {
      "x": -3,
      "y": 11,
      "z": 5,
      "name": "Soil_Dirt"
    },
    {
      "x": -3,
      "y": 12,
      "z": 5,
      "name": "Soil_Dirt"
    },
    {
      "x": -3,
      "y": 13,
      "z": 5,
      "name": "Soil_Dirt"
    },
    {
      "x": -3,
      "y": 14,
      "z": 5,
      "name": "Soil_Grass_Full"
    },
    {
      "x": -3,
      "y": 15,
      "z": 5,
      "name": "Plant_Grass_Sharp",
      "support": 15
    },
    {
      "x": -3,
      "y": 7,
      "z": 6,
      "name": "Rock_Marble"
    },
    {
      "x": -3,
      "y": 8,
      "z": 6,
      "name": "Rock_Marble"
    },
    {
      "x": -3,
      "y": 9,
      "z": 6,
      "name": "Rock_Marble"
    },
    {
      "x": -3,
      "y": 10,
      "z": 6,
      "name": "Soil_Dirt"
    },
    {
      "x": -3,
      "y": 11,
      "z": 6,
      "name": "Soil_Dirt"
    },
    {
      "x": -3,
      "y": 12,
      "z": 6,
      "name": "Soil_Dirt"
    },
    {
      "x": -3,
      "y": 13,
      "z": 6,
      "name": "Soil_Dirt"
    },
    {
      "x": -3,
      "y": 14,
      "z": 6,
      "name": "Soil_Grass_Full"
    },
    {
      "x": -3,
      "y": 7,
      "z": 7,
      "name": "Rock_Marble"
    },
    {
      "x": -3,
      "y": 8,
      "z": 7,
      "name": "Rock_Marble"
    },
    {
      "x": -3,
      "y": 9,
      "z": 7,
      "name": "Soil_Dirt"
    },
    {
      "x": -3,
      "y": 10,
      "z": 7,
      "name": "Soil_Dirt"
    },
    {
      "x": -3,
      "y": 11,
      "z": 7,
      "name": "Soil_Dirt"
    },
    {
      "x": -3,
      "y": 12,
      "z": 7,
      "name": "Soil_Dirt"
    },
    {
      "x": -3,
      "y": 13,
      "z": 7,
      "name": "Soil_Grass_Full"
    },
    {
      "x": -3,
      "y": 8,
      "z": 8,
      "name": "Soil_Dirt"
    },
    {
      "x": -3,
      "y": 9,
      "z": 8,
      "name": "Soil_Dirt"
    },
    {
      "x": -3,
      "y": 10,
      "z": 8,
      "name": "Soil_Dirt"
    },
    {
      "x": -3,
      "y": 11,
      "z": 8,
      "name": "Soil_Dirt"
    },
    {
      "x": -3,
      "y": 12,
      "z": 8,
      "name": "Soil_Grass_Full"
    },
    {
      "x": -3,
      "y": 13,
      "z": 8,
      "name": "Plant_Grass_Sharp",
      "support": 15
    },
    {
      "x": -3,
      "y": 9,
      "z": 9,
      "name": "Soil_Dirt"
    },
    {
      "x": -3,
      "y": 10,
      "z": 9,
      "name": "Soil_Dirt"
    },
    {
      "x": -3,
      "y": 11,
      "z": 9,
      "name": "Soil_Grass_Full"
    },
    {
      "x": -3,
      "y": 12,
      "z": 9,
      "name": "Plant_Crop_Mushroom_Glowing_Blue"
    },
    {
      "x": -2,
      "y": 8,
      "z": -9,
      "name": "Soil_Dirt"
    },
    {
      "x": -2,
      "y": 9,
      "z": -9,
      "name": "Soil_Dirt"
    },
    {
      "x": -2,
      "y": 10,
      "z": -9,
      "name": "Soil_Dirt"
    },
    {
      "x": -2,
      "y": 11,
      "z": -9,
      "name": "Soil_Dirt"
    },
    {
      "x": -2,
      "y": 12,
      "z": -9,
      "name": "Soil_Grass_Full"
    },
    {
      "x": -2,
      "y": 7,
      "z": -8,
      "name": "Rock_Marble"
    },
    {
      "x": -2,
      "y": 8,
      "z": -8,
      "name": "Rock_Marble"
    },
    {
      "x": -2,
      "y": 9,
      "z": -8,
      "name": "Rock_Marble"
    },
    {
      "x": -2,
      "y": 10,
      "z": -8,
      "name": "Soil_Dirt"
    },
    {
      "x": -2,
      "y": 11,
      "z": -8,
      "name": "Soil_Dirt"
    },
    {
      "x": -2,
      "y": 12,
      "z": -8,
      "name": "Soil_Dirt"
    },
    {
      "x": -2,
      "y": 13,
      "z": -8,
      "name": "Soil_Dirt"
    },
    {
      "x": -2,
      "y": 14,
      "z": -8,
      "name": "Soil_Grass_Full"
    },
    {
      "x": -2,
      "y": 7,
      "z": -7,
      "name": "Rock_Marble"
    },
    {
      "x": -2,
      "y": 8,
      "z": -7,
      "name": "Rock_Marble"
    },
    {
      "x": -2,
      "y": 9,
      "z": -7,
      "name": "Rock_Marble"
    },
    {
      "x": -2,
      "y": 10,
      "z": -7,
      "name": "Rock_Marble"
    },
    {
      "x": -2,
      "y": 11,
      "z": -7,
      "name": "Soil_Dirt"
    },
    {
      "x": -2,
      "y": 12,
      "z": -7,
      "name": "Soil_Dirt"
    },
    {
      "x": -2,
      "y": 13,
      "z": -7,
      "name": "Soil_Dirt"
    },
    {
      "x": -2,
      "y": 14,
      "z": -7,
      "name": "Soil_Dirt"
    },
    {
      "x": -2,
      "y": 15,
      "z": -7,
      "name": "Soil_Grass_Full"
    },
    {
      "x": -2,
      "y": 5,
      "z": -6,
      "name": "Rock_Marble"
    },
    {
      "x": -2,
      "y": 6,
      "z": -6,
      "name": "Rock_Marble"
    },
    {
      "x": -2,
      "y": 7,
      "z": -6,
      "name": "Rock_Marble"
    },
    {
      "x": -2,
      "y": 8,
      "z": -6,
      "name": "Rock_Marble"
    },
    {
      "x": -2,
      "y": 9,
      "z": -6,
      "name": "Rock_Marble"
    },
    {
      "x": -2,
      "y": 10,
      "z": -6,
      "name": "Rock_Marble"
    },
    {
      "x": -2,
      "y": 11,
      "z": -6,
      "name": "Soil_Dirt"
    },
    {
      "x": -2,
      "y": 12,
      "z": -6,
      "name": "Soil_Dirt"
    },
    {
      "x": -2,
      "y": 13,
      "z": -6,
      "name": "Soil_Dirt"
    },
    {
      "x": -2,
      "y": 14,
      "z": -6,
      "name": "Soil_Dirt"
    },
    {
      "x": -2,
      "y": 15,
      "z": -6,
      "name": "Soil_Grass_Full"
    },
    {
      "x": -2,
      "y": 4,
      "z": -5,
      "name": "Rock_Marble"
    },
    {
      "x": -2,
      "y": 5,
      "z": -5,
      "name": "Rock_Marble"
    },
    {
      "x": -2,
      "y": 6,
      "z": -5,
      "name": "Rock_Marble"
    },
    {
      "x": -2,
      "y": 7,
      "z": -5,
      "name": "Rock_Marble"
    },
    {
      "x": -2,
      "y": 8,
      "z": -5,
      "name": "Rock_Marble"
    },
    {
      "x": -2,
      "y": 9,
      "z": -5,
      "name": "Rock_Marble"
    },
    {
      "x": -2,
      "y": 10,
      "z": -5,
      "name": "Rock_Marble"
    },
    {
      "x": -2,
      "y": 11,
      "z": -5,
      "name": "Soil_Dirt"
    },
    {
      "x": -2,
      "y": 12,
      "z": -5,
      "name": "Soil_Dirt"
    },
    {
      "x": -2,
      "y": 13,
      "z": -5,
      "name": "Soil_Dirt"
    },
    {
      "x": -2,
      "y": 14,
      "z": -5,
      "name": "Soil_Dirt"
    },
    {
      "x": -2,
      "y": 15,
      "z": -5,
      "name": "Soil_Grass_Full"
    },
    {
      "x": -2,
      "y": 2,
      "z": -4,
      "name": "Rock_Marble"
    },
    {
      "x": -2,
      "y": 3,
      "z": -4,
      "name": "Rock_Marble"
    },
    {
      "x": -2,
      "y": 4,
      "z": -4,
      "name": "Rock_Marble"
    },
    {
      "x": -2,
      "y": 5,
      "z": -4,
      "name": "Rock_Marble"
    },
    {
      "x": -2,
      "y": 6,
      "z": -4,
      "name": "Rock_Marble"
    },
    {
      "x": -2,
      "y": 7,
      "z": -4,
      "name": "Rock_Marble"
    },
    {
      "x": -2,
      "y": 8,
      "z": -4,
      "name": "Rock_Marble"
    },
    {
      "x": -2,
      "y": 9,
      "z": -4,
      "name": "Rock_Marble"
    },
    {
      "x": -2,
      "y": 10,
      "z": -4,
      "name": "Rock_Marble"
    },
    {
      "x": -2,
      "y": 11,
      "z": -4,
      "name": "Soil_Dirt"
    },
    {
      "x": -2,
      "y": 12,
      "z": -4,
      "name": "Soil_Dirt"
    },
    {
      "x": -2,
      "y": 13,
      "z": -4,
      "name": "Soil_Dirt"
    },
    {
      "x": -2,
      "y": 14,
      "z": -4,
      "name": "Soil_Dirt"
    },
    {
      "x": -2,
      "y": 15,
      "z": -4,
      "name": "Soil_Grass_Full"
    },
    {
      "x": -2,
      "y": 1,
      "z": -3,
      "name": "Rock_Marble"
    },
    {
      "x": -2,
      "y": 2,
      "z": -3,
      "name": "Rock_Marble"
    },
    {
      "x": -2,
      "y": 3,
      "z": -3,
      "name": "Rock_Marble"
    },
    {
      "x": -2,
      "y": 4,
      "z": -3,
      "name": "Rock_Marble"
    },
    {
      "x": -2,
      "y": 5,
      "z": -3,
      "name": "Rock_Marble"
    },
    {
      "x": -2,
      "y": 6,
      "z": -3,
      "name": "Rock_Marble"
    },
    {
      "x": -2,
      "y": 7,
      "z": -3,
      "name": "Rock_Marble"
    },
    {
      "x": -2,
      "y": 8,
      "z": -3,
      "name": "Rock_Marble"
    },
    {
      "x": -2,
      "y": 9,
      "z": -3,
      "name": "Rock_Marble"
    },
    {
      "x": -2,
      "y": 10,
      "z": -3,
      "name": "Rock_Marble"
    },
    {
      "x": -2,
      "y": 11,
      "z": -3,
      "name": "Soil_Dirt"
    },
    {
      "x": -2,
      "y": 12,
      "z": -3,
      "name": "Soil_Dirt"
    },
    {
      "x": -2,
      "y": 13,
      "z": -3,
      "name": "Soil_Dirt"
    },
    {
      "x": -2,
      "y": 14,
      "z": -3,
      "name": "Soil_Dirt"
    },
    {
      "x": -2,
      "y": 15,
      "z": -3,
      "name": "Soil_Grass_Full"
    },
    {
      "x": -2,
      "y": 1,
      "z": -2,
      "name": "Rock_Marble"
    },
    {
      "x": -2,
      "y": 2,
      "z": -2,
      "name": "Rock_Marble"
    },
    {
      "x": -2,
      "y": 3,
      "z": -2,
      "name": "Rock_Marble"
    },
    {
      "x": -2,
      "y": 4,
      "z": -2,
      "name": "Rock_Marble"
    },
    {
      "x": -2,
      "y": 5,
      "z": -2,
      "name": "Rock_Marble"
    },
    {
      "x": -2,
      "y": 6,
      "z": -2,
      "name": "Rock_Marble"
    },
    {
      "x": -2,
      "y": 7,
      "z": -2,
      "name": "Rock_Marble"
    },
    {
      "x": -2,
      "y": 8,
      "z": -2,
      "name": "Rock_Marble"
    },
    {
      "x": -2,
      "y": 9,
      "z": -2,
      "name": "Rock_Marble"
    },
    {
      "x": -2,
      "y": 10,
      "z": -2,
      "name": "Rock_Marble"
    },
    {
      "x": -2,
      "y": 11,
      "z": -2,
      "name": "Soil_Dirt"
    },
    {
      "x": -2,
      "y": 12,
      "z": -2,
      "name": "Soil_Dirt"
    },
    {
      "x": -2,
      "y": 13,
      "z": -2,
      "name": "Soil_Dirt"
    },
    {
      "x": -2,
      "y": 14,
      "z": -2,
      "name": "Soil_Dirt"
    },
    {
      "x": -2,
      "y": 15,
      "z": -2,
      "name": "Soil_Grass_Full"
    },
    {
      "x": -2,
      "y": 2,
      "z": -1,
      "name": "Rock_Marble"
    },
    {
      "x": -2,
      "y": 3,
      "z": -1,
      "name": "Rock_Marble"
    },
    {
      "x": -2,
      "y": 4,
      "z": -1,
      "name": "Rock_Marble"
    },
    {
      "x": -2,
      "y": 5,
      "z": -1,
      "name": "Rock_Marble"
    },
    {
      "x": -2,
      "y": 6,
      "z": -1,
      "name": "Rock_Marble"
    },
    {
      "x": -2,
      "y": 7,
      "z": -1,
      "name": "Rock_Marble"
    },
    {
      "x": -2,
      "y": 8,
      "z": -1,
      "name": "Rock_Marble"
    },
    {
      "x": -2,
      "y": 9,
      "z": -1,
      "name": "Rock_Marble"
    },
    {
      "x": -2,
      "y": 10,
      "z": -1,
      "name": "Rock_Marble"
    },
    {
      "x": -2,
      "y": 11,
      "z": -1,
      "name": "Soil_Dirt"
    },
    {
      "x": -2,
      "y": 12,
      "z": -1,
      "name": "Soil_Dirt"
    },
    {
      "x": -2,
      "y": 13,
      "z": -1,
      "name": "Soil_Dirt"
    },
    {
      "x": -2,
      "y": 14,
      "z": -1,
      "name": "Soil_Dirt"
    },
    {
      "x": -2,
      "y": 15,
      "z": -1,
      "name": "Soil_Grass_Full"
    },
    {
      "x": -2,
      "y": 16,
      "z": -1,
      "name": "Plant_Grass_Sharp",
      "support": 15
    },
    {
      "x": -2,
      "y": 2,
      "z": 0,
      "name": "Rock_Marble"
    },
    {
      "x": -2,
      "y": 3,
      "z": 0,
      "name": "Rock_Marble"
    },
    {
      "x": -2,
      "y": 4,
      "z": 0,
      "name": "Rock_Marble"
    },
    {
      "x": -2,
      "y": 5,
      "z": 0,
      "name": "Rock_Marble"
    },
    {
      "x": -2,
      "y": 6,
      "z": 0,
      "name": "Rock_Marble"
    },
    {
      "x": -2,
      "y": 7,
      "z": 0,
      "name": "Rock_Marble"
    },
    {
      "x": -2,
      "y": 8,
      "z": 0,
      "name": "Rock_Marble"
    },
    {
      "x": -2,
      "y": 9,
      "z": 0,
      "name": "Rock_Marble"
    },
    {
      "x": -2,
      "y": 10,
      "z": 0,
      "name": "Rock_Marble"
    },
    {
      "x": -2,
      "y": 11,
      "z": 0,
      "name": "Soil_Dirt"
    },
    {
      "x": -2,
      "y": 12,
      "z": 0,
      "name": "Soil_Dirt"
    },
    {
      "x": -2,
      "y": 13,
      "z": 0,
      "name": "Soil_Dirt"
    },
    {
      "x": -2,
      "y": 14,
      "z": 0,
      "name": "Soil_Dirt"
    },
    {
      "x": -2,
      "y": 15,
      "z": 0,
      "name": "Soil_Grass_Full"
    },
    {
      "x": -2,
      "y": 16,
      "z": 0,
      "name": "Plant_Grass_Sharp",
      "support": 15
    },
    {
      "x": -2,
      "y": 2,
      "z": 1,
      "name": "Rock_Marble"
    },
    {
      "x": -2,
      "y": 3,
      "z": 1,
      "name": "Rock_Marble"
    },
    {
      "x": -2,
      "y": 4,
      "z": 1,
      "name": "Rock_Marble"
    },
    {
      "x": -2,
      "y": 5,
      "z": 1,
      "name": "Rock_Marble"
    },
    {
      "x": -2,
      "y": 6,
      "z": 1,
      "name": "Rock_Marble"
    },
    {
      "x": -2,
      "y": 7,
      "z": 1,
      "name": "Rock_Marble"
    },
    {
      "x": -2,
      "y": 8,
      "z": 1,
      "name": "Rock_Marble"
    },
    {
      "x": -2,
      "y": 9,
      "z": 1,
      "name": "Rock_Marble"
    },
    {
      "x": -2,
      "y": 10,
      "z": 1,
      "name": "Rock_Marble"
    },
    {
      "x": -2,
      "y": 11,
      "z": 1,
      "name": "Soil_Dirt"
    },
    {
      "x": -2,
      "y": 12,
      "z": 1,
      "name": "Soil_Dirt"
    },
    {
      "x": -2,
      "y": 13,
      "z": 1,
      "name": "Soil_Dirt"
    },
    {
      "x": -2,
      "y": 14,
      "z": 1,
      "name": "Soil_Dirt"
    },
    {
      "x": -2,
      "y": 15,
      "z": 1,
      "name": "Soil_Grass_Full"
    },
    {
      "x": -2,
      "y": 3,
      "z": 2,
      "name": "Rock_Marble"
    },
    {
      "x": -2,
      "y": 4,
      "z": 2,
      "name": "Rock_Marble"
    },
    {
      "x": -2,
      "y": 5,
      "z": 2,
      "name": "Rock_Marble"
    },
    {
      "x": -2,
      "y": 6,
      "z": 2,
      "name": "Rock_Marble"
    },
    {
      "x": -2,
      "y": 7,
      "z": 2,
      "name": "Rock_Marble"
    },
    {
      "x": -2,
      "y": 8,
      "z": 2,
      "name": "Rock_Marble"
    },
    {
      "x": -2,
      "y": 9,
      "z": 2,
      "name": "Rock_Marble"
    },
    {
      "x": -2,
      "y": 10,
      "z": 2,
      "name": "Rock_Marble"
    },
    {
      "x": -2,
      "y": 11,
      "z": 2,
      "name": "Soil_Dirt"
    },
    {
      "x": -2,
      "y": 12,
      "z": 2,
      "name": "Soil_Dirt"
    },
    {
      "x": -2,
      "y": 13,
      "z": 2,
      "name": "Soil_Dirt"
    },
    {
      "x": -2,
      "y": 14,
      "z": 2,
      "name": "Soil_Dirt"
    },
    {
      "x": -2,
      "y": 15,
      "z": 2,
      "name": "Soil_Grass_Full"
    },
    {
      "x": -2,
      "y": 16,
      "z": 2,
      "name": "Plant_Crop_Mushroom_Glowing_Blue"
    },
    {
      "x": -2,
      "y": 4,
      "z": 3,
      "name": "Rock_Marble"
    },
    {
      "x": -2,
      "y": 5,
      "z": 3,
      "name": "Rock_Marble"
    },
    {
      "x": -2,
      "y": 6,
      "z": 3,
      "name": "Rock_Marble"
    },
    {
      "x": -2,
      "y": 7,
      "z": 3,
      "name": "Rock_Marble"
    },
    {
      "x": -2,
      "y": 8,
      "z": 3,
      "name": "Rock_Marble"
    },
    {
      "x": -2,
      "y": 9,
      "z": 3,
      "name": "Rock_Marble"
    },
    {
      "x": -2,
      "y": 10,
      "z": 3,
      "name": "Rock_Marble"
    },
    {
      "x": -2,
      "y": 11,
      "z": 3,
      "name": "Soil_Dirt"
    },
    {
      "x": -2,
      "y": 12,
      "z": 3,
      "name": "Soil_Dirt"
    },
    {
      "x": -2,
      "y": 13,
      "z": 3,
      "name": "Soil_Dirt"
    },
    {
      "x": -2,
      "y": 14,
      "z": 3,
      "name": "Soil_Dirt"
    },
    {
      "x": -2,
      "y": 15,
      "z": 3,
      "name": "Soil_Grass"
    },
    {
      "x": -2,
      "y": 4,
      "z": 4,
      "name": "Rock_Marble"
    },
    {
      "x": -2,
      "y": 5,
      "z": 4,
      "name": "Rock_Marble"
    },
    {
      "x": -2,
      "y": 6,
      "z": 4,
      "name": "Rock_Marble"
    },
    {
      "x": -2,
      "y": 7,
      "z": 4,
      "name": "Rock_Marble"
    },
    {
      "x": -2,
      "y": 8,
      "z": 4,
      "name": "Rock_Marble"
    },
    {
      "x": -2,
      "y": 9,
      "z": 4,
      "name": "Rock_Marble"
    },
    {
      "x": -2,
      "y": 10,
      "z": 4,
      "name": "Rock_Marble"
    },
    {
      "x": -2,
      "y": 11,
      "z": 4,
      "name": "Soil_Dirt"
    },
    {
      "x": -2,
      "y": 12,
      "z": 4,
      "name": "Soil_Dirt"
    },
    {
      "x": -2,
      "y": 13,
      "z": 4,
      "name": "Soil_Dirt"
    },
    {
      "x": -2,
      "y": 14,
      "z": 4,
      "name": "Soil_Dirt"
    },
    {
      "x": -2,
      "y": 15,
      "z": 4,
      "name": "Soil_Grass_Full"
    },
    {
      "x": -2,
      "y": 6,
      "z": 5,
      "name": "Rock_Marble"
    },
    {
      "x": -2,
      "y": 7,
      "z": 5,
      "name": "Rock_Marble"
    },
    {
      "x": -2,
      "y": 8,
      "z": 5,
      "name": "Rock_Marble"
    },
    {
      "x": -2,
      "y": 9,
      "z": 5,
      "name": "Rock_Marble"
    },
    {
      "x": -2,
      "y": 10,
      "z": 5,
      "name": "Soil_Dirt"
    },
    {
      "x": -2,
      "y": 11,
      "z": 5,
      "name": "Soil_Dirt"
    },
    {
      "x": -2,
      "y": 12,
      "z": 5,
      "name": "Soil_Dirt"
    },
    {
      "x": -2,
      "y": 13,
      "z": 5,
      "name": "Soil_Dirt"
    },
    {
      "x": -2,
      "y": 14,
      "z": 5,
      "name": "Soil_Grass_Full"
    },
    {
      "x": -2,
      "y": 6,
      "z": 6,
      "name": "Rock_Marble"
    },
    {
      "x": -2,
      "y": 7,
      "z": 6,
      "name": "Rock_Marble"
    },
    {
      "x": -2,
      "y": 8,
      "z": 6,
      "name": "Rock_Marble"
    },
    {
      "x": -2,
      "y": 9,
      "z": 6,
      "name": "Rock_Marble"
    },
    {
      "x": -2,
      "y": 10,
      "z": 6,
      "name": "Soil_Dirt"
    },
    {
      "x": -2,
      "y": 11,
      "z": 6,
      "name": "Soil_Dirt"
    },
    {
      "x": -2,
      "y": 12,
      "z": 6,
      "name": "Soil_Dirt"
    },
    {
      "x": -2,
      "y": 13,
      "z": 6,
      "name": "Soil_Dirt"
    },
    {
      "x": -2,
      "y": 14,
      "z": 6,
      "name": "Soil_Grass_Full"
    },
    {
      "x": -2,
      "y": 7,
      "z": 7,
      "name": "Rock_Marble"
    },
    {
      "x": -2,
      "y": 8,
      "z": 7,
      "name": "Rock_Marble"
    },
    {
      "x": -2,
      "y": 9,
      "z": 7,
      "name": "Soil_Dirt"
    },
    {
      "x": -2,
      "y": 10,
      "z": 7,
      "name": "Soil_Dirt"
    },
    {
      "x": -2,
      "y": 11,
      "z": 7,
      "name": "Soil_Dirt"
    },
    {
      "x": -2,
      "y": 12,
      "z": 7,
      "name": "Soil_Dirt"
    },
    {
      "x": -2,
      "y": 13,
      "z": 7,
      "name": "Soil_Grass_Full"
    },
    {
      "x": -2,
      "y": 9,
      "z": 8,
      "name": "Soil_Dirt"
    },
    {
      "x": -2,
      "y": 10,
      "z": 8,
      "name": "Soil_Dirt"
    },
    {
      "x": -2,
      "y": 11,
      "z": 8,
      "name": "Soil_Dirt"
    },
    {
      "x": -2,
      "y": 12,
      "z": 8,
      "name": "Soil_Dirt"
    },
    {
      "x": -2,
      "y": 13,
      "z": 8,
      "name": "Soil_Grass_Full"
    },
    {
      "x": -2,
      "y": 9,
      "z": 9,
      "name": "Soil_Dirt"
    },
    {
      "x": -2,
      "y": 10,
      "z": 9,
      "name": "Soil_Dirt"
    },
    {
      "x": -2,
      "y": 11,
      "z": 9,
      "name": "Soil_Grass_Full"
    },
    {
      "x": -1,
      "y": 8,
      "z": -9,
      "name": "Rock_Marble"
    },
    {
      "x": -1,
      "y": 9,
      "z": -9,
      "name": "Soil_Dirt"
    },
    {
      "x": -1,
      "y": 10,
      "z": -9,
      "name": "Soil_Dirt"
    },
    {
      "x": -1,
      "y": 11,
      "z": -9,
      "name": "Soil_Dirt"
    },
    {
      "x": -1,
      "y": 12,
      "z": -9,
      "name": "Soil_Dirt"
    },
    {
      "x": -1,
      "y": 13,
      "z": -9,
      "name": "Soil_Grass_Full"
    },
    {
      "x": -1,
      "y": 14,
      "z": -9,
      "name": "Plant_Grass_Sharp",
      "support": 15
    },
    {
      "x": -1,
      "y": 7,
      "z": -8,
      "name": "Rock_Marble"
    },
    {
      "x": -1,
      "y": 8,
      "z": -8,
      "name": "Rock_Marble"
    },
    {
      "x": -1,
      "y": 9,
      "z": -8,
      "name": "Rock_Marble"
    },
    {
      "x": -1,
      "y": 10,
      "z": -8,
      "name": "Soil_Dirt"
    },
    {
      "x": -1,
      "y": 11,
      "z": -8,
      "name": "Soil_Dirt"
    },
    {
      "x": -1,
      "y": 12,
      "z": -8,
      "name": "Soil_Dirt"
    },
    {
      "x": -1,
      "y": 13,
      "z": -8,
      "name": "Soil_Dirt"
    },
    {
      "x": -1,
      "y": 14,
      "z": -8,
      "name": "Soil_Grass_Full"
    },
    {
      "x": -1,
      "y": 7,
      "z": -7,
      "name": "Rock_Marble"
    },
    {
      "x": -1,
      "y": 8,
      "z": -7,
      "name": "Rock_Marble"
    },
    {
      "x": -1,
      "y": 9,
      "z": -7,
      "name": "Rock_Marble"
    },
    {
      "x": -1,
      "y": 10,
      "z": -7,
      "name": "Rock_Marble"
    },
    {
      "x": -1,
      "y": 11,
      "z": -7,
      "name": "Soil_Dirt"
    },
    {
      "x": -1,
      "y": 12,
      "z": -7,
      "name": "Soil_Dirt"
    },
    {
      "x": -1,
      "y": 13,
      "z": -7,
      "name": "Soil_Dirt"
    },
    {
      "x": -1,
      "y": 14,
      "z": -7,
      "name": "Soil_Dirt"
    },
    {
      "x": -1,
      "y": 15,
      "z": -7,
      "name": "Soil_Grass_Full"
    },
    {
      "x": -1,
      "y": 4,
      "z": -6,
      "name": "Rock_Marble"
    },
    {
      "x": -1,
      "y": 5,
      "z": -6,
      "name": "Rock_Marble"
    },
    {
      "x": -1,
      "y": 6,
      "z": -6,
      "name": "Rock_Marble"
    },
    {
      "x": -1,
      "y": 7,
      "z": -6,
      "name": "Rock_Marble"
    },
    {
      "x": -1,
      "y": 8,
      "z": -6,
      "name": "Rock_Marble"
    },
    {
      "x": -1,
      "y": 9,
      "z": -6,
      "name": "Rock_Marble"
    },
    {
      "x": -1,
      "y": 10,
      "z": -6,
      "name": "Rock_Marble"
    },
    {
      "x": -1,
      "y": 11,
      "z": -6,
      "name": "Soil_Dirt"
    },
    {
      "x": -1,
      "y": 12,
      "z": -6,
      "name": "Soil_Dirt"
    },
    {
      "x": -1,
      "y": 13,
      "z": -6,
      "name": "Soil_Dirt"
    },
    {
      "x": -1,
      "y": 14,
      "z": -6,
      "name": "Soil_Dirt"
    },
    {
      "x": -1,
      "y": 15,
      "z": -6,
      "name": "Soil_Grass_Full"
    },
    {
      "x": -1,
      "y": 3,
      "z": -5,
      "name": "Rock_Marble"
    },
    {
      "x": -1,
      "y": 4,
      "z": -5,
      "name": "Rock_Marble"
    },
    {
      "x": -1,
      "y": 5,
      "z": -5,
      "name": "Rock_Marble"
    },
    {
      "x": -1,
      "y": 6,
      "z": -5,
      "name": "Rock_Marble"
    },
    {
      "x": -1,
      "y": 7,
      "z": -5,
      "name": "Rock_Marble"
    },
    {
      "x": -1,
      "y": 8,
      "z": -5,
      "name": "Rock_Marble"
    },
    {
      "x": -1,
      "y": 9,
      "z": -5,
      "name": "Rock_Marble"
    },
    {
      "x": -1,
      "y": 10,
      "z": -5,
      "name": "Rock_Marble"
    },
    {
      "x": -1,
      "y": 11,
      "z": -5,
      "name": "Soil_Dirt"
    },
    {
      "x": -1,
      "y": 12,
      "z": -5,
      "name": "Soil_Dirt"
    },
    {
      "x": -1,
      "y": 13,
      "z": -5,
      "name": "Soil_Dirt"
    },
    {
      "x": -1,
      "y": 14,
      "z": -5,
      "name": "Soil_Dirt"
    },
    {
      "x": -1,
      "y": 15,
      "z": -5,
      "name": "Soil_Grass_Full"
    },
    {
      "x": -1,
      "y": 16,
      "z": -5,
      "name": "Plant_Grass_Sharp",
      "support": 15
    },
    {
      "x": -1,
      "y": 1,
      "z": -4,
      "name": "Rock_Marble"
    },
    {
      "x": -1,
      "y": 2,
      "z": -4,
      "name": "Rock_Marble"
    },
    {
      "x": -1,
      "y": 3,
      "z": -4,
      "name": "Rock_Marble"
    },
    {
      "x": -1,
      "y": 4,
      "z": -4,
      "name": "Rock_Marble"
    },
    {
      "x": -1,
      "y": 5,
      "z": -4,
      "name": "Rock_Marble"
    },
    {
      "x": -1,
      "y": 6,
      "z": -4,
      "name": "Rock_Marble"
    },
    {
      "x": -1,
      "y": 7,
      "z": -4,
      "name": "Rock_Marble"
    },
    {
      "x": -1,
      "y": 8,
      "z": -4,
      "name": "Rock_Marble"
    },
    {
      "x": -1,
      "y": 9,
      "z": -4,
      "name": "Rock_Marble"
    },
    {
      "x": -1,
      "y": 10,
      "z": -4,
      "name": "Rock_Marble"
    },
    {
      "x": -1,
      "y": 11,
      "z": -4,
      "name": "Soil_Dirt"
    },
    {
      "x": -1,
      "y": 12,
      "z": -4,
      "name": "Soil_Dirt"
    },
    {
      "x": -1,
      "y": 13,
      "z": -4,
      "name": "Soil_Dirt"
    },
    {
      "x": -1,
      "y": 14,
      "z": -4,
      "name": "Soil_Dirt"
    },
    {
      "x": -1,
      "y": 15,
      "z": -4,
      "name": "Soil_Grass_Full"
    },
    {
      "x": -1,
      "y": 0,
      "z": -3,
      "name": "Rock_Marble"
    },
    {
      "x": -1,
      "y": 1,
      "z": -3,
      "name": "Rock_Marble"
    },
    {
      "x": -1,
      "y": 2,
      "z": -3,
      "name": "Rock_Marble"
    },
    {
      "x": -1,
      "y": 3,
      "z": -3,
      "name": "Rock_Marble"
    },
    {
      "x": -1,
      "y": 4,
      "z": -3,
      "name": "Rock_Marble"
    },
    {
      "x": -1,
      "y": 5,
      "z": -3,
      "name": "Rock_Marble"
    },
    {
      "x": -1,
      "y": 6,
      "z": -3,
      "name": "Rock_Marble"
    },
    {
      "x": -1,
      "y": 7,
      "z": -3,
      "name": "Rock_Marble"
    },
    {
      "x": -1,
      "y": 8,
      "z": -3,
      "name": "Rock_Marble"
    },
    {
      "x": -1,
      "y": 9,
      "z": -3,
      "name": "Rock_Marble"
    },
    {
      "x": -1,
      "y": 10,
      "z": -3,
      "name": "Rock_Marble"
    },
    {
      "x": -1,
      "y": 11,
      "z": -3,
      "name": "Soil_Dirt"
    },
    {
      "x": -1,
      "y": 12,
      "z": -3,
      "name": "Soil_Dirt"
    },
    {
      "x": -1,
      "y": 13,
      "z": -3,
      "name": "Soil_Dirt"
    },
    {
      "x": -1,
      "y": 14,
      "z": -3,
      "name": "Soil_Dirt"
    },
    {
      "x": -1,
      "y": 15,
      "z": -3,
      "name": "Soil_Grass_Full"
    },
    {
      "x": -1,
      "y": 1,
      "z": -2,
      "name": "Rock_Marble"
    },
    {
      "x": -1,
      "y": 2,
      "z": -2,
      "name": "Rock_Marble"
    },
    {
      "x": -1,
      "y": 3,
      "z": -2,
      "name": "Rock_Marble"
    },
    {
      "x": -1,
      "y": 4,
      "z": -2,
      "name": "Rock_Marble"
    },
    {
      "x": -1,
      "y": 5,
      "z": -2,
      "name": "Rock_Marble"
    },
    {
      "x": -1,
      "y": 6,
      "z": -2,
      "name": "Rock_Marble"
    },
    {
      "x": -1,
      "y": 7,
      "z": -2,
      "name": "Rock_Marble"
    },
    {
      "x": -1,
      "y": 8,
      "z": -2,
      "name": "Rock_Marble"
    },
    {
      "x": -1,
      "y": 9,
      "z": -2,
      "name": "Rock_Marble"
    },
    {
      "x": -1,
      "y": 10,
      "z": -2,
      "name": "Rock_Marble"
    },
    {
      "x": -1,
      "y": 11,
      "z": -2,
      "name": "Soil_Dirt"
    },
    {
      "x": -1,
      "y": 12,
      "z": -2,
      "name": "Soil_Dirt"
    },
    {
      "x": -1,
      "y": 13,
      "z": -2,
      "name": "Soil_Dirt"
    },
    {
      "x": -1,
      "y": 14,
      "z": -2,
      "name": "Soil_Dirt"
    },
    {
      "x": -1,
      "y": 15,
      "z": -2,
      "name": "Soil_Grass_Full"
    },
    {
      "x": -1,
      "y": 1,
      "z": -1,
      "name": "Rock_Marble"
    },
    {
      "x": -1,
      "y": 2,
      "z": -1,
      "name": "Rock_Marble"
    },
    {
      "x": -1,
      "y": 3,
      "z": -1,
      "name": "Rock_Marble"
    },
    {
      "x": -1,
      "y": 4,
      "z": -1,
      "name": "Rock_Marble"
    },
    {
      "x": -1,
      "y": 5,
      "z": -1,
      "name": "Rock_Marble"
    },
    {
      "x": -1,
      "y": 6,
      "z": -1,
      "name": "Rock_Marble"
    },
    {
      "x": -1,
      "y": 7,
      "z": -1,
      "name": "Rock_Marble"
    },
    {
      "x": -1,
      "y": 8,
      "z": -1,
      "name": "Rock_Marble"
    },
    {
      "x": -1,
      "y": 9,
      "z": -1,
      "name": "Rock_Marble"
    },
    {
      "x": -1,
      "y": 10,
      "z": -1,
      "name": "Rock_Marble"
    },
    {
      "x": -1,
      "y": 11,
      "z": -1,
      "name": "Soil_Dirt"
    },
    {
      "x": -1,
      "y": 12,
      "z": -1,
      "name": "Soil_Dirt"
    },
    {
      "x": -1,
      "y": 13,
      "z": -1,
      "name": "Soil_Dirt"
    },
    {
      "x": -1,
      "y": 14,
      "z": -1,
      "name": "Soil_Dirt"
    },
    {
      "x": -1,
      "y": 15,
      "z": -1,
      "name": "Soil_Grass_Full"
    },
    {
      "x": -1,
      "y": 2,
      "z": 0,
      "name": "Rock_Marble"
    },
    {
      "x": -1,
      "y": 3,
      "z": 0,
      "name": "Rock_Marble"
    },
    {
      "x": -1,
      "y": 4,
      "z": 0,
      "name": "Rock_Marble"
    },
    {
      "x": -1,
      "y": 5,
      "z": 0,
      "name": "Rock_Marble"
    },
    {
      "x": -1,
      "y": 6,
      "z": 0,
      "name": "Rock_Marble"
    },
    {
      "x": -1,
      "y": 7,
      "z": 0,
      "name": "Rock_Marble"
    },
    {
      "x": -1,
      "y": 8,
      "z": 0,
      "name": "Rock_Marble"
    },
    {
      "x": -1,
      "y": 9,
      "z": 0,
      "name": "Rock_Marble"
    },
    {
      "x": -1,
      "y": 10,
      "z": 0,
      "name": "Rock_Marble"
    },
    {
      "x": -1,
      "y": 11,
      "z": 0,
      "name": "Soil_Dirt"
    },
    {
      "x": -1,
      "y": 12,
      "z": 0,
      "name": "Soil_Dirt"
    },
    {
      "x": -1,
      "y": 13,
      "z": 0,
      "name": "Soil_Dirt"
    },
    {
      "x": -1,
      "y": 14,
      "z": 0,
      "name": "Soil_Dirt"
    },
    {
      "x": -1,
      "y": 15,
      "z": 0,
      "name": "Soil_Grass_Full"
    },
    {
      "x": -1,
      "y": 16,
      "z": 0,
      "name": "Plant_Grass_Sharp",
      "support": 15
    },
    {
      "x": -1,
      "y": 2,
      "z": 1,
      "name": "Rock_Marble"
    },
    {
      "x": -1,
      "y": 3,
      "z": 1,
      "name": "Rock_Marble"
    },
    {
      "x": -1,
      "y": 4,
      "z": 1,
      "name": "Rock_Marble"
    },
    {
      "x": -1,
      "y": 5,
      "z": 1,
      "name": "Rock_Marble"
    },
    {
      "x": -1,
      "y": 6,
      "z": 1,
      "name": "Rock_Marble"
    },
    {
      "x": -1,
      "y": 7,
      "z": 1,
      "name": "Rock_Marble"
    },
    {
      "x": -1,
      "y": 8,
      "z": 1,
      "name": "Rock_Marble"
    },
    {
      "x": -1,
      "y": 9,
      "z": 1,
      "name": "Rock_Marble"
    },
    {
      "x": -1,
      "y": 10,
      "z": 1,
      "name": "Rock_Marble"
    },
    {
      "x": -1,
      "y": 11,
      "z": 1,
      "name": "Soil_Dirt"
    },
    {
      "x": -1,
      "y": 12,
      "z": 1,
      "name": "Soil_Dirt"
    },
    {
      "x": -1,
      "y": 13,
      "z": 1,
      "name": "Soil_Dirt"
    },
    {
      "x": -1,
      "y": 14,
      "z": 1,
      "name": "Soil_Dirt"
    },
    {
      "x": -1,
      "y": 15,
      "z": 1,
      "name": "Soil_Grass_Full"
    },
    {
      "x": -1,
      "y": 3,
      "z": 2,
      "name": "Rock_Marble"
    },
    {
      "x": -1,
      "y": 4,
      "z": 2,
      "name": "Rock_Marble"
    },
    {
      "x": -1,
      "y": 5,
      "z": 2,
      "name": "Rock_Marble"
    },
    {
      "x": -1,
      "y": 6,
      "z": 2,
      "name": "Rock_Marble"
    },
    {
      "x": -1,
      "y": 7,
      "z": 2,
      "name": "Rock_Marble"
    },
    {
      "x": -1,
      "y": 8,
      "z": 2,
      "name": "Rock_Marble"
    },
    {
      "x": -1,
      "y": 9,
      "z": 2,
      "name": "Rock_Marble"
    },
    {
      "x": -1,
      "y": 10,
      "z": 2,
      "name": "Rock_Marble"
    },
    {
      "x": -1,
      "y": 11,
      "z": 2,
      "name": "Soil_Dirt"
    },
    {
      "x": -1,
      "y": 12,
      "z": 2,
      "name": "Soil_Dirt"
    },
    {
      "x": -1,
      "y": 13,
      "z": 2,
      "name": "Soil_Dirt"
    },
    {
      "x": -1,
      "y": 14,
      "z": 2,
      "name": "Soil_Dirt"
    },
    {
      "x": -1,
      "y": 15,
      "z": 2,
      "name": "Soil_Grass_Full"
    },
    {
      "x": -1,
      "y": 4,
      "z": 3,
      "name": "Rock_Marble"
    },
    {
      "x": -1,
      "y": 5,
      "z": 3,
      "name": "Rock_Marble"
    },
    {
      "x": -1,
      "y": 6,
      "z": 3,
      "name": "Rock_Marble"
    },
    {
      "x": -1,
      "y": 7,
      "z": 3,
      "name": "Rock_Marble"
    },
    {
      "x": -1,
      "y": 8,
      "z": 3,
      "name": "Rock_Marble"
    },
    {
      "x": -1,
      "y": 9,
      "z": 3,
      "name": "Rock_Marble"
    },
    {
      "x": -1,
      "y": 10,
      "z": 3,
      "name": "Rock_Marble"
    },
    {
      "x": -1,
      "y": 11,
      "z": 3,
      "name": "Soil_Dirt"
    },
    {
      "x": -1,
      "y": 12,
      "z": 3,
      "name": "Soil_Dirt"
    },
    {
      "x": -1,
      "y": 13,
      "z": 3,
      "name": "Soil_Dirt"
    },
    {
      "x": -1,
      "y": 14,
      "z": 3,
      "name": "Soil_Dirt"
    },
    {
      "x": -1,
      "y": 15,
      "z": 3,
      "name": "Soil_Grass_Full"
    },
    {
      "x": -1,
      "y": 16,
      "z": 3,
      "name": "Plant_Grass_Sharp",
      "support": 15
    },
    {
      "x": -1,
      "y": 4,
      "z": 4,
      "name": "Rock_Marble"
    },
    {
      "x": -1,
      "y": 5,
      "z": 4,
      "name": "Rock_Marble"
    },
    {
      "x": -1,
      "y": 6,
      "z": 4,
      "name": "Rock_Marble"
    },
    {
      "x": -1,
      "y": 7,
      "z": 4,
      "name": "Rock_Marble"
    },
    {
      "x": -1,
      "y": 8,
      "z": 4,
      "name": "Rock_Marble"
    },
    {
      "x": -1,
      "y": 9,
      "z": 4,
      "name": "Rock_Marble"
    },
    {
      "x": -1,
      "y": 10,
      "z": 4,
      "name": "Rock_Marble"
    },
    {
      "x": -1,
      "y": 11,
      "z": 4,
      "name": "Soil_Dirt"
    },
    {
      "x": -1,
      "y": 12,
      "z": 4,
      "name": "Soil_Dirt"
    },
    {
      "x": -1,
      "y": 13,
      "z": 4,
      "name": "Soil_Dirt"
    },
    {
      "x": -1,
      "y": 14,
      "z": 4,
      "name": "Soil_Dirt"
    },
    {
      "x": -1,
      "y": 15,
      "z": 4,
      "name": "Soil_Grass_Full"
    },
    {
      "x": -1,
      "y": 6,
      "z": 5,
      "name": "Rock_Marble"
    },
    {
      "x": -1,
      "y": 7,
      "z": 5,
      "name": "Rock_Marble"
    },
    {
      "x": -1,
      "y": 8,
      "z": 5,
      "name": "Rock_Marble"
    },
    {
      "x": -1,
      "y": 9,
      "z": 5,
      "name": "Rock_Marble"
    },
    {
      "x": -1,
      "y": 10,
      "z": 5,
      "name": "Rock_Marble"
    },
    {
      "x": -1,
      "y": 11,
      "z": 5,
      "name": "Soil_Dirt"
    },
    {
      "x": -1,
      "y": 12,
      "z": 5,
      "name": "Soil_Dirt"
    },
    {
      "x": -1,
      "y": 13,
      "z": 5,
      "name": "Soil_Dirt"
    },
    {
      "x": -1,
      "y": 14,
      "z": 5,
      "name": "Soil_Dirt"
    },
    {
      "x": -1,
      "y": 15,
      "z": 5,
      "name": "Soil_Grass_Full"
    },
    {
      "x": -1,
      "y": 6,
      "z": 6,
      "name": "Rock_Marble"
    },
    {
      "x": -1,
      "y": 7,
      "z": 6,
      "name": "Rock_Marble"
    },
    {
      "x": -1,
      "y": 8,
      "z": 6,
      "name": "Rock_Marble"
    },
    {
      "x": -1,
      "y": 9,
      "z": 6,
      "name": "Rock_Marble"
    },
    {
      "x": -1,
      "y": 10,
      "z": 6,
      "name": "Soil_Dirt"
    },
    {
      "x": -1,
      "y": 11,
      "z": 6,
      "name": "Soil_Dirt"
    },
    {
      "x": -1,
      "y": 12,
      "z": 6,
      "name": "Soil_Dirt"
    },
    {
      "x": -1,
      "y": 13,
      "z": 6,
      "name": "Soil_Dirt"
    },
    {
      "x": -1,
      "y": 14,
      "z": 6,
      "name": "Soil_Grass_Full"
    },
    {
      "x": -1,
      "y": 15,
      "z": 6,
      "name": "Plant_Grass_Sharp",
      "support": 15
    },
    {
      "x": -1,
      "y": 7,
      "z": 7,
      "name": "Rock_Marble"
    },
    {
      "x": -1,
      "y": 8,
      "z": 7,
      "name": "Rock_Marble"
    },
    {
      "x": -1,
      "y": 9,
      "z": 7,
      "name": "Rock_Marble"
    },
    {
      "x": -1,
      "y": 10,
      "z": 7,
      "name": "Soil_Dirt"
    },
    {
      "x": -1,
      "y": 11,
      "z": 7,
      "name": "Soil_Dirt"
    },
    {
      "x": -1,
      "y": 12,
      "z": 7,
      "name": "Soil_Dirt"
    },
    {
      "x": -1,
      "y": 13,
      "z": 7,
      "name": "Soil_Dirt"
    },
    {
      "x": -1,
      "y": 14,
      "z": 7,
      "name": "Soil_Grass_Full"
    },
    {
      "x": -1,
      "y": 15,
      "z": 7,
      "name": "Plant_Grass_Sharp",
      "support": 15
    },
    {
      "x": -1,
      "y": 8,
      "z": 8,
      "name": "Rock_Marble"
    },
    {
      "x": -1,
      "y": 9,
      "z": 8,
      "name": "Soil_Dirt"
    },
    {
      "x": -1,
      "y": 10,
      "z": 8,
      "name": "Soil_Dirt"
    },
    {
      "x": -1,
      "y": 11,
      "z": 8,
      "name": "Soil_Dirt"
    },
    {
      "x": -1,
      "y": 12,
      "z": 8,
      "name": "Soil_Dirt"
    },
    {
      "x": -1,
      "y": 13,
      "z": 8,
      "name": "Soil_Grass_Full"
    },
    {
      "x": -1,
      "y": 9,
      "z": 9,
      "name": "Soil_Dirt"
    },
    {
      "x": -1,
      "y": 10,
      "z": 9,
      "name": "Soil_Dirt"
    },
    {
      "x": -1,
      "y": 11,
      "z": 9,
      "name": "Soil_Grass_Full"
    },
    {
      "x": -1,
      "y": 10,
      "z": 10,
      "name": "Soil_Grass_Full"
    },
    {
      "x": 0,
      "y": 9,
      "z": -10,
      "name": "Soil_Dirt"
    },
    {
      "x": 0,
      "y": 10,
      "z": -10,
      "name": "Soil_Dirt"
    },
    {
      "x": 0,
      "y": 11,
      "z": -10,
      "name": "Soil_Dirt"
    },
    {
      "x": 0,
      "y": 12,
      "z": -10,
      "name": "Soil_Dirt"
    },
    {
      "x": 0,
      "y": 13,
      "z": -10,
      "name": "Soil_Grass_Full"
    },
    {
      "x": 0,
      "y": 8,
      "z": -9,
      "name": "Rock_Marble"
    },
    {
      "x": 0,
      "y": 9,
      "z": -9,
      "name": "Rock_Marble"
    },
    {
      "x": 0,
      "y": 10,
      "z": -9,
      "name": "Soil_Dirt"
    },
    {
      "x": 0,
      "y": 11,
      "z": -9,
      "name": "Soil_Dirt"
    },
    {
      "x": 0,
      "y": 12,
      "z": -9,
      "name": "Soil_Dirt"
    },
    {
      "x": 0,
      "y": 13,
      "z": -9,
      "name": "Soil_Dirt"
    },
    {
      "x": 0,
      "y": 14,
      "z": -9,
      "name": "Soil_Grass_Full"
    },
    {
      "x": 0,
      "y": 15,
      "z": -9,
      "name": "Plant_Crop_Mushroom_Glowing_Blue"
    },
    {
      "x": 0,
      "y": 7,
      "z": -8,
      "name": "Rock_Marble"
    },
    {
      "x": 0,
      "y": 8,
      "z": -8,
      "name": "Rock_Marble"
    },
    {
      "x": 0,
      "y": 9,
      "z": -8,
      "name": "Rock_Marble"
    },
    {
      "x": 0,
      "y": 10,
      "z": -8,
      "name": "Rock_Marble"
    },
    {
      "x": 0,
      "y": 11,
      "z": -8,
      "name": "Soil_Dirt"
    },
    {
      "x": 0,
      "y": 12,
      "z": -8,
      "name": "Soil_Dirt"
    },
    {
      "x": 0,
      "y": 13,
      "z": -8,
      "name": "Soil_Dirt"
    },
    {
      "x": 0,
      "y": 14,
      "z": -8,
      "name": "Soil_Dirt"
    },
    {
      "x": 0,
      "y": 15,
      "z": -8,
      "name": "Soil_Grass_Full"
    },
    {
      "x": 0,
      "y": 16,
      "z": -8,
      "name": "Plant_Grass_Sharp",
      "support": 15
    },
    {
      "x": 0,
      "y": 7,
      "z": -7,
      "name": "Rock_Marble"
    },
    {
      "x": 0,
      "y": 8,
      "z": -7,
      "name": "Rock_Marble"
    },
    {
      "x": 0,
      "y": 9,
      "z": -7,
      "name": "Rock_Marble"
    },
    {
      "x": 0,
      "y": 10,
      "z": -7,
      "name": "Rock_Marble"
    },
    {
      "x": 0,
      "y": 11,
      "z": -7,
      "name": "Soil_Dirt"
    },
    {
      "x": 0,
      "y": 12,
      "z": -7,
      "name": "Soil_Dirt"
    },
    {
      "x": 0,
      "y": 13,
      "z": -7,
      "name": "Soil_Dirt"
    },
    {
      "x": 0,
      "y": 14,
      "z": -7,
      "name": "Soil_Dirt"
    },
    {
      "x": 0,
      "y": 15,
      "z": -7,
      "name": "Soil_Grass_Full"
    },
    {
      "x": 0,
      "y": 6,
      "z": -6,
      "name": "Rock_Marble"
    },
    {
      "x": 0,
      "y": 7,
      "z": -6,
      "name": "Rock_Marble"
    },
    {
      "x": 0,
      "y": 8,
      "z": -6,
      "name": "Rock_Marble"
    },
    {
      "x": 0,
      "y": 9,
      "z": -6,
      "name": "Rock_Marble"
    },
    {
      "x": 0,
      "y": 10,
      "z": -6,
      "name": "Rock_Marble"
    },
    {
      "x": 0,
      "y": 11,
      "z": -6,
      "name": "Soil_Dirt"
    },
    {
      "x": 0,
      "y": 12,
      "z": -6,
      "name": "Soil_Dirt"
    },
    {
      "x": 0,
      "y": 13,
      "z": -6,
      "name": "Soil_Dirt"
    },
    {
      "x": 0,
      "y": 14,
      "z": -6,
      "name": "Soil_Dirt"
    },
    {
      "x": 0,
      "y": 15,
      "z": -6,
      "name": "Soil_Grass_Full"
    },
    {
      "x": 0,
      "y": 2,
      "z": -5,
      "name": "Rock_Marble"
    },
    {
      "x": 0,
      "y": 3,
      "z": -5,
      "name": "Rock_Marble"
    },
    {
      "x": 0,
      "y": 4,
      "z": -5,
      "name": "Rock_Marble"
    },
    {
      "x": 0,
      "y": 5,
      "z": -5,
      "name": "Rock_Marble"
    },
    {
      "x": 0,
      "y": 6,
      "z": -5,
      "name": "Rock_Marble"
    },
    {
      "x": 0,
      "y": 7,
      "z": -5,
      "name": "Rock_Marble"
    },
    {
      "x": 0,
      "y": 8,
      "z": -5,
      "name": "Rock_Marble"
    },
    {
      "x": 0,
      "y": 9,
      "z": -5,
      "name": "Rock_Marble"
    },
    {
      "x": 0,
      "y": 10,
      "z": -5,
      "name": "Rock_Marble"
    },
    {
      "x": 0,
      "y": 11,
      "z": -5,
      "name": "Soil_Dirt"
    },
    {
      "x": 0,
      "y": 12,
      "z": -5,
      "name": "Soil_Dirt"
    },
    {
      "x": 0,
      "y": 13,
      "z": -5,
      "name": "Soil_Dirt"
    },
    {
      "x": 0,
      "y": 14,
      "z": -5,
      "name": "Soil_Dirt"
    },
    {
      "x": 0,
      "y": 15,
      "z": -5,
      "name": "Soil_Grass_Full"
    },
    {
      "x": 0,
      "y": 16,
      "z": -5,
      "name": "Plant_Crop_Mushroom_Glowing_Blue"
    },
    {
      "x": 0,
      "y": 1,
      "z": -4,
      "name": "Rock_Marble"
    },
    {
      "x": 0,
      "y": 2,
      "z": -4,
      "name": "Rock_Marble"
    },
    {
      "x": 0,
      "y": 3,
      "z": -4,
      "name": "Rock_Marble"
    },
    {
      "x": 0,
      "y": 4,
      "z": -4,
      "name": "Rock_Marble"
    },
    {
      "x": 0,
      "y": 5,
      "z": -4,
      "name": "Rock_Marble"
    },
    {
      "x": 0,
      "y": 6,
      "z": -4,
      "name": "Rock_Marble"
    },
    {
      "x": 0,
      "y": 7,
      "z": -4,
      "name": "Rock_Marble"
    },
    {
      "x": 0,
      "y": 8,
      "z": -4,
      "name": "Rock_Marble"
    },
    {
      "x": 0,
      "y": 9,
      "z": -4,
      "name": "Rock_Marble"
    },
    {
      "x": 0,
      "y": 10,
      "z": -4,
      "name": "Rock_Marble"
    },
    {
      "x": 0,
      "y": 11,
      "z": -4,
      "name": "Soil_Dirt"
    },
    {
      "x": 0,
      "y": 12,
      "z": -4,
      "name": "Soil_Dirt"
    },
    {
      "x": 0,
      "y": 13,
      "z": -4,
      "name": "Soil_Dirt"
    },
    {
      "x": 0,
      "y": 14,
      "z": -4,
      "name": "Soil_Dirt"
    },
    {
      "x": 0,
      "y": 15,
      "z": -4,
      "name": "Soil_Grass_Full"
    },
    {
      "x": 0,
      "y": 1,
      "z": -3,
      "name": "Rock_Marble"
    },
    {
      "x": 0,
      "y": 2,
      "z": -3,
      "name": "Rock_Marble"
    },
    {
      "x": 0,
      "y": 3,
      "z": -3,
      "name": "Rock_Marble"
    },
    {
      "x": 0,
      "y": 4,
      "z": -3,
      "name": "Rock_Marble"
    },
    {
      "x": 0,
      "y": 5,
      "z": -3,
      "name": "Rock_Marble"
    },
    {
      "x": 0,
      "y": 6,
      "z": -3,
      "name": "Rock_Marble"
    },
    {
      "x": 0,
      "y": 7,
      "z": -3,
      "name": "Rock_Marble"
    },
    {
      "x": 0,
      "y": 8,
      "z": -3,
      "name": "Rock_Marble"
    },
    {
      "x": 0,
      "y": 9,
      "z": -3,
      "name": "Rock_Marble"
    },
    {
      "x": 0,
      "y": 10,
      "z": -3,
      "name": "Rock_Marble"
    },
    {
      "x": 0,
      "y": 11,
      "z": -3,
      "name": "Soil_Dirt"
    },
    {
      "x": 0,
      "y": 12,
      "z": -3,
      "name": "Soil_Dirt"
    },
    {
      "x": 0,
      "y": 13,
      "z": -3,
      "name": "Soil_Dirt"
    },
    {
      "x": 0,
      "y": 14,
      "z": -3,
      "name": "Soil_Dirt"
    },
    {
      "x": 0,
      "y": 15,
      "z": -3,
      "name": "Soil_Grass_Full"
    },
    {
      "x": 0,
      "y": 1,
      "z": -2,
      "name": "Rock_Marble"
    },
    {
      "x": 0,
      "y": 2,
      "z": -2,
      "name": "Rock_Marble"
    },
    {
      "x": 0,
      "y": 3,
      "z": -2,
      "name": "Rock_Marble"
    },
    {
      "x": 0,
      "y": 4,
      "z": -2,
      "name": "Rock_Marble"
    },
    {
      "x": 0,
      "y": 5,
      "z": -2,
      "name": "Rock_Marble"
    },
    {
      "x": 0,
      "y": 6,
      "z": -2,
      "name": "Rock_Marble"
    },
    {
      "x": 0,
      "y": 7,
      "z": -2,
      "name": "Rock_Marble"
    },
    {
      "x": 0,
      "y": 8,
      "z": -2,
      "name": "Rock_Marble"
    },
    {
      "x": 0,
      "y": 9,
      "z": -2,
      "name": "Rock_Marble"
    },
    {
      "x": 0,
      "y": 10,
      "z": -2,
      "name": "Rock_Marble"
    },
    {
      "x": 0,
      "y": 11,
      "z": -2,
      "name": "Soil_Dirt"
    },
    {
      "x": 0,
      "y": 12,
      "z": -2,
      "name": "Soil_Dirt"
    },
    {
      "x": 0,
      "y": 13,
      "z": -2,
      "name": "Soil_Dirt"
    },
    {
      "x": 0,
      "y": 14,
      "z": -2,
      "name": "Soil_Dirt"
    },
    {
      "x": 0,
      "y": 15,
      "z": -2,
      "name": "Soil_Grass_Full"
    },
    {
      "x": 0,
      "y": 16,
