{
  "version": 8,
  "blockIdVersion": 11,
  "anchorX": 0,
  "anchorY": 0,
  "anchorZ": 0,
  "blocks": [
    {
      "x": -13,
      "y": 16,
      "z": 6,
      "name": "Plant_Leaves_Azure",
      "support": 2,
      "rotation": 2
    },
    {
      "x": -13,
      "y": 15,
      "z": 7,
      "name": "Plant_Leaves_Azure",
      "support": 2,
      "rotation": 2
    },
    {
      "x": -13,
      "y": 16,
      "z": 7,
      "name": "Plant_Leaves_Azure",
      "support": 1,
      "rotation": 2
    },
    {
      "x": -13,
      "y": 17,
      "z": 7,
      "name": "Plant_Leaves_Azure",
      "rotation": 2
    },
    {
      "x": -13,
      "y": 15,
      "z": 8,
      "name": "Plant_Leaves_Azure",
      "support": 3,
      "rotation": 2
    },
    {
      "x": -13,
      "y": 16,
      "z": 8,
      "name": "Plant_Leaves_Azure",
      "support": 2,
      "rotation": 2
    },
    {
      "x": -13,
      "y": 17,
      "z": 8,
      "name": "Plant_Leaves_Azure",
      "support": 1,
      "rotation": 2
    },
    {
      "x": -13,
      "y": 18,
      "z": 8,
      "name": "Plant_Leaves_Azure",
      "support": 2,
      "rotation": 2
    },
    {
      "x": -13,
      "y": 15,
      "z": 9,
      "name": "Plant_Leaves_Azure",
      "support": 4,
      "rotation": 2
    },
    {
      "x": -13,
      "y": 16,
      "z": 9,
      "name": "Plant_Leaves_Azure",
      "support": 3,
      "rotation": 2
    },
    {
      "x": -13,
      "y": 17,
      "z": 9,
      "name": "Plant_Leaves_Azure",
      "support": 2,
      "rotation": 2
    },
    {
      "x": -12,
      "y": 20,
      "z": 5,
      "name": "Plant_Leaves_Azure",
      "support": 4,
      "rotation": 2
    },
    {
      "x": -12,
      "y": 21,
      "z": 5,
      "name": "Plant_Leaves_Azure",
      "support": 3,
      "rotation": 2
    },
    {
      "x": -12,
      "y": 15,
      "z": 6,
      "name": "Plant_Leaves_Azure",
      "support": 2,
      "rotation": 2
    },
    {
      "x": -12,
      "y": 16,
      "z": 6,
      "name": "Plant_Leaves_Azure",
      "support": 1,
      "rotation": 2
    },
    {
      "x": -12,
      "y": 17,
      "z": 6,
      "name": "Plant_Leaves_Azure",
      "rotation": 2
    },
    {
      "x": -12,
      "y": 19,
      "z": 6,
      "name": "Plant_Leaves_Azure",
      "support": 4,
      "rotation": 2
    },
    {
      "x": -12,
      "y": 20,
      "z": 6,
      "name": "Plant_Leaves_Azure",
      "support": 3,
      "rotation": 2
    },
    {
      "x": -12,
      "y": 21,
      "z": 6,
      "name": "Plant_Leaves_Azure",
      "support": 2,
      "rotation": 2
    },
    {
      "x": -12,
      "y": 22,
      "z": 6,
      "name": "Plant_Leaves_Azure",
      "support": 3,
      "rotation": 2
    },
    {
      "x": -12,
      "y": 15,
      "z": 7,
      "name": "Plant_Leaves_Azure",
      "support": 1,
      "rotation": 2
    },
    {
      "x": -12,
      "y": 16,
      "z": 7,
      "name": "Plant_Leaves_Azure",
      "rotation": 2
    },
    {
      "x": -12,
      "y": 17,
      "z": 7,
      "name": "Wood_Azure_Branch_Long",
      "support": 2,
      "rotation": 7
    },
    {
      "x": -12,
      "y": 18,
      "z": 7,
      "name": "Plant_Leaves_Azure",
      "rotation": 2
    },
    {
      "x": -12,
      "y": 20,
      "z": 7,
      "name": "Plant_Leaves_Azure",
      "support": 4,
      "rotation": 2
    },
    {
      "x": -12,
      "y": 21,
      "z": 7,
      "name": "Plant_Leaves_Azure",
      "support": 3,
      "rotation": 2
    },
    {
      "x": -12,
      "y": 22,
      "z": 7,
      "name": "Plant_Leaves_Azure",
      "support": 4,
      "rotation": 2
    },
    {
      "x": -12,
      "y": 15,
      "z": 8,
      "name": "Plant_Leaves_Azure",
      "support": 2,
      "rotation": 2
    },
    {
      "x": -12,
      "y": 16,
      "z": 8,
      "name": "Plant_Leaves_Azure",
      "support": 1,
      "rotation": 2
    },
    {
      "x": -12,
      "y": 17,
      "z": 8,
      "name": "Plant_Leaves_Azure",
      "rotation": 2
    },
    {
      "x": -12,
      "y": 18,
      "z": 8,
      "name": "Plant_Leaves_Azure",
      "support": 1,
      "rotation": 2
    },
    {
      "x": -12,
      "y": 19,
      "z": 8,
      "name": "Plant_Fruit_Azure",
      "rotation": 2
    },
    {
      "x": -12,
      "y": 21,
      "z": 8,
      "name": "Plant_Leaves_Azure",
      "support": 4,
      "rotation": 2
    },
    {
      "x": -12,
      "y": 23,
      "z": 8,
      "name": "Plant_Leaves_Azure",
      "support": 4,
      "rotation": 2
    },
    {
      "x": -12,
      "y": 16,
      "z": 9,
      "name": "Plant_Leaves_Azure",
      "support": 2,
      "rotation": 2
    },
    {
      "x": -12,
      "y": 17,
      "z": 9,
      "name": "Plant_Leaves_Azure",
      "support": 1,
      "rotation": 2
    },
    {
      "x": -12,
      "y": 18,
      "z": 9,
      "name": "Plant_Leaves_Azure",
      "support": 2,
      "rotation": 2
    },
    {
      "x": -12,
      "y": 19,
      "z": 9,
      "name": "Plant_Leaves_Azure",
      "support": 3,
      "rotation": 2
    },
    {
      "x": -12,
      "y": 16,
      "z": 10,
      "name": "Plant_Leaves_Azure",
      "support": 3,
      "rotation": 2
    },
    {
      "x": -12,
      "y": 17,
      "z": 10,
      "name": "Plant_Leaves_Azure",
      "support": 2,
      "rotation": 2
    },
    {
      "x": -12,
      "y": 18,
      "z": 10,
      "name": "Plant_Leaves_Azure",
      "support": 3,
      "rotation": 2
    },
    {
      "x": -12,
      "y": 19,
      "z": 10,
      "name": "Plant_Leaves_Azure",
      "support": 3,
      "rotation": 2
    },
    {
      "x": -12,
      "y": 16,
      "z": 11,
      "name": "Plant_Leaves_Azure",
      "support": 4,
      "rotation": 2
    },
    {
      "x": -12,
      "y": 17,
      "z": 11,
      "name": "Plant_Leaves_Azure",
      "support": 3,
      "rotation": 2
    },
    {
      "x": -12,
      "y": 18,
      "z": 11,
      "name": "Plant_Leaves_Azure",
      "support": 4,
      "rotation": 2
    },
    {
      "x": -11,
      "y": 10,
      "z": 2,
      "name": "Soil_Grass"
    },
    {
      "x": -11,
      "y": 10,
      "z": 3,
      "name": "Plant_Moss_Block_Blue",
      "support": 15
    },
    {
      "x": -11,
      "y": 11,
      "z": 3,
      "name": "Soil_Grass"
    },
    {
      "x": -11,
      "y": 21,
      "z": 3,
      "name": "Plant_Leaves_Azure",
      "support": 4,
      "rotation": 2
    },
    {
      "x": -11,
      "y": 11,
      "z": 4,
      "name": "Soil_Grass"
    },
    {
      "x": -11,
      "y": 20,
      "z": 4,
      "name": "Plant_Leaves_Azure",
      "support": 4,
      "rotation": 2
    },
    {
      "x": -11,
      "y": 21,
      "z": 4,
      "name": "Plant_Leaves_Azure",
      "support": 3,
      "rotation": 2
    },
    {
      "x": -11,
      "y": 22,
      "z": 4,
      "name": "Plant_Leaves_Azure",
      "support": 4,
      "rotation": 2
    },
    {
      "x": -11,
      "y": 23,
      "z": 4,
      "name": "Plant_Fruit_Azure",
      "rotation": 2
    },
    {
      "x": -11,
      "y": 11,
      "z": 5,
      "name": "Soil_Grass"
    },
    {
      "x": -11,
      "y": 12,
      "z": 5,
      "name": "Plant_Moss_Blue",
      "support": 15
    },
    {
      "x": -11,
      "y": 20,
      "z": 5,
      "name": "Plant_Leaves_Azure",
      "support": 3,
      "rotation": 2
    },
    {
      "x": -11,
      "y": 21,
      "z": 5,
      "name": "Plant_Leaves_Azure",
      "support": 2,
      "rotation": 2
    },
    {
      "x": -11,
      "y": 22,
      "z": 5,
      "name": "Plant_Leaves_Azure",
      "support": 3,
      "rotation": 2
    },
    {
      "x": -11,
      "y": 16,
      "z": 6,
      "name": "Plant_Leaves_Azure",
      "support": 1,
      "rotation": 2
    },
    {
      "x": -11,
      "y": 21,
      "z": 6,
      "name": "Plant_Leaves_Azure",
      "support": 1,
      "rotation": 2
    },
    {
      "x": -11,
      "y": 22,
      "z": 6,
      "name": "Plant_Leaves_Azure",
      "support": 2,
      "rotation": 2
    },
    {
      "x": -11,
      "y": 23,
      "z": 6,
      "name": "Plant_Leaves_Azure",
      "support": 3,
      "rotation": 2
    },
    {
      "x": -11,
      "y": 24,
      "z": 6,
      "name": "Plant_Fruit_Azure",
      "rotation": 2
    },
    {
      "x": -11,
      "y": 15,
      "z": 7,
      "name": "Plant_Leaves_Azure",
      "support": 1,
      "rotation": 2
    },
    {
      "x": -11,
      "y": 16,
      "z": 7,
      "name": "Plant_Leaves_Azure",
      "rotation": 2
    },
    {
      "x": -11,
      "y": 17,
      "z": 7,
      "name": "Wood_Azure_Branch_Long",
      "support": 1,
      "rotation": 7
    },
    {
      "x": -11,
      "y": 21,
      "z": 7,
      "name": "Plant_Leaves_Azure",
      "support": 2,
      "rotation": 2
    },
    {
      "x": -11,
      "y": 22,
      "z": 7,
      "name": "Plant_Leaves_Azure",
      "support": 3,
      "rotation": 2
    },
    {
      "x": -11,
      "y": 23,
      "z": 7,
      "name": "Plant_Leaves_Azure",
      "support": 4,
      "rotation": 2
    },
    {
      "x": -11,
      "y": 24,
      "z": 7,
      "name": "Plant_Leaves_Azure",
      "support": 3,
      "rotation": 2
    },
    {
      "x": -11,
      "y": 16,
      "z": 8,
      "name": "Plant_Leaves_Azure",
      "support": 1,
      "rotation": 2
    },
    {
      "x": -11,
      "y": 17,
      "z": 8,
      "name": "Plant_Leaves_Azure",
      "rotation": 2
    },
    {
      "x": -11,
      "y": 21,
      "z": 8,
      "name": "Plant_Leaves_Azure",
      "support": 3,
      "rotation": 2
    },
    {
      "x": -11,
      "y": 22,
      "z": 8,
      "name": "Plant_Leaves_Azure",
      "support": 4,
      "rotation": 2
    },
    {
      "x": -11,
      "y": 23,
      "z": 8,
      "name": "Plant_Leaves_Azure",
      "support": 3,
      "rotation": 2
    },
    {
      "x": -11,
      "y": 24,
      "z": 8,
      "name": "Plant_Leaves_Azure",
      "support": 2,
      "rotation": 2
    },
    {
      "x": -11,
      "y": 25,
      "z": 8,
      "name": "Plant_Fruit_Azure",
      "rotation": 2
    },
    {
      "x": -11,
      "y": 16,
      "z": 9,
      "name": "Plant_Leaves_Azure",
      "support": 2,
      "rotation": 2
    },
    {
      "x": -11,
      "y": 17,
      "z": 9,
      "name": "Plant_Leaves_Azure",
      "support": 1,
      "rotation": 2
    },
    {
      "x": -11,
      "y": 18,
      "z": 9,
      "name": "Plant_Leaves_Azure",
      "support": 2,
      "rotation": 2
    },
    {
      "x": -11,
      "y": 19,
      "z": 9,
      "name": "Plant_Leaves_Azure",
      "support": 3,
      "rotation": 2
    },
    {
      "x": -11,
      "y": 23,
      "z": 9,
      "name": "Plant_Leaves_Azure",
      "support": 4,
      "rotation": 2
    },
    {
      "x": -11,
      "y": 24,
      "z": 9,
      "name": "Plant_Leaves_Azure",
      "support": 3,
      "rotation": 2
    },
    {
      "x": -11,
      "y": 16,
      "z": 10,
      "name": "Plant_Leaves_Azure",
      "support": 3,
      "rotation": 2
    },
    {
      "x": -11,
      "y": 17,
      "z": 10,
      "name": "Plant_Leaves_Azure",
      "support": 2,
      "rotation": 2
    },
    {
      "x": -11,
      "y": 18,
      "z": 10,
      "name": "Plant_Leaves_Azure",
      "support": 3,
      "rotation": 2
    },
    {
      "x": -11,
      "y": 19,
      "z": 10,
      "name": "Plant_Leaves_Azure",
      "support": 2,
      "rotation": 2
    },
    {
      "x": -11,
      "y": 20,
      "z": 10,
      "name": "Plant_Fruit_Azure",
      "rotation": 2
    },
    {
      "x": -11,
      "y": 16,
      "z": 11,
      "name": "Plant_Leaves_Azure",
      "support": 4,
      "rotation": 2
    },
    {
      "x": -11,
      "y": 17,
      "z": 11,
      "name": "Plant_Leaves_Azure",
      "support": 3,
      "rotation": 2
    },
    {
      "x": -11,
      "y": 18,
      "z": 11,
      "name": "Plant_Leaves_Azure",
      "support": 3,
      "rotation": 2
    },
    {
      "x": -11,
      "y": 19,
      "z": 11,
      "name": "Plant_Leaves_Azure",
      "support": 2,
      "rotation": 2
    },
    {
      "x": -11,
      "y": 20,
      "z": 11,
      "name": "Plant_Leaves_Azure",
      "support": 3,
      "rotation": 2
    },
    {
      "x": -11,
      "y": 17,
      "z": 12,
      "name": "Plant_Leaves_Azure",
      "support": 4,
      "rotation": 2
    },
    {
      "x": -11,
      "y": 18,
      "z": 12,
      "name": "Plant_Leaves_Azure",
      "support": 4,
      "rotation": 2
    },
    {
      "x": -11,
      "y": 19,
      "z": 12,
      "name": "Plant_Leaves_Azure",
      "support": 3,
      "rotation": 2
    },
    {
      "x": -10,
      "y": 10,
      "z": 0,
      "name": "Soil_Grass"
    },
    {
      "x": -10,
      "y": 10,
      "z": 1,
      "name": "Soil_Grass"
    },
    {
      "x": -10,
      "y": 10,
      "z": 2,
      "name": "Plant_Moss_Block_Blue",
      "support": 15
    },
    {
      "x": -10,
      "y": 11,
      "z": 2,
      "name": "Soil_Grass"
    },
    {
      "x": -10,
      "y": 12,
      "z": 2,
      "name": "Plant_Moss_Blue",
      "support": 15
    },
    {
      "x": -10,
      "y": 18,
      "z": 2,
      "name": "Plant_Leaves_Azure",
      "support": 3,
      "rotation": 2
    },
    {
      "x": -10,
      "y": 19,
      "z": 2,
      "name": "Plant_Leaves_Azure",
      "support": 4,
      "rotation": 2
    },
    {
      "x": -10,
      "y": 10,
      "z": 3,
      "name": "Plant_Moss_Block_Blue",
      "support": 15
    },
    {
      "x": -10,
      "y": 11,
      "z": 3,
      "name": "Plant_Moss_Block_Blue",
      "support": 15
    },
    {
      "x": -10,
      "y": 12,
      "z": 3,
      "name": "Soil_Grass"
    },
    {
      "x": -10,
      "y": 13,
      "z": 3,
      "name": "Plant_Moss_Cave_Blue",
      "support": 15
    },
    {
      "x": -10,
      "y": 18,
      "z": 3,
      "name": "Plant_Leaves_Azure",
      "support": 4,
      "rotation": 2
    },
    {
      "x": -10,
      "y": 20,
      "z": 3,
      "name": "Plant_Leaves_Azure",
      "support": 4,
      "rotation": 2
    },
    {
      "x": -10,
      "y": 21,
      "z": 3,
      "name": "Plant_Leaves_Azure",
      "support": 3,
      "rotation": 2
    },
    {
      "x": -10,
      "y": 10,
      "z": 4,
      "name": "Plant_Moss_Block_Blue",
      "support": 15
    },
    {
      "x": -10,
      "y": 11,
      "z": 4,
      "name": "Wood_Azure_Trunk_Full",
      "rotation": 2
    },
    {
      "x": -10,
      "y": 12,
      "z": 4,
      "name": "Soil_Grass"
    },
    {
      "x": -10,
      "y": 19,
      "z": 4,
      "name": "Plant_Leaves_Azure",
      "support": 4,
      "rotation": 2
    },
    {
      "x": -10,
      "y": 20,
      "z": 4,
      "name": "Plant_Leaves_Azure",
      "support": 3,
      "rotation": 2
    },
    {
      "x": -10,
      "y": 21,
      "z": 4,
      "name": "Plant_Leaves_Azure",
      "support": 2,
      "rotation": 2
    },
    {
      "x": -10,
      "y": 11,
      "z": 5,
      "name": "Plant_Moss_Block_Blue",
      "support": 15
    },
    {
      "x": -10,
      "y": 12,
      "z": 5,
      "name": "Soil_Grass"
    },
    {
      "x": -10,
      "y": 13,
      "z": 5,
      "name": "Soil_Grass"
    },
    {
      "x": -10,
      "y": 21,
      "z": 5,
      "name": "Plant_Leaves_Azure",
      "support": 1,
      "rotation": 2
    },
    {
      "x": -10,
      "y": 22,
      "z": 5,
      "name": "Plant_Leaves_Azure",
      "support": 2,
      "rotation": 2
    },
    {
      "x": -10,
      "y": 25,
      "z": 5,
      "name": "Plant_Leaves_Azure",
      "rotation": 2
    },
    {
      "x": -10,
      "y": 10,
      "z": 6,
      "name": "Plant_Moss_Cave_Blue",
      "support": 15,
      "rotation": 8
    },
    {
      "x": -10,
      "y": 11,
      "z": 6,
      "name": "Soil_Grass"
    },
    {
      "x": -10,
      "y": 12,
      "z": 6,
      "name": "Soil_Grass"
    },
    {
      "x": -10,
      "y": 13,
      "z": 6,
      "name": "Plant_Moss_Blue",
      "support": 15
    },
    {
      "x": -10,
      "y": 21,
      "z": 6,
      "name": "Plant_Leaves_Azure",
      "rotation": 2
    },
    {
      "x": -10,
      "y": 22,
      "z": 6,
      "name": "Plant_Leaves_Azure",
      "support": 1,
      "rotation": 2
    },
    {
      "x": -10,
      "y": 11,
      "z": 7,
      "name": "Soil_Grass"
    },
    {
      "x": -10,
      "y": 17,
      "z": 7,
      "name": "Wood_Azure_Branch_Long",
      "rotation": 7
    },
    {
      "x": -10,
      "y": 19,
      "z": 7,
      "name": "Plant_Moss_Wall_Blue",
      "rotation": 3
    },
    {
      "x": -10,
      "y": 22,
      "z": 7,
      "name": "Plant_Leaves_Azure",
      "support": 2,
      "rotation": 2
    },
    {
      "x": -10,
      "y": 23,
      "z": 7,
      "name": "Plant_Leaves_Azure",
      "support": 3,
      "rotation": 2
    },
    {
      "x": -10,
      "y": 11,
      "z": 8,
      "name": "Soil_Grass"
    },
    {
      "x": -10,
      "y": 23,
      "z": 8,
      "name": "Plant_Leaves_Azure",
      "support": 2,
      "rotation": 2
    },
    {
      "x": -10,
      "y": 24,
      "z": 8,
      "name": "Plant_Leaves_Azure",
      "support": 1,
      "rotation": 2
    },
    {
      "x": -10,
      "y": 11,
      "z": 9,
      "name": "Soil_Grass"
    },
    {
      "x": -10,
      "y": 12,
      "z": 9,
      "name": "Plant_Moss_Rug_Blue",
      "support": 15
    },
    {
      "x": -10,
      "y": 22,
      "z": 9,
      "name": "Plant_Leaves_Azure",
      "support": 4,
      "rotation": 2
    },
    {
      "x": -10,
      "y": 23,
      "z": 9,
      "name": "Plant_Leaves_Azure",
      "support": 3,
      "rotation": 2
    },
    {
      "x": -10,
      "y": 24,
      "z": 9,
      "name": "Plant_Leaves_Azure",
      "support": 2,
      "rotation": 2
    },
    {
      "x": -10,
      "y": 25,
      "z": 9,
      "name": "Plant_Leaves_Azure",
      "support": 3,
      "rotation": 2
    },
    {
      "x": -10,
      "y": 18,
      "z": 10,
      "name": "Plant_Leaves_Azure",
      "support": 2,
      "rotation": 2
    },
    {
      "x": -10,
      "y": 19,
      "z": 10,
      "name": "Plant_Leaves_Azure",
      "support": 1,
      "rotation": 2
    },
    {
      "x": -10,
      "y": 20,
      "z": 10,
      "name": "Plant_Leaves_Azure",
      "support": 2,
      "rotation": 2
    },
    {
      "x": -10,
      "y": 23,
      "z": 10,
      "name": "Plant_Leaves_Azure",
      "support": 4,
      "rotation": 2
    },
    {
      "x": -10,
      "y": 24,
      "z": 10,
      "name": "Plant_Leaves_Azure",
      "support": 3,
      "rotation": 2
    },
    {
      "x": -10,
      "y": 25,
      "z": 10,
      "name": "Plant_Leaves_Azure",
      "support": 4,
      "rotation": 2
    },
    {
      "x": -10,
      "y": 17,
      "z": 11,
      "name": "Plant_Leaves_Azure",
      "support": 3,
      "rotation": 2
    },
    {
      "x": -10,
      "y": 18,
      "z": 11,
      "name": "Plant_Leaves_Azure",
      "support": 2,
      "rotation": 2
    },
    {
      "x": -10,
      "y": 19,
      "z": 11,
      "name": "Plant_Leaves_Azure",
      "support": 1,
      "rotation": 2
    },
    {
      "x": -10,
      "y": 20,
      "z": 11,
      "name": "Plant_Leaves_Azure",
      "support": 2,
      "rotation": 2
    },
    {
      "x": -10,
      "y": 21,
      "z": 11,
      "name": "Plant_Fruit_Azure",
      "rotation": 2
    },
    {
      "x": -10,
      "y": 17,
      "z": 12,
      "name": "Plant_Leaves_Azure",
      "support": 4,
      "rotation": 2
    },
    {
      "x": -10,
      "y": 18,
      "z": 12,
      "name": "Plant_Leaves_Azure",
      "support": 3,
      "rotation": 2
    },
    {
      "x": -10,
      "y": 19,
      "z": 12,
      "name": "Plant_Leaves_Azure",
      "support": 2,
      "rotation": 2
    },
    {
      "x": -10,
      "y": 20,
      "z": 12,
      "name": "Plant_Leaves_Azure",
      "support": 3,
      "rotation": 2
    },
    {
      "x": -10,
      "y": 18,
      "z": 13,
      "name": "Plant_Leaves_Azure",
      "support": 4,
      "rotation": 2
    },
    {
      "x": -10,
      "y": 19,
      "z": 13,
      "name": "Plant_Leaves_Azure",
      "support": 3,
      "rotation": 2
    },
    {
      "x": -9,
      "y": 10,
      "z": -1,
      "name": "Soil_Grass"
    },
    {
      "x": -9,
      "y": 11,
      "z": -1,
      "name": "Plant_Moss_Cave_Blue",
      "support": 15
    },
    {
      "x": -9,
      "y": 10,
      "z": 0,
      "name": "Plant_Moss_Block_Blue",
      "support": 15
    },
    {
      "x": -9,
      "y": 11,
      "z": 0,
      "name": "Soil_Grass"
    },
    {
      "x": -9,
      "y": 10,
      "z": 1,
      "name": "Plant_Moss_Block_Blue",
      "support": 15
    },
    {
      "x": -9,
      "y": 11,
      "z": 1,
      "name": "Soil_Grass"
    },
    {
      "x": -9,
      "y": 9,
      "z": 2,
      "name": "Plant_Moss_Block_Blue",
      "support": 15
    },
    {
      "x": -9,
      "y": 10,
      "z": 2,
      "name": "Plant_Moss_Block_Blue",
      "support": 15
    },
    {
      "x": -9,
      "y": 11,
      "z": 2,
      "name": "Soil_Grass"
    },
    {
      "x": -9,
      "y": 12,
      "z": 2,
      "name": "Plant_Moss_Rug_Blue",
      "support": 15
    },
    {
      "x": -9,
      "y": 17,
      "z": 2,
      "name": "Plant_Leaves_Azure",
      "support": 1,
      "rotation": 2
    },
    {
      "x": -9,
      "y": 18,
      "z": 2,
      "name": "Plant_Leaves_Azure",
      "support": 2,
      "rotation": 2
    },
    {
      "x": -9,
      "y": 19,
      "z": 2,
      "name": "Plant_Leaves_Azure",
      "support": 3,
      "rotation": 2
    },
    {
      "x": -9,
      "y": 20,
      "z": 2,
      "name": "Plant_Leaves_Azure",
      "support": 4,
      "rotation": 2
    },
    {
      "x": -9,
      "y": 21,
      "z": 2,
      "name": "Plant_Fruit_Azure",
      "rotation": 2
    },
    {
      "x": -9,
      "y": 9,
      "z": 3,
      "name": "Rock_Crystal_Blue_Medium",
      "rotation": 8
    },
    {
      "x": -9,
      "y": 10,
      "z": 3,
      "name": "Plant_Moss_Block_Blue",
      "support": 15
    },
    {
      "x": -9,
      "y": 11,
      "z": 3,
      "name": "Wood_Azure_Trunk_Full",
      "rotation": 2
    },
    {
      "x": -9,
      "y": 12,
      "z": 3,
      "name": "Soil_Grass"
    },
    {
      "x": -9,
      "y": 18,
      "z": 3,
      "name": "Plant_Leaves_Azure",
      "support": 3,
      "rotation": 2
    },
    {
      "x": -9,
      "y": 19,
      "z": 3,
      "name": "Plant_Leaves_Azure",
      "support": 4,
      "rotation": 2
    },
    {
      "x": -9,
      "y": 10,
      "z": 4,
      "name": "Plant_Moss_Block_Blue",
      "support": 15
    },
    {
      "x": -9,
      "y": 11,
      "z": 4,
      "name": "Wood_Azure_Trunk",
      "rotation": 2
    },
    {
      "x": -9,
      "y": 12,
      "z": 4,
      "name": "Wood_Azure_Trunk_Full",
      "rotation": 2
    },
    {
      "x": -9,
      "y": 13,
      "z": 4,
      "name": "Soil_Grass"
    },
    {
      "x": -9,
      "y": 14,
      "z": 4,
      "name": "Plant_Moss_Blue",
      "support": 15
    },
    {
      "x": -9,
      "y": 20,
      "z": 4,
      "name": "Plant_Leaves_Azure",
      "support": 4,
      "rotation": 2
    },
    {
      "x": -9,
      "y": 24,
      "z": 4,
      "name": "Plant_Leaves_Azure",
      "rotation": 2
    },
    {
      "x": -9,
      "y": 25,
      "z": 4,
      "name": "Plant_Leaves_Azure",
      "rotation": 2
    },
    {
      "x": -9,
      "y": 10,
      "z": 5,
      "name": "Plant_Moss_Block_Blue",
      "support": 15
    },
    {
      "x": -9,
      "y": 11,
      "z": 5,
      "name": "Wood_Azure_Trunk_Full",
      "rotation": 2
    },
    {
      "x": -9,
      "y": 12,
      "z": 5,
      "name": "Wood_Azure_Trunk",
      "rotation": 2
    },
    {
      "x": -9,
      "y": 13,
      "z": 5,
      "name": "Wood_Azure_Trunk",
      "rotation": 2
    },
    {
      "x": -9,
      "y": 14,
      "z": 5,
      "name": "Wood_Azure_Trunk_Full",
      "rotation": 2
    },
    {
      "x": -9,
      "y": 24,
      "z": 5,
      "name": "Plant_Leaves_Azure",
      "rotation": 2
    },
    {
      "x": -9,
      "y": 25,
      "z": 5,
      "name": "Plant_Leaves_Azure",
      "rotation": 2
    },
    {
      "x": -9,
      "y": 26,
      "z": 5,
      "name": "Plant_Fruit_Azure",
      "rotation": 2
    },
    {
      "x": -9,
      "y": 28,
      "z": 5,
      "name": "Plant_Leaves_Azure",
      "support": 3,
      "rotation": 2
    },
    {
      "x": -9,
      "y": 9,
      "z": 6,
      "name": "Plant_Moss_Block_Blue",
      "support": 15
    },
    {
      "x": -9,
      "y": 10,
      "z": 6,
      "name": "Plant_Moss_Block_Blue",
      "support": 15
    },
    {
      "x": -9,
      "y": 11,
      "z": 6,
      "name": "Plant_Moss_Block_Blue",
      "support": 15
    },
    {
      "x": -9,
      "y": 12,
      "z": 6,
      "name": "Plant_Moss_Block_Blue",
      "support": 15
    },
    {
      "x": -9,
      "y": 13,
      "z": 6,
      "name": "Soil_Grass"
    },
    {
      "x": -9,
      "y": 14,
      "z": 6,
      "name": "Wood_Azure_Trunk_Full",
      "rotation": 2
    },
    {
      "x": -9,
      "y": 15,
      "z": 6,
      "name": "Wood_Azure_Trunk",
      "rotation": 2
    },
    {
      "x": -9,
      "y": 16,
      "z": 6,
      "name": "Wood_Azure_Trunk",
      "rotation": 2
    },
    {
      "x": -9,
      "y": 17,
      "z": 6,
      "name": "Wood_Azure_Trunk_Full",
      "rotation": 2
    },
    {
      "x": -9,
      "y": 19,
      "z": 6,
      "name": "Plant_Moss_Wall_Blue",
      "rotation": 2
    },
    {
      "x": -9,
      "y": 21,
      "z": 6,
      "name": "Wood_Azure_Branch_Long",
      "rotation": 7
    },
    {
      "x": -9,
      "y": 22,
      "z": 6,
      "name": "Plant_Moss_Wall_Blue",
      "rotation": 3
    },
    {
      "x": -9,
      "y": 25,
      "z": 6,
      "name": "Plant_Leaves_Azure",
      "rotation": 2
    },
    {
      "x": -9,
      "y": 28,
      "z": 6,
      "name": "Plant_Leaves_Azure",
      "support": 2,
      "rotation": 2
    },
    {
      "x": -9,
      "y": 29,
      "z": 6,
      "name": "Plant_Leaves_Azure",
      "support": 2,
      "rotation": 2
    },
    {
      "x": -9,
      "y": 10,
      "z": 7,
      "name": "Plant_Moss_Block_Blue",
      "support": 15
    },
    {
      "x": -9,
      "y": 11,
      "z": 7,
      "name": "Plant_Moss_Block_Blue",
      "support": 15
    },
    {
      "x": -9,
      "y": 12,
      "z": 7,
      "name": "Plant_Moss_Block_Blue",
      "support": 15
    },
    {
      "x": -9,
      "y": 13,
      "z": 7,
      "name": "Soil_Grass"
    },
    {
      "x": -9,
      "y": 14,
      "z": 7,
      "name": "Plant_Moss_Rug_Blue",
      "support": 15
    },
    {
      "x": -9,
      "y": 16,
      "z": 7,
      "name": "Wood_Azure_Trunk_Full",
      "support": 1,
      "rotation": 2
    },
    {
      "x": -9,
      "y": 17,
      "z": 7,
      "name": "Wood_Azure_Trunk",
      "rotation": 2
    },
    {
      "x": -9,
      "y": 18,
      "z": 7,
      "name": "Wood_Azure_Trunk",
      "rotation": 2
    },
    {
      "x": -9,
      "y": 19,
      "z": 7,
      "name": "Wood_Azure_Trunk_Full",
      "rotation": 2
    },
    {
      "x": -9,
      "y": 20,
      "z": 7,
      "name": "Plant_Moss_Rug_Blue",
      "rotation": 2
    },
    {
      "x": -9,
      "y": 28,
      "z": 7,
      "name": "Plant_Leaves_Azure",
      "support": 2,
      "rotation": 2
    },
    {
      "x": -9,
      "y": 29,
      "z": 7,
      "name": "Plant_Leaves_Azure",
      "support": 1,
      "rotation": 2
    },
    {
      "x": -9,
      "y": 30,
      "z": 7,
      "name": "Plant_Leaves_Azure",
      "support": 1,
      "rotation": 2
    },
    {
      "x": -9,
      "y": 10,
      "z": 8,
      "name": "Plant_Moss_Block_Blue",
      "support": 15
    },
    {
      "x": -9,
      "y": 11,
      "z": 8,
      "name": "Plant_Moss_Block_Blue",
      "support": 15
    },
    {
      "x": -9,
      "y": 12,
      "z": 8,
      "name": "Soil_Grass"
    },
    {
      "x": -9,
      "y": 19,
      "z": 8,
      "name": "Plant_Moss_Wall_Blue"
    },
    {
      "x": -9,
      "y": 24,
      "z": 8,
      "name": "Plant_Leaves_Azure",
      "rotation": 2
    },
    {
      "x": -9,
      "y": 30,
      "z": 8,
      "name": "Plant_Leaves_Azure",
      "support": 2,
      "rotation": 2
    },
    {
      "x": -9,
      "y": 10,
      "z": 9,
      "name": "Rock_Crystal_Blue_Small",
      "rotation": 8
    },
    {
      "x": -9,
      "y": 11,
      "z": 9,
      "name": "Plant_Moss_Block_Blue",
      "support": 15
    },
    {
      "x": -9,
      "y": 12,
      "z": 9,
      "name": "Soil_Grass"
    },
    {
      "x": -9,
      "y": 23,
      "z": 9,
      "name": "Plant_Leaves_Azure",
      "support": 2,
      "rotation": 2
    },
    {
      "x": -9,
      "y": 24,
      "z": 9,
      "name": "Plant_Leaves_Azure",
      "support": 1,
      "rotation": 2
    },
    {
      "x": -9,
      "y": 25,
      "z": 9,
      "name": "Plant_Leaves_Azure",
      "support": 2,
      "rotation": 2
    },
    {
      "x": -9,
      "y": 26,
      "z": 9,
      "name": "Plant_Fruit_Azure",
      "rotation": 2
    },
    {
      "x": -9,
      "y": 11,
      "z": 10,
      "name": "Soil_Grass"
    },
    {
      "x": -9,
      "y": 19,
      "z": 10,
      "name": "Plant_Leaves_Azure",
      "rotation": 2
    },
    {
      "x": -9,
      "y": 20,
      "z": 10,
      "name": "Plant_Leaves_Azure",
      "support": 1,
      "rotation": 2
    },
    {
      "x": -9,
      "y": 24,
      "z": 10,
      "name": "Plant_Leaves_Azure",
      "support": 2,
      "rotation": 2
    },
    {
      "x": -9,
      "y": 25,
      "z": 10,
      "name": "Plant_Leaves_Azure",
      "support": 3,
      "rotation": 2
    },
    {
      "x": -9,
      "y": 26,
      "z": 10,
      "name": "Plant_Leaves_Azure",
      "support": 3,
      "rotation": 2
    },
    {
      "x": -9,
      "y": 18,
      "z": 11,
      "name": "Plant_Leaves_Azure",
      "support": 1,
      "rotation": 2
    },
    {
      "x": -9,
      "y": 19,
      "z": 11,
      "name": "Plant_Leaves_Azure",
      "rotation": 2
    },
    {
      "x": -9,
      "y": 20,
      "z": 11,
      "name": "Plant_Leaves_Azure",
      "support": 1,
      "rotation": 2
    },
    {
      "x": -9,
      "y": 16,
      "z": 12,
      "name": "Plant_Leaves_Azure",
      "support": 4,
      "rotation": 2
    },
    {
      "x": -9,
      "y": 17,
      "z": 12,
      "name": "Plant_Leaves_Azure",
      "support": 3,
      "rotation": 2
    },
    {
      "x": -9,
      "y": 18,
      "z": 12,
      "name": "Plant_Leaves_Azure",
      "support": 2,
      "rotation": 2
    },
    {
      "x": -9,
      "y": 19,
      "z": 12,
      "name": "Plant_Leaves_Azure",
      "support": 1,
      "rotation": 2
    },
    {
      "x": -9,
      "y": 20,
      "z": 12,
      "name": "Plant_Leaves_Azure",
      "support": 2,
      "rotation": 2
    },
    {
      "x": -9,
      "y": 21,
      "z": 12,
      "name": "Plant_Leaves_Azure",
      "support": 2,
      "rotation": 2
    },
    {
      "x": -9,
      "y": 17,
      "z": 13,
      "name": "Plant_Leaves_Azure",
      "support": 4,
      "rotation": 2
    },
    {
      "x": -9,
      "y": 18,
      "z": 13,
      "name": "Plant_Leaves_Azure",
      "support": 3,
      "rotation": 2
    },
    {
      "x": -9,
      "y": 19,
      "z": 13,
      "name": "Plant_Leaves_Azure",
      "support": 2,
      "rotation": 2
    },
    {
      "x": -9,
      "y": 20,
      "z": 13,
      "name": "Plant_Leaves_Azure",
      "support": 3,
      "rotation": 2
    },
    {
      "x": -8,
      "y": 10,
      "z": -3,
      "name": "Soil_Grass"
    },
    {
      "x": -8,
      "y": 11,
      "z": -3,
      "name": "Plant_Moss_Rug_Blue",
      "support": 15
    },
    {
      "x": -8,
      "y": 10,
      "z": -2,
      "name": "Soil_Grass"
    },
    {
      "x": -8,
      "y": 10,
      "z": -1,
      "name": "Soil_Grass"
    },
    {
      "x": -8,
      "y": 9,
      "z": 0,
      "name": "Plant_Moss_Block_Blue",
      "support": 15
    },
    {
      "x": -8,
      "y": 10,
      "z": 0,
      "name": "Plant_Moss_Block_Blue",
      "support": 15
    },
    {
      "x": -8,
      "y": 11,
      "z": 0,
      "name": "Soil_Grass"
    },
    {
      "x": -8,
      "y": 12,
      "z": 0,
      "name": "Plant_Moss_Rug_Blue",
      "support": 15
    },
    {
      "x": -8,
      "y": 9,
      "z": 1,
      "name": "Plant_Moss_Block_Blue",
      "support": 15
    },
    {
      "x": -8,
      "y": 10,
      "z": 1,
      "name": "Plant_Moss_Block_Blue",
      "support": 15
    },
    {
      "x": -8,
      "y": 11,
      "z": 1,
      "name": "Soil_Grass"
    },
    {
      "x": -8,
      "y": 12,
      "z": 1,
      "name": "Plant_Moss_Rug_Blue",
      "support": 15
    },
    {
      "x": -8,
      "y": 17,
      "z": 1,
      "name": "Plant_Leaves_Azure",
      "support": 1,
      "rotation": 2
    },
    {
      "x": -8,
      "y": 9,
      "z": 2,
      "name": "Plant_Moss_Block_Blue",
      "support": 15
    },
    {
      "x": -8,
      "y": 10,
      "z": 2,
      "name": "Plant_Moss_Block_Blue",
      "support": 15
    },
    {
      "x": -8,
      "y": 11,
      "z": 2,
      "name": "Plant_Moss_Block_Blue",
      "support": 15
    },
    {
      "x": -8,
      "y": 12,
      "z": 2,
      "name": "Soil_Grass"
    },
    {
      "x": -8,
      "y": 13,
      "z": 2,
      "name": "Plant_Moss_Rug_Blue",
      "support": 15
    },
    {
      "x": -8,
      "y": 16,
      "z": 2,
      "name": "Plant_Leaves_Azure",
      "support": 1,
      "rotation": 2
    },
    {
      "x": -8,
      "y": 17,
      "z": 2,
      "name": "Plant_Leaves_Azure",
      "rotation": 2
    },
    {
      "x": -8,
      "y": 18,
      "z": 2,
      "name": "Plant_Leaves_Azure",
      "support": 1,
      "rotation": 2
    },
    {
      "x": -8,
      "y": 19,
      "z": 2,
      "name": "Plant_Leaves_Azure",
      "support": 2,
      "rotation": 2
    },
    {
      "x": -8,
      "y": 9,
      "z": 3,
      "name": "Plant_Moss_Block_Blue",
      "support": 15
    },
    {
      "x": -8,
      "y": 10,
      "z": 3,
      "name": "Plant_Moss_Block_Blue",
      "support": 15
    },
    {
      "x": -8,
      "y": 11,
      "z": 3,
      "name": "Plant_Moss_Block_Blue",
      "support": 15
    },
    {
      "x": -8,
      "y": 12,
      "z": 3,
      "name": "Soil_Grass"
    },
    {
      "x": -8,
      "y": 13,
      "z": 3,
      "name": "Soil_Grass"
    },
    {
      "x": -8,
      "y": 16,
      "z": 3,
      "name": "Plant_Leaves_Azure",
      "rotation": 2
    },
    {
      "x": -8,
      "y": 17,
      "z": 3,
      "name": "Wood_Azure_Branch_Long",
      "support": 1,
      "rotation": 6
    },
    {
      "x": -8,
      "y": 19,
      "z": 3,
      "name": "Plant_Leaves_Azure",
      "support": 3,
      "rotation": 2
    },
    {
      "x": -8,
      "y": 22,
      "z": 3,
      "name": "Plant_Leaves_Azure",
      "rotation": 2
    },
    {
      "x": -8,
      "y": 23,
      "z": 3,
      "name": "Plant_Leaves_Azure",
      "rotation": 2
    },
    {
      "x": -8,
      "y": 24,
      "z": 3,
      "name": "Plant_Leaves_Azure",
      "rotation": 2
    },
    {
      "x": -8,
      "y": 9,
      "z": 4,
      "name": "Plant_Moss_Block_Blue",
      "support": 15
    },
    {
      "x": -8,
      "y": 10,
      "z": 4,
      "name": "Plant_Moss_Block_Blue",
      "support": 15
    },
    {
      "x": -8,
      "y": 11,
      "z": 4,
      "name": "Wood_Azure_Trunk_Full",
      "rotation": 2
    },
    {
      "x": -8,
      "y": 12,
      "z": 4,
      "name": "Wood_Azure_Trunk",
      "rotation": 2
    },
    {
      "x": -8,
      "y": 13,
      "z": 4,
      "name": "Wood_Azure_Trunk_Full",
      "rotation": 2
    },
    {
      "x": -8,
      "y": 14,
      "z": 4,
      "name": "Soil_Grass"
    },
    {
      "x": -8,
      "y": 17,
      "z": 4,
      "name": "Wood_Azure_Branch_Long",
      "rotation": 6
    },
    {
      "x": -8,
      "y": 23,
      "z": 4,
      "name": "Plant_Leaves_Azure",
      "rotation": 2
    },
    {
      "x": -8,
      "y": 24,
      "z": 4,
      "name": "Wood_Azure_Branch_Long",
      "rotation": 6
    },
    {
      "x": -8,
      "y": 25,
      "z": 4,
      "name": "Plant_Leaves_Azure",
      "rotation": 2
    },
    {
      "x": -8,
      "y": 9,
      "z": 5,
      "name": "Plant_Moss_Block_Blue",
      "support": 15
    },
    {
      "x": -8,
      "y": 10,
      "z": 5,
      "name": "Plant_Moss_Block_Blue",
      "support": 15
    },
    {
      "x": -8,
      "y": 11,
      "z": 5,
      "name": "Wood_Azure_Trunk_Full",
      "rotation": 2
    },
    {
      "x": -8,
      "y": 12,
      "z": 5,
      "name": "Wood_Azure_Trunk",
      "rotation": 2
    },
    {
      "x": -8,
      "y": 13,
      "z": 5,
      "name": "Wood_Azure_Trunk",
      "rotation": 2
    },
    {
      "x": -8,
      "y": 14,
      "z": 5,
      "name": "Wood_Azure_Trunk",
      "rotation": 2
    },
    {
      "x": -8,
      "y": 15,
      "z": 5,
      "name": "Wood_Azure_Trunk",
      "rotation": 2
    },
    {
      "x": -8,
      "y": 16,
      "z": 5,
      "name": "Wood_Azure_Trunk",
      "rotation": 2
    },
    {
      "x": -8,
      "y": 17,
      "z": 5,
      "name": "Wood_Azure_Trunk",
      "rotation": 2
    },
    {
      "x": -8,
      "y": 18,
      "z": 5,
      "name": "Wood_Azure_Trunk_Full",
      "rotation": 2
    },
    {
      "x": -8,
      "y": 22,
      "z": 5,
      "name": "Plant_Moss_Wall_Blue",
      "rotation": 2
    },
    {
      "x": -8,
      "y": 24,
      "z": 5,
      "name": "Wood_Azure_Branch_Long",
      "rotation": 6
    },
    {
      "x": -8,
      "y": 27,
      "z": 5,
      "name": "Plant_Leaves_Azure",
      "support": 1,
      "rotation": 2
    },
    {
      "x": -8,
      "y": 28,
      "z": 5,
      "name": "Plant_Leaves_Azure",
      "support": 2,
      "rotation": 2
    },
    {
      "x": -8,
      "y": 29,
      "z": 5,
      "name": "Plant_Leaves_Azure",
      "support": 2,
      "rotation": 2
    },
    {
      "x": -8,
      "y": 9,
      "z": 6,
      "name": "Plant_Moss_Block_Blue",
      "support": 15
    },
    {
      "x": -8,
      "y": 10,
      "z": 6,
      "name": "Plant_Moss_Block_Blue",
      "support": 15
    },
    {
      "x": -8,
      "y": 11,
      "z": 6,
      "name": "Plant_Moss_Block_Blue",
      "support": 15
    },
    {
      "x": -8,
      "y": 12,
      "z": 6,
      "name": "Wood_Azure_Trunk",
      "rotation": 2
    },
    {
      "x": -8,
      "y": 13,
      "z": 6,
      "name": "Wood_Azure_Trunk",
      "rotation": 2
    },
    {
      "x": -8,
      "y": 14,
      "z": 6,
      "name": "Wood_Azure_Trunk",
      "rotation": 2
    },
    {
      "x": -8,
      "y": 15,
      "z": 6,
      "name": "Wood_Azure_Trunk",
      "rotation": 2
    },
    {
      "x": -8,
      "y": 16,
      "z": 6,
      "name": "Wood_Azure_Trunk",
      "rotation": 2
    },
    {
      "x": -8,
      "y": 17,
      "z": 6,
      "name": "Wood_Azure_Trunk",
      "rotation": 2
    },
    {
      "x": -8,
      "y": 18,
      "z": 6,
      "name": "Wood_Azure_Trunk",
      "rotation": 2
    },
    {
      "x": -8,
      "y": 19,
      "z": 6,
      "name": "Wood_Azure_Trunk",
      "rotation": 2
    },
    {
      "x": -8,
      "y": 20,
      "z": 6,
      "name": "Wood_Azure_Trunk",
      "rotation": 2
    },
    {
      "x": -8,
      "y": 21,
      "z": 6,
      "name": "Wood_Azure_Trunk",
      "rotation": 2
    },
    {
      "x": -8,
      "y": 22,
      "z": 6,
      "name": "Wood_Azure_Trunk_Full",
      "rotation": 2
    },
    {
      "x": -8,
      "y": 23,
      "z": 6,
      "name": "Plant_Moss_Rug_Blue",
      "rotation": 2
    },
    {
      "x": -8,
      "y": 24,
      "z": 6,
      "name": "Wood_Azure_Branch_Long",
      "rotation": 6
    },
    {
      "x": -8,
      "y": 27,
      "z": 6,
      "name": "Plant_Leaves_Azure",
      "rotation": 2
    },
    {
      "x": -8,
      "y": 28,
      "z": 6,
      "name": "Plant_Leaves_Azure",
      "support": 1,
      "rotation": 2
    },
    {
      "x": -8,
      "y": 29,
      "z": 6,
      "name": "Plant_Leaves_Azure",
      "support": 1,
      "rotation": 2
    },
    {
      "x": -8,
      "y": 30,
      "z": 6,
      "name": "Plant_Leaves_Azure",
      "support": 1,
      "rotation": 2
    },
    {
      "x": -8,
      "y": 9,
      "z": 7,
      "name": "Plant_Moss_Block_Blue",
      "support": 15
    },
    {
      "x": -8,
      "y": 10,
      "z": 7,
      "name": "Plant_Moss_Block_Blue",
      "support": 15
    },
    {
      "x": -8,
      "y": 11,
      "z": 7,
      "name": "Wood_Azure_Trunk_Full",
      "rotation": 2
    },
    {
      "x": -8,
      "y": 12,
      "z": 7,
      "name": "Wood_Azure_Trunk",
      "rotation": 2
    },
    {
      "x": -8,
      "y": 13,
      "z": 7,
      "name": "Wood_Azure_Trunk",
      "rotation": 2
    },
    {
      "x": -8,
      "y": 14,
      "z": 7,
      "name": "Wood_Azure_Trunk",
      "rotation": 2
    },
    {
      "x": -8,
      "y": 15,
      "z": 7,
      "name": "Wood_Azure_Trunk",
      "rotation": 2
    },
    {
      "x": -8,
      "y": 16,
      "z": 7,
      "name": "Wood_Azure_Trunk",
      "rotation": 2
    },
    {
      "x": -8,
      "y": 17,
      "z": 7,
      "name": "Wood_Azure_Trunk",
      "rotation": 2
    },
    {
      "x": -8,
      "y": 18,
      "z": 7,
      "name": "Wood_Azure_Trunk",
      "rotation": 2
    },
    {
      "x": -8,
      "y": 19,
      "z": 7,
      "name": "Wood_Azure_Trunk",
      "rotation": 2
    },
    {
      "x": -8,
      "y": 20,
      "z": 7,
      "name": "Wood_Azure_Trunk",
      "rotation": 2
    },
    {
      "x": -8,
      "y": 21,
      "z": 7,
      "name": "Wood_Azure_Trunk",
      "rotation": 2
    },
    {
      "x": -8,
      "y": 22,
      "z": 7,
      "name": "Wood_Azure_Trunk",
      "rotation": 2
    },
    {
      "x": -8,
      "y": 23,
      "z": 7,
      "name": "Wood_Azure_Trunk",
      "rotation": 2
    },
    {
      "x": -8,
      "y": 24,
      "z": 7,
      "name": "Wood_Azure_Trunk_Full",
      "rotation": 2
    },
    {
      "x": -8,
      "y": 27,
      "z": 7,
      "name": "Plant_Moss_Wall_Blue",
      "rotation": 3
    },
    {
      "x": -8,
      "y": 29,
      "z": 7,
      "name": "Plant_Leaves_Azure",
      "rotation": 2
    },
    {
      "x": -8,
      "y": 30,
      "z": 7,
      "name": "Plant_Leaves_Azure",
      "rotation": 2
    },
    {
      "x": -8,
      "y": 31,
      "z": 7,
      "name": "Plant_Leaves_Azure",
      "support": 1,
      "rotation": 2
    },
    {
      "x": -8,
      "y": 32,
      "z": 7,
      "name": "Plant_Fruit_Azure",
      "rotation": 2
    },
    {
      "x": -8,
      "y": 10,
      "z": 8,
      "name": "Plant_Moss_Block_Blue",
      "support": 15
    },
    {
      "x": -8,
      "y": 11,
      "z": 8,
      "name": "Wood_Azure_Trunk_Full",
      "rotation": 2
    },
    {
      "x": -8,
      "y": 12,
      "z": 8,
      "name": "Wood_Azure_Trunk",
      "rotation": 2
    },
    {
      "x": -8,
      "y": 13,
      "z": 8,
      "name": "Wood_Azure_Trunk_Full",
      "rotation": 2
    },
    {
      "x": -8,
      "y": 16,
      "z": 8,
      "name": "Plant_Moss_Wall_Blue",
      "support": 15
    },
    {
      "x": -8,
      "y": 19,
      "z": 8,
      "name": "Wood_Azure_Trunk_Full",
      "rotation": 2
    },
    {
      "x": -8,
      "y": 20,
      "z": 8,
      "name": "Wood_Azure_Trunk",
      "rotation": 2
    },
    {
      "x": -8,
      "y": 21,
      "z": 8,
      "name": "Wood_Azure_Trunk_Full",
      "rotation": 2
    },
    {
      "x": -8,
      "y": 24,
      "z": 8,
      "name": "Wood_Azure_Branch_Long",
      "rotation": 6
    },
    {
      "x": -8,
      "y": 29,
      "z": 8,
      "name": "Plant_Leaves_Azure",
      "support": 1,
      "rotation": 2
    },
    {
      "x": -8,
      "y": 30,
      "z": 8,
      "name": "Plant_Leaves_Azure",
      "support": 1,
      "rotation": 2
    },
    {
      "x": -8,
      "y": 31,
      "z": 8,
      "name": "Plant_Leaves_Azure",
      "support": 2,
      "rotation": 2
    },
    {
      "x": -8,
      "y": 32,
      "z": 8,
      "name": "Plant_Leaves_Azure",
      "support": 3,
      "rotation": 2
    },
    {
      "x": -8,
      "y": 9,
      "z": 9,
      "name": "Rock_Crystal_Blue_Medium",
      "rotation": 8
    },
    {
      "x": -8,
      "y": 10,
      "z": 9,
      "name": "Plant_Moss_Block_Blue",
      "support": 15
    },
    {
      "x": -8,
      "y": 11,
      "z": 9,
      "name": "Plant_Moss_Block_Blue",
      "support": 15
    },
    {
      "x": -8,
      "y": 12,
      "z": 9,
      "name": "Soil_Grass"
    },
    {
      "x": -8,
      "y": 19,
      "z": 9,
      "name": "Wood_Azure_Branch_Long",
      "rotation": 6
    },
    {
      "x": -8,
      "y": 24,
      "z": 9,
      "name": "Plant_Leaves_Azure",
      "rotation": 2
    },
    {
      "x": -8,
      "y": 25,
      "z": 9,
      "name": "Plant_Leaves_Azure",
      "support": 1,
      "rotation": 2
    },
    {
      "x": -8,
      "y": 26,
      "z": 9,
      "name": "Plant_Leaves_Azure",
      "support": 1,
      "rotation": 2
    },
    {
      "x": -8,
      "y": 27,
      "z": 9,
      "name": "Plant_Leaves_Azure",
      "support": 2,
      "rotation": 2
    },
    {
      "x": -8,
      "y": 11,
      "z": 10,
      "name": "Plant_Moss_Block_Blue",
      "support": 15
    },
    {
      "x": -8,
      "y": 12,
      "z": 10,
      "name": "Soil_Grass"
    },
    {
      "x": -8,
      "y": 13,
      "z": 10,
      "name": "Plant_Moss_Rug_Blue",
      "support": 15
    },
    {
      "x": -8,
      "y": 19,
      "z": 10,
      "name": "Wood_Azure_Branch_Long",
      "support": 1,
      "rotation": 6
    },
    {
      "x": -8,
      "y": 25,
      "z": 10,
      "name": "Plant_Leaves_Azure",
      "support": 2,
      "rotation": 2
    },
    {
      "x": -8,
      "y": 26,
      "z": 10,
      "name": "Plant_Leaves_Azure",
      "support": 2,
      "rotation": 2
    },
    {
      "x": -8,
      "y": 27,
      "z": 10,
      "name": "Plant_Leaves_Azure",
      "support": 3,
      "rotation": 2
    },
    {
      "x": -8,
      "y": 11,
      "z": 11,
      "name": "Soil_Grass"
    },
    {
      "x": -8,
      "y": 12,
      "z": 11,
      "name": "Plant_Moss_Rug_Blue",
      "support": 15
    },
    {
      "x": -8,
      "y": 18,
      "z": 11,
      "name": "Plant_Leaves_Azure",
      "rotation": 2
    },
    {
      "x": -8,
      "y": 19,
      "z": 11,
      "name": "Wood_Azure_Branch_Long",
      "support": 2,
      "rotation": 6
    },
    {
      "x": -8,
      "y": 20,
      "z": 11,
      "name": "Plant_Leaves_Azure",
      "rotation": 2
    },
    {
      "x": -8,
      "y": 21,
      "z": 11,
      "name": "Plant_Leaves_Azure",
      "rotation": 2
    },
    {
      "x": -8,
      "y": 17,
      "z": 12,
      "name": "Plant_Leaves_Azure",
      "support": 2,
      "rotation": 2
    },
    {
      "x": -8,
      "y": 18,
      "z": 12,
      "name": "Plant_Leaves_Azure",
      "support": 1,
      "rotation": 2
    },
    {
      "x": -8,
      "y": 19,
      "z": 12,
      "name": "Plant_Leaves_Azure",
      "rotation": 2
    },
    {
      "x": -8,
      "y": 20,
      "z": 12,
      "name": "Plant_Leaves_Azure",
      "support": 1,
      "rotation": 2
    },
    {
      "x": -8,
      "y": 21,
      "z": 12,
      "name": "Plant_Leaves_Azure",
      "support": 1,
      "rotation": 2
    },
    {
      "x": -8,
      "y": 22,
      "z": 12,
      "name": "Plant_Fruit_Azure",
      "rotation": 2
    },
    {
      "x": -8,
      "y": 17,
      "z": 13,
      "name": "Plant_Leaves_Azure",
      "support": 3,
      "rotation": 2
    },
    {
      "x": -8,
      "y": 18,
      "z": 13,
      "name": "Plant_Leaves_Azure",
      "support": 2,
      "rotation": 2
    },
    {
      "x": -8,
      "y": 19,
      "z": 13,
      "name": "Plant_Leaves_Azure",
      "support": 1,
      "rotation": 2
    },
    {
      "x": -8,
      "y": 20,
      "z": 13,
      "name": "Plant_Leaves_Azure",
      "support": 2,
      "rotation": 2
    },
    {
      "x": -7,
      "y": 10,
      "z": -7,
      "name": "Soil_Grass"
    },
    {
      "x": -7,
      "y": 11,
      "z": -7,
      "name": "Plant_Moss_Short_Blue",
      "support": 15
    },
    {
      "x": -7,
      "y": 10,
      "z": -6,
      "name": "Soil_Grass"
    },
    {
      "x": -7,
      "y": 11,
      "z": -6,
      "name": "Plant_Grass_Wet_Wild",
      "support": 15
    },
    {
      "x": -7,
      "y": 12,
      "z": -6,
      "name": "Plant_Grass_Wet_Wild",
      "filler": 1024
    },
    {
      "x": -7,
      "y": 10,
      "z": -5,
      "name": "Soil_Grass"
    },
    {
      "x": -7,
      "y": 9,
      "z": -4,
      "name": "Plant_Moss_Block_Blue",
      "support": 15
    },
    {
      "x": -7,
      "y": 10,
      "z": -4,
      "name": "Soil_Grass"
    },
    {
      "x": -7,
      "y": 10,
      "z": -3,
      "name": "Soil_Grass"
    },
    {
      "x": -7,
      "y": 11,
      "z": -3,
      "name": "Plant_Moss_Rug_Blue",
      "support": 15
    },
    {
      "x": -7,
      "y": 9,
      "z": -2,
      "name": "Plant_Moss_Block_Blue",
      "support": 15
    },
    {
      "x": -7,
      "y": 10,
      "z": -2,
      "name": "Soil_Grass"
    },
    {
      "x": -7,
      "y": 11,
      "z": -2,
      "name": "Plant_Moss_Cave_Blue",
      "support": 15
    },
    {
      "x": -7,
      "y": 8,
      "z": -1,
      "name": "Plant_Moss_Cave_Blue",
      "support": 15,
      "rotation": 8
    },
    {
      "x": -7,
      "y": 9,
      "z": -1,
      "name": "Plant_Moss_Block_Blue",
      "support": 15
    },
    {
      "x": -7,
      "y": 10,
      "z": -1,
      "name": "Plant_Moss_Block_Blue",
      "support": 15
    },
    {
      "x": -7,
      "y": 11,
      "z": -1,
      "name": "Soil_Grass"
    },
    {
      "x": -7,
      "y": 12,
      "z": -1,
      "name": "Plant_Grass_Winter_Tall",
      "support": 15
    },
    {
      "x": -7,
      "y": 13,
      "z": -1,
      "name": "Plant_Grass_Winter_Tall",
      "filler": 1024
    },
    {
      "x": -7,
      "y": 9,
      "z": 0,
      "name": "Plant_Moss_Block_Blue",
      "support": 15
    },
    {
      "x": -7,
      "y": 10,
      "z": 0,
      "name": "Plant_Moss_Block_Blue",
      "support": 15
    },
    {
      "x": -7,
      "y": 11,
      "z": 0,
      "name": "Soil_Grass"
    },
    {
      "x": -7,
      "y": 12,
      "z": 0,
      "name": "Plant_Flower_Orchid_Cyan"
    },
    {
      "x": -7,
      "y": 9,
      "z": 1,
      "name": "Plant_Moss_Block_Blue",
      "support": 15
    },
    {
      "x": -7,
      "y": 10,
      "z": 1,
      "name": "Plant_Moss_Block_Blue",
      "support": 15
    },
    {
      "x": -7,
      "y": 11,
      "z": 1,
      "name": "Plant_Moss_Block_Blue",
      "support": 15
    },
    {
      "x": -7,
      "y": 12,
      "z": 1,
      "name": "Soil_Grass"
    },
    {
      "x": -7,
      "y": 13,
      "z": 1,
      "name": "Plant_Moss_Blue",
      "support": 15
    },
    {
      "x": -7,
      "y": 16,
      "z": 1,
      "name": "Plant_Leaves_Azure",
      "support": 3,
      "rotation": 2
    },
    {
      "x": -7,
      "y": 17,
      "z": 1,
      "name": "Plant_Leaves_Azure",
      "support": 2,
      "rotation": 2
    },
    {
      "x": -7,
      "y": 8,
      "z": 2,
      "name": "Rock_Crystal_Blue_Small",
      "rotation": 8
    },
    {
      "x": -7,
      "y": 9,
      "z": 2,
      "name": "Plant_Moss_Block_Blue",
      "support": 15
    },
    {
      "x": -7,
      "y": 10,
      "z": 2,
      "name": "Plant_Moss_Block_Blue",
      "support": 15
    },
    {
      "x": -7,
      "y": 11,
      "z": 2,
      "name": "Plant_Moss_Block_Blue",
      "support": 15
    },
    {
      "x": -7,
      "y": 12,
      "z": 2,
      "name": "Soil_Grass"
    },
    {
      "x": -7,
      "y": 15,
      "z": 2,
      "name": "Plant_Leaves_Azure",
      "support": 3,
      "rotation": 2
    },
    {
      "x": -7,
      "y": 16,
      "z": 2,
      "name": "Plant_Leaves_Azure",
      "support": 2,
      "rotation": 2
    },
    {
      "x": -7,
      "y": 17,
      "z": 2,
      "name": "Plant_Leaves_Azure",
      "support": 1,
      "rotation": 2
    },
    {
      "x": -7,
      "y": 18,
      "z": 2,
      "name": "Plant_Leaves_Azure",
      "support": 2,
      "rotation": 2
    },
    {
      "x": -7,
      "y": 19,
      "z": 2,
      "name": "Plant_Fruit_Azure",
      "rotation": 2
    },
    {
      "x": -7,
      "y": 22,
      "z": 2,
      "name": "Plant_Leaves_Azure",
      "rotation": 2
    },
    {
      "x": -7,
      "y": 23,
      "z": 2,
      "name": "Plant_Leaves_Azure",
      "rotation": 2
    },
    {
      "x": -7,
      "y": 8,
      "z": 3,
      "name": "Plant_Moss_Block_Blue",
      "support": 15
    },
    {
      "x": -7,
      "y": 9,
      "z": 3,
      "name": "Plant_Moss_Block_Blue",
      "support": 15
    },
    {
      "x": -7,
      "y": 10,
      "z": 3,
      "name": "Plant_Moss_Block_Blue",
      "support": 15
    },
    {
      "x": -7,
      "y": 11,
      "z": 3,
      "name": "Plant_Moss_Block_Blue",
      "support": 15
    },
    {
      "x": -7,
      "y": 12,
      "z": 3,
      "name": "Soil_Grass"
    },
    {
      "x": -7,
      "y": 13,
      "z": 3,
      "name": "Plant_Moss_Cave_Blue",
      "support": 15
    },
    {
      "x": -7,
      "y": 15,
      "z": 3,
      "name": "Plant_Leaves_Azure",
      "support": 2,
      "rotation": 2
    },
    {
      "x": -7,
      "y": 16,
      "z": 3,
      "name": "Plant_Leaves_Azure",
      "support": 1,
      "rotation": 2
    },
    {
      "x": -7,
      "y": 17,
      "z": 3,
      "name": "Plant_Leaves_Azure",
      "rotation": 2
    },
    {
      "x": -7,
      "y": 21,
      "z": 3,
      "name": "Plant_Leaves_Azure",
      "rotation": 2
    },
    {
      "x": -7,
      "y": 22,
      "z": 3,
      "name": "Plant_Leaves_Azure",
      "rotation": 2
    },
    {
      "x": -7,
      "y": 23,
      "z": 3,
      "name": "Plant_Leaves_Azure",
      "rotation": 2
    },
    {
      "x": -7,
      "y": 24,
      "z": 3,
      "name": "Plant_Fruit_Azure",
      "rotation": 2
    },
    {
      "x": -7,
      "y": 8,
      "z": 4,
      "name": "Plant_Moss_Cave_Blue",
      "support": 15,
      "rotation": 8
    },
    {
      "x": -7,
      "y": 9,
      "z": 4,
      "name": "Plant_Moss_Block_Blue",
      "support": 15
    },
    {
      "x": -7,
      "y": 10,
      "z": 4,
      "name": "Plant_Moss_Block_Blue",
      "support": 15
    },
    {
      "x": -7,
      "y": 11,
      "z": 4,
      "name": "Plant_Moss_Block_Blue",
      "support": 15
    },
    {
      "x": -7,
      "y": 12,
      "z": 4,
      "name": "Plant_Moss_Block_Blue",
      "support": 15
    },
    {
      "x": -7,
      "y": 13,
      "z": 4,
      "name": "Soil_Grass"
    },
    {
      "x": -7,
      "y": 14,
      "z": 4,
      "name": "Plant_Flower_Orchid_Cyan"
    },
    {
      "x": -7,
      "y": 21,
      "z": 4,
      "name": "Plant_Leaves_Azure",
      "rotation": 2
    },
    {
      "x": -7,
      "y": 22,
      "z": 4,
      "name": "Plant_Leaves_Azure",
      "rotation": 2
    },
    {
      "x": -7,
      "y": 23,
      "z": 4,
      "name": "Plant_Leaves_Azure",
      "rotation": 2
    },
    {
      "x": -7,
      "y": 27,
      "z": 4,
      "name": "Plant_Leaves_Azure",
      "support": 1,
      "rotation": 2
    },
    {
      "x": -7,
      "y": 28,
      "z": 4,
      "name": "Plant_Leaves_Azure",
      "support": 2,
      "rotation": 2
    },
    {
      "x": -7,
      "y": 8,
      "z": 5,
      "name": "Plant_Moss_Block_Blue",
      "support": 15
    },
    {
      "x": -7,
      "y": 9,
      "z": 5,
      "name": "Plant_Moss_Block_Blue",
      "support": 15
    },
    {
      "x": -7,
      "y": 10,
      "z": 5,
      "name": "Plant_Moss_Block_Blue",
      "support": 15
    },
    {
      "x": -7,
      "y": 11,
      "z": 5,
      "name": "Plant_Moss_Block_Blue",
      "support": 15
    },
    {
      "x": -7,
      "y": 12,
      "z": 5,
      "name": "Wood_Azure_Trunk_Full",
      "rotation": 2
    },
    {
      "x": -7,
      "y": 13,
      "z": 5,
      "name": "Wood_Azure_Trunk",
      "rotation": 2
    },
    {
      "x": -7,
      "y": 14,
      "z": 5,
      "name": "Wood_Azure_Trunk",
      "rotation": 2
    },
    {
      "x": -7,
      "y": 15,
      "z": 5,
      "name": "Wood_Azure_Trunk",
      "rotation": 2
    },
    {
      "x": -7,
      "y": 16,
      "z": 5,
      "name": "Wood_Azure_Trunk_Full",
      "rotation": 2
    },
    {
      "x": -7,
      "y": 27,
      "z": 5,
      "name": "Plant_Leaves_Azure",
      "rotation": 2
    },
    {
      "x": -7,
      "y": 28,
      "z": 5,
      "name": "Plant_Leaves_Azure",
      "support": 1,
      "rotation": 2
    },
    {
      "x": -7,
      "y": 29,
      "z": 5,
      "name": "Plant_Leaves_Azure",
      "support": 1,
      "rotation": 2
    },
    {
      "x": -7,
      "y": 8,
      "z": 6,
      "name": "Plant_Moss_Cave_Blue",
      "support": 15,
      "rotation": 8
    },
    {
      "x": -7,
      "y": 9,
      "z": 6,
      "name": "Plant_Moss_Block_Blue",
      "support": 15
    },
    {
      "x": -7,
      "y": 10,
      "z": 6,
      "name": "Plant_Moss_Block_Blue",
      "support": 15
    },
    {
      "x": -7,
      "y": 11,
      "z": 6,
      "name": "Plant_Moss_Block_Blue",
      "support": 15
    },
    {
      "x": -7,
      "y": 12,
      "z": 6,
      "name": "Wood_Azure_Trunk_Full",
      "rotation": 2
    },
    {
      "x": -7,
      "y": 13,
      "z": 6,
      "name": "Wood_Azure_Trunk",
      "rotation": 2
    },
    {
      "x": -7,
      "y": 14,
      "z": 6,
      "name": "Wood_Azure_Trunk",
      "rotation": 2
    },
    {
      "x": -7,
      "y": 15,
      "z": 6,
      "name": "Wood_Azure_Trunk",
      "rotation": 2
    },
    {
      "x": -7,
      "y": 16,
      "z": 6,
      "name": "Wood_Azure_Trunk",
      "rotation": 2
    },
    {
      "x": -7,
      "y": 17,
      "z": 6,
      "name": "Wood_Azure_Trunk",
      "rotation": 2
    },
    {
      "x": -7,
      "y": 18,
      "z": 6,
      "name": "Wood_Azure_Trunk",
      "rotation": 2
    },
    {
      "x": -7,
      "y": 19,
      "z": 6,
      "name": "Wood_Azure_Trunk",
      "rotation": 2
    },
    {
      "x": -7,
      "y": 20,
      "z": 6,
      "name": "Wood_Azure_Trunk_Full",
      "rotation": 2
    },
    {
      "x": -7,
      "y": 22,
      "z": 6,
      "name": "Plant_Moss_Wall_Blue",
      "rotation": 1
    },
    {
      "x": -7,
      "y": 27,
      "z": 6,
      "name": "Wood_Azure_Branch_Long",
      "rotation": 6
    },
    {
      "x": -7,
      "y": 29,
      "z": 6,
      "name": "Plant_Leaves_Azure",
      "rotation": 2
    },
    {
      "x": -7,
      "y": 30,
      "z": 6,
      "name": "Plant_Leaves_Azure",
      "rotation": 2
    },
    {
      "x": -7,
      "y": 9,
      "z": 7,
      "name": "Plant_Moss_Block_Blue",
      "support": 15
    },
    {
      "x": -7,
      "y": 10,
      "z": 7,
      "name": "Plant_Moss_Block_Blue",
      "support": 15
    },
    {
      "x": -7,
      "y": 11,
      "z": 7,
      "name": "Wood_Azure_Trunk_Full",
      "rotation": 2
    },
    {
      "x": -7,
      "y": 12,
      "z": 7,
      "name": "Wood_Azure_Trunk",
      "rotation": 2
    },
    {
      "x": -7,
      "y": 13,
      "z": 7,
      "name": "Wood_Azure_Trunk",
      "rotation": 2
    },
    {
      "x": -7,
      "y": 14,
      "z": 7,
      "name": "Wood_Azure_Trunk_Full",
      "rotation": 2
    },
    {
      "x": -7,
      "y": 15,
      "z": 7,
      "name": "Plant_Moss_Rug_Blue",
      "rotation": 2
    },
    {
      "x": -7,
      "y": 18,
      "z": 7,
      "name": "Wood_Azure_Trunk_Full",
      "rotation": 2
    },
    {
      "x": -7,
      "y": 19,
      "z": 7,
      "name": "Wood_Azure_Trunk",
      "rotation": 2
    },
    {
      "x": -7,
      "y": 20,
      "z": 7,
      "name": "Wood_Azure_Trunk",
      "rotation": 2
    },
    {
      "x": -7,
      "y": 21,
      "z": 7,
      "name": "Wood_Azure_Trunk",
      "rotation": 2
    },
    {
      "x": -7,
      "y": 22,
      "z": 7,
      "name": "Wood_Azure_Trunk",
      "rotation": 2
    },
    {
      "x": -7,
      "y": 23,
      "z": 7,
      "name": "Wood_Azure_Trunk",
      "rotation": 2
    },
    {
      "x": -7,
      "y": 24,
      "z": 7,
      "name": "Wood_Azure_Trunk",
      "rotation": 2
    },
    {
      "x": -7,
      "y": 25,
      "z": 7,
      "name": "Wood_Azure_Trunk",
      "rotation": 2
    },
    {
      "x": -7,
      "y": 26,
      "z": 7,
      "name": "Wood_Azure_Trunk",
      "rotation": 2
    },
    {
      "x": -7,
      "y": 27,
      "z": 7,
      "name": "Wood_Azure_Trunk_Full",
      "rotation": 2
    },
    {
      "x": -7,
      "y": 28,
      "z": 7,
      "name": "Wood_Azure_Branch_Long",
      "rotation": 2
    },
    {
      "x": -7,
      "y": 29,
      "z": 7,
      "name": "Wood_Azure_Branch_Long",
      "support": 1,
      "rotation": 2
    },
    {
      "x": -7,
      "y": 30,
      "z": 7,
      "name": "Wood_Azure_Branch_Long",
      "support": 2,
      "rotation": 2
    },
    {
      "x": -7,
      "y": 31,
      "z": 7,
      "name": "Plant_Leaves_Azure",
      "rotation": 2
    },
    {
      "x": -7,
      "y": 32,
      "z": 7,
      "name": "Plant_Leaves_Azure",
      "support": 1,
      "rotation": 2
    },
    {
      "x": -7,
      "y": 10,
      "z": 8,
      "name": "Plant_Moss_Block_Blue",
      "support": 15
    },
    {
      "x": -7,
      "y": 11,
      "z": 8,
      "name": "Wood_Azure_Trunk",
      "rotation": 2
    },
    {
      "x": -7,
      "y": 12,
      "z": 8,
      "name": "Wood_Azure_Trunk_Full",
      "rotation": 2
    },
    {
      "x": -7,
      "y": 13,
      "z": 8,
      "name": "Soil_Grass"
    },
    {
      "x": -7,
      "y": 14,
      "z": 8,
      "name": "Plant_Moss_Wall_Blue"
    },
    {
      "x": -7,
      "y": 21,
      "z": 8,
      "name": "Wood_Azure_Trunk_Full",
      "rotation": 2
    },
    {
      "x": -7,
      "y": 22,
      "z": 8,
      "name": "Wood_Azure_Trunk",
      "rotation": 2
    },
    {
      "x": -7,
      "y": 23,
      "z": 8,
      "name": "Wood_Azure_Trunk_Full",
      "rotation": 2
    },
    {
      "x": -7,
      "y": 26,
      "z": 8,
      "name": "Wood_Azure_Branch_Long",
      "rotation": 6
    },
    {
      "x": -7,
      "y": 30,
      "z": 8,
      "name": "Plant_Leaves_Azure",
      "rotation": 2
    },
    {
      "x": -7,
      "y": 31,
      "z": 8,
      "name": "Plant_Leaves_Azure",
      "support": 1,
      "rotation": 2
    },
    {
      "x": -7,
      "y": 32,
      "z": 8,
      "name": "Plant_Leaves_Azure",
      "support": 2,
      "rotation": 2
    },
    {
      "x": -7,
      "y": 33,
      "z": 8,
      "name": "Plant_Leaves_Azure",
      "support": 3,
      "rotation": 2
    },
    {
      "x": -7,
      "y": 10,
      "z": 9,
      "name": "Plant_Moss_Block_Blue",
      "support": 15
    },
    {
      "x": -7,
      "y": 11,
      "z": 9,
      "name": "Wood_Azure_Trunk_Full",
      "rotation": 2
    },
    {
      "x": -7,
      "y": 12,
      "z": 9,
      "name": "Soil_Grass"
    },
    {
      "x": -7,
      "y": 13,
      "z": 9,
      "name": "Plant_Moss_Rug_Blue",
      "support": 15
    },
    {
      "x": -7,
      "y": 21,
      "z": 9,
      "name": "Wood_Azure_Branch_Long",
      "rotation": 6
    },
    {
      "x": -7,
      "y": 26,
      "z": 9,
      "name": "Plant_Leaves_Azure",
      "rotation": 2
    },
    {
      "x": -7,
      "y": 27,
      "z": 9,
      "name": "Plant_Leaves_Azure",
      "support": 1,
      "rotation": 2
    },
    {
      "x": -7,
      "y": 28,
      "z": 9,
      "name": "Plant_Leaves_Azure",
      "support": 2,
      "rotation": 2
    },
    {
      "x": -7,
      "y": 10,
      "z": 10,
      "name": "Plant_Moss_Block_Blue",
      "support": 15
    },
    {
      "x": -7,
      "y": 11,
      "z": 10,
      "name": "Soil_Grass"
    },
    {
      "x": -7,
      "y": 12,
      "z": 10,
      "name": "Plant_Moss_Rug_Blue",
      "support": 15
    },
    {
      "x": -7,
      "y": 21,
      "z": 10,
      "name": "Wood_Azure_Branch_Long",
      "support": 1,
      "rotation": 6
    },
    {
      "x": -7,
      "y": 26,
      "z": 10,
      "name": "Plant_Leaves_Azure",
      "support": 1,
      "rotation": 2
    },
    {
      "x": -7,
      "y": 11,
      "z": 11,
      "name": "Soil_Grass"
    },
    {
      "x": -7,
      "y": 19,
      "z": 11,
      "name": "Plant_Leaves_Azure",
      "rotation": 2
    },
    {
      "x": -7,
      "y": 20,
      "z": 11,
      "name": "Plant_Leaves_Azure",
      "rotation": 2
    },
    {
      "x": -7,
      "y": 21,
      "z": 11,
      "name": "Wood_Azure_Branch_Long",
      "support": 2,
      "rotation": 6
    },
    {
      "x": -7,
      "y": 22,
      "z": 11,
      "name": "Plant_Leaves_Azure",
      "rotation": 2
    },
    {
      "x": -7,
      "y": 17,
      "z": 12,
      "name": "Plant_Leaves_Azure",
      "support": 3,
      "rotation": 2
    },
    {
      "x": -7,
      "y": 18,
      "z": 12,
      "name": "Plant_Leaves_Azure",
      "support": 2,
      "rotation": 2
    },
    {
      "x": -7,
      "y": 19,
      "z": 12,
      "name": "Plant_Leaves_Azure",
      "support": 1,
      "rotation": 2
    },
    {
      "x": -7,
      "y": 20,
      "z": 12,
      "name": "Plant_Leaves_Azure",
      "support": 1,
      "rotation": 2
    },
    {
      "x": -7,
      "y": 21,
      "z": 12,
      "name": "Plant_Leaves_Azure",
      "rotation": 2
    },
    {
      "x": -7,
      "y": 22,
      "z": 12,
      "name": "Plant_Leaves_Azure",
      "support": 1,
      "rotation": 2
    },
    {
      "x": -7,
      "y": 18,
      "z": 13,
      "name": "Plant_Leaves_Azure",
      "support": 3,
      "rotation": 2
    },
    {
      "x": -7,
      "y": 19,
      "z": 13,
      "name": "Plant_Leaves_Azure",
      "support": 2,
      "rotation": 2
    },
    {
      "x": -7,
      "y": 20,
      "z": 13,
      "name": "Plant_Leaves_Azure",
      "support": 2,
      "rotation": 2
    },
    {
      "x": -7,
      "y": 21,
      "z": 13,
      "name": "Plant_Leaves_Azure",
      "support": 1,
      "rotation": 2
    },
    {
      "x": -6,
      "y": 10,
      "z": -8,
      "name": "Soil_Grass"
    },
    {
      "x": -6,
      "y": 11,
      "z": -8,
      "name": "Plant_Grass_Wet_Wild",
      "support": 15
    },
    {
      "x": -6,
      "y": 12,
      "z": -8,
      "name": "Plant_Grass_Wet_Wild",
      "filler": 1024
    },
    {
      "x": -6,
      "y": 9,
      "z": -7,
      "name": "Plant_Moss_Block_Blue",
      "support": 15
    },
    {
      "x": -6,
      "y": 10,
      "z": -7,
      "name": "Soil_Grass"
    },
    {
      "x": -6,
      "y": 9,
      "z": -6,
      "name": "Plant_Moss_Block_Blue",
      "support": 15
    },
    {
      "x": -6,
      "y": 10,
      "z": -6,
      "name": "Soil_Grass"
    },
    {
      "x": -6,
      "y": 9,
      "z": -5,
      "name": "Plant_Moss_Block_Blue",
      "support": 15
    },
    {
      "x": -6,
      "y": 10,
      "z": -5,
      "name": "Soil_Grass"
    },
    {
      "x": -6,
      "y": 11,
      "z": -5,
      "name": "Plant_Grass_Wet_Wild",
      "support": 15
    },
    {
      "x": -6,
      "y": 12,
      "z": -5,
      "name": "Plant_Grass_Wet_Wild",
      "filler": 1024
    },
    {
      "x": -6,
      "y": 8,
      "z": -4,
      "name": "Rock_Crystal_Blue_Small",
      "rotation": 8
    },
    {
      "x": -6,
      "y": 9,
      "z": -4,
      "name": "Plant_Moss_Block_Blue",
      "support": 15
    },
    {
      "x": -6,
      "y": 10,
      "z": -4,
      "name": "Soil_Grass"
    },
    {
      "x": -6,
      "y": 11,
      "z": -4,
      "name": "Plant_Grass_Winter_Tall",
      "support": 15
    },
    {
      "x": -6,
      "y": 12,
      "z": -4,
      "name": "Plant_Grass_Winter_Tall",
      "filler": 1024
    },
    {
      "x": -6,
      "y": 9,
      "z": -3,
      "name": "Plant_Moss_Block_Blue",
      "support": 15
    },
    {
      "x": -6,
      "y": 10,
      "z": -3,
      "name": "Soil_Grass"
    },
    {
      "x": -6,
      "y": 9,
      "z": -2,
      "name": "Plant_Moss_Block_Blue",
      "support": 15
    },
    {
      "x": -6,
      "y": 10,
      "z": -2,
      "name": "Soil_Grass"
    },
    {
      "x": -6,
      "y": 9,
      "z": -1,
      "name": "Plant_Moss_Block_Blue",
      "support": 15
    },
    {
      "x": -6,
      "y": 10,
      "z": -1,
      "name": "Soil_Grass"
    },
    {
      "x": -6,
      "y": 8,
      "z": 0,
      "name": "Plant_Moss_Wall_Blue",
      "support": 15,
      "rotation": 3
    },
    {
      "x": -6,
      "y": 9,
      "z": 0,
      "name": "Plant_Moss_Block_Blue",
      "support": 15
    },
    {
      "x": -6,
      "y": 10,
      "z": 0,
      "name": "Plant_Moss_Block_Blue",
      "support": 15
    },
    {
      "x": -6,
      "y": 11,
      "z": 0,
      "name": "Soil_Grass"
    },
    {
      "x": -6,
      "y": 12,
      "z": 0,
      "name": "Plant_Moss_Rug_Blue",
      "support": 15
    },
    {
      "x": -6,
      "y": 8,
      "z": 1,
      "name": "Plant_Moss_Block_Blue",
      "support": 15
    },
    {
      "x": -6,
      "y": 9,
      "z": 1,
      "name": "Plant_Moss_Block_Blue",
      "support": 15
    },
    {
      "x": -6,
      "y": 10,
      "z": 1,
      "name": "Plant_Moss_Block_Blue",
      "support": 15
    },
    {
      "x": -6,
      "y": 11,
      "z": 1,
      "name": "Soil_Grass"
    },
    {
      "x": -6,
      "y": 8,
      "z": 2,
      "name": "Plant_Moss_Block_Blue",
      "support": 15
    },
    {
      "x": -6,
      "y": 9,
      "z": 2,
      "name": "Plant_Moss_Block_Blue",
      "support": 15
    },
    {
      "x": -6,
      "y": 10,
      "z": 2,
      "name": "Plant_Moss_Block_Blue",
      "support": 15
    },
    {
      "x": -6,
      "y": 11,
      "z": 2,
      "name": "Soil_Grass"
    },
    {
      "x": -6,
      "y": 12,
      "z": 2,
      "name": "Plant_Moss_Short_Blue",
      "support": 15
    },
    {
      "x": -6,
      "y": 16,
      "z": 2,
      "name": "Plant_Leaves_Azure",
      "support": 3,
      "rotation": 2
    },
    {
      "x": -6,
      "y": 17,
      "z": 2,
      "name": "Plant_Leaves_Azure",
      "support": 2,
      "rotation": 2
    },
    {
      "x": -6,
      "y": 20,
      "z": 2,
      "name": "Plant_Leaves_Azure",
      "rotation": 2
    },
    {
      "x": -6,
      "y": 21,
      "z": 2,
      "name": "Plant_Leaves_Azure",
      "rotation": 2
    },
    {
      "x": -6,
      "y": 22,
      "z": 2,
      "name": "Plant_Leaves_Azure",
      "rotation": 2
    },
    {
      "x": -6,
      "y": 8,
      "z": 3,
      "name": "Plant_Moss_Block_Blue",
      "support": 15
    },
    {
      "x": -6,
      "y": 9,
      "z": 3,
      "name": "Plant_Moss_Block_Blue",
      "support": 15
    },
    {
      "x": -6,
      "y": 10,
      "z": 3,
      "name": "Plant_Moss_Block_Blue",
      "support": 15
    },
    {
      "x": -6,
      "y": 11,
      "z": 3,
      "name": "Soil_Grass"
    },
    {
      "x": -6,
      "y": 12,
      "z": 3,
      "name": "Plant_Grass_Winter_Tall",
      "support": 15
    },
    {
      "x": -6,
      "y": 13,
      "z": 3,
      "name": "Plant_Grass_Winter_Tall",
      "filler": 1024
    },
    {
      "x": -6,
      "y": 16,
      "z": 3,
      "name": "Plant_Leaves_Azure",
      "support": 2,
      "rotation": 2
    },
    {
      "x": -6,
      "y": 20,
      "z": 3,
      "name": "Plant_Leaves_Azure",
      "rotation": 2
    },
    {
      "x": -6,
      "y": 21,
      "z": 3,
      "name": "Plant_Leaves_Azure",
      "rotation": 2
    },
    {
      "x": -6,
      "y": 22,
      "z": 3,
      "name": "Plant_Leaves_Azure",
      "rotation": 2
    },
    {
      "x": -6,
      "y": 23,
      "z": 3,
      "name": "Plant_Leaves_Azure",
      "rotation": 2
    },
    {
      "x": -6,
      "y": 8,
      "z": 4,
      "name": "Plant_Moss_Block_Blue",
      "support": 15
    },
    {
      "x": -6,
      "y": 9,
      "z": 4,
      "name": "Plant_Moss_Block_Blue",
      "support": 15
    },
    {
      "x": -6,
      "y": 10,
      "z": 4,
      "name": "Plant_Moss_Block_Blue",
      "support": 15
    },
    {
      "x": -6,
      "y": 11,
      "z": 4,
      "name": "Plant_Moss_Block_Blue",
      "support": 15
    },
    {
      "x": -6,
      "y": 12,
      "z": 4,
      "name": "Soil_Grass"
    },
    {
      "x": -6,
      "y": 21,
      "z": 4,
      "name": "Wood_Azure_Branch_Long",
      "rotation": 6
    },
    {
      "x": -6,
      "y": 22,
      "z": 4,
      "name": "Plant_Leaves_Azure",
      "rotation": 2
    },
    {
      "x": -6,
      "y": 25,
      "z": 4,
      "name": "Plant_Leaves_Azure",
      "support": 2,
      "rotation": 2
    },
    {
      "x": -6,
      "y": 26,
      "z": 4,
      "name": "Plant_Leaves_Azure",
      "support": 3,
      "rotation": 2
    },
    {
      "x": -6,
      "y": 27,
      "z": 4,
      "name": "Plant_Leaves_Azure",
      "support": 2,
      "rotation": 2
    },
    {
      "x": -6,
      "y": 28,
      "z": 4,
      "name": "Plant_Leaves_Azure",
      "support": 3,
      "rotation": 2
    },
    {
      "x": -6,
      "y": 9,
      "z": 5,
      "name": "Plant_Moss_Block_Blue",
      "support": 15
    },
    {
      "x": -6,
      "y": 10,
      "z": 5,
      "name": "Plant_Moss_Block_Blue",
      "support": 15
    },
    {
      "x": -6,
      "y": 11,
      "z": 5,
      "name": "Plant_Moss_Block_Blue",
      "support": 15
    },
    {
      "x": -6,
      "y": 12,
      "z": 5,
      "name": "Soil_Grass"
    },
    {
      "x": -6,
      "y": 13,
      "z": 5,
      "name": "Plant_Moss_Rug_Blue",
      "support": 15
    },
    {
      "x": -6,
      "y": 21,
      "z": 5,
      "name": "Wood_Azure_Branch_Long",
      "rotation": 6
    },
    {
      "x": -6,
      "y": 25,
      "z": 5,
      "name": "Plant_Leaves_Azure",
      "support": 1,
      "rotation": 2
    },
    {
      "x": -6,
      "y": 26,
      "z": 5,
      "name": "Plant_Leaves_Azure",
      "support": 2,
      "rotation": 2
    },
    {
      "x": -6,
      "y": 27,
      "z": 5,
      "name": "Plant_Leaves_Azure",
      "support": 1,
      "rotation": 2
    },
    {
      "x": -6,
      "y": 28,
      "z": 5,
      "name": "Plant_Leaves_Azure",
      "support": 2,
      "rotation": 2
    },
    {
      "x": -6,
      "y": 29,
      "z": 5,
      "name": "Plant_Leaves_Azure",
      "support": 2,
      "rotation": 2
    },
    {
      "x": -6,
      "y": 30,
      "z": 5,
      "name": "Plant_Fruit_Azure",
      "rotation": 2
    },
    {
      "x": -6,
      "y": 9,
      "z": 6,
      "name": "Plant_Moss_Block_Blue",
      "support": 15
    },
    {
      "x": -6,
      "y": 10,
      "z": 6,
      "name": "Plant_Moss_Block_Blue",
      "support": 15
    },
    {
      "x": -6,
      "y": 11,
      "z": 6,
      "name": "Wood_Azure_Trunk_Full",
      "rotation": 2
    },
    {
      "x": -6,
      "y": 12,
      "z": 6,
      "name": "Wood_Azure_Trunk_Full",
      "rotation": 2
    },
    {
      "x": -6,
      "y": 13,
      "z": 6,
      "name": "Soil_Grass"
    },
    {
      "x": -6,
      "y": 14,
      "z": 6,
      "name": "Plant_Moss_Short_Blue",
      "support": 15
    },
    {
      "x": -6,
      "y": 18,
      "z": 6,
      "name": "Wood_Azure_Trunk_Full",
      "rotation": 2
    },
    {
      "x": -6,
      "y": 20,
      "z": 6,
      "name": "Wood_Azure_Branch_Corner",
      "rotation": 1
    },
    {
      "x": -6,
      "y": 21,
      "z": 6,
      "name": "Wood_Azure_Branch_Corner",
      "rotation": 10
    },
    {
      "x": -6,
      "y": 25,
      "z": 6,
      "name": "Plant_Leaves_Azure",
      "rotation": 2
    },
    {
      "x": -6,
      "y": 26,
      "z": 6,
      "name": "Plant_Leaves_Azure",
      "support": 1,
      "rotation": 2
    },
    {
      "x": -6,
      "y": 27,
      "z": 6,
      "name": "Plant_Leaves_Azure",
      "rotation": 2
    },
    {
      "x": -6,
      "y": 9,
      "z": 7,
      "name": "Plant_Moss_Block_Blue",
      "support": 15
    },
    {
      "x": -6,
      "y": 10,
      "z": 7,
      "name": "Plant_Moss_Block_Blue",
      "support": 15
    },
    {
      "x": -6,
      "y": 11,
      "z": 7,
      "name": "Wood_Azure_Trunk_Full",
      "rotation": 2
    },
    {
      "x": -6,
      "y": 12,
      "z": 7,
      "name": "Plant_Moss_Block_Blue",
      "support": 15
    },
    {
      "x": -6,
      "y": 13,
      "z": 7,
      "name": "Soil_Grass"
    },
    {
      "x": -6,
      "y": 14,
      "z": 7,
      "name": "Plant_Moss_Wall_Blue",
      "rotation": 1
    },
    {
      "x": -6,
      "y": 25,
      "z": 7,
      "name": "Wood_Azure_Branch_Long",
      "rotation": 7
    },
    {
      "x": -6,
      "y": 30,
      "z": 7,
      "name": "Plant_Leaves_Azure",
      "rotation": 2
    },
    {
      "x": -6,
      "y": 10,
      "z": 8,
      "name": "Plant_Moss_Block_Blue",
      "support": 15
    },
    {
      "x": -6,
      "y": 11,
      "z": 8,
      "name": "Wood_Azure_Trunk_Full",
      "rotation": 2
    },
    {
      "x": -6,
      "y": 12,
      "z": 8,
      "name": "Soil_Grass"
    },
    {
      "x": -6,
      "y": 22,
      "z": 8,
      "name": "Wood_Azure_Branch_Long",
      "rotation": 7
    },
    {
      "x": -6,
      "y": 10,
      "z": 9,
      "name": "Plant_Moss_Block_Blue",
      "support": 15
    },
    {
      "x": -6,
      "y": 11,
      "z": 9,
      "name": "Soil_Grass"
    },
    {
      "x": -6,
      "y": 10,
      "z": 10,
      "name": "Plant_Moss_Wall_Blue",
      "support": 15
    },
    {
      "x": -6,
      "y": 11,
      "z": 10,
      "name": "Soil_Grass"
    },
    {
      "x": -6,
      "y": 22,
      "z": 10,
      "name": "Plant_Leaves_Azure",
      "support": 2,
      "rotation": 2
    },
    {
      "x": -6,
      "y": 23,
      "z": 10,
      "name": "Plant_Leaves_Azure",
      "support": 3,
      "rotation": 2
    },
    {
      "x": -6,
      "y": 19,
      "z": 11,
      "name": "Plant_Leaves_Azure",
      "support": 1,
      "rotation": 2
    },
    {
      "x": -6,
      "y": 20,
      "z": 11,
      "name": "Plant_Leaves_Azure",
      "support": 1,
      "rotation": 2
    },
    {
      "x": -6,
      "y": 21,
      "z": 11,
      "name": "Plant_Leaves_Azure",
      "rotation": 2
    },
    {
      "x": -6,
      "y": 22,
      "z": 11,
      "name": "Plant_Leaves_Azure",
      "support": 1,
      "rotation": 2
    },
    {
      "x": -6,
      "y": 23,
      "z": 11,
      "name": "Plant_Leaves_Azure",
      "support": 2,
      "rotation": 2
    },
    {
      "x": -6,
      "y": 18,
      "z": 12,
      "name": "Plant_Leaves_Azure",
      "support": 3,
      "rotation": 2
    },
    {
      "x": -6,
      "y": 19,
      "z": 12,
      "name": "Plant_Leaves_Azure",
      "support": 2,
      "rotation": 2
    },
    {
      "x": -6,
      "y": 20,
      "z": 12,
      "name": "Plant_Leaves_Azure",
      "support": 2,
      "rotation": 2
    },
    {
      "x": -6,
      "y": 21,
      "z": 12,
      "name": "Plant_Leaves_Azure",
      "support": 1,
      "rotation": 2
    },
    {
      "x": -6,
      "y": 22,
      "z": 12,
      "name": "Plant_Leaves_Azure",
      "support": 2,
      "rotation": 2
    },
    {
      "x": -6,
      "y": 19,
      "z": 13,
      "name": "Plant_Leaves_Azure",
      "support": 3,
      "rotation": 2
    },
    {
      "x": -6,
      "y": 20,
      "z": 13,
      "name": "Plant_Leaves_Azure",
      "support": 3,
      "rotation": 2
    },
    {
      "x": -6,
      "y": 21,
      "z": 13,
      "name": "Plant_Leaves_Azure",
      "support": 2,
      "rotation": 2
    },
    {
      "x": -5,
      "y": 10,
      "z": -9,
      "name": "Soil_Grass"
    },
    {
      "x": -5,
      "y": 11,
      "z": -9,
      "name": "Plant_Moss_Blue",
      "support": 15
    },
    {
      "x": -5,
      "y": 9,
      "z": -8,
      "name": "Plant_Moss_Block_Blue",
      "support": 15
    },
    {
      "x": -5,
      "y": 10,
      "z": -8,
      "name": "Soil_Grass"
    },
    {
      "x": -5,
      "y": 8,
      "z": -7,
      "name": "Plant_Moss_Wall_Blue",
      "support": 15,
      "rotation": 3
    },
    {
      "x": -5,
      "y": 9,
      "z": -7,
      "name": "Plant_Moss_Block_Blue",
      "support": 15
    },
    {
      "x": -5,
      "y": 10,
      "z": -7,
      "name": "Soil_Grass"
    },
    {
      "x": -5,
      "y": 11,
      "z": -7,
      "name": "Plant_Moss_Cave_Blue",
      "support": 15
    },
    {
      "x": -5,
      "y": 9,
      "z": -6,
      "name": "Plant_Moss_Block_Blue",
      "support": 15
    },
    {
      "x": -5,
      "y": 10,
      "z": -6,
      "name": "Soil_Grass"
    },
    {
      "x": -5,
      "y": 8,
      "z": -5,
      "name": "Rock_Crystal_Blue_Medium",
      "rotation": 7
    },
    {
      "x": -5,
      "y": 9,
      "z": -5,
      "name": "Plant_Moss_Block_Blue",
      "support": 15
    },
    {
      "x": -5,
      "y": 10,
      "z": -5,
      "name": "Soil_Grass"
    },
    {
      "x": -5,
      "y": 11,
      "z": -5,
      "name": "Plant_Moss_Rug_Blue",
      "support": 15
    },
    {
      "x": -5,
      "y": 9,
      "z": -4,
      "name": "Plant_Moss_Block_Blue",
      "support": 15
    },
    {
      "x": -5,
      "y": 10,
      "z": -4,
      "name": "Soil_Grass"
    },
    {
      "x": -5,
      "y": 9,
      "z": -3,
      "name": "Plant_Moss_Block_Blue",
      "support": 15
    },
    {
      "x": -5,
      "y": 10,
      "z": -3,
      "name": "Soil_Grass"
    },
    {
      "x": -5,
      "y": 11,
      "z": -3,
      "name": "Plant_Moss_Blue",
      "support": 15
    },
    {
      "x": -5,
      "y": 9,
      "z": -2,
      "name": "Plant_Moss_Block_Blue",
      "support": 15
    },
    {
      "x": -5,
      "y": 10,
      "z": -2,
      "name": "Soil_Grass"
    },
    {
      "x": -5,
      "y": 11,
      "z": -2,
      "name": "Plant_Moss_Short_Blue",
      "support": 15
    },
    {
      "x": -5,
      "y": 8,
      "z": -1,
      "name": "Plant_Moss_Block_Blue",
      "support": 15
    },
    {
      "x": -5,
      "y": 9,
      "z": -1,
      "name": "Plant_Moss_Block_Blue",
      "support": 15
    },
    {
      "x": -5,
      "y": 10,
      "z": -1,
      "name": "Soil_Grass"
    },
    {
      "x": -5,
      "y": 11,
      "z": -1,
      "name": "Plant_Moss_Rug_Blue",
      "support": 15
    },
    {
      "x": -5,
      "y": 7,
      "z": 0,
      "name": "Plant_Moss_Cave_Blue",
      "support": 15,
      "rotation": 8
    },
    {
      "x": -5,
      "y": 8,
      "z": 0,
      "name": "Plant_Moss_Block_Blue",
      "support": 15
    },
    {
      "x": -5,
      "y": 9,
      "z": 0,
      "name": "Plant_Moss_Block_Blue",
      "support": 15
    },
    {
      "x": -5,
      "y": 10,
      "z": 0,
      "name": "Soil_Grass"
    },
    {
      "x": -5,
      "y": 11,
      "z": 0,
      "name": "Plant_Moss_Rug_Blue",
      "support": 15
    },
    {
      "x": -5,
      "y": 7,
      "z": 1,
      "name": "Plant_Moss_Wall_Blue",
      "support": 15,
      "rotation": 3
    },
    {
      "x": -5,
      "y": 8,
      "z": 1,
      "name": "Plant_Moss_Block_Blue",
      "support": 15
    },
    {
      "x": -5,
      "y": 9,
      "z": 1,
      "name": "Plant_Moss_Block_Blue",
      "support": 15
    },
    {
      "x": -5,
      "y": 10,
      "z": 1,
      "name": "Soil_Grass"
    },
    {
      "x": -5,
      "y": 7,
      "z": 2,
      "name": "Plant_Moss_Block_Blue",
      "support": 15
    },
    {
      "x": -5,
      "y": 8,
      "z": 2,
      "name": "Plant_Moss_Block_Blue",
      "support": 15
    },
    {
      "x": -5,
      "y": 9,
      "z": 2,
      "name": "Plant_Moss_Block_Blue",
      "support": 15
    },
    {
      "x": -5,
      "y": 10,
      "z": 2,
      "name": "Soil_Grass"
    },
    {
      "x": -5,
      "y": 11,
      "z": 2,
      "name": "Plant_Grass_Wet_Wild",
      "support": 15
    },
    {
      "x": -5,
      "y": 12,
      "z": 2,
      "name": "Plant_Grass_Wet_Wild",
      "filler": 1024
    },
    {
      "x": -5,
      "y": 19,
      "z": 2,
      "name": "Plant_Leaves_Azure",
      "rotation": 2
    },
    {
      "x": -5,
      "y": 20,
      "z": 2,
      "name": "Plant_Leaves_Azure",
      "rotation": 2
    },
    {
      "x": -5,
      "y": 21,
      "z": 2,
      "name": "Plant_Leaves_Azure",
      "rotation": 2
    },
    {
      "x": -5,
      "y": 22,
      "z": 2,
      "name": "Plant_Leaves_Azure",
      "rotation": 2
    },
    {
      "x": -5,
      "y": 8,
      "z": 3,
      "name": "Plant_Moss_Block_Blue",
      "support": 15
    },
    {
      "x": -5,
      "y": 9,
      "z": 3,
      "name": "Plant_Moss_Block_Blue",
      "support": 15
    },
    {
      "x": -5,
      "y": 10,
      "z": 3,
      "name": "Plant_Moss_Block_Blue",
      "support": 15
    },
    {
      "x": -5,
      "y": 11,
      "z": 3,
      "name": "Soil_Grass"
    },
    {
      "x": -5,
      "y": 19,
      "z": 3,
      "name": "Plant_Leaves_Azure",
      "rotation": 2
    },
    {
      "x": -5,
      "y": 20,
      "z": 3,
      "name": "Plant_Leaves_Azure",
      "rotation": 2
    },
    {
      "x": -5,
      "y": 21,
      "z": 3,
      "name": "Plant_Leaves_Azure",
      "rotation": 2
    },
    {
      "x": -5,
      "y": 22,
      "z": 3,
      "name": "Plant_Leaves_Azure",
      "rotation": 2
    },
    {
      "x": -5,
      "y": 8,
      "z": 4,
      "name": "Plant_Moss_Block_Blue",
      "support": 15
    },
    {
      "x": -5,
      "y": 9,
      "z": 4,
      "name": "Plant_Moss_Block_Blue",
      "support": 15
    },
    {
      "x": -5,
      "y": 10,
      "z": 4,
      "name": "Plant_Moss_Block_Blue",
      "support": 15
    },
    {
      "x": -5,
      "y": 11,
      "z": 4,
      "name": "Soil_Grass"
    },
    {
      "x": -5,
      "y": 12,
      "z": 4,
      "name": "Plant_Moss_Blue",
      "support": 15
    },
    {
      "x": -5,
      "y": 20,
      "z": 4,
      "name": "Plant_Leaves_Azure",
      "rotation": 2
    },
    {
      "x": -5,
      "y": 21,
      "z": 4,
      "name": "Plant_Leaves_Azure",
      "rotation": 2
    },
    {
      "x": -5,
      "y": 22,
      "z": 4,
      "name": "Plant_Leaves_Azure",
      "rotation": 2
    },
    {
      "x": -5,
      "y": 25,
      "z": 4,
      "name": "Plant_Leaves_Azure",
      "support": 2,
      "rotation": 2
    },
    {
      "x": -5,
      "y": 26,
      "z": 4,
      "name": "Plant_Leaves_Azure",
      "support": 3,
      "rotation": 2
    },
    {
      "x": -5,
      "y": 27,
      "z": 4,
      "name": "Plant_Leaves_Azure",
      "support": 3,
      "rotation": 2
    },
    {
      "x": -5,
      "y": 8,
      "z": 5,
      "name": "Plant_Moss_Block_Blue",
      "support": 15
    },
    {
      "x": -5,
      "y": 9,
      "z": 5,
      "name": "Plant_Moss_Block_Blue",
      "support": 15
    },
    {
      "x": -5,
      "y": 10,
      "z": 5,
      "name": "Plant_Moss_Block_Blue",
      "support": 15
    },
    {
      "x": -5,
      "y": 11,
      "z": 5,
      "name": "Plant_Moss_Block_Blue",
      "support": 15
    },
    {
      "x": -5,
      "y": 12,
      "z": 5,
      "name": "Soil_Grass"
    },
    {
      "x": -5,
      "y": 18,
      "z": 5,
      "name": "Plant_Moss_Wall_Blue",
      "rotation": 2
    },
    {
      "x": -5,
      "y": 24,
      "z": 5,
      "name": "Plant_Leaves_Azure",
      "support": 2,
      "rotation": 2
    },
    {
      "x": -5,
      "y": 25,
      "z": 5,
      "name": "Plant_Leaves_Azure",
      "support": 1,
      "rotation": 2
    },
    {
      "x": -5,
      "y": 26,
      "z": 5,
      "name": "Plant_Leaves_Azure",
      "support": 2,
      "rotation": 2
    },
    {
      "x": -5,
      "y": 27,
      "z": 5,
      "name": "Plant_Leaves_Azure",
      "support": 2,
      "rotation": 2
    },
    {
      "x": -5,
      "y": 28,
      "z": 5,
      "name": "Plant_Leaves_Azure",
      "support": 3,
      "rotation": 2
    },
    {
      "x": -5,
      "y": 9,
      "z": 6,
      "name": "Plant_Moss_Block_Blue",
      "support": 15
    },
    {
      "x": -5,
      "y": 10,
      "z": 6,
      "name": "Plant_Moss_Block_Blue",
      "support": 15
    },
    {
      "x": -5,
      "y": 11,
      "z": 6,
      "name": "Plant_Moss_Block_Blue",
      "support": 15
    },
    {
      "x": -5,
      "y": 12,
      "z": 6,
      "name": "Soil_Grass"
    },
    {
      "x": -5,
      "y": 13,
      "z": 6,
      "name": "Plant_Moss_Rug_Blue",
      "support": 15
    },
    {
      "x": -5,
      "y": 18,
      "z": 6,
      "name": "Wood_Azure_Trunk_Full",
      "rotation": 2
    },
    {
      "x": -5,
      "y": 19,
      "z": 6,
      "name": "Plant_Moss_Rug_Blue",
      "rotation": 2
    },
    {
      "x": -5,
      "y": 23,
      "z": 6,
      "name": "Plant_Leaves_Azure",
      "support": 2,
      "rotation": 2
    },
    {
      "x": -5,
      "y": 24,
      "z": 6,
      "name": "Plant_Leaves_Azure",
      "support": 1,
      "rotation": 2
    },
    {
      "x": -5,
      "y": 25,
      "z": 6,
      "name": "Plant_Leaves_Azure",
      "rotation": 2
    },
    {
      "x": -5,
      "y": 26,
      "z": 6,
      "name": "Plant_Leaves_Azure",
      "support": 1,
      "rotation": 2
    },
    {
      "x": -5,
      "y": 27,
      "z": 6,
      "name": "Plant_Leaves_Azure",
      "support": 1,
      "rotation": 2
    },
    {
      "x": -5,
      "y": 28,
      "z": 6,
      "name": "Plant_Leaves_Azure",
      "support": 2,
      "rotation": 2
    },
    {
      "x": -5,
      "y": 10,
      "z": 7,
      "name": "Plant_Moss_Block_Blue",
      "support": 15
    },
    {
      "x": -5,
      "y": 11,
      "z": 7,
      "name": "Plant_Moss_Block_Blue",
      "support": 15
    },
    {
      "x": -5,
      "y": 12,
      "z": 7,
      "name": "Soil_Grass"
    },
    {
      "x": -5,
      "y": 13,
      "z": 7,
      "name": "Plant_Moss_Cave_Blue",
      "support": 15
    },
    {
      "x": -5,
      "y": 18,
      "z": 7,
      "name": "Plant_Moss_Wall_Blue"
    },
    {
      "x": -5,
      "y": 24,
      "z": 7,
      "name": "Plant_Leaves_Azure",
      "rotation": 2
    },
    {
      "x": -5,
      "y": 25,
      "z": 7,
      "name": "Wood_Azure_Branch_Long",
      "support": 1,
      "rotation": 7
    },
    {
      "x": -5,
      "y": 26,
      "z": 7,
      "name": "Plant_Leaves_Azure",
      "rotation": 2
    },
    {
      "x": -5,
      "y": 27,
      "z": 7,
      "name": "Plant_Fruit_Azure",
      "rotation": 2
    },
    {
      "x": -5,
      "y": 10,
      "z": 8,
      "name": "Plant_Moss_Block_Blue",
      "support": 15
    },
    {
      "x": -5,
      "y": 11,
      "z": 8,
      "name": "Soil_Grass"
    },
    {
      "x": -5,
      "y": 22,
      "z": 8,
      "name": "Wood_Azure_Branch_Long",
      "support": 1,
      "rotation": 7
    },
    {
      "x": -5,
      "y": 24,
      "z": 8,
      "name": "Plant_Leaves_Azure",
      "support": 1,
      "rotation": 2
    },
    {
      "x": -5,
      "y": 25,
      "z": 8,
      "name": "Plant_Leaves_Azure",
      "rotation": 2
    },
    {
      "x": -5,
      "y": 11,
      "z": 9,
      "name": "Soil_Grass"
    },
    {
      "x": -5,
      "y": 22,
      "z": 9,
      "name": "Plant_Leaves_Azure",
      "rotation": 2
    },
    {
      "x": -5,
      "y": 23,
      "z": 9,
      "name": "Plant_Leaves_Azure",
      "support": 1,
      "rotation": 2
    },
    {
      "x": -5,
      "y": 24,
      "z": 9,
      "name": "Plant_Leaves_Azure",
      "support": 2,
      "rotation": 2
    },
    {
      "x": -5,
      "y": 25,
      "z": 9,
      "name": "Plant_Fruit_Azure",
      "rotation": 2
    },
    {
      "x": -5,
      "y": 20,
      "z": 10,
      "name": "Plant_Leaves_Azure",
      "support": 3,
      "rotation": 2
    },
    {
      "x": -5,
      "y": 21,
      "z": 10,
      "name": "Plant_Leaves_Azure",
      "support": 2,
      "rotation": 2
    },
    {
      "x": -5,
      "y": 22,
      "z": 10,
      "name": "Plant_Leaves_Azure",
      "support": 1,
      "rotation": 2
    },
    {
      "x": -5,
      "y": 23,
      "z": 10,
      "name": "Plant_Leaves_Azure",
      "support": 2,
      "rotation": 2
    },
    {
      "x": -5,
      "y": 24,
      "z": 10,
      "name": "Plant_Leaves_Azure",
      "support": 3,
      "rotation": 2
    },
    {
      "x": -5,
      "y": 19,
      "z": 11,
      "name": "Plant_Leaves_Azure",
      "support": 2,
      "rotation": 2
    },
    {
      "x": -5,
      "y": 20,
      "z": 11,
      "name": "Plant_Leaves_Azure",
      "support": 2,
      "rotation": 2
    },
    {
      "x": -5,
      "y": 21,
      "z": 11,
      "name": "Plant_Leaves_Azure",
      "support": 1,
      "rotation": 2
    },
    {
      "x": -5,
      "y": 22,
      "z": 11,
      "name": "Plant_Leaves_Azure",
      "support": 2,
      "rotation": 2
    },
    {
      "x": -5,
      "y": 23,
      "z": 11,
      "name": "Plant_Leaves_Azure",
      "support": 3,
      "rotation": 2
    },
    {
      "x": -5,
      "y": 19,
      "z": 12,
      "name": "Plant_Leaves_Azure",
      "support": 3,
      "rotation": 2
    },
    {
      "x": -5,
      "y": 20,
      "z": 12,
      "name": "Plant_Leaves_Azure",
      "support": 3,
      "rotation": 2
    },
    {
      "x": -5,
      "y": 21,
      "z": 12,
      "name": "Plant_Leaves_Azure",
      "support": 2,
      "rotation": 2
    },
    {
      "x": -5,
      "y": 22,
      "z": 12,
      "name": "Plant_Leaves_Azure",
      "support": 3,
      "rotation": 2
    },
    {
      "x": -4,
      "y": 10,
      "z": -10,
      "name": "Soil_Grass"
    },
    {
      "x": -4,
      "y": 11,
      "z": -10,
      "name": "Plant_Moss_Cave_Blue",
      "support": 15
    },
    {
      "x": -4,
      "y": 9,
      "z": -9,
      "name": "Plant_Moss_Block_Blue",
      "support": 15
    },
    {
      "x": -4,
      "y": 10,
      "z": -9,
      "name": "Soil_Grass"
    },
    {
      "x": -4,
      "y": 8,
      "z": -8,
      "name": "Plant_Moss_Wall_Blue",
      "support": 15,
      "rotation": 2
    },
    {
      "x": -4,
      "y": 9,
      "z": -8,
      "name": "Plant_Moss_Block_Blue",
      "support": 15
    },
    {
      "x": -4,
      "y": 10,
      "z": -8,
      "name": "Soil_Grass"
    },
    {
      "x": -4,
      "y": 11,
      "z": -8,
      "name": "Plant_Flower_Orchid_Cyan"
    },
    {
      "x": -4,
      "y": 7,
      "z": -7,
      "name": "Plant_Moss_Cave_Blue",
      "support": 15,
      "rotation": 8
    },
    {
      "x": -4,
      "y": 8,
      "z": -7,
      "name": "Plant_Moss_Block_Blue",
      "support": 15
    },
    {
      "x": -4,
      "y": 9,
      "z": -7,
      "name": "Rock_Crystal_Blue_Block"
    },
    {
      "x": -4,
      "y": 10,
      "z": -7,
      "name": "Empty"
    },
    {
      "x": -4,
      "y": 8,
      "z": -6,
      "name": "Plant_Moss_Block_Blue",
      "support": 15
    },
    {
      "x": -4,
      "y": 9,
      "z": -6,
      "name": "Rock_Crystal_Blue_Block"
    },
    {
      "x": -4,
      "y": 10,
      "z": -6,
      "name": "Empty"
    },
    {
      "x": -4,
      "y": 8,
      "z": -5,
      "name": "Plant_Moss_Block_Blue",
      "support": 15
    },
    {
      "x": -4,
      "y": 9,
      "z": -5,
      "name": "Rock_Crystal_Blue_Block"
    },
    {
      "x": -4,
      "y": 10,
      "z": -5,
      "name": "Empty"
    },
    {
      "x": -4,
      "y": 8,
      "z": -4,
      "name": "Plant_Moss_Block_Blue",
      "support": 15
    },
    {
      "x": -4,
      "y": 9,
      "z": -4,
      "name": "Rock_Crystal_Blue_Block"
    },
    {
      "x": -4,
      "y": 10,
      "z": -4,
      "name": "Rock_Crystal_Blue_Large"
    },
    {
      "x": -4,
      "y": 8,
      "z": -3,
      "name": "Plant_Moss_Block_Blue",
      "support": 15
    },
    {
      "x": -4,
      "y": 9,
      "z": -3,
      "name": "Rock_Crystal_Blue_Block"
    },
    {
      "x": -4,
      "y": 10,
      "z": -3,
      "name": "Empty"
    },
    {
      "x": -4,
      "y": 8,
      "z": -2,
      "name": "Plant_Moss_Block_Blue",
      "support": 15
    },
    {
      "x": -4,
      "y": 9,
      "z": -2,
      "name": "Plant_Moss_Block_Blue",
      "support": 15
    },
    {
      "x": -4,
      "y": 10,
      "z": -2,
      "name": "Soil_Grass"
    },
    {
      "x": -4,
      "y": 11,
      "z": -2,
      "name": "Plant_Crop_Mana2"
    },
    {
      "x": -4,
      "y": 8,
      "z": -1,
      "name": "Plant_Moss_Block_Blue",
      "support": 15
    },
    {
      "x": -4,
      "y": 9,
      "z": -1,
      "name": "Plant_Moss_Block_Blue",
      "support": 15
    },
    {
      "x": -4,
      "y": 10,
      "z": -1,
      "name": "Empty"
    },
    {
      "x": -4,
      "y": 8,
      "z": 0,
      "name": "Plant_Moss_Block_Blue",
      "support": 15
    },
    {
      "x": -4,
      "y": 9,
      "z": 0,
      "name": "Plant_Moss_Block_Blue",
      "support": 15
    },
    {
      "x": -4,
      "y": 10,
      "z": 0,
      "name": "Empty"
    },
    {
      "x": -4,
      "y": 7,
      "z": 1,
      "name": "Plant_Moss_Block_Blue",
      "support": 15
    },
    {
      "x": -4,
      "y": 8,
      "z": 1,
      "name": "Plant_Moss_Block_Blue",
      "support": 15
    },
    {
      "x": -4,
      "y": 9,
      "z": 1,
      "name": "Plant_Moss_Block_Blue",
      "support": 15
    },
    {
      "x": -4,
      "y": 10,
      "z": 1,
      "name": "Soil_Grass"
    },
    {
      "x": -4,
      "y": 11,
      "z": 1,
      "name": "Plant_Grass_Wet_Wild",
      "support": 15
    },
    {
      "x": -4,
      "y": 12,
      "z": 1,
      "name": "Plant_Grass_Wet_Wild",
      "filler": 1024
    },
    {
      "x": -4,
      "y": 6,
      "z": 2,
      "name": "Plant_Moss_Block_Blue",
      "support": 15
    },
    {
      "x": -4,
      "y": 7,
      "z": 2,
      "name": "Plant_Moss_Block_Blue",
      "support": 15
    },
    {
      "x": -4,
      "y": 8,
      "z": 2,
      "name": "Plant_Moss_Block_Blue",
      "support": 15
    },
    {
      "x": -4,
      "y": 9,
      "z": 2,
      "name": "Plant_Moss_Block_Blue",
      "support": 15
    },
    {
      "x": -4,
      "y": 10,
      "z": 2,
      "name": "Soil_Grass"
    },
    {
      "x": -4,
      "y": 11,
      "z": 2,
      "name": "Plant_Grass_Wet_Wild",
      "support": 15
    },
    {
      "x": -4,
      "y": 12,
      "z": 2,
      "name": "Plant_Grass_Wet_Wild",
      "filler": 1024
    },
    {
      "x": -4,
      "y": 19,
      "z": 2,
      "name": "Plant_Leaves_Azure",
      "rotation": 2
    },
    {
      "x": -4,
      "y": 20,
      "z": 2,
      "name": "Plant_Leaves_Azure",
      "rotation": 2
    },
    {
      "x": -4,
      "y": 21,
      "z": 2,
      "name": "Plant_Leaves_Azure",
      "rotation": 2
    },
    {
      "x": -4,
      "y": 6,
      "z": 3,
      "name": "Plant_Moss_Cave_Blue",
      "support": 15,
      "rotation": 8
    },
    {
      "x": -4,
      "y": 7,
      "z": 3,
      "name": "Plant_Moss_Block_Blue",
      "support": 15
    },
    {
      "x": -4,
      "y": 8,
      "z": 3,
      "name": "Plant_Moss_Block_Blue",
      "support": 15
    },
    {
      "x": -4,
      "y": 9,
      "z": 3,
      "name": "Plant_Moss_Block_Blue",
