{
  "version": 8,
  "blockIdVersion": 11,
  "anchorX": 0,
  "anchorY": 0,
  "anchorZ": 0,
  "blocks": [
    {
      "x": -4,
      "y": 0,
      "z": -4,
      "name": "Soil_Grass"
    },
    {
      "x": -4,
      "y": 1,
      "z": -4,
      "name": "Plant_Flower_Tall_Cyan"
    },
    {
      "x": -4,
      "y": 0,
      "z": -3,
      "name": "Soil_Grass"
    },
    {
      "x": -4,
      "y": 1,
      "z": -3,
      "name": "Plant_Flower_Tall_Violet"
    },
    {
      "x": -4,
      "y": 0,
      "z": -2,
      "name": "Soil_Grass"
    },
    {
      "x": -4,
      "y": 1,
      "z": -2,
      "name": "Furniture_Temple_Light_Bench",
      "filler": 992,
      "rotation": 3
    },
    {
      "x": -4,
      "y": 0,
      "z": -1,
      "name": "Soil_Grass"
    },
    {
      "x": -4,
      "y": 1,
      "z": -1,
      "name": "Furniture_Temple_Light_Bench",
      "rotation": 3
    },
    {
      "x": -4,
      "y": 0,
      "z": 0,
      "name": "Soil_Grass"
    },
    {
      "x": -4,
      "y": 1,
      "z": 0,
      "name": "Furniture_Temple_Light_Statue",
      "rotation": 3
    },
    {
      "x": -4,
      "y": 2,
      "z": 0,
      "name": "Furniture_Temple_Light_Statue",
      "filler": 1024,
      "rotation": 3
    },
    {
      "x": -4,
      "y": 3,
      "z": 0,
      "name": "Furniture_Temple_Light_Statue",
      "filler": 2048,
      "rotation": 3
    },
    {
      "x": -4,
      "y": 0,
      "z": 1,
      "name": "Soil_Grass"
    },
    {
      "x": -4,
      "y": 1,
      "z": 1,
      "name": "Furniture_Temple_Light_Bench",
      "filler": 992,
      "rotation": 3
    },
    {
      "x": -4,
      "y": 0,
      "z": 2,
      "name": "Soil_Grass"
    },
    {
      "x": -4,
      "y": 1,
      "z": 2,
      "name": "Furniture_Temple_Light_Bench",
      "rotation": 3
    },
    {
      "x": -4,
      "y": 0,
      "z": 3,
      "name": "Soil_Grass"
    },
    {
      "x": -4,
      "y": 1,
      "z": 3,
      "name": "Plant_Flower_Tall_Cyan"
    },
    {
      "x": -4,
      "y": 0,
      "z": 4,
      "name": "Soil_Grass"
    },
    {
      "x": -4,
      "y": 1,
      "z": 4,
      "name": "Plant_Flower_Common_Violet2"
    },
    {
      "x": -3,
      "y": 0,
      "z": -4,
      "name": "Soil_Grass"
    },
    {
      "x": -3,
      "y": 1,
      "z": -4,
      "name": "Plant_Flower_Common_Violet2"
    },
    {
      "x": -3,
      "y": 0,
      "z": -3,
      "name": "Soil_Grass"
    },
    {
      "x": -3,
      "y": 1,
      "z": -3,
      "name": "Furnature_Marble_Planter"
    },
    {
      "x": -3,
      "y": 2,
      "z": -3,
      "name": "Plant_Leaves_Windwillow",
      "support": 15
    },
    {
      "x": -3,
      "y": 3,
      "z": -3,
      "name": "Plant_Leaves_Windwillow",
      "support": 15
    },
    {
      "x": -3,
      "y": 0,
      "z": -2,
      "name": "Soil_Grass"
    },
    {
      "x": -3,
      "y": 1,
      "z": -2,
      "name": "Rock_Marble_Brick_Stairs",
      "rotation": 2
    },
    {
      "x": -3,
      "y": 0,
      "z": -1,
      "name": "Soil_Grass"
    },
    {
      "x": -3,
      "y": 1,
      "z": -1,
      "name": "Rock_Marble_Brick"
    },
    {
      "x": -3,
      "y": 0,
      "z": 0,
      "name": "Soil_Grass"
    },
    {
      "x": -3,
      "y": 1,
      "z": 0,
      "name": "Rock_Marble_Brick_Ornate"
    },
    {
      "x": -3,
      "y": 0,
      "z": 1,
      "name": "Soil_Grass"
    },
    {
      "x": -3,
      "y": 1,
      "z": 1,
      "name": "Rock_Marble_Brick"
    },
    {
      "x": -3,
      "y": 0,
      "z": 2,
      "name": "Soil_Grass"
    },
    {
      "x": -3,
      "y": 1,
      "z": 2,
      "name": "Rock_Marble_Brick_Stairs"
    },
    {
      "x": -3,
      "y": 0,
      "z": 3,
      "name": "Soil_Grass"
    },
    {
      "x": -3,
      "y": 1,
      "z": 3,
      "name": "Furnature_Marble_Planter"
    },
    {
      "x": -3,
      "y": 2,
      "z": 3,
      "name": "Plant_Leaves_Windwillow",
      "support": 15
    },
    {
      "x": -3,
      "y": 3,
      "z": 3,
      "name": "Plant_Leaves_Windwillow",
      "support": 15
    },
    {
      "x": -3,
      "y": 0,
      "z": 4,
      "name": "Soil_Grass"
    },
    {
      "x": -3,
      "y": 1,
      "z": 4,
      "name": "Plant_Flower_Tall_Violet"
    },
    {
      "x": -2,
      "y": 0,
      "z": -4,
      "name": "Soil_Grass"
    },
    {
      "x": -2,
      "y": 1,
      "z": -4,
      "name": "Furniture_Temple_Light_Bench",
      "rotation": 2
    },
    {
      "x": -2,
      "y": 0,
      "z": -3,
      "name": "Soil_Grass"
    },
    {
      "x": -2,
      "y": 1,
      "z": -3,
      "name": "Rock_Marble_Brick_Stairs",
      "rotation": 3
    },
    {
      "x": -2,
      "y": 0,
      "z": -2,
      "name": "Soil_Grass"
    },
    {
      "x": -2,
      "y": 1,
      "z": -2,
      "name": "Rock_Marble_Brick_Ornate"
    },
    {
      "x": -2,
      "y": 0,
      "z": -1,
      "name": "Soil_Grass"
    },
    {
      "x": -2,
      "y": 1,
      "z": -1,
      "name": "Rock_Marble_Brick_Smooth_Half"
    },
    {
      "x": -2,
      "y": 0,
      "z": 0,
      "name": "Soil_Grass"
    },
    {
      "x": -2,
      "y": 1,
      "z": 0,
      "name": "Rock_Marble_Brick_Smooth_Half"
    },
    {
      "x": -2,
      "y": 0,
      "z": 1,
      "name": "Soil_Grass"
    },
    {
      "x": -2,
      "y": 1,
      "z": 1,
      "name": "Rock_Marble_Brick_Smooth_Half"
    },
    {
      "x": -2,
      "y": 0,
      "z": 2,
      "name": "Soil_Grass"
    },
    {
      "x": -2,
      "y": 1,
      "z": 2,
      "name": "Rock_Marble_Brick_Ornate"
    },
    {
      "x": -2,
      "y": 0,
      "z": 3,
      "name": "Soil_Grass"
    },
    {
      "x": -2,
      "y": 1,
      "z": 3,
      "name": "Rock_Marble_Brick_Stairs",
      "rotation": 3
    },
    {
      "x": -2,
      "y": 0,
      "z": 4,
      "name": "Soil_Grass"
    },
    {
      "x": -2,
      "y": 1,
      "z": 4,
      "name": "Furniture_Temple_Light_Bench",
      "filler": 31
    },
    {
      "x": -1,
      "y": 0,
      "z": -4,
      "name": "Soil_Grass"
    },
    {
      "x": -1,
      "y": 1,
      "z": -4,
      "name": "Furniture_Temple_Light_Bench",
      "filler": 1,
      "rotation": 2
    },
    {
      "x": -1,
      "y": 0,
      "z": -3,
      "name": "Soil_Grass"
    },
    {
      "x": -1,
      "y": 1,
      "z": -3,
      "name": "Rock_Marble_Brick"
    },
    {
      "x": -1,
      "y": 0,
      "z": -2,
      "name": "Soil_Grass"
    },
    {
      "x": -1,
      "y": 1,
      "z": -2,
      "name": "Rock_Marble_Brick_Smooth_Half"
    },
    {
      "x": -1,
      "y": 0,
      "z": -1,
      "name": "Soil_Grass"
    },
    {
      "x": -1,
      "y": 1,
      "z": -1,
      "name": "Rock_Marble_Brick_Smooth_Half"
    },
    {
      "x": -1,
      "y": 0,
      "z": 0,
      "name": "Soil_Grass"
    },
    {
      "x": -1,
      "y": 1,
      "z": 0,
      "name": "Rock_Marble_Brick_Stairs",
      "rotation": 3
    },
    {
      "x": -1,
      "y": 2,
      "z": 0,
      "name": "Empty"
    },
    {
      "x": -1,
      "y": 3,
      "z": 0,
      "name": "Empty"
    },
    {
      "x": -1,
      "y": 4,
      "z": 0,
      "name": "Empty"
    },
    {
      "x": -1,
      "y": 5,
      "z": 0,
      "name": "Empty"
    },
    {
      "x": -1,
      "y": 6,
      "z": 0,
      "name": "Rock_Marble_Brick_Stairs",
      "rotation": 9
    },
    {
      "x": -1,
      "y": 0,
      "z": 1,
      "name": "Soil_Grass"
    },
    {
      "x": -1,
      "y": 1,
      "z": 1,
      "name": "Rock_Marble_Brick_Smooth_Half"
    },
    {
      "x": -1,
      "y": 0,
      "z": 2,
      "name": "Soil_Grass"
    },
    {
      "x": -1,
      "y": 1,
      "z": 2,
      "name": "Rock_Marble_Brick_Smooth_Half"
    },
    {
      "x": -1,
      "y": 0,
      "z": 3,
      "name": "Soil_Grass"
    },
    {
      "x": -1,
      "y": 1,
      "z": 3,
      "name": "Rock_Marble_Brick"
    },
    {
      "x": -1,
      "y": 0,
      "z": 4,
      "name": "Soil_Grass"
    },
    {
      "x": -1,
      "y": 1,
      "z": 4,
      "name": "Furniture_Temple_Light_Bench"
    },
    {
      "x": 0,
      "y": 0,
      "z": -4,
      "name": "Soil_Grass"
    },
    {
      "x": 0,
      "y": 1,
      "z": -4,
      "name": "Furniture_Temple_Light_Statue",
      "rotation": 2
    },
    {
      "x": 0,
      "y": 2,
      "z": -4,
      "name": "Furniture_Temple_Light_Statue",
      "filler": 1024,
      "rotation": 2
    },
    {
      "x": 0,
      "y": 3,
      "z": -4,
      "name": "Furniture_Temple_Light_Statue",
      "filler": 2048,
      "rotation": 2
    },
    {
      "x": 0,
      "y": 0,
      "z": -3,
      "name": "Soil_Grass"
    },
    {
      "x": 0,
      "y": 1,
      "z": -3,
      "name": "Rock_Marble_Brick_Ornate"
    },
    {
      "x": 0,
      "y": 0,
      "z": -2,
      "name": "Soil_Grass"
    },
    {
      "x": 0,
      "y": 1,
      "z": -2,
      "name": "Rock_Marble_Brick_Smooth_Half"
    },
    {
      "x": 0,
      "y": 0,
      "z": -1,
      "name": "Soil_Grass"
    },
    {
      "x": 0,
      "y": 1,
      "z": -1,
      "name": "Rock_Marble_Brick_Stairs",
      "rotation": 2
    },
    {
      "x": 0,
      "y": 2,
      "z": -1,
      "name": "Empty"
    },
    {
      "x": 0,
      "y": 3,
      "z": -1,
      "name": "Empty"
    },
    {
      "x": 0,
      "y": 4,
      "z": -1,
      "name": "Empty"
    },
    {
      "x": 0,
      "y": 5,
      "z": -1,
      "name": "Empty"
    },
    {
      "x": 0,
      "y": 6,
      "z": -1,
      "name": "Rock_Marble_Brick_Stairs",
      "rotation": 8
    },
    {
      "x": 0,
      "y": 0,
      "z": 0,
      "name": "Soil_Grass"
    },
    {
      "x": 0,
      "y": 1,
      "z": 0,
      "name": "Rock_Marble_Brick_Ornate"
    },
    {
      "x": 0,
      "y": 2,
      "z": 0,
      "name": "Rock_Marble_Brick_Ornate"
    },
    {
      "x": 0,
      "y": 3,
      "z": 0,
      "name": "Rock_Marble_Brick_Ornate"
    },
    {
      "x": 0,
      "y": 4,
      "z": 0,
      "name": "Rock_Marble_Brick_Ornate"
    },
    {
      "x": 0,
      "y": 5,
      "z": 0,
      "name": "Rock_Marble_Brick_Beam"
    },
    {
      "x": 0,
      "y": 6,
      "z": 0,
      "name": "Rock_Marble_Brick_Ornate"
    },
    {
      "x": 0,
      "y": 7,
      "z": 0,
      "name": "Furniture_Temple_Light_Statue",
      "rotation": 2
    },
    {
      "x": 0,
      "y": 8,
      "z": 0,
      "name": "Furniture_Temple_Light_Statue",
      "filler": 1024,
      "rotation": 2
    },
    {
      "x": 0,
      "y": 9,
      "z": 0,
      "name": "Furniture_Temple_Light_Statue",
      "filler": 2048,
      "rotation": 2
    },
    {
      "x": 0,
      "y": 0,
      "z": 1,
      "name": "Soil_Grass"
    },
    {
      "x": 0,
      "y": 1,
      "z": 1,
      "name": "Rock_Marble_Brick_Stairs"
    },
    {
      "x": 0,
      "y": 2,
      "z": 1,
      "name": "Empty"
    },
    {
      "x": 0,
      "y": 3,
      "z": 1,
      "name": "Empty"
    },
    {
      "x": 0,
      "y": 4,
      "z": 1,
      "name": "Empty"
    },
    {
      "x": 0,
      "y": 5,
      "z": 1,
      "name": "Empty"
    },
    {
      "x": 0,
      "y": 6,
      "z": 1,
      "name": "Rock_Marble_Brick_Stairs",
      "rotation": 10
    },
    {
      "x": 0,
      "y": 0,
      "z": 2,
      "name": "Soil_Grass"
    },
    {
      "x": 0,
      "y": 1,
      "z": 2,
      "name": "Rock_Marble_Brick_Smooth_Half"
    },
    {
      "x": 0,
      "y": 0,
      "z": 3,
      "name": "Soil_Grass"
    },
    {
      "x": 0,
      "y": 1,
      "z": 3,
      "name": "Rock_Marble_Brick_Ornate"
    },
    {
      "x": 0,
      "y": 0,
      "z": 4,
      "name": "Soil_Grass"
    },
    {
      "x": 0,
      "y": 1,
      "z": 4,
      "name": "Furniture_Temple_Light_Statue"
    },
    {
      "x": 0,
      "y": 2,
      "z": 4,
      "name": "Furniture_Temple_Light_Statue",
      "filler": 1024
    },
    {
      "x": 0,
      "y": 3,
      "z": 4,
      "name": "Furniture_Temple_Light_Statue",
      "filler": 2048
    },
    {
      "x": 1,
      "y": 0,
      "z": -4,
      "name": "Soil_Grass"
    },
    {
      "x": 1,
      "y": 1,
      "z": -4,
      "name": "Furniture_Temple_Light_Bench",
      "rotation": 2
    },
    {
      "x": 1,
      "y": 0,
      "z": -3,
      "name": "Soil_Grass"
    },
    {
      "x": 1,
      "y": 1,
      "z": -3,
      "name": "Rock_Marble_Brick"
    },
    {
      "x": 1,
      "y": 0,
      "z": -2,
      "name": "Soil_Grass"
    },
    {
      "x": 1,
      "y": 1,
      "z": -2,
      "name": "Rock_Marble_Brick_Smooth_Half"
    },
    {
      "x": 1,
      "y": 0,
      "z": -1,
      "name": "Soil_Grass"
    },
    {
      "x": 1,
      "y": 1,
      "z": -1,
      "name": "Rock_Marble_Brick_Smooth_Half"
    },
    {
      "x": 1,
      "y": 0,
      "z": 0,
      "name": "Soil_Grass"
    },
    {
      "x": 1,
      "y": 1,
      "z": 0,
      "name": "Rock_Marble_Brick_Stairs",
      "rotation": 1
    },
    {
      "x": 1,
      "y": 2,
      "z": 0,
      "name": "Empty"
    },
    {
      "x": 1,
      "y": 3,
      "z": 0,
      "name": "Empty"
    },
    {
      "x": 1,
      "y": 4,
      "z": 0,
      "name": "Empty"
    },
    {
      "x": 1,
      "y": 5,
      "z": 0,
      "name": "Empty"
    },
    {
      "x": 1,
      "y": 6,
      "z": 0,
      "name": "Rock_Marble_Brick_Stairs",
      "rotation": 11
    },
    {
      "x": 1,
      "y": 0,
      "z": 1,
      "name": "Soil_Grass"
    },
    {
      "x": 1,
      "y": 1,
      "z": 1,
      "name": "Rock_Marble_Brick_Smooth_Half"
    },
    {
      "x": 1,
      "y": 0,
      "z": 2,
      "name": "Soil_Grass"
    },
    {
      "x": 1,
      "y": 1,
      "z": 2,
      "name": "Rock_Marble_Brick_Smooth_Half"
    },
    {
      "x": 1,
      "y": 0,
      "z": 3,
      "name": "Soil_Grass"
    },
    {
      "x": 1,
      "y": 1,
      "z": 3,
      "name": "Rock_Marble_Brick"
    },
    {
      "x": 1,
      "y": 0,
      "z": 4,
      "name": "Soil_Grass"
    },
    {
      "x": 1,
      "y": 1,
      "z": 4,
      "name": "Furniture_Temple_Light_Bench",
      "filler": 31
    },
    {
      "x": 2,
      "y": 0,
      "z": -4,
      "name": "Soil_Grass"
    },
    {
      "x": 2,
      "y": 1,
      "z": -4,
      "name": "Furniture_Temple_Light_Bench",
      "filler": 1,
      "rotation": 2
    },
    {
      "x": 2,
      "y": 0,
      "z": -3,
      "name": "Soil_Grass"
    },
    {
      "x": 2,
      "y": 1,
      "z": -3,
      "name": "Rock_Marble_Brick_Stairs",
      "rotation": 1
    },
    {
      "x": 2,
      "y": 0,
      "z": -2,
      "name": "Soil_Grass"
    },
    {
      "x": 2,
      "y": 1,
      "z": -2,
      "name": "Rock_Marble_Brick_Ornate"
    },
    {
      "x": 2,
      "y": 0,
      "z": -1,
      "name": "Soil_Grass"
    },
    {
      "x": 2,
      "y": 1,
      "z": -1,
      "name": "Rock_Marble_Brick_Smooth_Half"
    },
    {
      "x": 2,
      "y": 0,
      "z": 0,
      "name": "Soil_Grass"
    },
    {
      "x": 2,
      "y": 1,
      "z": 0,
      "name": "Rock_Marble_Brick_Smooth_Half"
    },
    {
      "x": 2,
      "y": 0,
      "z": 1,
      "name": "Soil_Grass"
    },
    {
      "x": 2,
      "y": 1,
      "z": 1,
      "name": "Rock_Marble_Brick_Smooth_Half"
    },
    {
      "x": 2,
      "y": 0,
      "z": 2,
      "name": "Soil_Grass"
    },
    {
      "x": 2,
      "y": 1,
      "z": 2,
      "name": "Rock_Marble_Brick_Ornate"
    },
    {
      "x": 2,
      "y": 0,
      "z": 3,
      "name": "Soil_Grass"
    },
    {
      "x": 2,
      "y": 1,
      "z": 3,
      "name": "Rock_Marble_Brick_Stairs",
      "rotation": 1
    },
    {
      "x": 2,
      "y": 0,
      "z": 4,
      "name": "Soil_Grass"
    },
    {
      "x": 2,
      "y": 1,
      "z": 4,
      "name": "Furniture_Temple_Light_Bench"
    },
    {
      "x": 3,
      "y": 0,
      "z": -4,
      "name": "Soil_Grass"
    },
    {
      "x": 3,
      "y": 1,
      "z": -4,
      "name": "Plant_Flower_Common_Violet2"
    },
    {
      "x": 3,
      "y": 0,
      "z": -3,
      "name": "Soil_Grass"
    },
    {
      "x": 3,
      "y": 1,
      "z": -3,
      "name": "Furnature_Marble_Planter"
    },
    {
      "x": 3,
      "y": 2,
      "z": -3,
      "name": "Plant_Leaves_Windwillow",
      "support": 15
    },
    {
      "x": 3,
      "y": 3,
      "z": -3,
      "name": "Plant_Leaves_Windwillow",
      "support": 15
    },
    {
      "x": 3,
      "y": 0,
      "z": -2,
      "name": "Soil_Grass"
    },
    {
      "x": 3,
      "y": 1,
      "z": -2,
      "name": "Rock_Marble_Brick_Stairs",
      "rotation": 2
    },
    {
      "x": 3,
      "y": 0,
      "z": -1,
      "name": "Soil_Grass"
    },
    {
      "x": 3,
      "y": 1,
      "z": -1,
      "name": "Rock_Marble_Brick"
    },
    {
      "x": 3,
      "y": 0,
      "z": 0,
      "name": "Soil_Grass"
    },
    {
      "x": 3,
      "y": 1,
      "z": 0,
      "name": "Rock_Marble_Brick_Ornate"
    },
    {
      "x": 3,
      "y": 0,
      "z": 1,
      "name": "Soil_Grass"
    },
    {
      "x": 3,
      "y": 1,
      "z": 1,
      "name": "Rock_Marble_Brick"
    },
    {
      "x": 3,
      "y": 0,
      "z": 2,
      "name": "Soil_Grass"
    },
    {
      "x": 3,
      "y": 1,
      "z": 2,
      "name": "Rock_Marble_Brick_Stairs"
    },
    {
      "x": 3,
      "y": 0,
      "z": 3,
      "name": "Soil_Grass"
    },
    {
      "x": 3,
      "y": 1,
      "z": 3,
      "name": "Furnature_Marble_Planter"
    },
    {
      "x": 3,
      "y": 2,
      "z": 3,
      "name": "Plant_Leaves_Windwillow",
      "support": 15
    },
    {
      "x": 3,
      "y": 3,
      "z": 3,
      "name": "Plant_Leaves_Windwillow",
      "support": 15
    },
    {
      "x": 3,
      "y": 0,
      "z": 4,
      "name": "Soil_Grass"
    },
    {
      "x": 3,
      "y": 1,
      "z": 4,
      "name": "Plant_Flower_Tall_Cyan"
    },
    {
      "x": 4,
      "y": 0,
      "z": -4,
      "name": "Soil_Grass"
    },
    {
      "x": 4,
      "y": 1,
      "z": -4,
      "name": "Plant_Flower_Tall_Violet"
    },
    {
      "x": 4,
      "y": 0,
      "z": -3,
      "name": "Soil_Grass"
    },
    {
      "x": 4,
      "y": 1,
      "z": -3,
      "name": "Plant_Flower_Tall_Cyan"
    },
    {
      "x": 4,
      "y": 0,
      "z": -2,
      "name": "Soil_Grass"
    },
    {
      "x": 4,
      "y": 1,
      "z": -2,
      "name": "Furniture_Temple_Light_Bench",
      "rotation": 1
    },
    {
      "x": 4,
      "y": 0,
      "z": -1,
      "name": "Soil_Grass"
    },
    {
      "x": 4,
      "y": 1,
      "z": -1,
      "name": "Furniture_Temple_Light_Bench",
      "filler": 32,
      "rotation": 1
    },
    {
      "x": 4,
      "y": 0,
      "z": 0,
      "name": "Soil_Grass"
    },
    {
      "x": 4,
      "y": 1,
      "z": 0,
      "name": "Furniture_Temple_Light_Statue",
      "rotation": 1
    },
    {
      "x": 4,
      "y": 2,
      "z": 0,
      "name": "Furniture_Temple_Light_Statue",
      "filler": 1024,
      "rotation": 1
    },
    {
      "x": 4,
      "y": 3,
      "z": 0,
      "name": "Furniture_Temple_Light_Statue",
      "filler": 2048,
      "rotation": 1
    },
    {
      "x": 4,
      "y": 0,
      "z": 1,
      "name": "Soil_Grass"
    },
    {
      "x": 4,
      "y": 1,
      "z": 1,
      "name": "Furniture_Temple_Light_Bench",
      "rotation": 1
    },
    {
      "x": 4,
      "y": 0,
      "z": 2,
      "name": "Soil_Grass"
    },
    {
      "x": 4,
      "y": 1,
      "z": 2,
      "name": "Furniture_Temple_Light_Bench",
      "filler": 32,
      "rotation": 1
    },
    {
      "x": 4,
      "y": 0,
      "z": 3,
      "name": "Soil_Grass"
    },
    {
      "x": 4,
      "y": 1,
      "z": 3,
      "name": "Plant_Flower_Common_Violet2"
    },
    {
      "x": 4,
      "y": 0,
      "z": 4,
      "name": "Soil_Grass"
    },
    {
      "x": 4,
      "y": 1,
      "z": 4,
      "name": "Plant_Flower_Tall_Violet"
    }
  ],
  "fluids": [
    {
      "x": -4,
      "y": 0,
      "z": -4,
      "name": "Empty",
      "level": 0
    },
    {
      "x": -4,
      "y": 1,
      "z": -4,
      "name": "Empty",
      "level": 0
    },
    {
      "x": -4,
      "y": 0,
      "z": -3,
      "name": "Empty",
      "level": 0
    },
    {
      "x": -4,
      "y": 1,
      "z": -3,
      "name": "Empty",
      "level": 0
    },
    {
      "x": -4,
      "y": 0,
      "z": -2,
      "name": "Empty",
      "level": 0
    },
    {
      "x": -4,
      "y": 1,
      "z": -2,
      "name": "Empty",
      "level": 0
    },
    {
      "x": -4,
      "y": 0,
      "z": -1,
      "name": "Empty",
      "level": 0
    },
    {
      "x": -4,
      "y": 1,
      "z": -1,
      "name": "Empty",
      "level": 0
    },
    {
      "x": -4,
      "y": 0,
      "z": 0,
      "name": "Empty",
      "level": 0
    },
    {
      "x": -4,
      "y": 1,
      "z": 0,
      "name": "Empty",
      "level": 0
    },
    {
      "x": -4,
      "y": 2,
      "z": 0,
      "name": "Empty",
      "level": 0
    },
    {
      "x": -4,
      "y": 3,
      "z": 0,
      "name": "Empty",
      "level": 0
    },
    {
      "x": -4,
      "y": 0,
      "z": 1,
      "name": "Empty",
      "level": 0
    },
    {
      "x": -4,
      "y": 1,
      "z": 1,
      "name": "Empty",
      "level": 0
    },
    {
      "x": -4,
      "y": 0,
      "z": 2,
      "name": "Empty",
      "level": 0
    },
    {
      "x": -4,
      "y": 1,
      "z": 2,
      "name": "Empty",
      "level": 0
    },
    {
      "x": -4,
      "y": 0,
      "z": 3,
      "name": "Empty",
      "level": 0
    },
    {
      "x": -4,
      "y": 1,
      "z": 3,
      "name": "Empty",
      "level": 0
    },
    {
      "x": -4,
      "y": 0,
      "z": 4,
      "name": "Empty",
      "level": 0
    },
    {
      "x": -4,
      "y": 1,
      "z": 4,
      "name": "Empty",
      "level": 0
    },
    {
      "x": -3,
      "y": 0,
      "z": -4,
      "name": "Empty",
      "level": 0
    },
    {
      "x": -3,
      "y": 1,
      "z": -4,
      "name": "Empty",
      "level": 0
    },
    {
      "x": -3,
      "y": 0,
      "z": -3,
      "name": "Empty",
      "level": 0
    },
    {
      "x": -3,
      "y": 1,
      "z": -3,
      "name": "Empty",
      "level": 0
    },
    {
      "x": -3,
      "y": 2,
      "z": -3,
      "name": "Empty",
      "level": 0
    },
    {
      "x": -3,
      "y": 3,
      "z": -3,
      "name": "Empty",
      "level": 0
    },
    {
      "x": -3,
      "y": 0,
      "z": -2,
      "name": "Empty",
      "level": 0
    },
    {
      "x": -3,
      "y": 1,
      "z": -2,
      "name": "Empty",
      "level": 0
    },
    {
      "x": -3,
      "y": 0,
      "z": -1,
      "name": "Empty",
      "level": 0
    },
    {
      "x": -3,
      "y": 1,
      "z": -1,
      "name": "Empty",
      "level": 0
    },
    {
      "x": -3,
      "y": 0,
      "z": 0,
      "name": "Empty",
      "level": 0
    },
    {
      "x": -3,
      "y": 1,
      "z": 0,
      "name": "Empty",
      "level": 0
    },
    {
      "x": -3,
      "y": 0,
      "z": 1,
      "name": "Empty",
      "level": 0
    },
    {
      "x": -3,
      "y": 1,
      "z": 1,
      "name": "Empty",
      "level": 0
    },
    {
      "x": -3,
      "y": 0,
      "z": 2,
      "name": "Empty",
      "level": 0
    },
    {
      "x": -3,
      "y": 1,
      "z": 2,
      "name": "Empty",
      "level": 0
    },
    {
      "x": -3,
      "y": 0,
      "z": 3,
      "name": "Empty",
      "level": 0
    },
    {
      "x": -3,
      "y": 1,
      "z": 3,
      "name": "Empty",
      "level": 0
    },
    {
      "x": -3,
      "y": 2,
      "z": 3,
      "name": "Empty",
      "level": 0
    },
    {
      "x": -3,
      "y": 3,
      "z": 3,
      "name": "Empty",
      "level": 0
    },
    {
      "x": -3,
      "y": 0,
      "z": 4,
      "name": "Empty",
      "level": 0
    },
    {
      "x": -3,
      "y": 1,
      "z": 4,
      "name": "Empty",
      "level": 0
    },
    {
      "x": -2,
      "y": 0,
      "z": -4,
      "name": "Empty",
      "level": 0
    },
    {
      "x": -2,
      "y": 1,
      "z": -4,
      "name": "Empty",
      "level": 0
    },
    {
      "x": -2,
      "y": 0,
      "z": -3,
      "name": "Empty",
      "level": 0
    },
    {
      "x": -2,
      "y": 1,
      "z": -3,
      "name": "Empty",
      "level": 0
    },
    {
      "x": -2,
      "y": 0,
      "z": -2,
      "name": "Empty",
      "level": 0
    },
    {
      "x": -2,
      "y": 1,
      "z": -2,
      "name": "Empty",
      "level": 0
    },
    {
      "x": -2,
      "y": 0,
      "z": -1,
      "name": "Empty",
      "level": 0
    },
    {
      "x": -2,
      "y": 1,
      "z": -1,
      "name": "Water_Source",
      "level": 1
    },
    {
      "x": -2,
      "y": 0,
      "z": 0,
      "name": "Empty",
      "level": 0
    },
    {
      "x": -2,
      "y": 1,
      "z": 0,
      "name": "Water_Source",
      "level": 1
    },
    {
      "x": -2,
      "y": 0,
      "z": 1,
      "name": "Empty",
      "level": 0
    },
    {
      "x": -2,
      "y": 1,
      "z": 1,
      "name": "Water_Source",
      "level": 1
    },
    {
      "x": -2,
      "y": 0,
      "z": 2,
      "name": "Empty",
      "level": 0
    },
    {
      "x": -2,
      "y": 1,
      "z": 2,
      "name": "Empty",
      "level": 0
    },
    {
      "x": -2,
      "y": 0,
      "z": 3,
      "name": "Empty",
      "level": 0
    },
    {
      "x": -2,
      "y": 1,
      "z": 3,
      "name": "Empty",
      "level": 0
    },
    {
      "x": -2,
      "y": 0,
      "z": 4,
      "name": "Empty",
      "level": 0
    },
    {
      "x": -2,
      "y": 1,
      "z": 4,
      "name": "Empty",
      "level": 0
    },
    {
      "x": -1,
      "y": 0,
      "z": -4,
      "name": "Empty",
      "level": 0
    },
    {
      "x": -1,
      "y": 1,
      "z": -4,
      "name": "Empty",
      "level": 0
    },
    {
      "x": -1,
      "y": 0,
      "z": -3,
      "name": "Empty",
      "level": 0
    },
    {
      "x": -1,
      "y": 1,
      "z": -3,
      "name": "Empty",
      "level": 0
    },
    {
      "x": -1,
      "y": 0,
      "z": -2,
      "name": "Empty",
      "level": 0
    },
    {
      "x": -1,
      "y": 1,
      "z": -2,
      "name": "Water_Source",
      "level": 1
    },
    {
      "x": -1,
      "y": 0,
      "z": -1,
      "name": "Empty",
      "level": 0
    },
    {
      "x": -1,
      "y": 1,
      "z": -1,
      "name": "Water_Source",
      "level": 1
    },
    {
      "x": -1,
      "y": 0,
      "z": 0,
      "name": "Empty",
      "level": 0
    },
    {
      "x": -1,
      "y": 1,
      "z": 0,
      "name": "Water_Source",
      "level": 1
    },
    {
      "x": -1,
      "y": 2,
      "z": 0,
      "name": "Water",
      "level": 8
    },
    {
      "x": -1,
      "y": 3,
      "z": 0,
      "name": "Water",
      "level": 8
    },
    {
      "x": -1,
      "y": 4,
      "z": 0,
      "name": "Water",
      "level": 8
    },
    {
      "x": -1,
      "y": 5,
      "z": 0,
      "name": "Water",
      "level": 7
    },
    {
      "x": -1,
      "y": 6,
      "z": 0,
      "name": "Empty",
      "level": 0
    },
    {
      "x": -1,
      "y": 0,
      "z": 1,
      "name": "Empty",
      "level": 0
    },
    {
      "x": -1,
      "y": 1,
      "z": 1,
      "name": "Water_Source",
      "level": 1
    },
    {
      "x": -1,
      "y": 0,
      "z": 2,
      "name": "Empty",
      "level": 0
    },
    {
      "x": -1,
      "y": 1,
      "z": 2,
      "name": "Water_Source",
      "level": 1
    },
    {
      "x": -1,
      "y": 0,
      "z": 3,
      "name": "Empty",
      "level": 0
    },
    {
      "x": -1,
      "y": 1,
      "z": 3,
      "name": "Empty",
      "level": 0
    },
    {
      "x": -1,
      "y": 0,
      "z": 4,
      "name": "Empty",
      "level": 0
    },
    {
      "x": -1,
      "y": 1,
      "z": 4,
      "name": "Empty",
      "level": 0
    },
    {
      "x": 0,
      "y": 0,
      "z": -4,
      "name": "Empty",
      "level": 0
    },
    {
      "x": 0,
      "y": 1,
      "z": -4,
      "name": "Empty",
      "level": 0
    },
    {
      "x": 0,
      "y": 2,
      "z": -4,
      "name": "Empty",
      "level": 0
    },
    {
      "x": 0,
      "y": 3,
      "z": -4,
      "name": "Empty",
      "level": 0
    },
    {
      "x": 0,
      "y": 0,
      "z": -3,
      "name": "Empty",
      "level": 0
    },
    {
      "x": 0,
      "y": 1,
      "z": -3,
      "name": "Empty",
      "level": 0
    },
    {
      "x": 0,
      "y": 0,
      "z": -2,
      "name": "Empty",
      "level": 0
    },
    {
      "x": 0,
      "y": 1,
      "z": -2,
      "name": "Water_Source",
      "level": 1
    },
    {
      "x": 0,
      "y": 0,
      "z": -1,
      "name": "Empty",
      "level": 0
    },
    {
      "x": 0,
      "y": 1,
      "z": -1,
      "name": "Water_Source",
      "level": 1
    },
    {
      "x": 0,
      "y": 2,
      "z": -1,
      "name": "Water",
      "level": 8
    },
    {
      "x": 0,
      "y": 3,
      "z": -1,
      "name": "Water",
      "level": 8
    },
    {
      "x": 0,
      "y": 4,
      "z": -1,
      "name": "Water",
      "level": 8
    },
    {
      "x": 0,
      "y": 5,
      "z": -1,
      "name": "Water",
      "level": 7
    },
    {
      "x": 0,
      "y": 6,
      "z": -1,
      "name": "Empty",
      "level": 0
    },
    {
      "x": 0,
      "y": 0,
      "z": 0,
      "name": "Empty",
      "level": 0
    },
    {
      "x": 0,
      "y": 1,
      "z": 0,
      "name": "Empty",
      "level": 0
    },
    {
      "x": 0,
      "y": 2,
      "z": 0,
      "name": "Empty",
      "level": 0
    },
    {
      "x": 0,
      "y": 3,
      "z": 0,
      "name": "Empty",
      "level": 0
    },
    {
      "x": 0,
      "y": 4,
      "z": 0,
      "name": "Empty",
      "level": 0
    },
    {
      "x": 0,
      "y": 5,
      "z": 0,
      "name": "Water_Source",
      "level": 1
    },
    {
      "x": 0,
      "y": 6,
      "z": 0,
      "name": "Empty",
      "level": 0
    },
    {
      "x": 0,
      "y": 7,
      "z": 0,
      "name": "Empty",
      "level": 0
    },
    {
      "x": 0,
      "y": 8,
      "z": 0,
      "name": "Empty",
      "level": 0
    },
    {
      "x": 0,
      "y": 9,
      "z": 0,
      "name": "Empty",
      "level": 0
    },
    {
      "x": 0,
      "y": 0,
      "z": 1,
      "name": "Empty",
      "level": 0
    },
    {
      "x": 0,
      "y": 1,
      "z": 1,
      "name": "Water_Source",
      "level": 1
    },
    {
      "x": 0,
      "y": 2,
      "z": 1,
      "name": "Water",
      "level": 8
    },
    {
      "x": 0,
      "y": 3,
      "z": 1,
      "name": "Water",
      "level": 8
    },
    {
      "x": 0,
      "y": 4,
      "z": 1,
      "name": "Water",
      "level": 8
    },
    {
      "x": 0,
      "y": 5,
      "z": 1,
      "name": "Water",
      "level": 7
    },
    {
      "x": 0,
      "y": 6,
      "z": 1,
      "name": "Empty",
      "level": 0
    },
    {
      "x": 0,
      "y": 0,
      "z": 2,
      "name": "Empty",
      "level": 0
    },
    {
      "x": 0,
      "y": 1,
      "z": 2,
      "name": "Water_Source",
      "level": 1
    },
    {
      "x": 0,
      "y": 0,
      "z": 3,
      "name": "Empty",
      "level": 0
    },
    {
      "x": 0,
      "y": 1,
      "z": 3,
      "name": "Empty",
      "level": 0
    },
    {
      "x": 0,
      "y": 0,
      "z": 4,
      "name": "Empty",
      "level": 0
    },
    {
      "x": 0,
      "y": 1,
      "z": 4,
      "name": "Empty",
      "level": 0
    },
    {
      "x": 0,
      "y": 2,
      "z": 4,
      "name": "Empty",
      "level": 0
    },
    {
      "x": 0,
      "y": 3,
      "z": 4,
      "name": "Empty",
      "level": 0
    },
    {
      "x": 1,
      "y": 0,
      "z": -4,
      "name": "Empty",
      "level": 0
    },
    {
      "x": 1,
      "y": 1,
      "z": -4,
      "name": "Empty",
      "level": 0
    },
    {
      "x": 1,
      "y": 0,
      "z": -3,
      "name": "Empty",
      "level": 0
    },
    {
      "x": 1,
      "y": 1,
      "z": -3,
      "name": "Empty",
      "level": 0
    },
    {
      "x": 1,
      "y": 0,
      "z": -2,
      "name": "Empty",
      "level": 0
    },
    {
      "x": 1,
      "y": 1,
      "z": -2,
      "name": "Water_Source",
      "level": 1
    },
    {
      "x": 1,
      "y": 0,
      "z": -1,
      "name": "Empty",
      "level": 0
    },
    {
      "x": 1,
      "y": 1,
      "z": -1,
      "name": "Water_Source",
      "level": 1
    },
    {
      "x": 1,
      "y": 0,
      "z": 0,
      "name": "Empty",
      "level": 0
    },
    {
      "x": 1,
      "y": 1,
      "z": 0,
      "name": "Water_Source",
      "level": 1
    },
    {
      "x": 1,
      "y": 2,
      "z": 0,
      "name": "Water",
      "level": 8
    },
    {
      "x": 1,
      "y": 3,
      "z": 0,
      "name": "Water",
      "level": 8
    },
    {
      "x": 1,
      "y": 4,
      "z": 0,
      "name": "Water",
      "level": 8
    },
    {
      "x": 1,
      "y": 5,
      "z": 0,
      "name": "Water",
      "level": 7
    },
    {
      "x": 1,
      "y": 6,
      "z": 0,
      "name": "Empty",
      "level": 0
    },
    {
      "x": 1,
      "y": 0,
      "z": 1,
      "name": "Empty",
      "level": 0
    },
    {
      "x": 1,
      "y": 1,
      "z": 1,
      "name": "Water_Source",
      "level": 1
    },
    {
      "x": 1,
      "y": 0,
      "z": 2,
      "name": "Empty",
      "level": 0
    },
    {
      "x": 1,
      "y": 1,
      "z": 2,
      "name": "Water_Source",
      "level": 1
    },
    {
      "x": 1,
      "y": 0,
      "z": 3,
      "name": "Empty",
      "level": 0
    },
    {
      "x": 1,
      "y": 1,
      "z": 3,
      "name": "Empty",
      "level": 0
    },
    {
      "x": 1,
      "y": 0,
      "z": 4,
      "name": "Empty",
      "level": 0
    },
    {
      "x": 1,
      "y": 1,
      "z": 4,
      "name": "Empty",
      "level": 0
    },
    {
      "x": 2,
      "y": 0,
      "z": -4,
      "name": "Empty",
      "level": 0
    },
    {
      "x": 2,
      "y": 1,
      "z": -4,
      "name": "Empty",
      "level": 0
    },
    {
      "x": 2,
      "y": 0,
      "z": -3,
      "name": "Empty",
      "level": 0
    },
    {
      "x": 2,
      "y": 1,
      "z": -3,
      "name": "Empty",
      "level": 0
    },
    {
      "x": 2,
      "y": 0,
      "z": -2,
      "name": "Empty",
      "level": 0
    },
    {
      "x": 2,
      "y": 1,
      "z": -2,
      "name": "Empty",
      "level": 0
    },
    {
      "x": 2,
      "y": 0,
      "z": -1,
      "name": "Empty",
      "level": 0
    },
    {
      "x": 2,
      "y": 1,
      "z": -1,
      "name": "Water_Source",
      "level": 1
    },
    {
      "x": 2,
      "y": 0,
      "z": 0,
      "name": "Empty",
      "level": 0
    },
    {
      "x": 2,
      "y": 1,
      "z": 0,
      "name": "Water_Source",
      "level": 1
    },
    {
      "x": 2,
      "y": 0,
      "z": 1,
      "name": "Empty",
      "level": 0
    },
    {
      "x": 2,
      "y": 1,
      "z": 1,
      "name": "Water_Source",
      "level": 1
    },
    {
      "x": 2,
      "y": 0,
      "z": 2,
      "name": "Empty",
      "level": 0
    },
    {
      "x": 2,
      "y": 1,
      "z": 2,
      "name": "Empty",
      "level": 0
    },
    {
      "x": 2,
      "y": 0,
      "z": 3,
      "name": "Empty",
      "level": 0
    },
    {
      "x": 2,
      "y": 1,
      "z": 3,
      "name": "Empty",
      "level": 0
    },
    {
      "x": 2,
      "y": 0,
      "z": 4,
      "name": "Empty",
      "level": 0
    },
    {
      "x": 2,
      "y": 1,
      "z": 4,
      "name": "Empty",
      "level": 0
    },
    {
      "x": 3,
      "y": 0,
      "z": -4,
      "name": "Empty",
      "level": 0
    },
    {
      "x": 3,
      "y": 1,
      "z": -4,
      "name": "Empty",
      "level": 0
    },
    {
      "x": 3,
      "y": 0,
      "z": -3,
      "name": "Empty",
      "level": 0
    },
    {
      "x": 3,
      "y": 1,
      "z": -3,
      "name": "Empty",
      "level": 0
    },
    {
      "x": 3,
      "y": 2,
      "z": -3,
      "name": "Empty",
      "level": 0
    },
    {
      "x": 3,
      "y": 3,
      "z": -3,
      "name": "Empty",
      "level": 0
    },
    {
      "x": 3,
      "y": 0,
      "z": -2,
      "name": "Empty",
      "level": 0
    },
    {
      "x": 3,
      "y": 1,
      "z": -2,
      "name": "Empty",
      "level": 0
    },
    {
      "x": 3,
      "y": 0,
      "z": -1,
      "name": "Empty",
      "level": 0
    },
    {
      "x": 3,
      "y": 1,
      "z": -1,
      "name": "Empty",
      "level": 0
    },
    {
      "x": 3,
      "y": 0,
      "z": 0,
      "name": "Empty",
      "level": 0
    },
    {
      "x": 3,
      "y": 1,
      "z": 0,
      "name": "Empty",
      "level": 0
    },
    {
      "x": 3,
      "y": 0,
      "z": 1,
      "name": "Empty",
      "level": 0
    },
    {
      "x": 3,
      "y": 1,
      "z": 1,
      "name": "Empty",
      "level": 0
    },
    {
      "x": 3,
      "y": 0,
      "z": 2,
      "name": "Empty",
      "level": 0
    },
    {
      "x": 3,
      "y": 1,
      "z": 2,
      "name": "Empty",
      "level": 0
    },
    {
      "x": 3,
      "y": 0,
      "z": 3,
      "name": "Empty",
      "level": 0
    },
    {
      "x": 3,
      "y": 1,
      "z": 3,
      "name": "Empty",
      "level": 0
    },
    {
      "x": 3,
      "y": 2,
      "z": 3,
      "name": "Empty",
      "level": 0
    },
    {
      "x": 3,
      "y": 3,
      "z": 3,
      "name": "Empty",
      "level": 0
    },
    {
      "x": 3,
      "y": 0,
      "z": 4,
      "name": "Empty",
      "level": 0
    },
    {
      "x": 3,
      "y": 1,
      "z": 4,
      "name": "Empty",
      "level": 0
    },
    {
      "x": 4,
      "y": 0,
      "z": -4,
      "name": "Empty",
      "level": 0
    },
    {
      "x": 4,
      "y": 1,
      "z": -4,
      "name": "Empty",
      "level": 0
    },
    {
      "x": 4,
      "y": 0,
      "z": -3,
      "name": "Empty",
      "level": 0
    },
    {
      "x": 4,
      "y": 1,
      "z": -3,
      "name": "Empty",
      "level": 0
    },
    {
      "x": 4,
      "y": 0,
      "z": -2,
      "name": "Empty",
      "level": 0
    },
    {
      "x": 4,
      "y": 1,
      "z": -2,
      "name": "Empty",
      "level": 0
    },
    {
      "x": 4,
      "y": 0,
      "z": -1,
      "name": "Empty",
      "level": 0
    },
    {
      "x": 4,
      "y": 1,
      "z": -1,
      "name": "Empty",
      "level": 0
    },
    {
      "x": 4,
      "y": 0,
      "z": 0,
      "name": "Empty",
      "level": 0
    },
    {
      "x": 4,
      "y": 1,
      "z": 0,
      "name": "Empty",
      "level": 0
    },
    {
      "x": 4,
      "y": 2,
      "z": 0,
      "name": "Empty",
      "level": 0
    },
    {
      "x": 4,
      "y": 3,
      "z": 0,
      "name": "Empty",
      "level": 0
    },
    {
      "x": 4,
      "y": 0,
      "z": 1,
      "name": "Empty",
      "level": 0
    },
    {
      "x": 4,
      "y": 1,
      "z": 1,
      "name": "Empty",
      "level": 0
    },
    {
      "x": 4,
      "y": 0,
      "z": 2,
      "name": "Empty",
      "level": 0
    },
    {
      "x": 4,
      "y": 1,
      "z": 2,
      "name": "Empty",
      "level": 0
    },
    {
      "x": 4,
      "y": 0,
      "z": 3,
      "name": "Empty",
      "level": 0
    },
    {
      "x": 4,
      "y": 1,
      "z": 3,
      "name": "Empty",
      "level": 0
    },
    {
      "x": 4,
      "y": 0,
      "z": 4,
      "name": "Empty",
      "level": 0
    },
    {
      "x": 4,
      "y": 1,
      "z": 4,
      "name": "Empty",
      "level": 0
    }
  ]
}