{
  "version": 8,
  "blockIdVersion": 11,
  "anchorX": 0,
  "anchorY": 0,
  "anchorZ": 0,
  "blocks": [
    {
      "x": -20,
      "y": 9,
      "z": -1,
      "name": "Rock_Marble"
    },
    {
      "x": -20,
      "y": 9,
      "z": 0,
      "name": "Rock_Marble"
    },
    {
      "x": -20,
      "y": 10,
      "z": 0,
      "name": "Rock_Marble"
    },
    {
      "x": -20,
      "y": 9,
      "z": 1,
      "name": "Rock_Marble"
    },
    {
      "x": -20,
      "y": 10,
      "z": 1,
      "name": "Rock_Marble"
    },
    {
      "x": -20,
      "y": 9,
      "z": 2,
      "name": "Rock_Marble"
    },
    {
      "x": -20,
      "y": 10,
      "z": 2,
      "name": "Rock_Marble"
    },
    {
      "x": -20,
      "y": 11,
      "z": 2,
      "name": "Rock_Marble_Stalactite_Small"
    },
    {
      "x": -20,
      "y": 9,
      "z": 3,
      "name": "Rock_Marble"
    },
    {
      "x": -20,
      "y": 10,
      "z": 3,
      "name": "Rock_Marble"
    },
    {
      "x": -20,
      "y": 9,
      "z": 4,
      "name": "Rock_Marble"
    },
    {
      "x": -20,
      "y": 10,
      "z": 4,
      "name": "Rock_Marble"
    },
    {
      "x": -20,
      "y": 9,
      "z": 5,
      "name": "Rock_Marble"
    },
    {
      "x": -19,
      "y": 9,
      "z": -5,
      "name": "Rock_Marble"
    },
    {
      "x": -19,
      "y": 9,
      "z": -4,
      "name": "Rock_Marble"
    },
    {
      "x": -19,
      "y": 10,
      "z": -4,
      "name": "Rock_Marble"
    },
    {
      "x": -19,
      "y": 9,
      "z": -3,
      "name": "Rock_Marble"
    },
    {
      "x": -19,
      "y": 10,
      "z": -3,
      "name": "Rock_Marble"
    },
    {
      "x": -19,
      "y": 9,
      "z": -2,
      "name": "Rock_Marble"
    },
    {
      "x": -19,
      "y": 10,
      "z": -2,
      "name": "Rock_Marble"
    },
    {
      "x": -19,
      "y": 9,
      "z": -1,
      "name": "Rock_Marble"
    },
    {
      "x": -19,
      "y": 10,
      "z": -1,
      "name": "Rock_Marble"
    },
    {
      "x": -19,
      "y": 11,
      "z": -1,
      "name": "Rock_Marble_Stalactite_Large"
    },
    {
      "x": -19,
      "y": 12,
      "z": -1,
      "name": "Rock_Marble_Stalactite_Large",
      "filler": 1024
    },
    {
      "x": -19,
      "y": 9,
      "z": 0,
      "name": "Rock_Marble"
    },
    {
      "x": -19,
      "y": 10,
      "z": 0,
      "name": "Rock_Marble"
    },
    {
      "x": -19,
      "y": 9,
      "z": 1,
      "name": "Rock_Marble"
    },
    {
      "x": -19,
      "y": 10,
      "z": 1,
      "name": "Rock_Marble"
    },
    {
      "x": -19,
      "y": 9,
      "z": 2,
      "name": "Rock_Marble"
    },
    {
      "x": -19,
      "y": 10,
      "z": 2,
      "name": "Rock_Marble"
    },
    {
      "x": -19,
      "y": 9,
      "z": 3,
      "name": "Rock_Marble"
    },
    {
      "x": -19,
      "y": 10,
      "z": 3,
      "name": "Rock_Marble"
    },
    {
      "x": -19,
      "y": 9,
      "z": 4,
      "name": "Rock_Marble"
    },
    {
      "x": -19,
      "y": 10,
      "z": 4,
      "name": "Rock_Marble"
    },
    {
      "x": -19,
      "y": 9,
      "z": 5,
      "name": "Rock_Marble"
    },
    {
      "x": -19,
      "y": 10,
      "z": 5,
      "name": "Rock_Marble"
    },
    {
      "x": -19,
      "y": 9,
      "z": 6,
      "name": "Rock_Marble"
    },
    {
      "x": -19,
      "y": 10,
      "z": 6,
      "name": "Rock_Marble"
    },
    {
      "x": -19,
      "y": 11,
      "z": 6,
      "name": "Rock_Marble_Stalactite_Large"
    },
    {
      "x": -19,
      "y": 12,
      "z": 6,
      "name": "Rock_Marble_Stalactite_Large",
      "filler": 1024
    },
    {
      "x": -19,
      "y": 9,
      "z": 7,
      "name": "Rock_Marble"
    },
    {
      "x": -19,
      "y": 10,
      "z": 7,
      "name": "Rock_Marble"
    },
    {
      "x": -19,
      "y": 9,
      "z": 8,
      "name": "Rock_Marble"
    },
    {
      "x": -19,
      "y": 10,
      "z": 8,
      "name": "Rock_Marble"
    },
    {
      "x": -19,
      "y": 9,
      "z": 9,
      "name": "Rock_Marble"
    },
    {
      "x": -18,
      "y": 9,
      "z": -8,
      "name": "Rock_Marble"
    },
    {
      "x": -18,
      "y": 9,
      "z": -7,
      "name": "Rock_Marble"
    },
    {
      "x": -18,
      "y": 9,
      "z": -6,
      "name": "Rock_Marble"
    },
    {
      "x": -18,
      "y": 10,
      "z": -6,
      "name": "Rock_Marble"
    },
    {
      "x": -18,
      "y": 8,
      "z": -5,
      "name": "Rock_Marble"
    },
    {
      "x": -18,
      "y": 10,
      "z": -5,
      "name": "Rock_Marble"
    },
    {
      "x": -18,
      "y": 8,
      "z": -4,
      "name": "Rock_Marble"
    },
    {
      "x": -18,
      "y": 9,
      "z": -4,
      "name": "Rock_Marble"
    },
    {
      "x": -18,
      "y": 10,
      "z": -4,
      "name": "Rock_Marble"
    },
    {
      "x": -18,
      "y": 7,
      "z": -3,
      "name": "Rock_Marble"
    },
    {
      "x": -18,
      "y": 8,
      "z": -3,
      "name": "Rock_Marble"
    },
    {
      "x": -18,
      "y": 9,
      "z": -3,
      "name": "Rock_Marble"
    },
    {
      "x": -18,
      "y": 10,
      "z": -3,
      "name": "Rock_Marble"
    },
    {
      "x": -18,
      "y": 7,
      "z": -2,
      "name": "Rock_Marble"
    },
    {
      "x": -18,
      "y": 8,
      "z": -2,
      "name": "Rock_Marble"
    },
    {
      "x": -18,
      "y": 9,
      "z": -2,
      "name": "Rock_Marble"
    },
    {
      "x": -18,
      "y": 10,
      "z": -2,
      "name": "Rock_Marble"
    },
    {
      "x": -18,
      "y": 7,
      "z": -1,
      "name": "Rock_Marble"
    },
    {
      "x": -18,
      "y": 8,
      "z": -1,
      "name": "Rock_Marble"
    },
    {
      "x": -18,
      "y": 9,
      "z": -1,
      "name": "Rock_Marble"
    },
    {
      "x": -18,
      "y": 10,
      "z": -1,
      "name": "Rock_Marble"
    },
    {
      "x": -18,
      "y": 8,
      "z": 0,
      "name": "Rock_Marble"
    },
    {
      "x": -18,
      "y": 9,
      "z": 0,
      "name": "Rock_Marble"
    },
    {
      "x": -18,
      "y": 10,
      "z": 0,
      "name": "Rock_Marble"
    },
    {
      "x": -18,
      "y": 11,
      "z": 0,
      "name": "Plant_Crop_Mushroom_Glowing_Blue"
    },
    {
      "x": -18,
      "y": 8,
      "z": 1,
      "name": "Rock_Marble"
    },
    {
      "x": -18,
      "y": 9,
      "z": 1,
      "name": "Rock_Marble"
    },
    {
      "x": -18,
      "y": 10,
      "z": 1,
      "name": "Rock_Marble"
    },
    {
      "x": -18,
      "y": 8,
      "z": 2,
      "name": "Rock_Marble"
    },
    {
      "x": -18,
      "y": 9,
      "z": 2,
      "name": "Rock_Marble"
    },
    {
      "x": -18,
      "y": 10,
      "z": 2,
      "name": "Rock_Marble"
    },
    {
      "x": -18,
      "y": 9,
      "z": 3,
      "name": "Rock_Marble"
    },
    {
      "x": -18,
      "y": 10,
      "z": 3,
      "name": "Rock_Marble"
    },
    {
      "x": -18,
      "y": 11,
      "z": 3,
      "name": "Rubble_Marble_Medium"
    },
    {
      "x": -18,
      "y": 9,
      "z": 4,
      "name": "Rock_Marble"
    },
    {
      "x": -18,
      "y": 10,
      "z": 4,
      "name": "Rock_Marble"
    },
    {
      "x": -18,
      "y": 9,
      "z": 5,
      "name": "Rock_Marble"
    },
    {
      "x": -18,
      "y": 10,
      "z": 5,
      "name": "Rock_Marble"
    },
    {
      "x": -18,
      "y": 9,
      "z": 6,
      "name": "Rock_Marble"
    },
    {
      "x": -18,
      "y": 10,
      "z": 6,
      "name": "Rock_Marble"
    },
    {
      "x": -18,
      "y": 9,
      "z": 7,
      "name": "Rock_Marble"
    },
    {
      "x": -18,
      "y": 10,
      "z": 7,
      "name": "Rock_Marble"
    },
    {
      "x": -18,
      "y": 11,
      "z": 7,
      "name": "Rubble_Marble_Medium"
    },
    {
      "x": -18,
      "y": 9,
      "z": 8,
      "name": "Rock_Marble"
    },
    {
      "x": -18,
      "y": 10,
      "z": 8,
      "name": "Rock_Marble"
    },
    {
      "x": -18,
      "y": 9,
      "z": 9,
      "name": "Rock_Marble"
    },
    {
      "x": -18,
      "y": 10,
      "z": 9,
      "name": "Rock_Marble"
    },
    {
      "x": -18,
      "y": 9,
      "z": 10,
      "name": "Rock_Marble"
    },
    {
      "x": -18,
      "y": 10,
      "z": 10,
      "name": "Rock_Marble"
    },
    {
      "x": -18,
      "y": 11,
      "z": 10,
      "name": "Rock_Marble_Stalactite_Large"
    },
    {
      "x": -18,
      "y": 12,
      "z": 10,
      "name": "Rock_Marble_Stalactite_Large",
      "filler": 1024
    },
    {
      "x": -18,
      "y": 9,
      "z": 11,
      "name": "Rock_Marble"
    },
    {
      "x": -18,
      "y": 10,
      "z": 11,
      "name": "Rock_Marble"
    },
    {
      "x": -18,
      "y": 9,
      "z": 12,
      "name": "Rock_Marble"
    },
    {
      "x": -18,
      "y": 10,
      "z": 12,
      "name": "Rock_Marble"
    },
    {
      "x": -18,
      "y": 9,
      "z": 13,
      "name": "Rock_Marble"
    },
    {
      "x": -17,
      "y": 9,
      "z": -10,
      "name": "Rock_Marble"
    },
    {
      "x": -17,
      "y": 8,
      "z": -9,
      "name": "Rock_Marble"
    },
    {
      "x": -17,
      "y": 9,
      "z": -9,
      "name": "Rock_Marble"
    },
    {
      "x": -17,
      "y": 10,
      "z": -9,
      "name": "Rock_Marble"
    },
    {
      "x": -17,
      "y": 11,
      "z": -9,
      "name": "Rock_Marble_Stalactite_Small"
    },
    {
      "x": -17,
      "y": 7,
      "z": -8,
      "name": "Rock_Marble"
    },
    {
      "x": -17,
      "y": 8,
      "z": -8,
      "name": "Rock_Marble"
    },
    {
      "x": -17,
      "y": 9,
      "z": -8,
      "name": "Rock_Marble"
    },
    {
      "x": -17,
      "y": 10,
      "z": -8,
      "name": "Rock_Marble"
    },
    {
      "x": -17,
      "y": 7,
      "z": -7,
      "name": "Rock_Marble"
    },
    {
      "x": -17,
      "y": 8,
      "z": -7,
      "name": "Rock_Marble"
    },
    {
      "x": -17,
      "y": 9,
      "z": -7,
      "name": "Rock_Marble"
    },
    {
      "x": -17,
      "y": 10,
      "z": -7,
      "name": "Rock_Marble"
    },
    {
      "x": -17,
      "y": 11,
      "z": -7,
      "name": "Rock_Marble_Stalactite_Large"
    },
    {
      "x": -17,
      "y": 12,
      "z": -7,
      "name": "Rock_Marble_Stalactite_Large",
      "filler": 1024
    },
    {
      "x": -17,
      "y": 7,
      "z": -6,
      "name": "Rock_Marble"
    },
    {
      "x": -17,
      "y": 8,
      "z": -6,
      "name": "Rock_Marble"
    },
    {
      "x": -17,
      "y": 9,
      "z": -6,
      "name": "Rock_Marble"
    },
    {
      "x": -17,
      "y": 10,
      "z": -6,
      "name": "Rock_Marble"
    },
    {
      "x": -17,
      "y": 11,
      "z": -6,
      "name": "Rock_Marble_Stalactite_Large"
    },
    {
      "x": -17,
      "y": 12,
      "z": -6,
      "name": "Rock_Marble_Stalactite_Large",
      "filler": 1024
    },
    {
      "x": -17,
      "y": 6,
      "z": -5,
      "name": "Rock_Marble"
    },
    {
      "x": -17,
      "y": 7,
      "z": -5,
      "name": "Rock_Marble"
    },
    {
      "x": -17,
      "y": 8,
      "z": -5,
      "name": "Rock_Marble"
    },
    {
      "x": -17,
      "y": 9,
      "z": -5,
      "name": "Rock_Marble"
    },
    {
      "x": -17,
      "y": 10,
      "z": -5,
      "name": "Rock_Marble"
    },
    {
      "x": -17,
      "y": 6,
      "z": -4,
      "name": "Rock_Marble"
    },
    {
      "x": -17,
      "y": 7,
      "z": -4,
      "name": "Rock_Marble"
    },
    {
      "x": -17,
      "y": 8,
      "z": -4,
      "name": "Rock_Marble"
    },
    {
      "x": -17,
      "y": 9,
      "z": -4,
      "name": "Rock_Marble"
    },
    {
      "x": -17,
      "y": 10,
      "z": -4,
      "name": "Rock_Marble"
    },
    {
      "x": -17,
      "y": 11,
      "z": -4,
      "name": "Rubble_Marble_Medium"
    },
    {
      "x": -17,
      "y": 6,
      "z": -3,
      "name": "Rock_Marble"
    },
    {
      "x": -17,
      "y": 7,
      "z": -3,
      "name": "Rock_Marble"
    },
    {
      "x": -17,
      "y": 8,
      "z": -3,
      "name": "Rock_Marble"
    },
    {
      "x": -17,
      "y": 9,
      "z": -3,
      "name": "Rock_Marble"
    },
    {
      "x": -17,
      "y": 10,
      "z": -3,
      "name": "Rock_Marble"
    },
    {
      "x": -17,
      "y": 6,
      "z": -2,
      "name": "Rock_Marble"
    },
    {
      "x": -17,
      "y": 7,
      "z": -2,
      "name": "Rock_Marble"
    },
    {
      "x": -17,
      "y": 8,
      "z": -2,
      "name": "Rock_Marble"
    },
    {
      "x": -17,
      "y": 9,
      "z": -2,
      "name": "Rock_Marble"
    },
    {
      "x": -17,
      "y": 10,
      "z": -2,
      "name": "Rock_Marble"
    },
    {
      "x": -17,
      "y": 6,
      "z": -1,
      "name": "Rock_Marble"
    },
    {
      "x": -17,
      "y": 7,
      "z": -1,
      "name": "Rock_Marble"
    },
    {
      "x": -17,
      "y": 8,
      "z": -1,
      "name": "Rock_Marble"
    },
    {
      "x": -17,
      "y": 9,
      "z": -1,
      "name": "Rock_Marble"
    },
    {
      "x": -17,
      "y": 10,
      "z": -1,
      "name": "Rock_Marble"
    },
    {
      "x": -17,
      "y": 7,
      "z": 0,
      "name": "Rock_Marble"
    },
    {
      "x": -17,
      "y": 8,
      "z": 0,
      "name": "Rock_Marble"
    },
    {
      "x": -17,
      "y": 9,
      "z": 0,
      "name": "Rock_Marble"
    },
    {
      "x": -17,
      "y": 10,
      "z": 0,
      "name": "Rock_Marble"
    },
    {
      "x": -17,
      "y": 7,
      "z": 1,
      "name": "Rock_Marble"
    },
    {
      "x": -17,
      "y": 8,
      "z": 1,
      "name": "Rock_Marble"
    },
    {
      "x": -17,
      "y": 9,
      "z": 1,
      "name": "Rock_Marble"
    },
    {
      "x": -17,
      "y": 10,
      "z": 1,
      "name": "Rock_Marble"
    },
    {
      "x": -17,
      "y": 7,
      "z": 2,
      "name": "Rock_Marble"
    },
    {
      "x": -17,
      "y": 8,
      "z": 2,
      "name": "Rock_Marble"
    },
    {
      "x": -17,
      "y": 9,
      "z": 2,
      "name": "Rock_Marble"
    },
    {
      "x": -17,
      "y": 10,
      "z": 2,
      "name": "Rock_Marble"
    },
    {
      "x": -17,
      "y": 7,
      "z": 3,
      "name": "Rock_Marble"
    },
    {
      "x": -17,
      "y": 8,
      "z": 3,
      "name": "Rock_Marble"
    },
    {
      "x": -17,
      "y": 9,
      "z": 3,
      "name": "Rock_Marble"
    },
    {
      "x": -17,
      "y": 10,
      "z": 3,
      "name": "Rock_Marble"
    },
    {
      "x": -17,
      "y": 7,
      "z": 4,
      "name": "Rock_Marble"
    },
    {
      "x": -17,
      "y": 8,
      "z": 4,
      "name": "Rock_Marble"
    },
    {
      "x": -17,
      "y": 9,
      "z": 4,
      "name": "Rock_Marble"
    },
    {
      "x": -17,
      "y": 10,
      "z": 4,
      "name": "Rock_Marble"
    },
    {
      "x": -17,
      "y": 7,
      "z": 5,
      "name": "Rock_Marble"
    },
    {
      "x": -17,
      "y": 8,
      "z": 5,
      "name": "Rock_Marble"
    },
    {
      "x": -17,
      "y": 9,
      "z": 5,
      "name": "Rock_Marble"
    },
    {
      "x": -17,
      "y": 10,
      "z": 5,
      "name": "Rock_Marble"
    },
    {
      "x": -17,
      "y": 7,
      "z": 6,
      "name": "Rock_Marble"
    },
    {
      "x": -17,
      "y": 8,
      "z": 6,
      "name": "Rock_Marble"
    },
    {
      "x": -17,
      "y": 9,
      "z": 6,
      "name": "Rock_Marble"
    },
    {
      "x": -17,
      "y": 10,
      "z": 6,
      "name": "Rock_Marble"
    },
    {
      "x": -17,
      "y": 7,
      "z": 7,
      "name": "Rock_Marble"
    },
    {
      "x": -17,
      "y": 9,
      "z": 7,
      "name": "Rock_Marble"
    },
    {
      "x": -17,
      "y": 10,
      "z": 7,
      "name": "Rock_Marble"
    },
    {
      "x": -17,
      "y": 11,
      "z": 7,
      "name": "Rubble_Marble"
    },
    {
      "x": -17,
      "y": 7,
      "z": 8,
      "name": "Rock_Marble"
    },
    {
      "x": -17,
      "y": 8,
      "z": 8,
      "name": "Rock_Marble"
    },
    {
      "x": -17,
      "y": 9,
      "z": 8,
      "name": "Rock_Marble"
    },
    {
      "x": -17,
      "y": 10,
      "z": 8,
      "name": "Rock_Marble"
    },
    {
      "x": -17,
      "y": 8,
      "z": 9,
      "name": "Rock_Marble"
    },
    {
      "x": -17,
      "y": 9,
      "z": 9,
      "name": "Rock_Marble"
    },
    {
      "x": -17,
      "y": 10,
      "z": 9,
      "name": "Rock_Marble"
    },
    {
      "x": -17,
      "y": 8,
      "z": 10,
      "name": "Rock_Marble"
    },
    {
      "x": -17,
      "y": 9,
      "z": 10,
      "name": "Rock_Marble"
    },
    {
      "x": -17,
      "y": 10,
      "z": 10,
      "name": "Rock_Marble"
    },
    {
      "x": -17,
      "y": 8,
      "z": 11,
      "name": "Rock_Marble"
    },
    {
      "x": -17,
      "y": 9,
      "z": 11,
      "name": "Rock_Marble"
    },
    {
      "x": -17,
      "y": 10,
      "z": 11,
      "name": "Rock_Marble"
    },
    {
      "x": -17,
      "y": 9,
      "z": 12,
      "name": "Rock_Marble"
    },
    {
      "x": -17,
      "y": 10,
      "z": 12,
      "name": "Rock_Marble"
    },
    {
      "x": -17,
      "y": 11,
      "z": 12,
      "name": "Rubble_Marble"
    },
    {
      "x": -17,
      "y": 9,
      "z": 13,
      "name": "Rock_Marble"
    },
    {
      "x": -17,
      "y": 10,
      "z": 13,
      "name": "Rock_Marble"
    },
    {
      "x": -17,
      "y": 9,
      "z": 14,
      "name": "Rock_Marble"
    },
    {
      "x": -17,
      "y": 10,
      "z": 14,
      "name": "Rock_Marble"
    },
    {
      "x": -17,
      "y": 9,
      "z": 15,
      "name": "Rock_Marble"
    },
    {
      "x": -16,
      "y": 9,
      "z": -12,
      "name": "Rock_Marble"
    },
    {
      "x": -16,
      "y": 8,
      "z": -11,
      "name": "Rock_Marble"
    },
    {
      "x": -16,
      "y": 9,
      "z": -11,
      "name": "Rock_Marble"
    },
    {
      "x": -16,
      "y": 7,
      "z": -10,
      "name": "Rock_Marble"
    },
    {
      "x": -16,
      "y": 8,
      "z": -10,
      "name": "Rock_Marble"
    },
    {
      "x": -16,
      "y": 9,
      "z": -10,
      "name": "Rock_Marble"
    },
    {
      "x": -16,
      "y": 10,
      "z": -10,
      "name": "Rock_Marble"
    },
    {
      "x": -16,
      "y": 6,
      "z": -9,
      "name": "Rock_Marble"
    },
    {
      "x": -16,
      "y": 7,
      "z": -9,
      "name": "Rock_Marble"
    },
    {
      "x": -16,
      "y": 8,
      "z": -9,
      "name": "Rock_Marble"
    },
    {
      "x": -16,
      "y": 9,
      "z": -9,
      "name": "Rock_Marble"
    },
    {
      "x": -16,
      "y": 10,
      "z": -9,
      "name": "Rock_Marble"
    },
    {
      "x": -16,
      "y": 6,
      "z": -8,
      "name": "Rock_Marble"
    },
    {
      "x": -16,
      "y": 7,
      "z": -8,
      "name": "Rock_Marble"
    },
    {
      "x": -16,
      "y": 8,
      "z": -8,
      "name": "Rock_Marble"
    },
    {
      "x": -16,
      "y": 9,
      "z": -8,
      "name": "Rock_Marble"
    },
    {
      "x": -16,
      "y": 10,
      "z": -8,
      "name": "Rock_Marble"
    },
    {
      "x": -16,
      "y": 11,
      "z": -8,
      "name": "Plant_Crop_Mushroom_Glowing_Blue"
    },
    {
      "x": -16,
      "y": 5,
      "z": -7,
      "name": "Rock_Marble"
    },
    {
      "x": -16,
      "y": 6,
      "z": -7,
      "name": "Rock_Marble"
    },
    {
      "x": -16,
      "y": 7,
      "z": -7,
      "name": "Rock_Marble"
    },
    {
      "x": -16,
      "y": 8,
      "z": -7,
      "name": "Rock_Marble"
    },
    {
      "x": -16,
      "y": 9,
      "z": -7,
      "name": "Rock_Marble"
    },
    {
      "x": -16,
      "y": 10,
      "z": -7,
      "name": "Rock_Marble"
    },
    {
      "x": -16,
      "y": 5,
      "z": -6,
      "name": "Rock_Marble"
    },
    {
      "x": -16,
      "y": 6,
      "z": -6,
      "name": "Rock_Marble"
    },
    {
      "x": -16,
      "y": 7,
      "z": -6,
      "name": "Rock_Marble"
    },
    {
      "x": -16,
      "y": 8,
      "z": -6,
      "name": "Rock_Marble"
    },
    {
      "x": -16,
      "y": 9,
      "z": -6,
      "name": "Rock_Marble"
    },
    {
      "x": -16,
      "y": 10,
      "z": -6,
      "name": "Rock_Marble"
    },
    {
      "x": -16,
      "y": 5,
      "z": -5,
      "name": "Rock_Marble"
    },
    {
      "x": -16,
      "y": 6,
      "z": -5,
      "name": "Rock_Marble"
    },
    {
      "x": -16,
      "y": 7,
      "z": -5,
      "name": "Rock_Marble"
    },
    {
      "x": -16,
      "y": 8,
      "z": -5,
      "name": "Rock_Marble"
    },
    {
      "x": -16,
      "y": 9,
      "z": -5,
      "name": "Rock_Marble"
    },
    {
      "x": -16,
      "y": 10,
      "z": -5,
      "name": "Rock_Marble"
    },
    {
      "x": -16,
      "y": 5,
      "z": -4,
      "name": "Rock_Marble"
    },
    {
      "x": -16,
      "y": 6,
      "z": -4,
      "name": "Rock_Marble"
    },
    {
      "x": -16,
      "y": 7,
      "z": -4,
      "name": "Rock_Marble"
    },
    {
      "x": -16,
      "y": 8,
      "z": -4,
      "name": "Rock_Marble"
    },
    {
      "x": -16,
      "y": 9,
      "z": -4,
      "name": "Rock_Marble"
    },
    {
      "x": -16,
      "y": 10,
      "z": -4,
      "name": "Rock_Marble"
    },
    {
      "x": -16,
      "y": 5,
      "z": -3,
      "name": "Rock_Marble"
    },
    {
      "x": -16,
      "y": 6,
      "z": -3,
      "name": "Rock_Marble"
    },
    {
      "x": -16,
      "y": 7,
      "z": -3,
      "name": "Rock_Marble"
    },
    {
      "x": -16,
      "y": 8,
      "z": -3,
      "name": "Rock_Marble"
    },
    {
      "x": -16,
      "y": 9,
      "z": -3,
      "name": "Rock_Marble"
    },
    {
      "x": -16,
      "y": 10,
      "z": -3,
      "name": "Rock_Marble"
    },
    {
      "x": -16,
      "y": 5,
      "z": -2,
      "name": "Rock_Marble"
    },
    {
      "x": -16,
      "y": 6,
      "z": -2,
      "name": "Rock_Marble"
    },
    {
      "x": -16,
      "y": 7,
      "z": -2,
      "name": "Rock_Marble"
    },
    {
      "x": -16,
      "y": 8,
      "z": -2,
      "name": "Rock_Marble"
    },
    {
      "x": -16,
      "y": 9,
      "z": -2,
      "name": "Rock_Marble"
    },
    {
      "x": -16,
      "y": 10,
      "z": -2,
      "name": "Rock_Marble"
    },
    {
      "x": -16,
      "y": 5,
      "z": -1,
      "name": "Rock_Marble"
    },
    {
      "x": -16,
      "y": 6,
      "z": -1,
      "name": "Rock_Marble"
    },
    {
      "x": -16,
      "y": 7,
      "z": -1,
      "name": "Rock_Marble"
    },
    {
      "x": -16,
      "y": 9,
      "z": -1,
      "name": "Rock_Marble"
    },
    {
      "x": -16,
      "y": 10,
      "z": -1,
      "name": "Rock_Marble"
    },
    {
      "x": -16,
      "y": 5,
      "z": 0,
      "name": "Rock_Marble"
    },
    {
      "x": -16,
      "y": 6,
      "z": 0,
      "name": "Rock_Marble"
    },
    {
      "x": -16,
      "y": 7,
      "z": 0,
      "name": "Rock_Marble"
    },
    {
      "x": -16,
      "y": 8,
      "z": 0,
      "name": "Rock_Marble"
    },
    {
      "x": -16,
      "y": 9,
      "z": 0,
      "name": "Rock_Marble"
    },
    {
      "x": -16,
      "y": 10,
      "z": 0,
      "name": "Rock_Marble"
    },
    {
      "x": -16,
      "y": 6,
      "z": 1,
      "name": "Rock_Marble"
    },
    {
      "x": -16,
      "y": 7,
      "z": 1,
      "name": "Rock_Marble"
    },
    {
      "x": -16,
      "y": 8,
      "z": 1,
      "name": "Rock_Marble"
    },
    {
      "x": -16,
      "y": 9,
      "z": 1,
      "name": "Rock_Marble"
    },
    {
      "x": -16,
      "y": 10,
      "z": 1,
      "name": "Rock_Marble"
    },
    {
      "x": -16,
      "y": 6,
      "z": 2,
      "name": "Rock_Marble"
    },
    {
      "x": -16,
      "y": 7,
      "z": 2,
      "name": "Rock_Marble"
    },
    {
      "x": -16,
      "y": 8,
      "z": 2,
      "name": "Rock_Marble"
    },
    {
      "x": -16,
      "y": 9,
      "z": 2,
      "name": "Rock_Marble"
    },
    {
      "x": -16,
      "y": 10,
      "z": 2,
      "name": "Rock_Marble"
    },
    {
      "x": -16,
      "y": 6,
      "z": 3,
      "name": "Rock_Marble"
    },
    {
      "x": -16,
      "y": 7,
      "z": 3,
      "name": "Rock_Marble"
    },
    {
      "x": -16,
      "y": 8,
      "z": 3,
      "name": "Rock_Marble"
    },
    {
      "x": -16,
      "y": 9,
      "z": 3,
      "name": "Rock_Marble"
    },
    {
      "x": -16,
      "y": 10,
      "z": 3,
      "name": "Rock_Marble"
    },
    {
      "x": -16,
      "y": 6,
      "z": 4,
      "name": "Rock_Marble"
    },
    {
      "x": -16,
      "y": 7,
      "z": 4,
      "name": "Rock_Marble"
    },
    {
      "x": -16,
      "y": 8,
      "z": 4,
      "name": "Rock_Marble"
    },
    {
      "x": -16,
      "y": 9,
      "z": 4,
      "name": "Rock_Marble"
    },
    {
      "x": -16,
      "y": 10,
      "z": 4,
      "name": "Rock_Marble"
    },
    {
      "x": -16,
      "y": 6,
      "z": 5,
      "name": "Rock_Marble"
    },
    {
      "x": -16,
      "y": 7,
      "z": 5,
      "name": "Rock_Marble"
    },
    {
      "x": -16,
      "y": 8,
      "z": 5,
      "name": "Rock_Marble"
    },
    {
      "x": -16,
      "y": 9,
      "z": 5,
      "name": "Rock_Marble"
    },
    {
      "x": -16,
      "y": 10,
      "z": 5,
      "name": "Rock_Marble"
    },
    {
      "x": -16,
      "y": 6,
      "z": 6,
      "name": "Rock_Marble"
    },
    {
      "x": -16,
      "y": 7,
      "z": 6,
      "name": "Rock_Marble"
    },
    {
      "x": -16,
      "y": 8,
      "z": 6,
      "name": "Rock_Marble"
    },
    {
      "x": -16,
      "y": 9,
      "z": 6,
      "name": "Rock_Marble"
    },
    {
      "x": -16,
      "y": 10,
      "z": 6,
      "name": "Rock_Marble"
    },
    {
      "x": -16,
      "y": 6,
      "z": 7,
      "name": "Rock_Marble"
    },
    {
      "x": -16,
      "y": 7,
      "z": 7,
      "name": "Rock_Marble"
    },
    {
      "x": -16,
      "y": 8,
      "z": 7,
      "name": "Rock_Marble"
    },
    {
      "x": -16,
      "y": 9,
      "z": 7,
      "name": "Rock_Marble"
    },
    {
      "x": -16,
      "y": 10,
      "z": 7,
      "name": "Rock_Marble"
    },
    {
      "x": -16,
      "y": 6,
      "z": 8,
      "name": "Rock_Marble"
    },
    {
      "x": -16,
      "y": 7,
      "z": 8,
      "name": "Rock_Marble"
    },
    {
      "x": -16,
      "y": 8,
      "z": 8,
      "name": "Rock_Marble"
    },
    {
      "x": -16,
      "y": 9,
      "z": 8,
      "name": "Rock_Marble"
    },
    {
      "x": -16,
      "y": 10,
      "z": 8,
      "name": "Rock_Marble"
    },
    {
      "x": -16,
      "y": 6,
      "z": 9,
      "name": "Rock_Marble"
    },
    {
      "x": -16,
      "y": 7,
      "z": 9,
      "name": "Rock_Marble"
    },
    {
      "x": -16,
      "y": 8,
      "z": 9,
      "name": "Rock_Marble"
    },
    {
      "x": -16,
      "y": 9,
      "z": 9,
      "name": "Rock_Marble"
    },
    {
      "x": -16,
      "y": 10,
      "z": 9,
      "name": "Rock_Marble"
    },
    {
      "x": -16,
      "y": 11,
      "z": 9,
      "name": "Plant_Crop_Mushroom_Glowing_Blue"
    },
    {
      "x": -16,
      "y": 7,
      "z": 10,
      "name": "Rock_Marble"
    },
    {
      "x": -16,
      "y": 8,
      "z": 10,
      "name": "Rock_Marble"
    },
    {
      "x": -16,
      "y": 9,
      "z": 10,
      "name": "Rock_Marble"
    },
    {
      "x": -16,
      "y": 10,
      "z": 10,
      "name": "Rock_Marble"
    },
    {
      "x": -16,
      "y": 7,
      "z": 11,
      "name": "Rock_Marble"
    },
    {
      "x": -16,
      "y": 8,
      "z": 11,
      "name": "Rock_Marble"
    },
    {
      "x": -16,
      "y": 9,
      "z": 11,
      "name": "Rock_Marble"
    },
    {
      "x": -16,
      "y": 10,
      "z": 11,
      "name": "Rock_Marble"
    },
    {
      "x": -16,
      "y": 7,
      "z": 12,
      "name": "Rock_Marble"
    },
    {
      "x": -16,
      "y": 8,
      "z": 12,
      "name": "Rock_Marble"
    },
    {
      "x": -16,
      "y": 9,
      "z": 12,
      "name": "Rock_Marble"
    },
    {
      "x": -16,
      "y": 10,
      "z": 12,
      "name": "Rock_Marble"
    },
    {
      "x": -16,
      "y": 8,
      "z": 13,
      "name": "Rock_Marble"
    },
    {
      "x": -16,
      "y": 9,
      "z": 13,
      "name": "Rock_Marble"
    },
    {
      "x": -16,
      "y": 10,
      "z": 13,
      "name": "Rock_Marble"
    },
    {
      "x": -16,
      "y": 9,
      "z": 14,
      "name": "Rock_Marble"
    },
    {
      "x": -16,
      "y": 10,
      "z": 14,
      "name": "Rock_Marble"
    },
    {
      "x": -16,
      "y": 9,
      "z": 15,
      "name": "Rock_Marble"
    },
    {
      "x": -16,
      "y": 10,
      "z": 15,
      "name": "Rock_Marble"
    },
    {
      "x": -16,
      "y": 11,
      "z": 15,
      "name": "Rock_Marble_Stalactite_Small"
    },
    {
      "x": -16,
      "y": 9,
      "z": 16,
      "name": "Rock_Marble"
    },
    {
      "x": -15,
      "y": 9,
      "z": -14,
      "name": "Rock_Marble"
    },
    {
      "x": -15,
      "y": 9,
      "z": -13,
      "name": "Rock_Marble"
    },
    {
      "x": -15,
      "y": 10,
      "z": -13,
      "name": "Rock_Marble"
    },
    {
      "x": -15,
      "y": 7,
      "z": -12,
      "name": "Rock_Marble"
    },
    {
      "x": -15,
      "y": 8,
      "z": -12,
      "name": "Rock_Marble"
    },
    {
      "x": -15,
      "y": 9,
      "z": -12,
      "name": "Rock_Marble"
    },
    {
      "x": -15,
      "y": 10,
      "z": -12,
      "name": "Rock_Marble"
    },
    {
      "x": -15,
      "y": 7,
      "z": -11,
      "name": "Rock_Marble"
    },
    {
      "x": -15,
      "y": 8,
      "z": -11,
      "name": "Rock_Marble"
    },
    {
      "x": -15,
      "y": 9,
      "z": -11,
      "name": "Rock_Marble"
    },
    {
      "x": -15,
      "y": 10,
      "z": -11,
      "name": "Rock_Marble"
    },
    {
      "x": -15,
      "y": 6,
      "z": -10,
      "name": "Rock_Marble"
    },
    {
      "x": -15,
      "y": 7,
      "z": -10,
      "name": "Rock_Marble"
    },
    {
      "x": -15,
      "y": 8,
      "z": -10,
      "name": "Rock_Marble"
    },
    {
      "x": -15,
      "y": 9,
      "z": -10,
      "name": "Rock_Marble"
    },
    {
      "x": -15,
      "y": 10,
      "z": -10,
      "name": "Rock_Marble"
    },
    {
      "x": -15,
      "y": 5,
      "z": -9,
      "name": "Rock_Marble"
    },
    {
      "x": -15,
      "y": 6,
      "z": -9,
      "name": "Rock_Marble"
    },
    {
      "x": -15,
      "y": 7,
      "z": -9,
      "name": "Rock_Marble"
    },
    {
      "x": -15,
      "y": 8,
      "z": -9,
      "name": "Rock_Marble"
    },
    {
      "x": -15,
      "y": 9,
      "z": -9,
      "name": "Rock_Marble"
    },
    {
      "x": -15,
      "y": 10,
      "z": -9,
      "name": "Rock_Marble"
    },
    {
      "x": -15,
      "y": 5,
      "z": -8,
      "name": "Rock_Marble"
    },
    {
      "x": -15,
      "y": 6,
      "z": -8,
      "name": "Rock_Marble"
    },
    {
      "x": -15,
      "y": 7,
      "z": -8,
      "name": "Rock_Marble"
    },
    {
      "x": -15,
      "y": 8,
      "z": -8,
      "name": "Rock_Marble"
    },
    {
      "x": -15,
      "y": 9,
      "z": -8,
      "name": "Rock_Marble"
    },
    {
      "x": -15,
      "y": 10,
      "z": -8,
      "name": "Rock_Marble"
    },
    {
      "x": -15,
      "y": 4,
      "z": -7,
      "name": "Rock_Marble"
    },
    {
      "x": -15,
      "y": 5,
      "z": -7,
      "name": "Rock_Marble"
    },
    {
      "x": -15,
      "y": 6,
      "z": -7,
      "name": "Rock_Marble"
    },
    {
      "x": -15,
      "y": 7,
      "z": -7,
      "name": "Rock_Marble"
    },
    {
      "x": -15,
      "y": 8,
      "z": -7,
      "name": "Rock_Marble"
    },
    {
      "x": -15,
      "y": 9,
      "z": -7,
      "name": "Rock_Marble"
    },
    {
      "x": -15,
      "y": 10,
      "z": -7,
      "name": "Rock_Marble"
    },
    {
      "x": -15,
      "y": 4,
      "z": -6,
      "name": "Rock_Marble"
    },
    {
      "x": -15,
      "y": 5,
      "z": -6,
      "name": "Rock_Marble"
    },
    {
      "x": -15,
      "y": 6,
      "z": -6,
      "name": "Rock_Marble"
    },
    {
      "x": -15,
      "y": 7,
      "z": -6,
      "name": "Rock_Marble"
    },
    {
      "x": -15,
      "y": 8,
      "z": -6,
      "name": "Rock_Marble"
    },
    {
      "x": -15,
      "y": 9,
      "z": -6,
      "name": "Rock_Marble"
    },
    {
      "x": -15,
      "y": 10,
      "z": -6,
      "name": "Rock_Marble"
    },
    {
      "x": -15,
      "y": 4,
      "z": -5,
      "name": "Rock_Marble"
    },
    {
      "x": -15,
      "y": 5,
      "z": -5,
      "name": "Rock_Marble"
    },
    {
      "x": -15,
      "y": 6,
      "z": -5,
      "name": "Rock_Marble"
    },
    {
      "x": -15,
      "y": 7,
      "z": -5,
      "name": "Rock_Marble"
    },
    {
      "x": -15,
      "y": 8,
      "z": -5,
      "name": "Rock_Marble"
    },
    {
      "x": -15,
      "y": 9,
      "z": -5,
      "name": "Rock_Marble"
    },
    {
      "x": -15,
      "y": 10,
      "z": -5,
      "name": "Rock_Marble"
    },
    {
      "x": -15,
      "y": 4,
      "z": -4,
      "name": "Rock_Marble"
    },
    {
      "x": -15,
      "y": 5,
      "z": -4,
      "name": "Rock_Marble"
    },
    {
      "x": -15,
      "y": 6,
      "z": -4,
      "name": "Rock_Marble"
    },
    {
      "x": -15,
      "y": 7,
      "z": -4,
      "name": "Rock_Marble"
    },
    {
      "x": -15,
      "y": 8,
      "z": -4,
      "name": "Rock_Marble"
    },
    {
      "x": -15,
      "y": 9,
      "z": -4,
      "name": "Rock_Marble"
    },
    {
      "x": -15,
      "y": 10,
      "z": -4,
      "name": "Rock_Marble"
    },
    {
      "x": -15,
      "y": 4,
      "z": -3,
      "name": "Rock_Marble"
    },
    {
      "x": -15,
      "y": 5,
      "z": -3,
      "name": "Rock_Marble"
    },
    {
      "x": -15,
      "y": 6,
      "z": -3,
      "name": "Rock_Marble"
    },
    {
      "x": -15,
      "y": 7,
      "z": -3,
      "name": "Rock_Marble"
    },
    {
      "x": -15,
      "y": 8,
      "z": -3,
      "name": "Rock_Marble"
    },
    {
      "x": -15,
      "y": 9,
      "z": -3,
      "name": "Rock_Marble"
    },
    {
      "x": -15,
      "y": 10,
      "z": -3,
      "name": "Rock_Marble"
    },
    {
      "x": -15,
      "y": 4,
      "z": -2,
      "name": "Rock_Marble"
    },
    {
      "x": -15,
      "y": 5,
      "z": -2,
      "name": "Rock_Marble"
    },
    {
      "x": -15,
      "y": 6,
      "z": -2,
      "name": "Rock_Marble"
    },
    {
      "x": -15,
      "y": 7,
      "z": -2,
      "name": "Rock_Marble"
    },
    {
      "x": -15,
      "y": 8,
      "z": -2,
      "name": "Rock_Marble"
    },
    {
      "x": -15,
      "y": 9,
      "z": -2,
      "name": "Rock_Marble"
    },
    {
      "x": -15,
      "y": 10,
      "z": -2,
      "name": "Rock_Marble"
    },
    {
      "x": -15,
      "y": 4,
      "z": -1,
      "name": "Rock_Marble"
    },
    {
      "x": -15,
      "y": 5,
      "z": -1,
      "name": "Rock_Marble"
    },
    {
      "x": -15,
      "y": 6,
      "z": -1,
      "name": "Rock_Marble"
    },
    {
      "x": -15,
      "y": 7,
      "z": -1,
      "name": "Rock_Marble"
    },
    {
      "x": -15,
      "y": 8,
      "z": -1,
      "name": "Rock_Marble"
    },
    {
      "x": -15,
      "y": 9,
      "z": -1,
      "name": "Rock_Marble"
    },
    {
      "x": -15,
      "y": 10,
      "z": -1,
      "name": "Rock_Marble"
    },
    {
      "x": -15,
      "y": 4,
      "z": 0,
      "name": "Rock_Marble"
    },
    {
      "x": -15,
      "y": 5,
      "z": 0,
      "name": "Rock_Marble"
    },
    {
      "x": -15,
      "y": 6,
      "z": 0,
      "name": "Rock_Marble"
    },
    {
      "x": -15,
      "y": 7,
      "z": 0,
      "name": "Rock_Marble"
    },
    {
      "x": -15,
      "y": 9,
      "z": 0,
      "name": "Rock_Marble"
    },
    {
      "x": -15,
      "y": 10,
      "z": 0,
      "name": "Rock_Marble"
    },
    {
      "x": -15,
      "y": 11,
      "z": 0,
      "name": "Deco_Bone_Pile"
    },
    {
      "x": -15,
      "y": 4,
      "z": 1,
      "name": "Rock_Marble"
    },
    {
      "x": -15,
      "y": 5,
      "z": 1,
      "name": "Rock_Marble"
    },
    {
      "x": -15,
      "y": 6,
      "z": 1,
      "name": "Rock_Marble"
    },
    {
      "x": -15,
      "y": 7,
      "z": 1,
      "name": "Rock_Marble"
    },
    {
      "x": -15,
      "y": 8,
      "z": 1,
      "name": "Rock_Marble"
    },
    {
      "x": -15,
      "y": 9,
      "z": 1,
      "name": "Rock_Marble"
    },
    {
      "x": -15,
      "y": 10,
      "z": 1,
      "name": "Rock_Marble"
    },
    {
      "x": -15,
      "y": 5,
      "z": 2,
      "name": "Rock_Marble"
    },
    {
      "x": -15,
      "y": 6,
      "z": 2,
      "name": "Rock_Marble"
    },
    {
      "x": -15,
      "y": 7,
      "z": 2,
      "name": "Rock_Marble"
    },
    {
      "x": -15,
      "y": 8,
      "z": 2,
      "name": "Rock_Marble"
    },
    {
      "x": -15,
      "y": 9,
      "z": 2,
      "name": "Rock_Marble"
    },
    {
      "x": -15,
      "y": 10,
      "z": 2,
      "name": "Rock_Marble"
    },
    {
      "x": -15,
      "y": 5,
      "z": 3,
      "name": "Rock_Marble"
    },
    {
      "x": -15,
      "y": 6,
      "z": 3,
      "name": "Rock_Marble"
    },
    {
      "x": -15,
      "y": 7,
      "z": 3,
      "name": "Rock_Marble"
    },
    {
      "x": -15,
      "y": 8,
      "z": 3,
      "name": "Rock_Marble"
    },
    {
      "x": -15,
      "y": 9,
      "z": 3,
      "name": "Rock_Marble"
    },
    {
      "x": -15,
      "y": 10,
      "z": 3,
      "name": "Rock_Marble"
    },
    {
      "x": -15,
      "y": 5,
      "z": 4,
      "name": "Rock_Marble"
    },
    {
      "x": -15,
      "y": 6,
      "z": 4,
      "name": "Rock_Marble"
    },
    {
      "x": -15,
      "y": 7,
      "z": 4,
      "name": "Rock_Marble"
    },
    {
      "x": -15,
      "y": 8,
      "z": 4,
      "name": "Rock_Marble"
    },
    {
      "x": -15,
      "y": 9,
      "z": 4,
      "name": "Rock_Marble"
    },
    {
      "x": -15,
      "y": 10,
      "z": 4,
      "name": "Rock_Marble"
    },
    {
      "x": -15,
      "y": 5,
      "z": 5,
      "name": "Rock_Marble"
    },
    {
      "x": -15,
      "y": 6,
      "z": 5,
      "name": "Rock_Marble"
    },
    {
      "x": -15,
      "y": 7,
      "z": 5,
      "name": "Rock_Marble"
    },
    {
      "x": -15,
      "y": 8,
      "z": 5,
      "name": "Rock_Marble"
    },
    {
      "x": -15,
      "y": 9,
      "z": 5,
      "name": "Rock_Marble"
    },
    {
      "x": -15,
      "y": 10,
      "z": 5,
      "name": "Rock_Marble"
    },
    {
      "x": -15,
      "y": 5,
      "z": 6,
      "name": "Rock_Marble"
    },
    {
      "x": -15,
      "y": 6,
      "z": 6,
      "name": "Rock_Marble"
    },
    {
      "x": -15,
      "y": 7,
      "z": 6,
      "name": "Rock_Marble"
    },
    {
      "x": -15,
      "y": 8,
      "z": 6,
      "name": "Rock_Marble"
    },
    {
      "x": -15,
      "y": 9,
      "z": 6,
      "name": "Rock_Marble"
    },
    {
      "x": -15,
      "y": 10,
      "z": 6,
      "name": "Rock_Marble"
    },
    {
      "x": -15,
      "y": 5,
      "z": 7,
      "name": "Rock_Marble"
    },
    {
      "x": -15,
      "y": 6,
      "z": 7,
      "name": "Rock_Marble"
    },
    {
      "x": -15,
      "y": 7,
      "z": 7,
      "name": "Rock_Marble"
    },
    {
      "x": -15,
      "y": 8,
      "z": 7,
      "name": "Rock_Marble"
    },
    {
      "x": -15,
      "y": 9,
      "z": 7,
      "name": "Rock_Marble"
    },
    {
      "x": -15,
      "y": 10,
      "z": 7,
      "name": "Rock_Marble"
    },
    {
      "x": -15,
      "y": 5,
      "z": 8,
      "name": "Rock_Marble"
    },
    {
      "x": -15,
      "y": 6,
      "z": 8,
      "name": "Rock_Marble"
    },
    {
      "x": -15,
      "y": 7,
      "z": 8,
      "name": "Rock_Marble"
    },
    {
      "x": -15,
      "y": 8,
      "z": 8,
      "name": "Rock_Marble"
    },
    {
      "x": -15,
      "y": 9,
      "z": 8,
      "name": "Rock_Marble"
    },
    {
      "x": -15,
      "y": 10,
      "z": 8,
      "name": "Rock_Marble"
    },
    {
      "x": -15,
      "y": 5,
      "z": 9,
      "name": "Rock_Marble"
    },
    {
      "x": -15,
      "y": 6,
      "z": 9,
      "name": "Rock_Marble"
    },
    {
      "x": -15,
      "y": 7,
      "z": 9,
      "name": "Rock_Marble"
    },
    {
      "x": -15,
      "y": 8,
      "z": 9,
      "name": "Rock_Marble"
    },
    {
      "x": -15,
      "y": 9,
      "z": 9,
      "name": "Rock_Marble"
    },
    {
      "x": -15,
      "y": 10,
      "z": 9,
      "name": "Rock_Marble"
    },
    {
      "x": -15,
      "y": 5,
      "z": 10,
      "name": "Rock_Marble"
    },
    {
      "x": -15,
      "y": 6,
      "z": 10,
      "name": "Rock_Marble"
    },
    {
      "x": -15,
      "y": 7,
      "z": 10,
      "name": "Rock_Marble"
    },
    {
      "x": -15,
      "y": 8,
      "z": 10,
      "name": "Rock_Marble"
    },
    {
      "x": -15,
      "y": 9,
      "z": 10,
      "name": "Rock_Marble"
    },
    {
      "x": -15,
      "y": 10,
      "z": 10,
      "name": "Rock_Marble"
    },
    {
      "x": -15,
      "y": 6,
      "z": 11,
      "name": "Rock_Marble"
    },
    {
      "x": -15,
      "y": 7,
      "z": 11,
      "name": "Rock_Marble"
    },
    {
      "x": -15,
      "y": 8,
      "z": 11,
      "name": "Rock_Marble"
    },
    {
      "x": -15,
      "y": 9,
      "z": 11,
      "name": "Rock_Marble"
    },
    {
      "x": -15,
      "y": 10,
      "z": 11,
      "name": "Rock_Marble"
    },
    {
      "x": -15,
      "y": 7,
      "z": 12,
      "name": "Rock_Marble"
    },
    {
      "x": -15,
      "y": 8,
      "z": 12,
      "name": "Rock_Marble"
    },
    {
      "x": -15,
      "y": 9,
      "z": 12,
      "name": "Rock_Marble"
    },
    {
      "x": -15,
      "y": 10,
      "z": 12,
      "name": "Rock_Marble"
    },
    {
      "x": -15,
      "y": 7,
      "z": 13,
      "name": "Rock_Marble"
    },
    {
      "x": -15,
      "y": 8,
      "z": 13,
      "name": "Rock_Marble"
    },
    {
      "x": -15,
      "y": 9,
      "z": 13,
      "name": "Rock_Marble"
    },
    {
      "x": -15,
      "y": 10,
      "z": 13,
      "name": "Rock_Marble"
    },
    {
      "x": -15,
      "y": 8,
      "z": 14,
      "name": "Rock_Marble"
    },
    {
      "x": -15,
      "y": 9,
      "z": 14,
      "name": "Rock_Marble"
    },
    {
      "x": -15,
      "y": 10,
      "z": 14,
      "name": "Rock_Marble"
    },
    {
      "x": -15,
      "y": 8,
      "z": 15,
      "name": "Rock_Marble"
    },
    {
      "x": -15,
      "y": 9,
      "z": 15,
      "name": "Rock_Marble"
    },
    {
      "x": -15,
      "y": 10,
      "z": 15,
      "name": "Rock_Marble"
    },
    {
      "x": -15,
      "y": 11,
      "z": 15,
      "name": "Rubble_Marble_Medium"
    },
    {
      "x": -15,
      "y": 9,
      "z": 16,
      "name": "Rock_Marble"
    },
    {
      "x": -14,
      "y": 9,
      "z": -15,
      "name": "Rock_Marble"
    },
    {
      "x": -14,
      "y": 9,
      "z": -14,
      "name": "Rock_Marble"
    },
    {
      "x": -14,
      "y": 10,
      "z": -14,
      "name": "Rock_Marble"
    },
    {
      "x": -14,
      "y": 7,
      "z": -13,
      "name": "Rock_Marble"
    },
    {
      "x": -14,
      "y": 8,
      "z": -13,
      "name": "Rock_Marble"
    },
    {
      "x": -14,
      "y": 9,
      "z": -13,
      "name": "Rock_Marble"
    },
    {
      "x": -14,
      "y": 10,
      "z": -13,
      "name": "Rock_Marble"
    },
    {
      "x": -14,
      "y": 6,
      "z": -12,
      "name": "Rock_Marble"
    },
    {
      "x": -14,
      "y": 7,
      "z": -12,
      "name": "Rock_Marble"
    },
    {
      "x": -14,
      "y": 8,
      "z": -12,
      "name": "Rock_Marble"
    },
    {
      "x": -14,
      "y": 9,
      "z": -12,
      "name": "Rock_Marble"
    },
    {
      "x": -14,
      "y": 10,
      "z": -12,
      "name": "Rock_Marble"
    },
    {
      "x": -14,
      "y": 5,
      "z": -11,
      "name": "Rock_Marble"
    },
    {
      "x": -14,
      "y": 6,
      "z": -11,
      "name": "Rock_Marble"
    },
    {
      "x": -14,
      "y": 7,
      "z": -11,
      "name": "Rock_Marble"
    },
    {
      "x": -14,
      "y": 8,
      "z": -11,
      "name": "Rock_Marble"
    },
    {
      "x": -14,
      "y": 9,
      "z": -11,
      "name": "Rock_Marble"
    },
    {
      "x": -14,
      "y": 10,
      "z": -11,
      "name": "Rock_Marble"
    },
    {
      "x": -14,
      "y": 5,
      "z": -10,
      "name": "Rock_Marble"
    },
    {
      "x": -14,
      "y": 6,
      "z": -10,
      "name": "Rock_Marble"
    },
    {
      "x": -14,
      "y": 7,
      "z": -10,
      "name": "Rock_Marble"
    },
    {
      "x": -14,
      "y": 8,
      "z": -10,
      "name": "Rock_Marble"
    },
    {
      "x": -14,
      "y": 9,
      "z": -10,
      "name": "Rock_Marble"
    },
    {
      "x": -14,
      "y": 10,
      "z": -10,
      "name": "Rock_Marble"
    },
    {
      "x": -14,
      "y": 4,
      "z": -9,
      "name": "Rock_Marble"
    },
    {
      "x": -14,
      "y": 5,
      "z": -9,
      "name": "Rock_Marble"
    },
    {
      "x": -14,
      "y": 6,
      "z": -9,
      "name": "Rock_Marble"
    },
    {
      "x": -14,
      "y": 7,
      "z": -9,
      "name": "Rock_Marble"
    },
    {
      "x": -14,
      "y": 8,
      "z": -9,
      "name": "Rock_Marble"
    },
    {
      "x": -14,
      "y": 9,
      "z": -9,
      "name": "Rock_Marble"
    },
    {
      "x": -14,
      "y": 10,
      "z": -9,
      "name": "Rock_Marble"
    },
    {
      "x": -14,
      "y": 4,
      "z": -8,
      "name": "Rock_Marble"
    },
    {
      "x": -14,
      "y": 5,
      "z": -8,
      "name": "Rock_Marble"
    },
    {
      "x": -14,
      "y": 6,
      "z": -8,
      "name": "Rock_Marble"
    },
    {
      "x": -14,
      "y": 7,
      "z": -8,
      "name": "Rock_Marble"
    },
    {
      "x": -14,
      "y": 8,
      "z": -8,
      "name": "Rock_Marble"
    },
    {
      "x": -14,
      "y": 9,
      "z": -8,
      "name": "Rock_Marble"
    },
    {
      "x": -14,
      "y": 10,
      "z": -8,
      "name": "Rock_Marble"
    },
    {
      "x": -14,
      "y": 4,
      "z": -7,
      "name": "Rock_Marble"
    },
    {
      "x": -14,
      "y": 5,
      "z": -7,
      "name": "Rock_Marble"
    },
    {
      "x": -14,
      "y": 6,
      "z": -7,
      "name": "Rock_Marble"
    },
    {
      "x": -14,
      "y": 7,
      "z": -7,
      "name": "Rock_Marble"
    },
    {
      "x": -14,
      "y": 8,
      "z": -7,
      "name": "Rock_Marble"
    },
    {
      "x": -14,
      "y": 9,
      "z": -7,
      "name": "Rock_Marble"
    },
    {
      "x": -14,
      "y": 10,
      "z": -7,
      "name": "Rock_Marble"
    },
    {
      "x": -14,
      "y": 3,
      "z": -6,
      "name": "Rock_Marble"
    },
    {
      "x": -14,
      "y": 4,
      "z": -6,
      "name": "Rock_Marble"
    },
    {
      "x": -14,
      "y": 5,
      "z": -6,
      "name": "Rock_Marble"
    },
    {
      "x": -14,
      "y": 6,
      "z": -6,
      "name": "Rock_Marble"
    },
    {
      "x": -14,
      "y": 7,
      "z": -6,
      "name": "Rock_Marble"
    },
    {
      "x": -14,
      "y": 8,
      "z": -6,
      "name": "Rock_Marble"
    },
    {
      "x": -14,
      "y": 9,
      "z": -6,
      "name": "Rock_Marble"
    },
    {
      "x": -14,
      "y": 10,
      "z": -6,
      "name": "Rock_Marble"
    },
    {
      "x": -14,
      "y": 3,
      "z": -5,
      "name": "Rock_Marble"
    },
    {
      "x": -14,
      "y": 4,
      "z": -5,
      "name": "Rock_Marble"
    },
    {
      "x": -14,
      "y": 5,
      "z": -5,
      "name": "Rock_Marble"
    },
    {
      "x": -14,
      "y": 6,
      "z": -5,
      "name": "Rock_Marble"
    },
    {
      "x": -14,
      "y": 7,
      "z": -5,
      "name": "Rock_Marble"
    },
    {
      "x": -14,
      "y": 8,
      "z": -5,
      "name": "Rock_Marble"
    },
    {
      "x": -14,
      "y": 9,
      "z": -5,
      "name": "Rock_Marble"
    },
    {
      "x": -14,
      "y": 10,
      "z": -5,
      "name": "Rock_Marble"
    },
    {
      "x": -14,
      "y": 3,
      "z": -4,
      "name": "Rock_Marble"
    },
    {
      "x": -14,
      "y": 4,
      "z": -4,
      "name": "Rock_Marble"
    },
    {
      "x": -14,
      "y": 5,
      "z": -4,
      "name": "Rock_Marble"
    },
    {
      "x": -14,
      "y": 6,
      "z": -4,
      "name": "Rock_Marble"
    },
    {
      "x": -14,
      "y": 7,
      "z": -4,
      "name": "Rock_Marble"
    },
    {
      "x": -14,
      "y": 8,
      "z": -4,
      "name": "Rock_Marble"
    },
    {
      "x": -14,
      "y": 9,
      "z": -4,
      "name": "Rock_Marble"
    },
    {
      "x": -14,
      "y": 10,
      "z": -4,
      "name": "Rock_Marble"
    },
    {
      "x": -14,
      "y": 3,
      "z": -3,
      "name": "Rock_Marble"
    },
    {
      "x": -14,
      "y": 4,
      "z": -3,
      "name": "Rock_Marble"
    },
    {
      "x": -14,
      "y": 5,
      "z": -3,
      "name": "Rock_Marble"
    },
    {
      "x": -14,
      "y": 6,
      "z": -3,
      "name": "Rock_Marble"
    },
    {
      "x": -14,
      "y": 7,
      "z": -3,
      "name": "Rock_Marble"
    },
    {
      "x": -14,
      "y": 8,
      "z": -3,
      "name": "Rock_Marble"
    },
    {
      "x": -14,
      "y": 9,
      "z": -3,
      "name": "Rock_Marble"
    },
    {
      "x": -14,
      "y": 10,
      "z": -3,
      "name": "Rock_Marble"
    },
    {
      "x": -14,
      "y": 3,
      "z": -2,
      "name": "Rock_Marble"
    },
    {
      "x": -14,
      "y": 4,
      "z": -2,
      "name": "Rock_Marble"
    },
    {
      "x": -14,
      "y": 5,
      "z": -2,
      "name": "Rock_Marble"
    },
    {
      "x": -14,
      "y": 6,
      "z": -2,
      "name": "Rock_Marble"
    },
    {
      "x": -14,
      "y": 7,
      "z": -2,
      "name": "Rock_Marble"
    },
    {
      "x": -14,
      "y": 8,
      "z": -2,
      "name": "Rock_Marble"
    },
    {
      "x": -14,
      "y": 9,
      "z": -2,
      "name": "Rock_Marble"
    },
    {
      "x": -14,
      "y": 10,
      "z": -2,
      "name": "Rock_Marble"
    },
    {
      "x": -14,
      "y": 3,
      "z": -1,
      "name": "Rock_Marble"
    },
    {
      "x": -14,
      "y": 4,
      "z": -1,
      "name": "Rock_Marble"
    },
    {
      "x": -14,
      "y": 5,
      "z": -1,
      "name": "Rock_Marble"
    },
    {
      "x": -14,
      "y": 6,
      "z": -1,
      "name": "Rock_Marble"
    },
    {
      "x": -14,
      "y": 7,
      "z": -1,
      "name": "Rock_Marble"
    },
    {
      "x": -14,
      "y": 8,
      "z": -1,
      "name": "Rock_Marble"
    },
    {
      "x": -14,
      "y": 9,
      "z": -1,
      "name": "Rock_Marble"
    },
    {
      "x": -14,
      "y": 10,
      "z": -1,
      "name": "Rock_Marble"
    },
    {
      "x": -14,
      "y": 3,
      "z": 0,
      "name": "Rock_Marble"
    },
    {
      "x": -14,
      "y": 4,
      "z": 0,
      "name": "Rock_Marble"
    },
    {
      "x": -14,
      "y": 5,
      "z": 0,
      "name": "Rock_Marble"
    },
    {
      "x": -14,
      "y": 6,
      "z": 0,
      "name": "Rock_Marble"
    },
    {
      "x": -14,
      "y": 7,
      "z": 0,
      "name": "Rock_Marble"
    },
    {
      "x": -14,
      "y": 8,
      "z": 0,
      "name": "Rock_Marble"
    },
    {
      "x": -14,
      "y": 9,
      "z": 0,
      "name": "Rock_Marble"
    },
    {
      "x": -14,
      "y": 10,
      "z": 0,
      "name": "Rock_Marble"
    },
    {
      "x": -14,
      "y": 3,
      "z": 1,
      "name": "Rock_Marble"
    },
    {
      "x": -14,
      "y": 4,
      "z": 1,
      "name": "Rock_Marble"
    },
    {
      "x": -14,
      "y": 5,
      "z": 1,
      "name": "Rock_Marble"
    },
    {
      "x": -14,
      "y": 6,
      "z": 1,
      "name": "Rock_Marble"
    },
    {
      "x": -14,
      "y": 7,
      "z": 1,
      "name": "Rock_Marble"
    },
    {
      "x": -14,
      "y": 8,
      "z": 1,
      "name": "Rock_Marble"
    },
    {
      "x": -14,
      "y": 9,
      "z": 1,
      "name": "Rock_Marble"
    },
    {
      "x": -14,
      "y": 10,
      "z": 1,
      "name": "Rock_Marble"
    },
    {
      "x": -14,
      "y": 4,
      "z": 2,
      "name": "Rock_Marble"
    },
    {
      "x": -14,
      "y": 5,
      "z": 2,
      "name": "Rock_Marble"
    },
    {
      "x": -14,
      "y": 6,
      "z": 2,
      "name": "Rock_Marble"
    },
    {
      "x": -14,
      "y": 7,
      "z": 2,
      "name": "Rock_Marble"
    },
    {
      "x": -14,
      "y": 8,
      "z": 2,
      "name": "Rock_Marble"
    },
    {
      "x": -14,
      "y": 9,
      "z": 2,
      "name": "Rock_Marble"
    },
    {
      "x": -14,
      "y": 10,
      "z": 2,
      "name": "Rock_Marble"
    },
    {
      "x": -14,
      "y": 4,
      "z": 3,
      "name": "Rock_Marble"
    },
    {
      "x": -14,
      "y": 5,
      "z": 3,
      "name": "Rock_Marble"
    },
    {
      "x": -14,
      "y": 6,
      "z": 3,
      "name": "Rock_Marble"
    },
    {
      "x": -14,
      "y": 7,
      "z": 3,
      "name": "Rock_Marble"
    },
    {
      "x": -14,
      "y": 8,
      "z": 3,
      "name": "Rock_Marble"
    },
    {
      "x": -14,
      "y": 9,
      "z": 3,
      "name": "Rock_Marble"
    },
    {
      "x": -14,
      "y": 10,
      "z": 3,
      "name": "Rock_Marble"
    },
    {
      "x": -14,
      "y": 4,
      "z": 4,
      "name": "Rock_Marble"
    },
    {
      "x": -14,
      "y": 5,
      "z": 4,
      "name": "Rock_Marble"
    },
    {
      "x": -14,
      "y": 6,
      "z": 4,
      "name": "Rock_Marble"
    },
    {
      "x": -14,
      "y": 7,
      "z": 4,
      "name": "Rock_Marble"
    },
    {
      "x": -14,
      "y": 8,
      "z": 4,
      "name": "Rock_Marble"
    },
    {
      "x": -14,
      "y": 9,
      "z": 4,
      "name": "Rock_Marble"
    },
    {
      "x": -14,
      "y": 10,
      "z": 4,
      "name": "Rock_Marble"
    },
    {
      "x": -14,
      "y": 4,
      "z": 5,
      "name": "Rock_Marble"
    },
    {
      "x": -14,
      "y": 5,
      "z": 5,
      "name": "Rock_Marble"
    },
    {
      "x": -14,
      "y": 6,
      "z": 5,
      "name": "Rock_Marble"
    },
    {
      "x": -14,
      "y": 7,
      "z": 5,
      "name": "Rock_Marble"
    },
    {
      "x": -14,
      "y": 8,
      "z": 5,
      "name": "Rock_Marble"
    },
    {
      "x": -14,
      "y": 9,
      "z": 5,
      "name": "Rock_Marble"
    },
    {
      "x": -14,
      "y": 10,
      "z": 5,
      "name": "Rock_Marble"
    },
    {
      "x": -14,
      "y": 4,
      "z": 6,
      "name": "Rock_Marble"
    },
    {
      "x": -14,
      "y": 5,
      "z": 6,
      "name": "Rock_Marble"
    },
    {
      "x": -14,
      "y": 6,
      "z": 6,
      "name": "Rock_Marble"
    },
    {
      "x": -14,
      "y": 7,
      "z": 6,
      "name": "Rock_Marble"
    },
    {
      "x": -14,
      "y": 8,
      "z": 6,
      "name": "Rock_Marble"
    },
    {
      "x": -14,
      "y": 9,
      "z": 6,
      "name": "Rock_Marble"
    },
    {
      "x": -14,
      "y": 10,
      "z": 6,
      "name": "Rock_Marble"
    },
    {
      "x": -14,
      "y": 4,
      "z": 7,
      "name": "Rock_Marble"
    },
    {
      "x": -14,
      "y": 5,
      "z": 7,
      "name": "Rock_Marble"
    },
    {
      "x": -14,
      "y": 6,
      "z": 7,
      "name": "Rock_Marble"
    },
    {
      "x": -14,
      "y": 7,
      "z": 7,
      "name": "Rock_Marble"
    },
    {
      "x": -14,
      "y": 8,
      "z": 7,
      "name": "Rock_Marble"
    },
    {
      "x": -14,
      "y": 9,
      "z": 7,
      "name": "Rock_Marble"
    },
    {
      "x": -14,
      "y": 10,
      "z": 7,
      "name": "Rock_Marble"
    },
    {
      "x": -14,
      "y": 4,
      "z": 8,
      "name": "Rock_Marble"
    },
    {
      "x": -14,
      "y": 5,
      "z": 8,
      "name": "Rock_Marble"
    },
    {
      "x": -14,
      "y": 6,
      "z": 8,
      "name": "Rock_Marble"
    },
    {
      "x": -14,
      "y": 7,
      "z": 8,
      "name": "Rock_Marble"
    },
    {
      "x": -14,
      "y": 8,
      "z": 8,
      "name": "Rock_Marble"
    },
    {
      "x": -14,
      "y": 9,
      "z": 8,
      "name": "Rock_Marble"
    },
    {
      "x": -14,
      "y": 10,
      "z": 8,
      "name": "Rock_Marble"
    },
    {
      "x": -14,
      "y": 5,
      "z": 9,
      "name": "Rock_Marble"
    },
    {
      "x": -14,
      "y": 6,
      "z": 9,
      "name": "Rock_Marble"
    },
    {
      "x": -14,
      "y": 7,
      "z": 9,
      "name": "Rock_Marble"
    },
    {
      "x": -14,
      "y": 8,
      "z": 9,
      "name": "Rock_Marble"
    },
    {
      "x": -14,
      "y": 9,
      "z": 9,
      "name": "Rock_Marble"
    },
    {
      "x": -14,
      "y": 10,
      "z": 9,
      "name": "Rock_Marble"
    },
    {
      "x": -14,
      "y": 5,
      "z": 10,
      "name": "Rock_Marble"
    },
    {
      "x": -14,
      "y": 6,
      "z": 10,
      "name": "Rock_Marble"
    },
    {
      "x": -14,
      "y": 7,
      "z": 10,
      "name": "Rock_Marble"
    },
    {
      "x": -14,
      "y": 8,
      "z": 10,
      "name": "Rock_Marble"
    },
    {
      "x": -14,
      "y": 9,
      "z": 10,
      "name": "Rock_Marble"
    },
    {
      "x": -14,
      "y": 10,
      "z": 10,
      "name": "Rock_Marble"
    },
    {
      "x": -14,
      "y": 5,
      "z": 11,
      "name": "Rock_Marble"
    },
    {
      "x": -14,
      "y": 6,
      "z": 11,
      "name": "Rock_Marble"
    },
    {
      "x": -14,
      "y": 7,
      "z": 11,
      "name": "Rock_Marble"
    },
    {
      "x": -14,
      "y": 8,
      "z": 11,
      "name": "Rock_Marble"
    },
    {
      "x": -14,
      "y": 9,
      "z": 11,
      "name": "Rock_Marble"
    },
    {
      "x": -14,
      "y": 10,
      "z": 11,
      "name": "Rock_Marble"
    },
    {
      "x": -14,
      "y": 5,
      "z": 12,
      "name": "Rock_Marble"
    },
    {
      "x": -14,
      "y": 6,
      "z": 12,
      "name": "Rock_Marble"
    },
    {
      "x": -14,
      "y": 7,
      "z": 12,
      "name": "Rock_Marble"
    },
    {
      "x": -14,
      "y": 8,
      "z": 12,
      "name": "Rock_Marble"
    },
    {
      "x": -14,
      "y": 9,
      "z": 12,
      "name": "Rock_Marble"
    },
    {
      "x": -14,
      "y": 10,
      "z": 12,
      "name": "Rock_Marble"
    },
    {
      "x": -14,
      "y": 6,
      "z": 13,
      "name": "Rock_Marble"
    },
    {
      "x": -14,
      "y": 7,
      "z": 13,
      "name": "Rock_Marble"
    },
    {
      "x": -14,
      "y": 8,
      "z": 13,
      "name": "Rock_Marble"
    },
    {
      "x": -14,
      "y": 9,
      "z": 13,
      "name": "Rock_Marble"
    },
    {
      "x": -14,
      "y": 10,
      "z": 13,
      "name": "Rock_Marble"
    },
    {
      "x": -14,
      "y": 7,
      "z": 14,
      "name": "Rock_Marble"
    },
    {
      "x": -14,
      "y": 8,
      "z": 14,
      "name": "Rock_Marble"
    },
    {
      "x": -14,
      "y": 9,
      "z": 14,
      "name": "Rock_Marble"
    },
    {
      "x": -14,
      "y": 10,
      "z": 14,
      "name": "Rock_Marble"
    },
    {
      "x": -14,
      "y": 7,
      "z": 15,
      "name": "Rock_Marble"
    },
    {
      "x": -14,
      "y": 8,
      "z": 15,
      "name": "Rock_Marble"
    },
    {
      "x": -14,
      "y": 9,
      "z": 15,
      "name": "Rock_Marble"
    },
    {
      "x": -14,
      "y": 10,
      "z": 15,
      "name": "Rock_Marble"
    },
    {
      "x": -14,
      "y": 8,
      "z": 16,
      "name": "Rock_Marble"
    },
    {
      "x": -14,
      "y": 10,
      "z": 16,
      "name": "Rock_Marble"
    },
    {
      "x": -14,
      "y": 9,
      "z": 17,
      "name": "Rock_Marble"
    },
    {
      "x": -14,
      "y": 10,
      "z": 17,
      "name": "Rock_Marble"
    },
    {
      "x": -14,
      "y": 11,
      "z": 17,
      "name": "Rock_Marble_Stalactite_Small"
    },
    {
      "x": -14,
      "y": 9,
      "z": 18,
      "name": "Rock_Marble"
    },
    {
      "x": -13,
      "y": 9,
      "z": -16,
      "name": "Rock_Marble"
    },
    {
      "x": -13,
      "y": 9,
      "z": -15,
      "name": "Rock_Marble"
    },
    {
      "x": -13,
      "y": 10,
      "z": -15,
      "name": "Rock_Marble"
    },
    {
      "x": -13,
      "y": 11,
      "z": -15,
      "name": "Rock_Marble_Stalactite_Large"
    },
    {
      "x": -13,
      "y": 12,
      "z": -15,
      "name": "Rock_Marble_Stalactite_Large",
      "filler": 1024
    },
    {
      "x": -13,
      "y": 7,
      "z": -14,
      "name": "Rock_Marble"
    },
    {
      "x": -13,
      "y": 8,
      "z": -14,
      "name": "Rock_Marble"
    },
    {
      "x": -13,
      "y": 9,
      "z": -14,
      "name": "Rock_Marble"
    },
    {
      "x": -13,
      "y": 10,
      "z": -14,
      "name": "Rock_Marble"
    },
    {
      "x": -13,
      "y": 6,
      "z": -13,
      "name": "Rock_Marble"
    },
    {
      "x": -13,
      "y": 7,
      "z": -13,
      "name": "Rock_Marble"
    },
    {
      "x": -13,
      "y": 8,
      "z": -13,
      "name": "Rock_Marble"
    },
    {
      "x": -13,
      "y": 9,
      "z": -13,
      "name": "Rock_Marble"
    },
    {
      "x": -13,
      "y": 10,
      "z": -13,
      "name": "Rock_Marble"
    },
    {
      "x": -13,
      "y": 5,
      "z": -12,
      "name": "Rock_Marble"
    },
    {
      "x": -13,
      "y": 6,
      "z": -12,
      "name": "Rock_Marble"
    },
    {
      "x": -13,
      "y": 7,
      "z": -12,
      "name": "Rock_Marble"
    },
    {
      "x": -13,
      "y": 8,
      "z": -12,
      "name": "Rock_Marble"
    },
    {
      "x": -13,
      "y": 9,
      "z": -12,
      "name": "Rock_Marble"
    },
    {
      "x": -13,
      "y": 10,
      "z": -12,
      "name": "Rock_Marble"
    },
    {
      "x": -13,
      "y": 5,
      "z": -11,
      "name": "Rock_Marble"
    },
    {
      "x": -13,
      "y": 6,
      "z": -11,
      "name": "Rock_Marble"
    },
    {
      "x": -13,
      "y": 7,
      "z": -11,
      "name": "Rock_Marble"
    },
    {
      "x": -13,
      "y": 8,
      "z": -11,
      "name": "Rock_Marble"
    },
    {
      "x": -13,
      "y": 9,
      "z": -11,
      "name": "Rock_Marble"
    },
    {
      "x": -13,
      "y": 10,
      "z": -11,
      "name": "Rock_Marble"
    },
    {
      "x": -13,
      "y": 11,
      "z": -11,
      "name": "Rubble_Marble_Medium"
    },
    {
      "x": -13,
      "y": 4,
      "z": -10,
      "name": "Rock_Marble"
    },
    {
      "x": -13,
      "y": 5,
      "z": -10,
      "name": "Rock_Marble"
    },
    {
      "x": -13,
      "y": 6,
      "z": -10,
      "name": "Rock_Marble"
    },
    {
      "x": -13,
      "y": 7,
      "z": -10,
      "name": "Rock_Marble"
    },
    {
      "x": -13,
      "y": 8,
      "z": -10,
      "name": "Rock_Marble"
    },
    {
      "x": -13,
      "y": 9,
      "z": -10,
      "name": "Rock_Marble"
    },
    {
      "x": -13,
      "y": 10,
      "z": -10,
      "name": "Rock_Marble"
    },
    {
      "x": -13,
      "y": 4,
      "z": -9,
      "name": "Rock_Marble"
    },
    {
      "x": -13,
      "y": 5,
      "z": -9,
      "name": "Rock_Marble"
    },
    {
      "x": -13,
      "y": 6,
      "z": -9,
      "name": "Rock_Marble"
    },
    {
      "x": -13,
      "y": 7,
      "z": -9,
      "name": "Rock_Marble"
    },
    {
      "x": -13,
      "y": 8,
      "z": -9,
      "name": "Rock_Marble"
    },
    {
      "x": -13,
      "y": 9,
      "z": -9,
      "name": "Rock_Marble"
    },
    {
      "x": -13,
      "y": 10,
      "z": -9,
      "name": "Rock_Marble"
    },
    {
      "x": -13,
      "y": 3,
      "z": -8,
      "name": "Rock_Marble"
    },
    {
      "x": -13,
      "y": 4,
      "z": -8,
      "name": "Rock_Marble"
    },
    {
      "x": -13,
      "y": 5,
      "z": -8,
      "name": "Rock_Marble"
    },
    {
      "x": -13,
      "y": 6,
      "z": -8,
      "name": "Rock_Marble"
    },
    {
      "x": -13,
      "y": 7,
      "z": -8,
      "name": "Rock_Marble"
    },
    {
      "x": -13,
      "y": 8,
      "z": -8,
      "name": "Rock_Marble"
    },
    {
      "x": -13,
      "y": 9,
      "z": -8,
      "name": "Rock_Marble"
    },
    {
      "x": -13,
      "y": 10,
      "z": -8,
      "name": "Rock_Marble"
    },
    {
      "x": -13,
      "y": 3,
      "z": -7,
      "name": "Rock_Marble"
    },
    {
      "x": -13,
      "y": 4,
      "z": -7,
      "name": "Rock_Marble"
    },
    {
      "x": -13,
      "y": 5,
      "z": -7,
      "name": "Rock_Marble"
    },
    {
      "x": -13,
      "y": 6,
      "z": -7,
      "name": "Rock_Marble"
    },
    {
      "x": -13,
      "y": 7,
      "z": -7,
      "name": "Rock_Marble"
    },
    {
      "x": -13,
      "y": 8,
      "z": -7,
      "name": "Rock_Marble"
    },
    {
      "x": -13,
      "y": 9,
      "z": -7,
      "name": "Rock_Marble"
    },
    {
      "x": -13,
      "y": 10,
      "z": -7,
      "name": "Rock_Marble"
    },
    {
      "x": -13,
      "y": 3,
      "z": -6,
      "name": "Rock_Marble"
    },
    {
      "x": -13,
      "y": 4,
      "z": -6,
      "name": "Rock_Marble"
    },
    {
      "x": -13,
      "y": 5,
      "z": -6,
      "name": "Rock_Marble"
    },
    {
      "x": -13,
      "y": 6,
      "z": -6,
      "name": "Rock_Marble"
    },
    {
      "x": -13,
      "y": 7,
      "z": -6,
      "name": "Rock_Marble"
    },
    {
      "x": -13,
      "y": 8,
      "z": -6,
      "name": "Rock_Marble"
    },
    {
      "x": -13,
      "y": 9,
      "z": -6,
      "name": "Rock_Marble"
    },
    {
      "x": -13,
      "y": 10,
      "z": -6,
      "name": "Rock_Marble"
    },
    {
      "x": -13,
      "y": 3,
      "z": -5,
      "name": "Rock_Marble"
    },
    {
      "x": -13,
      "y": 4,
      "z": -5,
      "name": "Rock_Marble"
    },
    {
      "x": -13,
      "y": 5,
      "z": -5,
      "name": "Rock_Marble"
    },
    {
      "x": -13,
      "y": 6,
      "z": -5,
      "name": "Rock_Marble"
    },
    {
      "x": -13,
      "y": 7,
      "z": -5,
      "name": "Rock_Marble"
    },
    {
      "x": -13,
      "y": 8,
      "z": -5,
      "name": "Rock_Marble"
    },
    {
      "x": -13,
      "y": 9,
      "z": -5,
      "name": "Rock_Marble"
    },
    {
      "x": -13,
      "y": 10,
      "z": -5,
      "name": "Rock_Marble"
    },
    {
      "x": -13,
      "y": 2,
      "z": -4,
      "name": "Rock_Marble"
    },
    {
      "x": -13,
      "y": 3,
      "z": -4,
      "name": "Rock_Marble"
    },
    {
      "x": -13,
      "y": 4,
      "z": -4,
      "name": "Rock_Marble"
    },
    {
      "x": -13,
      "y": 5,
      "z": -4,
      "name": "Rock_Marble"
    },
    {
      "x": -13,
      "y": 6,
      "z": -4,
      "name": "Rock_Marble"
    },
    {
      "x": -13,
      "y": 7,
      "z": -4,
      "name": "Rock_Marble"
    },
    {
      "x": -13,
      "y": 8,
      "z": -4,
      "name": "Rock_Marble"
    },
    {
      "x": -13,
      "y": 9,
      "z": -4,
      "name": "Rock_Marble"
    },
    {
      "x": -13,
      "y": 10,
      "z": -4,
      "name": "Rock_Marble"
    },
    {
      "x": -13,
      "y": 2,
      "z": -3,
      "name": "Rock_Marble"
    },
    {
      "x": -13,
      "y": 3,
      "z": -3,
      "name": "Rock_Marble"
    },
    {
      "x": -13,
      "y": 4,
      "z": -3,
      "name": "Rock_Marble"
    },
    {
      "x": -13,
      "y": 5,
      "z": -3,
      "name": "Rock_Marble"
    },
    {
      "x": -13,
      "y": 6,
      "z": -3,
      "name": "Rock_Marble"
    },
    {
      "x": -13,
      "y": 7,
      "z": -3,
      "name": "Rock_Marble"
    },
    {
      "x": -13,
      "y": 8,
      "z": -3,
      "name": "Rock_Marble"
    },
    {
      "x": -13,
      "y": 9,
      "z": -3,
      "name": "Rock_Marble"
    },
    {
      "x": -13,
      "y": 10,
      "z": -3,
      "name": "Rock_Marble"
    },
    {
      "x": -13,
      "y": 2,
      "z": -2,
      "name": "Rock_Marble"
    },
    {
      "x": -13,
      "y": 3,
      "z": -2,
      "name": "Rock_Marble"
    },
    {
      "x": -13,
      "y": 4,
      "z": -2,
      "name": "Rock_Marble"
    },
    {
      "x": -13,
      "y": 5,
      "z": -2,
      "name": "Rock_Marble"
    },
    {
      "x": -13,
      "y": 6,
      "z": -2,
      "name": "Rock_Marble"
    },
    {
      "x": -13,
      "y": 7,
      "z": -2,
      "name": "Rock_Marble"
    },
    {
      "x": -13,
      "y": 8,
      "z": -2,
      "name": "Rock_Marble"
    },
    {
      "x": -13,
      "y": 9,
      "z": -2,
      "name": "Rock_Marble"
    },
    {
      "x": -13,
      "y": 10,
      "z": -2,
      "name": "Rock_Marble"
    },
    {
      "x": -13,
      "y": 2,
      "z": -1,
      "name": "Rock_Marble"
    },
    {
      "x": -13,
      "y": 3,
      "z": -1,
      "name": "Rock_Marble"
    },
    {
      "x": -13,
      "y": 4,
      "z": -1,
      "name": "Rock_Marble"
    },
    {
      "x": -13,
      "y": 5,
      "z": -1,
      "name": "Rock_Marble"
    },
    {
      "x": -13,
      "y": 6,
      "z": -1,
      "name": "Rock_Marble"
    },
    {
      "x": -13,
      "y": 7,
      "z": -1,
      "name": "Rock_Marble"
    },
    {
      "x": -13,
      "y": 8,
      "z": -1,
      "name": "Rock_Marble"
    },
    {
      "x": -13,
      "y": 9,
      "z": -1,
      "name": "Rock_Marble"
    },
    {
      "x": -13,
      "y": 10,
      "z": -1,
      "name": "Rock_Marble"
    },
    {
      "x": -13,
      "y": 11,
      "z": -1,
      "name": "Deco_Bone_Pile"
    },
    {
      "x": -13,
      "y": 2,
      "z": 0,
      "name": "Rock_Marble"
    },
    {
      "x": -13,
      "y": 3,
      "z": 0,
      "name": "Rock_Marble"
    },
    {
      "x": -13,
      "y": 4,
      "z": 0,
      "name": "Rock_Marble"
    },
    {
      "x": -13,
      "y": 5,
      "z": 0,
      "name": "Rock_Marble"
    },
    {
      "x": -13,
      "y": 6,
      "z": 0,
      "name": "Rock_Marble"
    },
    {
      "x": -13,
      "y": 7,
      "z": 0,
      "name": "Rock_Marble"
    },
    {
      "x": -13,
      "y": 8,
      "z": 0,
      "name": "Rock_Marble"
    },
    {
      "x": -13,
      "y": 9,
      "z": 0,
      "name": "Rock_Marble"
    },
    {
      "x": -13,
      "y": 10,
      "z": 0,
      "name": "Rock_Marble"
    },
    {
      "x": -13,
      "y": 2,
      "z": 1,
      "name": "Rock_Marble"
    },
    {
      "x": -13,
      "y": 3,
      "z": 1,
      "name": "Rock_Marble"
    },
    {
      "x": -13,
      "y": 4,
      "z": 1,
      "name": "Rock_Marble"
    },
    {
      "x": -13,
      "y": 5,
      "z": 1,
      "name": "Rock_Marble"
    },
    {
      "x": -13,
      "y": 6,
      "z": 1,
      "name": "Rock_Marble"
    },
    {
      "x": -13,
      "y": 7,
      "z": 1,
      "name": "Rock_Marble"
    },
    {
      "x": -13,
      "y": 8,
      "z": 1,
      "name": "Rock_Marble"
    },
    {
      "x": -13,
      "y": 9,
      "z": 1,
      "name": "Rock_Marble"
    },
    {
      "x": -13,
      "y": 10,
      "z": 1,
      "name": "Rock_Marble"
    },
    {
      "x": -13,
      "y": 3,
      "z": 2,
      "name": "Rock_Marble"
    },
    {
      "x": -13,
      "y": 4,
      "z": 2,
      "name": "Rock_Marble"
    },
    {
      "x": -13,
      "y": 5,
      "z": 2,
      "name": "Rock_Marble"
    },
    {
      "x": -13,
      "y": 6,
      "z": 2,
      "name": "Rock_Marble"
    },
    {
      "x": -13,
      "y": 7,
      "z": 2,
      "name": "Rock_Marble"
    },
    {
      "x": -13,
      "y": 8,
      "z": 2,
      "name": "Rock_Marble"
    },
    {
      "x": -13,
      "y": 9,
      "z": 2,
      "name": "Rock_Marble"
    },
    {
      "x": -13,
      "y": 10,
      "z": 2,
      "name": "Rock_Marble"
    },
    {
      "x": -13,
      "y": 3,
      "z": 3,
      "name": "Rock_Marble"
    },
    {
      "x": -13,
      "y": 4,
      "z": 3,
      "name": "Rock_Marble"
    },
    {
      "x": -13,
      "y": 5,
      "z": 3,
      "name": "Rock_Marble"
    },
    {
      "x": -13,
      "y": 6,
      "z": 3,
      "name": "Rock_Marble"
    },
    {
      "x": -13,
      "y": 7,
      "z": 3,
      "name": "Rock_Marble"
    },
    {
      "x": -13,
      "y": 8,
      "z": 3,
      "name": "Rock_Marble"
    },
    {
      "x": -13,
      "y": 9,
      "z": 3,
      "name": "Rock_Marble"
    },
    {
      "x": -13,
      "y": 10,
      "z": 3,
      "name": "Rock_Marble"
    },
    {
      "x": -13,
      "y": 3,
      "z": 4,
      "name": "Rock_Marble"
    },
    {
      "x": -13,
      "y": 4,
      "z": 4,
      "name": "Rock_Marble"
    },
    {
      "x": -13,
      "y": 5,
      "z": 4,
      "name": "Rock_Marble"
    },
    {
      "x": -13,
      "y": 6,
      "z": 4,
      "name": "Rock_Marble"
    },
    {
      "x": -13,
      "y": 7,
      "z": 4,
      "name": "Rock_Marble"
    },
    {
      "x": -13,
      "y": 8,
      "z": 4,
      "name": "Rock_Marble"
    },
    {
      "x": -13,
      "y": 9,
      "z": 4,
      "name": "Rock_Marble"
    },
    {
      "x": -13,
      "y": 10,
      "z": 4,
      "name": "Rock_Marble"
    },
    {
      "x": -13,
      "y": 3,
      "z": 5,
      "name": "Rock_Marble"
    },
    {
      "x": -13,
      "y": 4,
      "z": 5,
      "name": "Rock_Marble"
    },
    {
      "x": -13,
      "y": 5,
      "z": 5,
      "name": "Rock_Marble"
    },
    {
      "x": -13,
      "y": 6,
      "z": 5,
      "name": "Rock_Marble"
    },
    {
      "x": -13,
      "y": 7,
      "z": 5,
      "name": "Rock_Marble"
    },
    {
      "x": -13,
      "y": 8,
      "z": 5,
      "name": "Rock_Marble"
    },
    {
      "x": -13,
      "y": 9,
      "z": 5,
      "name": "Rock_Marble"
    },
    {
      "x": -13,
      "y": 10,
      "z": 5,
      "name": "Rock_Marble"
    },
    {
      "x": -13,
      "y": 3,
      "z": 6,
      "name": "Rock_Marble"
    },
    {
      "x": -13,
      "y": 4,
      "z": 6,
      "name": "Rock_Marble"
    },
    {
      "x": -13,
      "y": 5,
      "z": 6,
      "name": "Rock_Marble"
    },
    {
      "x": -13,
      "y": 6,
      "z": 6,
      "name": "Rock_Marble"
    },
    {
      "x": -13,
      "y": 7,
      "z": 6,
      "name": "Rock_Marble"
    },
    {
      "x": -13,
      "y": 8,
      "z": 6,
      "name": "Rock_Marble"
    },
    {
      "x": -13,
      "y": 9,
      "z": 6,
      "name": "Rock_Marble"
    },
    {
      "x": -13,
      "y": 10,
      "z": 6,
      "name": "Rock_Marble"
    },
    {
      "x": -13,
      "y": 4,
      "z": 7,
      "name": "Rock_Marble"
    },
    {
      "x": -13,
      "y": 5,
      "z": 7,
      "name": "Rock_Marble"
    },
    {
      "x": -13,
      "y": 6,
      "z": 7,
      "name": "Rock_Marble"
    },
    {
      "x": -13,
      "y": 7,
      "z": 7,
      "name": "Rock_Marble"
    },
    {
      "x": -13,
      "y": 8,
      "z": 7,
      "name": "Rock_Marble"
    },
    {
      "x": -13,
      "y": 9,
      "z": 7,
      "name": "Rock_Marble"
    },
    {
      "x": -13,
      "y": 10,
      "z": 7,
      "name": "Rock_Marble"
    },
    {
      "x": -13,
      "y": 11,
      "z": 7,
      "name": "Rock_Slate_Cobble_Half",
      "rotation": 7
    },
    {
      "x": -13,
      "y": 12,
      "z": 7,
      "name": "Rock_Slate_Cobble_Half",
      "rotation": 7
    },
    {
      "x": -13,
      "y": 13,
      "z": 7,
      "name": "Rock_Slate_Cobble_Half",
      "rotation": 7
    },
    {
      "x": -13,
      "y": 4,
      "z": 8,
      "name": "Rock_Marble"
    },
    {
      "x": -13,
      "y": 5,
      "z": 8,
      "name": "Rock_Marble"
    },
    {
      "x": -13,
      "y": 6,
      "z": 8,
      "name": "Rock_Marble"
    },
    {
      "x": -13,
      "y": 7,
      "z": 8,
      "name": "Rock_Marble"
    },
    {
      "x": -13,
      "y": 8,
      "z": 8,
      "name": "Rock_Marble"
    },
    {
      "x": -13,
      "y": 9,
      "z": 8,
      "name": "Rock_Marble"
    },
    {
      "x": -13,
      "y": 10,
      "z": 8,
      "name": "Rock_Marble"
    },
    {
      "x": -13,
      "y": 11,
      "z": 8,
      "name": "Rock_Slate"
    },
    {
      "x": -13,
      "y": 12,
      "z": 8,
      "name": "Rock_Slate"
    },
    {
      "x": -13,
      "y": 13,
      "z": 8,
      "name": "Rock_Slate"
    },
    {
      "x": -13,
      "y": 4,
      "z": 9,
      "name": "Rock_Marble"
    },
    {
      "x": -13,
      "y": 5,
      "z": 9,
      "name": "Rock_Marble"
    },
    {
      "x": -13,
      "y": 6,
      "z": 9,
      "name": "Rock_Marble"
    },
    {
      "x": -13,
      "y": 7,
      "z": 9,
      "name": "Rock_Marble"
    },
    {
      "x": -13,
      "y": 8,
      "z": 9,
      "name": "Rock_Marble"
    },
    {
      "x": -13,
      "y": 9,
      "z": 9,
      "name": "Rock_Marble"
    },
    {
      "x": -13,
      "y": 10,
      "z": 9,
      "name": "Rock_Marble"
    },
    {
      "x": -13,
      "y": 11,
      "z": 9,
      "name": "Rock_Slate_Cobble"
    },
    {
      "x": -13,
      "y": 12,
      "z": 9,
      "name": "Rock_Slate"
    },
    {
      "x": -13,
      "y": 13,
      "z": 9,
      "name": "Rock_Slate_Cobble"
    },
    {
      "x": -13,
      "y": 14,
      "z": 9,
      "name": "Rubble_Slate_Medium"
    },
    {
      "x": -13,
      "y": 4,
      "z": 10,
      "name": "Rock_Marble"
    },
    {
      "x": -13,
      "y": 5,
      "z": 10,
      "name": "Rock_Marble"
    },
    {
      "x": -13,
      "y": 6,
      "z": 10,
      "name": "Rock_Marble"
    },
    {
      "x": -13,
      "y": 7,
      "z": 10,
      "name": "Rock_Marble"
    },
    {
      "x": -13,
      "y": 8,
      "z": 10,
      "name": "Rock_Marble"
    },
    {
      "x": -13,
      "y": 9,
      "z": 10,
      "name": "Rock_Marble"
    },
    {
      "x": -13,
      "y": 10,
      "z": 10,
      "name": "Rock_Marble"
    },
    {
      "x": -13,
      "y": 11,
      "z": 10,
      "name": "Rock_Slate_Cobble"
    },
    {
      "x": -13,
      "y": 12,
      "z": 10,
      "name": "Rock_Slate_Cobble"
    },
    {
      "x": -13,
      "y": 13,
      "z": 10,
      "name": "Rock_Slate"
    },
    {
      "x": -13,
      "y": 14,
      "z": 10,
      "name": "Rock_Slate_Cobble_Half"
    },
    {
      "x": -13,
      "y": 4,
      "z": 11,
      "name": "Rock_Marble"
    },
    {
      "x": -13,
      "y": 5,
      "z": 11,
      "name": "Rock_Marble"
    },
    {
      "x": -13,
      "y": 6,
      "z": 11,
      "name": "Rock_Marble"
    },
    {
      "x": -13,
      "y": 7,
      "z": 11,
      "name": "Rock_Marble"
    },
    {
      "x": -13,
      "y": 8,
      "z": 11,
      "name": "Rock_Marble"
    },
    {
      "x": -13,
      "y": 9,
      "z": 11,
      "name": "Rock_Marble"
    },
    {
      "x": -13,
      "y": 10,
      "z": 11,
      "name": "Rock_Marble"
    },
    {
      "x": -13,
      "y": 11,
      "z": 11,
      "name": "Rock_Slate"
    },
    {
      "x": -13,
      "y": 12,
      "z": 11,
      "name": "Rock_Slate_Cobble"
    },
    {
      "x": -13,
      "y": 13,
      "z": 11,
      "name": "Rock_Slate_Cobble_Stairs",
      "rotation": 3
    },
    {
      "x": -13,
      "y": 5,
      "z": 12,
      "name": "Rock_Marble"
    },
    {
      "x": -13,
      "y": 6,
      "z": 12,
      "name": "Rock_Marble"
    },
    {
      "x": -13,
      "y": 7,
      "z": 12,
      "name": "Rock_Marble"
    },
    {
      "x": -13,
      "y": 8,
      "z": 12,
      "name": "Rock_Marble"
    },
    {
      "x": -13,
      "y": 9,
      "z": 12,
      "name": "Rock_Marble"
    },
    {
      "x": -13,
      "y": 10,
      "z": 12,
      "name": "Rock_Marble"
    },
    {
      "x": -13,
      "y": 11,
      "z": 12,
      "name": "Rock_Slate_Cobble_Half",
      "rotation": 7
    },
    {
      "x": -13,
      "y": 12,
      "z": 12,
      "name": "Rock_Slate_Cobble_Half",
      "rotation": 7
    },
    {
      "x": -13,
      "y": 13,
      "z": 12,
      "name": "Rock_Slate_Cobble_Half",
      "rotation": 7
    },
    {
      "x": -13,
      "y": 5,
      "z": 13,
      "name": "Rock_Marble"
    },
    {
      "x": -13,
      "y": 6,
      "z": 13,
      "name": "Rock_Marble"
    },
    {
      "x": -13,
      "y": 7,
      "z": 13,
      "name": "Rock_Marble"
    },
    {
      "x": -13,
      "y": 8,
      "z": 13,
      "name": "Rock_Marble"
    },
    {
      "x": -13,
      "y": 9,
      "z": 13,
      "name": "Rock_Marble"
    },
    {
      "x": -13,
      "y": 10,
      "z": 13,
      "name": "Rock_Marble"
    },
    {
      "x": -13,
      "y": 6,
      "z": 14,
      "name": "Rock_Marble"
    },
    {
      "x": -13,
      "y": 7,
      "z": 14,
      "name": "Rock_Marble"
    },
    {
      "x": -13,
      "y": 8,
      "z": 14,
      "name": "Rock_Marble"
    },
    {
      "x": -13,
      "y": 9,
      "z": 14,
      "name": "Rock_Marble"
    },
    {
      "x": -13,
      "y": 10,
      "z": 14,
      "name": "Rock_Marble"
    },
    {
      "x": -13,
      "y": 7,
      "z": 15,
      "name": "Rock_Marble"
    },
    {
      "x": -13,
      "y": 8,
      "z": 15,
      "name": "Rock_Marble"
    },
    {
      "x": -13,
      "y": 9,
      "z": 15,
      "name": "Rock_Marble"
    },
    {
      "x": -13,
      "y": 10,
      "z": 15,
      "name": "Rock_Marble"
    },
    {
      "x": -13,
      "y": 7,
      "z": 16,
      "name": "Rock_Marble"
    },
    {
      "x": -13,
      "y": 8,
      "z": 16,
      "name": "Rock_Marble"
    },
    {
      "x": -13,
      "y": 9,
      "z": 16,
      "name": "Rock_Marble"
    },
    {
      "x": -13,
      "y": 10,
      "z": 16,
      "name": "Rock_Marble"
    },
    {
      "x": -13,
      "y": 8,
      "z": 17,
      "name": "Rock_Marble"
    },
    {
      "x": -13,
      "y": 9,
      "z": 17,
      "name": "Rock_Marble"
    },
    {
      "x": -13,
      "y": 10,
      "z": 17,
      "name": "Rock_Marble"
    },
    {
      "x": -13,
      "y": 9,
      "z": 18,
      "name": "Rock_Marble"
    },
    {
      "x": -13,
      "y": 10,
      "z": 18,
      "name": "Rock_Marble"
    },
    {
      "x": -13,
      "y": 11,
      "z": 18,
      "name": "Rock_Marble_Stalactite_Large"
    },
    {
      "x": -13,
      "y": 12,
      "z": 18,
      "name": "Rock_Marble_Stalactite_Large",
      "filler": 1024
    },
    {
      "x": -12,
      "y": 9,
      "z": -16,
      "name": "Rock_Marble"
    },
    {
      "x": -12,
      "y": 10,
      "z": -16,
      "name": "Rock_Marble"
    },
    {
      "x": -12,
      "y": 7,
      "z": -15,
      "name": "Rock_Marble"
    },
    {
      "x": -12,
      "y": 8,
      "z": -15,
      "name": "Rock_Marble"
    },
    {
      "x": -12,
      "y": 9,
      "z": -15,
      "name": "Rock_Marble"
    },
    {
      "x": -12,
      "y": 10,
      "z": -15,
      "name": "Rock_Marble"
    },
    {
      "x": -12,
      "y": 6,
      "z": -14,
      "name": "Rock_Marble"
    },
    {
      "x": -12,
      "y": 7,
      "z": -14,
      "name": "Rock_Marble"
    },
    {
      "x": -12,
      "y": 8,
      "z": -14,
      "name": "Rock_Marble"
    },
    {
      "x": -12,
      "y": 9,
      "z": -14,
      "name": "Rock_Marble"
    },
    {
      "x": -12,
      "y": 10,
      "z": -14,
      "name": "Rock_Marble"
    },
    {
      "x": -12,
      "y": 5,
      "z": -13,
      "name": "Rock_Marble"
    },
    {
      "x": -12,
      "y": 6,
      "z": -13,
      "name": "Rock_Marble"
    },
    {
      "x": -12,
      "y": 7,
      "z": -13,
      "name": "Rock_Marble"
    },
    {
      "x": -12,
      "y": 8,
      "z": -13,
      "name": "Rock_Marble"
    },
    {
      "x": -12,
      "y": 9,
      "z": -13,
      "name": "Rock_Marble"
    },
    {
      "x": -12,
      "y": 10,
      "z": -13,
      "name": "Rock_Marble"
    },
    {
      "x": -12,
      "y": 11,
      "z": -13,
      "name": "Rock_Marble_Stalactite_Large"
    },
    {
      "x": -12,
      "y": 12,
      "z": -13,
      "name": "Rock_Marble_Stalactite_Large",
      "filler": 1024
    },
    {
      "x": -12,
      "y": 5,
      "z": -12,
      "name": "Rock_Marble"
    },
    {
      "x": -12,
      "y": 6,
      "z": -12,
      "name": "Rock_Marble"
    },
    {
      "x": -12,
      "y": 7,
      "z": -12,
      "name": "Rock_Marble"
    },
    {
      "x": -12,
      "y": 8,
      "z": -12,
      "name": "Rock_Marble"
    },
    {
      "x": -12,
      "y": 9,
      "z": -12,
      "name": "Rock_Marble"
    },
    {
      "x": -12,
      "y": 10,
      "z": -12,
      "name": "Rock_Marble"
    },
    {
      "x": -12,
      "y": 11,
      "z": -12,
      "name": "Plant_Crop_Mushroom_Glowing_Blue"
    },
    {
      "x": -12,
      "y": 4,
      "z": -11,
      "name": "Rock_Marble"
    },
    {
      "x": -12,
      "y": 5,
      "z": -11,
      "name": "Rock_Marble"
    },
    {
      "x": -12,
      "y": 6,
      "z": -11,
      "name": "Rock_Marble"
    },
    {
      "x": -12,
      "y": 7,
      "z": -11,
      "name": "Rock_Marble"
    },
    {
      "x": -12,
      "y": 8,
      "z": -11,
      "name": "Rock_Marble"
    },
    {
      "x": -12,
      "y": 9,
      "z": -11,
      "name": "Rock_Marble"
    },
    {
      "x": -12,
      "y": 10,
      "z": -11,
      "name": "Rock_Marble"
    },
    {
      "x": -12,
      "y": 4,
      "z": -10,
      "name": "Rock_Marble"
    },
    {
      "x": -12,
      "y": 5,
      "z": -10,
      "name": "Rock_Marble"
    },
    {
      "x": -12,
      "y": 6,
      "z": -10,
      "name": "Rock_Marble"
    },
    {
      "x": -12,
      "y": 7,
      "z": -10,
      "name": "Rock_Marble"
    },
    {
      "x": -12,
      "y": 8,
      "z": -10,
      "name": "Rock_Marble"
    },
    {
      "x": -12,
      "y": 9,
      "z": -10,
      "name": "Rock_Marble"
    },
    {
      "x": -12,
      "y": 10,
      "z": -10,
      "name": "Rock_Marble"
    },
    {
      "x": -12,
      "y": 3,
      "z": -9,
      "name": "Rock_Marble"
    },
    {
      "x": -12,
      "y": 4,
      "z": -9,
      "name": "Rock_Marble"
    },
    {
      "x": -12,
      "y": 5,
      "z": -9,
      "name": "Rock_Marble"
    },
    {
      "x": -12,
      "y": 6,
      "z": -9,
      "name": "Rock_Marble"
    },
    {
      "x": -12,
      "y": 7,
      "z": -9,
      "name": "Rock_Marble"
    },
    {
      "x": -12,
      "y": 8,
      "z": -9,
      "name": "Rock_Marble"
    },
    {
      "x": -12,
      "y": 9,
      "z": -9,
      "name": "Rock_Marble"
    },
    {
      "x": -12,
      "y": 10,
      "z": -9,
      "name": "Rock_Marble"
    },
    {
      "x": -12,
      "y": 3,
      "z": -8,
      "name": "Rock_Marble"
    },
    {
      "x": -12,
      "y": 4,
      "z": -8,
      "name": "Rock_Marble"
    },
    {
      "x": -12,
      "y": 5,
      "z": -8,
      "name": "Rock_Marble"
    },
    {
      "x": -12,
      "y": 6,
      "z": -8,
      "name": "Rock_Marble"
    },
    {
      "x": -12,
      "y": 7,
      "z": -8,
      "name": "Rock_Marble"
    },
    {
      "x": -12,
      "y": 8,
      "z": -8,
      "name": "Rock_Marble"
    },
    {
      "x": -12,
      "y": 9,
      "z": -8,
      "name": "Rock_Marble"
    },
    {
      "x": -12,
      "y": 10,
      "z": -8,
      "name": "Rock_Marble"
    },
    {
      "x": -12,
      "y": 3,
      "z": -7,
      "name": "Rock_Marble"
    },
    {
      "x": -12,
      "y": 4,
      "z": -7,
      "name": "Rock_Marble"
    },
    {
      "x": -12,
      "y": 5,
      "z": -7,
      "name": "Rock_Marble"
    },
    {
      "x": -12,
      "y": 6,
      "z": -7,
      "name": "Rock_Marble"
    },
    {
      "x": -12,
      "y": 7,
      "z": -7,
      "name": "Rock_Marble"
    },
    {
      "x": -12,
      "y": 8,
      "z": -7,
      "name": "Rock_Marble"
    },
    {
      "x": -12,
      "y": 9,
      "z": -7,
      "name": "Rock_Marble"
    },
    {
      "x": -12,
      "y": 10,
      "z": -7,
      "name": "Rock_Marble"
    },
    {
      "x": -12,
      "y": 2,
      "z": -6,
      "name": "Rock_Marble"
    },
    {
      "x": -12,
      "y": 3,
      "z": -6,
      "name": "Rock_Marble"
    },
    {
      "x": -12,
      "y": 4,
      "z": -6,
      "name": "Rock_Marble"
    },
    {
      "x": -12,
      "y": 5,
      "z": -6,
      "name": "Rock_Marble"
    },
    {
      "x": -12,
      "y": 6,
      "z": -6,
      "name": "Rock_Marble"
    },
    {
      "x": -12,
      "y": 7,
      "z": -6,
      "name": "Rock_Marble"
    },
    {
      "x": -12,
      "y": 8,
      "z": -6,
      "name": "Rock_Marble"
    },
    {
      "x": -12,
      "y": 9,
      "z": -6,
      "name": "Rock_Marble"
    },
    {
      "x": -12,
      "y": 10,
      "z": -6,
      "name": "Rock_Marble"
    },
    {
      "x": -12,
      "y": 2,
      "z": -5,
      "name": "Rock_Marble"
    },
    {
      "x": -12,
      "y": 3,
      "z": -5,
      "name": "Rock_Marble"
    },
    {
      "x": -12,
      "y": 4,
      "z": -5,
      "name": "Rock_Marble"
    },
    {
      "x": -12,
      "y": 5,
      "z": -5,
      "name": "Rock_Marble"
    },
    {
      "x": -12,
      "y": 6,
      "z": -5,
      "name": "Rock_Marble"
    },
    {
      "x": -12,
      "y": 7,
      "z": -5,
      "name": "Rock_Marble"
    },
    {
      "x": -12,
      "y": 8,
      "z": -5,
      "name": "Rock_Marble"
    },
    {
      "x": -12,
      "y": 9,
      "z": -5,
      "name": "Rock_Marble"
    },
    {
      "x": -12,
      "y": 10,
      "z": -5,
      "name": "Rock_Marble"
    },
    {
      "x": -12,
      "y": 2,
      "z": -4,
      "name": "Rock_Marble"
    },
    {
      "x": -12,
      "y": 3,
      "z": -4,
      "name": "Rock_Marble"
    },
    {
      "x": -12,
      "y": 4,
      "z": -4,
      "name": "Rock_Marble"
    },
    {
      "x": -12,
      "y": 5,
      "z": -4,
      "name": "Rock_Marble"
    },
    {
      "x": -12,
      "y": 6,
      "z": -4,
      "name": "Rock_Marble"
    },
    {
      "x": -12,
      "y": 7,
      "z": -4,
      "name": "Rock_Marble"
    },
    {
      "x": -12,
      "y": 8,
      "z": -4,
      "name": "Rock_Marble"
    },
    {
      "x": -12,
      "y": 9,
      "z": -4,
      "name": "Rock_Marble"
    },
    {
      "x": -12,
      "y": 10,
      "z": -4,
      "name": "Rock_Marble"
    },
    {
      "x": -12,
      "y": 11,
      "z": -4,
      "name": "Rock_Slate_Cobble_Half",
      "rotation": 7
    },
    {
      "x": -12,
      "y": 12,
      "z": -4,
      "name": "Rock_Slate_Cobble_Half",
      "rotation": 7
    },
    {
      "x": -12,
      "y": 13,
      "z": -4,
      "name": "Rock_Slate_Cobble_Half",
      "rotation": 7
    },
    {
      "x": -12,
      "y": 1,
      "z": -3,
      "name": "Rock_Marble"
    },
    {
      "x": -12,
      "y": 2,
      "z": -3,
      "name": "Rock_Marble"
    },
    {
      "x": -12,
      "y": 3,
      "z": -3,
      "name": "Rock_Marble"
    },
    {
      "x": -12,
      "y": 4,
      "z": -3,
      "name": "Rock_Marble"
    },
    {
      "x": -12,
      "y": 5,
      "z": -3,
      "name": "Rock_Marble"
    },
    {
      "x": -12,
      "y": 6,
      "z": -3,
      "name": "Rock_Marble"
    },
    {
      "x": -12,
      "y": 7,
      "z": -3,
      "name": "Rock_Marble"
    },
    {
      "x": -12,
      "y": 8,
      "z": -3,
      "name": "Rock_Marble"
    },
    {
      "x": -12,
      "y": 9,
      "z": -3,
      "name": "Rock_Marble"
    },
    {
      "x": -12,
      "y": 10,
      "z": -3,
      "name": "Rock_Marble"
    },
    {
      "x": -12,
      "y": 11,
      "z": -3,
      "name": "Rock_Slate_Cobble_Half",
      "rotation": 7
    },
    {
      "x": -12,
      "y": 12,
      "z": -3,
      "name": "Rock_Slate_Cobble_Half",
      "rotation": 7
    },
    {
      "x": -12,
      "y": 13,
      "z": -3,
      "name": "Rock_Slate_Cobble_Half",
      "rotation": 7
    },
    {
      "x": -12,
      "y": 14,
      "z": -3,
      "name": "Rock_Slate_Cobble_Half",
      "rotation": 7
    },
    {
      "x": -12,
      "y": 1,
      "z": -2,
      "name": "Rock_Marble"
    },
    {
      "x": -12,
      "y": 2,
      "z": -2,
      "name": "Rock_Marble"
    },
    {
      "x": -12,
      "y": 3,
      "z": -2,
      "name": "Rock_Marble"
    },
    {
      "x": -12,
      "y": 4,
      "z": -2,
      "name": "Rock_Marble"
    },
    {
      "x": -12,
      "y": 5,
      "z": -2,
      "name": "Rock_Marble"
    },
    {
      "x": -12,
      "y": 6,
      "z": -2,
      "name": "Rock_Marble"
    },
    {
      "x": -12,
      "y": 7,
      "z": -2,
      "name": "Rock_Marble"
    },
    {
      "x": -12,
      "y": 8,
      "z": -2,
      "name": "Rock_Marble"
    },
    {
      "x": -12,
      "y": 9,
      "z": -2,
      "name": "Rock_Marble"
    },
    {
      "x": -12,
      "y": 10,
      "z": -2,
      "name": "Rock_Marble"
    },
    {
      "x": -12,
      "y": 11,
      "z": -2,
      "name": "Rock_Slate_Cobble_Half",
      "rotation": 7
    },
    {
      "x": -12,
      "y": 12,
      "z": -2,
      "name": "Rock_Slate_Cobble_Half",
      "rotation": 7
    },
    {
      "x": -12,
      "y": 13,
      "z": -2,
      "name": "Rock_Slate_Cobble_Half",
      "rotation": 7
    },
    {
      "x": -12,
      "y": 1,
      "z": -1,
      "name": "Rock_Marble"
    },
    {
      "x": -12,
      "y": 2,
      "z": -1,
      "name": "Rock_Marble"
    },
    {
      "x": -12,
      "y": 3,
      "z": -1,
      "name": "Rock_Marble"
    },
    {
      "x": -12,
      "y": 4,
      "z": -1,
      "name": "Rock_Marble"
    },
    {
      "x": -12,
      "y": 5,
      "z": -1,
      "name": "Rock_Marble"
    },
    {
      "x": -12,
      "y": 6,
      "z": -1,
      "name": "Rock_Marble"
    },
    {
      "x": -12,
      "y": 7,
      "z": -1,
      "name": "Rock_Marble"
    },
    {
      "x": -12,
      "y": 8,
      "z": -1,
      "name": "Rock_Marble"
    },
    {
      "x": -12,
      "y": 9,
      "z": -1,
      "name": "Rock_Marble"
    },
    {
      "x": -12,
      "y": 10,
      "z": -1,
      "name": "Rock_Marble"
    },
    {
      "x": -12,
      "y": 1,
      "z": 0,
      "name": "Rock_Marble"
    },
    {
      "x": -12,
      "y": 2,
      "z": 0,
      "name": "Rock_Marble"
    },
    {
      "x": -12,
      "y": 3,
      "z": 0,
      "name": "Rock_Marble"
    },
    {
      "x": -12,
      "y": 4,
      "z": 0,
      "name": "Rock_Marble"
    },
    {
      "x": -12,
      "y": 5,
      "z": 0,
      "name": "Rock_Marble"
    },
    {
      "x": -12,
      "y": 6,
      "z": 0,
      "name": "Rock_Marble"
    },
    {
      "x": -12,
      "y": 7,
      "z": 0,
      "name": "Rock_Marble"
    },
    {
      "x": -12,
      "y": 8,
      "z": 0,
      "name": "Rock_Marble"
    },
    {
      "x": -12,
      "y": 9,
      "z": 0,
      "name": "Rock_Marble"
    },
    {
      "x": -12,
      "y": 10,
      "z": 0,
      "name": "Rock_Marble"
    },
    {
      "x": -12,
      "y": 1,
      "z": 1,
      "name": "Rock_Marble"
    },
    {
      "x": -12,
      "y": 2,
      "z": 1,
      "name": "Rock_Marble"
    },
    {
      "x": -12,
      "y": 3,
      "z": 1,
      "name": "Rock_Marble"
    },
    {
      "x": -12,
      "y": 4,
      "z": 1,
      "name": "Rock_Marble"
    },
    {
      "x": -12,
      "y": 5,
      "z": 1,
      "name": "Rock_Marble"
    },
    {
      "x": -12,
      "y": 6,
      "z": 1,
      "name": "Rock_Marble"
    },
    {
      "x": -12,
      "y": 7,
      "z": 1,
      "name": "Rock_Marble"
    },
    {
      "x": -12,
      "y": 8,
      "z": 1,
      "name": "Rock_Marble"
    },
    {
      "x": -12,
      "y": 9,
      "z": 1,
      "name": "Rock_Marble"
    },
    {
      "x": -12,
      "y": 10,
      "z": 1,
      "name": "Rock_Marble"
    },
    {
      "x": -12,
      "y": 2,
      "z": 2,
      "name": "Rock_Marble"
    },
    {
      "x": -12,
      "y": 3,
      "z": 2,
      "name": "Rock_Marble"
    },
    {
      "x": -12,
      "y": 4,
      "z": 2,
      "name": "Rock_Marble"
    },
    {
      "x": -12,
      "y": 5,
      "z": 2,
      "name": "Rock_Marble"
    },
    {
      "x": -12,
      "y": 6,
      "z": 2,
      "name": "Rock_Marble"
    },
    {
      "x": -12,
      "y": 7,
      "z": 2,
      "name": "Rock_Marble"
    },
    {
      "x": -12,
      "y": 8,
      "z": 2,
      "name": "Rock_Marble"
    },
    {
      "x": -12,
      "y": 9,
      "z": 2,
      "name": "Rock_Marble"
    },
    {
      "x": -12,
      "y": 10,
      "z": 2,
      "name": "Rock_Marble"
    },
    {
      "x": -12,
      "y": 2,
      "z": 3,
      "name": "Rock_Marble"
    },
    {
      "x": -12,
      "y": 3,
      "z": 3,
      "name": "Rock_Marble"
    },
    {
      "x": -12,
      "y": 4,
      "z": 3,
      "name": "Rock_Marble"
    },
    {
      "x": -12,
      "y": 5,
      "z": 3,
      "name": "Rock_Marble"
    },
    {
      "x": -12,
      "y": 6,
      "z": 3,
      "name": "Rock_Marble"
    },
    {
      "x": -12,
      "y": 7,
      "z": 3,
      "name": "Rock_Marble"
    },
    {
      "x": -12,
      "y": 8,
      "z": 3,
      "name": "Rock_Marble"
    },
    {
      "x": -12,
      "y": 9,
      "z": 3,
      "name": "Rock_Marble"
    },
    {
      "x": -12,
      "y": 10,
      "z": 3,
      "name": "Rock_Marble"
    },
    {
      "x": -12,
      "y": 2,
      "z": 4,
      "name": "Rock_Marble"
    },
    {
      "x": -12,
      "y": 3,
      "z": 4,
      "name": "Rock_Marble"
    },
    {
      "x": -12,
      "y": 4,
      "z": 4,
      "name": "Rock_Marble"
    },
    {
      "x": -12,
      "y": 5,
      "z": 4,
      "name": "Rock_Marble"
    },
    {
      "x": -12,
      "y": 6,
      "z": 4,
      "name": "Rock_Marble"
    },
    {
      "x": -12,
      "y": 7,
      "z": 4,
      "name": "Rock_Marble"
    },
    {
      "x": -12,
      "y": 8,
      "z": 4,
      "name": "Rock_Marble"
    },
    {
      "x": -12,
      "y": 9,
      "z": 4,
      "name": "Rock_Marble"
    },
    {
      "x": -12,
      "y": 10,
      "z": 4,
      "name": "Rock_Marble"
    },
    {
      "x": -12,
      "y": 11,
      "z": 4,
      "name": "Rock_Slate_Cobble_Half",
      "rotation": 7
    },
    {
      "x": -12,
      "y": 12,
      "z": 4,
      "name": "Rock_Slate_Cobble_Half",
      "rotation": 7
    },
    {
      "x": -12,
      "y": 13,
      "z": 4,
      "name": "Rock_Slate_Cobble_Half",
      "rotation": 7
    },
    {
      "x": -12,
      "y": 3,
      "z": 5,
      "name": "Rock_Marble"
    },
    {
      "x": -12,
      "y": 4,
      "z": 5,
      "name": "Rock_Marble"
    },
    {
      "x": -12,
      "y": 5,
      "z": 5,
      "name": "Rock_Marble"
    },
    {
      "x": -12,
      "y": 6,
      "z": 5,
      "name": "Rock_Marble"
    },
    {
      "x": -12,
      "y": 7,
      "z": 5,
      "name": "Rock_Marble"
    },
    {
      "x": -12,
      "y": 8,
      "z": 5,
      "name": "Rock_Marble"
    },
    {
      "x": -12,
      "y": 9,
      "z": 5,
      "name": "Rock_Marble"
    },
    {
      "x": -12,
      "y": 10,
      "z": 5,
      "name": "Rock_Marble"
    },
    {
      "x": -12,
      "y": 11,
      "z": 5,
      "name": "Rock_Slate_Cobble_Half",
      "rotation": 7
    },
    {
      "x": -12,
      "y": 12,
      "z": 5,
      "name": "Rock_Slate_Cobble_Half",
