{
  "version": 8,
  "blockIdVersion": 11,
  "anchorX": 0,
  "anchorY": 0,
  "anchorZ": 0,
  "blocks": [
    {
      "x": -49,
      "y": 45,
      "z": -6,
      "name": "Rock_Stone_Mossy"
    },
    {
      "x": -48,
      "y": 45,
      "z": -7,
      "name": "Rock_Stone_Mossy"
    },
    {
      "x": -48,
      "y": 43,
      "z": -6,
      "name": "Rock_Stone"
    },
    {
      "x": -48,
      "y": 45,
      "z": -6,
      "name": "Rock_Stone_Cobble_Mossy"
    },
    {
      "x": -48,
      "y": 44,
      "z": -5,
      "name": "Rock_Stone"
    },
    {
      "x": -48,
      "y": 45,
      "z": -5,
      "name": "Soil_Dirt"
    },
    {
      "x": -48,
      "y": 46,
      "z": -5,
      "name": "Rock_Stone"
    },
    {
      "x": -48,
      "y": 44,
      "z": -4,
      "name": "Plant_Moss_Block_Green"
    },
    {
      "x": -48,
      "y": 45,
      "z": -4,
      "name": "Rock_Stone_Cobble_Mossy"
    },
    {
      "x": -48,
      "y": 46,
      "z": -4,
      "name": "Soil_Gravel_Mossy"
    },
    {
      "x": -48,
      "y": 44,
      "z": -3,
      "name": "Rock_Stone_Cobble_Mossy"
    },
    {
      "x": -48,
      "y": 45,
      "z": -3,
      "name": "Rock_Stone"
    },
    {
      "x": -48,
      "y": 46,
      "z": -3,
      "name": "Rock_Stone_Mossy"
    },
    {
      "x": -48,
      "y": 46,
      "z": -2,
      "name": "Rock_Stone"
    },
    {
      "x": -47,
      "y": 44,
      "z": -7,
      "name": "Rock_Stone_Mossy"
    },
    {
      "x": -47,
      "y": 45,
      "z": -7,
      "name": "Rock_Stone_Cobble_Mossy"
    },
    {
      "x": -47,
      "y": 46,
      "z": -7,
      "name": "Plant_Moss_Block_Green"
    },
    {
      "x": -47,
      "y": 43,
      "z": -6,
      "name": "Plant_Moss_Block_Green"
    },
    {
      "x": -47,
      "y": 44,
      "z": -6,
      "name": "Plant_Moss_Block_Green"
    },
    {
      "x": -47,
      "y": 45,
      "z": -6,
      "name": "Soil_Dirt"
    },
    {
      "x": -47,
      "y": 46,
      "z": -6,
      "name": "Rock_Stone"
    },
    {
      "x": -47,
      "y": 47,
      "z": -6,
      "name": "Soil_Dirt"
    },
    {
      "x": -47,
      "y": 43,
      "z": -5,
      "name": "Soil_Dirt"
    },
    {
      "x": -47,
      "y": 44,
      "z": -5,
      "name": "Rock_Stone_Cobble_Mossy"
    },
    {
      "x": -47,
      "y": 45,
      "z": -5,
      "name": "Soil_Gravel_Mossy"
    },
    {
      "x": -47,
      "y": 46,
      "z": -5,
      "name": "Soil_Gravel_Mossy"
    },
    {
      "x": -47,
      "y": 47,
      "z": -5,
      "name": "Rock_Stone_Mossy"
    },
    {
      "x": -47,
      "y": 49,
      "z": -5,
      "name": "Plant_Moss_Block_Green"
    },
    {
      "x": -47,
      "y": 50,
      "z": -5,
      "name": "Rock_Crystal_Green_Large"
    },
    {
      "x": -47,
      "y": 42,
      "z": -4,
      "name": "Rock_Stone"
    },
    {
      "x": -47,
      "y": 43,
      "z": -4,
      "name": "Rock_Stone_Mossy"
    },
    {
      "x": -47,
      "y": 44,
      "z": -4,
      "name": "Rock_Stone"
    },
    {
      "x": -47,
      "y": 45,
      "z": -4,
      "name": "Rock_Stone_Mossy"
    },
    {
      "x": -47,
      "y": 46,
      "z": -4,
      "name": "Plant_Moss_Block_Green"
    },
    {
      "x": -47,
      "y": 47,
      "z": -4,
      "name": "Rock_Stone_Cobble_Mossy"
    },
    {
      "x": -47,
      "y": 48,
      "z": -4,
      "name": "Rock_Stone"
    },
    {
      "x": -47,
      "y": 43,
      "z": -3,
      "name": "Rock_Stone"
    },
    {
      "x": -47,
      "y": 44,
      "z": -3,
      "name": "Rock_Stone"
    },
    {
      "x": -47,
      "y": 45,
      "z": -3,
      "name": "Rock_Stone_Cobble_Mossy"
    },
    {
      "x": -47,
      "y": 46,
      "z": -3,
      "name": "Rock_Stone_Cobble_Mossy"
    },
    {
      "x": -47,
      "y": 47,
      "z": -3,
      "name": "Rock_Stone_Mossy"
    },
    {
      "x": -47,
      "y": 43,
      "z": -2,
      "name": "Rock_Stone_Mossy"
    },
    {
      "x": -47,
      "y": 44,
      "z": -2,
      "name": "Soil_Gravel_Mossy"
    },
    {
      "x": -47,
      "y": 45,
      "z": -2,
      "name": "Soil_Dirt"
    },
    {
      "x": -47,
      "y": 46,
      "z": -2,
      "name": "Soil_Dirt"
    },
    {
      "x": -47,
      "y": 47,
      "z": -2,
      "name": "Rock_Stone"
    },
    {
      "x": -47,
      "y": 44,
      "z": -1,
      "name": "Soil_Dirt"
    },
    {
      "x": -47,
      "y": 45,
      "z": -1,
      "name": "Plant_Moss_Block_Green"
    },
    {
      "x": -47,
      "y": 46,
      "z": -1,
      "name": "Rock_Stone_Mossy"
    },
    {
      "x": -46,
      "y": 46,
      "z": -9,
      "name": "Rock_Stone"
    },
    {
      "x": -46,
      "y": 43,
      "z": -8,
      "name": "Rock_Stone_Mossy"
    },
    {
      "x": -46,
      "y": 44,
      "z": -8,
      "name": "Rock_Stone_Mossy"
    },
    {
      "x": -46,
      "y": 45,
      "z": -8,
      "name": "Rock_Stone"
    },
    {
      "x": -46,
      "y": 46,
      "z": -8,
      "name": "Soil_Dirt"
    },
    {
      "x": -46,
      "y": 47,
      "z": -8,
      "name": "Soil_Dirt"
    },
    {
      "x": -46,
      "y": 43,
      "z": -7,
      "name": "Rock_Stone"
    },
    {
      "x": -46,
      "y": 44,
      "z": -7,
      "name": "Rock_Stone_Cobble_Mossy"
    },
    {
      "x": -46,
      "y": 45,
      "z": -7,
      "name": "Soil_Gravel_Mossy"
    },
    {
      "x": -46,
      "y": 46,
      "z": -7,
      "name": "Rock_Stone_Cobble_Mossy"
    },
    {
      "x": -46,
      "y": 47,
      "z": -7,
      "name": "Rock_Stone_Cobble_Mossy"
    },
    {
      "x": -46,
      "y": 48,
      "z": -7,
      "name": "Soil_Dirt"
    },
    {
      "x": -46,
      "y": 42,
      "z": -6,
      "name": "Rock_Stone"
    },
    {
      "x": -46,
      "y": 43,
      "z": -6,
      "name": "Rock_Stone_Cobble_Mossy"
    },
    {
      "x": -46,
      "y": 44,
      "z": -6,
      "name": "Soil_Dirt"
    },
    {
      "x": -46,
      "y": 45,
      "z": -6,
      "name": "Soil_Dirt"
    },
    {
      "x": -46,
      "y": 46,
      "z": -6,
      "name": "Soil_Dirt"
    },
    {
      "x": -46,
      "y": 47,
      "z": -6,
      "name": "Rock_Stone"
    },
    {
      "x": -46,
      "y": 48,
      "z": -6,
      "name": "Rock_Stone"
    },
    {
      "x": -46,
      "y": 42,
      "z": -5,
      "name": "Rock_Stone_Mossy"
    },
    {
      "x": -46,
      "y": 43,
      "z": -5,
      "name": "Plant_Moss_Block_Green"
    },
    {
      "x": -46,
      "y": 44,
      "z": -5,
      "name": "Soil_Gravel_Mossy"
    },
    {
      "x": -46,
      "y": 45,
      "z": -5,
      "name": "Rock_Stone_Mossy"
    },
    {
      "x": -46,
      "y": 46,
      "z": -5,
      "name": "Rock_Stone_Mossy"
    },
    {
      "x": -46,
      "y": 47,
      "z": -5,
      "name": "Plant_Moss_Block_Green"
    },
    {
      "x": -46,
      "y": 48,
      "z": -5,
      "name": "Soil_Gravel_Mossy"
    },
    {
      "x": -46,
      "y": 49,
      "z": -5,
      "name": "Rock_Stone_Mossy"
    },
    {
      "x": -46,
      "y": 42,
      "z": -4,
      "name": "Rock_Stone_Mossy"
    },
    {
      "x": -46,
      "y": 43,
      "z": -4,
      "name": "Soil_Gravel_Mossy"
    },
    {
      "x": -46,
      "y": 44,
      "z": -4,
      "name": "Soil_Gravel_Mossy"
    },
    {
      "x": -46,
      "y": 45,
      "z": -4,
      "name": "Soil_Dirt"
    },
    {
      "x": -46,
      "y": 46,
      "z": -4,
      "name": "Plant_Moss_Block_Green"
    },
    {
      "x": -46,
      "y": 47,
      "z": -4,
      "name": "Rock_Stone_Cobble_Mossy"
    },
    {
      "x": -46,
      "y": 48,
      "z": -4,
      "name": "Rock_Stone_Mossy"
    },
    {
      "x": -46,
      "y": 49,
      "z": -4,
      "name": "Soil_Dirt"
    },
    {
      "x": -46,
      "y": 42,
      "z": -3,
      "name": "Rock_Stone_Cobble_Mossy"
    },
    {
      "x": -46,
      "y": 43,
      "z": -3,
      "name": "Rock_Stone"
    },
    {
      "x": -46,
      "y": 44,
      "z": -3,
      "name": "Plant_Moss_Block_Green"
    },
    {
      "x": -46,
      "y": 45,
      "z": -3,
      "name": "Soil_Dirt"
    },
    {
      "x": -46,
      "y": 46,
      "z": -3,
      "name": "Plant_Moss_Block_Green"
    },
    {
      "x": -46,
      "y": 47,
      "z": -3,
      "name": "Rock_Stone"
    },
    {
      "x": -46,
      "y": 48,
      "z": -3,
      "name": "Plant_Moss_Block_Green"
    },
    {
      "x": -46,
      "y": 42,
      "z": -2,
      "name": "Rock_Stone_Mossy"
    },
    {
      "x": -46,
      "y": 43,
      "z": -2,
      "name": "Plant_Moss_Block_Green"
    },
    {
      "x": -46,
      "y": 44,
      "z": -2,
      "name": "Soil_Dirt"
    },
    {
      "x": -46,
      "y": 45,
      "z": -2,
      "name": "Plant_Moss_Block_Green"
    },
    {
      "x": -46,
      "y": 46,
      "z": -2,
      "name": "Rock_Stone_Cobble_Mossy"
    },
    {
      "x": -46,
      "y": 47,
      "z": -2,
      "name": "Soil_Gravel_Mossy"
    },
    {
      "x": -46,
      "y": 48,
      "z": -2,
      "name": "Rock_Stone_Mossy"
    },
    {
      "x": -46,
      "y": 49,
      "z": -2,
      "name": "Rock_Stone_Mossy"
    },
    {
      "x": -46,
      "y": 43,
      "z": -1,
      "name": "Plant_Moss_Block_Green"
    },
    {
      "x": -46,
      "y": 44,
      "z": -1,
      "name": "Rock_Stone_Cobble_Mossy"
    },
    {
      "x": -46,
      "y": 45,
      "z": -1,
      "name": "Soil_Dirt"
    },
    {
      "x": -46,
      "y": 46,
      "z": -1,
      "name": "Plant_Moss_Block_Green"
    },
    {
      "x": -46,
      "y": 47,
      "z": -1,
      "name": "Rock_Stone"
    },
    {
      "x": -46,
      "y": 44,
      "z": 0,
      "name": "Rock_Stone"
    },
    {
      "x": -46,
      "y": 45,
      "z": 0,
      "name": "Rock_Stone_Mossy"
    },
    {
      "x": -46,
      "y": 46,
      "z": 0,
      "name": "Soil_Dirt"
    },
    {
      "x": -46,
      "y": 47,
      "z": 0,
      "name": "Rock_Stone_Cobble_Mossy"
    },
    {
      "x": -45,
      "y": 43,
      "z": -9,
      "name": "Soil_Gravel_Mossy"
    },
    {
      "x": -45,
      "y": 44,
      "z": -9,
      "name": "Plant_Moss_Block_Green"
    },
    {
      "x": -45,
      "y": 46,
      "z": -9,
      "name": "Plant_Moss_Block_Green"
    },
    {
      "x": -45,
      "y": 43,
      "z": -8,
      "name": "Rock_Stone_Cobble_Mossy"
    },
    {
      "x": -45,
      "y": 44,
      "z": -8,
      "name": "Soil_Dirt"
    },
    {
      "x": -45,
      "y": 45,
      "z": -8,
      "name": "Plant_Moss_Block_Green"
    },
    {
      "x": -45,
      "y": 46,
      "z": -8,
      "name": "Rock_Stone_Mossy"
    },
    {
      "x": -45,
      "y": 47,
      "z": -8,
      "name": "Soil_Gravel_Mossy"
    },
    {
      "x": -45,
      "y": 42,
      "z": -7,
      "name": "Soil_Dirt"
    },
    {
      "x": -45,
      "y": 43,
      "z": -7,
      "name": "Soil_Gravel_Mossy"
    },
    {
      "x": -45,
      "y": 44,
      "z": -7,
      "name": "Rock_Stone_Mossy"
    },
    {
      "x": -45,
      "y": 45,
      "z": -7,
      "name": "Plant_Moss_Block_Green"
    },
    {
      "x": -45,
      "y": 46,
      "z": -7,
      "name": "Soil_Dirt"
    },
    {
      "x": -45,
      "y": 47,
      "z": -7,
      "name": "Plant_Moss_Block_Green"
    },
    {
      "x": -45,
      "y": 48,
      "z": -7,
      "name": "Rock_Stone"
    },
    {
      "x": -45,
      "y": 41,
      "z": -6,
      "name": "Soil_Gravel_Mossy"
    },
    {
      "x": -45,
      "y": 42,
      "z": -6,
      "name": "Rock_Stone_Cobble_Mossy"
    },
    {
      "x": -45,
      "y": 43,
      "z": -6,
      "name": "Rock_Stone_Cobble_Mossy"
    },
    {
      "x": -45,
      "y": 44,
      "z": -6,
      "name": "Plant_Moss_Block_Green"
    },
    {
      "x": -45,
      "y": 45,
      "z": -6,
      "name": "Soil_Dirt"
    },
    {
      "x": -45,
      "y": 46,
      "z": -6,
      "name": "Rock_Stone"
    },
    {
      "x": -45,
      "y": 47,
      "z": -6,
      "name": "Rock_Stone_Mossy"
    },
    {
      "x": -45,
      "y": 48,
      "z": -6,
      "name": "Rock_Stone_Cobble_Mossy"
    },
    {
      "x": -45,
      "y": 41,
      "z": -5,
      "name": "Rock_Stone"
    },
    {
      "x": -45,
      "y": 42,
      "z": -5,
      "name": "Soil_Gravel_Mossy"
    },
    {
      "x": -45,
      "y": 43,
      "z": -5,
      "name": "Rock_Stone_Cobble_Mossy"
    },
    {
      "x": -45,
      "y": 44,
      "z": -5,
      "name": "Soil_Dirt"
    },
    {
      "x": -45,
      "y": 45,
      "z": -5,
      "name": "Rock_Stone_Mossy"
    },
    {
      "x": -45,
      "y": 46,
      "z": -5,
      "name": "Rock_Stone"
    },
    {
      "x": -45,
      "y": 47,
      "z": -5,
      "name": "Plant_Moss_Block_Green"
    },
    {
      "x": -45,
      "y": 48,
      "z": -5,
      "name": "Plant_Moss_Block_Green"
    },
    {
      "x": -45,
      "y": 49,
      "z": -5,
      "name": "Rock_Stone"
    },
    {
      "x": -45,
      "y": 41,
      "z": -4,
      "name": "Rock_Stone_Cobble_Mossy"
    },
    {
      "x": -45,
      "y": 42,
      "z": -4,
      "name": "Rock_Stone_Mossy"
    },
    {
      "x": -45,
      "y": 43,
      "z": -4,
      "name": "Soil_Gravel_Mossy"
    },
    {
      "x": -45,
      "y": 44,
      "z": -4,
      "name": "Rock_Stone"
    },
    {
      "x": -45,
      "y": 45,
      "z": -4,
      "name": "Rock_Stone"
    },
    {
      "x": -45,
      "y": 46,
      "z": -4,
      "name": "Rock_Stone"
    },
    {
      "x": -45,
      "y": 47,
      "z": -4,
      "name": "Rock_Stone"
    },
    {
      "x": -45,
      "y": 48,
      "z": -4,
      "name": "Soil_Gravel_Mossy"
    },
    {
      "x": -45,
      "y": 49,
      "z": -4,
      "name": "Rock_Stone_Mossy"
    },
    {
      "x": -45,
      "y": 41,
      "z": -3,
      "name": "Soil_Gravel_Mossy"
    },
    {
      "x": -45,
      "y": 42,
      "z": -3,
      "name": "Rock_Stone_Cobble_Mossy"
    },
    {
      "x": -45,
      "y": 43,
      "z": -3,
      "name": "Plant_Moss_Block_Green"
    },
    {
      "x": -45,
      "y": 44,
      "z": -3,
      "name": "Soil_Gravel_Mossy"
    },
    {
      "x": -45,
      "y": 45,
      "z": -3,
      "name": "Plant_Moss_Block_Green"
    },
    {
      "x": -45,
      "y": 46,
      "z": -3,
      "name": "Soil_Gravel_Mossy"
    },
    {
      "x": -45,
      "y": 47,
      "z": -3,
      "name": "Rock_Stone_Mossy"
    },
    {
      "x": -45,
      "y": 48,
      "z": -3,
      "name": "Soil_Dirt"
    },
    {
      "x": -45,
      "y": 49,
      "z": -3,
      "name": "Rock_Stone"
    },
    {
      "x": -45,
      "y": 41,
      "z": -2,
      "name": "Soil_Dirt"
    },
    {
      "x": -45,
      "y": 42,
      "z": -2,
      "name": "Rock_Stone_Mossy"
    },
    {
      "x": -45,
      "y": 43,
      "z": -2,
      "name": "Rock_Stone_Cobble_Mossy"
    },
    {
      "x": -45,
      "y": 44,
      "z": -2,
      "name": "Rock_Stone_Mossy"
    },
    {
      "x": -45,
      "y": 45,
      "z": -2,
      "name": "Plant_Moss_Block_Green"
    },
    {
      "x": -45,
      "y": 46,
      "z": -2,
      "name": "Rock_Stone_Mossy"
    },
    {
      "x": -45,
      "y": 47,
      "z": -2,
      "name": "Soil_Gravel_Mossy"
    },
    {
      "x": -45,
      "y": 48,
      "z": -2,
      "name": "Rock_Stone_Cobble_Mossy"
    },
    {
      "x": -45,
      "y": 49,
      "z": -2,
      "name": "Soil_Gravel_Mossy"
    },
    {
      "x": -45,
      "y": 42,
      "z": -1,
      "name": "Soil_Gravel_Mossy"
    },
    {
      "x": -45,
      "y": 43,
      "z": -1,
      "name": "Soil_Gravel_Mossy"
    },
    {
      "x": -45,
      "y": 44,
      "z": -1,
      "name": "Rock_Stone_Mossy"
    },
    {
      "x": -45,
      "y": 45,
      "z": -1,
      "name": "Soil_Gravel_Mossy"
    },
    {
      "x": -45,
      "y": 46,
      "z": -1,
      "name": "Rock_Stone_Cobble_Mossy"
    },
    {
      "x": -45,
      "y": 47,
      "z": -1,
      "name": "Plant_Moss_Block_Green"
    },
    {
      "x": -45,
      "y": 48,
      "z": -1,
      "name": "Rock_Stone_Mossy"
    },
    {
      "x": -45,
      "y": 49,
      "z": -1,
      "name": "Rock_Stone"
    },
    {
      "x": -45,
      "y": 41,
      "z": 0,
      "name": "Rock_Stone"
    },
    {
      "x": -45,
      "y": 42,
      "z": 0,
      "name": "Rock_Stone"
    },
    {
      "x": -45,
      "y": 43,
      "z": 0,
      "name": "Soil_Gravel_Mossy"
    },
    {
      "x": -45,
      "y": 44,
      "z": 0,
      "name": "Soil_Gravel_Mossy"
    },
    {
      "x": -45,
      "y": 45,
      "z": 0,
      "name": "Plant_Moss_Block_Green"
    },
    {
      "x": -45,
      "y": 46,
      "z": 0,
      "name": "Rock_Stone"
    },
    {
      "x": -45,
      "y": 47,
      "z": 0,
      "name": "Soil_Dirt"
    },
    {
      "x": -45,
      "y": 44,
      "z": 1,
      "name": "Soil_Dirt"
    },
    {
      "x": -45,
      "y": 45,
      "z": 1,
      "name": "Rock_Stone"
    },
    {
      "x": -45,
      "y": 46,
      "z": 1,
      "name": "Soil_Dirt"
    },
    {
      "x": -44,
      "y": 43,
      "z": -8,
      "name": "Soil_Gravel_Mossy"
    },
    {
      "x": -44,
      "y": 44,
      "z": -8,
      "name": "Rock_Stone_Mossy"
    },
    {
      "x": -44,
      "y": 45,
      "z": -8,
      "name": "Plant_Moss_Block_Green"
    },
    {
      "x": -44,
      "y": 46,
      "z": -8,
      "name": "Plant_Moss_Block_Green"
    },
    {
      "x": -44,
      "y": 47,
      "z": -8,
      "name": "Soil_Dirt"
    },
    {
      "x": -44,
      "y": 41,
      "z": -7,
      "name": "Rock_Stone"
    },
    {
      "x": -44,
      "y": 42,
      "z": -7,
      "name": "Plant_Moss_Block_Green"
    },
    {
      "x": -44,
      "y": 43,
      "z": -7,
      "name": "Soil_Dirt"
    },
    {
      "x": -44,
      "y": 44,
      "z": -7,
      "name": "Soil_Gravel_Mossy"
    },
    {
      "x": -44,
      "y": 45,
      "z": -7,
      "name": "Rock_Stone_Mossy"
    },
    {
      "x": -44,
      "y": 46,
      "z": -7,
      "name": "Rock_Stone_Mossy"
    },
    {
      "x": -44,
      "y": 47,
      "z": -7,
      "name": "Rock_Stone_Cobble_Mossy"
    },
    {
      "x": -44,
      "y": 48,
      "z": -7,
      "name": "Rock_Stone_Mossy"
    },
    {
      "x": -44,
      "y": 41,
      "z": -6,
      "name": "Rock_Stone"
    },
    {
      "x": -44,
      "y": 42,
      "z": -6,
      "name": "Soil_Gravel_Mossy"
    },
    {
      "x": -44,
      "y": 43,
      "z": -6,
      "name": "Rock_Stone_Cobble_Mossy"
    },
    {
      "x": -44,
      "y": 44,
      "z": -6,
      "name": "Rock_Stone_Mossy"
    },
    {
      "x": -44,
      "y": 45,
      "z": -6,
      "name": "Soil_Gravel_Mossy"
    },
    {
      "x": -44,
      "y": 46,
      "z": -6,
      "name": "Soil_Gravel_Mossy"
    },
    {
      "x": -44,
      "y": 47,
      "z": -6,
      "name": "Rock_Stone_Cobble_Mossy"
    },
    {
      "x": -44,
      "y": 48,
      "z": -6,
      "name": "Rock_Stone"
    },
    {
      "x": -44,
      "y": 49,
      "z": -6,
      "name": "Plant_Moss_Block_Green"
    },
    {
      "x": -44,
      "y": 41,
      "z": -5,
      "name": "Soil_Dirt"
    },
    {
      "x": -44,
      "y": 42,
      "z": -5,
      "name": "Soil_Dirt"
    },
    {
      "x": -44,
      "y": 43,
      "z": -5,
      "name": "Rock_Stone_Cobble_Mossy"
    },
    {
      "x": -44,
      "y": 44,
      "z": -5,
      "name": "Soil_Gravel_Mossy"
    },
    {
      "x": -44,
      "y": 45,
      "z": -5,
      "name": "Rock_Stone"
    },
    {
      "x": -44,
      "y": 46,
      "z": -5,
      "name": "Plant_Moss_Block_Green"
    },
    {
      "x": -44,
      "y": 47,
      "z": -5,
      "name": "Rock_Stone"
    },
    {
      "x": -44,
      "y": 48,
      "z": -5,
      "name": "Soil_Dirt"
    },
    {
      "x": -44,
      "y": 49,
      "z": -5,
      "name": "Soil_Gravel_Mossy"
    },
    {
      "x": -44,
      "y": 41,
      "z": -4,
      "name": "Rock_Stone_Cobble_Mossy"
    },
    {
      "x": -44,
      "y": 42,
      "z": -4,
      "name": "Rock_Stone_Mossy"
    },
    {
      "x": -44,
      "y": 43,
      "z": -4,
      "name": "Rock_Stone_Mossy"
    },
    {
      "x": -44,
      "y": 44,
      "z": -4,
      "name": "Soil_Gravel_Mossy"
    },
    {
      "x": -44,
      "y": 45,
      "z": -4,
      "name": "Plant_Moss_Block_Green"
    },
    {
      "x": -44,
      "y": 46,
      "z": -4,
      "name": "Rock_Stone"
    },
    {
      "x": -44,
      "y": 47,
      "z": -4,
      "name": "Rock_Stone_Mossy"
    },
    {
      "x": -44,
      "y": 48,
      "z": -4,
      "name": "Rock_Stone_Cobble_Mossy"
    },
    {
      "x": -44,
      "y": 49,
      "z": -4,
      "name": "Rock_Stone_Mossy"
    },
    {
      "x": -44,
      "y": 50,
      "z": -4,
      "name": "Rock_Stone"
    },
    {
      "x": -44,
      "y": 41,
      "z": -3,
      "name": "Rock_Stone_Mossy"
    },
    {
      "x": -44,
      "y": 42,
      "z": -3,
      "name": "Soil_Dirt"
    },
    {
      "x": -44,
      "y": 43,
      "z": -3,
      "name": "Plant_Moss_Block_Green"
    },
    {
      "x": -44,
      "y": 44,
      "z": -3,
      "name": "Rock_Stone_Cobble_Mossy"
    },
    {
      "x": -44,
      "y": 45,
      "z": -3,
      "name": "Soil_Dirt"
    },
    {
      "x": -44,
      "y": 46,
      "z": -3,
      "name": "Rock_Stone_Cobble_Mossy"
    },
    {
      "x": -44,
      "y": 47,
      "z": -3,
      "name": "Soil_Dirt"
    },
    {
      "x": -44,
      "y": 48,
      "z": -3,
      "name": "Rock_Stone_Cobble_Mossy"
    },
    {
      "x": -44,
      "y": 49,
      "z": -3,
      "name": "Rock_Stone"
    },
    {
      "x": -44,
      "y": 41,
      "z": -2,
      "name": "Rock_Stone"
    },
    {
      "x": -44,
      "y": 42,
      "z": -2,
      "name": "Plant_Moss_Block_Green"
    },
    {
      "x": -44,
      "y": 43,
      "z": -2,
      "name": "Rock_Stone_Cobble_Mossy"
    },
    {
      "x": -44,
      "y": 44,
      "z": -2,
      "name": "Rock_Stone"
    },
    {
      "x": -44,
      "y": 45,
      "z": -2,
      "name": "Plant_Moss_Block_Green"
    },
    {
      "x": -44,
      "y": 46,
      "z": -2,
      "name": "Rock_Stone"
    },
    {
      "x": -44,
      "y": 47,
      "z": -2,
      "name": "Soil_Gravel_Mossy"
    },
    {
      "x": -44,
      "y": 48,
      "z": -2,
      "name": "Rock_Stone_Mossy"
    },
    {
      "x": -44,
      "y": 49,
      "z": -2,
      "name": "Rock_Stone_Cobble_Mossy"
    },
    {
      "x": -44,
      "y": 41,
      "z": -1,
      "name": "Plant_Moss_Block_Green"
    },
    {
      "x": -44,
      "y": 42,
      "z": -1,
      "name": "Soil_Dirt"
    },
    {
      "x": -44,
      "y": 43,
      "z": -1,
      "name": "Plant_Moss_Block_Green"
    },
    {
      "x": -44,
      "y": 44,
      "z": -1,
      "name": "Plant_Moss_Block_Green"
    },
    {
      "x": -44,
      "y": 45,
      "z": -1,
      "name": "Soil_Dirt"
    },
    {
      "x": -44,
      "y": 46,
      "z": -1,
      "name": "Rock_Stone_Cobble_Mossy"
    },
    {
      "x": -44,
      "y": 47,
      "z": -1,
      "name": "Rock_Stone"
    },
    {
      "x": -44,
      "y": 48,
      "z": -1,
      "name": "Rock_Stone"
    },
    {
      "x": -44,
      "y": 49,
      "z": -1,
      "name": "Rock_Stone"
    },
    {
      "x": -44,
      "y": 50,
      "z": -1,
      "name": "Soil_Dirt"
    },
    {
      "x": -44,
      "y": 42,
      "z": 0,
      "name": "Plant_Moss_Block_Green"
    },
    {
      "x": -44,
      "y": 43,
      "z": 0,
      "name": "Soil_Dirt"
    },
    {
      "x": -44,
      "y": 44,
      "z": 0,
      "name": "Rock_Stone"
    },
    {
      "x": -44,
      "y": 45,
      "z": 0,
      "name": "Soil_Dirt"
    },
    {
      "x": -44,
      "y": 46,
      "z": 0,
      "name": "Rock_Stone_Mossy"
    },
    {
      "x": -44,
      "y": 47,
      "z": 0,
      "name": "Soil_Dirt"
    },
    {
      "x": -44,
      "y": 48,
      "z": 0,
      "name": "Soil_Dirt"
    },
    {
      "x": -44,
      "y": 43,
      "z": 1,
      "name": "Rock_Stone_Mossy"
    },
    {
      "x": -44,
      "y": 44,
      "z": 1,
      "name": "Plant_Moss_Block_Green"
    },
    {
      "x": -44,
      "y": 45,
      "z": 1,
      "name": "Soil_Gravel_Mossy"
    },
    {
      "x": -44,
      "y": 46,
      "z": 1,
      "name": "Rock_Stone_Mossy"
    },
    {
      "x": -44,
      "y": 47,
      "z": 1,
      "name": "Plant_Moss_Block_Green"
    },
    {
      "x": -43,
      "y": 45,
      "z": -9,
      "name": "Plant_Moss_Block_Green"
    },
    {
      "x": -43,
      "y": 43,
      "z": -8,
      "name": "Rock_Stone_Mossy"
    },
    {
      "x": -43,
      "y": 44,
      "z": -8,
      "name": "Soil_Dirt"
    },
    {
      "x": -43,
      "y": 45,
      "z": -8,
      "name": "Plant_Moss_Block_Green"
    },
    {
      "x": -43,
      "y": 46,
      "z": -8,
      "name": "Plant_Moss_Block_Green"
    },
    {
      "x": -43,
      "y": 47,
      "z": -8,
      "name": "Plant_Moss_Block_Green"
    },
    {
      "x": -43,
      "y": 48,
      "z": -8,
      "name": "Soil_Gravel_Mossy"
    },
    {
      "x": -43,
      "y": 41,
      "z": -7,
      "name": "Rock_Stone"
    },
    {
      "x": -43,
      "y": 42,
      "z": -7,
      "name": "Rock_Stone_Mossy"
    },
    {
      "x": -43,
      "y": 43,
      "z": -7,
      "name": "Rock_Stone"
    },
    {
      "x": -43,
      "y": 44,
      "z": -7,
      "name": "Soil_Gravel_Mossy"
    },
    {
      "x": -43,
      "y": 45,
      "z": -7,
      "name": "Rock_Stone_Cobble_Mossy"
    },
    {
      "x": -43,
      "y": 46,
      "z": -7,
      "name": "Soil_Gravel_Mossy"
    },
    {
      "x": -43,
      "y": 47,
      "z": -7,
      "name": "Plant_Moss_Block_Green"
    },
    {
      "x": -43,
      "y": 48,
      "z": -7,
      "name": "Rock_Stone_Cobble_Mossy"
    },
    {
      "x": -43,
      "y": 41,
      "z": -6,
      "name": "Rock_Stone_Cobble_Mossy"
    },
    {
      "x": -43,
      "y": 42,
      "z": -6,
      "name": "Rock_Stone"
    },
    {
      "x": -43,
      "y": 43,
      "z": -6,
      "name": "Rock_Stone"
    },
    {
      "x": -43,
      "y": 44,
      "z": -6,
      "name": "Soil_Gravel_Mossy"
    },
    {
      "x": -43,
      "y": 45,
      "z": -6,
      "name": "Rock_Stone_Cobble_Mossy"
    },
    {
      "x": -43,
      "y": 46,
      "z": -6,
      "name": "Rock_Stone"
    },
    {
      "x": -43,
      "y": 47,
      "z": -6,
      "name": "Rock_Stone"
    },
    {
      "x": -43,
      "y": 48,
      "z": -6,
      "name": "Rock_Stone_Cobble_Mossy"
    },
    {
      "x": -43,
      "y": 49,
      "z": -6,
      "name": "Soil_Dirt"
    },
    {
      "x": -43,
      "y": 41,
      "z": -5,
      "name": "Rock_Stone"
    },
    {
      "x": -43,
      "y": 42,
      "z": -5,
      "name": "Rock_Stone_Mossy"
    },
    {
      "x": -43,
      "y": 43,
      "z": -5,
      "name": "Rock_Stone_Mossy"
    },
    {
      "x": -43,
      "y": 44,
      "z": -5,
      "name": "Plant_Moss_Block_Green"
    },
    {
      "x": -43,
      "y": 45,
      "z": -5,
      "name": "Rock_Stone_Mossy"
    },
    {
      "x": -43,
      "y": 46,
      "z": -5,
      "name": "Soil_Gravel_Mossy"
    },
    {
      "x": -43,
      "y": 47,
      "z": -5,
      "name": "Rock_Stone_Cobble_Mossy"
    },
    {
      "x": -43,
      "y": 48,
      "z": -5,
      "name": "Rock_Stone"
    },
    {
      "x": -43,
      "y": 49,
      "z": -5,
      "name": "Soil_Dirt"
    },
    {
      "x": -43,
      "y": 40,
      "z": -4,
      "name": "Rock_Stone_Cobble_Mossy"
    },
    {
      "x": -43,
      "y": 41,
      "z": -4,
      "name": "Rock_Stone_Mossy"
    },
    {
      "x": -43,
      "y": 42,
      "z": -4,
      "name": "Soil_Gravel_Mossy"
    },
    {
      "x": -43,
      "y": 43,
      "z": -4,
      "name": "Plant_Moss_Block_Green"
    },
    {
      "x": -43,
      "y": 44,
      "z": -4,
      "name": "Rock_Stone"
    },
    {
      "x": -43,
      "y": 45,
      "z": -4,
      "name": "Soil_Dirt"
    },
    {
      "x": -43,
      "y": 46,
      "z": -4,
      "name": "Rock_Stone"
    },
    {
      "x": -43,
      "y": 47,
      "z": -4,
      "name": "Rock_Stone_Mossy"
    },
    {
      "x": -43,
      "y": 48,
      "z": -4,
      "name": "Soil_Gravel_Mossy"
    },
    {
      "x": -43,
      "y": 49,
      "z": -4,
      "name": "Plant_Moss_Block_Green"
    },
    {
      "x": -43,
      "y": 50,
      "z": -4,
      "name": "Soil_Dirt"
    },
    {
      "x": -43,
      "y": 40,
      "z": -3,
      "name": "Rock_Stone"
    },
    {
      "x": -43,
      "y": 41,
      "z": -3,
      "name": "Plant_Moss_Block_Green"
    },
    {
      "x": -43,
      "y": 42,
      "z": -3,
      "name": "Soil_Dirt"
    },
    {
      "x": -43,
      "y": 43,
      "z": -3,
      "name": "Plant_Moss_Block_Green"
    },
    {
      "x": -43,
      "y": 44,
      "z": -3,
      "name": "Rock_Stone_Cobble_Mossy"
    },
    {
      "x": -43,
      "y": 45,
      "z": -3,
      "name": "Soil_Gravel_Mossy"
    },
    {
      "x": -43,
      "y": 46,
      "z": -3,
      "name": "Rock_Stone_Mossy"
    },
    {
      "x": -43,
      "y": 47,
      "z": -3,
      "name": "Soil_Dirt"
    },
    {
      "x": -43,
      "y": 48,
      "z": -3,
      "name": "Soil_Dirt"
    },
    {
      "x": -43,
      "y": 49,
      "z": -3,
      "name": "Rock_Stone_Mossy"
    },
    {
      "x": -43,
      "y": 50,
      "z": -3,
      "name": "Soil_Dirt"
    },
    {
      "x": -43,
      "y": 38,
      "z": -2,
      "name": "Rock_Crystal_Green_Large",
      "rotation": 8
    },
    {
      "x": -43,
      "y": 39,
      "z": -2,
      "name": "Soil_Dirt"
    },
    {
      "x": -43,
      "y": 40,
      "z": -2,
      "name": "Rock_Stone"
    },
    {
      "x": -43,
      "y": 41,
      "z": -2,
      "name": "Soil_Gravel_Mossy"
    },
    {
      "x": -43,
      "y": 42,
      "z": -2,
      "name": "Rock_Stone_Cobble_Mossy"
    },
    {
      "x": -43,
      "y": 43,
      "z": -2,
      "name": "Soil_Dirt"
    },
    {
      "x": -43,
      "y": 44,
      "z": -2,
      "name": "Rock_Stone_Cobble_Mossy"
    },
    {
      "x": -43,
      "y": 45,
      "z": -2,
      "name": "Rock_Stone_Cobble_Mossy"
    },
    {
      "x": -43,
      "y": 46,
      "z": -2,
      "name": "Rock_Stone_Cobble_Mossy"
    },
    {
      "x": -43,
      "y": 47,
      "z": -2,
      "name": "Soil_Gravel_Mossy"
    },
    {
      "x": -43,
      "y": 48,
      "z": -2,
      "name": "Soil_Gravel_Mossy"
    },
    {
      "x": -43,
      "y": 49,
      "z": -2,
      "name": "Rock_Stone_Mossy"
    },
    {
      "x": -43,
      "y": 50,
      "z": -2,
      "name": "Rock_Stone_Cobble_Mossy"
    },
    {
      "x": -43,
      "y": 40,
      "z": -1,
      "name": "Plant_Moss_Block_Green"
    },
    {
      "x": -43,
      "y": 41,
      "z": -1,
      "name": "Plant_Moss_Block_Green"
    },
    {
      "x": -43,
      "y": 42,
      "z": -1,
      "name": "Soil_Dirt"
    },
    {
      "x": -43,
      "y": 43,
      "z": -1,
      "name": "Soil_Dirt"
    },
    {
      "x": -43,
      "y": 44,
      "z": -1,
      "name": "Soil_Dirt"
    },
    {
      "x": -43,
      "y": 45,
      "z": -1,
      "name": "Plant_Moss_Block_Green"
    },
    {
      "x": -43,
      "y": 46,
      "z": -1,
      "name": "Rock_Stone"
    },
    {
      "x": -43,
      "y": 47,
      "z": -1,
      "name": "Rock_Stone_Cobble_Mossy"
    },
    {
      "x": -43,
      "y": 48,
      "z": -1,
      "name": "Plant_Moss_Block_Green"
    },
    {
      "x": -43,
      "y": 49,
      "z": -1,
      "name": "Soil_Dirt"
    },
    {
      "x": -43,
      "y": 42,
      "z": 0,
      "name": "Rock_Stone_Cobble_Mossy"
    },
    {
      "x": -43,
      "y": 43,
      "z": 0,
      "name": "Soil_Dirt"
    },
    {
      "x": -43,
      "y": 44,
      "z": 0,
      "name": "Plant_Moss_Block_Green"
    },
    {
      "x": -43,
      "y": 45,
      "z": 0,
      "name": "Rock_Stone"
    },
    {
      "x": -43,
      "y": 46,
      "z": 0,
      "name": "Rock_Stone_Mossy"
    },
    {
      "x": -43,
      "y": 47,
      "z": 0,
      "name": "Soil_Gravel_Mossy"
    },
    {
      "x": -43,
      "y": 48,
      "z": 0,
      "name": "Soil_Gravel_Mossy"
    },
    {
      "x": -43,
      "y": 43,
      "z": 1,
      "name": "Soil_Gravel_Mossy"
    },
    {
      "x": -43,
      "y": 44,
      "z": 1,
      "name": "Soil_Gravel_Mossy"
    },
    {
      "x": -43,
      "y": 45,
      "z": 1,
      "name": "Rock_Stone"
    },
    {
      "x": -43,
      "y": 46,
      "z": 1,
      "name": "Soil_Dirt"
    },
    {
      "x": -43,
      "y": 47,
      "z": 1,
      "name": "Soil_Dirt"
    },
    {
      "x": -43,
      "y": 48,
      "z": 1,
      "name": "Rock_Stone_Cobble_Mossy"
    },
    {
      "x": -43,
      "y": 43,
      "z": 2,
      "name": "Rock_Stone_Cobble_Mossy"
    },
    {
      "x": -43,
      "y": 44,
      "z": 2,
      "name": "Soil_Dirt"
    },
    {
      "x": -43,
      "y": 45,
      "z": 2,
      "name": "Soil_Gravel_Mossy"
    },
    {
      "x": -43,
      "y": 46,
      "z": 2,
      "name": "Soil_Dirt"
    },
    {
      "x": -43,
      "y": 44,
      "z": 3,
      "name": "Rock_Stone"
    },
    {
      "x": -42,
      "y": 43,
      "z": -8,
      "name": "Rock_Stone"
    },
    {
      "x": -42,
      "y": 44,
      "z": -8,
      "name": "Rock_Stone"
    },
    {
      "x": -42,
      "y": 45,
      "z": -8,
      "name": "Plant_Moss_Block_Green"
    },
    {
      "x": -42,
      "y": 46,
      "z": -8,
      "name": "Rock_Stone_Mossy"
    },
    {
      "x": -42,
      "y": 47,
      "z": -8,
      "name": "Rock_Stone_Mossy"
    },
    {
      "x": -42,
      "y": 42,
      "z": -7,
      "name": "Soil_Gravel_Mossy"
    },
    {
      "x": -42,
      "y": 43,
      "z": -7,
      "name": "Plant_Moss_Block_Green"
    },
    {
      "x": -42,
      "y": 44,
      "z": -7,
      "name": "Plant_Moss_Block_Green"
    },
    {
      "x": -42,
      "y": 45,
      "z": -7,
      "name": "Plant_Moss_Block_Green"
    },
    {
      "x": -42,
      "y": 46,
      "z": -7,
      "name": "Soil_Gravel_Mossy"
    },
    {
      "x": -42,
      "y": 47,
      "z": -7,
      "name": "Plant_Moss_Block_Green"
    },
    {
      "x": -42,
      "y": 48,
      "z": -7,
      "name": "Rock_Stone"
    },
    {
      "x": -42,
      "y": 41,
      "z": -6,
      "name": "Plant_Moss_Block_Green"
    },
    {
      "x": -42,
      "y": 42,
      "z": -6,
      "name": "Soil_Dirt"
    },
    {
      "x": -42,
      "y": 43,
      "z": -6,
      "name": "Rock_Stone_Cobble_Mossy"
    },
    {
      "x": -42,
      "y": 44,
      "z": -6,
      "name": "Soil_Gravel_Mossy"
    },
    {
      "x": -42,
      "y": 45,
      "z": -6,
      "name": "Rock_Stone_Mossy"
    },
    {
      "x": -42,
      "y": 46,
      "z": -6,
      "name": "Rock_Stone"
    },
    {
      "x": -42,
      "y": 47,
      "z": -6,
      "name": "Rock_Stone"
    },
    {
      "x": -42,
      "y": 48,
      "z": -6,
      "name": "Rock_Stone_Cobble_Mossy"
    },
    {
      "x": -42,
      "y": 49,
      "z": -6,
      "name": "Rock_Stone"
    },
    {
      "x": -42,
      "y": 41,
      "z": -5,
      "name": "Soil_Gravel_Mossy"
    },
    {
      "x": -42,
      "y": 42,
      "z": -5,
      "name": "Rock_Stone_Cobble_Mossy"
    },
    {
      "x": -42,
      "y": 43,
      "z": -5,
      "name": "Rock_Stone"
    },
    {
      "x": -42,
      "y": 44,
      "z": -5,
      "name": "Rock_Stone"
    },
    {
      "x": -42,
      "y": 45,
      "z": -5,
      "name": "Soil_Gravel_Mossy"
    },
    {
      "x": -42,
      "y": 46,
      "z": -5,
      "name": "Soil_Gravel_Mossy"
    },
    {
      "x": -42,
      "y": 47,
      "z": -5,
      "name": "Rock_Stone_Mossy"
    },
    {
      "x": -42,
      "y": 48,
      "z": -5,
      "name": "Soil_Dirt"
    },
    {
      "x": -42,
      "y": 49,
      "z": -5,
      "name": "Rock_Stone_Mossy"
    },
    {
      "x": -42,
      "y": 40,
      "z": -4,
      "name": "Rock_Stone"
    },
    {
      "x": -42,
      "y": 41,
      "z": -4,
      "name": "Rock_Stone_Cobble_Mossy"
    },
    {
      "x": -42,
      "y": 42,
      "z": -4,
      "name": "Rock_Stone_Cobble_Mossy"
    },
    {
      "x": -42,
      "y": 43,
      "z": -4,
      "name": "Soil_Gravel_Mossy"
    },
    {
      "x": -42,
      "y": 44,
      "z": -4,
      "name": "Soil_Gravel_Mossy"
    },
    {
      "x": -42,
      "y": 45,
      "z": -4,
      "name": "Soil_Dirt"
    },
    {
      "x": -42,
      "y": 46,
      "z": -4,
      "name": "Rock_Stone"
    },
    {
      "x": -42,
      "y": 47,
      "z": -4,
      "name": "Soil_Gravel_Mossy"
    },
    {
      "x": -42,
      "y": 48,
      "z": -4,
      "name": "Rock_Stone_Cobble_Mossy"
    },
    {
      "x": -42,
      "y": 49,
      "z": -4,
      "name": "Soil_Dirt"
    },
    {
      "x": -42,
      "y": 50,
      "z": -4,
      "name": "Soil_Dirt"
    },
    {
      "x": -42,
      "y": 41,
      "z": -3,
      "name": "Rock_Stone"
    },
    {
      "x": -42,
      "y": 42,
      "z": -3,
      "name": "Soil_Gravel_Mossy"
    },
    {
      "x": -42,
      "y": 43,
      "z": -3,
      "name": "Soil_Gravel_Mossy"
    },
    {
      "x": -42,
      "y": 44,
      "z": -3,
      "name": "Soil_Gravel_Mossy"
    },
    {
      "x": -42,
      "y": 45,
      "z": -3,
      "name": "Rock_Stone"
    },
    {
      "x": -42,
      "y": 46,
      "z": -3,
      "name": "Soil_Gravel_Mossy"
    },
    {
      "x": -42,
      "y": 47,
      "z": -3,
      "name": "Soil_Dirt"
    },
    {
      "x": -42,
      "y": 48,
      "z": -3,
      "name": "Plant_Moss_Block_Green"
    },
    {
      "x": -42,
      "y": 49,
      "z": -3,
      "name": "Soil_Gravel_Mossy"
    },
    {
      "x": -42,
      "y": 50,
      "z": -3,
      "name": "Rock_Stone"
    },
    {
      "x": -42,
      "y": 40,
      "z": -2,
      "name": "Rock_Stone"
    },
    {
      "x": -42,
      "y": 41,
      "z": -2,
      "name": "Rock_Stone_Cobble_Mossy"
    },
    {
      "x": -42,
      "y": 42,
      "z": -2,
      "name": "Rock_Stone_Cobble_Mossy"
    },
    {
      "x": -42,
      "y": 43,
      "z": -2,
      "name": "Soil_Gravel_Mossy"
    },
    {
      "x": -42,
      "y": 44,
      "z": -2,
      "name": "Rock_Stone_Mossy"
    },
    {
      "x": -42,
      "y": 45,
      "z": -2,
      "name": "Plant_Moss_Block_Green"
    },
    {
      "x": -42,
      "y": 46,
      "z": -2,
      "name": "Rock_Stone_Mossy"
    },
    {
      "x": -42,
      "y": 47,
      "z": -2,
      "name": "Rock_Stone_Mossy"
    },
    {
      "x": -42,
      "y": 48,
      "z": -2,
      "name": "Rock_Stone_Cobble_Mossy"
    },
    {
      "x": -42,
      "y": 49,
      "z": -2,
      "name": "Rock_Stone_Mossy"
    },
    {
      "x": -42,
      "y": 50,
      "z": -2,
      "name": "Plant_Moss_Block_Green"
    },
    {
      "x": -42,
      "y": 41,
      "z": -1,
      "name": "Rock_Stone"
    },
    {
      "x": -42,
      "y": 42,
      "z": -1,
      "name": "Plant_Moss_Block_Green"
    },
    {
      "x": -42,
      "y": 43,
      "z": -1,
      "name": "Soil_Gravel_Mossy"
    },
    {
      "x": -42,
      "y": 44,
      "z": -1,
      "name": "Rock_Stone_Mossy"
    },
    {
      "x": -42,
      "y": 45,
      "z": -1,
      "name": "Rock_Stone"
    },
    {
      "x": -42,
      "y": 46,
      "z": -1,
      "name": "Rock_Stone"
    },
    {
      "x": -42,
      "y": 47,
      "z": -1,
      "name": "Rock_Stone_Mossy"
    },
    {
      "x": -42,
      "y": 48,
      "z": -1,
      "name": "Rock_Stone"
    },
    {
      "x": -42,
      "y": 49,
      "z": -1,
      "name": "Rock_Stone"
    },
    {
      "x": -42,
      "y": 50,
      "z": -1,
      "name": "Soil_Dirt"
    },
    {
      "x": -42,
      "y": 41,
      "z": 0,
      "name": "Soil_Gravel_Mossy"
    },
    {
      "x": -42,
      "y": 42,
      "z": 0,
      "name": "Soil_Dirt"
    },
    {
      "x": -42,
      "y": 43,
      "z": 0,
      "name": "Plant_Moss_Block_Green"
    },
    {
      "x": -42,
      "y": 44,
      "z": 0,
      "name": "Soil_Dirt"
    },
    {
      "x": -42,
      "y": 45,
      "z": 0,
      "name": "Rock_Stone_Mossy"
    },
    {
      "x": -42,
      "y": 46,
      "z": 0,
      "name": "Rock_Stone_Mossy"
    },
    {
      "x": -42,
      "y": 47,
      "z": 0,
      "name": "Soil_Gravel_Mossy"
    },
    {
      "x": -42,
      "y": 48,
      "z": 0,
      "name": "Soil_Dirt"
    },
    {
      "x": -42,
      "y": 49,
      "z": 0,
      "name": "Rock_Stone_Cobble_Mossy"
    },
    {
      "x": -42,
      "y": 42,
      "z": 1,
      "name": "Soil_Dirt"
    },
    {
      "x": -42,
      "y": 43,
      "z": 1,
      "name": "Rock_Stone_Cobble_Mossy"
    },
    {
      "x": -42,
      "y": 44,
      "z": 1,
      "name": "Plant_Moss_Block_Green"
    },
    {
      "x": -42,
      "y": 45,
      "z": 1,
      "name": "Rock_Stone"
    },
    {
      "x": -42,
      "y": 46,
      "z": 1,
      "name": "Soil_Gravel_Mossy"
    },
    {
      "x": -42,
      "y": 47,
      "z": 1,
      "name": "Soil_Gravel_Mossy"
    },
    {
      "x": -42,
      "y": 48,
      "z": 1,
      "name": "Plant_Moss_Block_Green"
    },
    {
      "x": -42,
      "y": 44,
      "z": 2,
      "name": "Rock_Stone"
    },
    {
      "x": -42,
      "y": 45,
      "z": 2,
      "name": "Rock_Stone_Mossy"
    },
    {
      "x": -42,
      "y": 46,
      "z": 2,
      "name": "Rock_Stone_Cobble_Mossy"
    },
    {
      "x": -42,
      "y": 47,
      "z": 2,
      "name": "Soil_Dirt"
    },
    {
      "x": -42,
      "y": 45,
      "z": 3,
      "name": "Plant_Moss_Block_Green"
    },
    {
      "x": -41,
      "y": 43,
      "z": -8,
      "name": "Rock_Stone_Cobble_Mossy"
    },
    {
      "x": -41,
      "y": 44,
      "z": -8,
      "name": "Plant_Moss_Block_Green"
    },
    {
      "x": -41,
      "y": 45,
      "z": -8,
      "name": "Plant_Moss_Block_Green"
    },
    {
      "x": -41,
      "y": 46,
      "z": -8,
      "name": "Rock_Stone"
    },
    {
      "x": -41,
      "y": 47,
      "z": -8,
      "name": "Soil_Dirt"
    },
    {
      "x": -41,
      "y": 42,
      "z": -7,
      "name": "Plant_Moss_Block_Green"
    },
    {
      "x": -41,
      "y": 43,
      "z": -7,
      "name": "Plant_Moss_Block_Green"
    },
    {
      "x": -41,
      "y": 44,
      "z": -7,
      "name": "Plant_Moss_Block_Green"
    },
    {
      "x": -41,
      "y": 45,
      "z": -7,
      "name": "Plant_Moss_Block_Green"
    },
    {
      "x": -41,
      "y": 46,
      "z": -7,
      "name": "Plant_Moss_Block_Green"
    },
    {
      "x": -41,
      "y": 47,
      "z": -7,
      "name": "Soil_Gravel_Mossy"
    },
    {
      "x": -41,
      "y": 48,
      "z": -7,
      "name": "Rock_Stone_Cobble_Mossy"
    },
    {
      "x": -41,
      "y": 49,
      "z": -7,
      "name": "Rock_Stone_Cobble_Mossy"
    },
    {
      "x": -41,
      "y": 41,
      "z": -6,
      "name": "Rock_Stone_Cobble_Mossy"
    },
    {
      "x": -41,
      "y": 42,
      "z": -6,
      "name": "Soil_Dirt"
    },
    {
      "x": -41,
      "y": 43,
      "z": -6,
      "name": "Rock_Stone"
    },
    {
      "x": -41,
      "y": 44,
      "z": -6,
      "name": "Soil_Gravel_Mossy"
    },
    {
      "x": -41,
      "y": 45,
      "z": -6,
      "name": "Rock_Stone"
    },
    {
      "x": -41,
      "y": 46,
      "z": -6,
      "name": "Rock_Stone_Cobble_Mossy"
    },
    {
      "x": -41,
      "y": 47,
      "z": -6,
      "name": "Soil_Gravel_Mossy"
    },
    {
      "x": -41,
      "y": 48,
      "z": -6,
      "name": "Rock_Stone_Cobble_Mossy"
    },
    {
      "x": -41,
      "y": 49,
      "z": -6,
      "name": "Plant_Moss_Block_Green"
    },
    {
      "x": -41,
      "y": 41,
      "z": -5,
      "name": "Soil_Dirt"
    },
    {
      "x": -41,
      "y": 42,
      "z": -5,
      "name": "Rock_Stone_Cobble_Mossy"
    },
    {
      "x": -41,
      "y": 43,
      "z": -5,
      "name": "Soil_Dirt"
    },
    {
      "x": -41,
      "y": 44,
      "z": -5,
      "name": "Rock_Stone_Mossy"
    },
    {
      "x": -41,
      "y": 45,
      "z": -5,
      "name": "Rock_Stone"
    },
    {
      "x": -41,
      "y": 46,
      "z": -5,
      "name": "Rock_Stone_Mossy"
    },
    {
      "x": -41,
      "y": 47,
      "z": -5,
      "name": "Plant_Moss_Block_Green"
    },
    {
      "x": -41,
      "y": 48,
      "z": -5,
      "name": "Rock_Stone_Mossy"
    },
    {
      "x": -41,
      "y": 49,
      "z": -5,
      "name": "Soil_Dirt"
    },
    {
      "x": -41,
      "y": 40,
      "z": -4,
      "name": "Rock_Stone_Mossy"
    },
    {
      "x": -41,
      "y": 41,
      "z": -4,
      "name": "Rock_Stone_Cobble_Mossy"
    },
    {
      "x": -41,
      "y": 42,
      "z": -4,
      "name": "Rock_Stone_Cobble_Mossy"
    },
    {
      "x": -41,
      "y": 43,
      "z": -4,
      "name": "Soil_Gravel_Mossy"
    },
    {
      "x": -41,
      "y": 44,
      "z": -4,
      "name": "Soil_Gravel_Mossy"
    },
    {
      "x": -41,
      "y": 45,
      "z": -4,
      "name": "Soil_Dirt"
    },
    {
      "x": -41,
      "y": 46,
      "z": -4,
      "name": "Soil_Gravel_Mossy"
    },
    {
      "x": -41,
      "y": 47,
      "z": -4,
      "name": "Rock_Stone"
    },
    {
      "x": -41,
      "y": 48,
      "z": -4,
      "name": "Rock_Stone_Mossy"
    },
    {
      "x": -41,
      "y": 49,
      "z": -4,
      "name": "Soil_Dirt"
    },
    {
      "x": -41,
      "y": 50,
      "z": -4,
      "name": "Soil_Gravel_Mossy"
    },
    {
      "x": -41,
      "y": 40,
      "z": -3,
      "name": "Soil_Dirt"
    },
    {
      "x": -41,
      "y": 41,
      "z": -3,
      "name": "Plant_Moss_Block_Green"
    },
    {
      "x": -41,
      "y": 42,
      "z": -3,
      "name": "Rock_Stone_Mossy"
    },
    {
      "x": -41,
      "y": 43,
      "z": -3,
      "name": "Plant_Moss_Block_Green"
    },
    {
      "x": -41,
      "y": 44,
      "z": -3,
      "name": "Rock_Stone_Cobble_Mossy"
    },
    {
      "x": -41,
      "y": 45,
      "z": -3,
      "name": "Soil_Dirt"
    },
    {
      "x": -41,
      "y": 46,
      "z": -3,
      "name": "Rock_Stone_Mossy"
    },
    {
      "x": -41,
      "y": 47,
      "z": -3,
      "name": "Rock_Stone_Mossy"
    },
    {
      "x": -41,
      "y": 48,
      "z": -3,
      "name": "Plant_Moss_Block_Green"
    },
    {
      "x": -41,
      "y": 49,
      "z": -3,
      "name": "Plant_Moss_Block_Green"
    },
    {
      "x": -41,
      "y": 50,
      "z": -3,
      "name": "Plant_Moss_Block_Green"
    },
    {
      "x": -41,
      "y": 40,
      "z": -2,
      "name": "Soil_Dirt"
    },
    {
      "x": -41,
      "y": 41,
      "z": -2,
      "name": "Plant_Moss_Block_Green"
    },
    {
      "x": -41,
      "y": 42,
      "z": -2,
      "name": "Soil_Dirt"
    },
    {
      "x": -41,
      "y": 43,
      "z": -2,
      "name": "Rock_Stone"
    },
    {
      "x": -41,
      "y": 44,
      "z": -2,
      "name": "Soil_Gravel_Mossy"
    },
    {
      "x": -41,
      "y": 45,
      "z": -2,
      "name": "Soil_Gravel_Mossy"
    },
    {
      "x": -41,
      "y": 46,
      "z": -2,
      "name": "Rock_Stone"
    },
    {
      "x": -41,
      "y": 47,
      "z": -2,
      "name": "Rock_Stone_Mossy"
    },
    {
      "x": -41,
      "y": 48,
      "z": -2,
      "name": "Rock_Stone_Cobble_Mossy"
    },
    {
      "x": -41,
      "y": 49,
      "z": -2,
      "name": "Rock_Stone_Cobble_Mossy"
    },
    {
      "x": -41,
      "y": 50,
      "z": -2,
      "name": "Rock_Stone_Mossy"
    },
    {
      "x": -41,
      "y": 51,
      "z": -2,
      "name": "Rock_Stone_Mossy"
    },
    {
      "x": -41,
      "y": 41,
      "z": -1,
      "name": "Soil_Dirt"
    },
    {
      "x": -41,
      "y": 42,
      "z": -1,
      "name": "Rock_Stone_Mossy"
    },
    {
      "x": -41,
      "y": 43,
      "z": -1,
      "name": "Rock_Stone_Mossy"
    },
    {
      "x": -41,
      "y": 44,
      "z": -1,
      "name": "Soil_Gravel_Mossy"
    },
    {
      "x": -41,
      "y": 45,
      "z": -1,
      "name": "Soil_Dirt"
    },
    {
      "x": -41,
      "y": 46,
      "z": -1,
      "name": "Rock_Stone_Mossy"
    },
    {
      "x": -41,
      "y": 47,
      "z": -1,
      "name": "Plant_Moss_Block_Green"
    },
    {
      "x": -41,
      "y": 48,
      "z": -1,
      "name": "Plant_Moss_Block_Green"
    },
    {
      "x": -41,
      "y": 49,
      "z": -1,
      "name": "Rock_Stone"
    },
    {
      "x": -41,
      "y": 40,
      "z": 0,
      "name": "Plant_Moss_Block_Green"
    },
    {
      "x": -41,
      "y": 41,
      "z": 0,
      "name": "Soil_Gravel_Mossy"
    },
    {
      "x": -41,
      "y": 42,
      "z": 0,
      "name": "Rock_Stone_Cobble_Mossy"
    },
    {
      "x": -41,
      "y": 43,
      "z": 0,
      "name": "Soil_Dirt"
    },
    {
      "x": -41,
      "y": 44,
      "z": 0,
      "name": "Soil_Dirt"
    },
    {
      "x": -41,
      "y": 45,
      "z": 0,
      "name": "Rock_Stone_Mossy"
    },
    {
      "x": -41,
      "y": 46,
      "z": 0,
      "name": "Rock_Stone_Mossy"
    },
    {
      "x": -41,
      "y": 47,
      "z": 0,
      "name": "Soil_Dirt"
    },
    {
      "x": -41,
      "y": 48,
      "z": 0,
      "name": "Rock_Stone_Mossy"
    },
    {
      "x": -41,
      "y": 49,
      "z": 0,
      "name": "Plant_Moss_Block_Green"
    },
    {
      "x": -41,
      "y": 50,
      "z": 0,
      "name": "Rock_Crystal_Green_Large"
    },
    {
      "x": -41,
      "y": 42,
      "z": 1,
      "name": "Rock_Stone"
    },
    {
      "x": -41,
      "y": 43,
      "z": 1,
      "name": "Soil_Gravel_Mossy"
    },
    {
      "x": -41,
      "y": 44,
      "z": 1,
      "name": "Soil_Dirt"
    },
    {
      "x": -41,
      "y": 45,
      "z": 1,
      "name": "Plant_Moss_Block_Green"
    },
    {
      "x": -41,
      "y": 46,
      "z": 1,
      "name": "Soil_Dirt"
    },
    {
      "x": -41,
      "y": 47,
      "z": 1,
      "name": "Rock_Stone_Mossy"
    },
    {
      "x": -41,
      "y": 48,
      "z": 1,
      "name": "Rock_Stone_Mossy"
    },
    {
      "x": -41,
      "y": 44,
      "z": 2,
      "name": "Rock_Stone_Cobble_Mossy"
    },
    {
      "x": -41,
      "y": 45,
      "z": 2,
      "name": "Rock_Stone_Mossy"
    },
    {
      "x": -41,
      "y": 46,
      "z": 2,
      "name": "Plant_Moss_Block_Green"
    },
    {
      "x": -41,
      "y": 46,
      "z": 3,
      "name": "Rock_Stone"
    },
    {
      "x": -40,
      "y": 43,
      "z": -8,
      "name": "Rock_Stone_Cobble_Mossy"
    },
    {
      "x": -40,
      "y": 44,
      "z": -8,
      "name": "Rock_Stone_Mossy"
    },
    {
      "x": -40,
      "y": 45,
      "z": -8,
      "name": "Soil_Dirt"
    },
    {
      "x": -40,
      "y": 46,
      "z": -8,
      "name": "Plant_Moss_Block_Green"
    },
    {
      "x": -40,
      "y": 47,
      "z": -8,
      "name": "Rock_Stone_Cobble_Mossy"
    },
    {
      "x": -40,
      "y": 42,
      "z": -7,
      "name": "Rock_Stone_Mossy"
    },
    {
      "x": -40,
      "y": 43,
      "z": -7,
      "name": "Rock_Stone_Mossy"
    },
    {
      "x": -40,
      "y": 44,
      "z": -7,
      "name": "Soil_Dirt"
    },
    {
      "x": -40,
      "y": 45,
      "z": -7,
      "name": "Rock_Stone"
    },
    {
      "x": -40,
      "y": 46,
      "z": -7,
      "name": "Rock_Stone_Cobble_Mossy"
    },
    {
      "x": -40,
      "y": 47,
      "z": -7,
      "name": "Rock_Stone_Mossy"
    },
    {
      "x": -40,
      "y": 48,
      "z": -7,
      "name": "Rock_Stone_Mossy"
    },
    {
      "x": -40,
      "y": 41,
      "z": -6,
      "name": "Rock_Stone_Mossy"
    },
    {
      "x": -40,
      "y": 42,
      "z": -6,
      "name": "Rock_Stone_Cobble_Mossy"
    },
    {
      "x": -40,
      "y": 43,
      "z": -6,
      "name": "Rock_Stone"
    },
    {
      "x": -40,
      "y": 44,
      "z": -6,
      "name": "Soil_Dirt"
    },
    {
      "x": -40,
      "y": 45,
      "z": -6,
      "name": "Rock_Stone"
    },
    {
      "x": -40,
      "y": 46,
      "z": -6,
      "name": "Soil_Dirt"
    },
    {
      "x": -40,
      "y": 47,
      "z": -6,
      "name": "Rock_Stone_Mossy"
    },
    {
      "x": -40,
      "y": 48,
      "z": -6,
      "name": "Plant_Moss_Block_Green"
    },
    {
      "x": -40,
      "y": 49,
      "z": -6,
      "name": "Rock_Stone"
    },
    {
      "x": -40,
      "y": 41,
      "z": -5,
      "name": "Rock_Stone_Mossy"
    },
    {
      "x": -40,
      "y": 42,
      "z": -5,
      "name": "Rock_Stone"
    },
    {
      "x": -40,
      "y": 43,
      "z": -5,
      "name": "Plant_Moss_Block_Green"
    },
    {
      "x": -40,
      "y": 44,
      "z": -5,
      "name": "Soil_Dirt"
    },
    {
      "x": -40,
      "y": 45,
      "z": -5,
      "name": "Rock_Stone_Cobble_Mossy"
    },
    {
      "x": -40,
      "y": 46,
      "z": -5,
      "name": "Rock_Stone"
    },
    {
      "x": -40,
      "y": 47,
      "z": -5,
      "name": "Soil_Gravel_Mossy"
    },
    {
      "x": -40,
      "y": 48,
      "z": -5,
      "name": "Soil_Dirt"
    },
    {
      "x": -40,
      "y": 49,
      "z": -5,
      "name": "Rock_Stone"
    },
    {
      "x": -40,
      "y": 40,
      "z": -4,
      "name": "Rock_Stone_Mossy"
    },
    {
      "x": -40,
      "y": 41,
      "z": -4,
      "name": "Plant_Moss_Block_Green"
    },
    {
      "x": -40,
      "y": 42,
      "z": -4,
      "name": "Soil_Gravel_Mossy"
    },
    {
      "x": -40,
      "y": 43,
      "z": -4,
      "name": "Plant_Moss_Block_Green"
    },
    {
      "x": -40,
      "y": 44,
      "z": -4,
      "name": "Soil_Gravel_Mossy"
    },
    {
      "x": -40,
      "y": 45,
      "z": -4,
      "name": "Plant_Moss_Block_Green"
    },
    {
      "x": -40,
      "y": 46,
      "z": -4,
      "name": "Soil_Dirt"
    },
    {
      "x": -40,
      "y": 47,
      "z": -4,
      "name": "Soil_Dirt"
    },
    {
      "x": -40,
      "y": 48,
      "z": -4,
      "name": "Rock_Stone"
    },
    {
      "x": -40,
      "y": 49,
      "z": -4,
      "name": "Rock_Stone_Cobble_Mossy"
    },
    {
      "x": -40,
      "y": 50,
      "z": -4,
      "name": "Rock_Stone_Cobble_Mossy"
    },
    {
      "x": -40,
      "y": 40,
      "z": -3,
      "name": "Plant_Moss_Block_Green"
    },
    {
      "x": -40,
      "y": 41,
      "z": -3,
      "name": "Soil_Gravel_Mossy"
    },
    {
      "x": -40,
      "y": 42,
      "z": -3,
      "name": "Rock_Stone"
    },
    {
      "x": -40,
      "y": 43,
      "z": -3,
      "name": "Soil_Gravel_Mossy"
    },
    {
      "x": -40,
      "y": 44,
      "z": -3,
      "name": "Soil_Dirt"
    },
    {
      "x": -40,
      "y": 45,
      "z": -3,
      "name": "Plant_Moss_Block_Green"
    },
    {
      "x": -40,
      "y": 46,
      "z": -3,
      "name": "Soil_Gravel_Mossy"
    },
    {
      "x": -40,
      "y": 47,
      "z": -3,
      "name": "Plant_Moss_Block_Green"
    },
    {
      "x": -40,
      "y": 48,
      "z": -3,
      "name": "Soil_Dirt"
    },
    {
      "x": -40,
      "y": 49,
      "z": -3,
      "name": "Rock_Stone_Cobble_Mossy"
    },
    {
      "x": -40,
      "y": 50,
      "z": -3,
      "name": "Rock_Stone"
    },
    {
      "x": -40,
      "y": 40,
      "z": -2,
      "name": "Rock_Stone_Cobble_Mossy"
    },
    {
      "x": -40,
      "y": 41,
      "z": -2,
      "name": "Soil_Dirt"
    },
    {
      "x": -40,
      "y": 42,
      "z": -2,
      "name": "Rock_Stone"
    },
    {
      "x": -40,
      "y": 43,
      "z": -2,
      "name": "Rock_Stone"
    },
    {
      "x": -40,
      "y": 44,
      "z": -2,
      "name": "Rock_Stone"
    },
    {
      "x": -40,
      "y": 45,
      "z": -2,
      "name": "Rock_Stone"
    },
    {
      "x": -40,
      "y": 46,
      "z": -2,
      "name": "Rock_Stone"
    },
    {
      "x": -40,
      "y": 47,
      "z": -2,
      "name": "Soil_Dirt"
    },
    {
      "x": -40,
      "y": 48,
      "z": -2,
      "name": "Rock_Stone"
    },
    {
      "x": -40,
      "y": 49,
      "z": -2,
      "name": "Rock_Stone_Cobble_Mossy"
    },
    {
      "x": -40,
      "y": 50,
      "z": -2,
      "name": "Soil_Gravel_Mossy"
    },
    {
      "x": -40,
      "y": 41,
      "z": -1,
      "name": "Rock_Stone_Cobble_Mossy"
    },
    {
      "x": -40,
      "y": 42,
      "z": -1,
      "name": "Plant_Moss_Block_Green"
    },
    {
      "x": -40,
      "y": 43,
      "z": -1,
      "name": "Rock_Stone_Cobble_Mossy"
    },
    {
      "x": -40,
      "y": 44,
      "z": -1,
      "name": "Soil_Gravel_Mossy"
    },
    {
      "x": -40,
      "y": 45,
      "z": -1,
      "name": "Rock_Stone_Cobble_Mossy"
    },
    {
      "x": -40,
      "y": 46,
      "z": -1,
      "name": "Soil_Gravel_Mossy"
    },
    {
      "x": -40,
      "y": 47,
      "z": -1,
      "name": "Soil_Dirt"
    },
    {
      "x": -40,
      "y": 48,
      "z": -1,
      "name": "Plant_Moss_Block_Green"
    },
    {
      "x": -40,
      "y": 49,
      "z": -1,
      "name": "Rock_Stone"
    },
    {
      "x": -40,
      "y": 41,
      "z": 0,
      "name": "Rock_Stone"
    },
    {
      "x": -40,
      "y": 42,
      "z": 0,
      "name": "Rock_Stone_Cobble_Mossy"
    },
    {
      "x": -40,
      "y": 43,
      "z": 0,
      "name": "Rock_Stone_Mossy"
    },
    {
      "x": -40,
      "y": 44,
      "z": 0,
      "name": "Plant_Moss_Block_Green"
    },
    {
      "x": -40,
      "y": 45,
      "z": 0,
      "name": "Soil_Dirt"
    },
    {
      "x": -40,
      "y": 46,
      "z": 0,
      "name": "Plant_Moss_Block_Green"
    },
    {
      "x": -40,
      "y": 47,
      "z": 0,
      "name": "Rock_Stone_Mossy"
    },
    {
      "x": -40,
      "y": 48,
      "z": 0,
      "name": "Rock_Stone_Mossy"
    },
    {
      "x": -40,
      "y": 49,
      "z": 0,
      "name": "Soil_Gravel_Mossy"
    },
    {
      "x": -40,
      "y": 42,
      "z": 1,
      "name": "Rock_Stone_Mossy"
    },
    {
      "x": -40,
      "y": 43,
      "z": 1,
      "name": "Rock_Stone"
    },
    {
      "x": -40,
      "y": 44,
      "z": 1,
      "name": "Soil_Gravel_Mossy"
    },
    {
      "x": -40,
      "y": 45,
      "z": 1,
      "name": "Soil_Dirt"
    },
    {
      "x": -40,
      "y": 46,
      "z": 1,
      "name": "Rock_Stone_Mossy"
    },
    {
      "x": -40,
      "y": 47,
      "z": 1,
      "name": "Soil_Dirt"
    },
    {
      "x": -40,
      "y": 48,
      "z": 1,
      "name": "Soil_Gravel_Mossy"
    },
    {
      "x": -40,
      "y": 42,
      "z": 2,
      "name": "Rock_Stone_Cobble_Mossy"
    },
    {
      "x": -40,
      "y": 43,
      "z": 2,
      "name": "Soil_Gravel_Mossy"
    },
    {
      "x": -40,
      "y": 44,
      "z": 2,
      "name": "Rock_Stone"
    },
    {
      "x": -40,
      "y": 45,
      "z": 2,
      "name": "Rock_Stone"
    },
    {
      "x": -40,
      "y": 46,
      "z": 2,
      "name": "Rock_Stone_Cobble_Mossy"
    },
    {
      "x": -40,
      "y": 48,
      "z": 2,
      "name": "Rock_Stone_Cobble_Mossy"
    },
    {
      "x": -39,
      "y": 44,
      "z": -8,
      "name": "Rock_Stone"
    },
    {
      "x": -39,
      "y": 45,
      "z": -8,
      "name": "Soil_Dirt"
    },
    {
      "x": -39,
      "y": 46,
      "z": -8,
      "name": "Soil_Gravel_Mossy"
    },
    {
      "x": -39,
      "y": 43,
      "z": -7,
      "name": "Rock_Stone"
    },
    {
      "x": -39,
      "y": 44,
      "z": -7,
      "name": "Soil_Gravel_Mossy"
    },
    {
      "x": -39,
      "y": 45,
      "z": -7,
      "name": "Rock_Stone_Cobble_Mossy"
    },
    {
      "x": -39,
      "y": 46,
      "z": -7,
      "name": "Rock_Stone"
    },
    {
      "x": -39,
      "y": 47,
      "z": -7,
      "name": "Soil_Gravel_Mossy"
    },
    {
      "x": -39,
      "y": 48,
      "z": -7,
      "name": "Rock_Stone"
    },
    {
      "x": -39,
      "y": 42,
      "z": -6,
      "name": "Soil_Gravel_Mossy"
    },
    {
      "x": -39,
      "y": 43,
      "z": -6,
      "name": "Plant_Moss_Block_Green"
    },
    {
      "x": -39,
      "y": 44,
      "z": -6,
      "name": "Rock_Stone"
    },
    {
      "x": -39,
      "y": 45,
      "z": -6,
      "name": "Soil_Dirt"
    },
    {
      "x": -39,
      "y": 46,
      "z": -6,
      "name": "Soil_Dirt"
    },
    {
      "x": -39,
      "y": 47,
      "z": -6,
      "name": "Rock_Stone"
    },
    {
      "x": -39,
      "y": 48,
      "z": -6,
      "name": "Rock_Stone_Mossy"
    },
    {
      "x": -39,
      "y": 41,
      "z": -5,
      "name": "Plant_Moss_Block_Green"
    },
    {
      "x": -39,
      "y": 42,
      "z": -5,
      "name": "Rock_Stone_Cobble_Mossy"
    },
    {
      "x": -39,
      "y": 43,
      "z": -5,
      "name": "Rock_Stone_Cobble_Mossy"
    },
    {
      "x": -39,
      "y": 44,
      "z": -5,
      "name": "Rock_Stone"
    },
    {
      "x": -39,
      "y": 45,
      "z": -5,
      "name": "Plant_Moss_Block_Green"
    },
    {
      "x": -39,
      "y": 46,
      "z": -5,
      "name": "Rock_Stone_Mossy"
    },
    {
      "x": -39,
      "y": 47,
      "z": -5,
      "name": "Plant_Moss_Block_Green"
    },
    {
      "x": -39,
      "y": 48,
      "z": -5,
      "name": "Rock_Stone"
    },
    {
      "x": -39,
      "y": 49,
      "z": -5,
      "name": "Plant_Moss_Block_Green"
    },
    {
      "x": -39,
      "y": 50,
      "z": -5,
      "name": "Rock_Stone"
    },
    {
      "x": -39,
      "y": 41,
      "z": -4,
      "name": "Plant_Moss_Block_Green"
    },
    {
      "x": -39,
      "y": 42,
      "z": -4,
      "name": "Rock_Stone_Mossy"
    },
    {
      "x": -39,
      "y": 43,
      "z": -4,
      "name": "Soil_Dirt"
    },
    {
      "x": -39,
      "y": 44,
      "z": -4,
      "name": "Plant_Moss_Block_Green"
    },
    {
      "x": -39,
      "y": 45,
      "z": -4,
      "name": "Rock_Stone_Cobble_Mossy"
    },
    {
      "x": -39,
      "y": 46,
      "z": -4,
      "name": "Plant_Moss_Block_Green"
    },
    {
      "x": -39,
      "y": 47,
      "z": -4,
      "name": "Rock_Stone_Cobble_Mossy"
    },
    {
      "x": -39,
      "y": 48,
      "z": -4,
      "name": "Rock_Stone_Cobble_Mossy"
    },
    {
      "x": -39,
      "y": 49,
      "z": -4,
      "name": "Soil_Dirt"
    },
    {
      "x": -39,
      "y": 41,
      "z": -3,
      "name": "Soil_Gravel_Mossy"
    },
    {
      "x": -39,
      "y": 42,
      "z": -3,
      "name": "Rock_Stone_Cobble_Mossy"
    },
    {
      "x": -39,
      "y": 43,
      "z": -3,
      "name": "Soil_Dirt"
    },
    {
      "x": -39,
      "y": 44,
      "z": -3,
      "name": "Rock_Stone_Cobble_Mossy"
    },
    {
      "x": -39,
      "y": 45,
      "z": -3,
      "name": "Plant_Moss_Block_Green"
    },
    {
      "x": -39,
      "y": 46,
      "z": -3,
      "name": "Rock_Stone_Mossy"
    },
    {
      "x": -39,
      "y": 47,
      "z": -3,
      "name": "Soil_Gravel_Mossy"
    },
    {
      "x": -39,
      "y": 48,
      "z": -3,
      "name": "Soil_Dirt"
    },
    {
      "x": -39,
      "y": 49,
      "z": -3,
      "name": "Rock_Stone"
    },
    {
      "x": -39,
      "y": 41,
      "z": -2,
      "name": "Rock_Stone_Mossy"
    },
    {
      "x": -39,
      "y": 42,
      "z": -2,
      "name": "Soil_Dirt"
    },
    {
      "x": -39,
      "y": 43,
      "z": -2,
      "name": "Rock_Stone"
    },
    {
      "x": -39,
      "y": 44,
      "z": -2,
      "name": "Rock_Stone"
    },
    {
      "x": -39,
      "y": 45,
      "z": -2,
      "name": "Rock_Stone_Cobble_Mossy"
    },
    {
      "x": -39,
      "y": 46,
      "z": -2,
      "name": "Rock_Stone_Cobble_Mossy"
    },
    {
      "x": -39,
      "y": 47,
      "z": -2,
      "name": "Soil_Dirt"
    },
    {
      "x": -39,
      "y": 48,
      "z": -2,
      "name": "Soil_Dirt"
    },
    {
      "x": -39,
      "y": 49,
      "z": -2,
      "name": "Soil_Dirt"
    },
    {
      "x": -39,
      "y": 41,
      "z": -1,
      "name": "Rock_Stone"
    },
    {
      "x": -39,
      "y": 42,
      "z": -1,
      "name": "Soil_Dirt"
    },
    {
      "x": -39,
      "y": 43,
      "z": -1,
      "name": "Soil_Gravel_Mossy"
    },
    {
      "x": -39,
      "y": 44,
      "z": -1,
      "name": "Rock_Stone"
    },
    {
      "x": -39,
      "y": 45,
      "z": -1,
      "name": "Plant_Moss_Block_Green"
    },
    {
      "x": -39,
      "y": 46,
      "z": -1,
      "name": "Soil_Dirt"
    },
    {
      "x": -39,
      "y": 47,
      "z": -1,
      "name": "Rock_Stone"
    },
    {
      "x": -39,
      "y": 48,
      "z": -1,
      "name": "Rock_Stone_Mossy"
    },
    {
      "x": -39,
      "y": 49,
      "z": -1,
      "name": "Rock_Stone_Mossy"
    },
    {
      "x": -39,
      "y": 42,
      "z": 0,
      "name": "Soil_Dirt"
    },
    {
      "x": -39,
      "y": 43,
      "z": 0,
      "name": "Rock_Stone_Mossy"
    },
    {
      "x": -39,
      "y": 44,
      "z": 0,
      "name": "Rock_Stone_Mossy"
    },
    {
      "x": -39,
      "y": 45,
      "z": 0,
      "name": "Plant_Moss_Block_Green"
    },
    {
      "x": -39,
      "y": 46,
      "z": 0,
      "name": "Plant_Moss_Block_Green"
    },
    {
      "x": -39,
      "y": 47,
      "z": 0,
      "name": "Soil_Gravel_Mossy"
    },
    {
      "x": -39,
      "y": 48,
      "z": 0,
      "name": "Rock_Stone"
    },
    {
      "x": -39,
      "y": 43,
      "z": 1,
      "name": "Plant_Moss_Block_Green"
    },
    {
      "x": -39,
      "y": 44,
      "z": 1,
      "name": "Rock_Stone"
    },
    {
      "x": -39,
      "y": 45,
      "z": 1,
      "name": "Soil_Gravel_Mossy"
    },
    {
      "x": -39,
      "y": 46,
      "z": 1,
      "name": "Rock_Stone_Mossy"
    },
    {
      "x": -39,
      "y": 47,
      "z": 1,
      "name": "Rock_Stone"
    },
    {
      "x": -39,
      "y": 44,
      "z": 2,
      "name": "Rock_Stone_Mossy"
    },
    {
      "x": -39,
      "y": 45,
      "z": 2,
      "name": "Soil_Dirt"
    },
    {
      "x": -38,
      "y": 44,
      "z": -7,
      "name": "Rock_Stone"
    },
    {
      "x": -38,
      "y": 45,
      "z": -7,
      "name": "Plant_Moss_Block_Green"
    },
    {
      "x": -38,
      "y": 46,
      "z": -7,
      "name": "Plant_Moss_Block_Green"
    },
    {
      "x": -38,
      "y": 47,
      "z": -7,
      "name": "Rock_Crystal_Green_Large"
    },
    {
      "x": -38,
      "y": 48,
      "z": -7,
      "name": "Soil_Dirt"
    },
    {
      "x": -38,
      "y": 42,
      "z": -6,
      "name": "Rock_Stone_Mossy"
    },
    {
      "x": -38,
      "y": 43,
      "z": -6,
      "name": "Soil_Gravel_Mossy"
    },
    {
      "x": -38,
      "y": 44,
      "z": -6,
      "name": "Plant_Moss_Block_Green"
    },
    {
      "x": -38,
      "y": 45,
      "z": -6,
      "name": "Soil_Gravel_Mossy"
    },
    {
      "x": -38,
      "y": 46,
      "z": -6,
      "name": "Soil_Gravel_Mossy"
    },
    {
      "x": -38,
      "y": 47,
      "z": -6,
      "name": "Rock_Stone_Mossy"
    },
    {
      "x": -38,
      "y": 48,
      "z": -6,
      "name": "Soil_Gravel_Mossy"
    },
    {
      "x": -38,
      "y": 42,
      "z": -5,
      "name": "Soil_Gravel_Mossy"
    },
    {
      "x": -38,
      "y": 43,
      "z": -5,
      "name": "Rock_Stone_Cobble_Mossy"
    },
    {
      "x": -38,
      "y": 44,
      "z": -5,
      "name": "Soil_Gravel_Mossy"
    },
    {
      "x": -38,
      "y": 45,
      "z": -5,
      "name": "Rock_Stone_Mossy"
    },
    {
      "x": -38,
      "y": 46,
      "z": -5,
      "name": "Soil_Dirt"
    },
    {
      "x": -38,
      "y": 47,
      "z": -5,
      "name": "Soil_Dirt"
    },
    {
      "x": -38,
      "y": 48,
      "z": -5,
      "name": "Rock_Stone_Mossy"
    },
    {
      "x": -38,
      "y": 41,
      "z": -4,
      "name": "Rock_Stone_Cobble_Mossy"
    },
    {
      "x": -38,
      "y": 42,
      "z": -4,
      "name": "Plant_Moss_Block_Green"
    },
    {
      "x": -38,
      "y": 43,
      "z": -4,
      "name": "Rock_Stone_Mossy"
    },
    {
      "x": -38,
      "y": 44,
      "z": -4,
      "name": "Rock_Stone"
    },
    {
      "x": -38,
      "y": 45,
      "z": -4,
      "name": "Plant_Moss_Block_Green"
    },
    {
      "x": -38,
      "y": 46,
      "z": -4,
      "name": "Plant_Moss_Block_Green"
    },
    {
      "x": -38,
      "y": 47,
      "z": -4,
      "name": "Rock_Stone_Cobble_Mossy"
    },
    {
      "x": -38,
      "y": 48,
      "z": -4,
      "name": "Rock_Stone_Cobble_Mossy"
    },
    {
      "x": -38,
      "y": 49,
      "z": -4,
      "name": "Plant_Moss_Block_Green"
    },
    {
      "x": -38,
      "y": 50,
      "z": -4,
      "name": "Plant_Moss_Block_Green"
    },
    {
      "x": -38,
      "y": 41,
      "z": -3,
      "name": "Rock_Stone_Cobble_Mossy"
    },
    {
      "x": -38,
      "y": 42,
      "z": -3,
      "name": "Rock_Stone"
    },
    {
      "x": -38,
      "y": 43,
      "z": -3,
      "name": "Rock_Stone_Cobble_Mossy"
    },
    {
      "x": -38,
      "y": 44,
      "z": -3,
      "name": "Rock_Stone_Mossy"
    },
    {
      "x": -38,
      "y": 45,
      "z": -3,
      "name": "Soil_Dirt"
    },
    {
      "x": -38,
      "y": 46,
      "z": -3,
      "name": "Rock_Stone_Mossy"
    },
    {
      "x": -38,
      "y": 47,
      "z": -3,
      "name": "Plant_Moss_Block_Green"
    },
    {
      "x": -38,
      "y": 48,
      "z": -3,
      "name": "Rock_Stone_Cobble_Mossy"
    },
    {
      "x": -38,
      "y": 49,
      "z": -3,
      "name": "Rock_Stone"
    },
    {
      "x": -38,
      "y": 41,
      "z": -2,
      "name": "Soil_Gravel_Mossy"
    },
    {
      "x": -38,
      "y": 42,
      "z": -2,
      "name": "Soil_Gravel_Mossy"
    },
    {
      "x": -38,
      "y": 43,
      "z": -2,
      "name": "Rock_Stone_Cobble_Mossy"
    },
    {
      "x": -38,
      "y": 44,
      "z": -2,
      "name": "Rock_Stone"
    },
    {
      "x": -38,
      "y": 45,
      "z": -2,
      "name": "Rock_Stone_Mossy"
    },
    {
      "x": -38,
      "y": 46,
      "z": -2,
      "name": "Plant_Moss_Block_Green"
    },
    {
      "x": -38,
      "y": 47,
      "z": -2,
      "name": "Rock_Stone"
    },
    {
      "x": -38,
      "y": 48,
      "z": -2,
      "name": "Rock_Stone_Mossy"
    },
    {
      "x": -38,
      "y": 49,
      "z": -2,
      "name": "Rock_Stone"
    },
    {
      "x": -38,
      "y": 42,
      "z": -1,
      "name": "Rock_Stone_Cobble_Mossy"
    },
    {
      "x": -38,
      "y": 43,
      "z": -1,
      "name": "Rock_Stone"
    },
    {
      "x": -38,
      "y": 44,
      "z": -1,
      "name": "Rock_Stone_Mossy"
    },
    {
      "x": -38,
      "y": 45,
      "z": -1,
      "name": "Rock_Stone"
    },
    {
      "x": -38,
      "y": 46,
      "z": -1,
      "name": "Rock_Stone"
    },
    {
      "x": -38,
      "y": 47,
      "z": -1,
      "name": "Rock_Stone"
    },
    {
      "x": -38,
      "y": 48,
      "z": -1,
      "name": "Rock_Stone_Cobble_Mossy"
    },
    {
      "x": -38,
      "y": 42,
      "z": 0,
      "name": "Plant_Moss_Block_Green"
    },
    {
      "x": -38,
      "y": 43,
      "z": 0,
      "name": "Rock_Stone_Mossy"
    },
    {
      "x": -38,
      "y": 44,
      "z": 0,
      "name": "Plant_Moss_Block_Green"
    },
    {
      "x": -38,
      "y": 45,
      "z": 0,
      "name": "Soil_Dirt"
    },
    {
      "x": -38,
      "y": 46,
      "z": 0,
      "name": "Rock_Stone"
    },
    {
      "x": -38,
      "y": 47,
      "z": 0,
      "name": "Plant_Moss_Block_Green"
    },
    {
      "x": -38,
      "y": 48,
      "z": 0,
      "name": "Plant_Moss_Block_Green"
    },
    {
      "x": -38,
      "y": 42,
      "z": 1,
      "name": "Rock_Crystal_Green_Large",
      "rotation": 4
    },
    {
      "x": -38,
      "y": 44,
      "z": 1,
      "name": "Rock_Stone_Mossy"
    },
    {
      "x": -38,
      "y": 45,
      "z": 1,
      "name": "Rock_Stone_Mossy"
    },
    {
      "x": -38,
      "y": 46,
      "z": 1,
      "name": "Plant_Moss_Block_Green"
    },
    {
      "x": -38,
      "y": 48,
      "z": 1,
      "name": "Plant_Moss_Block_Green"
    },
    {
      "x": -38,
      "y": 45,
      "z": 2,
      "name": "Plant_Moss_Block_Green"
    },
    {
      "x": -37,
      "y": 44,
      "z": -7,
      "name": "Rock_Stone"
    },
    {
      "x": -37,
      "y": 44,
      "z": -6,
      "name": "Rock_Stone_Mossy"
    },
    {
      "x": -37,
      "y": 45,
      "z": -6,
      "name": "Rock_Stone_Mossy"
    },
    {
      "x": -37,
      "y": 46,
      "z": -6,
      "name": "Rock_Stone_Cobble_Mossy"
    },
    {
      "x": -37,
      "y": 48,
      "z": -6,
      "name": "Rock_Stone"
    },
    {
      "x": -37,
      "y": 43,
      "z": -5,
      "name": "Rock_Stone"
    },
    {
      "x": -37,
      "y": 44,
      "z": -5,
      "name": "Rock_Stone"
    },
    {
      "x": -37,
      "y": 45,
      "z": -5,
      "name": "Rock_Stone"
    },
    {
      "x": -37,
      "y": 46,
      "z": -5,
      "name": "Rock_Stone"
    },
    {
      "x": -37,
      "y": 47,
      "z": -5,
      "name": "Soil_Dirt"
    },
    {
      "x": -37,
      "y": 48,
      "z": -5,
      "name": "Rock_Stone"
    },
    {
      "x": -37,
      "y": 42,
      "z": -4,
      "name": "Rock_Stone_Cobble_Mossy"
    },
    {
      "x": -37,
      "y": 43,
      "z": -4,
      "name": "Rock_Stone"
    },
    {
      "x": -37,
      "y": 44,
      "z": -4,
      "name": "Soil_Dirt"
    },
    {
      "x": -37,
      "y": 45,
      "z": -4,
      "name": "Plant_Moss_Block_Green"
    },
    {
      "x": -37,
      "y": 46,
      "z": -4,
      "name": "Rock_Stone"
    },
    {
      "x": -37,
      "y": 47,
      "z": -4,
      "name": "Rock_Stone"
    },
    {
      "x": -37,
      "y": 48,
      "z": -4,
      "name": "Soil_Dirt"
    },
    {
      "x": -37,
      "y": 42,
      "z": -3,
      "name": "Rock_Stone"
    },
    {
      "x": -37,
      "y": 43,
      "z": -3,
      "name": "Rock_Stone_Cobble_Mossy"
    },
    {
      "x": -37,
      "y": 44,
      "z": -3,
      "name": "Rock_Stone"
    },
    {
      "x": -37,
      "y": 45,
      "z": -3,
      "name": "Rock_Stone_Cobble_Mossy"
    },
    {
      "x": -37,
      "y": 46,
      "z": -3,
      "name": "Soil_Dirt"
    },
    {
      "x": -37,
      "y": 47,
      "z": -3,
      "name": "Soil_Gravel_Mossy"
    },
    {
      "x": -37,
      "y": 48,
      "z": -3,
      "name": "Rock_Stone_Mossy"
    },
    {
      "x": -37,
      "y": 41,
      "z": -2,
      "name": "Rock_Stone_Mossy"
    },
    {
      "x": -37,
      "y": 42,
      "z": -2,
      "name": "Rock_Stone_Mossy"
    },
    {
      "x": -37,
      "y": 43,
      "z": -2,
      "name": "Plant_Moss_Block_Green"
    },
    {
      "x": -37,
      "y": 44,
      "z": -2,
      "name": "Rock_Stone"
    },
    {
      "x": -37,
      "y": 45,
      "z": -2,
      "name": "Rock_Stone"
    },
    {
      "x": -37,
      "y": 46,
      "z": -2,
      "name": "Rock_Stone"
    },
    {
      "x": -37,
      "y": 47,
      "z": -2,
      "name": "Soil_Dirt"
    },
    {
      "x": -37,
      "y": 48,
      "z": -2,
      "name": "Soil_Dirt"
    },
    {
      "x": -37,
      "y": 43,
      "z": -1,
      "name": "Plant_Moss_Block_Green"
    },
    {
      "x": -37,
      "y": 44,
      "z": -1,
      "name": "Soil_Dirt"
    },
    {
      "x": -37,
      "y": 45,
      "z": -1,
      "name": "Rock_Stone_Cobble_Mossy"
    },
    {
      "x": -37,
      "y": 46,
      "z": -1,
      "name": "Rock_Stone"
    },
    {
      "x": -37,
      "y": 47,
      "z": -1,
      "name": "Plant_Moss_Block_Green"
    },
    {
      "x": -37,
      "y": 48,
      "z": -1,
      "name": "Soil_Dirt"
    },
    {
      "x": -37,
      "y": 43,
      "z": 0,
      "name": "Rock_Stone_Cobble_Mossy"
    },
    {
      "x": -37,
      "y": 44,
      "z": 0,
      "name": "Rock_Stone_Cobble_Mossy"
    },
    {
      "x": -37,
      "y": 45,
      "z": 0,
      "name": "Soil_Dirt"
    },
    {
      "x": -37,
      "y": 46,
      "z": 0,
      "name": "Rock_Stone"
    },
    {
      "x": -36,
      "y": 45,
      "z": -6,
      "name": "Rock_Stone"
    },
    {
      "x": -36,
      "y": 45,
      "z": -5,
      "name": "Rock_Stone"
    },
    {
      "x": -36,
      "y": 44,
      "z": -4,
      "name": "Rock_Stone_Mossy"
    },
    {
      "x": -36,
      "y": 45,
      "z": -4,
      "name": "Rock_Stone_Cobble_Mossy"
    },
    {
      "x": -36,
      "y": 46,
      "z": -4,
      "name": "Soil_Dirt"
    },
    {
      "x": -36,
      "y": 44,
      "z": -3,
      "name": "Plant_Moss_Block_Green"
    },
    {
      "x": -36,
      "y": 45,
      "z": -3,
      "name": "Plant_Moss_Block_Green"
    },
    {
      "x": -36,
      "y": 46,
      "z": -3,
      "name": "Plant_Moss_Block_Green"
    },
    {
      "x": -36,
      "y": 44,
      "z": -2,
      "name": "Plant_Moss_Block_Green"
    },
    {
      "x": -36,
      "y": 45,
      "z": -2,
      "name": "Rock_Stone_Mossy"
    },
    {
      "x": -36,
      "y": 46,
      "z": -2,
      "name": "Soil_Gravel_Mossy"
    },
    {
      "x": -36,
      "y": 43,
      "z": -1,
      "name": "Plant_Moss_Block_Green"
    },
    {
      "x": -36,
      "y": 45,
      "z": -1,
      "name": "Plant_Moss_Block_Green"
    },
    {
      "x": -35,
      "y": 45,
      "z": -5,
      "name": "Rock_Stone_Cobble_Mossy"
    },
    {
      "x": -28,
      "y": 9,
      "z": -36,
      "name": "Rock_Stone_Mossy"
    },
    {
      "x": -28,
      "y": 11,
      "z": -35,
      "name": "Rock_Stone"
    },
    {
      "x": -28,
      "y": 10,
      "z": -34,
      "name": "Rock_Stone_Mossy"
    },
    {
      "x": -28,
      "y": 9,
      "z": -33,
      "name": "Soil_Dirt"
    },
    {
      "x": -27,
      "y": 8,
      "z": -36,
      "name": "Plant_Moss_Block_Green"
    },
    {
      "x": -27,
      "y": 9,
      "z": -36,
      "name": "Soil_Dirt"
    },
    {
      "x": -27,
      "y": 10,
      "z": -36,
      "name": "Soil_Dirt"
    },
    {
      "x": -27,
      "y": 7,
      "z": -35,
      "name": "Rock_Stone"
    },
    {
      "x": -27,
      "y": 8,
      "z": -35,
      "name": "Rock_Stone_Cobble_Mossy"
    },
    {
      "x": -27,
      "y": 9,
      "z": -35,
      "name": "Soil_Gravel_Mossy"
    },
    {
      "x": -27,
      "y": 10,
      "z": -35,
      "name": "Rock_Stone_Cobble_Mossy"
    },
    {
      "x": -27,
      "y": 11,
      "z": -35,
      "name": "Soil_Gravel_Mossy"
    },
    {
      "x": -27,
      "y": 7,
      "z": -34,
      "name": "Soil_Gravel_Mossy"
    },
    {
      "x": -27,
      "y": 8,
      "z": -34,
      "name": "Plant_Moss_Block_Green"
    },
    {
      "x": -27,
      "y": 9,
      "z": -34,
      "name": "Rock_Stone_Mossy"
    },
    {
      "x": -27,
      "y": 10,
      "z": -34,
      "name": "Soil_Dirt"
    },
    {
      "x": -27,
      "y": 11,
      "z": -34,
      "name": "Plant_Moss_Block_Green"
    },
    {
      "x": -27,
      "y": 7,
      "z": -33,
      "name": "Rock_Stone_Cobble_Mossy"
    },
    {
      "x": -27,
      "y": 8,
      "z": -33,
      "name": "Rock_Stone_Mossy"
    },
    {
      "x": -27,
      "y": 9,
      "z": -33,
      "name": "Rock_Stone"
    },
    {
      "x": -27,
      "y": 10,
      "z": -33,
      "name": "Soil_Gravel_Mossy"
    },
    {
      "x": -27,
      "y": 11,
      "z": -33,
      "name": "Rock_Stone_Mossy"
    },
    {
      "x": -27,
      "y": 7,
      "z": -32,
      "name": "Soil_Dirt"
    },
    {
      "x": -27,
      "y": 8,
      "z": -32,
      "name": "Plant_Moss_Block_Green"
    },
    {
      "x": -27,
      "y": 9,
      "z": -32,
      "name": "Rock_Stone_Cobble_Mossy"
    },
    {
      "x": -27,
      "y": 10,
      "z": -32,
      "name": "Soil_Dirt"
    },
    {
      "x": -27,
      "y": 11,
      "z": -32,
      "name": "Rock_Stone_Cobble_Mossy"
    },
    {
      "x": -27,
      "y": 12,
      "z": -32,
      "name": "Rock_Stone_Cobble_Mossy"
    },
    {
      "x": -27,
      "y": 7,
      "z": -31,
      "name": "Rock_Stone_Mossy"
    },
    {
      "x": -27,
      "y": 8,
      "z": -31,
      "name": "Soil_Gravel_Mossy"
    },
    {
      "x": -27,
      "y": 9,
      "z": -31,
      "name": "Plant_Moss_Block_Green"
    },
    {
      "x": -27,
      "y": 10,
      "z": -31,
      "name": "Rock_Stone"
    },
    {
      "x": -27,
      "y": 11,
      "z": -31,
      "name": "Soil_Gravel_Mossy"
    },
    {
      "x": -27,
      "y": 7,
      "z": -30,
      "name": "Rock_Stone"
    },
    {
      "x": -27,
      "y": 8,
      "z": -30,
      "name": "Plant_Moss_Block_Green"
    },
    {
      "x": -27,
      "y": 9,
      "z": -30,
      "name": "Rock_Stone"
    },
    {
      "x": -27,
      "y": 10,
      "z": -30,
      "name": "Rock_Stone"
    },
    {
      "x": -27,
      "y": 11,
      "z": -30,
      "name": "Rock_Stone_Mossy"
    },
    {
      "x": -27,
      "y": 8,
      "z": -29,
      "name": "Soil_Gravel_Mossy"
    },
    {
      "x": -27,
      "y": 9,
      "z": -29,
      "name": "Plant_Moss_Block_Green"
    },
    {
      "x": -27,
      "y": 10,
      "z": -29,
      "name": "Plant_Moss_Block_Green"
    },
    {
      "x": -27,
      "y": 8,
      "z": -28,
      "name": "Plant_Moss_Block_Green"
    },
    {
      "x": -26,
      "y": 9,
      "z": -38,
      "name": "Soil_Dirt"
    },
    {
      "x": -26,
      "y": 8,
      "z": -37,
      "name": "Rock_Stone_Cobble_Mossy"
    },
    {
      "x": -26,
      "y": 9,
      "z": -37,
      "name": "Rock_Stone_Mossy"
    },
    {
      "x": -26,
      "y": 10,
      "z": -37,
      "name": "Plant_Moss_Block_Green"
    },
    {
      "x": -26,
      "y": 11,
      "z": -37,
      "name": "Soil_Dirt"
    },
    {
      "x": -26,
      "y": 7,
      "z": -36,
      "name": "Rock_Stone_Cobble_Mossy"
    },
    {
      "x": -26,
      "y": 8,
      "z": -36,
      "name": "Soil_Dirt"
    },
    {
      "x": -26,
      "y": 9,
      "z": -36,
      "name": "Rock_Stone"
    },
    {
      "x": -26,
      "y": 10,
      "z": -36,
      "name": "Rock_Stone_Cobble_Mossy"
    },
    {
      "x": -26,
      "y": 11,
      "z": -36,
      "name": "Rock_Stone_Cobble_Mossy"
    },
    {
      "x": -26,
      "y": 12,
      "z": -36,
      "name": "Rock_Stone_Cobble_Mossy"
    },
    {
      "x": -26,
      "y": 6,
      "z": -35,
      "name": "Rock_Stone_Mossy"
    },
    {
      "x": -26,
      "y": 7,
      "z": -35,
      "name": "Rock_Stone_Cobble_Mossy"
    },
    {
      "x": -26,
      "y": 8,
      "z": -35,
      "name": "Rock_Stone_Mossy"
    },
    {
      "x": -26,
      "y": 9,
      "z": -35,
      "name": "Plant_Moss_Block_Green"
    },
    {
      "x": -26,
      "y": 10,
      "z": -35,
      "name": "Soil_Gravel_Mossy"
    },
    {
      "x": -26,
      "y": 11,
      "z": -35,
      "name": "Rock_Stone_Cobble_Mossy"
    },
    {
      "x": -26,
      "y": 12,
      "z": -35,
      "name": "Soil_Gravel_Mossy"
    },
    {
      "x": -26,
      "y": 6,
      "z": -34,
      "name": "Soil_Gravel_Mossy"
    },
    {
      "x": -26,
      "y": 7,
      "z": -34,
      "name": "Rock_Stone_Mossy"
    },
    {
      "x": -26,
      "y": 8,
      "z": -34,
      "name": "Plant_Moss_Block_Green"
    },
    {
      "x": -26,
      "y": 9,
      "z": -34,
      "name": "Plant_Moss_Block_Green"
    },
    {
      "x": -26,
      "y": 10,
      "z": -34,
      "name": "Soil_Gravel_Mossy"
    },
    {
      "x": -26,
      "y": 11,
      "z": -34,
      "name": "Rock_Stone_Mossy"
    },
    {
      "x": -26,
      "y": 12,
      "z": -34,
      "name": "Rock_Stone_Mossy"
    },
    {
      "x": -26,
      "y": 5,
      "z": -33,
      "name": "Soil_Gravel_Mossy"
    },
    {
      "x": -26,
      "y": 6,
      "z": -33,
      "name": "Soil_Dirt"
    },
    {
      "x": -26,
      "y": 7,
      "z": -33,
      "name": "Plant_Moss_Block_Green"
    },
    {
      "x": -26,
      "y": 8,
      "z": -33,
      "name": "Plant_Moss_Block_Green"
    },
    {
      "x": -26,
      "y": 9,
      "z": -33,
      "name": "Soil_Dirt"
    },
    {
      "x": -26,
      "y": 10,
      "z": -33,
      "name": "Soil_Gravel_Mossy"
    },
    {
      "x": -26,
      "y": 11,
      "z": -33,
      "name": "Soil_Gravel_Mossy"
    },
    {
      "x": -26,
      "y": 12,
      "z": -33,
      "name": "Plant_Moss_Block_Green"
    },
    {
      "x": -26,
      "y": 6,
      "z": -32,
      "name": "Rock_Stone"
    },
    {
      "x": -26,
      "y": 7,
      "z": -32,
      "name": "Soil_Dirt"
    },
    {
      "x": -26,
      "y": 8,
      "z": -32,
      "name": "Rock_Stone"
    },
    {
      "x": -26,
      "y": 9,
      "z": -32,
      "name": "Soil_Gravel_Mossy"
    },
    {
      "x": -26,
      "y": 10,
      "z": -32,
      "name": "Rock_Stone_Mossy"
    },
    {
      "x": -26,
      "y": 11,
      "z": -32,
      "name": "Soil_Dirt"
    },
    {
      "x": -26,
      "y": 12,
      "z": -32,
      "name": "Plant_Moss_Block_Green"
    },
    {
      "x": -26,
      "y": 6,
      "z": -31,
      "name": "Soil_Dirt"
    },
    {
      "x": -26,
      "y": 7,
      "z": -31,
      "name": "Rock_Stone_Mossy"
    },
    {
      "x": -26,
      "y": 8,
      "z": -31,
      "name": "Soil_Dirt"
    },
    {
      "x": -26,
      "y": 9,
      "z": -31,
      "name": "Rock_Stone_Mossy"
    },
    {
      "x": -26,
      "y": 10,
      "z": -31,
      "name": "Rock_Stone_Cobble_Mossy"
    },
    {
      "x": -26,
      "y": 11,
      "z": -31,
      "name": "Soil_Gravel_Mossy"
    },
    {
      "x": -26,
      "y": 12,
      "z": -31,
      "name": "Rock_Stone"
    },
    {
      "x": -26,
      "y": 6,
      "z": -30,
      "name": "Soil_Dirt"
    },
    {
      "x": -26,
      "y": 7,
      "z": -30,
      "name": "Rock_Stone_Mossy"
    },
    {
      "x": -26,
      "y": 8,
      "z": -30,
      "name": "Soil_Gravel_Mossy"
    },
    {
      "x": -26,
      "y": 9,
      "z": -30,
      "name": "Plant_Moss_Block_Green"
    },
    {
      "x": -26,
      "y": 10,
      "z": -30,
      "name": "Soil_Dirt"
    },
    {
      "x": -26,
      "y": 11,
      "z": -30,
      "name": "Plant_Moss_Block_Green"
    },
    {
      "x": -26,
      "y": 12,
      "z": -30,
      "name": "Soil_Dirt"
    },
    {
      "x": -26,
      "y": 7,
      "z": -29,
      "name": "Soil_Dirt"
    },
    {
      "x": -26,
      "y": 8,
      "z": -29,
      "name": "Rock_Stone_Cobble_Mossy"
    },
    {
      "x": -26,
      "y": 9,
      "z": -29,
      "name": "Rock_Stone_Cobble_Mossy"
    },
    {
      "x": -26,
      "y": 10,
      "z": -29,
      "name": "Soil_Gravel_Mossy"
    },
    {
      "x": -26,
      "y": 11,
      "z": -29,
      "name": "Plant_Moss_Block_Green"
    },
    {
      "x": -26,
      "y": 8,
      "z": -28,
      "name": "Soil_Gravel_Mossy"
    },
    {
      "x": -26,
      "y": 9,
      "z": -28,
      "name": "Soil_Gravel_Mossy"
    },
    {
      "x": -26,
      "y": 10,
      "z": -28,
      "name": "Rock_Stone"
    },
    {
      "x": -25,
      "y": 9,
      "z": -38,
      "name": "Plant_Moss_Block_Green"
    },
    {
      "x": -25,
      "y": 7,
      "z": -37,
      "name": "Plant_Moss_Block_Green"
    },
    {
      "x": -25,
      "y": 8,
      "z": -37,
      "name": "Soil_Dirt"
    },
    {
      "x": -25,
      "y": 9,
      "z": -37,
      "name": "Soil_Dirt"
    },
    {
      "x": -25,
      "y": 10,
      "z": -37,
      "name": "Rock_Stone"
    },
    {
      "x": -25,
      "y": 11,
      "z": -37,
      "name": "Plant_Moss_Block_Green"
    },
    {
      "x": -25,
      "y": 6,
      "z": -36,
      "name": "Rock_Stone_Mossy"
    },
    {
      "x": -25,
      "y": 7,
      "z": -36,
      "name": "Plant_Moss_Block_Green"
    },
    {
      "x": -25,
      "y": 8,
      "z": -36,
      "name": "Plant_Moss_Block_Green"
    },
    {
      "x": -25,
      "y": 9,
      "z": -36,
      "name": "Rock_Stone"
    },
    {
      "x": -25,
      "y": 10,
      "z": -36,
      "name": "Plant_Moss_Block_Green"
    },
    {
      "x": -25,
      "y": 11,
      "z": -36,
      "name": "Rock_Stone_Mossy"
    },
    {
      "x": -25,
      "y": 12,
      "z": -36,
      "name": "Rock_Stone_Mossy"
    },
    {
      "x": -25,
      "y": 6,
      "z": -35,
      "name": "Soil_Gravel_Mossy"
    },
    {
      "x": -25,
      "y": 7,
      "z": -35,
      "name": "Rock_Stone"
    },
    {
      "x": -25,
      "y": 8,
      "z": -35,
      "name": "Rock_Stone_Cobble_Mossy"
    },
    {
      "x": -25,
      "y": 9,
      "z": -35,
      "name": "Soil_Gravel_Mossy"
    },
    {
      "x": -25,
      "y": 10,
      "z": -35,
      "name": "Soil_Gravel_Mossy"
    },
    {
      "x": -25,
      "y": 11,
      "z": -35,
      "name": "Rock_Stone"
    },
    {
      "x": -25,
      "y": 12,
      "z": -35,
      "name": "Soil_Gravel_Mossy"
    },
    {
      "x": -25,
      "y": 5,
      "z": -34,
      "name": "Soil_Gravel_Mossy"
    },
    {
      "x": -25,
      "y": 6,
      "z": -34,
      "name": "Soil_Dirt"
    },
    {
      "x": -25,
      "y": 7,
      "z": -34,
      "name": "Rock_Stone_Mossy"
    },
    {
      "x": -25,
      "y": 8,
      "z": -34,
      "name": "Soil_Dirt"
    },
    {
      "x": -25,
      "y": 9,
      "z": -34,
      "name": "Plant_Moss_Block_Green"
    },
    {
      "x": -25,
      "y": 10,
      "z": -34,
      "name": "Rock_Stone"
    },
    {
      "x": -25,
      "y": 11,
      "z": -34,
      "name": "Soil_Gravel_Mossy"
    },
    {
      "x": -25,
      "y": 12,
      "z": -34,
      "name": "Soil_Dirt"
    },
    {
      "x": -25,
      "y": 13,
      "z": -34,
      "name": "Soil_Dirt"
    },
    {
      "x": -25,
      "y": 5,
      "z": -33,
      "name": "Rock_Stone"
    },
    {
      "x": -25,
      "y": 6,
      "z": -33,
      "name": "Soil_Gravel_Mossy"
    },
    {
      "x": -25,
      "y": 7,
      "z": -33,
      "name": "Soil_Gravel_Mossy"
    },
    {
      "x": -25,
      "y": 8,
      "z": -33,
      "name": "Plant_Moss_Block_Green"
    },
    {
      "x": -25,
      "y": 9,
      "z": -33,
      "name": "Soil_Dirt"
    },
    {
      "x": -25,
      "y": 10,
      "z": -33,
      "name": "Rock_Stone_Cobble_Mossy"
    },
    {
      "x": -25,
      "y": 11,
      "z": -33,
      "name": "Rock_Stone_Cobble_Mossy"
    },
    {
      "x": -25,
      "y": 12,
      "z": -33,
      "name": "Rock_Stone_Mossy"
    },
    {
      "x": -25,
      "y": 13,
      "z": -33,
      "name": "Soil_Gravel_Mossy"
    },
    {
      "x": -25,
      "y": 5,
      "z": -32,
      "name": "Plant_Moss_Block_Green"
    },
    {
      "x": -25,
      "y": 6,
      "z": -32,
      "name": "Rock_Stone_Mossy"
    },
    {
      "x": -25,
      "y": 7,
      "z": -32,
      "name": "Soil_Gravel_Mossy"
    },
    {
      "x": -25,
      "y": 8,
      "z": -32,
      "name": "Rock_Stone_Cobble_Mossy"
    },
    {
      "x": -25,
      "y": 9,
      "z": -32,
      "name": "Soil_Gravel_Mossy"
    },
    {
      "x": -25,
      "y": 10,
      "z": -32,
      "name": "Soil_Gravel_Mossy"
    },
    {
      "x": -25,
      "y": 11,
      "z": -32,
      "name": "Rock_Stone_Mossy"
    },
    {
      "x": -25,
      "y": 12,
      "z": -32,
      "name": "Rock_Stone_Mossy"
    },
    {
      "x": -25,
      "y": 13,
      "z": -32,
      "name": "Soil_Gravel_Mossy"
    },
    {
      "x": -25,
      "y": 5,
      "z": -31,
      "name": "Plant_Moss_Block_Green"
    },
    {
      "x": -25,
      "y": 6,
      "z": -31,
      "name": "Soil_Gravel_Mossy"
    },
    {
      "x": -25,
      "y": 7,
      "z": -31,
      "name": "Rock_Stone"
    },
    {
      "x": -25,
      "y": 8,
      "z": -31,
      "name": "Rock_Stone_Mossy"
    },
    {
      "x": -25,
      "y": 9,
      "z": -31,
      "name": "Soil_Dirt"
    },
    {
      "x": -25,
      "y": 10,
      "z": -31,
      "name": "Soil_Dirt"
    },
    {
      "x": -25,
      "y": 11,
      "z": -31,
      "name": "Rock_Stone"
    },
    {
      "x": -25,
      "y": 12,
      "z": -31,
      "name": "Soil_Gravel_Mossy"
    },
    {
      "x": -25,
      "y": 13,
      "z": -31,
      "name": "Soil_Gravel_Mossy"
    },
    {
      "x": -25,
      "y": 5,
      "z": -30,
      "name": "Rock_Stone_Mossy"
    },
    {
      "x": -25,
      "y": 6,
      "z": -30,
      "name": "Plant_Moss_Block_Green"
    },
    {
      "x": -25,
      "y": 7,
      "z": -30,
      "name": "Soil_Dirt"
    },
    {
      "x": -25,
      "y": 8,
      "z": -30,
      "name": "Rock_Stone"
    },
    {
      "x": -25,
      "y": 9,
      "z": -30,
      "name": "Plant_Moss_Block_Green"
    },
    {
      "x": -25,
      "y": 10,
      "z": -30,
      "name": "Rock_Stone"
    },
    {
      "x": -25,
      "y": 11,
      "z": -30,
      "name": "Plant_Moss_Block_Green"
    },
    {
      "x": -25,
      "y": 12,
      "z": -30,
      "name": "Rock_Stone_Mossy"
    },
    {
      "x": -25,
      "y": 13,
      "z": -30,
      "name": "Rock_Stone_Mossy"
    },
    {
      "x": -25,
      "y": 6,
      "z": -29,
      "name": "Rock_Stone"
    },
    {
      "x": -25,
      "y": 7,
      "z": -29,
      "name": "Soil_Dirt"
    },
    {
      "x": -25,
      "y": 8,
      "z": -29,
      "name": "Rock_Stone_Cobble_Mossy"
    },
    {
      "x": -25,
      "y": 9,
      "z": -29,
      "name": "Soil_Gravel_Mossy"
    },
    {
      "x": -25,
      "y": 10,
      "z": -29,
      "name": "Rock_Stone"
    },
    {
      "x": -25,
      "y": 11,
      "z": -29,
      "name": "Soil_Gravel_Mossy"
    },
    {
      "x": -25,
      "y": 12,
      "z": -29,
      "name": "Soil_Dirt"
    },
    {
      "x": -25,
      "y": 6,
      "z": -28,
      "name": "Soil_Gravel_Mossy"
    },
    {
      "x": -25,
      "y": 7,
      "z": -28,
      "name": "Rock_Stone_Cobble_Mossy"
    },
    {
      "x": -25,
      "y": 8,
      "z": -28,
      "name": "Soil_Gravel_Mossy"
    },
    {
      "x": -25,
      "y": 9,
      "z": -28,
      "name": "Plant_Moss_Block_Green"
    },
    {
      "x": -25,
      "y": 10,
      "z": -28,
      "name": "Soil_Dirt"
    },
    {
      "x": -25,
      "y": 11,
      "z": -28,
      "name": "Soil_Dirt"
    },
    {
      "x": -25,
      "y": 12,
      "z": -28,
      "name": "Rock_Stone_Mossy"
    },
    {
      "x": -25,
      "y": 8,
      "z": -27,
      "name": "Rock_Stone_Mossy"
    },
    {
      "x": -25,
      "y": 9,
      "z": -27,
      "name": "Rock_Stone_Mossy"
    },
    {
      "x": -25,
      "y": 10,
      "z": -27,
      "name": "Rock_Stone_Mossy"
    },
    {
      "x": -25,
      "y": 9,
      "z": -26,
      "name": "Soil_Dirt"
    },
    {
      "x": -24,
      "y": 8,
      "z": -38,
      "name": "Rock_Stone_Mossy"
    },
    {
      "x": -24,
      "y": 9,
      "z": -38,
      "name": "Rock_Stone_Cobble_Mossy"
    },
    {
      "x": -24,
      "y": 10,
      "z": -38,
      "name": "Rock_Stone_Cobble_Mossy"
    },
    {
      "x": -24,
      "y": 7,
      "z": -37,
      "name": "Soil_Gravel_Mossy"
    },
    {
      "x": -24,
      "y": 8,
      "z": -37,
      "name": "Rock_Stone_Cobble_Mossy"
    },
    {
      "x": -24,
      "y": 9,
      "z": -37,
      "name": "Rock_Stone"
    },
    {
      "x": -24,
      "y": 10,
      "z": -37,
      "name": "Rock_Stone_Cobble_Mossy"
    },
    {
      "x": -24,
      "y": 11,
      "z": -37,
      "name": "Soil_Dirt"
    },
    {
      "x": -24,
      "y": 5,
      "z": -36,
      "name": "Rock_Stone"
    },
    {
      "x": -24,
      "y": 6,
      "z": -36,
      "name": "Rock_Stone_Cobble_Mossy"
    },
    {
      "x": -24,
      "y": 7,
      "z": -36,
      "name": "Rock_Stone"
    },
    {
      "x": -24,
      "y": 8,
      "z": -36,
      "name": "Soil_Dirt"
    },
    {
      "x": -24,
      "y": 9,
      "z": -36,
      "name": "Soil_Gravel_Mossy"
    },
    {
      "x": -24,
      "y": 10,
      "z": -36,
      "name": "Soil_Dirt"
    },
    {
      "x": -24,
      "y": 11,
      "z": -36,
      "name": "Soil_Dirt"
    },
    {
      "x": -24,
      "y": 12,
      "z": -36,
      "name": "Rock_Stone_Mossy"
    },
    {
      "x": -24,
      "y": 5,
      "z": -35,
      "name": "Soil_Gravel_Mossy"
    },
    {
      "x": -24,
      "y": 6,
      "z": -35,
      "name": "Plant_Moss_Block_Green"
    },
    {
      "x": -24,
      "y": 7,
      "z": -35,
      "name": "Rock_Stone_Mossy"
    },
    {
      "x": -24,
      "y": 8,
      "z": -35,
      "name": "Plant_Moss_Block_Green"
    },
    {
      "x": -24,
      "y": 9,
      "z": -35,
      "name": "Rock_Stone"
    },
    {
      "x": -24,
      "y": 10,
      "z": -35,
      "name": "Plant_Moss_Block_Green"
    },
    {
      "x": -24,
      "y": 11,
      "z": -35,
      "name": "Soil_Dirt"
    },
    {
      "x": -24,
      "y": 12,
      "z": -35,
      "name": "Soil_Dirt"
    },
    {
      "x": -24,
      "y": 13,
      "z": -35,
      "name": "Soil_Dirt"
    },
    {
      "x": -24,
      "y": 5,
      "z": -34,
      "name": "Soil_Dirt"
    },
    {
      "x": -24,
      "y": 6,
      "z": -34,
      "name": "Rock_Stone_Mossy"
    },
    {
      "x": -24,
      "y": 7,
      "z": -34,
      "name": "Soil_Gravel_Mossy"
    },
    {
      "x": -24,
      "y": 8,
      "z": -34,
      "name": "Plant_Moss_Block_Green"
    },
    {
      "x": -24,
      "y": 9,
      "z": -34,
      "name": "Soil_Dirt"
    },
    {
      "x": -24,
      "y": 10,
      "z": -34,
      "name": "Rock_Stone"
    },
    {
      "x": -24,
      "y": 11,
      "z": -34,
      "name": "Rock_Stone_Cobble_Mossy"
    },
    {
      "x": -24,
      "y": 12,
      "z": -34,
      "name": "Rock_Stone_Cobble_Mossy"
    },
    {
      "x": -24,
      "y": 13,
      "z": -34,
      "name": "Rock_Stone_Cobble_Mossy"
    },
    {
      "x": -24,
      "y": 5,
      "z": -33,
      "name": "Rock_Stone"
    },
    {
      "x": -24,
      "y": 6,
      "z": -33,
      "name": "Rock_Stone"
    },
    {
      "x": -24,
      "y": 7,
      "z": -33,
      "name": "Soil_Gravel_Mossy"
    },
    {
      "x": -24,
      "y": 8,
      "z": -33,
      "name": "Soil_Dirt"
    },
    {
      "x": -24,
      "y": 9,
      "z": -33,
      "name": "Rock_Stone_Mossy"
    },
    {
      "x": -24,
      "y": 10,
      "z": -33,
      "name": "Plant_Moss_Block_Green"
    },
    {
      "x": -24,
      "y": 11,
      "z": -33,
      "name": "Soil_Dirt"
    },
    {
      "x": -24,
      "y": 12,
      "z": -33,
      "name": "Rock_Stone"
    },
    {
      "x": -24,
      "y": 13,
      "z": -33,
      "name": "Soil_Dirt"
    },
    {
      "x": -24,
      "y": 14,
      "z": -33,
      "name": "Rock_Stone"
    },
    {
      "x": -24,
      "y": 5,
      "z": -32,
      "name": "Soil_Gravel_Mossy"
    },
    {
      "x": -24,
      "y": 6,
      "z": -32,
      "name": "Soil_Dirt"
    },
    {
      "x": -24,
      "y": 7,
      "z": -32,
      "name": "Plant_Moss_Block_Green"
    },
    {
      "x": -24,
      "y": 8,
      "z": -32,
      "name": "Rock_Stone"
    },
    {
      "x": -24,
      "y": 9,
      "z": -32,
      "name": "Rock_Stone_Cobble_Mossy"
    },
    {
      "x": -24,
      "y": 10,
      "z": -32,
      "name": "Rock_Stone"
    },
    {
      "x": -24,
      "y": 11,
      "z": -32,
      "name": "Rock_Stone_Mossy"
    },
    {
      "x": -24,
      "y": 12,
      "z": -32,
      "name": "Rock_Stone_Cobble_Mossy"
    },
    {
      "x": -24,
      "y": 13,
      "z": -32,
      "name": "Rock_Stone_Cobble_Mossy"
    },
    {
      "x": -24,
      "y": 5,
      "z": -31,
      "name": "Soil_Dirt"
    },
    {
      "x": -24,
      "y": 6,
      "z": -31,
