{
  "version": 8,
  "blockIdVersion": 11,
  "anchorX": 0,
  "anchorY": 5,
  "anchorZ": 0,
  "blocks": [
    {
      "x": -22,
      "y": 37,
      "z": -8,
      "name": "Rock_Aqua"
    },
    {
      "x": -22,
      "y": 37,
      "z": -7,
      "name": "Rock_Aqua_Brick_Smooth"
    },
    {
      "x": -22,
      "y": 33,
      "z": 2,
      "name": "Rock_Aqua_Brick"
    },
    {
      "x": -22,
      "y": 31,
      "z": 3,
      "name": "Rock_Crystal_Cyan_Large",
      "rotation": 8
    },
    {
      "x": -22,
      "y": 32,
      "z": 3,
      "name": "Rock_Aqua_Brick"
    },
    {
      "x": -22,
      "y": 33,
      "z": 3,
      "name": "Rock_Aqua_Brick"
    },
    {
      "x": -22,
      "y": 34,
      "z": 3,
      "name": "Rock_Aqua_Brick"
    },
    {
      "x": -22,
      "y": 32,
      "z": 4,
      "name": "Rock_Aqua_Cobble"
    },
    {
      "x": -22,
      "y": 33,
      "z": 4,
      "name": "Rock_Aqua_Cobble"
    },
    {
      "x": -22,
      "y": 34,
      "z": 4,
      "name": "Plant_Coral_Model_Cyan"
    },
    {
      "x": -22,
      "y": 33,
      "z": 5,
      "name": "Rock_Aqua_Cobble"
    },
    {
      "x": -22,
      "y": 34,
      "z": 6,
      "name": "Rock_Aqua_Brick"
    },
    {
      "x": -21,
      "y": 36,
      "z": -9,
      "name": "Rock_Aqua"
    },
    {
      "x": -21,
      "y": 37,
      "z": -9,
      "name": "Rock_Aqua_Brick_Smooth"
    },
    {
      "x": -21,
      "y": 38,
      "z": -9,
      "name": "Rock_Aqua_Brick_Smooth"
    },
    {
      "x": -21,
      "y": 39,
      "z": -9,
      "name": "Plant_Crop_Mushroom_Glowing_Blue"
    },
    {
      "x": -21,
      "y": 35,
      "z": -8,
      "name": "Rock_Aqua"
    },
    {
      "x": -21,
      "y": 36,
      "z": -8,
      "name": "Rock_Aqua"
    },
    {
      "x": -21,
      "y": 37,
      "z": -8,
      "name": "Rock_Aqua_Brick_Smooth"
    },
    {
      "x": -21,
      "y": 38,
      "z": -8,
      "name": "Rock_Aqua_Brick_Smooth"
    },
    {
      "x": -21,
      "y": 39,
      "z": -8,
      "name": "Rock_Aqua_Brick_Smooth"
    },
    {
      "x": -21,
      "y": 35,
      "z": -7,
      "name": "Rock_Aqua"
    },
    {
      "x": -21,
      "y": 36,
      "z": -7,
      "name": "Rock_Aqua"
    },
    {
      "x": -21,
      "y": 37,
      "z": -7,
      "name": "Rock_Aqua_Brick_Smooth"
    },
    {
      "x": -21,
      "y": 38,
      "z": -7,
      "name": "Rock_Aqua"
    },
    {
      "x": -21,
      "y": 39,
      "z": -7,
      "name": "Rock_Aqua"
    },
    {
      "x": -21,
      "y": 40,
      "z": -7,
      "name": "Plant_Crop_Mushroom_Glowing_Blue"
    },
    {
      "x": -21,
      "y": 36,
      "z": -6,
      "name": "Rock_Aqua_Brick_Smooth"
    },
    {
      "x": -21,
      "y": 37,
      "z": -6,
      "name": "Rock_Aqua_Brick_Smooth"
    },
    {
      "x": -21,
      "y": 38,
      "z": -6,
      "name": "Rock_Aqua"
    },
    {
      "x": -21,
      "y": 33,
      "z": 1,
      "name": "Rock_Aqua_Cobble"
    },
    {
      "x": -21,
      "y": 34,
      "z": 1,
      "name": "Rock_Aqua_Cobble"
    },
    {
      "x": -21,
      "y": 35,
      "z": 1,
      "name": "Plant_Crop_Mushroom_Glowing_Blue"
    },
    {
      "x": -21,
      "y": 31,
      "z": 2,
      "name": "Rock_Aqua_Brick"
    },
    {
      "x": -21,
      "y": 32,
      "z": 2,
      "name": "Rock_Aqua_Brick"
    },
    {
      "x": -21,
      "y": 33,
      "z": 2,
      "name": "Rock_Aqua_Cobble"
    },
    {
      "x": -21,
      "y": 34,
      "z": 2,
      "name": "Rock_Aqua_Brick"
    },
    {
      "x": -21,
      "y": 35,
      "z": 2,
      "name": "Rock_Aqua_Cobble"
    },
    {
      "x": -21,
      "y": 36,
      "z": 2,
      "name": "Plant_Coral_Model_Cyan"
    },
    {
      "x": -21,
      "y": 30,
      "z": 3,
      "name": "Rock_Aqua_Brick_Smooth"
    },
    {
      "x": -21,
      "y": 31,
      "z": 3,
      "name": "Rock_Aqua_Cobble"
    },
    {
      "x": -21,
      "y": 32,
      "z": 3,
      "name": "Rock_Aqua_Cobble"
    },
    {
      "x": -21,
      "y": 30,
      "z": 4,
      "name": "Rock_Aqua_Brick_Smooth"
    },
    {
      "x": -21,
      "y": 31,
      "z": 4,
      "name": "Rock_Aqua_Cobble"
    },
    {
      "x": -21,
      "y": 32,
      "z": 4,
      "name": "Rock_Aqua_Brick"
    },
    {
      "x": -21,
      "y": 29,
      "z": 5,
      "name": "Rock_Aqua_Stalactite_Large",
      "filler": 31744,
      "rotation": 8
    },
    {
      "x": -21,
      "y": 30,
      "z": 5,
      "name": "Rock_Aqua_Stalactite_Large",
      "rotation": 8
    },
    {
      "x": -21,
      "y": 31,
      "z": 5,
      "name": "Rock_Aqua_Brick"
    },
    {
      "x": -21,
      "y": 32,
      "z": 5,
      "name": "Rock_Aqua_Cobble"
    },
    {
      "x": -21,
      "y": 33,
      "z": 5,
      "name": "Rock_Aqua_Cobble"
    },
    {
      "x": -21,
      "y": 34,
      "z": 5,
      "name": "Rock_Aqua_Brick"
    },
    {
      "x": -21,
      "y": 35,
      "z": 5,
      "name": "Rock_Aqua_Cobble"
    },
    {
      "x": -21,
      "y": 36,
      "z": 5,
      "name": "Plant_Coral_Bush_Cyan"
    },
    {
      "x": -21,
      "y": 31,
      "z": 6,
      "name": "Rock_Aqua_Cobble"
    },
    {
      "x": -21,
      "y": 32,
      "z": 6,
      "name": "Rock_Aqua_Brick"
    },
    {
      "x": -21,
      "y": 33,
      "z": 6,
      "name": "Rock_Aqua_Brick"
    },
    {
      "x": -21,
      "y": 35,
      "z": 6,
      "name": "Rock_Aqua_Brick"
    },
    {
      "x": -21,
      "y": 32,
      "z": 7,
      "name": "Rock_Aqua_Brick"
    },
    {
      "x": -21,
      "y": 33,
      "z": 7,
      "name": "Rock_Aqua_Cobble"
    },
    {
      "x": -21,
      "y": 34,
      "z": 7,
      "name": "Rock_Aqua_Brick"
    },
    {
      "x": -21,
      "y": 35,
      "z": 7,
      "name": "Rock_Aqua_Cobble"
    },
    {
      "x": -21,
      "y": 36,
      "z": 7,
      "name": "Plant_Coral_Bush_Blue"
    },
    {
      "x": -20,
      "y": 37,
      "z": -10,
      "name": "Rock_Aqua"
    },
    {
      "x": -20,
      "y": 35,
      "z": -9,
      "name": "Rock_Aqua"
    },
    {
      "x": -20,
      "y": 36,
      "z": -9,
      "name": "Rock_Aqua_Brick_Smooth"
    },
    {
      "x": -20,
      "y": 37,
      "z": -9,
      "name": "Rock_Aqua"
    },
    {
      "x": -20,
      "y": 38,
      "z": -9,
      "name": "Rock_Aqua_Brick_Smooth"
    },
    {
      "x": -20,
      "y": 39,
      "z": -9,
      "name": "Rock_Aqua_Brick_Smooth"
    },
    {
      "x": -20,
      "y": 35,
      "z": -8,
      "name": "Rock_Aqua_Brick_Smooth"
    },
    {
      "x": -20,
      "y": 36,
      "z": -8,
      "name": "Rock_Aqua_Brick_Smooth"
    },
    {
      "x": -20,
      "y": 37,
      "z": -8,
      "name": "Rock_Aqua_Brick_Smooth"
    },
    {
      "x": -20,
      "y": 38,
      "z": -8,
      "name": "Rock_Aqua_Brick_Smooth"
    },
    {
      "x": -20,
      "y": 39,
      "z": -8,
      "name": "Rock_Aqua_Brick_Smooth"
    },
    {
      "x": -20,
      "y": 35,
      "z": -7,
      "name": "Rock_Aqua_Brick_Smooth"
    },
    {
      "x": -20,
      "y": 36,
      "z": -7,
      "name": "Rock_Aqua"
    },
    {
      "x": -20,
      "y": 37,
      "z": -7,
      "name": "Rock_Aqua_Brick_Smooth"
    },
    {
      "x": -20,
      "y": 38,
      "z": -7,
      "name": "Rock_Aqua_Brick_Smooth"
    },
    {
      "x": -20,
      "y": 39,
      "z": -7,
      "name": "Rock_Aqua_Brick_Smooth"
    },
    {
      "x": -20,
      "y": 36,
      "z": -6,
      "name": "Rock_Aqua_Brick_Smooth"
    },
    {
      "x": -20,
      "y": 37,
      "z": -6,
      "name": "Rock_Aqua"
    },
    {
      "x": -20,
      "y": 38,
      "z": -6,
      "name": "Rock_Aqua_Brick_Smooth"
    },
    {
      "x": -20,
      "y": 37,
      "z": -5,
      "name": "Rock_Aqua_Brick_Smooth"
    },
    {
      "x": -20,
      "y": 38,
      "z": -5,
      "name": "Plant_Crop_Mushroom_Glowing_Blue"
    },
    {
      "x": -20,
      "y": 32,
      "z": 0,
      "name": "Rock_Aqua_Brick_Smooth"
    },
    {
      "x": -20,
      "y": 33,
      "z": 0,
      "name": "Rock_Aqua_Cobble"
    },
    {
      "x": -20,
      "y": 34,
      "z": 0,
      "name": "Rock_Aqua_Brick"
    },
    {
      "x": -20,
      "y": 31,
      "z": 1,
      "name": "Rock_Aqua_Brick_Smooth"
    },
    {
      "x": -20,
      "y": 33,
      "z": 1,
      "name": "Rock_Aqua_Cobble"
    },
    {
      "x": -20,
      "y": 34,
      "z": 1,
      "name": "Rock_Aqua_Cobble"
    },
    {
      "x": -20,
      "y": 35,
      "z": 1,
      "name": "Rock_Aqua_Cobble"
    },
    {
      "x": -20,
      "y": 30,
      "z": 2,
      "name": "Rock_Aqua_Brick_Smooth"
    },
    {
      "x": -20,
      "y": 31,
      "z": 2,
      "name": "Rock_Aqua_Cobble"
    },
    {
      "x": -20,
      "y": 32,
      "z": 2,
      "name": "Rock_Aqua_Brick"
    },
    {
      "x": -20,
      "y": 33,
      "z": 2,
      "name": "Rock_Aqua_Brick"
    },
    {
      "x": -20,
      "y": 34,
      "z": 2,
      "name": "Rock_Aqua_Brick"
    },
    {
      "x": -20,
      "y": 35,
      "z": 2,
      "name": "Rock_Aqua_Cobble"
    },
    {
      "x": -20,
      "y": 36,
      "z": 2,
      "name": "Rock_Aqua_Cobble"
    },
    {
      "x": -20,
      "y": 37,
      "z": 2,
      "name": "Plant_Coral_Model_Cyan"
    },
    {
      "x": -20,
      "y": 27,
      "z": 3,
      "name": "Rock_Aqua_Stalactite_Large",
      "filler": 31744,
      "rotation": 8
    },
    {
      "x": -20,
      "y": 28,
      "z": 3,
      "name": "Rock_Aqua_Stalactite_Large",
      "rotation": 8
    },
    {
      "x": -20,
      "y": 29,
      "z": 3,
      "name": "Rock_Aqua_Brick_Smooth"
    },
    {
      "x": -20,
      "y": 30,
      "z": 3,
      "name": "Rock_Aqua_Brick_Smooth"
    },
    {
      "x": -20,
      "y": 31,
      "z": 3,
      "name": "Rock_Aqua_Brick"
    },
    {
      "x": -20,
      "y": 32,
      "z": 3,
      "name": "Rock_Aqua_Cobble"
    },
    {
      "x": -20,
      "y": 33,
      "z": 3,
      "name": "Rock_Aqua_Brick"
    },
    {
      "x": -20,
      "y": 34,
      "z": 3,
      "name": "Rock_Aqua_Brick"
    },
    {
      "x": -20,
      "y": 35,
      "z": 3,
      "name": "Rock_Aqua_Cobble"
    },
    {
      "x": -20,
      "y": 36,
      "z": 3,
      "name": "Rock_Aqua_Cobble"
    },
    {
      "x": -20,
      "y": 29,
      "z": 4,
      "name": "Rock_Aqua_Brick_Smooth"
    },
    {
      "x": -20,
      "y": 30,
      "z": 4,
      "name": "Rock_Aqua_Brick_Smooth"
    },
    {
      "x": -20,
      "y": 31,
      "z": 4,
      "name": "Rock_Aqua_Cobble"
    },
    {
      "x": -20,
      "y": 32,
      "z": 4,
      "name": "Rock_Aqua_Cobble"
    },
    {
      "x": -20,
      "y": 29,
      "z": 5,
      "name": "Rock_Aqua_Brick_Smooth"
    },
    {
      "x": -20,
      "y": 30,
      "z": 5,
      "name": "Rock_Aqua_Brick_Smooth"
    },
    {
      "x": -20,
      "y": 31,
      "z": 5,
      "name": "Rock_Aqua_Cobble"
    },
    {
      "x": -20,
      "y": 32,
      "z": 5,
      "name": "Rock_Aqua_Cobble"
    },
    {
      "x": -20,
      "y": 34,
      "z": 5,
      "name": "Rock_Aqua_Brick"
    },
    {
      "x": -20,
      "y": 35,
      "z": 5,
      "name": "Rock_Aqua_Cobble"
    },
    {
      "x": -20,
      "y": 36,
      "z": 5,
      "name": "Rock_Aqua_Cobble"
    },
    {
      "x": -20,
      "y": 30,
      "z": 6,
      "name": "Rock_Aqua_Brick_Smooth"
    },
    {
      "x": -20,
      "y": 31,
      "z": 6,
      "name": "Rock_Aqua_Brick"
    },
    {
      "x": -20,
      "y": 32,
      "z": 6,
      "name": "Rock_Aqua_Brick"
    },
    {
      "x": -20,
      "y": 33,
      "z": 6,
      "name": "Rock_Aqua_Brick"
    },
    {
      "x": -20,
      "y": 34,
      "z": 6,
      "name": "Rock_Aqua_Brick"
    },
    {
      "x": -20,
      "y": 36,
      "z": 6,
      "name": "Rock_Aqua_Cobble"
    },
    {
      "x": -20,
      "y": 31,
      "z": 7,
      "name": "Rock_Aqua_Cobble"
    },
    {
      "x": -20,
      "y": 32,
      "z": 7,
      "name": "Rock_Aqua_Brick"
    },
    {
      "x": -20,
      "y": 33,
      "z": 7,
      "name": "Rock_Aqua_Brick"
    },
    {
      "x": -20,
      "y": 34,
      "z": 7,
      "name": "Rock_Aqua_Cobble"
    },
    {
      "x": -20,
      "y": 35,
      "z": 7,
      "name": "Rock_Aqua_Brick"
    },
    {
      "x": -20,
      "y": 36,
      "z": 7,
      "name": "Plant_Coral_Model_Cyan"
    },
    {
      "x": -20,
      "y": 30,
      "z": 8,
      "name": "Rock_Aqua_Stalactite_Large",
      "filler": 31744,
      "rotation": 8
    },
    {
      "x": -20,
      "y": 31,
      "z": 8,
      "name": "Rock_Aqua_Stalactite_Large",
      "rotation": 8
    },
    {
      "x": -20,
      "y": 32,
      "z": 8,
      "name": "Rock_Aqua_Brick"
    },
    {
      "x": -20,
      "y": 33,
      "z": 8,
      "name": "Rock_Aqua_Brick"
    },
    {
      "x": -20,
      "y": 34,
      "z": 8,
      "name": "Rock_Aqua_Cobble"
    },
    {
      "x": -20,
      "y": 35,
      "z": 8,
      "name": "Rock_Aqua_Brick"
    },
    {
      "x": -20,
      "y": 36,
      "z": 8,
      "name": "Plant_Coral_Model_Cyan"
    },
    {
      "x": -19,
      "y": 28,
      "z": -14,
      "name": "Rock_Aqua_Cobble"
    },
    {
      "x": -19,
      "y": 29,
      "z": -14,
      "name": "Rock_Aqua_Brick"
    },
    {
      "x": -19,
      "y": 28,
      "z": -12,
      "name": "Rock_Aqua_Cobble"
    },
    {
      "x": -19,
      "y": 29,
      "z": -12,
      "name": "Rock_Aqua_Brick"
    },
    {
      "x": -19,
      "y": 36,
      "z": -9,
      "name": "Rock_Aqua"
    },
    {
      "x": -19,
      "y": 37,
      "z": -9,
      "name": "Rock_Aqua"
    },
    {
      "x": -19,
      "y": 38,
      "z": -9,
      "name": "Rock_Aqua"
    },
    {
      "x": -19,
      "y": 35,
      "z": -8,
      "name": "Rock_Aqua"
    },
    {
      "x": -19,
      "y": 36,
      "z": -8,
      "name": "Rock_Aqua"
    },
    {
      "x": -19,
      "y": 37,
      "z": -8,
      "name": "Rock_Aqua"
    },
    {
      "x": -19,
      "y": 38,
      "z": -8,
      "name": "Rock_Aqua_Brick_Smooth"
    },
    {
      "x": -19,
      "y": 39,
      "z": -8,
      "name": "Rock_Aqua_Brick_Smooth"
    },
    {
      "x": -19,
      "y": 36,
      "z": -7,
      "name": "Rock_Aqua_Brick_Smooth"
    },
    {
      "x": -19,
      "y": 37,
      "z": -7,
      "name": "Rock_Aqua_Brick_Smooth"
    },
    {
      "x": -19,
      "y": 38,
      "z": -7,
      "name": "Rock_Aqua_Brick_Smooth"
    },
    {
      "x": -19,
      "y": 36,
      "z": -6,
      "name": "Rock_Aqua_Brick_Smooth"
    },
    {
      "x": -19,
      "y": 37,
      "z": -6,
      "name": "Rock_Aqua_Brick_Smooth"
    },
    {
      "x": -19,
      "y": 38,
      "z": -6,
      "name": "Rock_Aqua_Brick_Smooth"
    },
    {
      "x": -19,
      "y": 33,
      "z": -1,
      "name": "Rock_Aqua_Brick"
    },
    {
      "x": -19,
      "y": 30,
      "z": 0,
      "name": "Rock_Aqua_Stalactite_Small",
      "rotation": 8
    },
    {
      "x": -19,
      "y": 31,
      "z": 0,
      "name": "Rock_Aqua_Brick_Smooth"
    },
    {
      "x": -19,
      "y": 32,
      "z": 0,
      "name": "Rock_Aqua_Brick_Smooth"
    },
    {
      "x": -19,
      "y": 33,
      "z": 0,
      "name": "Rock_Aqua_Brick"
    },
    {
      "x": -19,
      "y": 34,
      "z": 0,
      "name": "Rock_Aqua_Brick"
    },
    {
      "x": -19,
      "y": 35,
      "z": 0,
      "name": "Rock_Aqua_Cobble"
    },
    {
      "x": -19,
      "y": 36,
      "z": 0,
      "name": "Plant_Coral_Model_Blue"
    },
    {
      "x": -19,
      "y": 30,
      "z": 1,
      "name": "Rock_Aqua_Brick_Smooth"
    },
    {
      "x": -19,
      "y": 31,
      "z": 1,
      "name": "Rock_Aqua_Brick_Smooth"
    },
    {
      "x": -19,
      "y": 32,
      "z": 1,
      "name": "Rock_Aqua_Brick_Smooth"
    },
    {
      "x": -19,
      "y": 33,
      "z": 1,
      "name": "Rock_Aqua_Brick"
    },
    {
      "x": -19,
      "y": 34,
      "z": 1,
      "name": "Rock_Aqua_Cobble"
    },
    {
      "x": -19,
      "y": 35,
      "z": 1,
      "name": "Rock_Aqua_Brick"
    },
    {
      "x": -19,
      "y": 36,
      "z": 1,
      "name": "Rock_Aqua_Brick"
    },
    {
      "x": -19,
      "y": 28,
      "z": 2,
      "name": "Rock_Crystal_Cyan_Large",
      "rotation": 8
    },
    {
      "x": -19,
      "y": 29,
      "z": 2,
      "name": "Rock_Aqua_Brick_Smooth"
    },
    {
      "x": -19,
      "y": 30,
      "z": 2,
      "name": "Rock_Aqua_Brick_Smooth"
    },
    {
      "x": -19,
      "y": 31,
      "z": 2,
      "name": "Rock_Aqua_Brick"
    },
    {
      "x": -19,
      "y": 32,
      "z": 2,
      "name": "Rock_Aqua_Cobble"
    },
    {
      "x": -19,
      "y": 33,
      "z": 2,
      "name": "Rock_Aqua_Brick"
    },
    {
      "x": -19,
      "y": 34,
      "z": 2,
      "name": "Rock_Aqua_Cobble"
    },
    {
      "x": -19,
      "y": 35,
      "z": 2,
      "name": "Rock_Aqua_Cobble"
    },
    {
      "x": -19,
      "y": 36,
      "z": 2,
      "name": "Rock_Aqua_Brick"
    },
    {
      "x": -19,
      "y": 28,
      "z": 3,
      "name": "Rock_Aqua_Brick_Smooth"
    },
    {
      "x": -19,
      "y": 29,
      "z": 3,
      "name": "Rock_Aqua_Brick_Smooth"
    },
    {
      "x": -19,
      "y": 30,
      "z": 3,
      "name": "Rock_Aqua_Brick_Smooth"
    },
    {
      "x": -19,
      "y": 31,
      "z": 3,
      "name": "Rock_Aqua_Brick"
    },
    {
      "x": -19,
      "y": 32,
      "z": 3,
      "name": "Rock_Aqua_Brick"
    },
    {
      "x": -19,
      "y": 33,
      "z": 3,
      "name": "Rock_Aqua_Cobble"
    },
    {
      "x": -19,
      "y": 34,
      "z": 3,
      "name": "Rock_Aqua_Cobble"
    },
    {
      "x": -19,
      "y": 35,
      "z": 3,
      "name": "Rock_Aqua_Brick"
    },
    {
      "x": -19,
      "y": 36,
      "z": 3,
      "name": "Rock_Aqua_Brick"
    },
    {
      "x": -19,
      "y": 28,
      "z": 4,
      "name": "Rock_Aqua_Brick_Smooth"
    },
    {
      "x": -19,
      "y": 29,
      "z": 4,
      "name": "Rock_Aqua_Brick_Smooth"
    },
    {
      "x": -19,
      "y": 30,
      "z": 4,
      "name": "Rock_Aqua_Brick_Smooth"
    },
    {
      "x": -19,
      "y": 31,
      "z": 4,
      "name": "Rock_Aqua_Brick"
    },
    {
      "x": -19,
      "y": 32,
      "z": 4,
      "name": "Rock_Aqua_Cobble"
    },
    {
      "x": -19,
      "y": 33,
      "z": 4,
      "name": "Rock_Aqua_Cobble"
    },
    {
      "x": -19,
      "y": 34,
      "z": 4,
      "name": "Rock_Aqua_Cobble"
    },
    {
      "x": -19,
      "y": 35,
      "z": 4,
      "name": "Rock_Aqua_Brick"
    },
    {
      "x": -19,
      "y": 36,
      "z": 4,
      "name": "Rock_Aqua_Brick"
    },
    {
      "x": -19,
      "y": 26,
      "z": 5,
      "name": "Rock_Aqua_Stalactite_Large",
      "filler": 31744,
      "rotation": 8
    },
    {
      "x": -19,
      "y": 27,
      "z": 5,
      "name": "Rock_Aqua_Stalactite_Large",
      "rotation": 8
    },
    {
      "x": -19,
      "y": 28,
      "z": 5,
      "name": "Rock_Aqua_Brick_Smooth"
    },
    {
      "x": -19,
      "y": 29,
      "z": 5,
      "name": "Rock_Aqua_Brick_Smooth"
    },
    {
      "x": -19,
      "y": 30,
      "z": 5,
      "name": "Rock_Aqua_Brick_Smooth"
    },
    {
      "x": -19,
      "y": 31,
      "z": 5,
      "name": "Rock_Aqua_Brick"
    },
    {
      "x": -19,
      "y": 32,
      "z": 5,
      "name": "Rock_Aqua_Cobble"
    },
    {
      "x": -19,
      "y": 33,
      "z": 5,
      "name": "Rock_Aqua_Cobble"
    },
    {
      "x": -19,
      "y": 34,
      "z": 5,
      "name": "Rock_Aqua_Cobble"
    },
    {
      "x": -19,
      "y": 29,
      "z": 6,
      "name": "Rock_Aqua_Brick_Smooth"
    },
    {
      "x": -19,
      "y": 30,
      "z": 6,
      "name": "Rock_Aqua_Brick_Smooth"
    },
    {
      "x": -19,
      "y": 31,
      "z": 6,
      "name": "Rock_Aqua_Cobble"
    },
    {
      "x": -19,
      "y": 32,
      "z": 6,
      "name": "Rock_Aqua_Brick"
    },
    {
      "x": -19,
      "y": 34,
      "z": 6,
      "name": "Rock_Aqua_Brick"
    },
    {
      "x": -19,
      "y": 36,
      "z": 6,
      "name": "Rock_Aqua_Cobble"
    },
    {
      "x": -19,
      "y": 29,
      "z": 7,
      "name": "Rock_Aqua_Brick_Smooth"
    },
    {
      "x": -19,
      "y": 30,
      "z": 7,
      "name": "Rock_Aqua_Brick_Smooth"
    },
    {
      "x": -19,
      "y": 31,
      "z": 7,
      "name": "Rock_Aqua_Brick"
    },
    {
      "x": -19,
      "y": 32,
      "z": 7,
      "name": "Rock_Aqua_Cobble"
    },
    {
      "x": -19,
      "y": 33,
      "z": 7,
      "name": "Rock_Aqua_Cobble"
    },
    {
      "x": -19,
      "y": 34,
      "z": 7,
      "name": "Rock_Aqua_Cobble"
    },
    {
      "x": -19,
      "y": 35,
      "z": 7,
      "name": "Rock_Aqua_Cobble"
    },
    {
      "x": -19,
      "y": 36,
      "z": 7,
      "name": "Rock_Aqua_Brick"
    },
    {
      "x": -19,
      "y": 29,
      "z": 8,
      "name": "Rock_Crystal_Cyan_Large",
      "rotation": 8
    },
    {
      "x": -19,
      "y": 30,
      "z": 8,
      "name": "Rock_Aqua_Brick_Smooth"
    },
    {
      "x": -19,
      "y": 31,
      "z": 8,
      "name": "Rock_Aqua_Brick"
    },
    {
      "x": -19,
      "y": 32,
      "z": 8,
      "name": "Rock_Aqua_Brick"
    },
    {
      "x": -19,
      "y": 33,
      "z": 8,
      "name": "Rock_Aqua_Cobble"
    },
    {
      "x": -19,
      "y": 34,
      "z": 8,
      "name": "Rock_Aqua_Cobble"
    },
    {
      "x": -19,
      "y": 35,
      "z": 8,
      "name": "Rock_Aqua_Brick"
    },
    {
      "x": -19,
      "y": 36,
      "z": 8,
      "name": "Plant_Coral_Model_Blue"
    },
    {
      "x": -19,
      "y": 32,
      "z": 9,
      "name": "Rock_Aqua_Cobble"
    },
    {
      "x": -19,
      "y": 33,
      "z": 9,
      "name": "Rock_Aqua_Cobble"
    },
    {
      "x": -19,
      "y": 26,
      "z": 12,
      "name": "Rock_Aqua_Brick_Smooth"
    },
    {
      "x": -19,
      "y": 25,
      "z": 13,
      "name": "Rock_Aqua_Brick_Smooth"
    },
    {
      "x": -19,
      "y": 26,
      "z": 13,
      "name": "Rock_Aqua"
    },
    {
      "x": -19,
      "y": 27,
      "z": 13,
      "name": "Rock_Aqua_Brick_Smooth"
    },
    {
      "x": -19,
      "y": 25,
      "z": 14,
      "name": "Rock_Aqua_Brick_Smooth"
    },
    {
      "x": -19,
      "y": 26,
      "z": 14,
      "name": "Rock_Aqua"
    },
    {
      "x": -19,
      "y": 27,
      "z": 14,
      "name": "Rock_Aqua"
    },
    {
      "x": -19,
      "y": 25,
      "z": 15,
      "name": "Rock_Aqua_Brick_Smooth"
    },
    {
      "x": -19,
      "y": 26,
      "z": 15,
      "name": "Rock_Aqua_Brick_Smooth"
    },
    {
      "x": -19,
      "y": 27,
      "z": 15,
      "name": "Rock_Aqua"
    },
    {
      "x": -19,
      "y": 26,
      "z": 16,
      "name": "Rock_Aqua_Brick_Smooth"
    },
    {
      "x": -18,
      "y": 27,
      "z": -15,
      "name": "Rock_Crystal_Cyan_Large",
      "rotation": 8
    },
    {
      "x": -18,
      "y": 28,
      "z": -15,
      "name": "Rock_Aqua_Cobble"
    },
    {
      "x": -18,
      "y": 29,
      "z": -15,
      "name": "Rock_Aqua_Brick"
    },
    {
      "x": -18,
      "y": 27,
      "z": -14,
      "name": "Rock_Aqua_Cobble"
    },
    {
      "x": -18,
      "y": 28,
      "z": -14,
      "name": "Rock_Aqua_Brick"
    },
    {
      "x": -18,
      "y": 29,
      "z": -14,
      "name": "Rock_Aqua_Cobble"
    },
    {
      "x": -18,
      "y": 30,
      "z": -14,
      "name": "Rock_Aqua_Brick"
    },
    {
      "x": -18,
      "y": 27,
      "z": -13,
      "name": "Rock_Aqua_Cobble"
    },
    {
      "x": -18,
      "y": 28,
      "z": -13,
      "name": "Rock_Aqua_Cobble"
    },
    {
      "x": -18,
      "y": 29,
      "z": -13,
      "name": "Rock_Aqua_Brick"
    },
    {
      "x": -18,
      "y": 30,
      "z": -13,
      "name": "Rock_Aqua_Cobble"
    },
    {
      "x": -18,
      "y": 31,
      "z": -13,
      "name": "Plant_Coral_Bush_Cyan"
    },
    {
      "x": -18,
      "y": 29,
      "z": -12,
      "name": "Rock_Aqua_Brick"
    },
    {
      "x": -18,
      "y": 27,
      "z": -11,
      "name": "Rock_Aqua_Brick_Smooth"
    },
    {
      "x": -18,
      "y": 28,
      "z": -11,
      "name": "Rock_Aqua_Cobble"
    },
    {
      "x": -18,
      "y": 29,
      "z": -11,
      "name": "Rock_Aqua_Cobble"
    },
    {
      "x": -18,
      "y": 30,
      "z": -11,
      "name": "Rock_Aqua_Cobble"
    },
    {
      "x": -18,
      "y": 31,
      "z": -11,
      "name": "Plant_Crop_Mushroom_Glowing_Blue"
    },
    {
      "x": -18,
      "y": 29,
      "z": -10,
      "name": "Rock_Aqua_Brick"
    },
    {
      "x": -18,
      "y": 30,
      "z": -10,
      "name": "Plant_Coral_Model_Blue"
    },
    {
      "x": -18,
      "y": 37,
      "z": -8,
      "name": "Rock_Aqua_Brick_Smooth"
    },
    {
      "x": -18,
      "y": 37,
      "z": -7,
      "name": "Rock_Aqua_Brick_Smooth"
    },
    {
      "x": -18,
      "y": 32,
      "z": -1,
      "name": "Rock_Aqua_Brick_Smooth"
    },
    {
      "x": -18,
      "y": 33,
      "z": -1,
      "name": "Rock_Aqua_Cobble"
    },
    {
      "x": -18,
      "y": 34,
      "z": -1,
      "name": "Rock_Aqua_Cobble"
    },
    {
      "x": -18,
      "y": 31,
      "z": 0,
      "name": "Rock_Aqua_Brick_Smooth"
    },
    {
      "x": -18,
      "y": 32,
      "z": 0,
      "name": "Rock_Aqua_Brick_Smooth"
    },
    {
      "x": -18,
      "y": 33,
      "z": 0,
      "name": "Rock_Aqua_Brick"
    },
    {
      "x": -18,
      "y": 34,
      "z": 0,
      "name": "Rock_Aqua_Brick"
    },
    {
      "x": -18,
      "y": 35,
      "z": 0,
      "name": "Rock_Aqua_Cobble"
    },
    {
      "x": -18,
      "y": 29,
      "z": 1,
      "name": "Rock_Aqua_Brick_Smooth"
    },
    {
      "x": -18,
      "y": 30,
      "z": 1,
      "name": "Rock_Aqua_Brick_Smooth"
    },
    {
      "x": -18,
      "y": 31,
      "z": 1,
      "name": "Rock_Aqua_Brick_Smooth"
    },
    {
      "x": -18,
      "y": 32,
      "z": 1,
      "name": "Rock_Aqua_Brick_Smooth"
    },
    {
      "x": -18,
      "y": 33,
      "z": 1,
      "name": "Rock_Aqua_Cobble"
    },
    {
      "x": -18,
      "y": 34,
      "z": 1,
      "name": "Rock_Aqua_Cobble"
    },
    {
      "x": -18,
      "y": 35,
      "z": 1,
      "name": "Rock_Aqua_Brick"
    },
    {
      "x": -18,
      "y": 36,
      "z": 1,
      "name": "Rock_Aqua_Cobble"
    },
    {
      "x": -18,
      "y": 29,
      "z": 2,
      "name": "Rock_Aqua_Brick_Smooth"
    },
    {
      "x": -18,
      "y": 30,
      "z": 2,
      "name": "Rock_Aqua_Brick_Smooth"
    },
    {
      "x": -18,
      "y": 33,
      "z": 2,
      "name": "Rock_Aqua_Cobble"
    },
    {
      "x": -18,
      "y": 34,
      "z": 2,
      "name": "Rock_Aqua_Cobble"
    },
    {
      "x": -18,
      "y": 35,
      "z": 2,
      "name": "Rock_Aqua_Brick"
    },
    {
      "x": -18,
      "y": 36,
      "z": 2,
      "name": "Rock_Aqua_Cobble"
    },
    {
      "x": -18,
      "y": 37,
      "z": 2,
      "name": "Plant_Coral_Bush_Blue"
    },
    {
      "x": -18,
      "y": 28,
      "z": 3,
      "name": "Rock_Aqua_Brick_Smooth"
    },
    {
      "x": -18,
      "y": 29,
      "z": 3,
      "name": "Rock_Aqua_Brick_Smooth"
    },
    {
      "x": -18,
      "y": 30,
      "z": 3,
      "name": "Rock_Aqua_Brick_Smooth"
    },
    {
      "x": -18,
      "y": 31,
      "z": 3,
      "name": "Rock_Aqua_Brick"
    },
    {
      "x": -18,
      "y": 32,
      "z": 3,
      "name": "Rock_Aqua_Brick"
    },
    {
      "x": -18,
      "y": 33,
      "z": 3,
      "name": "Rock_Aqua_Cobble"
    },
    {
      "x": -18,
      "y": 34,
      "z": 3,
      "name": "Rock_Aqua_Brick"
    },
    {
      "x": -18,
      "y": 35,
      "z": 3,
      "name": "Rock_Aqua_Cobble"
    },
    {
      "x": -18,
      "y": 36,
      "z": 3,
      "name": "Rock_Aqua_Brick"
    },
    {
      "x": -18,
      "y": 27,
      "z": 4,
      "name": "Rock_Crystal_Cyan_Large",
      "rotation": 8
    },
    {
      "x": -18,
      "y": 28,
      "z": 4,
      "name": "Rock_Aqua_Brick_Smooth"
    },
    {
      "x": -18,
      "y": 29,
      "z": 4,
      "name": "Rock_Aqua_Brick_Smooth"
    },
    {
      "x": -18,
      "y": 30,
      "z": 4,
      "name": "Rock_Aqua_Brick_Smooth"
    },
    {
      "x": -18,
      "y": 31,
      "z": 4,
      "name": "Rock_Aqua_Brick"
    },
    {
      "x": -18,
      "y": 32,
      "z": 4,
      "name": "Rock_Aqua_Brick"
    },
    {
      "x": -18,
      "y": 33,
      "z": 4,
      "name": "Rock_Aqua_Brick"
    },
    {
      "x": -18,
      "y": 34,
      "z": 4,
      "name": "Rock_Aqua_Cobble"
    },
    {
      "x": -18,
      "y": 35,
      "z": 4,
      "name": "Rock_Aqua_Brick"
    },
    {
      "x": -18,
      "y": 36,
      "z": 4,
      "name": "Rock_Aqua_Brick"
    },
    {
      "x": -18,
      "y": 37,
      "z": 4,
      "name": "Plant_Crop_Mushroom_Glowing_Blue"
    },
    {
      "x": -18,
      "y": 28,
      "z": 5,
      "name": "Rock_Aqua_Brick_Smooth"
    },
    {
      "x": -18,
      "y": 29,
      "z": 5,
      "name": "Rock_Aqua_Brick_Smooth"
    },
    {
      "x": -18,
      "y": 30,
      "z": 5,
      "name": "Rock_Aqua_Brick_Smooth"
    },
    {
      "x": -18,
      "y": 31,
      "z": 5,
      "name": "Rock_Aqua_Brick"
    },
    {
      "x": -18,
      "y": 32,
      "z": 5,
      "name": "Rock_Aqua_Cobble"
    },
    {
      "x": -18,
      "y": 33,
      "z": 5,
      "name": "Plant_Coral_Bush_Blue"
    },
    {
      "x": -18,
      "y": 28,
      "z": 6,
      "name": "Rock_Aqua_Brick_Smooth"
    },
    {
      "x": -18,
      "y": 29,
      "z": 6,
      "name": "Rock_Aqua_Brick_Smooth"
    },
    {
      "x": -18,
      "y": 30,
      "z": 6,
      "name": "Rock_Aqua_Brick_Smooth"
    },
    {
      "x": -18,
      "y": 31,
      "z": 6,
      "name": "Rock_Aqua_Brick"
    },
    {
      "x": -18,
      "y": 32,
      "z": 6,
      "name": "Rock_Aqua_Cobble"
    },
    {
      "x": -18,
      "y": 33,
      "z": 6,
      "name": "Rock_Aqua_Brick"
    },
    {
      "x": -18,
      "y": 34,
      "z": 6,
      "name": "Rock_Aqua_Cobble"
    },
    {
      "x": -18,
      "y": 35,
      "z": 6,
      "name": "Rock_Aqua_Cobble"
    },
    {
      "x": -18,
      "y": 36,
      "z": 6,
      "name": "Rock_Aqua_Brick"
    },
    {
      "x": -18,
      "y": 29,
      "z": 7,
      "name": "Rock_Aqua_Brick_Smooth"
    },
    {
      "x": -18,
      "y": 30,
      "z": 7,
      "name": "Rock_Aqua_Brick_Smooth"
    },
    {
      "x": -18,
      "y": 31,
      "z": 7,
      "name": "Rock_Aqua_Cobble"
    },
    {
      "x": -18,
      "y": 32,
      "z": 7,
      "name": "Rock_Aqua_Cobble"
    },
    {
      "x": -18,
      "y": 33,
      "z": 7,
      "name": "Rock_Aqua_Cobble"
    },
    {
      "x": -18,
      "y": 34,
      "z": 7,
      "name": "Rock_Aqua_Brick"
    },
    {
      "x": -18,
      "y": 35,
      "z": 7,
      "name": "Rock_Aqua_Brick"
    },
    {
      "x": -18,
      "y": 36,
      "z": 7,
      "name": "Rock_Aqua_Cobble"
    },
    {
      "x": -18,
      "y": 37,
      "z": 7,
      "name": "Plant_Crop_Mushroom_Glowing_Blue"
    },
    {
      "x": -18,
      "y": 30,
      "z": 8,
      "name": "Rock_Aqua_Brick_Smooth"
    },
    {
      "x": -18,
      "y": 31,
      "z": 9,
      "name": "Rock_Aqua_Brick_Smooth"
    },
    {
      "x": -18,
      "y": 32,
      "z": 9,
      "name": "Rock_Aqua_Cobble"
    },
    {
      "x": -18,
      "y": 34,
      "z": 9,
      "name": "Rock_Aqua_Cobble"
    },
    {
      "x": -18,
      "y": 33,
      "z": 10,
      "name": "Rock_Aqua_Cobble"
    },
    {
      "x": -18,
      "y": 34,
      "z": 10,
      "name": "Plant_Crop_Mushroom_Glowing_Blue"
    },
    {
      "x": -18,
      "y": 25,
      "z": 11,
      "name": "Rock_Aqua_Brick_Smooth"
    },
    {
      "x": -18,
      "y": 26,
      "z": 11,
      "name": "Rock_Aqua"
    },
    {
      "x": -18,
      "y": 27,
      "z": 11,
      "name": "Rock_Aqua"
    },
    {
      "x": -18,
      "y": 24,
      "z": 12,
      "name": "Rock_Aqua"
    },
    {
      "x": -18,
      "y": 25,
      "z": 12,
      "name": "Rock_Aqua"
    },
    {
      "x": -18,
      "y": 26,
      "z": 12,
      "name": "Rock_Aqua"
    },
    {
      "x": -18,
      "y": 27,
      "z": 12,
      "name": "Rock_Aqua"
    },
    {
      "x": -18,
      "y": 28,
      "z": 12,
      "name": "Rock_Aqua"
    },
    {
      "x": -18,
      "y": 24,
      "z": 13,
      "name": "Rock_Aqua"
    },
    {
      "x": -18,
      "y": 25,
      "z": 13,
      "name": "Rock_Aqua_Brick_Smooth"
    },
    {
      "x": -18,
      "y": 26,
      "z": 13,
      "name": "Rock_Aqua_Brick_Smooth"
    },
    {
      "x": -18,
      "y": 27,
      "z": 13,
      "name": "Rock_Aqua_Brick_Smooth"
    },
    {
      "x": -18,
      "y": 28,
      "z": 13,
      "name": "Rock_Aqua_Brick_Smooth"
    },
    {
      "x": -18,
      "y": 24,
      "z": 14,
      "name": "Rock_Aqua_Brick_Smooth"
    },
    {
      "x": -18,
      "y": 25,
      "z": 14,
      "name": "Rock_Aqua_Brick_Smooth"
    },
    {
      "x": -18,
      "y": 26,
      "z": 14,
      "name": "Rock_Aqua_Brick_Smooth"
    },
    {
      "x": -18,
      "y": 27,
      "z": 14,
      "name": "Rock_Aqua_Brick_Smooth"
    },
    {
      "x": -18,
      "y": 28,
      "z": 14,
      "name": "Rock_Aqua_Brick_Smooth"
    },
    {
      "x": -18,
      "y": 24,
      "z": 15,
      "name": "Rock_Aqua_Brick_Smooth"
    },
    {
      "x": -18,
      "y": 25,
      "z": 15,
      "name": "Rock_Aqua_Brick_Smooth"
    },
    {
      "x": -18,
      "y": 26,
      "z": 15,
      "name": "Rock_Aqua_Brick_Smooth"
    },
    {
      "x": -18,
      "y": 27,
      "z": 15,
      "name": "Rock_Aqua"
    },
    {
      "x": -18,
      "y": 28,
      "z": 15,
      "name": "Rock_Aqua_Brick_Smooth"
    },
    {
      "x": -18,
      "y": 29,
      "z": 15,
      "name": "Plant_Crop_Mushroom_Glowing_Blue"
    },
    {
      "x": -18,
      "y": 24,
      "z": 16,
      "name": "Rock_Aqua_Brick_Smooth"
    },
    {
      "x": -18,
      "y": 25,
      "z": 16,
      "name": "Rock_Aqua_Brick_Smooth"
    },
    {
      "x": -18,
      "y": 26,
      "z": 16,
      "name": "Rock_Aqua_Brick_Smooth"
    },
    {
      "x": -18,
      "y": 27,
      "z": 16,
      "name": "Rock_Aqua_Brick_Smooth"
    },
    {
      "x": -18,
      "y": 28,
      "z": 16,
      "name": "Rock_Aqua"
    },
    {
      "x": -18,
      "y": 25,
      "z": 17,
      "name": "Rock_Aqua"
    },
    {
      "x": -18,
      "y": 26,
      "z": 17,
      "name": "Rock_Aqua"
    },
    {
      "x": -18,
      "y": 27,
      "z": 17,
      "name": "Rock_Aqua"
    },
    {
      "x": -18,
      "y": 25,
      "z": 18,
      "name": "Rock_Aqua"
    },
    {
      "x": -18,
      "y": 26,
      "z": 18,
      "name": "Rock_Aqua"
    },
    {
      "x": -18,
      "y": 27,
      "z": 18,
      "name": "Rock_Aqua"
    },
    {
      "x": -17,
      "y": 29,
      "z": -16,
      "name": "Rock_Aqua_Cobble"
    },
    {
      "x": -17,
      "y": 30,
      "z": -16,
      "name": "Plant_Coral_Bush_Blue"
    },
    {
      "x": -17,
      "y": 27,
      "z": -15,
      "name": "Rock_Aqua_Brick"
    },
    {
      "x": -17,
      "y": 28,
      "z": -15,
      "name": "Rock_Aqua_Brick"
    },
    {
      "x": -17,
      "y": 29,
      "z": -15,
      "name": "Rock_Aqua_Cobble"
    },
    {
      "x": -17,
      "y": 30,
      "z": -15,
      "name": "Rock_Aqua_Brick"
    },
    {
      "x": -17,
      "y": 27,
      "z": -14,
      "name": "Rock_Aqua_Brick"
    },
    {
      "x": -17,
      "y": 28,
      "z": -14,
      "name": "Rock_Aqua_Cobble"
    },
    {
      "x": -17,
      "y": 29,
      "z": -14,
      "name": "Rock_Aqua_Cobble"
    },
    {
      "x": -17,
      "y": 30,
      "z": -14,
      "name": "Rock_Aqua_Cobble"
    },
    {
      "x": -17,
      "y": 31,
      "z": -14,
      "name": "Rock_Aqua_Cobble"
    },
    {
      "x": -17,
      "y": 32,
      "z": -14,
      "name": "Plant_Coral_Model_Blue"
    },
    {
      "x": -17,
      "y": 26,
      "z": -13,
      "name": "Rock_Aqua_Brick_Smooth"
    },
    {
      "x": -17,
      "y": 27,
      "z": -13,
      "name": "Rock_Aqua_Cobble"
    },
    {
      "x": -17,
      "y": 28,
      "z": -13,
      "name": "Rock_Aqua_Cobble"
    },
    {
      "x": -17,
      "y": 29,
      "z": -13,
      "name": "Rock_Aqua_Cobble"
    },
    {
      "x": -17,
      "y": 30,
      "z": -13,
      "name": "Rock_Aqua_Brick"
    },
    {
      "x": -17,
      "y": 31,
      "z": -13,
      "name": "Rock_Aqua_Brick"
    },
    {
      "x": -17,
      "y": 26,
      "z": -12,
      "name": "Rock_Aqua_Brick_Smooth"
    },
    {
      "x": -17,
      "y": 27,
      "z": -12,
      "name": "Rock_Aqua_Brick"
    },
    {
      "x": -17,
      "y": 28,
      "z": -12,
      "name": "Rock_Aqua_Cobble"
    },
    {
      "x": -17,
      "y": 29,
      "z": -12,
      "name": "Rock_Aqua_Cobble"
    },
    {
      "x": -17,
      "y": 30,
      "z": -12,
      "name": "Rock_Aqua_Brick"
    },
    {
      "x": -17,
      "y": 31,
      "z": -12,
      "name": "Rock_Aqua_Brick"
    },
    {
      "x": -17,
      "y": 27,
      "z": -11,
      "name": "Rock_Crystal_Cyan_Large",
      "rotation": 8
    },
    {
      "x": -17,
      "y": 28,
      "z": -11,
      "name": "Rock_Aqua_Cobble"
    },
    {
      "x": -17,
      "y": 29,
      "z": -11,
      "name": "Plant_Coral_Model_Blue"
    },
    {
      "x": -17,
      "y": 29,
      "z": -10,
      "name": "Rock_Aqua_Brick"
    },
    {
      "x": -17,
      "y": 30,
      "z": -10,
      "name": "Rock_Aqua_Cobble"
    },
    {
      "x": -17,
      "y": 31,
      "z": -10,
      "name": "Plant_Coral_Bush_Blue"
    },
    {
      "x": -17,
      "y": 32,
      "z": -1,
      "name": "Rock_Aqua_Brick_Smooth"
    },
    {
      "x": -17,
      "y": 33,
      "z": -1,
      "name": "Rock_Aqua_Cobble"
    },
    {
      "x": -17,
      "y": 34,
      "z": -1,
      "name": "Rock_Aqua_Brick"
    },
    {
      "x": -17,
      "y": 29,
      "z": 0,
      "name": "Rock_Aqua_Stalactite_Large",
      "filler": 31744,
      "rotation": 8
    },
    {
      "x": -17,
      "y": 30,
      "z": 0,
      "name": "Rock_Aqua_Stalactite_Large",
      "rotation": 8
    },
    {
      "x": -17,
      "y": 31,
      "z": 0,
      "name": "Rock_Aqua_Brick_Smooth"
    },
    {
      "x": -17,
      "y": 32,
      "z": 0,
      "name": "Rock_Aqua_Brick_Smooth"
    },
    {
      "x": -17,
      "y": 33,
      "z": 0,
      "name": "Rock_Aqua_Cobble"
    },
    {
      "x": -17,
      "y": 34,
      "z": 0,
      "name": "Rock_Aqua_Cobble"
    },
    {
      "x": -17,
      "y": 35,
      "z": 0,
      "name": "Rock_Aqua_Brick"
    },
    {
      "x": -17,
      "y": 36,
      "z": 0,
      "name": "Plant_Coral_Bush_Blue"
    },
    {
      "x": -17,
      "y": 29,
      "z": 1,
      "name": "Rock_Aqua_Brick_Smooth"
    },
    {
      "x": -17,
      "y": 30,
      "z": 1,
      "name": "Rock_Aqua_Brick_Smooth"
    },
    {
      "x": -17,
      "y": 31,
      "z": 1,
      "name": "Rock_Aqua_Brick_Smooth"
    },
    {
      "x": -17,
      "y": 32,
      "z": 1,
      "name": "Rock_Aqua_Brick_Smooth"
    },
    {
      "x": -17,
      "y": 33,
      "z": 1,
      "name": "Rock_Aqua_Cobble"
    },
    {
      "x": -17,
      "y": 34,
      "z": 1,
      "name": "Rock_Aqua_Brick"
    },
    {
      "x": -17,
      "y": 35,
      "z": 1,
      "name": "Rock_Aqua_Cobble"
    },
    {
      "x": -17,
      "y": 36,
      "z": 1,
      "name": "Rock_Aqua_Cobble"
    },
    {
      "x": -17,
      "y": 29,
      "z": 2,
      "name": "Rock_Aqua_Brick_Smooth"
    },
    {
      "x": -17,
      "y": 30,
      "z": 2,
      "name": "Rock_Aqua_Brick_Smooth"
    },
    {
      "x": -17,
      "y": 31,
      "z": 2,
      "name": "Rock_Aqua_Brick_Smooth"
    },
    {
      "x": -17,
      "y": 32,
      "z": 2,
      "name": "Rock_Aqua_Brick_Smooth"
    },
    {
      "x": -17,
      "y": 33,
      "z": 2,
      "name": "Rock_Aqua_Cobble"
    },
    {
      "x": -17,
      "y": 34,
      "z": 2,
      "name": "Rock_Aqua_Cobble"
    },
    {
      "x": -17,
      "y": 35,
      "z": 2,
      "name": "Rock_Aqua_Brick"
    },
    {
      "x": -17,
      "y": 36,
      "z": 2,
      "name": "Rock_Aqua_Brick"
    },
    {
      "x": -17,
      "y": 28,
      "z": 3,
      "name": "Rock_Aqua_Brick_Smooth"
    },
    {
      "x": -17,
      "y": 29,
      "z": 3,
      "name": "Rock_Aqua_Brick_Smooth"
    },
    {
      "x": -17,
      "y": 30,
      "z": 3,
      "name": "Rock_Aqua_Brick_Smooth"
    },
    {
      "x": -17,
      "y": 31,
      "z": 3,
      "name": "Rock_Aqua_Brick_Smooth"
    },
    {
      "x": -17,
      "y": 32,
      "z": 3,
      "name": "Rock_Aqua_Brick_Smooth"
    },
    {
      "x": -17,
      "y": 33,
      "z": 3,
      "name": "Rock_Aqua_Cobble"
    },
    {
      "x": -17,
      "y": 34,
      "z": 3,
      "name": "Rock_Aqua_Cobble"
    },
    {
      "x": -17,
      "y": 35,
      "z": 3,
      "name": "Rock_Aqua_Cobble"
    },
    {
      "x": -17,
      "y": 36,
      "z": 3,
      "name": "Rock_Aqua_Brick"
    },
    {
      "x": -17,
      "y": 28,
      "z": 4,
      "name": "Rock_Aqua_Brick_Smooth"
    },
    {
      "x": -17,
      "y": 29,
      "z": 4,
      "name": "Rock_Aqua_Brick_Smooth"
    },
    {
      "x": -17,
      "y": 30,
      "z": 4,
      "name": "Rock_Aqua_Brick_Smooth"
    },
    {
      "x": -17,
      "y": 31,
      "z": 4,
      "name": "Rock_Aqua_Brick"
    },
    {
      "x": -17,
      "y": 32,
      "z": 4,
      "name": "Rock_Aqua_Brick"
    },
    {
      "x": -17,
      "y": 33,
      "z": 4,
      "name": "Rock_Aqua_Cobble"
    },
    {
      "x": -17,
      "y": 34,
      "z": 4,
      "name": "Rock_Aqua_Brick"
    },
    {
      "x": -17,
      "y": 35,
      "z": 4,
      "name": "Rock_Aqua_Cobble"
    },
    {
      "x": -17,
      "y": 36,
      "z": 4,
      "name": "Rock_Aqua_Brick"
    },
    {
      "x": -17,
      "y": 28,
      "z": 5,
      "name": "Rock_Aqua_Brick_Smooth"
    },
    {
      "x": -17,
      "y": 29,
      "z": 5,
      "name": "Rock_Aqua_Brick_Smooth"
    },
    {
      "x": -17,
      "y": 30,
      "z": 5,
      "name": "Rock_Aqua_Brick_Smooth"
    },
    {
      "x": -17,
      "y": 31,
      "z": 5,
      "name": "Rock_Aqua_Cobble"
    },
    {
      "x": -17,
      "y": 32,
      "z": 5,
      "name": "Rock_Aqua_Cobble"
    },
    {
      "x": -17,
      "y": 35,
      "z": 5,
      "name": "Rock_Aqua_Cobble"
    },
    {
      "x": -17,
      "y": 28,
      "z": 6,
      "name": "Rock_Aqua_Brick_Smooth"
    },
    {
      "x": -17,
      "y": 29,
      "z": 6,
      "name": "Rock_Aqua_Brick_Smooth"
    },
    {
      "x": -17,
      "y": 30,
      "z": 6,
      "name": "Rock_Aqua_Brick_Smooth"
    },
    {
      "x": -17,
      "y": 31,
      "z": 6,
      "name": "Rock_Aqua_Brick"
    },
    {
      "x": -17,
      "y": 32,
      "z": 6,
      "name": "Rock_Aqua_Cobble"
    },
    {
      "x": -17,
      "y": 33,
      "z": 6,
      "name": "Rock_Aqua_Brick"
    },
    {
      "x": -17,
      "y": 34,
      "z": 6,
      "name": "Rock_Aqua_Cobble"
    },
    {
      "x": -17,
      "y": 35,
      "z": 6,
      "name": "Rock_Aqua_Brick"
    },
    {
      "x": -17,
      "y": 36,
      "z": 6,
      "name": "Rock_Aqua_Cobble"
    },
    {
      "x": -17,
      "y": 28,
      "z": 7,
      "name": "Rock_Aqua_Stalactite_Small",
      "rotation": 8
    },
    {
      "x": -17,
      "y": 29,
      "z": 7,
      "name": "Rock_Aqua_Brick_Smooth"
    },
    {
      "x": -17,
      "y": 30,
      "z": 7,
      "name": "Rock_Aqua_Brick_Smooth"
    },
    {
      "x": -17,
      "y": 31,
      "z": 7,
      "name": "Rock_Aqua_Brick_Smooth"
    },
    {
      "x": -17,
      "y": 32,
      "z": 7,
      "name": "Rock_Aqua_Cobble"
    },
    {
      "x": -17,
      "y": 33,
      "z": 7,
      "name": "Plant_Coral_Bush_Blue"
    },
    {
      "x": -17,
      "y": 30,
      "z": 8,
      "name": "Rock_Aqua_Brick_Smooth"
    },
    {
      "x": -17,
      "y": 32,
      "z": 8,
      "name": "Rock_Aqua_Brick"
    },
    {
      "x": -17,
      "y": 31,
      "z": 9,
      "name": "Rock_Aqua_Brick_Smooth"
    },
    {
      "x": -17,
      "y": 32,
      "z": 9,
      "name": "Rock_Aqua_Cobble"
    },
    {
      "x": -17,
      "y": 34,
      "z": 9,
      "name": "Rock_Aqua_Brick"
    },
    {
      "x": -17,
      "y": 26,
      "z": 10,
      "name": "Rock_Aqua"
    },
    {
      "x": -17,
      "y": 31,
      "z": 10,
      "name": "Rock_Aqua_Stalactite_Large",
      "filler": 31744,
      "rotation": 8
    },
    {
      "x": -17,
      "y": 32,
      "z": 10,
      "name": "Rock_Aqua_Stalactite_Large",
      "rotation": 8
    },
    {
      "x": -17,
      "y": 33,
      "z": 10,
      "name": "Rock_Aqua_Brick"
    },
    {
      "x": -17,
      "y": 34,
      "z": 10,
      "name": "Plant_Coral_Model_Blue"
    },
    {
      "x": -17,
      "y": 24,
      "z": 11,
      "name": "Rock_Aqua"
    },
    {
      "x": -17,
      "y": 25,
      "z": 11,
      "name": "Rock_Aqua_Brick_Smooth"
    },
    {
      "x": -17,
      "y": 26,
      "z": 11,
      "name": "Rock_Aqua_Brick_Smooth"
    },
    {
      "x": -17,
      "y": 27,
      "z": 11,
      "name": "Rock_Aqua"
    },
    {
      "x": -17,
      "y": 28,
      "z": 11,
      "name": "Rock_Aqua_Brick_Smooth"
    },
    {
      "x": -17,
      "y": 24,
      "z": 12,
      "name": "Rock_Aqua"
    },
    {
      "x": -17,
      "y": 25,
      "z": 12,
      "name": "Rock_Aqua"
    },
    {
      "x": -17,
      "y": 26,
      "z": 12,
      "name": "Rock_Aqua_Brick_Smooth"
    },
    {
      "x": -17,
      "y": 27,
      "z": 12,
      "name": "Rock_Aqua_Brick_Smooth"
    },
    {
      "x": -17,
      "y": 28,
      "z": 12,
      "name": "Rock_Aqua"
    },
    {
      "x": -17,
      "y": 23,
      "z": 13,
      "name": "Rock_Aqua"
    },
    {
      "x": -17,
      "y": 24,
      "z": 13,
      "name": "Rock_Aqua_Brick_Smooth"
    },
    {
      "x": -17,
      "y": 25,
      "z": 13,
      "name": "Rock_Aqua_Brick_Smooth"
    },
    {
      "x": -17,
      "y": 26,
      "z": 13,
      "name": "Rock_Aqua_Brick_Smooth"
    },
    {
      "x": -17,
      "y": 27,
      "z": 13,
      "name": "Rock_Aqua_Brick_Smooth"
    },
    {
      "x": -17,
      "y": 28,
      "z": 13,
      "name": "Rock_Aqua"
    },
    {
      "x": -17,
      "y": 29,
      "z": 13,
      "name": "Rock_Aqua_Brick_Smooth"
    },
    {
      "x": -17,
      "y": 23,
      "z": 14,
      "name": "Rock_Aqua_Brick_Smooth"
    },
    {
      "x": -17,
      "y": 24,
      "z": 14,
      "name": "Rock_Aqua_Brick_Smooth"
    },
    {
      "x": -17,
      "y": 25,
      "z": 14,
      "name": "Rock_Aqua_Brick_Smooth"
    },
    {
      "x": -17,
      "y": 26,
      "z": 14,
      "name": "Rock_Aqua_Brick_Smooth"
    },
    {
      "x": -17,
      "y": 27,
      "z": 14,
      "name": "Rock_Aqua_Brick_Smooth"
    },
    {
      "x": -17,
      "y": 28,
      "z": 14,
      "name": "Rock_Aqua"
    },
    {
      "x": -17,
      "y": 29,
      "z": 14,
      "name": "Rock_Aqua"
    },
    {
      "x": -17,
      "y": 24,
      "z": 15,
      "name": "Rock_Aqua_Brick_Smooth"
    },
    {
      "x": -17,
      "y": 25,
      "z": 15,
      "name": "Rock_Aqua_Brick_Smooth"
    },
    {
      "x": -17,
      "y": 26,
      "z": 15,
      "name": "Rock_Aqua_Brick_Smooth"
    },
    {
      "x": -17,
      "y": 27,
      "z": 15,
      "name": "Rock_Aqua_Brick_Smooth"
    },
    {
      "x": -17,
      "y": 28,
      "z": 15,
      "name": "Rock_Aqua_Brick_Smooth"
    },
    {
      "x": -17,
      "y": 24,
      "z": 16,
      "name": "Rock_Aqua"
    },
    {
      "x": -17,
      "y": 25,
      "z": 16,
      "name": "Rock_Aqua_Brick_Smooth"
    },
    {
      "x": -17,
      "y": 26,
      "z": 16,
      "name": "Rock_Aqua_Brick_Smooth"
    },
    {
      "x": -17,
      "y": 27,
      "z": 16,
      "name": "Rock_Aqua_Brick_Smooth"
    },
    {
      "x": -17,
      "y": 28,
      "z": 16,
      "name": "Rock_Aqua"
    },
    {
      "x": -17,
      "y": 24,
      "z": 17,
      "name": "Rock_Aqua"
    },
    {
      "x": -17,
      "y": 25,
      "z": 17,
      "name": "Rock_Aqua_Brick_Smooth"
    },
    {
      "x": -17,
      "y": 26,
      "z": 17,
      "name": "Rock_Aqua_Brick_Smooth"
    },
    {
      "x": -17,
      "y": 27,
      "z": 17,
      "name": "Rock_Aqua_Brick_Smooth"
    },
    {
      "x": -17,
      "y": 28,
      "z": 17,
      "name": "Rock_Aqua"
    },
    {
      "x": -17,
      "y": 25,
      "z": 18,
      "name": "Rock_Aqua_Brick_Smooth"
    },
    {
      "x": -17,
      "y": 26,
      "z": 18,
      "name": "Rock_Aqua_Brick_Smooth"
    },
    {
      "x": -17,
      "y": 27,
      "z": 18,
      "name": "Rock_Aqua"
    },
    {
      "x": -17,
      "y": 26,
      "z": 19,
      "name": "Rock_Aqua_Brick_Smooth"
    },
    {
      "x": -16,
      "y": 28,
      "z": -16,
      "name": "Rock_Crystal_Cyan_Large",
      "rotation": 8
    },
    {
      "x": -16,
      "y": 29,
      "z": -16,
      "name": "Rock_Aqua_Brick"
    },
    {
      "x": -16,
      "y": 27,
      "z": -15,
      "name": "Rock_Aqua_Cobble"
    },
    {
      "x": -16,
      "y": 28,
      "z": -15,
      "name": "Rock_Aqua_Cobble"
    },
    {
      "x": -16,
      "y": 29,
      "z": -15,
      "name": "Rock_Aqua_Cobble"
    },
    {
      "x": -16,
      "y": 30,
      "z": -15,
      "name": "Rock_Aqua_Cobble"
    },
    {
      "x": -16,
      "y": 31,
      "z": -15,
      "name": "Plant_Coral_Bush_Cyan"
    },
    {
      "x": -16,
      "y": 26,
      "z": -14,
      "name": "Rock_Aqua_Brick_Smooth"
    },
    {
      "x": -16,
      "y": 27,
      "z": -14,
      "name": "Rock_Aqua_Brick"
    },
    {
      "x": -16,
      "y": 28,
      "z": -14,
      "name": "Rock_Aqua_Cobble"
    },
    {
      "x": -16,
      "y": 29,
      "z": -14,
      "name": "Rock_Aqua_Brick"
    },
    {
      "x": -16,
      "y": 30,
      "z": -14,
      "name": "Rock_Aqua_Cobble"
    },
    {
      "x": -16,
      "y": 31,
      "z": -14,
      "name": "Rock_Aqua_Cobble"
    },
    {
      "x": -16,
      "y": 26,
      "z": -13,
      "name": "Rock_Aqua_Brick_Smooth"
    },
    {
      "x": -16,
      "y": 27,
      "z": -13,
      "name": "Rock_Aqua_Cobble"
    },
    {
      "x": -16,
      "y": 28,
      "z": -13,
      "name": "Rock_Aqua_Cobble"
    },
    {
      "x": -16,
      "y": 29,
      "z": -13,
      "name": "Rock_Aqua_Cobble"
    },
    {
      "x": -16,
      "y": 30,
      "z": -13,
      "name": "Rock_Aqua_Cobble"
    },
    {
      "x": -16,
      "y": 31,
      "z": -13,
      "name": "Rock_Aqua_Cobble"
    },
    {
      "x": -16,
      "y": 32,
      "z": -13,
      "name": "Plant_Coral_Bush_Cyan"
    },
    {
      "x": -16,
      "y": 26,
      "z": -12,
      "name": "Rock_Aqua_Brick_Smooth"
    },
    {
      "x": -16,
      "y": 27,
      "z": -12,
      "name": "Rock_Aqua_Brick"
    },
    {
      "x": -16,
      "y": 28,
      "z": -12,
      "name": "Rock_Aqua_Cobble"
    },
    {
      "x": -16,
      "y": 29,
      "z": -12,
      "name": "Rock_Aqua_Brick"
    },
    {
      "x": -16,
      "y": 30,
      "z": -12,
      "name": "Rock_Aqua_Cobble"
    },
    {
      "x": -16,
      "y": 31,
      "z": -12,
      "name": "Rock_Aqua_Brick"
    },
    {
      "x": -16,
      "y": 29,
      "z": -11,
      "name": "Rock_Aqua_Cobble"
    },
    {
      "x": -16,
      "y": 31,
      "z": -11,
      "name": "Rock_Aqua_Cobble"
    },
    {
      "x": -16,
      "y": 27,
      "z": -10,
      "name": "Rock_Aqua_Brick_Smooth"
    },
    {
      "x": -16,
      "y": 28,
      "z": -10,
      "name": "Rock_Aqua_Brick"
    },
    {
      "x": -16,
      "y": 29,
      "z": -10,
      "name": "Rock_Aqua_Cobble"
    },
    {
      "x": -16,
      "y": 30,
      "z": -10,
      "name": "Rock_Aqua_Cobble"
    },
    {
      "x": -16,
      "y": 29,
      "z": -9,
      "name": "Rock_Aqua_Cobble"
    },
    {
      "x": -16,
      "y": 0,
      "z": -6,
      "name": "Rock_Aqua"
    },
    {
      "x": -16,
      "y": 1,
      "z": -6,
      "name": "Rock_Aqua"
    },
    {
      "x": -16,
      "y": 2,
      "z": -6,
      "name": "Rock_Aqua"
    },
    {
      "x": -16,
      "y": 3,
      "z": -6,
      "name": "Rock_Aqua"
    },
    {
      "x": -16,
      "y": 4,
      "z": -6,
      "name": "Rock_Aqua_Brick_Pillar_Base"
    },
    {
      "x": -16,
      "y": 5,
      "z": -6,
      "name": "Rock_Aqua_Brick_Pillar_Middle"
    },
    {
      "x": -16,
      "y": 6,
      "z": -6,
      "name": "Rock_Aqua_Brick_Pillar_Base",
      "rotation": 8
    },
    {
      "x": -16,
      "y": 0,
      "z": -5,
      "name": "Rock_Aqua"
    },
    {
      "x": -16,
      "y": 1,
      "z": -5,
      "name": "Rock_Aqua"
    },
    {
      "x": -16,
      "y": 2,
      "z": -5,
      "name": "Rock_Aqua"
    },
    {
      "x": -16,
      "y": 3,
      "z": -5,
      "name": "Rock_Aqua_Brick_Stairs",
      "rotation": 3
    },
    {
      "x": -16,
      "y": 0,
      "z": -4,
      "name": "Rock_Aqua"
    },
    {
      "x": -16,
      "y": 1,
      "z": -4,
      "name": "Rock_Aqua"
    },
    {
      "x": -16,
      "y": 2,
      "z": -4,
      "name": "Rock_Aqua"
    },
    {
      "x": -16,
      "y": 3,
      "z": -4,
      "name": "Rock_Aqua_Brick_Stairs",
      "rotation": 3
    },
    {
      "x": -16,
      "y": 0,
      "z": -3,
      "name": "Rock_Aqua"
    },
    {
      "x": -16,
      "y": 1,
      "z": -3,
      "name": "Rock_Aqua"
    },
    {
      "x": -16,
      "y": 2,
      "z": -3,
      "name": "Rock_Aqua"
    },
    {
      "x": -16,
      "y": 3,
      "z": -3,
      "name": "Rock_Aqua_Brick_Stairs",
      "rotation": 3
    },
    {
      "x": -16,
      "y": 0,
      "z": -2,
      "name": "Rock_Aqua"
    },
    {
      "x": -16,
      "y": 1,
      "z": -2,
      "name": "Rock_Aqua"
    },
    {
      "x": -16,
      "y": 2,
      "z": -2,
      "name": "Rock_Aqua"
    },
    {
      "x": -16,
      "y": 3,
      "z": -2,
      "name": "Rock_Aqua"
    },
    {
      "x": -16,
      "y": 4,
      "z": -2,
      "name": "Rock_Aqua_Brick_Pillar_Base"
    },
    {
      "x": -16,
      "y": 5,
      "z": -2,
      "name": "Rock_Aqua_Brick_Pillar_Middle"
    },
    {
      "x": -16,
      "y": 6,
      "z": -2,
      "name": "Rock_Aqua_Brick_Pillar_Base",
      "rotation": 8
    },
    {
      "x": -16,
      "y": 31,
      "z": 0,
      "name": "Rock_Aqua_Brick_Smooth"
    },
    {
      "x": -16,
      "y": 32,
      "z": 0,
      "name": "Rock_Aqua_Brick_Smooth"
    },
    {
      "x": -16,
      "y": 33,
      "z": 0,
      "name": "Rock_Aqua_Cobble"
    },
    {
      "x": -16,
      "y": 34,
      "z": 0,
      "name": "Rock_Aqua_Brick"
    },
    {
      "x": -16,
      "y": 35,
      "z": 0,
      "name": "Rock_Aqua_Cobble"
    },
    {
      "x": -16,
      "y": 30,
      "z": 1,
      "name": "Rock_Aqua_Brick_Smooth"
    },
    {
      "x": -16,
      "y": 31,
      "z": 1,
      "name": "Rock_Aqua_Brick_Smooth"
    },
    {
      "x": -16,
      "y": 32,
      "z": 1,
      "name": "Rock_Aqua_Brick_Smooth"
    },
    {
      "x": -16,
      "y": 33,
      "z": 1,
      "name": "Rock_Aqua_Cobble"
    },
    {
      "x": -16,
      "y": 34,
      "z": 1,
      "name": "Rock_Aqua_Cobble"
    },
    {
      "x": -16,
      "y": 35,
      "z": 1,
      "name": "Rock_Aqua_Cobble"
    },
    {
      "x": -16,
      "y": 36,
      "z": 1,
      "name": "Plant_Coral_Bush_Cyan"
    },
    {
      "x": -16,
      "y": 28,
      "z": 2,
      "name": "Rock_Aqua_Stalactite_Small",
      "rotation": 8
    },
    {
      "x": -16,
      "y": 29,
      "z": 2,
      "name": "Rock_Aqua_Brick_Smooth"
    },
    {
      "x": -16,
      "y": 30,
      "z": 2,
      "name": "Rock_Aqua_Brick_Smooth"
    },
    {
      "x": -16,
      "y": 31,
      "z": 2,
      "name": "Rock_Aqua_Brick_Smooth"
    },
    {
      "x": -16,
      "y": 32,
      "z": 2,
      "name": "Rock_Aqua_Brick_Smooth"
    },
    {
      "x": -16,
      "y": 33,
      "z": 2,
      "name": "Rock_Aqua_Cobble"
    },
    {
      "x": -16,
      "y": 34,
      "z": 2,
      "name": "Rock_Aqua_Cobble"
    },
    {
      "x": -16,
      "y": 35,
      "z": 2,
      "name": "Rock_Aqua_Cobble"
    },
    {
      "x": -16,
      "y": 36,
      "z": 2,
      "name": "Rock_Aqua_Cobble"
    },
    {
      "x": -16,
      "y": 29,
      "z": 3,
      "name": "Rock_Aqua_Brick_Smooth"
    },
    {
      "x": -16,
      "y": 30,
      "z": 3,
      "name": "Rock_Aqua_Brick_Smooth"
    },
    {
      "x": -16,
      "y": 31,
      "z": 3,
      "name": "Rock_Aqua_Brick_Smooth"
    },
    {
      "x": -16,
      "y": 32,
      "z": 3,
      "name": "Rock_Aqua_Brick_Smooth"
    },
    {
      "x": -16,
      "y": 33,
      "z": 3,
      "name": "Rock_Aqua_Cobble"
    },
    {
      "x": -16,
      "y": 34,
      "z": 3,
      "name": "Rock_Aqua_Cobble"
    },
    {
      "x": -16,
      "y": 35,
      "z": 3,
      "name": "Rock_Aqua_Brick"
    },
    {
      "x": -16,
      "y": 36,
      "z": 3,
      "name": "Rock_Aqua_Brick"
    },
    {
      "x": -16,
      "y": 29,
      "z": 4,
      "name": "Rock_Aqua_Brick_Smooth"
    },
    {
      "x": -16,
      "y": 30,
      "z": 4,
      "name": "Rock_Aqua_Brick_Smooth"
    },
    {
      "x": -16,
      "y": 31,
      "z": 4,
      "name": "Rock_Aqua_Brick_Smooth"
    },
    {
      "x": -16,
      "y": 32,
      "z": 4,
      "name": "Rock_Aqua_Brick_Smooth"
    },
    {
      "x": -16,
      "y": 29,
      "z": 5,
      "name": "Rock_Aqua_Brick_Smooth"
    },
    {
      "x": -16,
      "y": 30,
      "z": 5,
      "name": "Rock_Aqua_Brick_Smooth"
    },
    {
      "x": -16,
      "y": 31,
      "z": 5,
      "name": "Rock_Aqua_Brick_Smooth"
    },
    {
      "x": -16,
      "y": 32,
      "z": 5,
      "name": "Rock_Aqua_Cobble"
    },
    {
      "x": -16,
      "y": 36,
      "z": 5,
      "name": "Rock_Aqua_Cobble"
    },
    {
      "x": -16,
      "y": 37,
      "z": 5,
      "name": "Plant_Coral_Model_Cyan"
    },
    {
      "x": -16,
      "y": 28,
      "z": 6,
      "name": "Rock_Crystal_Cyan_Large",
      "rotation": 8
    },
    {
      "x": -16,
      "y": 29,
      "z": 6,
      "name": "Rock_Aqua_Brick_Smooth"
    },
    {
      "x": -16,
      "y": 30,
      "z": 6,
      "name": "Rock_Aqua_Brick_Smooth"
    },
    {
      "x": -16,
      "y": 36,
      "z": 6,
      "name": "Rock_Aqua_Brick"
    },
    {
      "x": -16,
      "y": 37,
      "z": 6,
      "name": "Plant_Coral_Model_Blue"
    },
    {
      "x": -16,
      "y": 29,
      "z": 7,
      "name": "Rock_Aqua_Brick_Smooth"
    },
    {
      "x": -16,
      "y": 30,
      "z": 7,
      "name": "Rock_Aqua_Brick_Smooth"
    },
    {
      "x": -16,
      "y": 31,
      "z": 7,
      "name": "Rock_Aqua_Brick_Smooth"
    },
    {
      "x": -16,
      "y": 32,
      "z": 7,
      "name": "Rock_Aqua_Cobble"
    },
    {
      "x": -16,
      "y": 34,
      "z": 7,
      "name": "Rock_Aqua_Cobble"
    },
    {
      "x": -16,
      "y": 36,
      "z": 7,
      "name": "Rock_Aqua_Brick"
    },
    {
      "x": -16,
      "y": 30,
      "z": 8,
      "name": "Rock_Aqua_Brick_Smooth"
    },
    {
      "x": -16,
      "y": 31,
      "z": 8,
      "name": "Rock_Aqua_Brick_Smooth"
    },
    {
      "x": -16,
      "y": 32,
      "z": 8,
      "name": "Rock_Aqua_Brick"
    },
    {
      "x": -16,
      "y": 34,
      "z": 8,
      "name": "Rock_Aqua_Brick"
    },
    {
      "x": -16,
      "y": 35,
      "z": 8,
      "name": "Rock_Aqua_Cobble"
    },
    {
      "x": -16,
      "y": 36,
      "z": 8,
      "name": "Plant_Coral_Bush_Cyan"
    },
    {
      "x": -16,
      "y": 30,
      "z": 9,
      "name": "Rock_Crystal_Cyan_Large",
      "rotation": 8
    },
    {
      "x": -16,
      "y": 31,
      "z": 9,
      "name": "Rock_Aqua_Brick_Smooth"
    },
    {
      "x": -16,
      "y": 32,
      "z": 9,
      "name": "Rock_Aqua_Brick"
    },
    {
      "x": -16,
      "y": 33,
      "z": 9,
      "name": "Rock_Aqua_Brick"
    },
    {
      "x": -16,
      "y": 34,
      "z": 9,
      "name": "Rock_Aqua_Brick"
    },
    {
      "x": -16,
      "y": 25,
      "z": 10,
      "name": "Rock_Aqua_Brick_Smooth"
    },
    {
      "x": -16,
      "y": 26,
      "z": 10,
      "name": "Rock_Aqua_Brick_Smooth"
    },
    {
      "x": -16,
      "y": 27,
      "z": 10,
      "name": "Rock_Aqua"
    },
    {
      "x": -16,
      "y": 24,
      "z": 11,
      "name": "Rock_Aqua_Brick_Smooth"
    },
    {
      "x": -16,
      "y": 25,
      "z": 11,
      "name": "Rock_Aqua"
    },
    {
      "x": -16,
      "y": 26,
      "z": 11,
      "name": "Rock_Aqua_Brick_Smooth"
    },
    {
      "x": -16,
      "y": 27,
      "z": 11,
      "name": "Rock_Aqua"
    },
    {
      "x": -16,
      "y": 28,
      "z": 11,
      "name": "Rock_Aqua_Brick_Smooth"
    },
    {
      "x": -16,
      "y": 23,
      "z": 12,
      "name": "Rock_Aqua"
    },
    {
      "x": -16,
      "y": 24,
      "z": 12,
      "name": "Rock_Aqua"
    },
    {
      "x": -16,
      "y": 25,
      "z": 12,
      "name": "Rock_Aqua_Brick_Smooth"
    },
    {
      "x": -16,
      "y": 26,
      "z": 12,
      "name": "Rock_Aqua_Brick_Smooth"
    },
    {
      "x": -16,
      "y": 27,
      "z": 12,
      "name": "Rock_Aqua_Brick_Smooth"
    },
    {
      "x": -16,
      "y": 28,
      "z": 12,
      "name": "Rock_Aqua_Brick_Smooth"
    },
    {
      "x": -16,
      "y": 29,
      "z": 12,
      "name": "Rock_Aqua_Brick_Smooth"
    },
    {
      "x": -16,
      "y": 23,
      "z": 13,
      "name": "Rock_Aqua_Brick_Smooth"
    },
    {
      "x": -16,
      "y": 24,
      "z": 13,
      "name": "Rock_Aqua"
    },
    {
      "x": -16,
      "y": 25,
      "z": 13,
      "name": "Rock_Aqua_Brick_Smooth"
    },
    {
      "x": -16,
      "y": 26,
      "z": 13,
      "name": "Rock_Aqua_Brick_Smooth"
    },
    {
      "x": -16,
      "y": 27,
      "z": 13,
      "name": "Rock_Aqua_Brick_Smooth"
    },
    {
      "x": -16,
      "y": 28,
      "z": 13,
      "name": "Rock_Aqua_Brick_Smooth"
    },
    {
      "x": -16,
      "y": 29,
      "z": 13,
      "name": "Rock_Aqua"
    },
    {
      "x": -16,
      "y": 30,
      "z": 13,
      "name": "Plant_Crop_Mushroom_Glowing_Blue"
    },
    {
      "x": -16,
      "y": 23,
      "z": 14,
      "name": "Rock_Aqua"
    },
    {
      "x": -16,
      "y": 24,
      "z": 14,
      "name": "Rock_Aqua_Brick_Smooth"
    },
    {
      "x": -16,
      "y": 25,
      "z": 14,
      "name": "Rock_Aqua_Brick_Smooth"
    },
    {
      "x": -16,
      "y": 26,
      "z": 14,
      "name": "Rock_Aqua_Brick_Smooth"
    },
    {
      "x": -16,
      "y": 27,
      "z": 14,
      "name": "Rock_Aqua_Brick_Smooth"
    },
    {
      "x": -16,
      "y": 28,
      "z": 14,
      "name": "Rock_Aqua"
    },
    {
      "x": -16,
      "y": 29,
      "z": 14,
      "name": "Rock_Aqua"
    },
    {
      "x": -16,
      "y": 23,
      "z": 15,
      "name": "Rock_Aqua_Brick_Smooth"
    },
    {
      "x": -16,
      "y": 24,
      "z": 15,
      "name": "Rock_Aqua_Brick_Smooth"
    },
    {
      "x": -16,
      "y": 25,
      "z": 15,
      "name": "Rock_Aqua_Brick_Smooth"
    },
    {
      "x": -16,
      "y": 26,
      "z": 15,
      "name": "Rock_Aqua_Brick_Smooth"
    },
    {
      "x": -16,
      "y": 27,
      "z": 15,
      "name": "Rock_Aqua_Brick_Smooth"
    },
    {
      "x": -16,
      "y": 28,
      "z": 15,
      "name": "Rock_Aqua_Brick_Smooth"
    },
    {
      "x": -16,
      "y": 29,
      "z": 15,
      "name": "Rock_Aqua_Brick_Smooth"
    },
    {
      "x": -16,
      "y": 24,
      "z": 16,
      "name": "Rock_Aqua"
    },
    {
      "x": -16,
      "y": 25,
      "z": 16,
      "name": "Rock_Aqua_Brick_Smooth"
    },
    {
      "x": -16,
      "y": 26,
      "z": 16,
      "name": "Rock_Aqua_Brick_Smooth"
    },
    {
      "x": -16,
      "y": 27,
      "z": 16,
      "name": "Rock_Aqua_Brick_Smooth"
    },
    {
      "x": -16,
      "y": 28,
      "z": 16,
      "name": "Rock_Aqua_Brick_Smooth"
    },
    {
      "x": -16,
      "y": 24,
      "z": 17,
      "name": "Rock_Aqua_Brick_Smooth"
    },
    {
      "x": -16,
      "y": 25,
      "z": 17,
      "name": "Rock_Aqua_Brick_Smooth"
    },
    {
      "x": -16,
      "y": 26,
      "z": 17,
      "name": "Rock_Aqua_Brick_Smooth"
    },
    {
      "x": -16,
      "y": 27,
      "z": 17,
      "name": "Rock_Aqua_Brick_Smooth"
    },
    {
      "x": -16,
      "y": 28,
      "z": 17,
      "name": "Rock_Aqua"
    },
    {
      "x": -16,
      "y": 25,
      "z": 18,
      "name": "Rock_Aqua_Brick_Smooth"
    },
    {
      "x": -16,
      "y": 26,
      "z": 18,
      "name": "Rock_Aqua_Brick_Smooth"
    },
    {
      "x": -16,
      "y": 27,
      "z": 18,
      "name": "Rock_Aqua"
    },
    {
      "x": -15,
      "y": 28,
      "z": -15,
      "name": "Rock_Aqua_Cobble"
    },
    {
      "x": -15,
      "y": 29,
      "z": -15,
      "name": "Rock_Aqua_Brick"
    },
    {
      "x": -15,
      "y": 27,
      "z": -14,
      "name": "Rock_Aqua_Brick"
    },
    {
      "x": -15,
      "y": 28,
      "z": -14,
      "name": "Rock_Aqua_Cobble"
    },
    {
      "x": -15,
      "y": 29,
      "z": -14,
      "name": "Rock_Aqua_Cobble"
    },
    {
      "x": -15,
      "y": 30,
      "z": -14,
      "name": "Rock_Aqua_Brick"
    },
    {
      "x": -15,
      "y": 31,
      "z": -14,
      "name": "Plant_Crop_Mushroom_Glowing_Blue"
    },
    {
      "x": -15,
      "y": 25,
      "z": -13,
      "name": "Rock_Crystal_Cyan_Large",
      "rotation": 8
    },
    {
      "x": -15,
      "y": 26,
      "z": -13,
      "name": "Rock_Aqua_Brick_Smooth"
    },
    {
      "x": -15,
      "y": 27,
      "z": -13,
      "name": "Rock_Aqua_Brick"
    },
    {
      "x": -15,
      "y": 28,
      "z": -13,
      "name": "Rock_Aqua_Cobble"
    },
    {
      "x": -15,
      "y": 29,
      "z": -13,
      "name": "Rock_Aqua_Cobble"
    },
    {
      "x": -15,
      "y": 30,
      "z": -13,
      "name": "Rock_Aqua_Brick"
    },
    {
      "x": -15,
      "y": 31,
      "z": -13,
      "name": "Rock_Aqua_Cobble"
    },
    {
      "x": -15,
      "y": 26,
      "z": -12,
      "name": "Rock_Aqua_Brick_Smooth"
    },
    {
      "x": -15,
      "y": 27,
      "z": -12,
      "name": "Rock_Aqua_Cobble"
    },
    {
      "x": -15,
      "y": 28,
      "z": -12,
      "name": "Rock_Aqua_Cobble"
    },
    {
      "x": -15,
      "y": 29,
      "z": -12,
      "name": "Rock_Aqua_Cobble"
    },
    {
      "x": -15,
      "y": 30,
      "z": -12,
      "name": "Rock_Aqua_Brick"
    },
    {
      "x": -15,
      "y": 31,
      "z": -12,
      "name": "Rock_Aqua_Brick"
    },
    {
      "x": -15,
      "y": 32,
      "z": -12,
      "name": "Plant_Crop_Mushroom_Glowing_Blue"
    },
    {
      "x": -15,
      "y": 27,
      "z": -11,
      "name": "Rock_Aqua_Brick_Smooth"
    },
    {
      "x": -15,
      "y": 28,
      "z": -11,
      "name": "Plant_Coral_Bush_Cyan"
    },
    {
      "x": -15,
      "y": 31,
      "z": -11,
      "name": "Rock_Aqua_Brick"
    },
    {
      "x": -15,
      "y": 32,
      "z": -11,
      "name": "Plant_Coral_Model_Blue"
    },
    {
      "x": -15,
      "y": 30,
      "z": -10,
      "name": "Rock_Aqua_Brick"
    },
    {
      "x": -15,
      "y": 0,
      "z": -9,
      "name": "Rock_Aqua"
    },
    {
      "x": -15,
      "y": 1,
      "z": -9,
      "name": "Rock_Aqua"
    },
    {
      "x": -15,
      "y": 2,
      "z": -9,
      "name": "Rock_Aqua"
    },
    {
      "x": -15,
      "y": 3,
      "z": -9,
      "name": "Rock_Aqua"
    },
    {
      "x": -15,
      "y": 4,
      "z": -9,
      "name": "Rock_Aqua"
    },
    {
      "x": -15,
      "y": 5,
      "z": -9,
      "name": "Rock_Aqua"
    },
    {
      "x": -15,
      "y": 0,
      "z": -8,
      "name": "Rock_Aqua"
    },
    {
      "x": -15,
      "y": 1,
      "z": -8,
      "name": "Rock_Aqua"
    },
    {
      "x": -15,
      "y": 2,
      "z": -8,
      "name": "Rock_Aqua"
    },
    {
      "x": -15,
      "y": 3,
      "z": -8,
      "name": "Rock_Aqua"
    },
    {
      "x": -15,
      "y": 4,
      "z": -8,
      "name": "Rock_Aqua"
    },
    {
      "x": -15,
      "y": 5,
      "z": -8,
      "name": "Rock_Aqua"
    },
    {
      "x": -15,
      "y": 0,
      "z": -7,
      "name": "Rock_Aqua"
    },
    {
      "x": -15,
      "y": 1,
      "z": -7,
      "name": "Rock_Aqua"
    },
    {
      "x": -15,
      "y": 2,
      "z": -7,
      "name": "Rock_Aqua"
    },
    {
      "x": -15,
      "y": 3,
      "z": -7,
      "name": "Rock_Aqua"
    },
    {
      "x": -15,
      "y": 4,
      "z": -7,
      "name": "Rock_Aqua"
    },
    {
      "x": -15,
      "y": 5,
      "z": -7,
      "name": "Rock_Aqua"
    },
    {
      "x": -15,
      "y": 0,
      "z": -6,
      "name": "Rock_Aqua"
    },
    {
      "x": -15,
      "y": 1,
      "z": -6,
      "name": "Rock_Aqua"
    },
    {
      "x": -15,
      "y": 2,
      "z": -6,
      "name": "Rock_Aqua"
    },
    {
      "x": -15,
      "y": 3,
      "z": -6,
      "name": "Rock_Aqua"
    },
    {
      "x": -15,
      "y": 4,
      "z": -6,
      "name": "Rock_Aqua"
    },
    {
      "x": -15,
      "y": 5,
      "z": -6,
      "name": "Rock_Aqua"
    },
    {
      "x": -15,
      "y": 0,
      "z": -5,
      "name": "Rock_Aqua"
    },
    {
      "x": -15,
      "y": 1,
      "z": -5,
      "name": "Rock_Aqua"
    },
    {
      "x": -15,
      "y": 2,
      "z": -5,
      "name": "Rock_Aqua"
    },
    {
      "x": -15,
      "y": 3,
      "z": -5,
      "name": "Rock_Aqua"
    },
    {
      "x": -15,
      "y": 4,
      "z": -5,
      "name": "Rock_Aqua_Brick_Stairs",
      "rotation": 3
    },
    {
      "x": -15,
      "y": 0,
      "z": -4,
      "name": "Rock_Aqua"
    },
    {
      "x": -15,
      "y": 1,
      "z": -4,
      "name": "Rock_Aqua"
    },
    {
      "x": -15,
      "y": 2,
      "z": -4,
      "name": "Rock_Aqua"
    },
    {
      "x": -15,
      "y": 3,
      "z": -4,
      "name": "Rock_Aqua"
    },
    {
      "x": -15,
      "y": 4,
      "z": -4,
      "name": "Rock_Aqua_Brick_Stairs",
      "rotation": 3
    },
    {
      "x": -15,
      "y": 0,
      "z": -3,
      "name": "Rock_Aqua"
    },
    {
      "x": -15,
      "y": 1,
      "z": -3,
      "name": "Rock_Aqua"
    },
    {
      "x": -15,
      "y": 2,
      "z": -3,
      "name": "Rock_Aqua"
    },
    {
      "x": -15,
      "y": 3,
      "z": -3,
      "name": "Rock_Aqua"
    },
    {
      "x": -15,
      "y": 4,
      "z": -3,
      "name": "Rock_Aqua_Brick_Stairs",
      "rotation": 3
    },
    {
      "x": -15,
      "y": 0,
      "z": -2,
      "name": "Rock_Aqua"
    },
    {
      "x": -15,
      "y": 1,
      "z": -2,
      "name": "Rock_Aqua"
    },
    {
      "x": -15,
      "y": 2,
      "z": -2,
      "name": "Rock_Aqua"
    },
    {
      "x": -15,
      "y": 3,
      "z": -2,
      "name": "Rock_Aqua"
    },
    {
      "x": -15,
      "y": 4,
      "z": -2,
      "name": "Rock_Aqua"
    },
    {
      "x": -15,
      "y": 5,
      "z": -2,
      "name": "Rock_Aqua"
    },
    {
      "x": -15,
      "y": 0,
      "z": -1,
      "name": "Rock_Aqua"
    },
    {
      "x": -15,
      "y": 1,
      "z": -1,
      "name": "Rock_Aqua"
    },
    {
      "x": -15,
      "y": 2,
      "z": -1,
      "name": "Rock_Aqua"
    },
    {
      "x": -15,
      "y": 3,
      "z": -1,
      "name": "Rock_Aqua"
    },
    {
      "x": -15,
      "y": 4,
      "z": -1,
      "name": "Rock_Aqua"
    },
    {
      "x": -15,
      "y": 5,
      "z": -1,
      "name": "Rock_Aqua"
    },
    {
      "x": -15,
      "y": 0,
      "z": 0,
      "name": "Rock_Aqua"
    },
    {
      "x": -15,
      "y": 1,
      "z": 0,
      "name": "Rock_Aqua"
    },
    {
      "x": -15,
      "y": 2,
      "z": 0,
      "name": "Rock_Aqua"
    },
    {
      "x": -15,
      "y": 3,
      "z": 0,
      "name": "Rock_Aqua"
    },
    {
      "x": -15,
      "y": 4,
      "z": 0,
      "name": "Rock_Aqua"
    },
    {
      "x": -15,
      "y": 5,
      "z": 0,
      "name": "Rock_Aqua"
    },
    {
      "x": -15,
      "y": 33,
      "z": 0,
      "name": "Rock_Aqua_Brick"
    },
    {
      "x": -15,
      "y": 34,
      "z": 0,
      "name": "Rock_Aqua_Cobble"
    },
    {
      "x": -15,
      "y": 0,
      "z": 1,
      "name": "Rock_Aqua"
    },
    {
      "x": -15,
      "y": 1,
      "z": 1,
      "name": "Rock_Aqua"
    },
    {
      "x": -15,
      "y": 2,
      "z": 1,
      "name": "Rock_Aqua"
    },
    {
      "x": -15,
      "y": 3,
      "z": 1,
      "name": "Rock_Aqua"
    },
    {
      "x": -15,
      "y": 4,
      "z": 1,
      "name": "Rock_Aqua"
    },
    {
      "x": -15,
      "y": 5,
      "z": 1,
      "name": "Rock_Aqua"
    },
    {
      "x": -15,
      "y": 31,
      "z": 1,
      "name": "Rock_Aqua_Brick_Smooth"
    },
    {
      "x": -15,
      "y": 32,
      "z": 1,
      "name": "Rock_Aqua_Brick_Smooth"
    },
    {
      "x": -15,
      "y": 33,
      "z": 1,
      "name": "Rock_Aqua_Cobble"
    },
    {
      "x": -15,
      "y": 34,
      "z": 1,
      "name": "Rock_Aqua_Cobble"
    },
    {
      "x": -15,
      "y": 35,
      "z": 1,
      "name": "Rock_Aqua_Cobble"
    },
    {
      "x": -15,
      "y": 30,
      "z": 2,
      "name": "Rock_Aqua_Brick_Smooth"
    },
    {
      "x": -15,
      "y": 31,
      "z": 2,
      "name": "Rock_Aqua_Brick_Smooth"
    },
    {
      "x": -15,
      "y": 32,
      "z": 2,
      "name": "Rock_Aqua_Brick_Smooth"
    },
    {
      "x": -15,
      "y": 33,
      "z": 2,
      "name": "Rock_Aqua_Cobble"
    },
    {
      "x": -15,
      "y": 34,
      "z": 2,
      "name": "Rock_Aqua_Brick"
    },
    {
      "x": -15,
      "y": 35,
      "z": 2,
      "name": "Rock_Aqua_Brick"
    },
    {
      "x": -15,
      "y": 30,
      "z": 3,
      "name": "Rock_Aqua_Brick_Smooth"
    },
    {
      "x": -15,
      "y": 31,
      "z": 3,
      "name": "Rock_Aqua_Brick_Smooth"
    },
    {
      "x": -15,
      "y": 32,
      "z": 3,
      "name": "Rock_Aqua_Brick_Smooth"
    },
    {
      "x": -15,
      "y": 33,
      "z": 3,
      "name": "Rock_Aqua_Cobble"
    },
    {
      "x": -15,
      "y": 30,
      "z": 4,
      "name": "Rock_Aqua_Brick_Smooth"
    },
    {
      "x": -15,
      "y": 31,
      "z": 4,
      "name": "Rock_Aqua_Brick_Smooth"
    },
    {
      "x": -15,
      "y": 35,
      "z": 4,
      "name": "Rock_Aqua_Brick"
    },
    {
      "x": -15,
      "y": 36,
      "z": 4,
      "name": "Rock_Aqua_Cobble"
    },
    {
      "x": -15,
      "y": 30,
      "z": 5,
      "name": "Rock_Aqua_Brick_Smooth"
    },
    {
      "x": -15,
      "y": 31,
      "z": 5,
      "name": "Rock_Aqua_Brick_Smooth"
    },
    {
      "x": -15,
      "y": 32,
      "z": 5,
      "name": "Rock_Aqua_Cobble"
    },
    {
      "x": -15,
      "y": 33,
      "z": 5,
      "name": "Rock_Aqua_Cobble"
    },
    {
      "x": -15,
      "y": 34,
      "z": 5,
      "name": "Rock_Aqua_Brick"
    },
    {
      "x": -15,
      "y": 35,
      "z": 5,
      "name": "Rock_Aqua_Brick"
    },
    {
      "x": -15,
      "y": 36,
      "z": 5,
      "name": "Rock_Aqua_Brick"
    },
    {
      "x": -15,
      "y": 30,
      "z": 6,
      "name": "Rock_Aqua_Brick_Smooth"
    },
    {
      "x": -15,
      "y": 31,
      "z": 6,
      "name": "Rock_Aqua_Brick_Smooth"
    },
    {
      "x": -15,
      "y": 32,
      "z": 6,
      "name": "Rock_Aqua_Cobble"
    },
    {
      "x": -15,
      "y": 36,
      "z": 6,
      "name": "Rock_Aqua_Cobble"
    },
    {
      "x": -15,
      "y": 37,
      "z": 6,
      "name": "Plant_Coral_Bush_Blue"
    },
    {
      "x": -15,
      "y": 30,
      "z": 7,
      "name": "Rock_Aqua_Brick_Smooth"
    },
    {
      "x": -15,
      "y": 31,
      "z": 7,
      "name": "Rock_Aqua_Brick_Smooth"
    },
    {
      "x": -15,
      "y": 32,
      "z": 7,
      "name": "Rock_Aqua_Cobble"
    },
    {
      "x": -15,
      "y": 33,
      "z": 7,
      "name": "Rock_Aqua_Cobble"
    },
    {
      "x": -15,
      "y": 34,
      "z": 7,
      "name": "Rock_Aqua_Brick"
    },
    {
      "x": -15,
      "y": 31,
      "z": 8,
      "name": "Rock_Aqua_Brick_Smooth"
    },
    {
      "x": -15,
      "y": 32,
      "z": 8,
      "name": "Rock_Aqua_Brick"
    },
    {
      "x": -15,
      "y": 34,
      "z": 8,
      "name": "Rock_Aqua_Cobble"
    },
    {
      "x": -15,
      "y": 35,
      "z": 8,
      "name": "Rock_Aqua_Cobble"
    },
    {
      "x": -15,
      "y": 32,
      "z": 9,
      "name": "Rock_Aqua_Cobble"
    },
    {
      "x": -15,
      "y": 33,
      "z": 9,
      "name": "Rock_Aqua_Brick"
    },
    {
      "x": -15,
      "y": 34,
      "z": 9,
      "name": "Rock_Aqua_Brick"
    },
    {
      "x": -15,
      "y": 26,
      "z": 10,
      "name": "Rock_Aqua_Brick_Smooth"
    },
    {
      "x": -15,
      "y": 24,
      "z": 11,
      "name": "Rock_Aqua_Brick_Smooth"
    },
    {
      "x": -15,
      "y": 25,
      "z": 11,
      "name": "Rock_Aqua"
    },
    {
      "x": -15,
      "y": 26,
      "z": 11,
      "name": "Rock_Aqua"
    },
    {
      "x": -15,
      "y": 27,
      "z": 11,
      "name": "Rock_Aqua_Brick_Smooth"
    },
    {
      "x": -15,
      "y": 28,
      "z": 11,
      "name": "Rock_Aqua"
    },
    {
      "x": -15,
      "y": 24,
      "z": 12,
      "name": "Rock_Aqua_Brick_Smooth"
    },
    {
      "x": -15,
      "y": 25,
      "z": 12,
      "name": "Rock_Aqua_Brick_Smooth"
    },
    {
      "x": -15,
      "y": 26,
      "z": 12,
      "name": "Rock_Aqua_Brick_Smooth"
    },
    {
      "x": -15,
      "y": 27,
      "z": 12,
      "name": "Rock_Aqua_Brick_Smooth"
    },
    {
      "x": -15,
      "y": 28,
      "z": 12,
      "name": "Rock_Aqua_Brick_Smooth"
    },
    {
      "x": -15,
      "y": 23,
      "z": 13,
      "name": "Rock_Aqua"
    },
    {
      "x": -15,
      "y": 24,
      "z": 13,
      "name": "Rock_Aqua_Brick_Smooth"
    },
    {
      "x": -15,
      "y": 25,
      "z": 13,
      "name": "Rock_Aqua_Brick_Smooth"
    },
    {
      "x": -15,
      "y": 26,
      "z": 13,
      "name": "Rock_Aqua_Brick_Smooth"
    },
    {
      "x": -15,
      "y": 27,
      "z": 13,
      "name": "Rock_Aqua_Brick_Smooth"
    },
    {
      "x": -15,
      "y": 28,
      "z": 13,
      "name": "Rock_Aqua"
    },
    {
      "x": -15,
      "y": 29,
      "z": 13,
      "name": "Rock_Aqua"
    },
    {
      "x": -15,
      "y": 23,
      "z": 14,
      "name": "Rock_Aqua_Brick_Smooth"
    },
    {
      "x": -15,
      "y": 24,
      "z": 14,
      "name": "Rock_Aqua"
    },
    {
      "x": -15,
      "y": 25,
      "z": 14,
      "name": "Rock_Aqua_Brick_Smooth"
    },
    {
      "x": -15,
      "y": 26,
      "z": 14,
      "name": "Rock_Aqua_Brick_Smooth"
    },
    {
      "x": -15,
      "y": 27,
      "z": 14,
      "name": "Rock_Aqua_Brick_Smooth"
    },
    {
      "x": -15,
      "y": 28,
      "z": 14,
      "name": "Rock_Aqua"
    },
    {
      "x": -15,
      "y": 29,
      "z": 14,
      "name": "Rock_Aqua"
    },
    {
      "x": -15,
      "y": 24,
      "z": 15,
      "name": "Rock_Aqua_Brick_Smooth"
    },
    {
      "x": -15,
      "y": 25,
      "z": 15,
      "name": "Rock_Aqua_Brick_Smooth"
    },
    {
      "x": -15,
      "y": 26,
      "z": 15,
      "name": "Rock_Aqua_Brick_Smooth"
    },
    {
      "x": -15,
      "y": 27,
      "z": 15,
      "name": "Rock_Aqua_Brick_Smooth"
    },
    {
      "x": -15,
      "y": 28,
      "z": 15,
      "name": "Rock_Aqua"
    },
    {
      "x": -15,
      "y": 24,
      "z": 16,
      "name": "Rock_Aqua"
    },
    {
      "x": -15,
      "y": 25,
      "z": 16,
      "name": "Rock_Aqua_Brick_Smooth"
    },
    {
      "x": -15,
      "y": 26,
      "z": 16,
      "name": "Rock_Aqua_Brick_Smooth"
    },
    {
      "x": -15,
      "y": 27,
      "z": 16,
      "name": "Rock_Aqua_Brick_Smooth"
    },
    {
      "x": -15,
      "y": 28,
      "z": 16,
      "name": "Rock_Aqua"
    },
    {
      "x": -15,
      "y": 29,
      "z": 16,
      "name": "Plant_Crop_Mushroom_Glowing_Blue"
    },
    {
      "x": -15,
      "y": 25,
      "z": 17,
      "name": "Rock_Aqua"
    },
    {
      "x": -15,
      "y": 26,
      "z": 17,
      "name": "Rock_Aqua_Brick_Smooth"
    },
    {
      "x": -15,
      "y": 27,
      "z": 17,
      "name": "Rock_Aqua"
    },
    {
      "x": -15,
      "y": 26,
      "z": 18,
      "name": "Rock_Aqua_Brick_Smooth"
    },
    {
      "x": -14,
      "y": 28,
      "z": -14,
      "name": "Rock_Aqua_Brick"
    },
    {
      "x": -14,
      "y": 29,
      "z": -14,
      "name": "Rock_Aqua_Cobble"
    },
    {
      "x": -14,
      "y": 30,
      "z": -14,
      "name": "Plant_Coral_Bush_Cyan"
    },
    {
      "x": -14,
      "y": 27,
      "z": -13,
      "name": "Rock_Aqua_Brick"
    },
    {
      "x": -14,
      "y": 28,
      "z": -13,
      "name": "Rock_Aqua_Cobble"
    },
    {
      "x": -14,
      "y": 29,
      "z": -13,
      "name": "Rock_Aqua_Brick"
    },
    {
      "x": -14,
      "y": 30,
      "z": -13,
      "name": "Rock_Aqua_Cobble"
    },
    {
      "x": -14,
      "y": 28,
      "z": -12,
      "name": "Rock_Aqua_Cobble"
    },
    {
      "x": -14,
      "y": 0,
      "z": -11,
      "name": "Rock_Aqua"
    },
    {
      "x": -14,
      "y": 1,
      "z": -11,
      "name": "Rock_Aqua"
    },
    {
      "x": -14,
      "y": 2,
      "z": -11,
      "name": "Rock_Aqua"
    },
    {
      "x": -14,
      "y": 3,
      "z": -11,
      "name": "Rock_Aqua"
    },
    {
      "x": -14,
      "y": 4,
      "z": -11,
      "name": "Rock_Aqua"
    },
    {
      "x": -14,
      "y": 5,
      "z": -11,
      "name": "Rock_Aqua"
    },
    {
      "x": -14,
      "y": 0,
      "z": -10,
      "name": "Rock_Aqua"
    },
    {
      "x": -14,
      "y": 1,
      "z": -10,
      "name": "Rock_Aqua"
    },
    {
      "x": -14,
      "y": 2,
      "z": -10,
      "name": "Rock_Aqua"
    },
    {
      "x": -14,
      "y": 3,
      "z": -10,
      "name": "Rock_Aqua"
    },
    {
      "x": -14,
      "y": 4,
      "z": -10,
      "name": "Rock_Aqua"
    },
    {
      "x": -14,
      "y": 5,
      "z": -10,
      "name": "Rock_Aqua"
    },
    {
      "x": -14,
      "y": 0,
      "z": -9,
      "name": "Rock_Aqua"
    },
    {
      "x": -14,
      "y": 1,
      "z": -9,
      "name": "Rock_Aqua"
    },
    {
      "x": -14,
      "y": 2,
      "z": -9,
      "name": "Rock_Aqua"
    },
    {
      "x": -14,
      "y": 3,
      "z": -9,
      "name": "Rock_Aqua"
    },
    {
      "x": -14,
      "y": 4,
      "z": -9,
      "name": "Rock_Aqua"
    },
    {
      "x": -14,
      "y": 5,
      "z": -9,
      "name": "Rock_Aqua"
    },
    {
      "x": -14,
      "y": 0,
      "z": -8,
      "name": "Rock_Aqua"
    },
    {
      "x": -14,
      "y": 1,
      "z": -8,
      "name": "Rock_Aqua"
    },
    {
      "x": -14,
      "y": 2,
      "z": -8,
      "name": "Rock_Aqua"
    },
    {
      "x": -14,
      "y": 3,
      "z": -8,
      "name": "Rock_Aqua"
    },
    {
      "x": -14,
      "y": 4,
      "z": -8,
      "name": "Rock_Aqua"
    },
    {
      "x": -14,
      "y": 5,
      "z": -8,
      "name": "Rock_Aqua"
    },
    {
      "x": -14,
      "y": 0,
      "z": -7,
      "name": "Rock_Aqua"
    },
    {
      "x": -14,
      "y": 1,
      "z": -7,
      "name": "Rock_Aqua"
    },
    {
      "x": -14,
      "y": 2,
      "z": -7,
      "name": "Rock_Aqua"
    },
    {
      "x": -14,
      "y": 3,
      "z": -7,
      "name": "Rock_Aqua"
    },
    {
      "x": -14,
      "y": 4,
      "z": -7,
      "name": "Rock_Aqua"
    },
    {
      "x": -14,
      "y": 5,
      "z": -7,
      "name": "Rock_Aqua"
    },
    {
      "x": -14,
      "y": 10,
      "z": -7,
      "name": "Rock_Aqua_Brick_Smooth_Half"
    },
    {
      "x": -14,
      "y": 0,
      "z": -6,
      "name": "Rock_Aqua"
    },
    {
      "x": -14,
      "y": 1,
      "z": -6,
      "name": "Rock_Aqua"
    },
    {
      "x": -14,
      "y": 2,
      "z": -6,
      "name": "Rock_Aqua"
    },
    {
      "x": -14,
      "y": 3,
      "z": -6,
      "name": "Rock_Aqua"
    },
    {
      "x": -14,
      "y": 4,
      "z": -6,
      "name": "Rock_Aqua"
    },
    {
      "x": -14,
      "y": 5,
      "z": -6,
      "name": "Rock_Aqua"
    },
    {
      "x": -14,
      "y": 10,
      "z": -6,
      "name": "Rock_Aqua_Brick_Smooth_Half"
    },
    {
      "x": -14,
      "y": 0,
      "z": -5,
      "name": "Rock_Aqua"
    },
    {
      "x": -14,
      "y": 1,
      "z": -5,
      "name": "Rock_Aqua"
    },
    {
      "x": -14,
      "y": 2,
      "z": -5,
      "name": "Rock_Aqua"
    },
    {
      "x": -14,
      "y": 3,
      "z": -5,
      "name": "Rock_Aqua"
    },
    {
      "x": -14,
      "y": 4,
      "z": -5,
      "name": "Rock_Aqua"
    },
    {
      "x": -14,
      "y": 5,
      "z": -5,
      "name": "Rock_Aqua_Brick_Stairs",
      "rotation": 3
    },
    {
      "x": -14,
      "y": 10,
      "z": -5,
      "name": "Rock_Aqua_Brick_Smooth_Half"
    },
    {
      "x": -14,
      "y": 0,
      "z": -4,
      "name": "Rock_Aqua"
    },
    {
      "x": -14,
      "y": 1,
      "z": -4,
      "name": "Rock_Aqua"
    },
    {
      "x": -14,
      "y": 2,
      "z": -4,
      "name": "Rock_Aqua"
    },
    {
      "x": -14,
      "y": 3,
      "z": -4,
      "name": "Rock_Aqua"
    },
    {
      "x": -14,
      "y": 4,
      "z": -4,
      "name": "Rock_Aqua"
    },
    {
      "x": -14,
      "y": 5,
      "z": -4,
      "name": "Rock_Aqua_Brick_Stairs",
      "rotation": 3
    },
    {
      "x": -14,
      "y": 10,
      "z": -4,
      "name": "Rock_Aqua_Brick_Smooth_Half"
    },
    {
      "x": -14,
      "y": 0,
      "z": -3,
      "name": "Rock_Aqua"
    },
    {
      "x": -14,
      "y": 1,
      "z": -3,
      "name": "Rock_Aqua"
    },
    {
      "x": -14,
      "y": 2,
      "z": -3,
      "name": "Rock_Aqua"
    },
    {
      "x": -14,
      "y": 3,
      "z": -3,
      "name": "Rock_Aqua"
    },
    {
      "x": -14,
      "y": 4,
      "z": -3,
      "name": "Rock_Aqua"
    },
    {
      "x": -14,
      "y": 5,
      "z": -3,
      "name": "Rock_Aqua_Brick_Stairs",
      "rotation": 3
    },
    {
      "x": -14,
      "y": 10,
      "z": -3,
      "name": "Rock_Aqua_Brick_Smooth_Half"
    },
    {
      "x": -14,
      "y": 0,
      "z": -2,
      "name": "Rock_Aqua"
    },
    {
      "x": -14,
      "y": 1,
      "z": -2,
      "name": "Rock_Aqua"
    },
    {
      "x": -14,
      "y": 2,
      "z": -2,
      "name": "Rock_Aqua"
    },
    {
      "x": -14,
      "y": 3,
      "z": -2,
      "name": "Rock_Aqua"
    },
    {
      "x": -14,
      "y": 4,
      "z": -2,
      "name": "Rock_Aqua"
    },
    {
      "x": -14,
      "y": 5,
      "z": -2,
      "name": "Rock_Aqua"
    },
    {
      "x": -14,
      "y": 10,
      "z": -2,
      "name": "Rock_Aqua_Brick_Smooth_Half"
    },
    {
      "x": -14,
      "y": 0,
      "z": -1,
      "name": "Rock_Aqua"
    },
    {
      "x": -14,
      "y": 1,
      "z": -1,
      "name": "Rock_Aqua"
    },
    {
      "x": -14,
      "y": 2,
      "z": -1,
      "name": "Rock_Aqua"
    },
    {
      "x": -14,
      "y": 3,
      "z": -1,
      "name": "Rock_Aqua"
    },
    {
      "x": -14,
      "y": 4,
      "z": -1,
      "name": "Rock_Aqua"
    },
    {
      "x": -14,
      "y": 5,
      "z": -1,
      "name": "Rock_Aqua"
    },
    {
      "x": -14,
      "y": 10,
      "z": -1,
      "name": "Rock_Aqua_Brick_Smooth_Half"
    },
    {
      "x": -14,
      "y": 0,
      "z": 0,
      "name": "Rock_Aqua"
    },
    {
      "x": -14,
      "y": 1,
      "z": 0,
      "name": "Rock_Aqua"
    },
    {
      "x": -14,
      "y": 2,
      "z": 0,
      "name": "Rock_Aqua"
    },
    {
      "x": -14,
      "y": 3,
      "z": 0,
      "name": "Rock_Aqua"
    },
    {
      "x": -14,
      "y": 4,
      "z": 0,
      "name": "Rock_Aqua"
    },
    {
      "x": -14,
      "y": 5,
      "z": 0,
      "name": "Rock_Aqua"
    },
    {
      "x": -14,
      "y": 0,
      "z": 1,
      "name": "Rock_Aqua"
    },
    {
      "x": -14,
      "y": 1,
      "z": 1,
      "name": "Rock_Aqua"
    },
    {
      "x": -14,
      "y": 2,
      "z": 1,
      "name": "Rock_Aqua"
    },
    {
      "x": -14,
      "y": 3,
      "z": 1,
      "name": "Rock_Aqua"
    },
    {
      "x": -14,
      "y": 4,
      "z": 1,
      "name": "Rock_Aqua"
    },
    {
      "x": -14,
      "y": 5,
      "z": 1,
      "name": "Rock_Aqua"
    },
    {
      "x": -14,
      "y": 0,
      "z": 2,
      "name": "Rock_Aqua"
    },
    {
      "x": -14,
      "y": 1,
      "z": 2,
      "name": "Rock_Aqua"
    },
    {
      "x": -14,
      "y": 2,
      "z": 2,
      "name": "Rock_Aqua"
    },
    {
      "x": -14,
      "y": 3,
      "z": 2,
      "name": "Rock_Aqua"
    },
    {
      "x": -14,
      "y": 4,
      "z": 2,
      "name": "Rock_Aqua"
    },
    {
      "x": -14,
      "y": 5,
      "z": 2,
      "name": "Rock_Aqua"
    },
    {
      "x": -14,
      "y": 32,
      "z": 2,
      "name": "Rock_Aqua_Brick_Smooth"
    },
    {
      "x": -14,
      "y": 33,
      "z": 2,
      "name": "Rock_Aqua_Brick"
    },
    {
      "x": -14,
      "y": 34,
      "z": 2,
      "name": "Rock_Aqua_Cobble"
    },
    {
      "x": -14,
      "y": 35,
      "z": 2,
      "name": "Plant_Coral_Bush_Cyan"
    },
    {
      "x": -14,
      "y": 0,
      "z": 3,
      "name": "Rock_Aqua"
    },
    {
      "x": -14,
      "y": 1,
      "z": 3,
      "name": "Rock_Aqua"
    },
    {
      "x": -14,
      "y": 2,
      "z": 3,
      "name": "Rock_Aqua"
    },
    {
      "x": -14,
      "y": 3,
      "z": 3,
      "name": "Rock_Aqua"
    },
    {
      "x": -14,
      "y": 4,
      "z": 3,
      "name": "Rock_Aqua"
    },
    {
      "x": -14,
      "y": 5,
      "z": 3,
      "name": "Rock_Aqua"
    },
    {
      "x": -14,
      "y": 31,
      "z": 3,
      "name": "Rock_Aqua_Brick_Smooth"
    },
    {
      "x": -14,
      "y": 32,
      "z": 3,
      "name": "Rock_Aqua_Brick_Smooth"
    },
    {
      "x": -14,
      "y": 33,
      "z": 3,
      "name": "Rock_Aqua_Brick"
    },
    {
      "x": -14,
      "y": 34,
      "z": 3,
      "name": "Rock_Aqua_Cobble"
    },
    {
      "x": -14,
      "y": 35,
      "z": 3,
      "name": "Rock_Aqua_Brick"
    },
    {
      "x": -14,
      "y": 31,
      "z": 4,
      "name": "Rock_Aqua_Brick_Smooth"
    },
    {
      "x": -14,
      "y": 32,
      "z": 4,
      "name": "Rock_Aqua_Brick_Smooth"
    },
    {
      "x": -14,
      "y": 33,
      "z": 4,
      "name": "Rock_Aqua_Brick"
    },
    {
      "x": -14,
      "y": 34,
      "z": 4,
      "name": "Rock_Aqua_Cobble"
    },
    {
      "x": -14,
      "y": 35,
      "z": 4,
      "name": "Rock_Aqua_Brick"
    },
    {
      "x": -14,
      "y": 31,
      "z": 5,
      "name": "Rock_Aqua_Brick_Smooth"
    },
    {
      "x": -14,
      "y": 32,
      "z": 5,
      "name": "Rock_Aqua_Brick"
    },
    {
      "x": -14,
      "y": 33,
      "z": 5,
      "name": "Rock_Aqua_Brick"
    },
    {
      "x": -14,
      "y": 34,
      "z": 5,
      "name": "Rock_Aqua_Cobble"
    },
    {
      "x": -14,
      "y": 35,
      "z": 5,
      "name": "Rock_Aqua_Brick"
    },
    {
      "x": -14,
      "y": 31,
      "z": 6,
      "name": "Rock_Aqua_Brick_Smooth"
    },
    {
      "x": -14,
      "y": 32,
      "z": 6,
      "name": "Rock_Aqua_Brick"
    },
    {
      "x": -14,
      "y": 33,
      "z": 6,
      "name": "Rock_Aqua_Cobble"
    },
    {
      "x": -14,
      "y": 31,
      "z": 7,
      "name": "Rock_Aqua_Brick_Smooth"
    },
    {
      "x": -14,
      "y": 32,
      "z": 7,
      "name": "Rock_Aqua_Cobble"
    },
    {
      "x": -14,
      "y": 33,
      "z": 7,
      "name": "Rock_Aqua_Brick"
    },
    {
      "x": -14,
      "y": 34,
      "z": 7,
      "name": "Rock_Aqua_Brick"
    },
    {
      "x": -14,
      "y": 33,
      "z": 8,
      "name": "Rock_Aqua_Cobble"
    },
    {
      "x": -14,
      "y": 25,
      "z": 11,
      "name": "Rock_Aqua_Brick_Smooth"
    },
    {
      "x": -14,
      "y": 26,
      "z": 11,
      "name": "Rock_Aqua_Brick_Smooth"
    },
    {
      "x": -14,
      "y": 27,
      "z": 11,
      "name": "Rock_Aqua"
    },
    {
      "x": -14,
      "y": 24,
      "z": 12,
      "name": "Rock_Aqua"
    },
    {
      "x": -14,
      "y": 25,
      "z": 12,
      "name": "Rock_Aqua_Brick_Smooth"
    },
    {
      "x": -14,
      "y": 26,
      "z": 12,
      "name": "Rock_Aqua"
    },
    {
      "x": -14,
      "y": 27,
      "z": 12,
      "name": "Rock_Aqua_Brick_Smooth"
    },
    {
      "x": -14,
      "y": 28,
      "z": 12,
      "name": "Rock_Aqua_Brick_Smooth"
    },
    {
      "x": -14,
      "y": 24,
      "z": 13,
      "name": "Rock_Aqua_Brick_Smooth"
    },
    {
      "x": -14,
      "y": 25,
      "z": 13,
      "name": "Rock_Aqua"
    },
    {
      "x": -14,
      "y": 26,
      "z": 13,
      "name": "Rock_Aqua_Brick_Smooth"
    },
    {
      "x": -14,
      "y": 27,
      "z": 13,
      "name": "Rock_Aqua"
    },
    {
      "x": -14,
      "y": 28,
      "z": 13,
      "name": "Rock_Aqua"
    },
    {
      "x": -14,
      "y": 24,
      "z": 14,
      "name": "Rock_Aqua"
    },
    {
      "x": -14,
      "y": 25,
      "z": 14,
      "name": "Rock_Aqua_Brick_Smooth"
    },
    {
      "x": -14,
      "y": 26,
      "z": 14,
      "name": "Rock_Aqua_Brick_Smooth"
    },
    {
      "x": -14,
      "y": 27,
      "z": 14,
      "name": "Rock_Aqua"
    },
    {
      "x": -14,
      "y": 28,
      "z": 14,
      "name": "Rock_Aqua_Brick_Smooth"
    },
    {
      "x": -14,
      "y": 25,
      "z": 15,
      "name": "Rock_Aqua"
    },
    {
      "x": -14,
      "y": 26,
      "z": 15,
      "name": "Rock_Aqua"
    },
    {
      "x": -14,
      "y": 27,
      "z": 15,
      "name": "Rock_Aqua_Brick_Smooth"
    },
    {
      "x": -14,
      "y": 25,
      "z": 16,
      "name": "Rock_Aqua_Brick_Smooth"
    },
    {
      "x": -14,
      "y": 26,
      "z": 16,
      "name": "Rock_Aqua"
    },
    {
      "x": -14,
      "y": 27,
      "z": 16,
      "name": "Rock_Aqua_Brick_Smooth"
    },
    {
      "x": -13,
      "y": 41,
      "z": -15,
      "name": "Rock_Aqua_Brick_Smooth"
    },
    {
      "x": -13,
      "y": 42,
      "z": -15,
      "name": "Plant_Coral_Model_Blue"
    },
    {
      "x": -13,
      "y": 0,
      "z": -12,
      "name": "Rock_Aqua"
    },
    {
      "x": -13,
      "y": 1,
      "z": -12,
      "name": "Rock_Aqua"
    },
    {
      "x": -13,
      "y": 2,
      "z": -12,
      "name": "Rock_Aqua"
    },
    {
      "x": -13,
      "y": 3,
      "z": -12,
      "name": "Rock_Aqua"
    },
    {
      "x": -13,
      "y": 4,
      "z": -12,
      "name": "Rock_Aqua"
    },
    {
      "x": -13,
      "y": 5,
      "z": -12,
      "name": "Rock_Aqua"
    },
    {
      "x": -13,
      "y": 0,
      "z": -11,
      "name": "Rock_Aqua"
    },
    {
      "x": -13,
      "y": 1,
      "z": -11,
      "name": "Rock_Aqua"
    },
    {
      "x": -13,
      "y": 2,
      "z": -11,
      "name": "Rock_Aqua"
    },
    {
      "x": -13,
      "y": 3,
      "z": -11,
      "name": "Rock_Aqua"
    },
    {
      "x": -13,
      "y": 4,
      "z": -11,
      "name": "Rock_Aqua"
    },
    {
      "x": -13,
      "y": 5,
      "z": -11,
      "name": "Rock_Aqua"
    },
    {
      "x": -13,
      "y": 41,
      "z": -11,
      "name": "Rock_Aqua_Cobble"
    },
    {
      "x": -13,
      "y": 0,
      "z": -10,
      "name": "Rock_Aqua"
    },
    {
      "x": -13,
      "y": 1,
      "z": -10,
      "name": "Rock_Aqua"
    },
    {
      "x": -13,
      "y": 2,
      "z": -10,
      "name": "Rock_Aqua"
    },
    {
      "x": -13,
      "y": 3,
      "z": -10,
      "name": "Rock_Aqua"
    },
    {
      "x": -13,
      "y": 4,
      "z": -10,
      "name": "Rock_Aqua"
    },
    {
      "x": -13,
      "y": 5,
      "z": -10,
      "name": "Rock_Aqua"
    },
    {
      "x": -13,
      "y": 42,
      "z": -10,
      "name": "Rock_Aqua_Cobble"
    },
    {
      "x": -13,
      "y": 43,
      "z": -10,
      "name": "Plant_Crop_Mushroom_Glowing_Blue"
    },
    {
      "x": -13,
      "y": 0,
      "z": -9,
      "name": "Rock_Aqua"
    },
    {
      "x": -13,
      "y": 1,
      "z": -9,
      "name": "Rock_Aqua"
    },
    {
      "x": -13,
      "y": 2,
      "z": -9,
      "name": "Rock_Aqua"
    },
    {
      "x": -13,
      "y": 3,
      "z": -9,
      "name": "Rock_Aqua"
    },
    {
      "x": -13,
      "y": 4,
      "z": -9,
      "name": "Rock_Aqua"
    },
    {
      "x": -13,
      "y": 5,
      "z": -9,
      "name": "Rock_Aqua"
    },
    {
      "x": -13,
      "y": 10,
      "z": -9,
      "name": "Rock_Aqua_Brick_Smooth_Half"
    },
    {
      "x": -13,
      "y": 0,
      "z": -8,
      "name": "Rock_Aqua"
    },
    {
      "x": -13,
      "y": 1,
      "z": -8,
      "name": "Rock_Aqua"
    },
    {
      "x": -13,
      "y": 2,
      "z": -8,
      "name": "Rock_Aqua"
    },
    {
      "x": -13,
      "y": 3,
      "z": -8,
      "name": "Rock_Aqua"
    },
    {
      "x": -13,
      "y": 4,
      "z": -8,
      "name": "Rock_Aqua"
    },
    {
      "x": -13,
      "y": 5,
      "z": -8,
      "name": "Rock_Aqua"
    },
    {
      "x": -13,
      "y": 6,
      "z": -8,
      "name": "Rock_Aqua_Brick_Pillar_Base"
    },
    {
      "x": -13,
      "y": 7,
      "z": -8,
      "name": "Rock_Aqua_Brick_Pillar_Middle"
    },
    {
      "x": -13,
      "y": 8,
      "z": -8,
      "name": "Rock_Aqua_Brick_Pillar_Middle"
    },
    {
      "x": -13,
      "y": 9,
      "z": -8,
      "name": "Rock_Aqua_Brick_Pillar_Middle"
    },
    {
      "x": -13,
      "y": 10,
      "z": -8,
      "name": "Rock_Aqua_Brick_Smooth_Half"
    },
    {
      "x": -13,
      "y": 0,
      "z": -7,
      "name": "Rock_Aqua"
    },
    {
      "x": -13,
      "y": 1,
      "z": -7,
      "name": "Rock_Aqua"
    },
    {
      "x": -13,
      "y": 2,
      "z": -7,
      "name": "Rock_Aqua"
    },
    {
      "x": -13,
      "y": 3,
      "z": -7,
      "name": "Rock_Aqua"
    },
    {
      "x": -13,
      "y": 4,
      "z": -7,
      "name": "Rock_Aqua"
    },
    {
      "x": -13,
      "y": 5,
      "z": -7,
      "name": "Rock_Aqua"
    },
    {
      "x": -13,
      "y": 10,
      "z": -7,
      "name": "Rock_Aqua_Brick_Smooth_Half"
    },
    {
      "x": -13,
      "y": 0,
      "z": -6,
      "name": "Rock_Aqua"
    },
    {
      "x": -13,
      "y": 1,
      "z": -6,
      "name": "Rock_Aqua"
    },
    {
      "x": -13,
      "y": 2,
      "z": -6,
      "name": "Rock_Aqua"
    },
    {
      "x": -13,
      "y": 3,
      "z": -6,
      "name": "Rock_Aqua"
    },
    {
      "x": -13,
      "y": 4,
      "z": -6,
      "name": "Rock_Aqua"
    },
    {
      "x": -13,
      "y": 5,
      "z": -6,
      "name": "Rock_Aqua"
    },
    {
      "x": -13,
      "y": 10,
      "z": -6,
      "name": "Rock_Aqua_Brick_Smooth_Half",
