{
  "version": 8,
  "blockIdVersion": 11,
  "anchorX": 0,
  "anchorY": 0,
  "anchorZ": 0,
  "blocks": [
    {
      "x": -22,
      "y": 32,
      "z": -8,
      "name": "Rock_Aqua"
    },
    {
      "x": -22,
      "y": 32,
      "z": -7,
      "name": "Rock_Aqua_Brick_Smooth"
    },
    {
      "x": -22,
      "y": 28,
      "z": 2,
      "name": "Rock_Aqua_Brick"
    },
    {
      "x": -22,
      "y": 26,
      "z": 3,
      "name": "Rock_Crystal_Cyan_Large",
      "rotation": 8
    },
    {
      "x": -22,
      "y": 27,
      "z": 3,
      "name": "Rock_Aqua_Brick"
    },
    {
      "x": -22,
      "y": 28,
      "z": 3,
      "name": "Rock_Aqua_Brick"
    },
    {
      "x": -22,
      "y": 29,
      "z": 3,
      "name": "Rock_Aqua_Brick"
    },
    {
      "x": -22,
      "y": 27,
      "z": 4,
      "name": "Rock_Aqua_Cobble"
    },
    {
      "x": -22,
      "y": 28,
      "z": 4,
      "name": "Rock_Aqua_Cobble"
    },
    {
      "x": -22,
      "y": 29,
      "z": 4,
      "name": "Plant_Coral_Model_Cyan"
    },
    {
      "x": -22,
      "y": 28,
      "z": 5,
      "name": "Rock_Aqua_Cobble"
    },
    {
      "x": -22,
      "y": 29,
      "z": 6,
      "name": "Rock_Aqua_Brick"
    },
    {
      "x": -21,
      "y": 31,
      "z": -9,
      "name": "Rock_Aqua"
    },
    {
      "x": -21,
      "y": 32,
      "z": -9,
      "name": "Rock_Aqua_Brick_Smooth"
    },
    {
      "x": -21,
      "y": 33,
      "z": -9,
      "name": "Rock_Aqua_Brick_Smooth"
    },
    {
      "x": -21,
      "y": 34,
      "z": -9,
      "name": "Plant_Crop_Mushroom_Glowing_Blue"
    },
    {
      "x": -21,
      "y": 30,
      "z": -8,
      "name": "Rock_Aqua"
    },
    {
      "x": -21,
      "y": 31,
      "z": -8,
      "name": "Rock_Aqua"
    },
    {
      "x": -21,
      "y": 32,
      "z": -8,
      "name": "Rock_Aqua_Brick_Smooth"
    },
    {
      "x": -21,
      "y": 33,
      "z": -8,
      "name": "Rock_Aqua_Brick_Smooth"
    },
    {
      "x": -21,
      "y": 34,
      "z": -8,
      "name": "Rock_Aqua_Brick_Smooth"
    },
    {
      "x": -21,
      "y": 30,
      "z": -7,
      "name": "Rock_Aqua"
    },
    {
      "x": -21,
      "y": 31,
      "z": -7,
      "name": "Rock_Aqua"
    },
    {
      "x": -21,
      "y": 32,
      "z": -7,
      "name": "Rock_Aqua_Brick_Smooth"
    },
    {
      "x": -21,
      "y": 33,
      "z": -7,
      "name": "Rock_Aqua"
    },
    {
      "x": -21,
      "y": 34,
      "z": -7,
      "name": "Rock_Aqua"
    },
    {
      "x": -21,
      "y": 35,
      "z": -7,
      "name": "Plant_Crop_Mushroom_Glowing_Blue"
    },
    {
      "x": -21,
      "y": 31,
      "z": -6,
      "name": "Rock_Aqua_Brick_Smooth"
    },
    {
      "x": -21,
      "y": 32,
      "z": -6,
      "name": "Rock_Aqua_Brick_Smooth"
    },
    {
      "x": -21,
      "y": 33,
      "z": -6,
      "name": "Rock_Aqua"
    },
    {
      "x": -21,
      "y": 28,
      "z": 1,
      "name": "Rock_Aqua_Cobble"
    },
    {
      "x": -21,
      "y": 29,
      "z": 1,
      "name": "Rock_Aqua_Cobble"
    },
    {
      "x": -21,
      "y": 30,
      "z": 1,
      "name": "Plant_Crop_Mushroom_Glowing_Blue"
    },
    {
      "x": -21,
      "y": 26,
      "z": 2,
      "name": "Rock_Aqua_Brick"
    },
    {
      "x": -21,
      "y": 27,
      "z": 2,
      "name": "Rock_Aqua_Brick"
    },
    {
      "x": -21,
      "y": 28,
      "z": 2,
      "name": "Rock_Aqua_Cobble"
    },
    {
      "x": -21,
      "y": 29,
      "z": 2,
      "name": "Rock_Aqua_Brick"
    },
    {
      "x": -21,
      "y": 30,
      "z": 2,
      "name": "Rock_Aqua_Cobble"
    },
    {
      "x": -21,
      "y": 31,
      "z": 2,
      "name": "Plant_Coral_Model_Cyan"
    },
    {
      "x": -21,
      "y": 25,
      "z": 3,
      "name": "Rock_Aqua_Brick_Smooth"
    },
    {
      "x": -21,
      "y": 26,
      "z": 3,
      "name": "Rock_Aqua_Cobble"
    },
    {
      "x": -21,
      "y": 27,
      "z": 3,
      "name": "Rock_Aqua_Cobble"
    },
    {
      "x": -21,
      "y": 25,
      "z": 4,
      "name": "Rock_Aqua_Brick_Smooth"
    },
    {
      "x": -21,
      "y": 26,
      "z": 4,
      "name": "Rock_Aqua_Cobble"
    },
    {
      "x": -21,
      "y": 27,
      "z": 4,
      "name": "Rock_Aqua_Brick"
    },
    {
      "x": -21,
      "y": 24,
      "z": 5,
      "name": "Rock_Aqua_Stalactite_Large",
      "filler": 31744,
      "rotation": 8
    },
    {
      "x": -21,
      "y": 25,
      "z": 5,
      "name": "Rock_Aqua_Stalactite_Large",
      "rotation": 8
    },
    {
      "x": -21,
      "y": 26,
      "z": 5,
      "name": "Rock_Aqua_Brick"
    },
    {
      "x": -21,
      "y": 27,
      "z": 5,
      "name": "Rock_Aqua_Cobble"
    },
    {
      "x": -21,
      "y": 28,
      "z": 5,
      "name": "Rock_Aqua_Cobble"
    },
    {
      "x": -21,
      "y": 29,
      "z": 5,
      "name": "Rock_Aqua_Brick"
    },
    {
      "x": -21,
      "y": 30,
      "z": 5,
      "name": "Rock_Aqua_Cobble"
    },
    {
      "x": -21,
      "y": 31,
      "z": 5,
      "name": "Plant_Coral_Bush_Cyan"
    },
    {
      "x": -21,
      "y": 26,
      "z": 6,
      "name": "Rock_Aqua_Cobble"
    },
    {
      "x": -21,
      "y": 27,
      "z": 6,
      "name": "Rock_Aqua_Brick"
    },
    {
      "x": -21,
      "y": 28,
      "z": 6,
      "name": "Rock_Aqua_Brick"
    },
    {
      "x": -21,
      "y": 30,
      "z": 6,
      "name": "Rock_Aqua_Brick"
    },
    {
      "x": -21,
      "y": 27,
      "z": 7,
      "name": "Rock_Aqua_Brick"
    },
    {
      "x": -21,
      "y": 28,
      "z": 7,
      "name": "Rock_Aqua_Cobble"
    },
    {
      "x": -21,
      "y": 29,
      "z": 7,
      "name": "Rock_Aqua_Brick"
    },
    {
      "x": -21,
      "y": 30,
      "z": 7,
      "name": "Rock_Aqua_Cobble"
    },
    {
      "x": -21,
      "y": 31,
      "z": 7,
      "name": "Plant_Coral_Bush_Blue"
    },
    {
      "x": -20,
      "y": 32,
      "z": -10,
      "name": "Rock_Aqua"
    },
    {
      "x": -20,
      "y": 30,
      "z": -9,
      "name": "Rock_Aqua"
    },
    {
      "x": -20,
      "y": 31,
      "z": -9,
      "name": "Rock_Aqua_Brick_Smooth"
    },
    {
      "x": -20,
      "y": 32,
      "z": -9,
      "name": "Rock_Aqua"
    },
    {
      "x": -20,
      "y": 33,
      "z": -9,
      "name": "Rock_Aqua_Brick_Smooth"
    },
    {
      "x": -20,
      "y": 34,
      "z": -9,
      "name": "Rock_Aqua_Brick_Smooth"
    },
    {
      "x": -20,
      "y": 30,
      "z": -8,
      "name": "Rock_Aqua_Brick_Smooth"
    },
    {
      "x": -20,
      "y": 31,
      "z": -8,
      "name": "Rock_Aqua_Brick_Smooth"
    },
    {
      "x": -20,
      "y": 32,
      "z": -8,
      "name": "Rock_Aqua_Brick_Smooth"
    },
    {
      "x": -20,
      "y": 33,
      "z": -8,
      "name": "Rock_Aqua_Brick_Smooth"
    },
    {
      "x": -20,
      "y": 34,
      "z": -8,
      "name": "Rock_Aqua_Brick_Smooth"
    },
    {
      "x": -20,
      "y": 30,
      "z": -7,
      "name": "Rock_Aqua_Brick_Smooth"
    },
    {
      "x": -20,
      "y": 31,
      "z": -7,
      "name": "Rock_Aqua"
    },
    {
      "x": -20,
      "y": 32,
      "z": -7,
      "name": "Rock_Aqua_Brick_Smooth"
    },
    {
      "x": -20,
      "y": 33,
      "z": -7,
      "name": "Rock_Aqua_Brick_Smooth"
    },
    {
      "x": -20,
      "y": 34,
      "z": -7,
      "name": "Rock_Aqua_Brick_Smooth"
    },
    {
      "x": -20,
      "y": 31,
      "z": -6,
      "name": "Rock_Aqua_Brick_Smooth"
    },
    {
      "x": -20,
      "y": 32,
      "z": -6,
      "name": "Rock_Aqua"
    },
    {
      "x": -20,
      "y": 33,
      "z": -6,
      "name": "Rock_Aqua_Brick_Smooth"
    },
    {
      "x": -20,
      "y": 32,
      "z": -5,
      "name": "Rock_Aqua_Brick_Smooth"
    },
    {
      "x": -20,
      "y": 33,
      "z": -5,
      "name": "Plant_Crop_Mushroom_Glowing_Blue"
    },
    {
      "x": -20,
      "y": 27,
      "z": 0,
      "name": "Rock_Aqua_Brick_Smooth"
    },
    {
      "x": -20,
      "y": 28,
      "z": 0,
      "name": "Rock_Aqua_Cobble"
    },
    {
      "x": -20,
      "y": 29,
      "z": 0,
      "name": "Rock_Aqua_Brick"
    },
    {
      "x": -20,
      "y": 26,
      "z": 1,
      "name": "Rock_Aqua_Brick_Smooth"
    },
    {
      "x": -20,
      "y": 28,
      "z": 1,
      "name": "Rock_Aqua_Cobble"
    },
    {
      "x": -20,
      "y": 29,
      "z": 1,
      "name": "Rock_Aqua_Cobble"
    },
    {
      "x": -20,
      "y": 30,
      "z": 1,
      "name": "Rock_Aqua_Cobble"
    },
    {
      "x": -20,
      "y": 25,
      "z": 2,
      "name": "Rock_Aqua_Brick_Smooth"
    },
    {
      "x": -20,
      "y": 26,
      "z": 2,
      "name": "Rock_Aqua_Cobble"
    },
    {
      "x": -20,
      "y": 27,
      "z": 2,
      "name": "Rock_Aqua_Brick"
    },
    {
      "x": -20,
      "y": 28,
      "z": 2,
      "name": "Rock_Aqua_Brick"
    },
    {
      "x": -20,
      "y": 29,
      "z": 2,
      "name": "Rock_Aqua_Brick"
    },
    {
      "x": -20,
      "y": 30,
      "z": 2,
      "name": "Rock_Aqua_Cobble"
    },
    {
      "x": -20,
      "y": 31,
      "z": 2,
      "name": "Rock_Aqua_Cobble"
    },
    {
      "x": -20,
      "y": 32,
      "z": 2,
      "name": "Plant_Coral_Model_Cyan"
    },
    {
      "x": -20,
      "y": 22,
      "z": 3,
      "name": "Rock_Aqua_Stalactite_Large",
      "filler": 31744,
      "rotation": 8
    },
    {
      "x": -20,
      "y": 23,
      "z": 3,
      "name": "Rock_Aqua_Stalactite_Large",
      "rotation": 8
    },
    {
      "x": -20,
      "y": 24,
      "z": 3,
      "name": "Rock_Aqua_Brick_Smooth"
    },
    {
      "x": -20,
      "y": 25,
      "z": 3,
      "name": "Rock_Aqua_Brick_Smooth"
    },
    {
      "x": -20,
      "y": 26,
      "z": 3,
      "name": "Rock_Aqua_Brick"
    },
    {
      "x": -20,
      "y": 27,
      "z": 3,
      "name": "Rock_Aqua_Cobble"
    },
    {
      "x": -20,
      "y": 28,
      "z": 3,
      "name": "Rock_Aqua_Brick"
    },
    {
      "x": -20,
      "y": 29,
      "z": 3,
      "name": "Rock_Aqua_Brick"
    },
    {
      "x": -20,
      "y": 30,
      "z": 3,
      "name": "Rock_Aqua_Cobble"
    },
    {
      "x": -20,
      "y": 31,
      "z": 3,
      "name": "Rock_Aqua_Cobble"
    },
    {
      "x": -20,
      "y": 24,
      "z": 4,
      "name": "Rock_Aqua_Brick_Smooth"
    },
    {
      "x": -20,
      "y": 25,
      "z": 4,
      "name": "Rock_Aqua_Brick_Smooth"
    },
    {
      "x": -20,
      "y": 26,
      "z": 4,
      "name": "Rock_Aqua_Cobble"
    },
    {
      "x": -20,
      "y": 27,
      "z": 4,
      "name": "Rock_Aqua_Cobble"
    },
    {
      "x": -20,
      "y": 24,
      "z": 5,
      "name": "Rock_Aqua_Brick_Smooth"
    },
    {
      "x": -20,
      "y": 25,
      "z": 5,
      "name": "Rock_Aqua_Brick_Smooth"
    },
    {
      "x": -20,
      "y": 26,
      "z": 5,
      "name": "Rock_Aqua_Cobble"
    },
    {
      "x": -20,
      "y": 27,
      "z": 5,
      "name": "Rock_Aqua_Cobble"
    },
    {
      "x": -20,
      "y": 29,
      "z": 5,
      "name": "Rock_Aqua_Brick"
    },
    {
      "x": -20,
      "y": 30,
      "z": 5,
      "name": "Rock_Aqua_Cobble"
    },
    {
      "x": -20,
      "y": 31,
      "z": 5,
      "name": "Rock_Aqua_Cobble"
    },
    {
      "x": -20,
      "y": 25,
      "z": 6,
      "name": "Rock_Aqua_Brick_Smooth"
    },
    {
      "x": -20,
      "y": 26,
      "z": 6,
      "name": "Rock_Aqua_Brick"
    },
    {
      "x": -20,
      "y": 27,
      "z": 6,
      "name": "Rock_Aqua_Brick"
    },
    {
      "x": -20,
      "y": 28,
      "z": 6,
      "name": "Rock_Aqua_Brick"
    },
    {
      "x": -20,
      "y": 29,
      "z": 6,
      "name": "Rock_Aqua_Brick"
    },
    {
      "x": -20,
      "y": 31,
      "z": 6,
      "name": "Rock_Aqua_Cobble"
    },
    {
      "x": -20,
      "y": 26,
      "z": 7,
      "name": "Rock_Aqua_Cobble"
    },
    {
      "x": -20,
      "y": 27,
      "z": 7,
      "name": "Rock_Aqua_Brick"
    },
    {
      "x": -20,
      "y": 28,
      "z": 7,
      "name": "Rock_Aqua_Brick"
    },
    {
      "x": -20,
      "y": 29,
      "z": 7,
      "name": "Rock_Aqua_Cobble"
    },
    {
      "x": -20,
      "y": 30,
      "z": 7,
      "name": "Rock_Aqua_Brick"
    },
    {
      "x": -20,
      "y": 31,
      "z": 7,
      "name": "Plant_Coral_Model_Cyan"
    },
    {
      "x": -20,
      "y": 25,
      "z": 8,
      "name": "Rock_Aqua_Stalactite_Large",
      "filler": 31744,
      "rotation": 8
    },
    {
      "x": -20,
      "y": 26,
      "z": 8,
      "name": "Rock_Aqua_Stalactite_Large",
      "rotation": 8
    },
    {
      "x": -20,
      "y": 27,
      "z": 8,
      "name": "Rock_Aqua_Brick"
    },
    {
      "x": -20,
      "y": 28,
      "z": 8,
      "name": "Rock_Aqua_Brick"
    },
    {
      "x": -20,
      "y": 29,
      "z": 8,
      "name": "Rock_Aqua_Cobble"
    },
    {
      "x": -20,
      "y": 30,
      "z": 8,
      "name": "Rock_Aqua_Brick"
    },
    {
      "x": -20,
      "y": 31,
      "z": 8,
      "name": "Plant_Coral_Model_Cyan"
    },
    {
      "x": -19,
      "y": 23,
      "z": -14,
      "name": "Rock_Aqua_Cobble"
    },
    {
      "x": -19,
      "y": 24,
      "z": -14,
      "name": "Rock_Aqua_Brick"
    },
    {
      "x": -19,
      "y": 23,
      "z": -12,
      "name": "Rock_Aqua_Cobble"
    },
    {
      "x": -19,
      "y": 24,
      "z": -12,
      "name": "Rock_Aqua_Brick"
    },
    {
      "x": -19,
      "y": 31,
      "z": -9,
      "name": "Rock_Aqua"
    },
    {
      "x": -19,
      "y": 32,
      "z": -9,
      "name": "Rock_Aqua"
    },
    {
      "x": -19,
      "y": 33,
      "z": -9,
      "name": "Rock_Aqua"
    },
    {
      "x": -19,
      "y": 30,
      "z": -8,
      "name": "Rock_Aqua"
    },
    {
      "x": -19,
      "y": 31,
      "z": -8,
      "name": "Rock_Aqua"
    },
    {
      "x": -19,
      "y": 32,
      "z": -8,
      "name": "Rock_Aqua"
    },
    {
      "x": -19,
      "y": 33,
      "z": -8,
      "name": "Rock_Aqua_Brick_Smooth"
    },
    {
      "x": -19,
      "y": 34,
      "z": -8,
      "name": "Rock_Aqua_Brick_Smooth"
    },
    {
      "x": -19,
      "y": 31,
      "z": -7,
      "name": "Rock_Aqua_Brick_Smooth"
    },
    {
      "x": -19,
      "y": 32,
      "z": -7,
      "name": "Rock_Aqua_Brick_Smooth"
    },
    {
      "x": -19,
      "y": 33,
      "z": -7,
      "name": "Rock_Aqua_Brick_Smooth"
    },
    {
      "x": -19,
      "y": 31,
      "z": -6,
      "name": "Rock_Aqua_Brick_Smooth"
    },
    {
      "x": -19,
      "y": 32,
      "z": -6,
      "name": "Rock_Aqua_Brick_Smooth"
    },
    {
      "x": -19,
      "y": 33,
      "z": -6,
      "name": "Rock_Aqua_Brick_Smooth"
    },
    {
      "x": -19,
      "y": 28,
      "z": -1,
      "name": "Rock_Aqua_Brick"
    },
    {
      "x": -19,
      "y": 25,
      "z": 0,
      "name": "Rock_Aqua_Stalactite_Small",
      "rotation": 8
    },
    {
      "x": -19,
      "y": 26,
      "z": 0,
      "name": "Rock_Aqua_Brick_Smooth"
    },
    {
      "x": -19,
      "y": 27,
      "z": 0,
      "name": "Rock_Aqua_Brick_Smooth"
    },
    {
      "x": -19,
      "y": 28,
      "z": 0,
      "name": "Rock_Aqua_Brick"
    },
    {
      "x": -19,
      "y": 29,
      "z": 0,
      "name": "Rock_Aqua_Brick"
    },
    {
      "x": -19,
      "y": 30,
      "z": 0,
      "name": "Rock_Aqua_Cobble"
    },
    {
      "x": -19,
      "y": 31,
      "z": 0,
      "name": "Plant_Coral_Model_Blue"
    },
    {
      "x": -19,
      "y": 25,
      "z": 1,
      "name": "Rock_Aqua_Brick_Smooth"
    },
    {
      "x": -19,
      "y": 26,
      "z": 1,
      "name": "Rock_Aqua_Brick_Smooth"
    },
    {
      "x": -19,
      "y": 27,
      "z": 1,
      "name": "Rock_Aqua_Brick_Smooth"
    },
    {
      "x": -19,
      "y": 28,
      "z": 1,
      "name": "Rock_Aqua_Brick"
    },
    {
      "x": -19,
      "y": 29,
      "z": 1,
      "name": "Rock_Aqua_Cobble"
    },
    {
      "x": -19,
      "y": 30,
      "z": 1,
      "name": "Rock_Aqua_Brick"
    },
    {
      "x": -19,
      "y": 31,
      "z": 1,
      "name": "Rock_Aqua_Brick"
    },
    {
      "x": -19,
      "y": 23,
      "z": 2,
      "name": "Rock_Crystal_Cyan_Large",
      "rotation": 8
    },
    {
      "x": -19,
      "y": 24,
      "z": 2,
      "name": "Rock_Aqua_Brick_Smooth"
    },
    {
      "x": -19,
      "y": 25,
      "z": 2,
      "name": "Rock_Aqua_Brick_Smooth"
    },
    {
      "x": -19,
      "y": 26,
      "z": 2,
      "name": "Rock_Aqua_Brick"
    },
    {
      "x": -19,
      "y": 27,
      "z": 2,
      "name": "Rock_Aqua_Cobble"
    },
    {
      "x": -19,
      "y": 28,
      "z": 2,
      "name": "Rock_Aqua_Brick"
    },
    {
      "x": -19,
      "y": 29,
      "z": 2,
      "name": "Rock_Aqua_Cobble"
    },
    {
      "x": -19,
      "y": 30,
      "z": 2,
      "name": "Rock_Aqua_Cobble"
    },
    {
      "x": -19,
      "y": 31,
      "z": 2,
      "name": "Rock_Aqua_Brick"
    },
    {
      "x": -19,
      "y": 23,
      "z": 3,
      "name": "Rock_Aqua_Brick_Smooth"
    },
    {
      "x": -19,
      "y": 24,
      "z": 3,
      "name": "Rock_Aqua_Brick_Smooth"
    },
    {
      "x": -19,
      "y": 25,
      "z": 3,
      "name": "Rock_Aqua_Brick_Smooth"
    },
    {
      "x": -19,
      "y": 26,
      "z": 3,
      "name": "Rock_Aqua_Brick"
    },
    {
      "x": -19,
      "y": 27,
      "z": 3,
      "name": "Rock_Aqua_Brick"
    },
    {
      "x": -19,
      "y": 28,
      "z": 3,
      "name": "Rock_Aqua_Cobble"
    },
    {
      "x": -19,
      "y": 29,
      "z": 3,
      "name": "Rock_Aqua_Cobble"
    },
    {
      "x": -19,
      "y": 30,
      "z": 3,
      "name": "Rock_Aqua_Brick"
    },
    {
      "x": -19,
      "y": 31,
      "z": 3,
      "name": "Rock_Aqua_Brick"
    },
    {
      "x": -19,
      "y": 23,
      "z": 4,
      "name": "Rock_Aqua_Brick_Smooth"
    },
    {
      "x": -19,
      "y": 24,
      "z": 4,
      "name": "Rock_Aqua_Brick_Smooth"
    },
    {
      "x": -19,
      "y": 25,
      "z": 4,
      "name": "Rock_Aqua_Brick_Smooth"
    },
    {
      "x": -19,
      "y": 26,
      "z": 4,
      "name": "Rock_Aqua_Brick"
    },
    {
      "x": -19,
      "y": 27,
      "z": 4,
      "name": "Rock_Aqua_Cobble"
    },
    {
      "x": -19,
      "y": 28,
      "z": 4,
      "name": "Rock_Aqua_Cobble"
    },
    {
      "x": -19,
      "y": 29,
      "z": 4,
      "name": "Rock_Aqua_Cobble"
    },
    {
      "x": -19,
      "y": 30,
      "z": 4,
      "name": "Rock_Aqua_Brick"
    },
    {
      "x": -19,
      "y": 31,
      "z": 4,
      "name": "Rock_Aqua_Brick"
    },
    {
      "x": -19,
      "y": 21,
      "z": 5,
      "name": "Rock_Aqua_Stalactite_Large",
      "filler": 31744,
      "rotation": 8
    },
    {
      "x": -19,
      "y": 22,
      "z": 5,
      "name": "Rock_Aqua_Stalactite_Large",
      "rotation": 8
    },
    {
      "x": -19,
      "y": 23,
      "z": 5,
      "name": "Rock_Aqua_Brick_Smooth"
    },
    {
      "x": -19,
      "y": 24,
      "z": 5,
      "name": "Rock_Aqua_Brick_Smooth"
    },
    {
      "x": -19,
      "y": 25,
      "z": 5,
      "name": "Rock_Aqua_Brick_Smooth"
    },
    {
      "x": -19,
      "y": 26,
      "z": 5,
      "name": "Rock_Aqua_Brick"
    },
    {
      "x": -19,
      "y": 27,
      "z": 5,
      "name": "Rock_Aqua_Cobble"
    },
    {
      "x": -19,
      "y": 28,
      "z": 5,
      "name": "Rock_Aqua_Cobble"
    },
    {
      "x": -19,
      "y": 29,
      "z": 5,
      "name": "Rock_Aqua_Cobble"
    },
    {
      "x": -19,
      "y": 24,
      "z": 6,
      "name": "Rock_Aqua_Brick_Smooth"
    },
    {
      "x": -19,
      "y": 25,
      "z": 6,
      "name": "Rock_Aqua_Brick_Smooth"
    },
    {
      "x": -19,
      "y": 26,
      "z": 6,
      "name": "Rock_Aqua_Cobble"
    },
    {
      "x": -19,
      "y": 27,
      "z": 6,
      "name": "Rock_Aqua_Brick"
    },
    {
      "x": -19,
      "y": 29,
      "z": 6,
      "name": "Rock_Aqua_Brick"
    },
    {
      "x": -19,
      "y": 31,
      "z": 6,
      "name": "Rock_Aqua_Cobble"
    },
    {
      "x": -19,
      "y": 24,
      "z": 7,
      "name": "Rock_Aqua_Brick_Smooth"
    },
    {
      "x": -19,
      "y": 25,
      "z": 7,
      "name": "Rock_Aqua_Brick_Smooth"
    },
    {
      "x": -19,
      "y": 26,
      "z": 7,
      "name": "Rock_Aqua_Brick"
    },
    {
      "x": -19,
      "y": 27,
      "z": 7,
      "name": "Rock_Aqua_Cobble"
    },
    {
      "x": -19,
      "y": 28,
      "z": 7,
      "name": "Rock_Aqua_Cobble"
    },
    {
      "x": -19,
      "y": 29,
      "z": 7,
      "name": "Rock_Aqua_Cobble"
    },
    {
      "x": -19,
      "y": 30,
      "z": 7,
      "name": "Rock_Aqua_Cobble"
    },
    {
      "x": -19,
      "y": 31,
      "z": 7,
      "name": "Rock_Aqua_Brick"
    },
    {
      "x": -19,
      "y": 24,
      "z": 8,
      "name": "Rock_Crystal_Cyan_Large",
      "rotation": 8
    },
    {
      "x": -19,
      "y": 25,
      "z": 8,
      "name": "Rock_Aqua_Brick_Smooth"
    },
    {
      "x": -19,
      "y": 26,
      "z": 8,
      "name": "Rock_Aqua_Brick"
    },
    {
      "x": -19,
      "y": 27,
      "z": 8,
      "name": "Rock_Aqua_Brick"
    },
    {
      "x": -19,
      "y": 28,
      "z": 8,
      "name": "Rock_Aqua_Cobble"
    },
    {
      "x": -19,
      "y": 29,
      "z": 8,
      "name": "Rock_Aqua_Cobble"
    },
    {
      "x": -19,
      "y": 30,
      "z": 8,
      "name": "Rock_Aqua_Brick"
    },
    {
      "x": -19,
      "y": 31,
      "z": 8,
      "name": "Plant_Coral_Model_Blue"
    },
    {
      "x": -19,
      "y": 27,
      "z": 9,
      "name": "Rock_Aqua_Cobble"
    },
    {
      "x": -19,
      "y": 28,
      "z": 9,
      "name": "Rock_Aqua_Cobble"
    },
    {
      "x": -19,
      "y": 21,
      "z": 12,
      "name": "Rock_Aqua_Brick_Smooth"
    },
    {
      "x": -19,
      "y": 20,
      "z": 13,
      "name": "Rock_Aqua_Brick_Smooth"
    },
    {
      "x": -19,
      "y": 21,
      "z": 13,
      "name": "Rock_Aqua"
    },
    {
      "x": -19,
      "y": 22,
      "z": 13,
      "name": "Rock_Aqua_Brick_Smooth"
    },
    {
      "x": -19,
      "y": 20,
      "z": 14,
      "name": "Rock_Aqua_Brick_Smooth"
    },
    {
      "x": -19,
      "y": 21,
      "z": 14,
      "name": "Rock_Aqua"
    },
    {
      "x": -19,
      "y": 22,
      "z": 14,
      "name": "Rock_Aqua"
    },
    {
      "x": -19,
      "y": 20,
      "z": 15,
      "name": "Rock_Aqua_Brick_Smooth"
    },
    {
      "x": -19,
      "y": 21,
      "z": 15,
      "name": "Rock_Aqua_Brick_Smooth"
    },
    {
      "x": -19,
      "y": 22,
      "z": 15,
      "name": "Rock_Aqua"
    },
    {
      "x": -19,
      "y": 21,
      "z": 16,
      "name": "Rock_Aqua_Brick_Smooth"
    },
    {
      "x": -18,
      "y": 22,
      "z": -15,
      "name": "Rock_Crystal_Cyan_Large",
      "rotation": 8
    },
    {
      "x": -18,
      "y": 23,
      "z": -15,
      "name": "Rock_Aqua_Cobble"
    },
    {
      "x": -18,
      "y": 24,
      "z": -15,
      "name": "Rock_Aqua_Brick"
    },
    {
      "x": -18,
      "y": 22,
      "z": -14,
      "name": "Rock_Aqua_Cobble"
    },
    {
      "x": -18,
      "y": 23,
      "z": -14,
      "name": "Rock_Aqua_Brick"
    },
    {
      "x": -18,
      "y": 24,
      "z": -14,
      "name": "Rock_Aqua_Cobble"
    },
    {
      "x": -18,
      "y": 25,
      "z": -14,
      "name": "Rock_Aqua_Brick"
    },
    {
      "x": -18,
      "y": 22,
      "z": -13,
      "name": "Rock_Aqua_Cobble"
    },
    {
      "x": -18,
      "y": 23,
      "z": -13,
      "name": "Rock_Aqua_Cobble"
    },
    {
      "x": -18,
      "y": 24,
      "z": -13,
      "name": "Rock_Aqua_Brick"
    },
    {
      "x": -18,
      "y": 25,
      "z": -13,
      "name": "Rock_Aqua_Cobble"
    },
    {
      "x": -18,
      "y": 26,
      "z": -13,
      "name": "Plant_Coral_Bush_Cyan"
    },
    {
      "x": -18,
      "y": 24,
      "z": -12,
      "name": "Rock_Aqua_Brick"
    },
    {
      "x": -18,
      "y": 22,
      "z": -11,
      "name": "Rock_Aqua_Brick_Smooth"
    },
    {
      "x": -18,
      "y": 23,
      "z": -11,
      "name": "Rock_Aqua_Cobble"
    },
    {
      "x": -18,
      "y": 24,
      "z": -11,
      "name": "Rock_Aqua_Cobble"
    },
    {
      "x": -18,
      "y": 25,
      "z": -11,
      "name": "Rock_Aqua_Cobble"
    },
    {
      "x": -18,
      "y": 26,
      "z": -11,
      "name": "Plant_Crop_Mushroom_Glowing_Blue"
    },
    {
      "x": -18,
      "y": 24,
      "z": -10,
      "name": "Rock_Aqua_Brick"
    },
    {
      "x": -18,
      "y": 25,
      "z": -10,
      "name": "Plant_Coral_Model_Blue"
    },
    {
      "x": -18,
      "y": 32,
      "z": -8,
      "name": "Rock_Aqua_Brick_Smooth"
    },
    {
      "x": -18,
      "y": 32,
      "z": -7,
      "name": "Rock_Aqua_Brick_Smooth"
    },
    {
      "x": -18,
      "y": 27,
      "z": -1,
      "name": "Rock_Aqua_Brick_Smooth"
    },
    {
      "x": -18,
      "y": 28,
      "z": -1,
      "name": "Rock_Aqua_Cobble"
    },
    {
      "x": -18,
      "y": 29,
      "z": -1,
      "name": "Rock_Aqua_Cobble"
    },
    {
      "x": -18,
      "y": 26,
      "z": 0,
      "name": "Rock_Aqua_Brick_Smooth"
    },
    {
      "x": -18,
      "y": 27,
      "z": 0,
      "name": "Rock_Aqua_Brick_Smooth"
    },
    {
      "x": -18,
      "y": 28,
      "z": 0,
      "name": "Rock_Aqua_Brick"
    },
    {
      "x": -18,
      "y": 29,
      "z": 0,
      "name": "Rock_Aqua_Brick"
    },
    {
      "x": -18,
      "y": 30,
      "z": 0,
      "name": "Rock_Aqua_Cobble"
    },
    {
      "x": -18,
      "y": 24,
      "z": 1,
      "name": "Rock_Aqua_Brick_Smooth"
    },
    {
      "x": -18,
      "y": 25,
      "z": 1,
      "name": "Rock_Aqua_Brick_Smooth"
    },
    {
      "x": -18,
      "y": 26,
      "z": 1,
      "name": "Rock_Aqua_Brick_Smooth"
    },
    {
      "x": -18,
      "y": 27,
      "z": 1,
      "name": "Rock_Aqua_Brick_Smooth"
    },
    {
      "x": -18,
      "y": 28,
      "z": 1,
      "name": "Rock_Aqua_Cobble"
    },
    {
      "x": -18,
      "y": 29,
      "z": 1,
      "name": "Rock_Aqua_Cobble"
    },
    {
      "x": -18,
      "y": 30,
      "z": 1,
      "name": "Rock_Aqua_Brick"
    },
    {
      "x": -18,
      "y": 31,
      "z": 1,
      "name": "Rock_Aqua_Cobble"
    },
    {
      "x": -18,
      "y": 24,
      "z": 2,
      "name": "Rock_Aqua_Brick_Smooth"
    },
    {
      "x": -18,
      "y": 25,
      "z": 2,
      "name": "Rock_Aqua_Brick_Smooth"
    },
    {
      "x": -18,
      "y": 28,
      "z": 2,
      "name": "Rock_Aqua_Cobble"
    },
    {
      "x": -18,
      "y": 29,
      "z": 2,
      "name": "Rock_Aqua_Cobble"
    },
    {
      "x": -18,
      "y": 30,
      "z": 2,
      "name": "Rock_Aqua_Brick"
    },
    {
      "x": -18,
      "y": 31,
      "z": 2,
      "name": "Rock_Aqua_Cobble"
    },
    {
      "x": -18,
      "y": 32,
      "z": 2,
      "name": "Plant_Coral_Bush_Blue"
    },
    {
      "x": -18,
      "y": 23,
      "z": 3,
      "name": "Rock_Aqua_Brick_Smooth"
    },
    {
      "x": -18,
      "y": 24,
      "z": 3,
      "name": "Rock_Aqua_Brick_Smooth"
    },
    {
      "x": -18,
      "y": 25,
      "z": 3,
      "name": "Rock_Aqua_Brick_Smooth"
    },
    {
      "x": -18,
      "y": 26,
      "z": 3,
      "name": "Rock_Aqua_Brick"
    },
    {
      "x": -18,
      "y": 27,
      "z": 3,
      "name": "Rock_Aqua_Brick"
    },
    {
      "x": -18,
      "y": 28,
      "z": 3,
      "name": "Rock_Aqua_Cobble"
    },
    {
      "x": -18,
      "y": 29,
      "z": 3,
      "name": "Rock_Aqua_Brick"
    },
    {
      "x": -18,
      "y": 30,
      "z": 3,
      "name": "Rock_Aqua_Cobble"
    },
    {
      "x": -18,
      "y": 31,
      "z": 3,
      "name": "Rock_Aqua_Brick"
    },
    {
      "x": -18,
      "y": 22,
      "z": 4,
      "name": "Rock_Crystal_Cyan_Large",
      "rotation": 8
    },
    {
      "x": -18,
      "y": 23,
      "z": 4,
      "name": "Rock_Aqua_Brick_Smooth"
    },
    {
      "x": -18,
      "y": 24,
      "z": 4,
      "name": "Rock_Aqua_Brick_Smooth"
    },
    {
      "x": -18,
      "y": 25,
      "z": 4,
      "name": "Rock_Aqua_Brick_Smooth"
    },
    {
      "x": -18,
      "y": 26,
      "z": 4,
      "name": "Rock_Aqua_Brick"
    },
    {
      "x": -18,
      "y": 27,
      "z": 4,
      "name": "Rock_Aqua_Brick"
    },
    {
      "x": -18,
      "y": 28,
      "z": 4,
      "name": "Rock_Aqua_Brick"
    },
    {
      "x": -18,
      "y": 29,
      "z": 4,
      "name": "Rock_Aqua_Cobble"
    },
    {
      "x": -18,
      "y": 30,
      "z": 4,
      "name": "Rock_Aqua_Brick"
    },
    {
      "x": -18,
      "y": 31,
      "z": 4,
      "name": "Rock_Aqua_Brick"
    },
    {
      "x": -18,
      "y": 32,
      "z": 4,
      "name": "Plant_Crop_Mushroom_Glowing_Blue"
    },
    {
      "x": -18,
      "y": 23,
      "z": 5,
      "name": "Rock_Aqua_Brick_Smooth"
    },
    {
      "x": -18,
      "y": 24,
      "z": 5,
      "name": "Rock_Aqua_Brick_Smooth"
    },
    {
      "x": -18,
      "y": 25,
      "z": 5,
      "name": "Rock_Aqua_Brick_Smooth"
    },
    {
      "x": -18,
      "y": 26,
      "z": 5,
      "name": "Rock_Aqua_Brick"
    },
    {
      "x": -18,
      "y": 27,
      "z": 5,
      "name": "Rock_Aqua_Cobble"
    },
    {
      "x": -18,
      "y": 28,
      "z": 5,
      "name": "Plant_Coral_Bush_Blue"
    },
    {
      "x": -18,
      "y": 23,
      "z": 6,
      "name": "Rock_Aqua_Brick_Smooth"
    },
    {
      "x": -18,
      "y": 24,
      "z": 6,
      "name": "Rock_Aqua_Brick_Smooth"
    },
    {
      "x": -18,
      "y": 25,
      "z": 6,
      "name": "Rock_Aqua_Brick_Smooth"
    },
    {
      "x": -18,
      "y": 26,
      "z": 6,
      "name": "Rock_Aqua_Brick"
    },
    {
      "x": -18,
      "y": 27,
      "z": 6,
      "name": "Rock_Aqua_Cobble"
    },
    {
      "x": -18,
      "y": 28,
      "z": 6,
      "name": "Rock_Aqua_Brick"
    },
    {
      "x": -18,
      "y": 29,
      "z": 6,
      "name": "Rock_Aqua_Cobble"
    },
    {
      "x": -18,
      "y": 30,
      "z": 6,
      "name": "Rock_Aqua_Cobble"
    },
    {
      "x": -18,
      "y": 31,
      "z": 6,
      "name": "Rock_Aqua_Brick"
    },
    {
      "x": -18,
      "y": 24,
      "z": 7,
      "name": "Rock_Aqua_Brick_Smooth"
    },
    {
      "x": -18,
      "y": 25,
      "z": 7,
      "name": "Rock_Aqua_Brick_Smooth"
    },
    {
      "x": -18,
      "y": 26,
      "z": 7,
      "name": "Rock_Aqua_Cobble"
    },
    {
      "x": -18,
      "y": 27,
      "z": 7,
      "name": "Rock_Aqua_Cobble"
    },
    {
      "x": -18,
      "y": 28,
      "z": 7,
      "name": "Rock_Aqua_Cobble"
    },
    {
      "x": -18,
      "y": 29,
      "z": 7,
      "name": "Rock_Aqua_Brick"
    },
    {
      "x": -18,
      "y": 30,
      "z": 7,
      "name": "Rock_Aqua_Brick"
    },
    {
      "x": -18,
      "y": 31,
      "z": 7,
      "name": "Rock_Aqua_Cobble"
    },
    {
      "x": -18,
      "y": 32,
      "z": 7,
      "name": "Plant_Crop_Mushroom_Glowing_Blue"
    },
    {
      "x": -18,
      "y": 25,
      "z": 8,
      "name": "Rock_Aqua_Brick_Smooth"
    },
    {
      "x": -18,
      "y": 26,
      "z": 9,
      "name": "Rock_Aqua_Brick_Smooth"
    },
    {
      "x": -18,
      "y": 27,
      "z": 9,
      "name": "Rock_Aqua_Cobble"
    },
    {
      "x": -18,
      "y": 29,
      "z": 9,
      "name": "Rock_Aqua_Cobble"
    },
    {
      "x": -18,
      "y": 28,
      "z": 10,
      "name": "Rock_Aqua_Cobble"
    },
    {
      "x": -18,
      "y": 29,
      "z": 10,
      "name": "Plant_Crop_Mushroom_Glowing_Blue"
    },
    {
      "x": -18,
      "y": 20,
      "z": 11,
      "name": "Rock_Aqua_Brick_Smooth"
    },
    {
      "x": -18,
      "y": 21,
      "z": 11,
      "name": "Rock_Aqua"
    },
    {
      "x": -18,
      "y": 22,
      "z": 11,
      "name": "Rock_Aqua"
    },
    {
      "x": -18,
      "y": 19,
      "z": 12,
      "name": "Rock_Aqua"
    },
    {
      "x": -18,
      "y": 20,
      "z": 12,
      "name": "Rock_Aqua"
    },
    {
      "x": -18,
      "y": 21,
      "z": 12,
      "name": "Rock_Aqua"
    },
    {
      "x": -18,
      "y": 22,
      "z": 12,
      "name": "Rock_Aqua"
    },
    {
      "x": -18,
      "y": 23,
      "z": 12,
      "name": "Rock_Aqua"
    },
    {
      "x": -18,
      "y": 19,
      "z": 13,
      "name": "Rock_Aqua"
    },
    {
      "x": -18,
      "y": 20,
      "z": 13,
      "name": "Rock_Aqua_Brick_Smooth"
    },
    {
      "x": -18,
      "y": 21,
      "z": 13,
      "name": "Rock_Aqua_Brick_Smooth"
    },
    {
      "x": -18,
      "y": 22,
      "z": 13,
      "name": "Rock_Aqua_Brick_Smooth"
    },
    {
      "x": -18,
      "y": 23,
      "z": 13,
      "name": "Rock_Aqua_Brick_Smooth"
    },
    {
      "x": -18,
      "y": 19,
      "z": 14,
      "name": "Rock_Aqua_Brick_Smooth"
    },
    {
      "x": -18,
      "y": 20,
      "z": 14,
      "name": "Rock_Aqua_Brick_Smooth"
    },
    {
      "x": -18,
      "y": 21,
      "z": 14,
      "name": "Rock_Aqua_Brick_Smooth"
    },
    {
      "x": -18,
      "y": 22,
      "z": 14,
      "name": "Rock_Aqua_Brick_Smooth"
    },
    {
      "x": -18,
      "y": 23,
      "z": 14,
      "name": "Rock_Aqua_Brick_Smooth"
    },
    {
      "x": -18,
      "y": 19,
      "z": 15,
      "name": "Rock_Aqua_Brick_Smooth"
    },
    {
      "x": -18,
      "y": 20,
      "z": 15,
      "name": "Rock_Aqua_Brick_Smooth"
    },
    {
      "x": -18,
      "y": 21,
      "z": 15,
      "name": "Rock_Aqua_Brick_Smooth"
    },
    {
      "x": -18,
      "y": 22,
      "z": 15,
      "name": "Rock_Aqua"
    },
    {
      "x": -18,
      "y": 23,
      "z": 15,
      "name": "Rock_Aqua_Brick_Smooth"
    },
    {
      "x": -18,
      "y": 24,
      "z": 15,
      "name": "Plant_Crop_Mushroom_Glowing_Blue"
    },
    {
      "x": -18,
      "y": 19,
      "z": 16,
      "name": "Rock_Aqua_Brick_Smooth"
    },
    {
      "x": -18,
      "y": 20,
      "z": 16,
      "name": "Rock_Aqua_Brick_Smooth"
    },
    {
      "x": -18,
      "y": 21,
      "z": 16,
      "name": "Rock_Aqua_Brick_Smooth"
    },
    {
      "x": -18,
      "y": 22,
      "z": 16,
      "name": "Rock_Aqua_Brick_Smooth"
    },
    {
      "x": -18,
      "y": 23,
      "z": 16,
      "name": "Rock_Aqua"
    },
    {
      "x": -18,
      "y": 20,
      "z": 17,
      "name": "Rock_Aqua"
    },
    {
      "x": -18,
      "y": 21,
      "z": 17,
      "name": "Rock_Aqua"
    },
    {
      "x": -18,
      "y": 22,
      "z": 17,
      "name": "Rock_Aqua"
    },
    {
      "x": -18,
      "y": 20,
      "z": 18,
      "name": "Rock_Aqua"
    },
    {
      "x": -18,
      "y": 21,
      "z": 18,
      "name": "Rock_Aqua"
    },
    {
      "x": -18,
      "y": 22,
      "z": 18,
      "name": "Rock_Aqua"
    },
    {
      "x": -17,
      "y": 24,
      "z": -16,
      "name": "Rock_Aqua_Cobble"
    },
    {
      "x": -17,
      "y": 25,
      "z": -16,
      "name": "Plant_Coral_Bush_Blue"
    },
    {
      "x": -17,
      "y": 22,
      "z": -15,
      "name": "Rock_Aqua_Brick"
    },
    {
      "x": -17,
      "y": 23,
      "z": -15,
      "name": "Rock_Aqua_Brick"
    },
    {
      "x": -17,
      "y": 24,
      "z": -15,
      "name": "Rock_Aqua_Cobble"
    },
    {
      "x": -17,
      "y": 25,
      "z": -15,
      "name": "Rock_Aqua_Brick"
    },
    {
      "x": -17,
      "y": 22,
      "z": -14,
      "name": "Rock_Aqua_Brick"
    },
    {
      "x": -17,
      "y": 23,
      "z": -14,
      "name": "Rock_Aqua_Cobble"
    },
    {
      "x": -17,
      "y": 24,
      "z": -14,
      "name": "Rock_Aqua_Cobble"
    },
    {
      "x": -17,
      "y": 25,
      "z": -14,
      "name": "Rock_Aqua_Cobble"
    },
    {
      "x": -17,
      "y": 26,
      "z": -14,
      "name": "Rock_Aqua_Cobble"
    },
    {
      "x": -17,
      "y": 27,
      "z": -14,
      "name": "Plant_Coral_Model_Blue"
    },
    {
      "x": -17,
      "y": 21,
      "z": -13,
      "name": "Rock_Aqua_Brick_Smooth"
    },
    {
      "x": -17,
      "y": 22,
      "z": -13,
      "name": "Rock_Aqua_Cobble"
    },
    {
      "x": -17,
      "y": 23,
      "z": -13,
      "name": "Rock_Aqua_Cobble"
    },
    {
      "x": -17,
      "y": 24,
      "z": -13,
      "name": "Rock_Aqua_Cobble"
    },
    {
      "x": -17,
      "y": 25,
      "z": -13,
      "name": "Rock_Aqua_Brick"
    },
    {
      "x": -17,
      "y": 26,
      "z": -13,
      "name": "Rock_Aqua_Brick"
    },
    {
      "x": -17,
      "y": 21,
      "z": -12,
      "name": "Rock_Aqua_Brick_Smooth"
    },
    {
      "x": -17,
      "y": 22,
      "z": -12,
      "name": "Rock_Aqua_Brick"
    },
    {
      "x": -17,
      "y": 23,
      "z": -12,
      "name": "Rock_Aqua_Cobble"
    },
    {
      "x": -17,
      "y": 24,
      "z": -12,
      "name": "Rock_Aqua_Cobble"
    },
    {
      "x": -17,
      "y": 25,
      "z": -12,
      "name": "Rock_Aqua_Brick"
    },
    {
      "x": -17,
      "y": 26,
      "z": -12,
      "name": "Rock_Aqua_Brick"
    },
    {
      "x": -17,
      "y": 22,
      "z": -11,
      "name": "Rock_Crystal_Cyan_Large",
      "rotation": 8
    },
    {
      "x": -17,
      "y": 23,
      "z": -11,
      "name": "Rock_Aqua_Cobble"
    },
    {
      "x": -17,
      "y": 24,
      "z": -11,
      "name": "Plant_Coral_Model_Blue"
    },
    {
      "x": -17,
      "y": 24,
      "z": -10,
      "name": "Rock_Aqua_Brick"
    },
    {
      "x": -17,
      "y": 25,
      "z": -10,
      "name": "Rock_Aqua_Cobble"
    },
    {
      "x": -17,
      "y": 26,
      "z": -10,
      "name": "Plant_Coral_Bush_Blue"
    },
    {
      "x": -17,
      "y": 27,
      "z": -1,
      "name": "Rock_Aqua_Brick_Smooth"
    },
    {
      "x": -17,
      "y": 28,
      "z": -1,
      "name": "Rock_Aqua_Cobble"
    },
    {
      "x": -17,
      "y": 29,
      "z": -1,
      "name": "Rock_Aqua_Brick"
    },
    {
      "x": -17,
      "y": 24,
      "z": 0,
      "name": "Rock_Aqua_Stalactite_Large",
      "filler": 31744,
      "rotation": 8
    },
    {
      "x": -17,
      "y": 25,
      "z": 0,
      "name": "Rock_Aqua_Stalactite_Large",
      "rotation": 8
    },
    {
      "x": -17,
      "y": 26,
      "z": 0,
      "name": "Rock_Aqua_Brick_Smooth"
    },
    {
      "x": -17,
      "y": 27,
      "z": 0,
      "name": "Rock_Aqua_Brick_Smooth"
    },
    {
      "x": -17,
      "y": 28,
      "z": 0,
      "name": "Rock_Aqua_Cobble"
    },
    {
      "x": -17,
      "y": 29,
      "z": 0,
      "name": "Rock_Aqua_Cobble"
    },
    {
      "x": -17,
      "y": 30,
      "z": 0,
      "name": "Rock_Aqua_Brick"
    },
    {
      "x": -17,
      "y": 31,
      "z": 0,
      "name": "Plant_Coral_Bush_Blue"
    },
    {
      "x": -17,
      "y": 24,
      "z": 1,
      "name": "Rock_Aqua_Brick_Smooth"
    },
    {
      "x": -17,
      "y": 25,
      "z": 1,
      "name": "Rock_Aqua_Brick_Smooth"
    },
    {
      "x": -17,
      "y": 26,
      "z": 1,
      "name": "Rock_Aqua_Brick_Smooth"
    },
    {
      "x": -17,
      "y": 27,
      "z": 1,
      "name": "Rock_Aqua_Brick_Smooth"
    },
    {
      "x": -17,
      "y": 28,
      "z": 1,
      "name": "Rock_Aqua_Cobble"
    },
    {
      "x": -17,
      "y": 29,
      "z": 1,
      "name": "Rock_Aqua_Brick"
    },
    {
      "x": -17,
      "y": 30,
      "z": 1,
      "name": "Rock_Aqua_Cobble"
    },
    {
      "x": -17,
      "y": 31,
      "z": 1,
      "name": "Rock_Aqua_Cobble"
    },
    {
      "x": -17,
      "y": 24,
      "z": 2,
      "name": "Rock_Aqua_Brick_Smooth"
    },
    {
      "x": -17,
      "y": 25,
      "z": 2,
      "name": "Rock_Aqua_Brick_Smooth"
    },
    {
      "x": -17,
      "y": 26,
      "z": 2,
      "name": "Rock_Aqua_Brick_Smooth"
    },
    {
      "x": -17,
      "y": 27,
      "z": 2,
      "name": "Rock_Aqua_Brick_Smooth"
    },
    {
      "x": -17,
      "y": 28,
      "z": 2,
      "name": "Rock_Aqua_Cobble"
    },
    {
      "x": -17,
      "y": 29,
      "z": 2,
      "name": "Rock_Aqua_Cobble"
    },
    {
      "x": -17,
      "y": 30,
      "z": 2,
      "name": "Rock_Aqua_Brick"
    },
    {
      "x": -17,
      "y": 31,
      "z": 2,
      "name": "Rock_Aqua_Brick"
    },
    {
      "x": -17,
      "y": 23,
      "z": 3,
      "name": "Rock_Aqua_Brick_Smooth"
    },
    {
      "x": -17,
      "y": 24,
      "z": 3,
      "name": "Rock_Aqua_Brick_Smooth"
    },
    {
      "x": -17,
      "y": 25,
      "z": 3,
      "name": "Rock_Aqua_Brick_Smooth"
    },
    {
      "x": -17,
      "y": 26,
      "z": 3,
      "name": "Rock_Aqua_Brick_Smooth"
    },
    {
      "x": -17,
      "y": 27,
      "z": 3,
      "name": "Rock_Aqua_Brick_Smooth"
    },
    {
      "x": -17,
      "y": 28,
      "z": 3,
      "name": "Rock_Aqua_Cobble"
    },
    {
      "x": -17,
      "y": 29,
      "z": 3,
      "name": "Rock_Aqua_Cobble"
    },
    {
      "x": -17,
      "y": 30,
      "z": 3,
      "name": "Rock_Aqua_Cobble"
    },
    {
      "x": -17,
      "y": 31,
      "z": 3,
      "name": "Rock_Aqua_Brick"
    },
    {
      "x": -17,
      "y": 23,
      "z": 4,
      "name": "Rock_Aqua_Brick_Smooth"
    },
    {
      "x": -17,
      "y": 24,
      "z": 4,
      "name": "Rock_Aqua_Brick_Smooth"
    },
    {
      "x": -17,
      "y": 25,
      "z": 4,
      "name": "Rock_Aqua_Brick_Smooth"
    },
    {
      "x": -17,
      "y": 26,
      "z": 4,
      "name": "Rock_Aqua_Brick"
    },
    {
      "x": -17,
      "y": 27,
      "z": 4,
      "name": "Rock_Aqua_Brick"
    },
    {
      "x": -17,
      "y": 28,
      "z": 4,
      "name": "Rock_Aqua_Cobble"
    },
    {
      "x": -17,
      "y": 29,
      "z": 4,
      "name": "Rock_Aqua_Brick"
    },
    {
      "x": -17,
      "y": 30,
      "z": 4,
      "name": "Rock_Aqua_Cobble"
    },
    {
      "x": -17,
      "y": 31,
      "z": 4,
      "name": "Rock_Aqua_Brick"
    },
    {
      "x": -17,
      "y": 23,
      "z": 5,
      "name": "Rock_Aqua_Brick_Smooth"
    },
    {
      "x": -17,
      "y": 24,
      "z": 5,
      "name": "Rock_Aqua_Brick_Smooth"
    },
    {
      "x": -17,
      "y": 25,
      "z": 5,
      "name": "Rock_Aqua_Brick_Smooth"
    },
    {
      "x": -17,
      "y": 26,
      "z": 5,
      "name": "Rock_Aqua_Cobble"
    },
    {
      "x": -17,
      "y": 27,
      "z": 5,
      "name": "Rock_Aqua_Cobble"
    },
    {
      "x": -17,
      "y": 30,
      "z": 5,
      "name": "Rock_Aqua_Cobble"
    },
    {
      "x": -17,
      "y": 23,
      "z": 6,
      "name": "Rock_Aqua_Brick_Smooth"
    },
    {
      "x": -17,
      "y": 24,
      "z": 6,
      "name": "Rock_Aqua_Brick_Smooth"
    },
    {
      "x": -17,
      "y": 25,
      "z": 6,
      "name": "Rock_Aqua_Brick_Smooth"
    },
    {
      "x": -17,
      "y": 26,
      "z": 6,
      "name": "Rock_Aqua_Brick"
    },
    {
      "x": -17,
      "y": 27,
      "z": 6,
      "name": "Rock_Aqua_Cobble"
    },
    {
      "x": -17,
      "y": 28,
      "z": 6,
      "name": "Rock_Aqua_Brick"
    },
    {
      "x": -17,
      "y": 29,
      "z": 6,
      "name": "Rock_Aqua_Cobble"
    },
    {
      "x": -17,
      "y": 30,
      "z": 6,
      "name": "Rock_Aqua_Brick"
    },
    {
      "x": -17,
      "y": 31,
      "z": 6,
      "name": "Rock_Aqua_Cobble"
    },
    {
      "x": -17,
      "y": 23,
      "z": 7,
      "name": "Rock_Aqua_Stalactite_Small",
      "rotation": 8
    },
    {
      "x": -17,
      "y": 24,
      "z": 7,
      "name": "Rock_Aqua_Brick_Smooth"
    },
    {
      "x": -17,
      "y": 25,
      "z": 7,
      "name": "Rock_Aqua_Brick_Smooth"
    },
    {
      "x": -17,
      "y": 26,
      "z": 7,
      "name": "Rock_Aqua_Brick_Smooth"
    },
    {
      "x": -17,
      "y": 27,
      "z": 7,
      "name": "Rock_Aqua_Cobble"
    },
    {
      "x": -17,
      "y": 28,
      "z": 7,
      "name": "Plant_Coral_Bush_Blue"
    },
    {
      "x": -17,
      "y": 25,
      "z": 8,
      "name": "Rock_Aqua_Brick_Smooth"
    },
    {
      "x": -17,
      "y": 27,
      "z": 8,
      "name": "Rock_Aqua_Brick"
    },
    {
      "x": -17,
      "y": 26,
      "z": 9,
      "name": "Rock_Aqua_Brick_Smooth"
    },
    {
      "x": -17,
      "y": 27,
      "z": 9,
      "name": "Rock_Aqua_Cobble"
    },
    {
      "x": -17,
      "y": 29,
      "z": 9,
      "name": "Rock_Aqua_Brick"
    },
    {
      "x": -17,
      "y": 21,
      "z": 10,
      "name": "Rock_Aqua"
    },
    {
      "x": -17,
      "y": 26,
      "z": 10,
      "name": "Rock_Aqua_Stalactite_Large",
      "filler": 31744,
      "rotation": 8
    },
    {
      "x": -17,
      "y": 27,
      "z": 10,
      "name": "Rock_Aqua_Stalactite_Large",
      "rotation": 8
    },
    {
      "x": -17,
      "y": 28,
      "z": 10,
      "name": "Rock_Aqua_Brick"
    },
    {
      "x": -17,
      "y": 29,
      "z": 10,
      "name": "Plant_Coral_Model_Blue"
    },
    {
      "x": -17,
      "y": 19,
      "z": 11,
      "name": "Rock_Aqua"
    },
    {
      "x": -17,
      "y": 20,
      "z": 11,
      "name": "Rock_Aqua_Brick_Smooth"
    },
    {
      "x": -17,
      "y": 21,
      "z": 11,
      "name": "Rock_Aqua_Brick_Smooth"
    },
    {
      "x": -17,
      "y": 22,
      "z": 11,
      "name": "Rock_Aqua"
    },
    {
      "x": -17,
      "y": 23,
      "z": 11,
      "name": "Rock_Aqua_Brick_Smooth"
    },
    {
      "x": -17,
      "y": 19,
      "z": 12,
      "name": "Rock_Aqua"
    },
    {
      "x": -17,
      "y": 20,
      "z": 12,
      "name": "Rock_Aqua"
    },
    {
      "x": -17,
      "y": 21,
      "z": 12,
      "name": "Rock_Aqua_Brick_Smooth"
    },
    {
      "x": -17,
      "y": 22,
      "z": 12,
      "name": "Rock_Aqua_Brick_Smooth"
    },
    {
      "x": -17,
      "y": 23,
      "z": 12,
      "name": "Rock_Aqua"
    },
    {
      "x": -17,
      "y": 18,
      "z": 13,
      "name": "Rock_Aqua"
    },
    {
      "x": -17,
      "y": 19,
      "z": 13,
      "name": "Rock_Aqua_Brick_Smooth"
    },
    {
      "x": -17,
      "y": 20,
      "z": 13,
      "name": "Rock_Aqua_Brick_Smooth"
    },
    {
      "x": -17,
      "y": 21,
      "z": 13,
      "name": "Rock_Aqua_Brick_Smooth"
    },
    {
      "x": -17,
      "y": 22,
      "z": 13,
      "name": "Rock_Aqua_Brick_Smooth"
    },
    {
      "x": -17,
      "y": 23,
      "z": 13,
      "name": "Rock_Aqua"
    },
    {
      "x": -17,
      "y": 24,
      "z": 13,
      "name": "Rock_Aqua_Brick_Smooth"
    },
    {
      "x": -17,
      "y": 18,
      "z": 14,
      "name": "Rock_Aqua_Brick_Smooth"
    },
    {
      "x": -17,
      "y": 19,
      "z": 14,
      "name": "Rock_Aqua_Brick_Smooth"
    },
    {
      "x": -17,
      "y": 20,
      "z": 14,
      "name": "Rock_Aqua_Brick_Smooth"
    },
    {
      "x": -17,
      "y": 21,
      "z": 14,
      "name": "Rock_Aqua_Brick_Smooth"
    },
    {
      "x": -17,
      "y": 22,
      "z": 14,
      "name": "Rock_Aqua_Brick_Smooth"
    },
    {
      "x": -17,
      "y": 23,
      "z": 14,
      "name": "Rock_Aqua"
    },
    {
      "x": -17,
      "y": 24,
      "z": 14,
      "name": "Rock_Aqua"
    },
    {
      "x": -17,
      "y": 19,
      "z": 15,
      "name": "Rock_Aqua_Brick_Smooth"
    },
    {
      "x": -17,
      "y": 20,
      "z": 15,
      "name": "Rock_Aqua_Brick_Smooth"
    },
    {
      "x": -17,
      "y": 21,
      "z": 15,
      "name": "Rock_Aqua_Brick_Smooth"
    },
    {
      "x": -17,
      "y": 22,
      "z": 15,
      "name": "Rock_Aqua_Brick_Smooth"
    },
    {
      "x": -17,
      "y": 23,
      "z": 15,
      "name": "Rock_Aqua_Brick_Smooth"
    },
    {
      "x": -17,
      "y": 19,
      "z": 16,
      "name": "Rock_Aqua"
    },
    {
      "x": -17,
      "y": 20,
      "z": 16,
      "name": "Rock_Aqua_Brick_Smooth"
    },
    {
      "x": -17,
      "y": 21,
      "z": 16,
      "name": "Rock_Aqua_Brick_Smooth"
    },
    {
      "x": -17,
      "y": 22,
      "z": 16,
      "name": "Rock_Aqua_Brick_Smooth"
    },
    {
      "x": -17,
      "y": 23,
      "z": 16,
      "name": "Rock_Aqua"
    },
    {
      "x": -17,
      "y": 19,
      "z": 17,
      "name": "Rock_Aqua"
    },
    {
      "x": -17,
      "y": 20,
      "z": 17,
      "name": "Rock_Aqua_Brick_Smooth"
    },
    {
      "x": -17,
      "y": 21,
      "z": 17,
      "name": "Rock_Aqua_Brick_Smooth"
    },
    {
      "x": -17,
      "y": 22,
      "z": 17,
      "name": "Rock_Aqua_Brick_Smooth"
    },
    {
      "x": -17,
      "y": 23,
      "z": 17,
      "name": "Rock_Aqua"
    },
    {
      "x": -17,
      "y": 20,
      "z": 18,
      "name": "Rock_Aqua_Brick_Smooth"
    },
    {
      "x": -17,
      "y": 21,
      "z": 18,
      "name": "Rock_Aqua_Brick_Smooth"
    },
    {
      "x": -17,
      "y": 22,
      "z": 18,
      "name": "Rock_Aqua"
    },
    {
      "x": -17,
      "y": 21,
      "z": 19,
      "name": "Rock_Aqua_Brick_Smooth"
    },
    {
      "x": -16,
      "y": 23,
      "z": -16,
      "name": "Rock_Crystal_Cyan_Large",
      "rotation": 8
    },
    {
      "x": -16,
      "y": 24,
      "z": -16,
      "name": "Rock_Aqua_Brick"
    },
    {
      "x": -16,
      "y": 22,
      "z": -15,
      "name": "Rock_Aqua_Cobble"
    },
    {
      "x": -16,
      "y": 23,
      "z": -15,
      "name": "Rock_Aqua_Cobble"
    },
    {
      "x": -16,
      "y": 24,
      "z": -15,
      "name": "Rock_Aqua_Cobble"
    },
    {
      "x": -16,
      "y": 25,
      "z": -15,
      "name": "Rock_Aqua_Cobble"
    },
    {
      "x": -16,
      "y": 26,
      "z": -15,
      "name": "Plant_Coral_Bush_Cyan"
    },
    {
      "x": -16,
      "y": 21,
      "z": -14,
      "name": "Rock_Aqua_Brick_Smooth"
    },
    {
      "x": -16,
      "y": 22,
      "z": -14,
      "name": "Rock_Aqua_Brick"
    },
    {
      "x": -16,
      "y": 23,
      "z": -14,
      "name": "Rock_Aqua_Cobble"
    },
    {
      "x": -16,
      "y": 24,
      "z": -14,
      "name": "Rock_Aqua_Brick"
    },
    {
      "x": -16,
      "y": 25,
      "z": -14,
      "name": "Rock_Aqua_Cobble"
    },
    {
      "x": -16,
      "y": 26,
      "z": -14,
      "name": "Rock_Aqua_Cobble"
    },
    {
      "x": -16,
      "y": 21,
      "z": -13,
      "name": "Rock_Aqua_Brick_Smooth"
    },
    {
      "x": -16,
      "y": 22,
      "z": -13,
      "name": "Rock_Aqua_Cobble"
    },
    {
      "x": -16,
      "y": 23,
      "z": -13,
      "name": "Rock_Aqua_Cobble"
    },
    {
      "x": -16,
      "y": 24,
      "z": -13,
      "name": "Rock_Aqua_Cobble"
    },
    {
      "x": -16,
      "y": 25,
      "z": -13,
      "name": "Rock_Aqua_Cobble"
    },
    {
      "x": -16,
      "y": 26,
      "z": -13,
      "name": "Rock_Aqua_Cobble"
    },
    {
      "x": -16,
      "y": 27,
      "z": -13,
      "name": "Plant_Coral_Bush_Cyan"
    },
    {
      "x": -16,
      "y": 21,
      "z": -12,
      "name": "Rock_Aqua_Brick_Smooth"
    },
    {
      "x": -16,
      "y": 22,
      "z": -12,
      "name": "Rock_Aqua_Brick"
    },
    {
      "x": -16,
      "y": 23,
      "z": -12,
      "name": "Rock_Aqua_Cobble"
    },
    {
      "x": -16,
      "y": 24,
      "z": -12,
      "name": "Rock_Aqua_Brick"
    },
    {
      "x": -16,
      "y": 25,
      "z": -12,
      "name": "Rock_Aqua_Cobble"
    },
    {
      "x": -16,
      "y": 26,
      "z": -12,
      "name": "Rock_Aqua_Brick"
    },
    {
      "x": -16,
      "y": 24,
      "z": -11,
      "name": "Rock_Aqua_Cobble"
    },
    {
      "x": -16,
      "y": 26,
      "z": -11,
      "name": "Rock_Aqua_Cobble"
    },
    {
      "x": -16,
      "y": 22,
      "z": -10,
      "name": "Rock_Aqua_Brick_Smooth"
    },
    {
      "x": -16,
      "y": 23,
      "z": -10,
      "name": "Rock_Aqua_Brick"
    },
    {
      "x": -16,
      "y": 24,
      "z": -10,
      "name": "Rock_Aqua_Cobble"
    },
    {
      "x": -16,
      "y": 25,
      "z": -10,
      "name": "Rock_Aqua_Cobble"
    },
    {
      "x": -16,
      "y": 24,
      "z": -9,
      "name": "Rock_Aqua_Cobble"
    },
    {
      "x": -16,
      "y": 0,
      "z": -6,
      "name": "Rock_Aqua"
    },
    {
      "x": -16,
      "y": 0,
      "z": -5,
      "name": "Rock_Aqua"
    },
    {
      "x": -16,
      "y": 0,
      "z": -4,
      "name": "Rock_Aqua"
    },
    {
      "x": -16,
      "y": 0,
      "z": -3,
      "name": "Rock_Aqua"
    },
    {
      "x": -16,
      "y": 0,
      "z": -2,
      "name": "Rock_Aqua"
    },
    {
      "x": -16,
      "y": 26,
      "z": 0,
      "name": "Rock_Aqua_Brick_Smooth"
    },
    {
      "x": -16,
      "y": 27,
      "z": 0,
      "name": "Rock_Aqua_Brick_Smooth"
    },
    {
      "x": -16,
      "y": 28,
      "z": 0,
      "name": "Rock_Aqua_Cobble"
    },
    {
      "x": -16,
      "y": 29,
      "z": 0,
      "name": "Rock_Aqua_Brick"
    },
    {
      "x": -16,
      "y": 30,
      "z": 0,
      "name": "Rock_Aqua_Cobble"
    },
    {
      "x": -16,
      "y": 25,
      "z": 1,
      "name": "Rock_Aqua_Brick_Smooth"
    },
    {
      "x": -16,
      "y": 26,
      "z": 1,
      "name": "Rock_Aqua_Brick_Smooth"
    },
    {
      "x": -16,
      "y": 27,
      "z": 1,
      "name": "Rock_Aqua_Brick_Smooth"
    },
    {
      "x": -16,
      "y": 28,
      "z": 1,
      "name": "Rock_Aqua_Cobble"
    },
    {
      "x": -16,
      "y": 29,
      "z": 1,
      "name": "Rock_Aqua_Cobble"
    },
    {
      "x": -16,
      "y": 30,
      "z": 1,
      "name": "Rock_Aqua_Cobble"
    },
    {
      "x": -16,
      "y": 31,
      "z": 1,
      "name": "Plant_Coral_Bush_Cyan"
    },
    {
      "x": -16,
      "y": 23,
      "z": 2,
      "name": "Rock_Aqua_Stalactite_Small",
      "rotation": 8
    },
    {
      "x": -16,
      "y": 24,
      "z": 2,
      "name": "Rock_Aqua_Brick_Smooth"
    },
    {
      "x": -16,
      "y": 25,
      "z": 2,
      "name": "Rock_Aqua_Brick_Smooth"
    },
    {
      "x": -16,
      "y": 26,
      "z": 2,
      "name": "Rock_Aqua_Brick_Smooth"
    },
    {
      "x": -16,
      "y": 27,
      "z": 2,
      "name": "Rock_Aqua_Brick_Smooth"
    },
    {
      "x": -16,
      "y": 28,
      "z": 2,
      "name": "Rock_Aqua_Cobble"
    },
    {
      "x": -16,
      "y": 29,
      "z": 2,
      "name": "Rock_Aqua_Cobble"
    },
    {
      "x": -16,
      "y": 30,
      "z": 2,
      "name": "Rock_Aqua_Cobble"
    },
    {
      "x": -16,
      "y": 31,
      "z": 2,
      "name": "Rock_Aqua_Cobble"
    },
    {
      "x": -16,
      "y": 24,
      "z": 3,
      "name": "Rock_Aqua_Brick_Smooth"
    },
    {
      "x": -16,
      "y": 25,
      "z": 3,
      "name": "Rock_Aqua_Brick_Smooth"
    },
    {
      "x": -16,
      "y": 26,
      "z": 3,
      "name": "Rock_Aqua_Brick_Smooth"
    },
    {
      "x": -16,
      "y": 27,
      "z": 3,
      "name": "Rock_Aqua_Brick_Smooth"
    },
    {
      "x": -16,
      "y": 28,
      "z": 3,
      "name": "Rock_Aqua_Cobble"
    },
    {
      "x": -16,
      "y": 29,
      "z": 3,
      "name": "Rock_Aqua_Cobble"
    },
    {
      "x": -16,
      "y": 30,
      "z": 3,
      "name": "Rock_Aqua_Brick"
    },
    {
      "x": -16,
      "y": 31,
      "z": 3,
      "name": "Rock_Aqua_Brick"
    },
    {
      "x": -16,
      "y": 24,
      "z": 4,
      "name": "Rock_Aqua_Brick_Smooth"
    },
    {
      "x": -16,
      "y": 25,
      "z": 4,
      "name": "Rock_Aqua_Brick_Smooth"
    },
    {
      "x": -16,
      "y": 26,
      "z": 4,
      "name": "Rock_Aqua_Brick_Smooth"
    },
    {
      "x": -16,
      "y": 27,
      "z": 4,
      "name": "Rock_Aqua_Brick_Smooth"
    },
    {
      "x": -16,
      "y": 24,
      "z": 5,
      "name": "Rock_Aqua_Brick_Smooth"
    },
    {
      "x": -16,
      "y": 25,
      "z": 5,
      "name": "Rock_Aqua_Brick_Smooth"
    },
    {
      "x": -16,
      "y": 26,
      "z": 5,
      "name": "Rock_Aqua_Brick_Smooth"
    },
    {
      "x": -16,
      "y": 27,
      "z": 5,
      "name": "Rock_Aqua_Cobble"
    },
    {
      "x": -16,
      "y": 31,
      "z": 5,
      "name": "Rock_Aqua_Cobble"
    },
    {
      "x": -16,
      "y": 32,
      "z": 5,
      "name": "Plant_Coral_Model_Cyan"
    },
    {
      "x": -16,
      "y": 23,
      "z": 6,
      "name": "Rock_Crystal_Cyan_Large",
      "rotation": 8
    },
    {
      "x": -16,
      "y": 24,
      "z": 6,
      "name": "Rock_Aqua_Brick_Smooth"
    },
    {
      "x": -16,
      "y": 25,
      "z": 6,
      "name": "Rock_Aqua_Brick_Smooth"
    },
    {
      "x": -16,
      "y": 31,
      "z": 6,
      "name": "Rock_Aqua_Brick"
    },
    {
      "x": -16,
      "y": 32,
      "z": 6,
      "name": "Plant_Coral_Model_Blue"
    },
    {
      "x": -16,
      "y": 24,
      "z": 7,
      "name": "Rock_Aqua_Brick_Smooth"
    },
    {
      "x": -16,
      "y": 25,
      "z": 7,
      "name": "Rock_Aqua_Brick_Smooth"
    },
    {
      "x": -16,
      "y": 26,
      "z": 7,
      "name": "Rock_Aqua_Brick_Smooth"
    },
    {
      "x": -16,
      "y": 27,
      "z": 7,
      "name": "Rock_Aqua_Cobble"
    },
    {
      "x": -16,
      "y": 29,
      "z": 7,
      "name": "Rock_Aqua_Cobble"
    },
    {
      "x": -16,
      "y": 31,
      "z": 7,
      "name": "Rock_Aqua_Brick"
    },
    {
      "x": -16,
      "y": 25,
      "z": 8,
      "name": "Rock_Aqua_Brick_Smooth"
    },
    {
      "x": -16,
      "y": 26,
      "z": 8,
      "name": "Rock_Aqua_Brick_Smooth"
    },
    {
      "x": -16,
      "y": 27,
      "z": 8,
      "name": "Rock_Aqua_Brick"
    },
    {
      "x": -16,
      "y": 29,
      "z": 8,
      "name": "Rock_Aqua_Brick"
    },
    {
      "x": -16,
      "y": 30,
      "z": 8,
      "name": "Rock_Aqua_Cobble"
    },
    {
      "x": -16,
      "y": 31,
      "z": 8,
      "name": "Plant_Coral_Bush_Cyan"
    },
    {
      "x": -16,
      "y": 25,
      "z": 9,
      "name": "Rock_Crystal_Cyan_Large",
      "rotation": 8
    },
    {
      "x": -16,
      "y": 26,
      "z": 9,
      "name": "Rock_Aqua_Brick_Smooth"
    },
    {
      "x": -16,
      "y": 27,
      "z": 9,
      "name": "Rock_Aqua_Brick"
    },
    {
      "x": -16,
      "y": 28,
      "z": 9,
      "name": "Rock_Aqua_Brick"
    },
    {
      "x": -16,
      "y": 29,
      "z": 9,
      "name": "Rock_Aqua_Brick"
    },
    {
      "x": -16,
      "y": 20,
      "z": 10,
      "name": "Rock_Aqua_Brick_Smooth"
    },
    {
      "x": -16,
      "y": 21,
      "z": 10,
      "name": "Rock_Aqua_Brick_Smooth"
    },
    {
      "x": -16,
      "y": 22,
      "z": 10,
      "name": "Rock_Aqua"
    },
    {
      "x": -16,
      "y": 19,
      "z": 11,
      "name": "Rock_Aqua_Brick_Smooth"
    },
    {
      "x": -16,
      "y": 20,
      "z": 11,
      "name": "Rock_Aqua"
    },
    {
      "x": -16,
      "y": 21,
      "z": 11,
      "name": "Rock_Aqua_Brick_Smooth"
    },
    {
      "x": -16,
      "y": 22,
      "z": 11,
      "name": "Rock_Aqua"
    },
    {
      "x": -16,
      "y": 23,
      "z": 11,
      "name": "Rock_Aqua_Brick_Smooth"
    },
    {
      "x": -16,
      "y": 18,
      "z": 12,
      "name": "Rock_Aqua"
    },
    {
      "x": -16,
      "y": 19,
      "z": 12,
      "name": "Rock_Aqua"
    },
    {
      "x": -16,
      "y": 20,
      "z": 12,
      "name": "Rock_Aqua_Brick_Smooth"
    },
    {
      "x": -16,
      "y": 21,
      "z": 12,
      "name": "Rock_Aqua_Brick_Smooth"
    },
    {
      "x": -16,
      "y": 22,
      "z": 12,
      "name": "Rock_Aqua_Brick_Smooth"
    },
    {
      "x": -16,
      "y": 23,
      "z": 12,
      "name": "Rock_Aqua_Brick_Smooth"
    },
    {
      "x": -16,
      "y": 24,
      "z": 12,
      "name": "Rock_Aqua_Brick_Smooth"
    },
    {
      "x": -16,
      "y": 18,
      "z": 13,
      "name": "Rock_Aqua_Brick_Smooth"
    },
    {
      "x": -16,
      "y": 19,
      "z": 13,
      "name": "Rock_Aqua"
    },
    {
      "x": -16,
      "y": 20,
      "z": 13,
      "name": "Rock_Aqua_Brick_Smooth"
    },
    {
      "x": -16,
      "y": 21,
      "z": 13,
      "name": "Rock_Aqua_Brick_Smooth"
    },
    {
      "x": -16,
      "y": 22,
      "z": 13,
      "name": "Rock_Aqua_Brick_Smooth"
    },
    {
      "x": -16,
      "y": 23,
      "z": 13,
      "name": "Rock_Aqua_Brick_Smooth"
    },
    {
      "x": -16,
      "y": 24,
      "z": 13,
      "name": "Rock_Aqua"
    },
    {
      "x": -16,
      "y": 25,
      "z": 13,
      "name": "Plant_Crop_Mushroom_Glowing_Blue"
    },
    {
      "x": -16,
      "y": 18,
      "z": 14,
      "name": "Rock_Aqua"
    },
    {
      "x": -16,
      "y": 19,
      "z": 14,
      "name": "Rock_Aqua_Brick_Smooth"
    },
    {
      "x": -16,
      "y": 20,
      "z": 14,
      "name": "Rock_Aqua_Brick_Smooth"
    },
    {
      "x": -16,
      "y": 21,
      "z": 14,
      "name": "Rock_Aqua_Brick_Smooth"
    },
    {
      "x": -16,
      "y": 22,
      "z": 14,
      "name": "Rock_Aqua_Brick_Smooth"
    },
    {
      "x": -16,
      "y": 23,
      "z": 14,
      "name": "Rock_Aqua"
    },
    {
      "x": -16,
      "y": 24,
      "z": 14,
      "name": "Rock_Aqua"
    },
    {
      "x": -16,
      "y": 18,
      "z": 15,
      "name": "Rock_Aqua_Brick_Smooth"
    },
    {
      "x": -16,
      "y": 19,
      "z": 15,
      "name": "Rock_Aqua_Brick_Smooth"
    },
    {
      "x": -16,
      "y": 20,
      "z": 15,
      "name": "Rock_Aqua_Brick_Smooth"
    },
    {
      "x": -16,
      "y": 21,
      "z": 15,
      "name": "Rock_Aqua_Brick_Smooth"
    },
    {
      "x": -16,
      "y": 22,
      "z": 15,
      "name": "Rock_Aqua_Brick_Smooth"
    },
    {
      "x": -16,
      "y": 23,
      "z": 15,
      "name": "Rock_Aqua_Brick_Smooth"
    },
    {
      "x": -16,
      "y": 24,
      "z": 15,
      "name": "Rock_Aqua_Brick_Smooth"
    },
    {
      "x": -16,
      "y": 19,
      "z": 16,
      "name": "Rock_Aqua"
    },
    {
      "x": -16,
      "y": 20,
      "z": 16,
      "name": "Rock_Aqua_Brick_Smooth"
    },
    {
      "x": -16,
      "y": 21,
      "z": 16,
      "name": "Rock_Aqua_Brick_Smooth"
    },
    {
      "x": -16,
      "y": 22,
      "z": 16,
      "name": "Rock_Aqua_Brick_Smooth"
    },
    {
      "x": -16,
      "y": 23,
      "z": 16,
      "name": "Rock_Aqua_Brick_Smooth"
    },
    {
      "x": -16,
      "y": 19,
      "z": 17,
      "name": "Rock_Aqua_Brick_Smooth"
    },
    {
      "x": -16,
      "y": 20,
      "z": 17,
      "name": "Rock_Aqua_Brick_Smooth"
    },
    {
      "x": -16,
      "y": 21,
      "z": 17,
      "name": "Rock_Aqua_Brick_Smooth"
    },
    {
      "x": -16,
      "y": 22,
      "z": 17,
      "name": "Rock_Aqua_Brick_Smooth"
    },
    {
      "x": -16,
      "y": 23,
      "z": 17,
      "name": "Rock_Aqua"
    },
    {
      "x": -16,
      "y": 20,
      "z": 18,
      "name": "Rock_Aqua_Brick_Smooth"
    },
    {
      "x": -16,
      "y": 21,
      "z": 18,
      "name": "Rock_Aqua_Brick_Smooth"
    },
    {
      "x": -16,
      "y": 22,
      "z": 18,
      "name": "Rock_Aqua"
    },
    {
      "x": -15,
      "y": 23,
      "z": -15,
      "name": "Rock_Aqua_Cobble"
    },
    {
      "x": -15,
      "y": 24,
      "z": -15,
      "name": "Rock_Aqua_Brick"
    },
    {
      "x": -15,
      "y": 22,
      "z": -14,
      "name": "Rock_Aqua_Brick"
    },
    {
      "x": -15,
      "y": 23,
      "z": -14,
      "name": "Rock_Aqua_Cobble"
    },
    {
      "x": -15,
      "y": 24,
      "z": -14,
      "name": "Rock_Aqua_Cobble"
    },
    {
      "x": -15,
      "y": 25,
      "z": -14,
      "name": "Rock_Aqua_Brick"
    },
    {
      "x": -15,
      "y": 26,
      "z": -14,
      "name": "Plant_Crop_Mushroom_Glowing_Blue"
    },
    {
      "x": -15,
      "y": 20,
      "z": -13,
      "name": "Rock_Crystal_Cyan_Large",
      "rotation": 8
    },
    {
      "x": -15,
      "y": 21,
      "z": -13,
      "name": "Rock_Aqua_Brick_Smooth"
    },
    {
      "x": -15,
      "y": 22,
      "z": -13,
      "name": "Rock_Aqua_Brick"
    },
    {
      "x": -15,
      "y": 23,
      "z": -13,
      "name": "Rock_Aqua_Cobble"
    },
    {
      "x": -15,
      "y": 24,
      "z": -13,
      "name": "Rock_Aqua_Cobble"
    },
    {
      "x": -15,
      "y": 25,
      "z": -13,
      "name": "Rock_Aqua_Brick"
    },
    {
      "x": -15,
      "y": 26,
      "z": -13,
      "name": "Rock_Aqua_Cobble"
    },
    {
      "x": -15,
      "y": 21,
      "z": -12,
      "name": "Rock_Aqua_Brick_Smooth"
    },
    {
      "x": -15,
      "y": 22,
      "z": -12,
      "name": "Rock_Aqua_Cobble"
    },
    {
      "x": -15,
      "y": 23,
      "z": -12,
      "name": "Rock_Aqua_Cobble"
    },
    {
      "x": -15,
      "y": 24,
      "z": -12,
      "name": "Rock_Aqua_Cobble"
    },
    {
      "x": -15,
      "y": 25,
      "z": -12,
      "name": "Rock_Aqua_Brick"
    },
    {
      "x": -15,
      "y": 26,
      "z": -12,
      "name": "Rock_Aqua_Brick"
    },
    {
      "x": -15,
      "y": 27,
      "z": -12,
      "name": "Plant_Crop_Mushroom_Glowing_Blue"
    },
    {
      "x": -15,
      "y": 22,
      "z": -11,
      "name": "Rock_Aqua_Brick_Smooth"
    },
    {
      "x": -15,
      "y": 23,
      "z": -11,
      "name": "Plant_Coral_Bush_Cyan"
    },
    {
      "x": -15,
      "y": 26,
      "z": -11,
      "name": "Rock_Aqua_Brick"
    },
    {
      "x": -15,
      "y": 27,
      "z": -11,
      "name": "Plant_Coral_Model_Blue"
    },
    {
      "x": -15,
      "y": 25,
      "z": -10,
      "name": "Rock_Aqua_Brick"
    },
    {
      "x": -15,
      "y": 0,
      "z": -9,
      "name": "Rock_Aqua"
    },
    {
      "x": -15,
      "y": 0,
      "z": -8,
      "name": "Rock_Aqua"
    },
    {
      "x": -15,
      "y": 0,
      "z": -7,
      "name": "Rock_Aqua"
    },
    {
      "x": -15,
      "y": 0,
      "z": -6,
      "name": "Rock_Aqua"
    },
    {
      "x": -15,
      "y": 0,
      "z": -5,
      "name": "Rock_Aqua"
    },
    {
      "x": -15,
      "y": 0,
      "z": -4,
      "name": "Rock_Aqua"
    },
    {
      "x": -15,
      "y": 0,
      "z": -3,
      "name": "Rock_Aqua"
    },
    {
      "x": -15,
      "y": 0,
      "z": -2,
      "name": "Rock_Aqua"
    },
    {
      "x": -15,
      "y": 0,
      "z": -1,
      "name": "Rock_Aqua"
    },
    {
      "x": -15,
      "y": 0,
      "z": 0,
      "name": "Rock_Aqua"
    },
    {
      "x": -15,
      "y": 28,
      "z": 0,
      "name": "Rock_Aqua_Brick"
    },
    {
      "x": -15,
      "y": 29,
      "z": 0,
      "name": "Rock_Aqua_Cobble"
    },
    {
      "x": -15,
      "y": 0,
      "z": 1,
      "name": "Rock_Aqua"
    },
    {
      "x": -15,
      "y": 26,
      "z": 1,
      "name": "Rock_Aqua_Brick_Smooth"
    },
    {
      "x": -15,
      "y": 27,
      "z": 1,
      "name": "Rock_Aqua_Brick_Smooth"
    },
    {
      "x": -15,
      "y": 28,
      "z": 1,
      "name": "Rock_Aqua_Cobble"
    },
    {
      "x": -15,
      "y": 29,
      "z": 1,
      "name": "Rock_Aqua_Cobble"
    },
    {
      "x": -15,
      "y": 30,
      "z": 1,
      "name": "Rock_Aqua_Cobble"
    },
    {
      "x": -15,
      "y": 25,
      "z": 2,
      "name": "Rock_Aqua_Brick_Smooth"
    },
    {
      "x": -15,
      "y": 26,
      "z": 2,
      "name": "Rock_Aqua_Brick_Smooth"
    },
    {
      "x": -15,
      "y": 27,
      "z": 2,
      "name": "Rock_Aqua_Brick_Smooth"
    },
    {
      "x": -15,
      "y": 28,
      "z": 2,
      "name": "Rock_Aqua_Cobble"
    },
    {
      "x": -15,
      "y": 29,
      "z": 2,
      "name": "Rock_Aqua_Brick"
    },
    {
      "x": -15,
      "y": 30,
      "z": 2,
      "name": "Rock_Aqua_Brick"
    },
    {
      "x": -15,
      "y": 25,
      "z": 3,
      "name": "Rock_Aqua_Brick_Smooth"
    },
    {
      "x": -15,
      "y": 26,
      "z": 3,
      "name": "Rock_Aqua_Brick_Smooth"
    },
    {
      "x": -15,
      "y": 27,
      "z": 3,
      "name": "Rock_Aqua_Brick_Smooth"
    },
    {
      "x": -15,
      "y": 28,
      "z": 3,
      "name": "Rock_Aqua_Cobble"
    },
    {
      "x": -15,
      "y": 25,
      "z": 4,
      "name": "Rock_Aqua_Brick_Smooth"
    },
    {
      "x": -15,
      "y": 26,
      "z": 4,
      "name": "Rock_Aqua_Brick_Smooth"
    },
    {
      "x": -15,
      "y": 30,
      "z": 4,
      "name": "Rock_Aqua_Brick"
    },
    {
      "x": -15,
      "y": 31,
      "z": 4,
      "name": "Rock_Aqua_Cobble"
    },
    {
      "x": -15,
      "y": 25,
      "z": 5,
      "name": "Rock_Aqua_Brick_Smooth"
    },
    {
      "x": -15,
      "y": 26,
      "z": 5,
      "name": "Rock_Aqua_Brick_Smooth"
    },
    {
      "x": -15,
      "y": 27,
      "z": 5,
      "name": "Rock_Aqua_Cobble"
    },
    {
      "x": -15,
      "y": 28,
      "z": 5,
      "name": "Rock_Aqua_Cobble"
    },
    {
      "x": -15,
      "y": 29,
      "z": 5,
      "name": "Rock_Aqua_Brick"
    },
    {
      "x": -15,
      "y": 30,
      "z": 5,
      "name": "Rock_Aqua_Brick"
    },
    {
      "x": -15,
      "y": 31,
      "z": 5,
      "name": "Rock_Aqua_Brick"
    },
    {
      "x": -15,
      "y": 25,
      "z": 6,
      "name": "Rock_Aqua_Brick_Smooth"
    },
    {
      "x": -15,
      "y": 26,
      "z": 6,
      "name": "Rock_Aqua_Brick_Smooth"
    },
    {
      "x": -15,
      "y": 27,
      "z": 6,
      "name": "Rock_Aqua_Cobble"
    },
    {
      "x": -15,
      "y": 31,
      "z": 6,
      "name": "Rock_Aqua_Cobble"
    },
    {
      "x": -15,
      "y": 32,
      "z": 6,
      "name": "Plant_Coral_Bush_Blue"
    },
    {
      "x": -15,
      "y": 25,
      "z": 7,
      "name": "Rock_Aqua_Brick_Smooth"
    },
    {
      "x": -15,
      "y": 26,
      "z": 7,
      "name": "Rock_Aqua_Brick_Smooth"
    },
    {
      "x": -15,
      "y": 27,
      "z": 7,
      "name": "Rock_Aqua_Cobble"
    },
    {
      "x": -15,
      "y": 28,
      "z": 7,
      "name": "Rock_Aqua_Cobble"
    },
    {
      "x": -15,
      "y": 29,
      "z": 7,
      "name": "Rock_Aqua_Brick"
    },
    {
      "x": -15,
      "y": 26,
      "z": 8,
      "name": "Rock_Aqua_Brick_Smooth"
    },
    {
      "x": -15,
      "y": 27,
      "z": 8,
      "name": "Rock_Aqua_Brick"
    },
    {
      "x": -15,
      "y": 29,
      "z": 8,
      "name": "Rock_Aqua_Cobble"
    },
    {
      "x": -15,
      "y": 30,
      "z": 8,
      "name": "Rock_Aqua_Cobble"
    },
    {
      "x": -15,
      "y": 27,
      "z": 9,
      "name": "Rock_Aqua_Cobble"
    },
    {
      "x": -15,
      "y": 28,
      "z": 9,
      "name": "Rock_Aqua_Brick"
    },
    {
      "x": -15,
      "y": 29,
      "z": 9,
      "name": "Rock_Aqua_Brick"
    },
    {
      "x": -15,
      "y": 21,
      "z": 10,
      "name": "Rock_Aqua_Brick_Smooth"
    },
    {
      "x": -15,
      "y": 19,
      "z": 11,
      "name": "Rock_Aqua_Brick_Smooth"
    },
    {
      "x": -15,
      "y": 20,
      "z": 11,
      "name": "Rock_Aqua"
    },
    {
      "x": -15,
      "y": 21,
      "z": 11,
      "name": "Rock_Aqua"
    },
    {
      "x": -15,
      "y": 22,
      "z": 11,
      "name": "Rock_Aqua_Brick_Smooth"
    },
    {
      "x": -15,
      "y": 23,
      "z": 11,
      "name": "Rock_Aqua"
    },
    {
      "x": -15,
      "y": 19,
      "z": 12,
      "name": "Rock_Aqua_Brick_Smooth"
    },
    {
      "x": -15,
      "y": 20,
      "z": 12,
      "name": "Rock_Aqua_Brick_Smooth"
    },
    {
      "x": -15,
      "y": 21,
      "z": 12,
      "name": "Rock_Aqua_Brick_Smooth"
    },
    {
      "x": -15,
      "y": 22,
      "z": 12,
      "name": "Rock_Aqua_Brick_Smooth"
    },
    {
      "x": -15,
      "y": 23,
      "z": 12,
      "name": "Rock_Aqua_Brick_Smooth"
    },
    {
      "x": -15,
      "y": 18,
      "z": 13,
      "name": "Rock_Aqua"
    },
    {
      "x": -15,
      "y": 19,
      "z": 13,
      "name": "Rock_Aqua_Brick_Smooth"
    },
    {
      "x": -15,
      "y": 20,
      "z": 13,
      "name": "Rock_Aqua_Brick_Smooth"
    },
    {
      "x": -15,
      "y": 21,
      "z": 13,
      "name": "Rock_Aqua_Brick_Smooth"
    },
    {
      "x": -15,
      "y": 22,
      "z": 13,
      "name": "Rock_Aqua_Brick_Smooth"
    },
    {
      "x": -15,
      "y": 23,
      "z": 13,
      "name": "Rock_Aqua"
    },
    {
      "x": -15,
      "y": 24,
      "z": 13,
      "name": "Rock_Aqua"
    },
    {
      "x": -15,
      "y": 18,
      "z": 14,
      "name": "Rock_Aqua_Brick_Smooth"
    },
    {
      "x": -15,
      "y": 19,
      "z": 14,
      "name": "Rock_Aqua"
    },
    {
      "x": -15,
      "y": 20,
      "z": 14,
      "name": "Rock_Aqua_Brick_Smooth"
    },
    {
      "x": -15,
      "y": 21,
      "z": 14,
      "name": "Rock_Aqua_Brick_Smooth"
    },
    {
      "x": -15,
      "y": 22,
      "z": 14,
      "name": "Rock_Aqua_Brick_Smooth"
    },
    {
      "x": -15,
      "y": 23,
      "z": 14,
      "name": "Rock_Aqua"
    },
    {
      "x": -15,
      "y": 24,
      "z": 14,
      "name": "Rock_Aqua"
    },
    {
      "x": -15,
      "y": 19,
      "z": 15,
      "name": "Rock_Aqua_Brick_Smooth"
    },
    {
      "x": -15,
      "y": 20,
      "z": 15,
      "name": "Rock_Aqua_Brick_Smooth"
    },
    {
      "x": -15,
      "y": 21,
      "z": 15,
      "name": "Rock_Aqua_Brick_Smooth"
    },
    {
      "x": -15,
      "y": 22,
      "z": 15,
      "name": "Rock_Aqua_Brick_Smooth"
    },
    {
      "x": -15,
      "y": 23,
      "z": 15,
      "name": "Rock_Aqua"
    },
    {
      "x": -15,
      "y": 19,
      "z": 16,
      "name": "Rock_Aqua"
    },
    {
      "x": -15,
      "y": 20,
      "z": 16,
      "name": "Rock_Aqua_Brick_Smooth"
    },
    {
      "x": -15,
      "y": 21,
      "z": 16,
      "name": "Rock_Aqua_Brick_Smooth"
    },
    {
      "x": -15,
      "y": 22,
      "z": 16,
      "name": "Rock_Aqua_Brick_Smooth"
    },
    {
      "x": -15,
      "y": 23,
      "z": 16,
      "name": "Rock_Aqua"
    },
    {
      "x": -15,
      "y": 24,
      "z": 16,
      "name": "Plant_Crop_Mushroom_Glowing_Blue"
    },
    {
      "x": -15,
      "y": 20,
      "z": 17,
      "name": "Rock_Aqua"
    },
    {
      "x": -15,
      "y": 21,
      "z": 17,
      "name": "Rock_Aqua_Brick_Smooth"
    },
    {
      "x": -15,
      "y": 22,
      "z": 17,
      "name": "Rock_Aqua"
    },
    {
      "x": -15,
      "y": 21,
      "z": 18,
      "name": "Rock_Aqua_Brick_Smooth"
    },
    {
      "x": -14,
      "y": 23,
      "z": -14,
      "name": "Rock_Aqua_Brick"
    },
    {
      "x": -14,
      "y": 24,
      "z": -14,
      "name": "Rock_Aqua_Cobble"
    },
    {
      "x": -14,
      "y": 25,
      "z": -14,
      "name": "Plant_Coral_Bush_Cyan"
    },
    {
      "x": -14,
      "y": 22,
      "z": -13,
      "name": "Rock_Aqua_Brick"
    },
    {
      "x": -14,
      "y": 23,
      "z": -13,
      "name": "Rock_Aqua_Cobble"
    },
    {
      "x": -14,
      "y": 24,
      "z": -13,
      "name": "Rock_Aqua_Brick"
    },
    {
      "x": -14,
      "y": 25,
      "z": -13,
      "name": "Rock_Aqua_Cobble"
    },
    {
      "x": -14,
      "y": 23,
      "z": -12,
      "name": "Rock_Aqua_Cobble"
    },
    {
      "x": -14,
      "y": 0,
      "z": -11,
      "name": "Rock_Aqua"
    },
    {
      "x": -14,
      "y": 0,
      "z": -10,
      "name": "Rock_Aqua"
    },
    {
      "x": -14,
      "y": 0,
      "z": -9,
      "name": "Rock_Aqua"
    },
    {
      "x": -14,
      "y": 0,
      "z": -8,
      "name": "Rock_Aqua"
    },
    {
      "x": -14,
      "y": 0,
      "z": -7,
      "name": "Rock_Aqua"
    },
    {
      "x": -14,
      "y": 5,
      "z": -7,
      "name": "Rock_Aqua_Brick_Smooth_Half"
    },
    {
      "x": -14,
      "y": 0,
      "z": -6,
      "name": "Rock_Aqua"
    },
    {
      "x": -14,
      "y": 5,
      "z": -6,
      "name": "Rock_Aqua_Brick_Smooth_Half"
    },
    {
      "x": -14,
      "y": 0,
      "z": -5,
      "name": "Rock_Aqua"
    },
    {
      "x": -14,
      "y": 5,
      "z": -5,
      "name": "Rock_Aqua_Brick_Smooth_Half"
    },
    {
      "x": -14,
      "y": 0,
      "z": -4,
      "name": "Rock_Aqua"
    },
    {
      "x": -14,
      "y": 5,
      "z": -4,
      "name": "Rock_Aqua_Brick_Smooth_Half"
    },
    {
      "x": -14,
      "y": 0,
      "z": -3,
      "name": "Rock_Aqua"
    },
    {
      "x": -14,
      "y": 5,
      "z": -3,
      "name": "Rock_Aqua_Brick_Smooth_Half"
    },
    {
      "x": -14,
      "y": 0,
      "z": -2,
      "name": "Rock_Aqua"
    },
    {
      "x": -14,
      "y": 5,
      "z": -2,
      "name": "Rock_Aqua_Brick_Smooth_Half"
    },
    {
      "x": -14,
      "y": 0,
      "z": -1,
      "name": "Rock_Aqua"
    },
    {
      "x": -14,
      "y": 5,
      "z": -1,
      "name": "Rock_Aqua_Brick_Smooth_Half"
    },
    {
      "x": -14,
      "y": 0,
      "z": 0,
      "name": "Rock_Aqua"
    },
    {
      "x": -14,
      "y": 0,
      "z": 1,
      "name": "Rock_Aqua"
    },
    {
      "x": -14,
      "y": 0,
      "z": 2,
      "name": "Rock_Aqua"
    },
    {
      "x": -14,
      "y": 27,
      "z": 2,
      "name": "Rock_Aqua_Brick_Smooth"
    },
    {
      "x": -14,
      "y": 28,
      "z": 2,
      "name": "Rock_Aqua_Brick"
    },
    {
      "x": -14,
      "y": 29,
      "z": 2,
      "name": "Rock_Aqua_Cobble"
    },
    {
      "x": -14,
      "y": 30,
      "z": 2,
      "name": "Plant_Coral_Bush_Cyan"
    },
    {
      "x": -14,
      "y": 0,
      "z": 3,
      "name": "Rock_Aqua"
    },
    {
      "x": -14,
      "y": 26,
      "z": 3,
      "name": "Rock_Aqua_Brick_Smooth"
    },
    {
      "x": -14,
      "y": 27,
      "z": 3,
      "name": "Rock_Aqua_Brick_Smooth"
    },
    {
      "x": -14,
      "y": 28,
      "z": 3,
      "name": "Rock_Aqua_Brick"
    },
    {
      "x": -14,
      "y": 29,
      "z": 3,
      "name": "Rock_Aqua_Cobble"
    },
    {
      "x": -14,
      "y": 30,
      "z": 3,
      "name": "Rock_Aqua_Brick"
    },
    {
      "x": -14,
      "y": 26,
      "z": 4,
      "name": "Rock_Aqua_Brick_Smooth"
    },
    {
      "x": -14,
      "y": 27,
      "z": 4,
      "name": "Rock_Aqua_Brick_Smooth"
    },
    {
      "x": -14,
      "y": 28,
      "z": 4,
      "name": "Rock_Aqua_Brick"
    },
    {
      "x": -14,
      "y": 29,
      "z": 4,
      "name": "Rock_Aqua_Cobble"
    },
    {
      "x": -14,
      "y": 30,
      "z": 4,
      "name": "Rock_Aqua_Brick"
    },
    {
      "x": -14,
      "y": 26,
      "z": 5,
      "name": "Rock_Aqua_Brick_Smooth"
    },
    {
      "x": -14,
      "y": 27,
      "z": 5,
      "name": "Rock_Aqua_Brick"
    },
    {
      "x": -14,
      "y": 28,
      "z": 5,
      "name": "Rock_Aqua_Brick"
    },
    {
      "x": -14,
      "y": 29,
      "z": 5,
      "name": "Rock_Aqua_Cobble"
    },
    {
      "x": -14,
      "y": 30,
      "z": 5,
      "name": "Rock_Aqua_Brick"
    },
    {
      "x": -14,
      "y": 26,
      "z": 6,
      "name": "Rock_Aqua_Brick_Smooth"
    },
    {
      "x": -14,
      "y": 27,
      "z": 6,
      "name": "Rock_Aqua_Brick"
    },
    {
      "x": -14,
      "y": 28,
      "z": 6,
      "name": "Rock_Aqua_Cobble"
    },
    {
      "x": -14,
      "y": 26,
      "z": 7,
      "name": "Rock_Aqua_Brick_Smooth"
    },
    {
      "x": -14,
      "y": 27,
      "z": 7,
      "name": "Rock_Aqua_Cobble"
    },
    {
      "x": -14,
      "y": 28,
      "z": 7,
      "name": "Rock_Aqua_Brick"
    },
    {
      "x": -14,
      "y": 29,
      "z": 7,
      "name": "Rock_Aqua_Brick"
    },
    {
      "x": -14,
      "y": 28,
      "z": 8,
      "name": "Rock_Aqua_Cobble"
    },
    {
      "x": -14,
      "y": 20,
      "z": 11,
      "name": "Rock_Aqua_Brick_Smooth"
    },
    {
      "x": -14,
      "y": 21,
      "z": 11,
      "name": "Rock_Aqua_Brick_Smooth"
    },
    {
      "x": -14,
      "y": 22,
      "z": 11,
      "name": "Rock_Aqua"
    },
    {
      "x": -14,
      "y": 19,
      "z": 12,
      "name": "Rock_Aqua"
    },
    {
      "x": -14,
      "y": 20,
      "z": 12,
      "name": "Rock_Aqua_Brick_Smooth"
    },
    {
      "x": -14,
      "y": 21,
      "z": 12,
      "name": "Rock_Aqua"
    },
    {
      "x": -14,
      "y": 22,
      "z": 12,
      "name": "Rock_Aqua_Brick_Smooth"
    },
    {
      "x": -14,
      "y": 23,
      "z": 12,
      "name": "Rock_Aqua_Brick_Smooth"
    },
    {
      "x": -14,
      "y": 19,
      "z": 13,
      "name": "Rock_Aqua_Brick_Smooth"
    },
    {
      "x": -14,
      "y": 20,
      "z": 13,
      "name": "Rock_Aqua"
    },
    {
      "x": -14,
      "y": 21,
      "z": 13,
      "name": "Rock_Aqua_Brick_Smooth"
    },
    {
      "x": -14,
      "y": 22,
      "z": 13,
      "name": "Rock_Aqua"
    },
    {
      "x": -14,
      "y": 23,
      "z": 13,
      "name": "Rock_Aqua"
    },
    {
      "x": -14,
      "y": 19,
      "z": 14,
      "name": "Rock_Aqua"
    },
    {
      "x": -14,
      "y": 20,
      "z": 14,
      "name": "Rock_Aqua_Brick_Smooth"
    },
    {
      "x": -14,
      "y": 21,
      "z": 14,
      "name": "Rock_Aqua_Brick_Smooth"
    },
    {
      "x": -14,
      "y": 22,
      "z": 14,
      "name": "Rock_Aqua"
    },
    {
      "x": -14,
      "y": 23,
      "z": 14,
      "name": "Rock_Aqua_Brick_Smooth"
    },
    {
      "x": -14,
      "y": 20,
      "z": 15,
      "name": "Rock_Aqua"
    },
    {
      "x": -14,
      "y": 21,
      "z": 15,
      "name": "Rock_Aqua"
    },
    {
      "x": -14,
      "y": 22,
      "z": 15,
      "name": "Rock_Aqua_Brick_Smooth"
    },
    {
      "x": -14,
      "y": 20,
      "z": 16,
      "name": "Rock_Aqua_Brick_Smooth"
    },
    {
      "x": -14,
      "y": 21,
      "z": 16,
      "name": "Rock_Aqua"
    },
    {
      "x": -14,
      "y": 22,
      "z": 16,
      "name": "Rock_Aqua_Brick_Smooth"
    },
    {
      "x": -13,
      "y": 36,
      "z": -15,
      "name": "Rock_Aqua_Brick_Smooth"
    },
    {
      "x": -13,
      "y": 37,
      "z": -15,
      "name": "Plant_Coral_Model_Blue"
    },
    {
      "x": -13,
      "y": 0,
      "z": -12,
      "name": "Rock_Aqua"
    },
    {
      "x": -13,
      "y": 0,
      "z": -11,
      "name": "Rock_Aqua"
    },
    {
      "x": -13,
      "y": 36,
      "z": -11,
      "name": "Rock_Aqua_Cobble"
    },
    {
      "x": -13,
      "y": 0,
      "z": -10,
      "name": "Rock_Aqua"
    },
    {
      "x": -13,
      "y": 37,
      "z": -10,
      "name": "Rock_Aqua_Cobble"
    },
    {
      "x": -13,
      "y": 38,
      "z": -10,
      "name": "Plant_Crop_Mushroom_Glowing_Blue"
    },
    {
      "x": -13,
      "y": 0,
      "z": -9,
      "name": "Rock_Aqua"
    },
    {
      "x": -13,
      "y": 5,
      "z": -9,
      "name": "Rock_Aqua_Brick_Smooth_Half"
    },
    {
      "x": -13,
      "y": 0,
      "z": -8,
      "name": "Rock_Aqua"
    },
    {
      "x": -13,
      "y": 1,
      "z": -8,
      "name": "Rock_Aqua_Brick_Pillar_Base"
    },
    {
      "x": -13,
      "y": 2,
      "z": -8,
      "name": "Rock_Aqua_Brick_Pillar_Middle"
    },
    {
      "x": -13,
      "y": 3,
      "z": -8,
      "name": "Rock_Aqua_Brick_Pillar_Middle"
    },
    {
      "x": -13,
      "y": 4,
      "z": -8,
      "name": "Rock_Aqua_Brick_Pillar_Middle"
    },
    {
      "x": -13,
      "y": 5,
      "z": -8,
      "name": "Rock_Aqua_Brick_Smooth_Half"
    },
    {
      "x": -13,
      "y": 0,
      "z": -7,
      "name": "Rock_Aqua"
    },
    {
      "x": -13,
      "y": 5,
      "z": -7,
      "name": "Rock_Aqua_Brick_Smooth_Half"
    },
    {
      "x": -13,
      "y": 0,
      "z": -6,
      "name": "Rock_Aqua"
    },
    {
      "x": -13,
      "y": 5,
      "z": -6,
      "name": "Rock_Aqua_Brick_Smooth_Half",
      "rotation": 8
    },
    {
      "x": -13,
      "y": 0,
      "z": -5,
      "name": "Rock_Aqua"
    },
    {
      "x": -13,
      "y": 5,
      "z": -5,
      "name": "Rock_Aqua_Brick_Smooth_Half",
      "rotation": 8
    },
    {
      "x": -13,
      "y": 0,
      "z": -4,
      "name": "Rock_Aqua"
    },
    {
      "x": -13,
      "y": 5,
      "z": -4,
      "name": "Rock_Aqua_Brick_Smooth_Half",
      "rotation": 8
    },
    {
      "x": -13,
      "y": 0,
      "z": -3,
      "name": "Rock_Aqua"
    },
    {
      "x": -13,
      "y": 5,
      "z": -3,
      "name": "Rock_Aqua_Brick_Smooth_Half",
      "rotation": 8
    },
    {
      "x": -13,
      "y": 0,
      "z": -2,
      "name": "Rock_Aqua"
    },
    {
      "x": -13,
      "y": 5,
      "z": -2,
      "name": "Rock_Aqua_Brick_Smooth_Half",
      "rotation": 8
    },
    {
      "x": -13,
      "y": 0,
      "z": -1,
      "name": "Rock_Aqua"
    },
    {
      "x": -13,
      "y": 5,
      "z": -1,
      "name": "Rock_Aqua_Brick_Smooth_Half"
    },
    {
      "x": -13,
      "y": 0,
      "z": 0,
      "name": "Rock_Aqua"
    },
    {
      "x": -13,
      "y": 1,
      "z": 0,
      "name": "Rock_Aqua_Brick_Pillar_Base"
    },
    {
      "x": -13,
      "y": 2,
      "z": 0,
      "name": "Rock_Aqua_Brick_Pillar_Middle"
    },
    {
      "x": -13,
      "y": 3,
      "z": 0,
      "name": "Rock_Aqua_Brick_Pillar_Middle"
    },
    {
      "x": -13,
      "y": 4,
      "z": 0,
      "name": "Rock_Aqua_Brick_Pillar_Middle"
    },
    {
      "x": -13,
      "y": 5,
      "z": 0,
      "name": "Rock_Aqua_Brick_Smooth_Half"
    },
    {
      "x": -13,
      "y": 0,
      "z": 1,
      "name": "Rock_Aqua"
    },
    {
      "x": -13,
      "y": 5,
      "z": 1,
      "name": "Rock_Aqua_Brick_Smooth_Half"
    },
    {
      "x": -13,
      "y": 0,
      "z": 2,
      "name": "Rock_Aqua"
    },
    {
      "x": -13,
      "y": 0,
      "z": 3,
      "name": "Rock_Aqua"
    },
    {
      "x": -13,
      "y": 0,
      "z": 4,
      "name": "Rock_Aqua"
    },
    {
      "x": -13,
      "y": 21,
      "z": 12,
      "name": "Rock_Aqua"
    },
    {
      "x": -13,
      "y": 20,
      "z": 13,
      "name": "Rock_Aqua"
    },
    {
      "x": -13,
      "y": 21,
      "z": 13,
      "name": "Rock_Aqua"
    },
    {
      "x": -13,
      "y": 22,
      "z": 13,
      "name": "Rock_Aqua"
    },
    {
      "x": -13,
      "y": 21,
      "z": 14,
      "name": "Rock_Aqua_Brick_Smooth"
    },
    {
      "x": -12,
      "y": 36,
      "z": -15,
      "name": "Rock_Aqua_Brick"
    },
    {
      "x": -12,
      "y": 37,
      "z": -15,
      "name": "Rock_Aqua_Brick"
    },
    {
      "x": -12,
      "y": 38,
      "z": -15,
      "name": "Rock_Aqua_Cobble"
    },
    {
      "x": -12,
      "y": 36,
      "z": -14,
      "name": "Rock_Aqua_Brick"
    },
    {
      "x": -12,
      "y": 37,
      "z": -14,
      "name": "Rock_Aqua_Brick"
    },
    {
      "x": -12,
      "y": 38,
      "z": -14,
      "name": "Rock_Aqua_Cobble"
    },
    {
      "x": -12,
      "y": 39,
      "z": -14,
      "name": "Plant_Crop_Mushroom_Glowing_Blue"
    },
    {
      "x": -12,
      "y": 0,
      "z": -13,
      "name": "Rock_Aqua"
    },
    {
      "x": -12,
      "y": 35,
      "z": -13,
      "name": "Rock_Aqua_Brick_Smooth"
    },
    {
      "x": -12,
      "y": 36,
      "z": -13,
      "name": "Rock_Aqua_Cobble"
    },
    {
      "x": -12,
      "y": 37,
      "z": -13,
      "name": "Rock_Aqua_Brick"
    },
    {
      "x": -12,
      "y": 38,
      "z": -13,
      "name": "Rock_Aqua_Cobble"
    },
    {
      "x": -12,
      "y": 39,
      "z": -13,
      "name": "Plant_Coral_Model_Cyan"
    },
    {
      "x": -12,
      "y": 0,
      "z": -12,
      "name": "Rock_Aqua"
    },
    {
      "x": -12,
      "y": 36,
      "z": -12,
      "name": "Rock_Aqua_Cobble"
    },
    {
      "x": -12,
      "y": 37,
      "z": -12,
      "name": "Rock_Aqua_Brick"
    },
    {
      "x": -12,
      "y": 38,
      "z": -12,
      "name": "Rock_Aqua_Cobble"
    },
    {
      "x": -12,
      "y": 0,
      "z": -11,
      "name": "Rock_Aqua"
    },
    {
      "x": -12,
      "y": 5,
      "z": -11,
      "name": "Rock_Aqua_Brick_Smooth_Half"
    },
    {
      "x": -12,
      "y": 34,
      "z": -11,
      "name": "Rock_Aqua_Brick_Smooth"
    },
    {
      "x": -12,
      "y": 36,
      "z": -11,
      "name": "Rock_Aqua_Cobble"
    },
    {
      "x": -12,
      "y": 37,
      "z": -11,
      "name": "Rock_Aqua_Cobble"
    },
    {
      "x": -12,
      "y": 38,
      "z": -11,
      "name": "Rock_Aqua_Brick"
    },
    {
      "x": -12,
      "y": 0,
      "z": -10,
      "name": "Rock_Aqua"
    },
    {
      "x": -12,
      "y": 5,
      "z": -10,
      "name": "Rock_Aqua_Brick_Smooth_Half"
    },
    {
      "x": -12,
      "y": 35,
      "z": -10,
      "name": "Rock_Aqua_Brick_Smooth"
    },
    {
      "x": -12,
      "y": 0,
      "z": -9,
      "name": "Rock_Aqua"
    },
    {
      "x": -12,
      "y": 5,
      "z": -9,
      "name": "Rock_Aqua_Brick_Smooth_Half"
    },
    {
      "x": -12,
      "y": 0,
      "z": -8,
      "name": "Rock_Aqua"
    },
    {
      "x": -12,
      "y": 5,
      "z": -8,
      "name": "Rock_Aqua_Brick_Smooth_Half",
      "rotation": 8
    },
    {
      "x": -12,
      "y": 0,
      "z": -7,
      "name": "Rock_Aqua"
    },
    {
      "x": -12,
      "y": 5,
      "z": -7,
      "name": "Rock_Aqua_Brick_Smooth_Half",
      "rotation": 8
    },
    {
      "x": -12,
      "y": 0,
      "z": -6,
      "name": "Rock_Aqua"
    },
    {
      "x": -12,
      "y": 5,
      "z": -6,
      "name": "Furniture_Human_Ruins_Lantern_Ceiling"
    },
    {
      "x": -12,
      "y": 6,
      "z": -6,
      "name": "Rock_Aqua_Brick_Smooth_Half"
    },
    {
      "x": -12,
      "y": 9,
      "z": -6,
      "name": "*Rock_Aqua_Brick_Stairs_State_Definitions_Corner_Right",
      "rotation": 8
    },
    {
      "x": -12,
      "y": 10,
      "z": -6,
      "name": "Rock_Aqua_Brick_Wall"
    },
    {
      "x": -12,
      "y": 11,
      "z": -6,
      "name": "Rock_Aqua_Brick_Wall"
    },
    {
      "x": -12,
      "y": 12,
      "z": -6,
      "name": "Rock_Aqua_Brick_Wall"
    },
    {
      "x": -12,
      "y": 13,
      "z": -6,
      "name": "Rock_Aqua_Brick_Wall"
    },
    {
      "x": -12,
      "y": 14,
      "z": -6,
      "name": "Rock_Aqua_Brick_Smooth_Half"
    },
    {
      "x": -12,
      "y": 0,
      "z": -5,
      "name": "Rock_Aqua"
    },
    {
      "x": -12,
      "y": 6,
      "z": -5,
      "name": "Rock_Aqua_Brick_Smooth_Half"
    },
    {
      "x": -12,
      "y": 9,
      "z": -5,
      "name": "Rock_Aqua_Brick_Stairs",
      "rotation": 9
    },
    {
      "x": -12,
      "y": 14,
      "z": -5,
      "name": "Rock_Aqua_Brick_Stairs",
      "rotation": 2
    },
    {
      "x": -12,
      "y": 0,
      "z": -4,
      "name": "Rock_Aqua"
    },
    {
      "x": -12,
      "y": 6,
      "z": -4,
      "name": "Rock_Aqua_Brick_Smooth_Half"
    },
    {
      "x": -12,
      "y": 9,
      "z": -4,
      "name": "Rock_Aqua_Brick_Stairs",
      "rotation": 9
    },
    {
      "x": -12,
      "y": 14,
      "z": -4,
      "name": "Rock_Aqua_Brick_Stairs",
      "rotation": 9
    },
    {
      "x": -12,
      "y": 15,
      "z": -4,
      "name": "Rock_Aqua_Brick_Smooth_Half"
    },
    {
      "x": -12,
      "y": 0,
      "z": -3,
      "name": "Rock_Aqua"
    },
    {
      "x": -12,
      "y": 6,
      "z": -3,
      "name": "Rock_Aqua_Brick_Smooth_Half"
    },
    {
      "x": -12,
      "y": 9,
      "z": -3,
      "name": "Rock_Aqua_Brick_Stairs",
      "rotation": 9
    },
    {
      "x": -12,
      "y": 14,
      "z": -3,
      "name": "Rock_Aqua_Brick_Stairs"
    },
    {
      "x": -12,
      "y": 0,
      "z": -2,
      "name": "Rock_Aqua"
    },
    {
      "x": -12,
      "y": 5,
      "z": -2,
      "name": "Furniture_Human_Ruins_Lantern_Ceiling"
    },
    {
      "x": -12,
      "y": 6,
      "z": -2,
      "name": "Rock_Aqua_Brick_Smooth_Half"
    },
    {
      "x": -12,
      "y": 9,
      "z": -2,
      "name": "*Rock_Aqua_Brick_Stairs_State_Definitions_Corner_Left",
      "rotation": 10
    },
    {
      "x": -12,
      "y": 10,
      "z": -2,
      "name": "Rock_Aqua_Brick_Wall"
    },
    {
      "x": -12,
      "y": 11,
      "z": -2,
      "name": "Rock_Aqua_Brick_Wall"
    },
    {
      "x": -12,
      "y": 12,
      "z": -2,
      "name": "Rock_Aqua_Brick_Wall"
    },
    {
      "x": -12,
      "y": 13,
      "z": -2,
      "name": "Rock_Aqua_Brick_Wall"
    },
    {
      "x": -12,
      "y": 14,
      "z": -2,
      "name": "Rock_Aqua_Brick_Smooth_Half"
    },
    {
      "x": -12,
      "y": 0,
      "z": -1,
      "name": "Rock_Aqua"
    },
    {
      "x": -12,
      "y": 5,
      "z": -1,
      "name": "Rock_Aqua_Brick_Smooth_Half",
      "rotation": 8
    },
    {
      "x": -12,
      "y": 0,
      "z": 0,
      "name": "Rock_Aqua"
    },
    {
      "x": -12,
      "y": 5,
      "z": 0,
      "name": "Rock_Aqua_Brick_Smooth_Half",
      "rotation": 8
    },
    {
      "x": -12,
      "y": 0,
      "z": 1,
      "name": "Rock_Aqua"
    },
    {
      "x": -12,
      "y": 5,
      "z": 1,
      "name": "Rock_Aqua_Brick_Smooth_Half"
    },
    {
      "x": -12,
      "y": 0,
      "z": 2,
      "name": "Rock_Aqua"
    },
    {
      "x": -12,
      "y": 5,
      "z": 2,
      "name": "Rock_Aqua_Brick_Smooth_Half"
    },
    {
      "x": -12,
      "y": 0,
      "z": 3,
      "name": "Rock_Aqua"
    },
    {
      "x": -12,
      "y": 5,
      "z": 3,
      "name": "Rock_Aqua_Brick_Smooth_Half"
    },
    {
      "x": -12,
      "y": 0,
      "z": 4,
      "name": "Rock_Aqua"
    },
    {
      "x": -12,
      "y": 0,
      "z": 5,
      "name": "Rock_Aqua"
    },
    {
      "x": -11,
      "y": 14,
      "z": -24,
      "name": "Rock_Aqua_Cobble"
    },
    {
      "x": -11,
      "y": 15,
      "z": -24,
      "name": "Plant_Coral_Model_Blue"
    },
    {
      "x": -11,
      "y": 11,
      "z": -23,
      "name": "Rock_Aqua_Stalactite_Large",
      "filler": 31744,
      "rotation": 8
    },
    {
      "x": -11,
      "y": 12,
      "z": -23,
      "name": "Rock_Aqua_Stalactite_Large",
      "rotation": 8
    },
    {
      "x": -11,
      "y": 13,
      "z": -23,
      "name": "Rock_Aqua_Brick"
    },
    {
      "x": -11,
      "y": 13,
      "z": -22,
      "name": "Rock_Aqua_Cobble"
    },
    {
      "x": -11,
      "y": 14,
      "z": -22,
      "name": "Plant_Crop_Mushroom_Glowing_Blue"
    },
    {
      "x": -11,
      "y": 36,
      "z": -16,
      "name": "Rock_Aqua_Brick"
    },
    {
      "x": -11,
      "y": 37,
      "z": -16,
      "name": "Rock_Aqua_Cobble"
    },
    {
      "x": -11,
      "y": 38,
      "z": -16,
      "name": "Rock_Aqua_Cobble"
    },
    {
      "x": -11,
      "y": 35,
      "z": -15,
      "name": "Rock_Aqua_Brick_Smooth"
    },
    {
      "x": -11,
      "y": 37,
      "z": -15,
      "name": "Rock_Aqua_Brick"
    },
    {
      "x": -11,
      "y": 39,
      "z": -15,
      "name": "Rock_Aqua_Cobble"
    },
    {
      "x": -11,
      "y": 40,
      "z": -15,
      "name": "Plant_Coral_Bush_Blue"
    },
    {
      "x": -11,
      "y": 34,
      "z": -14,
      "name": "Rock_Aqua_Brick_Smooth"
    },
    {
      "x": -11,
      "y": 35,
      "z": -14,
      "name": "Rock_Aqua_Brick_Smooth"
    },
    {
      "x": -11,
      "y": 36,
      "z": -14,
      "name": "Rock_Aqua_Brick"
    },
    {
      "x": -11,
      "y": 37,
      "z": -14,
      "name": "Rock_Aqua_Cobble"
    },
    {
      "x": -11,
      "y": 38,
      "z": -14,
      "name": "Rock_Aqua_Cobble"
    },
    {
      "x": -11,
      "y": 0,
      "z": -13,
      "name": "Rock_Aqua"
    },
    {
      "x": -11,
      "y": 32,
      "z": -13,
      "name": "Rock_Aqua_Stalactite_Large",
      "filler": 31744,
      "rotation": 8
    },
    {
      "x": -11,
      "y": 33,
      "z": -13,
      "name": "Rock_Aqua_Stalactite_Large",
      "rotation": 8
    },
    {
      "x": -11,
      "y": 34,
      "z": -13,
      "name": "Rock_Aqua_Brick_Smooth"
    },
    {
      "x": -11,
      "y": 35,
      "z": -13,
      "name": "Rock_Aqua_Brick_Smooth"
    },
    {
      "x": -11,
      "y": 36,
      "z": -13,
      "name": "Rock_Aqua_Cobble"
    },
    {
      "x": -11,
      "y": 37,
      "z": -13,
      "name": "Rock_Aqua_Cobble"
    },
    {
      "x": -11,
      "y": 39,
      "z": -13,
      "name": "Rock_Aqua_Brick"
    },
    {
      "x": -11,
      "y": 0,
      "z": -12,
      "name": "Rock_Aqua"
    },
    {
      "x": -11,
      "y": 34,
      "z": -12,
      "name": "Rock_Aqua_Brick_Smooth"
    },
    {
      "x": -11,
      "y": 35,
      "z": -12,
      "name": "Rock_Aqua_Brick_Smooth"
    },
    {
      "x": -11,
      "y": 36,
      "z": -12,
      "name": "Rock_Aqua_Brick"
    },
    {
      "x": -11,
      "y": 37,
      "z": -12,
      "name": "Rock_Aqua_Cobble"
    },
    {
      "x": -11,
      "y": 38,
      "z": -12,
      "name": "Rock_Aqua_Cobble"
    },
    {
      "x": -11,
      "y": 39,
      "z": -12,
      "name": "Rock_Aqua_Brick"
    },
    {
      "x": -11,
      "y": 40,
      "z": -12,
      "name": "Plant_Coral_Model_Blue"
    },
    {
      "x": -11,
      "y": 0,
      "z": -11,
      "name": "Rock_Aqua"
    },
    {
      "x": -11,
      "y": 5,
      "z": -11,
      "name": "Rock_Aqua_Brick_Smooth_Half"
    },
    {
      "x": -11,
      "y": 35,
      "z": -11,
      "name": "Rock_Aqua_Brick_Smooth"
    },
    {
      "x": -11,
      "y": 36,
      "z": -11,
      "name": "Rock_Aqua_Brick"
    },
    {
      "x": -11,
      "y": 37,
      "z": -11,
      "name": "Rock_Aqua_Cobble"
    },
    {
      "x": -11,
      "y": 38,
      "z": -11,
      "name": "Rock_Aqua_Brick"
    },
    {
      "x": -11,
      "y": 39,
      "z": -11,
      "name": "Rock_Aqua_Cobble"
    },
    {
      "x": -11,
      "y": 0,
      "z": -10,
      "name": "Rock_Aqua"
    },
    {
      "x": -11,
      "y": 5,
      "z": -10,
      "name": "Rock_Aqua_Brick_Smooth_Half",
      "rotation": 8
    },
    {
      "x": -11,
      "y": 36,
      "z": -10,
      "name": "Rock_Aqua_Cobble"
    },
    {
      "x": -11,
      "y": 37,
      "z": -10,
      "name": "Rock_Aqua_Cobble"
    },
    {
      "x": -11,
      "y": 38,
      "z": -10,
      "name": "Rock_Aqua_Cobble"
    },
    {
      "x": -11,
      "y": 0,
      "z": -9,
      "name": "Rock_Aqua"
    },
    {
      "x": -11,
      "y": 5,
      "z": -9,
      "name": "Rock_Aqua_Brick_Smooth_Half",
      "rotation": 8
    },
    {
      "x": -11,
      "y": 0,
      "z": -8,
      "name": "Rock_Aqua"
    },
    {
      "x": -11,
      "y": 6,
      "z": -8,
      "name": "Rock_Aqua_Brick_Smooth_Half"
    },
    {
      "x": -11,
      "y": 0,
      "z": -7,
      "name": "Rock_Aqua"
    },
    {
      "x": -11,
      "y": 6,
      "z": -7,
      "name": "Rock_Aqua_Brick_Smooth_Half"
    },
    {
      "x": -11,
      "y": 10,
      "z": -7,
      "name": "Rock_Aqua_Brick_Smooth_Half",
      "rotation": 7
    },
    {
      "x": -11,
      "y": 13,
      "z": -7,
      "name": "Rock_Aqua_Brick_Smooth_Half",
      "rotation": 7
    },
    {
      "x": -11,
      "y": 17,
      "z": -7,
      "name": "Rock_Aqua_Brick_Stairs",
      "rotation": 9
    },
    {
      "x": -11,
      "y": 18,
      "z": -7,
      "name": "*Rock_Aqua_Brick_Wall_State_Definitions_Corner",
      "rotation": 1
    },
    {
      "x": -11,
      "y": 19,
      "z": -7,
      "name": "Furniture_Human_Ruins_Lantern"
    },
    {
      "x": -11,
      "y": 0,
      "z": -6,
      "name": "Rock_Aqua"
    },
    {
      "x": -11,
      "y": 1,
      "z": -6,
