{
  "version": 8,
  "blockIdVersion": 11,
  "anchorX": 1,
  "anchorY": 2,
  "anchorZ": 0,
  "blocks": [
    {
      "x": -3,
      "y": 6,
      "z": 0,
      "name": "Plant_Leaves_Skylands"
    },
    {
      "x": -3,
      "y": 7,
      "z": 0,
      "name": "Plant_Leaves_Skylands"
    },
    {
      "x": -2,
      "y": 5,
      "z": -1,
      "name": "Plant_Leaves_Skylands"
    },
    {
      "x": -2,
      "y": 5,
      "z": 0,
      "name": "Plant_Leaves_Skylands"
    },
    {
      "x": -2,
      "y": 6,
      "z": 0,
      "name": "Plant_Leaves_Skylands"
    },
    {
      "x": -2,
      "y": 7,
      "z": 0,
      "name": "Plant_Leaves_Skylands"
    },
    {
      "x": -2,
      "y": 8,
      "z": 0,
      "name": "Plant_Leaves_Skylands"
    },
    {
      "x": -1,
      "y": 6,
      "z": -2,
      "name": "Plant_Leaves_Skylands"
    },
    {
      "x": -1,
      "y": 5,
      "z": -1,
      "name": "Plant_Leaves_Skylands"
    },
    {
      "x": -1,
      "y": 6,
      "z": -1,
      "name": "Plant_Leaves_Skylands"
    },
    {
      "x": -1,
      "y": 7,
      "z": -1,
      "name": "Plant_Leaves_Skylands"
    },
    {
      "x": -1,
      "y": 8,
      "z": -1,
      "name": "Plant_Leaves_Skylands"
    },
    {
      "x": -1,
      "y": 5,
      "z": 0,
      "name": "Plant_Leaves_Skylands"
    },
    {
      "x": -1,
      "y": 6,
      "z": 0,
      "name": "Wood_Ash_Branch_Long",
      "rotation": 5
    },
    {
      "x": -1,
      "y": 7,
      "z": 0,
      "name": "Plant_Leaves_Skylands"
    },
    {
      "x": -1,
      "y": 8,
      "z": 0,
      "name": "Plant_Leaves_Skylands"
    },
    {
      "x": -1,
      "y": 9,
      "z": 0,
      "name": "Plant_Leaves_Skylands"
    },
    {
      "x": -1,
      "y": 5,
      "z": 1,
      "name": "Plant_Leaves_Skylands"
    },
    {
      "x": -1,
      "y": 6,
      "z": 1,
      "name": "Plant_Leaves_Skylands"
    },
    {
      "x": -1,
      "y": 7,
      "z": 1,
      "name": "Plant_Leaves_Skylands"
    },
    {
      "x": -1,
      "y": 5,
      "z": 2,
      "name": "Plant_Leaves_Skylands"
    },
    {
      "x": -1,
      "y": 7,
      "z": 2,
      "name": "Plant_Leaves_Skylands"
    },
    {
      "x": 0,
      "y": 6,
      "z": -2,
      "name": "Plant_Leaves_Skylands"
    },
    {
      "x": 0,
      "y": 7,
      "z": -2,
      "name": "Plant_Leaves_Skylands"
    },
    {
      "x": 0,
      "y": 8,
      "z": -2,
      "name": "Plant_Leaves_Skylands"
    },
    {
      "x": 0,
      "y": 6,
      "z": -1,
      "name": "Plant_Leaves_Skylands"
    },
    {
      "x": 0,
      "y": 8,
      "z": -1,
      "name": "Plant_Leaves_Skylands"
    },
    {
      "x": 0,
      "y": 9,
      "z": -1,
      "name": "Plant_Leaves_Skylands"
    },
    {
      "x": 0,
      "y": 6,
      "z": 0,
      "name": "Wood_Ash_Branch_Long",
      "rotation": 5
    },
    {
      "x": 0,
      "y": 7,
      "z": 0,
      "name": "Plant_Leaves_Skylands"
    },
    {
      "x": 0,
      "y": 8,
      "z": 0,
      "name": "Wood_Ash_Branch_Long",
      "rotation": 5
    },
    {
      "x": 0,
      "y": 9,
      "z": 0,
      "name": "Plant_Leaves_Skylands"
    },
    {
      "x": 0,
      "y": 10,
      "z": 0,
      "name": "Plant_Leaves_Skylands"
    },
    {
      "x": 0,
      "y": 5,
      "z": 1,
      "name": "Plant_Leaves_Skylands"
    },
    {
      "x": 0,
      "y": 8,
      "z": 1,
      "name": "Plant_Leaves_Skylands"
    },
    {
      "x": 0,
      "y": 9,
      "z": 1,
      "name": "Plant_Leaves_Skylands"
    },
    {
      "x": 0,
      "y": 5,
      "z": 2,
      "name": "Plant_Leaves_Skylands"
    },
    {
      "x": 0,
      "y": 6,
      "z": 2,
      "name": "Plant_Leaves_Skylands"
    },
    {
      "x": 0,
      "y": 8,
      "z": 2,
      "name": "Plant_Leaves_Skylands"
    },
    {
      "x": 1,
      "y": 7,
      "z": -3,
      "name": "Plant_Leaves_Skylands"
    },
    {
      "x": 1,
      "y": 5,
      "z": -2,
      "name": "Plant_Leaves_Skylands"
    },
    {
      "x": 1,
      "y": 6,
      "z": -2,
      "name": "Plant_Leaves_Skylands"
    },
    {
      "x": 1,
      "y": 7,
      "z": -2,
      "name": "Wood_Ash_Branch_Long",
      "rotation": 4
    },
    {
      "x": 1,
      "y": 8,
      "z": -2,
      "name": "Plant_Leaves_Skylands"
    },
    {
      "x": 1,
      "y": 9,
      "z": -2,
      "name": "Plant_Leaves_Skylands"
    },
    {
      "x": 1,
      "y": 5,
      "z": -1,
      "name": "Plant_Leaves_Skylands"
    },
    {
      "x": 1,
      "y": 7,
      "z": -1,
      "name": "Wood_Ash_Branch_Long",
      "rotation": 4
    },
    {
      "x": 1,
      "y": 9,
      "z": -1,
      "name": "Wood_Ash_Branch_Long",
      "rotation": 4
    },
    {
      "x": 1,
      "y": 10,
      "z": -1,
      "name": "Plant_Leaves_Skylands"
    },
    {
      "x": 1,
      "y": 0,
      "z": 0,
      "name": "Wood_Ash_Trunk"
    },
    {
      "x": 1,
      "y": 1,
      "z": 0,
      "name": "Wood_Ash_Trunk"
    },
    {
      "x": 1,
      "y": 2,
      "z": 0,
      "name": "Wood_Ash_Trunk"
    },
    {
      "x": 1,
      "y": 3,
      "z": 0,
      "name": "Wood_Ash_Trunk"
    },
    {
      "x": 1,
      "y": 4,
      "z": 0,
      "name": "Wood_Ash_Trunk"
    },
    {
      "x": 1,
      "y": 5,
      "z": 0,
      "name": "Wood_Ash_Trunk"
    },
    {
      "x": 1,
      "y": 6,
      "z": 0,
      "name": "Wood_Ash_Trunk"
    },
    {
      "x": 1,
      "y": 7,
      "z": 0,
      "name": "Wood_Ash_Trunk"
    },
    {
      "x": 1,
      "y": 8,
      "z": 0,
      "name": "Wood_Ash_Trunk"
    },
    {
      "x": 1,
      "y": 9,
      "z": 0,
      "name": "Wood_Ash_Trunk"
    },
    {
      "x": 1,
      "y": 10,
      "z": 0,
      "name": "Plant_Leaves_Skylands"
    },
    {
      "x": 1,
      "y": 6,
      "z": 1,
      "name": "Wood_Ash_Branch_Long",
      "rotation": 4
    },
    {
      "x": 1,
      "y": 9,
      "z": 1,
      "name": "Wood_Ash_Branch_Long",
      "rotation": 4
    },
    {
      "x": 1,
      "y": 10,
      "z": 1,
      "name": "Plant_Leaves_Skylands"
    },
    {
      "x": 1,
      "y": 5,
      "z": 2,
      "name": "Plant_Leaves_Skylands"
    },
    {
      "x": 1,
      "y": 6,
      "z": 2,
      "name": "Wood_Ash_Branch_Long",
      "rotation": 4
    },
    {
      "x": 1,
      "y": 7,
      "z": 2,
      "name": "Plant_Leaves_Skylands"
    },
    {
      "x": 1,
      "y": 8,
      "z": 2,
      "name": "Plant_Leaves_Skylands"
    },
    {
      "x": 1,
      "y": 9,
      "z": 2,
      "name": "Plant_Leaves_Skylands"
    },
    {
      "x": 1,
      "y": 6,
      "z": 3,
      "name": "Plant_Leaves_Skylands"
    },
    {
      "x": 1,
      "y": 7,
      "z": 3,
      "name": "Plant_Leaves_Skylands"
    },
    {
      "x": 2,
      "y": 6,
      "z": -3,
      "name": "Plant_Leaves_Skylands"
    },
    {
      "x": 2,
      "y": 5,
      "z": -2,
      "name": "Plant_Leaves_Skylands"
    },
    {
      "x": 2,
      "y": 6,
      "z": -2,
      "name": "Plant_Leaves_Skylands"
    },
    {
      "x": 2,
      "y": 7,
      "z": -2,
      "name": "Plant_Leaves_Skylands"
    },
    {
      "x": 2,
      "y": 8,
      "z": -2,
      "name": "Plant_Leaves_Skylands"
    },
    {
      "x": 2,
      "y": 5,
      "z": -1,
      "name": "Plant_Leaves_Skylands"
    },
    {
      "x": 2,
      "y": 8,
      "z": -1,
      "name": "Plant_Leaves_Skylands"
    },
    {
      "x": 2,
      "y": 9,
      "z": -1,
      "name": "Plant_Leaves_Skylands"
    },
    {
      "x": 2,
      "y": 5,
      "z": 0,
      "name": "Wood_Ash_Branch_Long",
      "rotation": 5
    },
    {
      "x": 2,
      "y": 8,
      "z": 0,
      "name": "Wood_Ash_Branch_Long",
      "rotation": 5
    },
    {
      "x": 2,
      "y": 9,
      "z": 0,
      "name": "Plant_Leaves_Skylands"
    },
    {
      "x": 2,
      "y": 10,
      "z": 0,
      "name": "Plant_Leaves_Skylands"
    },
    {
      "x": 2,
      "y": 7,
      "z": 1,
      "name": "Plant_Leaves_Skylands"
    },
    {
      "x": 2,
      "y": 8,
      "z": 1,
      "name": "Plant_Leaves_Skylands"
    },
    {
      "x": 2,
      "y": 9,
      "z": 1,
      "name": "Plant_Leaves_Skylands"
    },
    {
      "x": 2,
      "y": 5,
      "z": 2,
      "name": "Plant_Leaves_Skylands"
    },
    {
      "x": 2,
      "y": 6,
      "z": 2,
      "name": "Plant_Leaves_Skylands"
    },
    {
      "x": 2,
      "y": 7,
      "z": 2,
      "name": "Plant_Leaves_Skylands"
    },
    {
      "x": 2,
      "y": 8,
      "z": 2,
      "name": "Plant_Leaves_Skylands"
    },
    {
      "x": 3,
      "y": 5,
      "z": -2,
      "name": "Plant_Leaves_Skylands"
    },
    {
      "x": 3,
      "y": 6,
      "z": -2,
      "name": "Plant_Leaves_Skylands"
    },
    {
      "x": 3,
      "y": 5,
      "z": -1,
      "name": "Plant_Leaves_Skylands"
    },
    {
      "x": 3,
      "y": 6,
      "z": -1,
      "name": "Plant_Leaves_Skylands"
    },
    {
      "x": 3,
      "y": 7,
      "z": -1,
      "name": "Plant_Leaves_Skylands"
    },
    {
      "x": 3,
      "y": 8,
      "z": -1,
      "name": "Plant_Leaves_Skylands"
    },
    {
      "x": 3,
      "y": 5,
      "z": 0,
      "name": "Plant_Leaves_Skylands"
    },
    {
      "x": 3,
      "y": 6,
      "z": 0,
      "name": "Plant_Leaves_Skylands"
    },
    {
      "x": 3,
      "y": 7,
      "z": 0,
      "name": "Plant_Leaves_Skylands"
    },
    {
      "x": 3,
      "y": 8,
      "z": 0,
      "name": "Plant_Leaves_Skylands"
    },
    {
      "x": 3,
      "y": 9,
      "z": 0,
      "name": "Plant_Leaves_Skylands"
    },
    {
      "x": 3,
      "y": 6,
      "z": 1,
      "name": "Plant_Leaves_Skylands"
    },
    {
      "x": 3,
      "y": 7,
      "z": 1,
      "name": "Plant_Leaves_Skylands"
    },
    {
      "x": 3,
      "y": 5,
      "z": 2,
      "name": "Plant_Leaves_Skylands"
    },
    {
      "x": 3,
      "y": 6,
      "z": 2,
      "name": "Plant_Leaves_Skylands"
    },
    {
      "x": 4,
      "y": 6,
      "z": 0,
      "name": "Plant_Leaves_Skylands"
    },
    {
      "x": 4,
      "y": 7,
      "z": 0,
      "name": "Plant_Leaves_Skylands"
    },
    {
      "x": 4,
      "y": 8,
      "z": 0,
      "name": "Plant_Leaves_Skylands"
    }
  ]
}